Workbook
Name _ChartDates: 实盘组合预估净值!$A$8:INDEX(实盘组合预估净值!$A$8:$A$1000,MATCH(9.99999999999999E+307,实盘组合预估净值!$A$8:$A$1000))
Name _ChartDates: 实盘组合预估净值!$A$5:INDEX(实盘组合预估净值!$A$5:$A$1000,MATCH(9.99999999999999E+307,实盘组合预估净值!$A$5:$A$1000))
Name _ChartDates: 实盘组合预估净值!$A$8:INDEX(实盘组合预估净值!$A$8:$A$1000,MATCH(9.99999999999999E+307,实盘组合预估净值!$A$8:$A$1000))
Name _ChartDates: 实盘组合预估净值!$A$6:INDEX(实盘组合预估净值!$A$6:$A$1000,MATCH(9.99999999999999E+307,实盘组合预估净值!$A$6:$A$1000))
Name _ChartDates: 实盘组合预估净值!$A$7:INDEX(实盘组合预估净值!$A$7:$A$1000,MATCH(9.99999999999999E+307,实盘组合预估净值!$A$7:$A$1000))
Name _ChartDates: 实盘组合预估净值!$A$5:INDEX(实盘组合预估净值!$A$5:$A$1000,MATCH(9.99999999999999E+307,实盘组合预估净值!$A$5:$A$1000))
Name _ChartValues: 实盘组合预估净值!$K$8:INDEX(实盘组合预估净值!$K$8:$K$1000,MATCH(9.99999999999999E+307,实盘组合预估净值!$A$8:$A$1000))
Name _ChartValues: 实盘组合预估净值!$N$5:INDEX(实盘组合预估净值!$N$5:$N$1000,MATCH(9.99999999999999E+307,实盘组合预估净值!$A$5:$A$1000))
Name _ChartValues: 实盘组合预估净值!$Q$8:INDEX(实盘组合预估净值!$Q$8:$Q$1000,MATCH(9.99999999999999E+307,实盘组合预估净值!$A$8:$A$1000))
Name _ChartValues: 实盘组合预估净值!$B$6:INDEX(实盘组合预估净值!$B$6:$B$1000,MATCH(9.99999999999999E+307,实盘组合预估净值!$A$6:$A$1000))
Name _ChartValues: 实盘组合预估净值!$H$7:INDEX(实盘组合预估净值!$H$7:$H$1000,MATCH(9.99999999999999E+307,实盘组合预估净值!$A$7:$A$1000))
Name _ChartValues: 实盘组合预估净值!$E$5:INDEX(实盘组合预估净值!$E$5:$E$1000,MATCH(9.99999999999999E+307,实盘组合预估净值!$A$5:$A$1000))
Name _ChartDates: 实盘组合预估净值!$A$69:INDEX(实盘组合预估净值!$A$69:$A$1000,MATCH(9.99999999999999E+307,实盘组合预估净值!$A$69:$A$1000))
Name _ChartValues: 实盘组合预估净值!$T$69:INDEX(实盘组合预估净值!$T$69:$T$1000,MATCH(9.99999999999999E+307,实盘组合预估净值!$A$69:$A$1000))

Sheet 实盘持仓初始配置
A1: 持仓配置（实盘·初始权重）
A2: 基金简称 | B2: 华安黄金ETF联接A | C2: 嘉实快线货币A | D2: 宏利复兴混合A | E2: 博道沪深300增强A | F2: 博道沪深300指增C | G2: 国泰通信设备ETF联接A | H2: 国泰通信设备C | I2: 嘉实前沿科技创新 | J2: 银华集成电路混合A | K2: 银华集成电路混合C | L2: 天弘中证1000指增A | M2: 天弘中证1000指增C | N2: 中欧中证500指增A | O2: 中欧中证500指增C | P2: 信澳业绩驱动A | Q2: 嘉实信息产业A | R2: 嘉实信息产业C | S2: 宏利复兴伟业C | T2: 国泰半导体材料设备ETF联接A | U2: 国泰半导体材料设备C | V2: 华泰柏瑞中证2000指增A | W2: 华泰柏瑞中证2000指增C | X2: 易方达中债新综指LOFA | Y2: 合计 | Z2: 年化费率 | AA2: 净值起始日 | AB2: 嘉实中证500指数增强C | AC2: 博道中证500指数增强C | AD2: 汇添富中证1000指数增强C | AE2: 招商中证2000指数增强C | AF2: 嘉实价值优势混合A | AG2: 民生加银优选 | AH2: 大成竞争优势混合A | AI2: 国投瑞银瑞源混合A | AJ2: 华泰柏瑞红利低波ETF链接A | AK2: 天弘中证红利低波动100ETF联接A | AL2: 嘉实中债3-5年国开行A | AM2: 广发7-10年国开行A | AN2: 嘉实上海金ETF联接A
A3: 基金代码 | B3: 000216.OF | C3: 000917.OF | D3: 001170.OF | E3: 007044.OF | F3: 007045.OF | G3: 007817.OF | H3: 007818.OF | I3: 009993.OF | J3: 013840.OF | K3: 013841.OF | L3: 014201.OF | M3: 014202.OF | N3: 015453.OF | O3: 015454.OF | P3: 016370.OF | Q3: 017488.OF | R3: 017489.OF | S3: 017612.OF | T3: 019632.OF | U3: 019633.OF | V3: 019923.OF | W3: 019924.OF | X3: 161119.OF | AB3: 008779.OF | AC3: 006594.OF | AD3: 017954.OF | AE3: 019919.OF | AF3: 070019.OF | AG3: 000884.OF | AH3: 090013.OF | AI3: 121010.OF | AJ3: 007466.OF | AK3: 008114.OF | AL3: 008015.OF | AM3: 003376.OF | AN3: 016581.OF
A4: 产业趋势 权重 | B4: 0 | C4: 0.02 | D4: 0.19 | E4: 0 | F4: 0 | G4: 0.11 | H4: 0 | I4: 0 | J4: 0.19 | K4: 0 | L4: 0 | M4: 0 | N4: 0 | O4: 0 | P4: 0.19 | Q4: 0.19 | R4: 0 | S4: 0 | T4: 0.11 | U4: 0 | V4: 0 | W4: 0 | X4: 0 | Y4: =SUM(B4:X4) -> 1 | Z4: 0.015 | AA4: 46195
A5: 产业趋势基石 权重 | B5: 0 | C5: 0.02 | D5: 0.19 | E5: 0 | F5: 0 | G5: 0.11 | H5: 0 | I5: 0 | J5: 0.19 | K5: 0 | L5: 0 | M5: 0 | N5: 0 | O5: 0 | P5: 0.19 | Q5: 0.19 | R5: 0 | S5: 0 | T5: 0.11 | U5: 0 | V5: 0 | W5: 0 | X5: 0 | Y5: =SUM(B5:X5) -> 1 | Z5: 0.012 | AA5: 46191
A6: 产业趋势2号 权重 | B6: 0 | C6: 0.02 | D6: 0 | E6: 0 | F6: 0 | G6: 0 | H6: 0.11 | I6: 0.19 | J6: 0 | K6: 0.19 | L6: 0 | M6: 0 | N6: 0 | O6: 0 | P6: 0 | Q6: 0 | R6: 0.19 | S6: 0.19 | T6: 0 | U6: 0.11 | V6: 0 | W6: 0 | X6: 0 | Y6: =SUM(B6:X6) -> 1 | Z6: 0.015 | AA6: 46196
A7: 10-90 权重 | B7: 0.05 | C7: 0.02 | D7: 0 | E7: 0 | F7: 0.0125 | G7: 0 | H7: 0.005 | I7: 0.01 | J7: 0 | K7: 0.01 | L7: 0 | M7: 0.0125 | N7: 0 | O7: 0.0125 | P7: 0 | Q7: 0 | R7: 0.01 | S7: 0.01 | T7: 0 | U7: 0.005 | V7: 0 | W7: 0.0125 | X7: 0.83 | Y7: =SUM(B7:X7) -> 1 | Z7: 0.008 | AA7: 46197
A8: 10-90基石 权重 | B8: 0.05 | C8: 0.02 | D8: 0.01 | E8: 0.0125 | F8: 0 | G8: 0.005 | H8: 0 | I8: 0 | J8: 0.01 | K8: 0 | L8: 0.0125 | M8: 0 | N8: 0.0125 | O8: 0 | P8: 0.01 | Q8: 0.01 | R8: 0 | S8: 0 | T8: 0.005 | U8: 0 | V8: 0.0125 | W8: 0 | X8: 0.83 | Y8: =SUM(B8:X8) -> 1 | Z8: 0.005 | AA8: 46191
A9: 30-70 权重 | B9: 0.1 | C9: 0.02 | D9: 0 | E9: 0 | F9: 0.0375 | G9: 0 | H9: 0.015 | I9: 0.03 | J9: 0 | K9: 0.03 | L9: 0 | M9: 0.0375 | N9: 0 | O9: 0.0375 | P9: 0 | Q9: 0 | R9: 0.03 | S9: 0.03 | T9: 0 | U9: 0.015 | V9: 0 | W9: 0.0375 | X9: 0.58 | Y9: =SUM(B9:X9) -> 1 | Z9: 0.012 | AA9: 46197
A10: 20-80 权重 | B10: 0 | C10: 0.05 | D10: 0 | E10: 0 | F10: 0.025 | G10: 0 | H10: 0 | I10: 0 | J10: 0 | K10: 0 | L10: 0 | M10: 0.0125 | N10: 0 | O10: 0 | P10: 0 | Q10: 0 | R10: 0 | S10: 0 | T10: 0 | U10: 0 | V10: 0 | W10: 0.0125 | X10: 0.3 | Y10: =SUM(B10:X10)+SUM(AB10:AN10) -> 1 | Z10: 0.008 | AA10: 46282 | AB10: 0.0125 | AC10: 0.0125 | AD10: 0.0125 | AE10: 0.0125 | AF10: 0.005 | AG10: 0.005 | AH10: 0.005 | AI10: 0.005 | AJ10: 0.06 | AK10: 0.02 | AL10: 0.2 | AM10: 0.2 | AN10: 0.05
A11: 权重蓝色输入；Z列为各组合年化费率、AA列为各组合净值起始日(当日净值=1)。新增交易日下拉填充，下游净值与看板自动重算。

Sheet 偏离度监控
A1: 样板间投顾组合 · 偏离度监控
A2: 净值截止日 | B2: =$B$82 -> 46286 | C2: 权重口径 | D2: 上一完整交易日（避免当日净值更新不同步） | I2: 配比预警阈值 | J2: 0.02 | K2: 主动基金上限 | L2: 0.2
A3: 三个产业趋势组合展示全部最新持仓；10-90（含基石）及30-70的结构偏离按目标配比监控。红色表示超过约束或预警阈值。
A5: 1. 产业趋势组合详细持仓及集中度风险 | F5: 数据截止日 | G5: =$B$82 -> 46286
A6: 组合 | B6: 基金代码 | C6: 基金简称 | D6: 基金类型 | E6: 当前权重 | F6: 是否超限 | G6: 调仓生效日
A7: =IF(B7<>"","产业趋势","") -> 产业趋势 | B7: =IFERROR(INDEX($A$53:$A$78,MATCH(1,M$53:M$78,0)),"") -> 000917.OF | C7: =IFERROR(INDEX($B$53:$B$78,MATCH(1,M$53:M$78,0)),"") -> 嘉实快线货币A | D7: =IFERROR(INDEX($E$53:$E$78,MATCH(1,M$53:M$78,0)),"") -> 货币 | E7: =IFERROR(INDEX(G$53:G$78,MATCH(1,M$53:M$78,0)),"") -> 0.051384207 | F7: =IF(B7="","",IF(D7<>"主动","不适用",IF(E7>$L$2,"超限","正常"))) -> 不适用 | G7: =IF(B7<>"",G$84,"") -> 46213
A8: =IF(B8<>"","产业趋势","") -> 产业趋势 | B8: =IFERROR(INDEX($A$53:$A$78,MATCH(2,M$53:M$78,0)),"") -> 001170.OF | C8: =IFERROR(INDEX($B$53:$B$78,MATCH(2,M$53:M$78,0)),"") -> 宏利复兴混合A | D8: =IFERROR(INDEX($E$53:$E$78,MATCH(2,M$53:M$78,0)),"") -> 主动 | E8: =IFERROR(INDEX(G$53:G$78,MATCH(2,M$53:M$78,0)),"") -> 0.1678591 | F8: =IF(B8="","",IF(D8<>"主动","不适用",IF(E8>$L$2,"超限","正常"))) -> 正常 | G8: =IF(B8<>"",G$84,"") -> 46213
A9: =IF(B9<>"","产业趋势","") -> 产业趋势 | B9: =IFERROR(INDEX($A$53:$A$78,MATCH(3,M$53:M$78,0)),"") -> 013840.OF | C9: =IFERROR(INDEX($B$53:$B$78,MATCH(3,M$53:M$78,0)),"") -> 银华集成电路混合A | D9: =IFERROR(INDEX($E$53:$E$78,MATCH(3,M$53:M$78,0)),"") -> 主动 | E9: =IFERROR(INDEX(G$53:G$78,MATCH(3,M$53:M$78,0)),"") -> 0.23005113 | F9: =IF(B9="","",IF(D9<>"主动","不适用",IF(E9>$L$2,"超限","正常"))) -> 超限 | G9: =IF(B9<>"",G$84,"") -> 46213
A10: =IF(B10<>"","产业趋势","") -> 产业趋势 | B10: =IFERROR(INDEX($A$53:$A$78,MATCH(4,M$53:M$78,0)),"") -> 016370.OF | C10: =IFERROR(INDEX($B$53:$B$78,MATCH(4,M$53:M$78,0)),"") -> 信澳业绩驱动A | D10: =IFERROR(INDEX($E$53:$E$78,MATCH(4,M$53:M$78,0)),"") -> 主动 | E10: =IFERROR(INDEX(G$53:G$78,MATCH(4,M$53:M$78,0)),"") -> 0.18244613 | F10: =IF(B10="","",IF(D10<>"主动","不适用",IF(E10>$L$2,"超限","正常"))) -> 正常 | G10: =IF(B10<>"",G$84,"") -> 46213
A11: =IF(B11<>"","产业趋势","") -> 产业趋势 | B11: =IFERROR(INDEX($A$53:$A$78,MATCH(5,M$53:M$78,0)),"") -> 017488.OF | C11: =IFERROR(INDEX($B$53:$B$78,MATCH(5,M$53:M$78,0)),"") -> 嘉实信息产业A | D11: =IFERROR(INDEX($E$53:$E$78,MATCH(5,M$53:M$78,0)),"") -> 主动 | E11: =IFERROR(INDEX(G$53:G$78,MATCH(5,M$53:M$78,0)),"") -> 0.18091632 | F11: =IF(B11="","",IF(D11<>"主动","不适用",IF(E11>$L$2,"超限","正常"))) -> 正常 | G11: =IF(B11<>"",G$84,"") -> 46213
A12: =IF(B12<>"","产业趋势","") -> 产业趋势 | B12: =IFERROR(INDEX($A$53:$A$78,MATCH(6,M$53:M$78,0)),"") -> 019632.OF | C12: =IFERROR(INDEX($B$53:$B$78,MATCH(6,M$53:M$78,0)),"") -> 国泰半导体材料设备ETF联接A | D12: =IFERROR(INDEX($E$53:$E$78,MATCH(6,M$53:M$78,0)),"") -> 指数 | E12: =IFERROR(INDEX(G$53:G$78,MATCH(6,M$53:M$78,0)),"") -> 0.12199435 | F12: =IF(B12="","",IF(D12<>"主动","不适用",IF(E12>$L$2,"超限","正常"))) -> 不适用 | G12: =IF(B12<>"",G$84,"") -> 46213
A13: =IF(B13<>"","产业趋势","") -> 产业趋势 | B13: =IFERROR(INDEX($A$53:$A$78,MATCH(7,M$53:M$78,0)),"") -> 162214.OF | C13: =IFERROR(INDEX($B$53:$B$78,MATCH(7,M$53:M$78,0)),"") -> 宏利领先中小盘混合 | D13: =IFERROR(INDEX($E$53:$E$78,MATCH(7,M$53:M$78,0)),"") -> 主动 | E13: =IFERROR(INDEX(G$53:G$78,MATCH(7,M$53:M$78,0)),"") -> 0.065348778 | F13: =IF(B13="","",IF(D13<>"主动","不适用",IF(E13>$L$2,"超限","正常"))) -> 正常 | G13: =IF(B13<>"",G$84,"") -> 46213
A14: =IF(B14<>"","产业趋势","") | B14: =IFERROR(INDEX($A$53:$A$78,MATCH(8,M$53:M$78,0)),"") | C14: =IFERROR(INDEX($B$53:$B$78,MATCH(8,M$53:M$78,0)),"") | D14: =IFERROR(INDEX($E$53:$E$78,MATCH(8,M$53:M$78,0)),"") | E14: =IFERROR(INDEX(G$53:G$78,MATCH(8,M$53:M$78,0)),"") | F14: =IF(B14="","",IF(D14<>"主动","不适用",IF(E14>$L$2,"超限","正常"))) | G14: =IF(B14<>"",G$84,"")
A15: =IF(B15<>"","产业趋势基石","") -> 产业趋势基石 | B15: =IFERROR(INDEX($A$53:$A$78,MATCH(1,N$53:N$78,0)),"") -> 000917.OF | C15: =IFERROR(INDEX($B$53:$B$78,MATCH(1,N$53:N$78,0)),"") -> 嘉实快线货币A | D15: =IFERROR(INDEX($E$53:$E$78,MATCH(1,N$53:N$78,0)),"") -> 货币 | E15: =IFERROR(INDEX(H$53:H$78,MATCH(1,N$53:N$78,0)),"") -> 0.05023646 | F15: =IF(B15="","",IF(D15<>"主动","不适用",IF(E15>$L$2,"超限","正常"))) -> 不适用 | G15: =IF(B15<>"",H$84,"") -> 46213
A16: =IF(B16<>"","产业趋势基石","") -> 产业趋势基石 | B16: =IFERROR(INDEX($A$53:$A$78,MATCH(2,N$53:N$78,0)),"") -> 001170.OF | C16: =IFERROR(INDEX($B$53:$B$78,MATCH(2,N$53:N$78,0)),"") -> 宏利复兴混合A | D16: =IFERROR(INDEX($E$53:$E$78,MATCH(2,N$53:N$78,0)),"") -> 主动 | E16: =IFERROR(INDEX(H$53:H$78,MATCH(2,N$53:N$78,0)),"") -> 0.1694059 | F16: =IF(B16="","",IF(D16<>"主动","不适用",IF(E16>$L$2,"超限","正常"))) -> 正常 | G16: =IF(B16<>"",H$84,"") -> 46213
A17: =IF(B17<>"","产业趋势基石","") -> 产业趋势基石 | B17: =IFERROR(INDEX($A$53:$A$78,MATCH(3,N$53:N$78,0)),"") -> 013840.OF | C17: =IFERROR(INDEX($B$53:$B$78,MATCH(3,N$53:N$78,0)),"") -> 银华集成电路混合A | D17: =IFERROR(INDEX($E$53:$E$78,MATCH(3,N$53:N$78,0)),"") -> 主动 | E17: =IFERROR(INDEX(H$53:H$78,MATCH(3,N$53:N$78,0)),"") -> 0.22839766 | F17: =IF(B17="","",IF(D17<>"主动","不适用",IF(E17>$L$2,"超限","正常"))) -> 超限 | G17: =IF(B17<>"",H$84,"") -> 46213
A18: =IF(B18<>"","产业趋势基石","") -> 产业趋势基石 | B18: =IFERROR(INDEX($A$53:$A$78,MATCH(4,N$53:N$78,0)),"") -> 016370.OF | C18: =IFERROR(INDEX($B$53:$B$78,MATCH(4,N$53:N$78,0)),"") -> 信澳业绩驱动A | D18: =IFERROR(INDEX($E$53:$E$78,MATCH(4,N$53:N$78,0)),"") -> 主动 | E18: =IFERROR(INDEX(H$53:H$78,MATCH(4,N$53:N$78,0)),"") -> 0.18230281 | F18: =IF(B18="","",IF(D18<>"主动","不适用",IF(E18>$L$2,"超限","正常"))) -> 正常 | G18: =IF(B18<>"",H$84,"") -> 46213
A19: =IF(B19<>"","产业趋势基石","") -> 产业趋势基石 | B19: =IFERROR(INDEX($A$53:$A$78,MATCH(5,N$53:N$78,0)),"") -> 017488.OF | C19: =IFERROR(INDEX($B$53:$B$78,MATCH(5,N$53:N$78,0)),"") -> 嘉实信息产业A | D19: =IFERROR(INDEX($E$53:$E$78,MATCH(5,N$53:N$78,0)),"") -> 主动 | E19: =IFERROR(INDEX(H$53:H$78,MATCH(5,N$53:N$78,0)),"") -> 0.18173267 | F19: =IF(B19="","",IF(D19<>"主动","不适用",IF(E19>$L$2,"超限","正常"))) -> 正常 | G19: =IF(B19<>"",H$84,"") -> 46213
A20: =IF(B20<>"","产业趋势基石","") -> 产业趋势基石 | B20: =IFERROR(INDEX($A$53:$A$78,MATCH(6,N$53:N$78,0)),"") -> 019632.OF | C20: =IFERROR(INDEX($B$53:$B$78,MATCH(6,N$53:N$78,0)),"") -> 国泰半导体材料设备ETF联接A | D20: =IFERROR(INDEX($E$53:$E$78,MATCH(6,N$53:N$78,0)),"") -> 指数 | E20: =IFERROR(INDEX(H$53:H$78,MATCH(6,N$53:N$78,0)),"") -> 0.12257624 | F20: =IF(B20="","",IF(D20<>"主动","不适用",IF(E20>$L$2,"超限","正常"))) -> 不适用 | G20: =IF(B20<>"",H$84,"") -> 46213
A21: =IF(B21<>"","产业趋势基石","") -> 产业趋势基石 | B21: =IFERROR(INDEX($A$53:$A$78,MATCH(7,N$53:N$78,0)),"") -> 162214.OF | C21: =IFERROR(INDEX($B$53:$B$78,MATCH(7,N$53:N$78,0)),"") -> 宏利领先中小盘混合 | D21: =IFERROR(INDEX($E$53:$E$78,MATCH(7,N$53:N$78,0)),"") -> 主动 | E21: =IFERROR(INDEX(H$53:H$78,MATCH(7,N$53:N$78,0)),"") -> 0.065348257 | F21: =IF(B21="","",IF(D21<>"主动","不适用",IF(E21>$L$2,"超限","正常"))) -> 正常 | G21: =IF(B21<>"",H$84,"") -> 46213
A22: =IF(B22<>"","产业趋势基石","") | B22: =IFERROR(INDEX($A$53:$A$78,MATCH(8,N$53:N$78,0)),"") | C22: =IFERROR(INDEX($B$53:$B$78,MATCH(8,N$53:N$78,0)),"") | D22: =IFERROR(INDEX($E$53:$E$78,MATCH(8,N$53:N$78,0)),"") | E22: =IFERROR(INDEX(H$53:H$78,MATCH(8,N$53:N$78,0)),"") | F22: =IF(B22="","",IF(D22<>"主动","不适用",IF(E22>$L$2,"超限","正常"))) | G22: =IF(B22<>"",H$84,"")
A23: =IF(B23<>"","产业趋势2号","") -> 产业趋势2号 | B23: =IFERROR(INDEX($A$53:$A$78,MATCH(1,O$53:O$78,0)),"") -> 000917.OF | C23: =IFERROR(INDEX($B$53:$B$78,MATCH(1,O$53:O$78,0)),"") -> 嘉实快线货币A | D23: =IFERROR(INDEX($E$53:$E$78,MATCH(1,O$53:O$78,0)),"") -> 货币 | E23: =IFERROR(INDEX(I$53:I$78,MATCH(1,O$53:O$78,0)),"") -> 0.050033798 | F23: =IF(B23="","",IF(D23<>"主动","不适用",IF(E23>$L$2,"超限","正常"))) -> 不适用 | G23: =IF(B23<>"",I$84,"") -> 46213
A24: =IF(B24<>"","产业趋势2号","") -> 产业趋势2号 | B24: =IFERROR(INDEX($A$53:$A$78,MATCH(2,O$53:O$78,0)),"") -> 009993.OF | C24: =IFERROR(INDEX($B$53:$B$78,MATCH(2,O$53:O$78,0)),"") -> 嘉实前沿科技创新 | D24: =IFERROR(INDEX($E$53:$E$78,MATCH(2,O$53:O$78,0)),"") -> 主动 | E24: =IFERROR(INDEX(I$53:I$78,MATCH(2,O$53:O$78,0)),"") -> 0.18359663 | F24: =IF(B24="","",IF(D24<>"主动","不适用",IF(E24>$L$2,"超限","正常"))) -> 正常 | G24: =IF(B24<>"",I$84,"") -> 46213
A25: =IF(B25<>"","产业趋势2号","") -> 产业趋势2号 | B25: =IFERROR(INDEX($A$53:$A$78,MATCH(3,O$53:O$78,0)),"") -> 013841.OF | C25: =IFERROR(INDEX($B$53:$B$78,MATCH(3,O$53:O$78,0)),"") -> 银华集成电路混合C | D25: =IFERROR(INDEX($E$53:$E$78,MATCH(3,O$53:O$78,0)),"") -> 主动 | E25: =IFERROR(INDEX(I$53:I$78,MATCH(3,O$53:O$78,0)),"") -> 0.22464241 | F25: =IF(B25="","",IF(D25<>"主动","不适用",IF(E25>$L$2,"超限","正常"))) -> 超限 | G25: =IF(B25<>"",I$84,"") -> 46213
A26: =IF(B26<>"","产业趋势2号","") -> 产业趋势2号 | B26: =IFERROR(INDEX($A$53:$A$78,MATCH(4,O$53:O$78,0)),"") -> 017489.OF | C26: =IFERROR(INDEX($B$53:$B$78,MATCH(4,O$53:O$78,0)),"") -> 嘉实信息产业C | D26: =IFERROR(INDEX($E$53:$E$78,MATCH(4,O$53:O$78,0)),"") -> 主动 | E26: =IFERROR(INDEX(I$53:I$78,MATCH(4,O$53:O$78,0)),"") -> 0.18202238 | F26: =IF(B26="","",IF(D26<>"主动","不适用",IF(E26>$L$2,"超限","正常"))) -> 正常 | G26: =IF(B26<>"",I$84,"") -> 46213
A27: =IF(B27<>"","产业趋势2号","") -> 产业趋势2号 | B27: =IFERROR(INDEX($A$53:$A$78,MATCH(5,O$53:O$78,0)),"") -> 017612.OF | C27: =IFERROR(INDEX($B$53:$B$78,MATCH(5,O$53:O$78,0)),"") -> 宏利复兴伟业C | D27: =IFERROR(INDEX($E$53:$E$78,MATCH(5,O$53:O$78,0)),"") -> 主动 | E27: =IFERROR(INDEX(I$53:I$78,MATCH(5,O$53:O$78,0)),"") -> 0.17233309 | F27: =IF(B27="","",IF(D27<>"主动","不适用",IF(E27>$L$2,"超限","正常"))) -> 正常 | G27: =IF(B27<>"",I$84,"") -> 46213
A28: =IF(B28<>"","产业趋势2号","") -> 产业趋势2号 | B28: =IFERROR(INDEX($A$53:$A$78,MATCH(6,O$53:O$78,0)),"") -> 019633.OF | C28: =IFERROR(INDEX($B$53:$B$78,MATCH(6,O$53:O$78,0)),"") -> 国泰半导体材料设备C | D28: =IFERROR(INDEX($E$53:$E$78,MATCH(6,O$53:O$78,0)),"") -> 指数 | E28: =IFERROR(INDEX(I$53:I$78,MATCH(6,O$53:O$78,0)),"") -> 0.12002747 | F28: =IF(B28="","",IF(D28<>"主动","不适用",IF(E28>$L$2,"超限","正常"))) -> 不适用 | G28: =IF(B28<>"",I$84,"") -> 46213
A29: =IF(B29<>"","产业趋势2号","") -> 产业趋势2号 | B29: =IFERROR(INDEX($A$53:$A$78,MATCH(7,O$53:O$78,0)),"") -> 162214.OF | C29: =IFERROR(INDEX($B$53:$B$78,MATCH(7,O$53:O$78,0)),"") -> 宏利领先中小盘混合 | D29: =IFERROR(INDEX($E$53:$E$78,MATCH(7,O$53:O$78,0)),"") -> 主动 | E29: =IFERROR(INDEX(I$53:I$78,MATCH(7,O$53:O$78,0)),"") -> 0.067344212 | F29: =IF(B29="","",IF(D29<>"主动","不适用",IF(E29>$L$2,"超限","正常"))) -> 正常 | G29: =IF(B29<>"",I$84,"") -> 46213
A30: =IF(B30<>"","产业趋势2号","") | B30: =IFERROR(INDEX($A$53:$A$78,MATCH(8,O$53:O$78,0)),"") | C30: =IFERROR(INDEX($B$53:$B$78,MATCH(8,O$53:O$78,0)),"") | D30: =IFERROR(INDEX($E$53:$E$78,MATCH(8,O$53:O$78,0)),"") | E30: =IFERROR(INDEX(I$53:I$78,MATCH(8,O$53:O$78,0)),"") | F30: =IF(B30="","",IF(D30<>"主动","不适用",IF(E30>$L$2,"超限","正常"))) | G30: =IF(B30<>"",I$84,"")
A31: 约束口径：仅“主动”基金适用单只20%上限；主题指数、指增、货币、债券及保障基金不纳入该上限。超限基金整行标红。
A33: 2. 组合内部增值 / 生息配比偏离（10-90/30-70） | G33: 数据截止日 | H33: =$B$82 -> 46286
A34: 组合 | B34: 增值目标 | C34: 增值当前 | D34: 偏离度 | E34: 生息目标 | F34: 生息当前 | G34: 偏离度 | H34: 调仓生效日
A35: 10-90 | B35: 0.1 | C35: =SUMIF($C$53:$C$78,"增值",J$53:J$78) -> 0.10492083 | D35: =C35-B35 -> 0.0049208324 | E35: =1-B35 -> 0.9 | F35: =SUMIF($C$53:$C$78,"生息",J$53:J$78) -> 0.89507917 | G35: =F35-E35 -> -0.0049208324 | H35: =J$84 -> 46276
A36: 10-90基石 | B36: 0.1 | C36: =SUMIF($C$53:$C$78,"增值",K$53:K$78) -> 0.10516393 | D36: =C36-B36 -> 0.0051639298 | E36: =1-B36 -> 0.9 | F36: =SUMIF($C$53:$C$78,"生息",K$53:K$78) -> 0.89483607 | G36: =F36-E36 -> -0.0051639298 | H36: =K$84 -> 46276
A37: 30-70 | B37: 0.3 | C37: =SUMIF($C$53:$C$78,"增值",L$53:L$78) -> 0.31165404 | D37: =C37-B37 -> 0.011654037 | E37: =1-B37 -> 0.7 | F37: =SUMIF($C$53:$C$78,"生息",L$53:L$78) -> 0.68834596 | G37: =F37-E37 -> -0.011654037 | H37: =L$84 -> 46276
A38: 生息含债券、货币及保障类基金；默认预警阈值为±2个百分点，可在J2直接修改。偏离度=当前配比−目标配比。
A40: 3. 增值部分内部产业趋势 / 指增当前配比 | D40: 数据截止日 | E40: =$B$82 -> 46286
A41: 组合 | B41: 产业趋势当前权重 | C41: 指增部分当前权重 | D41: 增值部分总权重 | E41: 调仓生效日
A42: 10-90 | B42: =IFERROR(SUMIF($D$53:$D$78,"产业趋势",J$53:J$78)/SUMIF($C$53:$C$78,"增值",J$53:J$78),0) -> 0.50682207 | C42: =IFERROR(SUMIF($D$53:$D$78,"指增",J$53:J$78)/SUMIF($C$53:$C$78,"增值",J$53:J$78),0) -> 0.49317793 | D42: =SUMIF($C$53:$C$78,"增值",J$53:J$78) -> 0.10492083 | E42: =J$84 -> 46276
A43: 10-90基石 | B43: =IFERROR(SUMIF($D$53:$D$78,"产业趋势",K$53:K$78)/SUMIF($C$53:$C$78,"增值",K$53:K$78),0) -> 0.50804359 | C43: =IFERROR(SUMIF($D$53:$D$78,"指增",K$53:K$78)/SUMIF($C$53:$C$78,"增值",K$53:K$78),0) -> 0.49195641 | D43: =SUMIF($C$53:$C$78,"增值",K$53:K$78) -> 0.10516393 | E43: =K$84 -> 46276
...

Sheet vs固收+对比（模拟数据）
E1: =VLOOKUP(E3,实盘组合预估净值!$A:$P,14) -> 0.99372212 | F1: =VLOOKUP(F3,实盘组合预估净值!$A:$P,14) -> 1 | G1: =VLOOKUP(G3,实盘组合预估净值!$A:$P,14) -> 1 | H1: =VLOOKUP(H3,实盘组合预估净值!$A:$P,14) -> 0.97719837
E2: =VLOOKUP(E5,实盘组合预估净值!$A:$P,14) -> 0.99508534 | F2: =VLOOKUP(F5,实盘组合预估净值!$A:$P,14) -> 0.99696347 | G2: =VLOOKUP(G5,实盘组合预估净值!$A:$P,14) -> 0.97390321 | H2: =VLOOKUP(H5,实盘组合预估净值!$A:$P,14) -> 0.99696347
E3: =E5-7 -> 46248 | F3: 46191 | G3: 46191 | H3: 46234
E4: =E5-5 -> 46250 | F4: 46195 | G4: 46195 | H4: 46237
E5: 46255 | F5: =偏离度监控!B2 -> 46286 | G5: 46233 | H5: =F5 -> 46286
C6: 公募固收+规模前十（2026Q2）基金表现
A7: 序号 | B7: 基金代码 | C7: 产品/基金名称 | D7: 26Q2规模（亿元） | E7: 上周 | F7: 上线以来 | G7: 6/22-7/30 | H7: 7.31至今 | I7: 最大回撤（上线以来）
A8: 组合 | C8: 10/90基石投顾组合 | E8: =E$2/E$1-1 -> 0.0013718321 | F8: =F$2/F$1-1 -> -0.0030365332 | G8: =G$2/G$1-1 -> -0.02609679 | H8: =H$2/H$1-1 -> 0.020226287 | I8: ='看板-10-90基石'!$F$7 -> -0.028729069
A9: 1 | B9: 003504.OF | C9: 景顺长城景颐丰利债券 | D9: 712 | E9: =[1]!thsiFinD("ths_adjustment_nvg_ratio_fund",$B9,E$4,E$5,101)/100 -> -0.0037683097 | F9: =[1]!thsiFinD("ths_adjustment_nvg_ratio_fund",$B9,F$4,F$5,101)/100 -> -0.041459854 | G9: =[1]!thsiFinD("ths_adjustment_nvg_ratio_fund",$B9,G$4,G$5,101)/100 -> -0.07340146 | H9: =[1]!thsiFinD("ths_adjustment_nvg_ratio_fund",$B9,H$4,H$5,101)/100 -> 0.024848598 | I9: =-[1]!thsiFinD("ths_max_retrace_rate_all_fund",$B9,F$3,F$5)/100 -> -0.078192169
A10: 2 | B10: 000143.OF | C10: 鹏华双债加利债券 | D10: 584 | E10: =[1]!thsiFinD("ths_adjustment_nvg_ratio_fund",$B10,E$4,E$5,101)/100 -> 0.00049961394 | F10: =[1]!thsiFinD("ths_adjustment_nvg_ratio_fund",$B10,F$4,F$5,101)/100 -> -0.018728742 | G10: =[1]!thsiFinD("ths_adjustment_nvg_ratio_fund",$B10,G$4,G$5,101)/100 -> -0.051945757 | H10: =[1]!thsiFinD("ths_adjustment_nvg_ratio_fund",$B10,H$4,H$5,101)/100 -> 0.027758501 | I10: =-[1]!thsiFinD("ths_max_retrace_rate_all_fund",$B10,F$3,F$5)/100 -> -0.06090571
A11: 3 | B11: 000385.OF | C11: 景顺长城景颐双利债券 | D11: 576 | E11: =[1]!thsiFinD("ths_adjustment_nvg_ratio_fund",$B11,E$4,E$5,101)/100 -> 0.00052714815 | F11: =[1]!thsiFinD("ths_adjustment_nvg_ratio_fund",$B11,F$4,F$5,101)/100 -> -0.0062926062 | G11: =[1]!thsiFinD("ths_adjustment_nvg_ratio_fund",$B11,G$4,G$5,101)/100 -> -0.01363398 | H11: =[1]!thsiFinD("ths_adjustment_nvg_ratio_fund",$B11,H$4,H$5,101)/100 -> 0.0058386412 | I11: =-[1]!thsiFinD("ths_max_retrace_rate_all_fund",$B11,F$3,F$5)/100 -> -0.024530271
A12: 4 | B12: 002065.OF | C12: 景顺长城景盛双息收益债券 | D12: 393 | E12: =[1]!thsiFinD("ths_adjustment_nvg_ratio_fund",$B12,E$4,E$5,101)/100 -> 0.0031128404 | F12: =[1]!thsiFinD("ths_adjustment_nvg_ratio_fund",$B12,F$4,F$5,101)/100 -> 0.022346369 | G12: =[1]!thsiFinD("ths_adjustment_nvg_ratio_fund",$B12,G$4,G$5,101)/100 -> 0.015961692 | H12: =[1]!thsiFinD("ths_adjustment_nvg_ratio_fund",$B12,H$4,H$5,101)/100 -> 0.0039184953 | I12: =-[1]!thsiFinD("ths_max_retrace_rate_all_fund",$B12,F$3,F$5)/100 -> -0.019857029
A13: 5 | B13: 002969.OF | C13: 易方达丰和债券 | D13: 391 | E13: =[1]!thsiFinD("ths_adjustment_nvg_ratio_fund",$B13,E$4,E$5,101)/100 -> -0.003457526 | F13: =[1]!thsiFinD("ths_adjustment_nvg_ratio_fund",$B13,F$4,F$5,101)/100 -> -0.017357256 | G13: =[1]!thsiFinD("ths_adjustment_nvg_ratio_fund",$B13,G$4,G$5,101)/100 -> -0.056454912 | H13: =[1]!thsiFinD("ths_adjustment_nvg_ratio_fund",$B13,H$4,H$5,101)/100 -> 0.032103615 | I13: =-[1]!thsiFinD("ths_max_retrace_rate_all_fund",$B13,F$3,F$5)/100 -> -0.070577399
A14: 6 | B14: 014088.OF | C14: 永赢稳健增强债券 | D14: 365 | E14: =[1]!thsiFinD("ths_adjustment_nvg_ratio_fund",$B14,E$4,E$5,101)/100 -> 0.001478318 | F14: =[1]!thsiFinD("ths_adjustment_nvg_ratio_fund",$B14,F$4,F$5,101)/100 -> -0.028592023 | G14: =[1]!thsiFinD("ths_adjustment_nvg_ratio_fund",$B14,G$4,G$5,101)/100 -> -0.039484222 | H14: =[1]!thsiFinD("ths_adjustment_nvg_ratio_fund",$B14,H$4,H$5,101)/100 -> 0.0059716347 | I14: =-[1]!thsiFinD("ths_max_retrace_rate_all_fund",$B14,F$3,F$5)/100 -> -0.045758396
A15: 7 | B15: 001751.OF | C15: 华商信用增强债券 | D15: 361 | E15: =[1]!thsiFinD("ths_adjustment_nvg_ratio_fund",$B15,E$4,E$5,101)/100 -> -0.010653753 | F15: =[1]!thsiFinD("ths_adjustment_nvg_ratio_fund",$B15,F$4,F$5,101)/100 -> 0 | G15: =[1]!thsiFinD("ths_adjustment_nvg_ratio_fund",$B15,G$4,G$5,101)/100 -> -0.02872444 | H15: =[1]!thsiFinD("ths_adjustment_nvg_ratio_fund",$B15,H$4,H$5,101)/100 -> 0.020874751 | I15: =-[1]!thsiFinD("ths_max_retrace_rate_all_fund",$B15,F$3,F$5)/100 -> -0.052405908
A16: 8 | B16: 014846.OF | C16: 博时恒乐债券 | D16: 359 | E16: =[1]!thsiFinD("ths_adjustment_nvg_ratio_fund",$B16,E$4,E$5,101)/100 -> -0.0009668842 | F16: =[1]!thsiFinD("ths_adjustment_nvg_ratio_fund",$B16,F$4,F$5,101)/100 -> -0.013521037 | G16: =[1]!thsiFinD("ths_adjustment_nvg_ratio_fund",$B16,G$4,G$5,101)/100 -> -0.016463851 | H16: =[1]!thsiFinD("ths_adjustment_nvg_ratio_fund",$B16,H$4,H$5,101)/100 -> 0.0020197124 | I16: =-[1]!thsiFinD("ths_max_retrace_rate_all_fund",$B16,F$3,F$5)/100 -> -0.032053291
A17: 9 | B17: 000171.OF | C17: 易方达裕丰回报债券 | D17: 342 | E17: =[1]!thsiFinD("ths_adjustment_nvg_ratio_fund",$B17,E$4,E$5,101)/100 -> -0.0047732697 | F17: =[1]!thsiFinD("ths_adjustment_nvg_ratio_fund",$B17,F$4,F$5,101)/100 -> -0.029419954 | G17: =[1]!thsiFinD("ths_adjustment_nvg_ratio_fund",$B17,G$4,G$5,101)/100 -> -0.048259861 | H17: =[1]!thsiFinD("ths_adjustment_nvg_ratio_fund",$B17,H$4,H$5,101)/100 -> 0.014354995 | I17: =-[1]!thsiFinD("ths_max_retrace_rate_all_fund",$B17,F$3,F$5)/100 -> -0.06347032
A18: 10 | B18: 202101.OF | C18: 南方宝元债券 | D18: 314 | E18: =[1]!thsiFinD("ths_adjustment_nvg_ratio_fund",$B18,E$4,E$5,101)/100 -> -0.0008965208 | F18: =[1]!thsiFinD("ths_adjustment_nvg_ratio_fund",$B18,F$4,F$5,101)/100 -> -0.0065794006 | G18: =[1]!thsiFinD("ths_adjustment_nvg_ratio_fund",$B18,G$4,G$5,101)/100 -> -0.00072338959 | H18: =[1]!thsiFinD("ths_adjustment_nvg_ratio_fund",$B18,H$4,H$5,101)/100 -> -0.0062370779 | I18: =-[1]!thsiFinD("ths_max_retrace_rate_all_fund",$B18,F$3,F$5)/100 -> -0.026377751
C21: 公募固收+Q2规模增长前十基金表现
A22: =表3[[#Headers],[序号]] -> 序号 | B22: =表3[[#Headers],[基金代码]] -> 基金代码 | C22: =表3[[#Headers],[产品/基金名称]] -> 产品/基金名称 | D22: =表3[[#Headers],[26Q2规模（亿元）]] -> 26Q2规模（亿元） | E22: =表3[[#Headers],[上周]] -> 上周 | F22: =表3[[#Headers],[上线以来]] -> 上线以来 | G22: =表3[[#Headers],[6/22-7/30]] -> 6/22-7/30 | H22: =表3[[#Headers],[7.31至今]] -> 7.31至今 | I22: =表3[[#Headers],[最大回撤（上线以来）]] -> 最大回撤（上线以来）
A23: 组合 | C23: =C8 -> 10/90基石投顾组合 | E23: =E$2/E$1-1 -> 0.0013718321 | F23: =F$2/F$1-1 -> -0.0030365332 | G23: =G$2/G$1-1 -> -0.02609679 | H23: =H$2/H$1-1 -> 0.020226287 | I23: ='看板-10-90基石'!$F$7 -> -0.028729069
A24: 1 | B24: 003504.OF | C24: 景顺长城景颐丰利债券 | D24: 391 | E24: =[1]!thsiFinD("ths_adjustment_nvg_ratio_fund",$B24,E$4,E$5,101)/100 -> -0.0037683097 | F24: =[1]!thsiFinD("ths_adjustment_nvg_ratio_fund",$B24,F$4,F$5,101)/100 -> -0.041459854 | G24: =[1]!thsiFinD("ths_adjustment_nvg_ratio_fund",$B24,G$4,G$5,101)/100 -> -0.07340146 | H24: =[1]!thsiFinD("ths_adjustment_nvg_ratio_fund",$B24,H$4,H$5,101)/100 -> 0.024848598 | I24: =-[1]!thsiFinD("ths_max_retrace_rate_all_fund",$B24,F$3,F$5)/100 -> -0.078192169
A25: 2 | B25: 002969.OF | C25: 易方达丰和债券 | D25: 347 | E25: =[1]!thsiFinD("ths_adjustment_nvg_ratio_fund",$B25,E$4,E$5,101)/100 -> -0.003457526 | F25: =[1]!thsiFinD("ths_adjustment_nvg_ratio_fund",$B25,F$4,F$5,101)/100 -> -0.017357256 | G25: =[1]!thsiFinD("ths_adjustment_nvg_ratio_fund",$B25,G$4,G$5,101)/100 -> -0.056454912 | H25: =[1]!thsiFinD("ths_adjustment_nvg_ratio_fund",$B25,H$4,H$5,101)/100 -> 0.032103615 | I25: =-[1]!thsiFinD("ths_max_retrace_rate_all_fund",$B25,F$3,F$5)/100 -> -0.070577399
A26: 3 | B26: 470010.OF | C26: 汇添富多元收益债券 | D26: 255 | E26: =[1]!thsiFinD("ths_adjustment_nvg_ratio_fund",$B26,E$4,E$5,101)/100 -> -0.0042573006 | F26: =[1]!thsiFinD("ths_adjustment_nvg_ratio_fund",$B26,F$4,F$5,101)/100 -> -0.044208098 | G26: =[1]!thsiFinD("ths_adjustment_nvg_ratio_fund",$B26,G$4,G$5,101)/100 -> -0.053754485 | H26: =[1]!thsiFinD("ths_adjustment_nvg_ratio_fund",$B26,H$4,H$5,101)/100 -> 0.0034304164 | I26: =-[1]!thsiFinD("ths_max_retrace_rate_all_fund",$B26,F$3,F$5)/100 -> -0.066641376
A27: 4 | B27: 000143.OF | C27: 鹏华双债加利债券 | D27: 228 | E27: =[1]!thsiFinD("ths_adjustment_nvg_ratio_fund",$B27,E$4,E$5,101)/100 -> 0.00049961394 | F27: =[1]!thsiFinD("ths_adjustment_nvg_ratio_fund",$B27,F$4,F$5,101)/100 -> -0.018728742 | G27: =[1]!thsiFinD("ths_adjustment_nvg_ratio_fund",$B27,G$4,G$5,101)/100 -> -0.051945757 | H27: =[1]!thsiFinD("ths_adjustment_nvg_ratio_fund",$B27,H$4,H$5,101)/100 -> 0.027758501 | I27: =-[1]!thsiFinD("ths_max_retrace_rate_all_fund",$B27,F$3,F$5)/100 -> -0.06090571
A28: 5 | B28: 000406.OF | C28: 汇添富双利增强债券 | D28: 172 | E28: =[1]!thsiFinD("ths_adjustment_nvg_ratio_fund",$B28,E$4,E$5,101)/100 -> -0.0073800738 | F28: =[1]!thsiFinD("ths_adjustment_nvg_ratio_fund",$B28,F$4,F$5,101)/100 -> -0.017622418 | G28: =[1]!thsiFinD("ths_adjustment_nvg_ratio_fund",$B28,G$4,G$5,101)/100 -> -0.04058934 | H28: =[1]!thsiFinD("ths_adjustment_nvg_ratio_fund",$B28,H$4,H$5,101)/100 -> 0.022168783 | I28: =-[1]!thsiFinD("ths_max_retrace_rate_all_fund",$B28,F$3,F$5)/100 -> -0.050897344
A29: 6 | B29: 000171.OF | C29: 易方达裕丰回报债券 | D29: 146 | E29: =[1]!thsiFinD("ths_adjustment_nvg_ratio_fund",$B29,E$4,E$5,101)/100 -> -0.0047732697 | F29: =[1]!thsiFinD("ths_adjustment_nvg_ratio_fund",$B29,F$4,F$5,101)/100 -> -0.029419954 | G29: =[1]!thsiFinD("ths_adjustment_nvg_ratio_fund",$B29,G$4,G$5,101)/100 -> -0.048259861 | H29: =[1]!thsiFinD("ths_adjustment_nvg_ratio_fund",$B29,H$4,H$5,101)/100 -> 0.014354995 | I29: =-[1]!thsiFinD("ths_max_retrace_rate_all_fund",$B29,F$3,F$5)/100 -> -0.06347032
A30: 7 | B30: 018595.OF | C30: 华商利欣回报债券 | D30: 130 | E30: =[1]!thsiFinD("ths_adjustment_nvg_ratio_fund",$B30,E$4,E$5,101)/100 -> -0.00861259 | F30: =[1]!thsiFinD("ths_adjustment_nvg_ratio_fund",$B30,F$4,F$5,101)/100 -> 0.0095879556 | G30: =[1]!thsiFinD("ths_adjustment_nvg_ratio_fund",$B30,G$4,G$5,101)/100 -> -0.022028526 | H30: =[1]!thsiFinD("ths_adjustment_nvg_ratio_fund",$B30,H$4,H$5,101)/100 -> 0.025680245 | I30: =-[1]!thsiFinD("ths_max_retrace_rate_all_fund",$B30,F$3,F$5)/100 -> -0.04644491
A31: 8 | B31: 001751.OF | C31: 华商信用增强债券 | D31: 123 | E31: =[1]!thsiFinD("ths_adjustment_nvg_ratio_fund",$B31,E$4,E$5,101)/100 -> -0.010653753 | F31: =[1]!thsiFinD("ths_adjustment_nvg_ratio_fund",$B31,F$4,F$5,101)/100 -> 0 | G31: =[1]!thsiFinD("ths_adjustment_nvg_ratio_fund",$B31,G$4,G$5,101)/100 -> -0.02872444 | H31: =[1]!thsiFinD("ths_adjustment_nvg_ratio_fund",$B31,H$4,H$5,101)/100 -> 0.020874751 | I31: =-[1]!thsiFinD("ths_max_retrace_rate_all_fund",$B31,F$3,F$5)/100 -> -0.052405908
A32: 9 | B32: 020218.OF | C32: 万家锦利债券发起式 | D32: 120 | E32: =[1]!thsiFinD("ths_adjustment_nvg_ratio_fund",$B32,E$4,E$5,101)/100 -> -0.0015971755 | F32: =[1]!thsiFinD("ths_adjustment_nvg_ratio_fund",$B32,F$4,F$5,101)/100 -> -0.037181361 | G32: =[1]!thsiFinD("ths_adjustment_nvg_ratio_fund",$B32,G$4,G$5,101)/100 -> -0.047978568 | H32: =[1]!thsiFinD("ths_adjustment_nvg_ratio_fund",$B32,H$4,H$5,101)/100 -> 0.0073042297 | I32: =-[1]!thsiFinD("ths_max_retrace_rate_all_fund",$B32,F$3,F$5)/100 -> -0.057478667
A33: 10 | B33: 014846.OF | C33: 博时恒乐债券 | D33: 114 | E33: =[1]!thsiFinD("ths_adjustment_nvg_ratio_fund",$B33,E$4,E$5,101)/100 -> -0.0009668842 | F33: =[1]!thsiFinD("ths_adjustment_nvg_ratio_fund",$B33,F$4,F$5,101)/100 -> -0.013521037 | G33: =[1]!thsiFinD("ths_adjustment_nvg_ratio_fund",$B33,G$4,G$5,101)/100 -> -0.016463851 | H33: =[1]!thsiFinD("ths_adjustment_nvg_ratio_fund",$B33,H$4,H$5,101)/100 -> 0.0020197124 | I33: =-[1]!thsiFinD("ths_max_retrace_rate_all_fund",$B33,F$3,F$5)/100 -> -0.032053291
C36: 公司公募固收+保有前十基金表现（2026Q2）
A37: =A22 -> 序号 | B37: =B22 -> 基金代码 | C37: =C22 -> 产品/基金名称 | D37: 公司固收加保有前十（万元） | E37: =E22 -> 上周 | F37: =F22 -> 上线以来 | G37: =G22 -> 6/22-7/30 | H37: =H22 -> 7.31至今 | I37: =I22 -> 最大回撤（上线以来）
A38: 组合 | C38: =C8 -> 10/90基石投顾组合 | E38: =E$2/E$1-1 -> 0.0013718321 | F38: =F$2/F$1-1 -> -0.0030365332 | G38: =G$2/G$1-1 -> -0.02609679 | H38: =H$2/H$1-1 -> 0.020226287 | I38: ='看板-10-90基石'!$F$7 -> -0.028729069
A39: 1 | B39: 009355.OF | C39: 宏利泰和稳健养老目标一年持有期混合(FOF) | D39: 5265 | E39: =[1]!thsiFinD("ths_adjustment_nvg_ratio_fund",$B39,E$4,E$5,101)/100 -> -0.00044835012 | F39: =[1]!thsiFinD("ths_adjustment_nvg_ratio_fund",$B39,F$4,F$5,101)/100 -> -0.011155228 | G39: =[1]!thsiFinD("ths_adjustment_nvg_ratio_fund",$B39,G$4,G$5,101)/100 -> -0.018110759 | H39: =[1]!thsiFinD("ths_adjustment_nvg_ratio_fund",$B39,H$4,H$5,101)/100 -> 0.0034386029 | I39: =-[1]!thsiFinD("ths_max_retrace_rate_all_fund",$B39,F$3,F$5)/100 -> -0.018873622
A40: 2 | B40: 024057.OF | C40: 宏利鼎森稳健3个月持有期混合(FOF) | D40: 896 | E40: =[1]!thsiFinD("ths_adjustment_nvg_ratio_fund",$B40,E$4,E$5,101)/100 -> -0.00029460866 | F40: =[1]!thsiFinD("ths_adjustment_nvg_ratio_fund",$B40,F$4,F$5,101)/100 -> -0.0017711306 | G40: =[1]!thsiFinD("ths_adjustment_nvg_ratio_fund",$B40,G$4,G$5,101)/100 -> -0.012397914 | H40: =[1]!thsiFinD("ths_adjustment_nvg_ratio_fund",$B40,H$4,H$5,101)/100 -> 0.0077480878 | I40: =-[1]!thsiFinD("ths_max_retrace_rate_all_fund",$B40,F$3,F$5)/100 -> -0.013283479
A41: 3 | B41: 011168.OF | C41: 嘉实睿享安久双利18个月持有期债券 | D41: 239 | E41: =[1]!thsiFinD("ths_adjustment_nvg_ratio_fund",$B41,E$4,E$5,101)/100 -> 0.00016557662 | F41: =[1]!thsiFinD("ths_adjustment_nvg_ratio_fund",$B41,F$4,F$5,101)/100 -> -0.022243871 | G41: =[1]!thsiFinD("ths_adjustment_nvg_ratio_fund",$B41,G$4,G$5,101)/100 -> -0.026627699 | H41: =[1]!thsiFinD("ths_adjustment_nvg_ratio_fund",$B41,H$4,H$5,101)/100 -> 0.0024970867 | I41: =-[1]!thsiFinD("ths_max_retrace_rate_all_fund",$B41,F$3,F$5)/100 -> -0.04941999
A42: 4 | B42: 002969.OF | C42: 易方达丰和债券 | D42: 225 | E42: =[1]!thsiFinD("ths_adjustment_nvg_ratio_fund",$B42,E$4,E$5,101)/100 -> -0.003457526 | F42: =[1]!thsiFinD("ths_adjustment_nvg_ratio_fund",$B42,F$4,F$5,101)/100 -> -0.017357256 | G42: =[1]!thsiFinD("ths_adjustment_nvg_ratio_fund",$B42,G$4,G$5,101)/100 -> -0.056454912 | H42: =[1]!thsiFinD("ths_adjustment_nvg_ratio_fund",$B42,H$4,H$5,101)/100 -> 0.032103615 | I42: =-[1]!thsiFinD("ths_max_retrace_rate_all_fund",$B42,F$3,F$5)/100 -> -0.070577399
A43: 5 | B43: 014738.OF | C43: 广发恒祥债券 | D43: 205 | E43: =[1]!thsiFinD("ths_adjustment_nvg_ratio_fund",$B43,E$4,E$5,101)/100 -> -0.0033681971 | F43: =[1]!thsiFinD("ths_adjustment_nvg_ratio_fund",$B43,F$4,F$5,101)/100 -> -0.032751655 | G43: =[1]!thsiFinD("ths_adjustment_nvg_ratio_fund",$B43,G$4,G$5,101)/100 -> -0.029313161 | H43: =[1]!thsiFinD("ths_adjustment_nvg_ratio_fund",$B43,H$4,H$5,101)/100 -> -0.0014199503 | I43: =-[1]!thsiFinD("ths_max_retrace_rate_all_fund",$B43,F$3,F$5)/100 -> -0.06586123
A44: 6 | B44: 006307.OF | C44: 嘉实养老目标日期2040五年持有期混合(FOF) | D44: 190 | E44: =[1]!thsiFinD("ths_adjustment_nvg_ratio_fund",$B44,E$4,E$5,101)/100 -> -0.0047773418 | F44: =[1]!thsiFinD("ths_adjustment_nvg_ratio_fund",$B44,F$4,F$5,101)/100 -> -0.05733882 | G44: =[1]!thsiFinD("ths_adjustment_nvg_ratio_fund",$B44,G$4,G$5,101)/100 -> -0.093443073 | H44: =[1]!thsiFinD("ths_adjustment_nvg_ratio_fund",$B44,H$4,H$5,101)/100 -> 0.027757837 | I44: =-[1]!thsiFinD("ths_max_retrace_rate_all_fund",$B44,F$3,F$5)/100 -> -0.11736738
...

Sheet vs固收+对比（恒生实盘数据） 
E1: =VLOOKUP(E3,[2]恒生净值!$A:$C,2) -> 0.99494352 | F1: =VLOOKUP(F3,[2]恒生净值!$A:$C,2) -> 1 | G1: =VLOOKUP(G3,[2]恒生净值!$A:$C,2) -> 1 | H1: =VLOOKUP(H3,[2]恒生净值!$A:$C,2) -> 0.97705802 | K1: =VLOOKUP(K3,[2]恒生净值!$A:$C,2) -> 0.97705802
E2: =VLOOKUP(E5,[2]恒生净值!$A:$C,2) -> 0.99520286 | F2: =VLOOKUP(F5,[2]恒生净值!$A:$C,2) -> 0.99520286 | G2: =VLOOKUP(G5,[2]恒生净值!$A:$C,2) -> 0.97376326 | H2: =VLOOKUP(H5,[2]恒生净值!$A:$C,2) -> 0.99520286 | K2: =VLOOKUP(K5,[2]恒生净值!$A:$C,2) -> 0 | L2: =1-F2 -> 0.00479714
E3: =E5-7 -> 46255 | F3: 46191 | G3: 46191 | H3: 46234 | K3: 46234
E4: =E5-4 -> 46258 | F4: 46195 | G4: 46195 | H4: 46237 | I4: =DATE(YEAR(I5),MONTH(I5)-6,DAY(I5)) -> 46096 | J4: =DATE(YEAR(J5)-1,MONTH(J5),DAY(J5)) -> 45915 | K4: 46237
E5: 46262 | F5: =E5 -> 46262 | G5: 46233 | H5: =F5 -> 46262 | I5: 46280 | J5: =I5 -> 46280 | K5: =I5 -> 46280
A6: 公募固收+规模前十（2026Q2）基金表现
A7: 序号 | B7: 基金代码 | C7: 8/24-8/28 | D7: 26Q2规模（亿元） | E7: 上周 | F7: 6/22以来 | G7: 6/22-7/30 | H7: 7/31以来 | I7: 近六月 | J7: 近一年 | K7: 近一年最大回撤 | L7: 最大回撤（6/22以来）
C8: 10/90基石投顾组合 | E8: =E$2/E$1-1 -> 0.00026065801 | F8: =F$2/F$1-1 -> -0.00479714 | G8: =G$2/G$1-1 -> -0.02623674 | H8: =H$2/H$1-1 -> 0.018570893 | L8: =[2]恒生净值!S25 -> -0.0289
A9: 1 | B9: 003504.OF | C9: 景顺长城景颐丰利债券 | D9: =[1]!thsiFinD("ths_mergesize_fund",$B9,"2026-06-30")/100000000 -> 712.08736 | E9: =[1]!thsiFinD("ths_adjustment_nvg_ratio_fund",$B9,E$4,E$5,101)/100 -> -0.0093343908 | F9: =[1]!thsiFinD("ths_adjustment_nvg_ratio_fund",$B9,F$4,F$5,101)/100 -> -0.05179562 | G9: =[1]!thsiFinD("ths_adjustment_nvg_ratio_fund",$B9,G$4,G$5,101)/100 -> -0.07340146 | H9: =[1]!thsiFinD("ths_adjustment_nvg_ratio_fund",$B9,H$4,H$5,101)/100 -> 0.01379784 | I9: =[1]!thsiFinD("ths_adjustment_nvg_ratio_fund",$B9,I$4,I$5,101)/100 -> 0.067190285 | J9: =[1]!thsiFinD("ths_adjustment_nvg_ratio_fund",$B9,J$4,J$5,101)/100 -> 0.11088973 | K9: =-[1]!thsiFinD("ths_max_retrace_rate_all_fund",$B9,J$4,J$5)/100 -> -0.078192169 | L9: =-[1]!thsiFinD("ths_max_retrace_rate_all_fund",$B9,F$3,F$5)/100 -> -0.078192169
A10: 2 | B10: 000143.OF | C10: 鹏华双债加利债券 | D10: =[1]!thsiFinD("ths_mergesize_fund",$B10,"2026-06-30")/100000000 -> 584.43202 | E10: =[1]!thsiFinD("ths_adjustment_nvg_ratio_fund",$B10,E$4,E$5,101)/100 -> -0.0030415834 | F10: =[1]!thsiFinD("ths_adjustment_nvg_ratio_fund",$B10,F$4,F$5,101)/100 -> -0.029948319 | G10: =[1]!thsiFinD("ths_adjustment_nvg_ratio_fund",$B10,G$4,G$5,101)/100 -> -0.051945757 | H10: =[1]!thsiFinD("ths_adjustment_nvg_ratio_fund",$B10,H$4,H$5,101)/100 -> 0.016007402 | I10: =[1]!thsiFinD("ths_adjustment_nvg_ratio_fund",$B10,I$4,I$5,101)/100 -> 0.026313321 | J10: =[1]!thsiFinD("ths_adjustment_nvg_ratio_fund",$B10,J$4,J$5,101)/100 -> 0.07671489 | K10: =-[1]!thsiFinD("ths_max_retrace_rate_all_fund",$B10,J$4,J$5)/100 -> -0.06090571 | L10: =-[1]!thsiFinD("ths_max_retrace_rate_all_fund",$B10,F$3,F$5)/100 -> -0.06090571
A11: 3 | B11: 000385.OF | C11: 景顺长城景颐双利债券 | D11: =[1]!thsiFinD("ths_mergesize_fund",$B11,"2026-06-30")/100000000 -> 575.96586 | E11: =[1]!thsiFinD("ths_adjustment_nvg_ratio_fund",$B11,E$4,E$5,101)/100 -> 0 | F11: =[1]!thsiFinD("ths_adjustment_nvg_ratio_fund",$B11,F$4,F$5,101)/100 -> -0.0047194546 | G11: =[1]!thsiFinD("ths_adjustment_nvg_ratio_fund",$B11,G$4,G$5,101)/100 -> -0.01363398 | H11: =[1]!thsiFinD("ths_adjustment_nvg_ratio_fund",$B11,H$4,H$5,101)/100 -> 0.0074309979 | I11: =[1]!thsiFinD("ths_adjustment_nvg_ratio_fund",$B11,I$4,I$5,101)/100 -> -0.0021197668 | J11: =[1]!thsiFinD("ths_adjustment_nvg_ratio_fund",$B11,J$4,J$5,101)/100 -> 0.03632361 | K11: =-[1]!thsiFinD("ths_max_retrace_rate_all_fund",$B11,J$4,J$5)/100 -> -0.024530271 | L11: =-[1]!thsiFinD("ths_max_retrace_rate_all_fund",$B11,F$3,F$5)/100 -> -0.024530271
A12: 4 | B12: 002065.OF | C12: 景顺长城景盛双息收益债券 | D12: =[1]!thsiFinD("ths_mergesize_fund",$B12,"2026-06-30")/100000000 -> 393.16065 | E12: =[1]!thsiFinD("ths_adjustment_nvg_ratio_fund",$B12,E$4,E$5,101)/100 -> 0.0031031808 | F12: =[1]!thsiFinD("ths_adjustment_nvg_ratio_fund",$B12,F$4,F$5,101)/100 -> 0.031923384 | G12: =[1]!thsiFinD("ths_adjustment_nvg_ratio_fund",$B12,G$4,G$5,101)/100 -> 0.015961692 | H12: =[1]!thsiFinD("ths_adjustment_nvg_ratio_fund",$B12,H$4,H$5,101)/100 -> 0.013322884 | I12: =[1]!thsiFinD("ths_adjustment_nvg_ratio_fund",$B12,I$4,I$5,101)/100 -> 0.0031372549 | J12: =[1]!thsiFinD("ths_adjustment_nvg_ratio_fund",$B12,J$4,J$5,101)/100 -> 0.055280528 | K12: =-[1]!thsiFinD("ths_max_retrace_rate_all_fund",$B12,J$4,J$5)/100 -> -0.039688716 | L12: =-[1]!thsiFinD("ths_max_retrace_rate_all_fund",$B12,F$3,F$5)/100 -> -0.019857029
A13: 5 | B13: 002969.OF | C13: 易方达丰和债券 | D13: =[1]!thsiFinD("ths_mergesize_fund",$B13,"2026-06-30")/100000000 -> 390.92894 | E13: =[1]!thsiFinD("ths_adjustment_nvg_ratio_fund",$B13,E$4,E$5,101)/100 -> -0.0056230185 | F13: =[1]!thsiFinD("ths_adjustment_nvg_ratio_fund",$B13,F$4,F$5,101)/100 -> -0.028519666 | G13: =[1]!thsiFinD("ths_adjustment_nvg_ratio_fund",$B13,G$4,G$5,101)/100 -> -0.056454912 | H13: =[1]!thsiFinD("ths_adjustment_nvg_ratio_fund",$B13,H$4,H$5,101)/100 -> 0.020379351 | I13: =[1]!thsiFinD("ths_adjustment_nvg_ratio_fund",$B13,I$4,I$5,101)/100 -> 0.09340515 | J13: =[1]!thsiFinD("ths_adjustment_nvg_ratio_fund",$B13,J$4,J$5,101)/100 -> 0.13207291 | K13: =-[1]!thsiFinD("ths_max_retrace_rate_all_fund",$B13,J$4,J$5)/100 -> -0.070577399 | L13: =-[1]!thsiFinD("ths_max_retrace_rate_all_fund",$B13,F$3,F$5)/100 -> -0.070577399
A14: 6 | B14: 014088.OF | C14: 永赢稳健增强债券 | D14: =[1]!thsiFinD("ths_mergesize_fund",$B14,"2026-06-30")/100000000 -> 364.61857 | E14: =[1]!thsiFinD("ths_adjustment_nvg_ratio_fund",$B14,E$4,E$5,101)/100 -> -0.0031162867 | F14: =[1]!thsiFinD("ths_adjustment_nvg_ratio_fund",$B14,F$4,F$5,101)/100 -> -0.026429601 | G14: =[1]!thsiFinD("ths_adjustment_nvg_ratio_fund",$B14,G$4,G$5,101)/100 -> -0.039484222 | H14: =[1]!thsiFinD("ths_adjustment_nvg_ratio_fund",$B14,H$4,H$5,101)/100 -> 0.0082109978 | I14: =[1]!thsiFinD("ths_adjustment_nvg_ratio_fund",$B14,I$4,I$5,101)/100 -> 0.0029176392 | J14: =[1]!thsiFinD("ths_adjustment_nvg_ratio_fund",$B14,J$4,J$5,101)/100 -> 0.034124119 | K14: =-[1]!thsiFinD("ths_max_retrace_rate_all_fund",$B14,J$4,J$5)/100 -> -0.045758396 | L14: =-[1]!thsiFinD("ths_max_retrace_rate_all_fund",$B14,F$3,F$5)/100 -> -0.045758396
A15: 7 | B15: 001751.OF | C15: 华商信用增强债券 | D15: =[1]!thsiFinD("ths_mergesize_fund",$B15,"2026-06-30")/100000000 -> 360.5434 | E15: =[1]!thsiFinD("ths_adjustment_nvg_ratio_fund",$B15,E$4,E$5,101)/100 -> 0.001957905 | F15: =[1]!thsiFinD("ths_adjustment_nvg_ratio_fund",$B15,F$4,F$5,101)/100 -> -0.0034079844 | G15: =[1]!thsiFinD("ths_adjustment_nvg_ratio_fund",$B15,G$4,G$5,101)/100 -> -0.02872444 | H15: =[1]!thsiFinD("ths_adjustment_nvg_ratio_fund",$B15,H$4,H$5,101)/100 -> 0.017395626 | I15: =[1]!thsiFinD("ths_adjustment_nvg_ratio_fund",$B15,I$4,I$5,101)/100 -> 0.03749358 | J15: =[1]!thsiFinD("ths_adjustment_nvg_ratio_fund",$B15,J$4,J$5,101)/100 -> 0.12849162 | K15: =-[1]!thsiFinD("ths_max_retrace_rate_all_fund",$B15,J$4,J$5)/100 -> -0.052405908 | L15: =-[1]!thsiFinD("ths_max_retrace_rate_all_fund",$B15,F$3,F$5)/100 -> -0.052405908
A16: 8 | B16: 014846.OF | C16: 博时恒乐债券 | D16: =[1]!thsiFinD("ths_mergesize_fund",$B16,"2026-06-30")/100000000 -> 359.11302 | E16: =[1]!thsiFinD("ths_adjustment_nvg_ratio_fund",$B16,E$4,E$5,101)/100 -> -0.00088716837 | F16: =[1]!thsiFinD("ths_adjustment_nvg_ratio_fund",$B16,F$4,F$5,101)/100 -> -0.01471407 | G16: =[1]!thsiFinD("ths_adjustment_nvg_ratio_fund",$B16,G$4,G$5,101)/100 -> -0.016463851 | H16: =[1]!thsiFinD("ths_adjustment_nvg_ratio_fund",$B16,H$4,H$5,101)/100 -> 0.00080788491 | I16: =[1]!thsiFinD("ths_adjustment_nvg_ratio_fund",$B16,I$4,I$5,101)/100 -> 0.01312336 | J16: =[1]!thsiFinD("ths_adjustment_nvg_ratio_fund",$B16,J$4,J$5,101)/100 -> 0.032241891 | K16: =-[1]!thsiFinD("ths_max_retrace_rate_all_fund",$B16,J$4,J$5)/100 -> -0.032053291 | L16: =-[1]!thsiFinD("ths_max_retrace_rate_all_fund",$B16,F$3,F$5)/100 -> -0.030877743
A17: 9 | B17: 000171.OF | C17: 易方达裕丰回报债券 | D17: =[1]!thsiFinD("ths_mergesize_fund",$B17,"2026-06-30")/100000000 -> 341.58069 | E17: =[1]!thsiFinD("ths_adjustment_nvg_ratio_fund",$B17,E$4,E$5,101)/100 -> -0.006235012 | F17: =[1]!thsiFinD("ths_adjustment_nvg_ratio_fund",$B17,F$4,F$5,101)/100 -> -0.038515081 | G17: =[1]!thsiFinD("ths_adjustment_nvg_ratio_fund",$B17,G$4,G$5,101)/100 -> -0.048259861 | H17: =[1]!thsiFinD("ths_adjustment_nvg_ratio_fund",$B17,H$4,H$5,101)/100 -> 0.0048496605 | I17: =[1]!thsiFinD("ths_adjustment_nvg_ratio_fund",$B17,I$4,I$5,101)/100 -> 0.057749361 | J17: =[1]!thsiFinD("ths_adjustment_nvg_ratio_fund",$B17,J$4,J$5,101)/100 -> 0.084942287 | K17: =-[1]!thsiFinD("ths_max_retrace_rate_all_fund",$B17,J$4,J$5)/100 -> -0.06347032 | L17: =-[1]!thsiFinD("ths_max_retrace_rate_all_fund",$B17,F$3,F$5)/100 -> -0.06347032
A18: 10 | B18: 202101.OF | C18: 南方宝元债券 | D18: =[1]!thsiFinD("ths_mergesize_fund",$B18,"2026-06-30")/100000000 -> 313.59883 | E18: =[1]!thsiFinD("ths_adjustment_nvg_ratio_fund",$B18,E$4,E$5,101)/100 -> 0.0028990509 | F18: =[1]!thsiFinD("ths_adjustment_nvg_ratio_fund",$B18,F$4,F$5,101)/100 -> 0.00099896658 | G18: =[1]!thsiFinD("ths_adjustment_nvg_ratio_fund",$B18,G$4,G$5,101)/100 -> -0.00072338959 | H18: =[1]!thsiFinD("ths_adjustment_nvg_ratio_fund",$B18,H$4,H$5,101)/100 -> 0.0013439008 | I18: =[1]!thsiFinD("ths_adjustment_nvg_ratio_fund",$B18,I$4,I$5,101)/100 -> -0.013849371 | J18: =[1]!thsiFinD("ths_adjustment_nvg_ratio_fund",$B18,J$4,J$5,101)/100 -> 0.056106202 | K18: =-[1]!thsiFinD("ths_max_retrace_rate_all_fund",$B18,J$4,J$5)/100 -> -0.0332527 | L18: =-[1]!thsiFinD("ths_max_retrace_rate_all_fund",$B18,F$3,F$5)/100 -> -0.026377751
C19: 公募固收+Q2规模增长前十基金表现
A20: =表3_23[[#Headers],[序号]] -> 序号 | B20: =表3_23[[#Headers],[基金代码]] -> 基金代码 | C20: =表3_23[[#Headers],[8/24-8/28]] -> 8/24-8/28 | D20: 26Q2增长（亿元） | E20: =表3_23[[#Headers],[上周]] -> 上周 | F20: =表3_23[[#Headers],[6/22以来]] -> 6/22以来 | G20: =表3_23[[#Headers],[6/22-7/30]] -> 6/22-7/30 | H20: =表3_23[[#Headers],[7/31以来]] -> 7/31以来 | I20: 近六月 | J20: 近一年 | K20: 近一年最大回撤 | L20: =表3_23[[#Headers],[最大回撤（6/22以来）]] -> 最大回撤（6/22以来）
A21: 组合 | C21: =C8 -> 10/90基石投顾组合 | E21: =E$2/E$1-1 -> 0.00026065801 | F21: =F$2/F$1-1 -> -0.00479714 | G21: =G$2/G$1-1 -> -0.02623674 | H21: =H$2/H$1-1 -> 0.018570893 | L21: =L8 -> -0.0289
A22: 1 | B22: 003504.OF | C22: 景顺长城景颐丰利债券 | D22: =[1]!thsiFinD("ths_mergesize_fund",$B22,"2026-06-30")/100000000-[1]!thsiFinD("ths_mergesize_fund",$B22,"2026-03-31")/100000000 -> 390.96864 | E22: =[1]!thsiFinD("ths_adjustment_nvg_ratio_fund",$B22,E$4,E$5,101)/100 -> -0.0093343908 | F22: =[1]!thsiFinD("ths_adjustment_nvg_ratio_fund",$B22,F$4,F$5,101)/100 -> -0.05179562 | G22: =[1]!thsiFinD("ths_adjustment_nvg_ratio_fund",$B22,G$4,G$5,101)/100 -> -0.07340146 | H22: =[1]!thsiFinD("ths_adjustment_nvg_ratio_fund",$B22,H$4,H$5,101)/100 -> 0.01379784 | I22: =[1]!thsiFinD("ths_adjustment_nvg_ratio_fund",$B22,I$4,I$5,101)/100 -> 0.067190285 | J22: =[1]!thsiFinD("ths_adjustment_nvg_ratio_fund",$B22,J$4,J$5,101)/100 -> 0.11088973 | K22: =-[1]!thsiFinD("ths_max_retrace_rate_all_fund",$B22,J$4,J$5)/100 -> -0.078192169 | L22: =-[1]!thsiFinD("ths_max_retrace_rate_all_fund",$B22,F$3,F$5)/100 -> -0.078192169
A23: 2 | B23: 002969.OF | C23: 易方达丰和债券 | D23: =[1]!thsiFinD("ths_mergesize_fund",$B23,"2026-06-30")/100000000-[1]!thsiFinD("ths_mergesize_fund",$B23,"2026-03-31")/100000000 -> 347.40494 | E23: =[1]!thsiFinD("ths_adjustment_nvg_ratio_fund",$B23,E$4,E$5,101)/100 -> -0.0056230185 | F23: =[1]!thsiFinD("ths_adjustment_nvg_ratio_fund",$B23,F$4,F$5,101)/100 -> -0.028519666 | G23: =[1]!thsiFinD("ths_adjustment_nvg_ratio_fund",$B23,G$4,G$5,101)/100 -> -0.056454912 | H23: =[1]!thsiFinD("ths_adjustment_nvg_ratio_fund",$B23,H$4,H$5,101)/100 -> 0.020379351 | I23: =[1]!thsiFinD("ths_adjustment_nvg_ratio_fund",$B23,I$4,I$5,101)/100 -> 0.09340515 | J23: =[1]!thsiFinD("ths_adjustment_nvg_ratio_fund",$B23,J$4,J$5,101)/100 -> 0.13207291 | K23: =-[1]!thsiFinD("ths_max_retrace_rate_all_fund",$B23,J$4,J$5)/100 -> -0.070577399 | L23: =-[1]!thsiFinD("ths_max_retrace_rate_all_fund",$B23,F$3,F$5)/100 -> -0.070577399
A24: 3 | B24: 470010.OF | C24: 汇添富多元收益债券 | D24: =[1]!thsiFinD("ths_mergesize_fund",$B24,"2026-06-30")/100000000-[1]!thsiFinD("ths_mergesize_fund",$B24,"2026-03-31")/100000000 -> 254.64495 | E24: =[1]!thsiFinD("ths_adjustment_nvg_ratio_fund",$B24,E$4,E$5,101)/100 -> -0.0042755027 | F24: =[1]!thsiFinD("ths_adjustment_nvg_ratio_fund",$B24,F$4,F$5,101)/100 -> -0.045041005 | G24: =[1]!thsiFinD("ths_adjustment_nvg_ratio_fund",$B24,G$4,G$5,101)/100 -> -0.053754485 | H24: =[1]!thsiFinD("ths_adjustment_nvg_ratio_fund",$B24,H$4,H$5,101)/100 -> 0.0025559965 | I24: =[1]!thsiFinD("ths_adjustment_nvg_ratio_fund",$B24,I$4,I$5,101)/100 -> 0.088491011 | J24: =[1]!thsiFinD("ths_adjustment_nvg_ratio_fund",$B24,J$4,J$5,101)/100 -> 0.12081576 | K24: =-[1]!thsiFinD("ths_max_retrace_rate_all_fund",$B24,J$4,J$5)/100 -> -0.066641376 | L24: =-[1]!thsiFinD("ths_max_retrace_rate_all_fund",$B24,F$3,F$5)/100 -> -0.066198786
A25: 4 | B25: 000143.OF | C25: 鹏华双债加利债券 | D25: =[1]!thsiFinD("ths_mergesize_fund",$B25,"2026-06-30")/100000000-[1]!thsiFinD("ths_mergesize_fund",$B25,"2026-03-31")/100000000 -> 227.51174 | E25: =[1]!thsiFinD("ths_adjustment_nvg_ratio_fund",$B25,E$4,E$5,101)/100 -> -0.0030415834 | F25: =[1]!thsiFinD("ths_adjustment_nvg_ratio_fund",$B25,F$4,F$5,101)/100 -> -0.029948319 | G25: =[1]!thsiFinD("ths_adjustment_nvg_ratio_fund",$B25,G$4,G$5,101)/100 -> -0.051945757 | H25: =[1]!thsiFinD("ths_adjustment_nvg_ratio_fund",$B25,H$4,H$5,101)/100 -> 0.016007402 | I25: =[1]!thsiFinD("ths_adjustment_nvg_ratio_fund",$B25,I$4,I$5,101)/100 -> 0.026313321 | J25: =[1]!thsiFinD("ths_adjustment_nvg_ratio_fund",$B25,J$4,J$5,101)/100 -> 0.07671489 | K25: =-[1]!thsiFinD("ths_max_retrace_rate_all_fund",$B25,J$4,J$5)/100 -> -0.06090571 | L25: =-[1]!thsiFinD("ths_max_retrace_rate_all_fund",$B25,F$3,F$5)/100 -> -0.06090571
A26: 5 | B26: 000406.OF | C26: 汇添富双利增强债券 | D26: =[1]!thsiFinD("ths_mergesize_fund",$B26,"2026-06-30")/100000000-[1]!thsiFinD("ths_mergesize_fund",$B26,"2026-03-31")/100000000 -> 171.69679 | E26: =[1]!thsiFinD("ths_adjustment_nvg_ratio_fund",$B26,E$4,E$5,101)/100 -> 0.0019330855 | F26: =[1]!thsiFinD("ths_adjustment_nvg_ratio_fund",$B26,F$4,F$5,101)/100 -> -0.026722519 | G26: =[1]!thsiFinD("ths_adjustment_nvg_ratio_fund",$B26,G$4,G$5,101)/100 -> -0.04058934 | H26: =[1]!thsiFinD("ths_adjustment_nvg_ratio_fund",$B26,H$4,H$5,101)/100 -> 0.012700083 | I26: =[1]!thsiFinD("ths_adjustment_nvg_ratio_fund",$B26,I$4,I$5,101)/100 -> 0.065844597 | J26: =[1]!thsiFinD("ths_adjustment_nvg_ratio_fund",$B26,J$4,J$5,101)/100 -> 0.11557872 | K26: =-[1]!thsiFinD("ths_max_retrace_rate_all_fund",$B26,J$4,J$5)/100 -> -0.050897344 | L26: =-[1]!thsiFinD("ths_max_retrace_rate_all_fund",$B26,F$3,F$5)/100 -> -0.050897344
A27: 6 | B27: 000171.OF | C27: 易方达裕丰回报债券 | D27: =[1]!thsiFinD("ths_mergesize_fund",$B27,"2026-06-30")/100000000-[1]!thsiFinD("ths_mergesize_fund",$B27,"2026-03-31")/100000000 -> 146.24505 | E27: =[1]!thsiFinD("ths_adjustment_nvg_ratio_fund",$B27,E$4,E$5,101)/100 -> -0.006235012 | F27: =[1]!thsiFinD("ths_adjustment_nvg_ratio_fund",$B27,F$4,F$5,101)/100 -> -0.038515081 | G27: =[1]!thsiFinD("ths_adjustment_nvg_ratio_fund",$B27,G$4,G$5,101)/100 -> -0.048259861 | H27: =[1]!thsiFinD("ths_adjustment_nvg_ratio_fund",$B27,H$4,H$5,101)/100 -> 0.0048496605 | I27: =[1]!thsiFinD("ths_adjustment_nvg_ratio_fund",$B27,I$4,I$5,101)/100 -> 0.057749361 | J27: =[1]!thsiFinD("ths_adjustment_nvg_ratio_fund",$B27,J$4,J$5,101)/100 -> 0.084942287 | K27: =-[1]!thsiFinD("ths_max_retrace_rate_all_fund",$B27,J$4,J$5)/100 -> -0.06347032 | L27: =-[1]!thsiFinD("ths_max_retrace_rate_all_fund",$B27,F$3,F$5)/100 -> -0.06347032
A28: 7 | B28: 018595.OF | C28: 华商利欣回报债券 | D28: =[1]!thsiFinD("ths_mergesize_fund",$B28,"2026-06-30")/100000000-[1]!thsiFinD("ths_mergesize_fund",$B28,"2026-03-31")/100000000 -> 129.58399 | E28: =[1]!thsiFinD("ths_adjustment_nvg_ratio_fund",$B28,E$4,E$5,101)/100 -> -0.00039488233 | F28: =[1]!thsiFinD("ths_adjustment_nvg_ratio_fund",$B28,F$4,F$5,101)/100 -> 0.0029318542 | G28: =[1]!thsiFinD("ths_adjustment_nvg_ratio_fund",$B28,G$4,G$5,101)/100 -> -0.022028526 | H28: =[1]!thsiFinD("ths_adjustment_nvg_ratio_fund",$B28,H$4,H$5,101)/100 -> 0.018918049 | I28: =[1]!thsiFinD("ths_adjustment_nvg_ratio_fund",$B28,I$4,I$5,101)/100 -> 0.046082183 | J28: =[1]!thsiFinD("ths_adjustment_nvg_ratio_fund",$B28,J$4,J$5,101)/100 -> 0.10879915 | K28: =-[1]!thsiFinD("ths_max_retrace_rate_all_fund",$B28,J$4,J$5)/100 -> -0.04644491 | L28: =-[1]!thsiFinD("ths_max_retrace_rate_all_fund",$B28,F$3,F$5)/100 -> -0.04644491
A29: 8 | B29: 001751.OF | C29: 华商信用增强债券 | D29: =[1]!thsiFinD("ths_mergesize_fund",$B29,"2026-06-30")/100000000-[1]!thsiFinD("ths_mergesize_fund",$B29,"2026-03-31")/100000000 -> 123.13431 | E29: =[1]!thsiFinD("ths_adjustment_nvg_ratio_fund",$B29,E$4,E$5,101)/100 -> 0.001957905 | F29: =[1]!thsiFinD("ths_adjustment_nvg_ratio_fund",$B29,F$4,F$5,101)/100 -> -0.0034079844 | G29: =[1]!thsiFinD("ths_adjustment_nvg_ratio_fund",$B29,G$4,G$5,101)/100 -> -0.02872444 | H29: =[1]!thsiFinD("ths_adjustment_nvg_ratio_fund",$B29,H$4,H$5,101)/100 -> 0.017395626 | I29: =[1]!thsiFinD("ths_adjustment_nvg_ratio_fund",$B29,I$4,I$5,101)/100 -> 0.03749358 | J29: =[1]!thsiFinD("ths_adjustment_nvg_ratio_fund",$B29,J$4,J$5,101)/100 -> 0.12849162 | K29: =-[1]!thsiFinD("ths_max_retrace_rate_all_fund",$B29,J$4,J$5)/100 -> -0.052405908 | L29: =-[1]!thsiFinD("ths_max_retrace_rate_all_fund",$B29,F$3,F$5)/100 -> -0.052405908
A30: 9 | B30: 020218.OF | C30: 万家锦利债券发起式 | D30: =[1]!thsiFinD("ths_mergesize_fund",$B30,"2026-06-30")/100000000-[1]!thsiFinD("ths_mergesize_fund",$B30,"2026-03-31")/100000000 -> 120.11025 | E30: =[1]!thsiFinD("ths_adjustment_nvg_ratio_fund",$B30,E$4,E$5,101)/100 -> -0.00075776711 | F30: =[1]!thsiFinD("ths_adjustment_nvg_ratio_fund",$B30,F$4,F$5,101)/100 -> -0.036531905 | G30: =[1]!thsiFinD("ths_adjustment_nvg_ratio_fund",$B30,G$4,G$5,101)/100 -> -0.047978568 | H30: =[1]!thsiFinD("ths_adjustment_nvg_ratio_fund",$B30,H$4,H$5,101)/100 -> 0.0079836929 | I30: =[1]!thsiFinD("ths_adjustment_nvg_ratio_fund",$B30,I$4,I$5,101)/100 -> 0.021341199 | J30: =[1]!thsiFinD("ths_adjustment_nvg_ratio_fund",$B30,J$4,J$5,101)/100 -> 0.061108607 | K30: =-[1]!thsiFinD("ths_max_retrace_rate_all_fund",$B30,J$4,J$5)/100 -> -0.057478667 | L30: =-[1]!thsiFinD("ths_max_retrace_rate_all_fund",$B30,F$3,F$5)/100 -> -0.057478667
A31: 10 | B31: 014846.OF | C31: 博时恒乐债券 | D31: =[1]!thsiFinD("ths_mergesize_fund",$B31,"2026-06-30")/100000000-[1]!thsiFinD("ths_mergesize_fund",$B31,"2026-03-31")/100000000 -> 113.87928 | E31: =[1]!thsiFinD("ths_adjustment_nvg_ratio_fund",$B31,E$4,E$5,101)/100 -> -0.00088716837 | F31: =[1]!thsiFinD("ths_adjustment_nvg_ratio_fund",$B31,F$4,F$5,101)/100 -> -0.01471407 | G31: =[1]!thsiFinD("ths_adjustment_nvg_ratio_fund",$B31,G$4,G$5,101)/100 -> -0.016463851 | H31: =[1]!thsiFinD("ths_adjustment_nvg_ratio_fund",$B31,H$4,H$5,101)/100 -> 0.00080788491 | I31: =[1]!thsiFinD("ths_adjustment_nvg_ratio_fund",$B31,I$4,I$5,101)/100 -> 0.01312336 | J31: =[1]!thsiFinD("ths_adjustment_nvg_ratio_fund",$B31,J$4,J$5,101)/100 -> 0.032241891 | K31: =-[1]!thsiFinD("ths_max_retrace_rate_all_fund",$B31,J$4,J$5)/100 -> -0.032053291 | L31: =-[1]!thsiFinD("ths_max_retrace_rate_all_fund",$B31,F$3,F$5)/100 -> -0.030877743
C32: 数据源：同花顺 iFinD
C35: 公司公募固收+保有前十基金表现（2026Q2）
A36: =A20 -> 序号 | B36: =B20 -> 基金代码 | C36: =C20 -> 8/24-8/28 | D36: 公司固收加保有前十（万元） | E36: =E20 -> 上周 | F36: =F20 -> 6/22以来 | G36: =G20 -> 6/22-7/30 | H36: =H20 -> 7/31以来 | L36: =L20 -> 最大回撤（6/22以来）
A37: 组合 | C37: =C8 -> 10/90基石投顾组合 | E37: =E$2/E$1-1 -> 0.00026065801 | F37: =F$2/F$1-1 -> -0.00479714 | G37: =G$2/G$1-1 -> -0.02623674 | H37: =H$2/H$1-1 -> 0.018570893 | L37: =L8 -> -0.0289
A38: 1 | B38: 009355.OF | C38: 宏利泰和稳健养老目标一年持有期混合(FOF) | D38: 5265 | E38: =[1]!thsiFinD("ths_adjustment_nvg_ratio_fund",$B38,E$4,E$5,101)/100 -> 0.00026913069 | F38: =[1]!thsiFinD("ths_adjustment_nvg_ratio_fund",$B38,F$4,F$5,101)/100 -> -0.0057156451 | G38: =[1]!thsiFinD("ths_adjustment_nvg_ratio_fund",$B38,G$4,G$5,101)/100 -> -0.018110759 | H38: =[1]!thsiFinD("ths_adjustment_nvg_ratio_fund",$B38,H$4,H$5,101)/100 -> 0.0089584653 | L38: =-[1]!thsiFinD("ths_max_retrace_rate_all_fund",$B38,F$3,F$5)/100 -> -0.018873622
A39: 2 | B39: 024057.OF | C39: 宏利鼎森稳健3个月持有期混合(FOF) | D39: 896 | E39: =[1]!thsiFinD("ths_adjustment_nvg_ratio_fund",$B39,E$4,E$5,101)/100 -> 0.00058939096 | F39: =[1]!thsiFinD("ths_adjustment_nvg_ratio_fund",$B39,F$4,F$5,101)/100 -> 0.0022631113 | G39: =[1]!thsiFinD("ths_adjustment_nvg_ratio_fund",$B39,G$4,G$5,101)/100 -> -0.012397914 | H39: =[1]!thsiFinD("ths_adjustment_nvg_ratio_fund",$B39,H$4,H$5,101)/100 -> 0.011820801 | L39: =-[1]!thsiFinD("ths_max_retrace_rate_all_fund",$B39,F$3,F$5)/100 -> -0.013283479
A40: 3 | B40: 011168.OF | C40: 嘉实睿享安久双利18个月持有期债券 | D40: 239 | E40: =[1]!thsiFinD("ths_adjustment_nvg_ratio_fund",$B40,E$4,E$5,101)/100 -> -0.00099329526 | F40: =[1]!thsiFinD("ths_adjustment_nvg_ratio_fund",$B40,F$4,F$5,101)/100 -> -0.020214321 | G40: =[1]!thsiFinD("ths_adjustment_nvg_ratio_fund",$B40,G$4,G$5,101)/100 -> -0.026627699 | H40: =[1]!thsiFinD("ths_adjustment_nvg_ratio_fund",$B40,H$4,H$5,101)/100 -> 0.0045779923 | L40: =-[1]!thsiFinD("ths_max_retrace_rate_all_fund",$B40,F$3,F$5)/100 -> -0.04941999
A41: 4 | B41: 002969.OF | C41: 易方达丰和债券 | D41: 225 | E41: =[1]!thsiFinD("ths_adjustment_nvg_ratio_fund",$B41,E$4,E$5,101)/100 -> -0.0056230185 | F41: =[1]!thsiFinD("ths_adjustment_nvg_ratio_fund",$B41,F$4,F$5,101)/100 -> -0.028519666 | G41: =[1]!thsiFinD("ths_adjustment_nvg_ratio_fund",$B41,G$4,G$5,101)/100 -> -0.056454912 | H41: =[1]!thsiFinD("ths_adjustment_nvg_ratio_fund",$B41,H$4,H$5,101)/100 -> 0.020379351 | L41: =-[1]!thsiFinD("ths_max_retrace_rate_all_fund",$B41,F$3,F$5)/100 -> -0.070577399
A42: 5 | B42: 014738.OF | C42: 广发恒祥债券 | D42: 205 | E42: =[1]!thsiFinD("ths_adjustment_nvg_ratio_fund",$B42,E$4,E$5,101)/100 -> -0.0037353255 | F42: =[1]!thsiFinD("ths_adjustment_nvg_ratio_fund",$B42,F$4,F$5,101)/100 -> -0.037049772 | G42: =[1]!thsiFinD("ths_adjustment_nvg_ratio_fund",$B42,G$4,G$5,101)/100 -> -0.029313161 | H42: =[1]!thsiFinD("ths_adjustment_nvg_ratio_fund",$B42,H$4,H$5,101)/100 -> -0.005857295 | L42: =-[1]!thsiFinD("ths_max_retrace_rate_all_fund",$B42,F$3,F$5)/100 -> -0.060827251
...

Sheet 恒生净值
A1: =[1]!HX_AutoDate(1,"2026-06-18",偏离度监控!B82,-1,-1,0,1,0,0,0,"SSE",67,0) -> 日期 | B1: 1090基石 | C1: 1090
A2: 46191 | B2: 1
A3: 46195 | B3: 1.0008957
A4: 46196 | B4: 0.99782281
A5: 46197 | B5: 0.9997708 | C5: 1.00000000 | G5: 粘系统最新净值序列与绩效表
A6: 46198 | B6: 1.0012783 | C6: 1.00141431
A7: 46199 | B7: 0.99893009 | C7: 0.99948240
A8: 46202 | B8: 1.0005215 | C8: 1.00138192
A9: 46203 | B9: 1.0027107 | C9: 1.00327268
A10: 46204 | B10: 0.99998488 | C10: 1.00086493
A11: 46205 | B11: 0.99402933 | C11: 0.99528176
A12: 46206 | B12: 0.99491237 | C12: 0.99645158
A13: 46209 | B13: 0.99396984 | C13: 0.99563225
A14: 46210 | B14: 0.99336489 | C14: 0.99480363
A15: 46211 | B15: 0.99351509 | C15: 0.99491291
A16: 46212 | B16: 0.99860982 | C16: 0.99993265
A17: 46213 | B17: 0.99488466 | C17: 0.99608736
A18: 46216 | B18: 0.98970134 | C18: 0.99082824
A19: 46217 | B19: 0.99245271 | C19: 0.99325571 | G19: 指标名称 | H19: 本周 | I19: 本月 | J19: 本季度 | K19: 本年 | L19: 近1周 | M19: 近1月 | N19: 近3月 | O19: 近6月 | P19: 近1年 | Q19: 近3年 | R19: 近5年 | S19: 成立至今 | T19: 选择区间
A20: 46218 | B20: 0.99005834 | C20: 0.99062576 | G20: 累计收益率 | H20: -0.030252% | I20: 1.799740% | J20: -0.804632% | K20: -0.535747% | L20: -0.387552% | M20: 1.335983% | N20: -0.535747% | O20: -0.535747% | P20: -0.535747% | Q20: -0.535747% | R20: -0.535747% | S20: -0.535747% | T20: -0.535747%
A21: 46219 | B21: 0.98597556 | C21: 0.98667073 | G21: 基准收益率 | H21: -0.028625% | I21: 0.963579% | J21: -0.045171% | K21: 0.236847% | L21: -0.218682% | M21: 0.933315% | N21: 0.236847% | O21: 0.236847% | P21: 0.236847% | Q21: 0.236847% | R21: 0.236847% | S21: 0.236847% | T21: 0.236847%
A22: 46220 | B22: 0.97886372 | C22: 0.98008903 | G22: 年化收益率 | H22: -10.455690% | I22: 31.163777% | J22: -5.220241% | K22: -2.842259% | L22: -18.329155% | M22: 16.912980% | N22: -2.842259% | O22: -2.842259% | P22: -2.842259% | Q22: -2.842259% | R22: -2.842259% | S22: -2.842259% | T22: -2.842259%
A23: 46223 | B23: 0.9753755 | C23: 0.97683759 | G23: 基准年化收益率 | H23: -9.922182% | I23: 15.701421% | J23: -0.299392% | K23: 1.277906% | L23: -10.787738% | M23: 11.558700% | N23: 1.277906% | O23: 1.277906% | P23: 1.277906% | Q23: 1.277906% | R23: 1.277906% | S23: 1.277906% | T23: 1.277906%
A24: 46224 | B24: 0.98437008 | C24: 0.98586080 | G24: 回撤率 | H24: -0.030252% | I24: -0.472383% | J24: -0.804632% | K24: -0.804632% | L24: -0.472383% | M24: -0.472383% | N24: -0.804632% | O24: -0.804632% | P24: -0.804632% | Q24: -0.804632% | R24: -0.804632% | S24: -0.804632% | T24: -0.804632%
A25: 46225 | B25: 0.98402324 | C25: 0.98570780 | G25: 最大回撤 | H25: -0.030252% | I25: -0.771982% | J25: -2.886915% | K25: -2.886915% | L25: -0.771982% | M25: -1.157256% | N25: -2.886915% | O25: -2.886915% | P25: -2.886915% | Q25: -2.886915% | R25: -2.886915% | S25: -0.0289 | T25: -2.886915%
A26: 46226 | B26: 0.98279921 | C26: 0.98438731 | G26: 区间最大涨幅 | H26: 0.000000% | I26: 2.282907% | J26: 0.000000% | K26: 0.271066% | L26: 0.000000% | M26: 1.816949% | N26: 0.271066% | O26: 0.271066% | P26: 0.271066% | Q26: 0.271066% | R26: 0.271066% | S26: 0.271066% | T26: 0.271066%
A27: 46227 | B27: 0.98152946 | C27: 0.98336003 | G27: 回撤最长修复时间 | H27: 3* | I27: 4 | J27: 55* | K27: 5 | L27: 6* | M27: 10 | N27: 5 | O27: 5 | P27: 5 | Q27: 5 | R27: 5 | S27: 5 | T27: 5
A28: 46230 | B28: 0.98516413 | C28: 0.98687417 | G28: 最大回撤修复时间 | H28: 未修复 | I28: 未修复 | J28: 未修复 | K28: 未修复 | L28: 未修复 | M28: 7 | N28: 未修复 | O28: 未修复 | P28: 未修复 | Q28: 未修复 | R28: 未修复 | S28: 未修复 | T28: 未修复
A29: 46231 | B29: 0.97865577 | C29: 0.98060895 | G29: 基准回撤率 | H29: -0.028625% | I29: -0.252567% | J29: -0.252567% | K29: -0.252567% | L29: -0.252567% | M29: -0.252567% | N29: -0.252567% | O29: -0.252567% | P29: -0.252567% | Q29: -0.252567% | R29: -0.252567% | S29: -0.252567% | T29: -0.252567%
A30: 46232 | B30: 0.97811843 | C30: 0.98017950 | G30: 基准最大回撤 | H30: -0.028625% | I30: -0.444646% | J30: -1.357488% | K30: -1.357488% | L30: -0.444646% | M30: -0.470584% | N30: -1.357488% | O30: -1.357488% | P30: -1.357488% | Q30: -1.357488% | R30: -1.357488% | S30: -1.357488% | T30: -1.357488%
A31: 46233 | B31: 0.97376326 | C31: 0.97603230 | G31: 波动率 | H31: -- | I31: 0.321241% | J31: 0.383270% | K31: 0.357635% | L31: 0.397820% | M31: 0.357248% | N31: 0.357635% | O31: 0.357635% | P31: 0.357635% | Q31: 0.357635% | R31: 0.357635% | S31: 0.357635% | T31: 0.357635%
A32: 46234 | B32: 0.97705802 | C32: 0.97918283 | G32: 基准波动率 | H32: -- | I32: 0.184951% | J32: 0.220195% | K32: 0.217573% | L32: 0.233125% | M32: 0.198592% | N32: 0.217573% | O32: 0.217573% | P32: 0.217573% | Q32: 0.217573% | R32: 0.217573% | S32: 0.217573% | T32: 0.217573%
A33: 46237 | B33: 0.97469599 | C33: 0.97636941 | G33: 年化波动率 | H33: -- | I33: 5.099549% | J33: 6.084215% | K33: 5.677277% | L33: 6.315191% | M33: 5.671142% | N33: 5.677277% | O33: 5.677277% | P33: 5.677277% | Q33: 5.677277% | R33: 5.677277% | S33: 5.677277% | T33: 5.677277%
A34: 46238 | B34: 0.97954497 | C34: 0.98084157 | G34: 基准年化波动率 | H34: -- | I34: 2.935999% | J34: 3.495492% | K34: 3.453859% | L34: 3.700744% | M34: 3.152554% | N34: 3.453859% | O34: 3.453859% | P34: 3.453859% | Q34: 3.453859% | R34: 3.453859% | S34: 3.453859% | T34: 3.453859%
