Workbook

Sheet 净值底稿
I1: HSSCSOY.HK | J1: 930955.CSI | Q1: 000852.SH | R1: 000852.SH | S1: 932000.CSI | T1: 932000.CSI
A2: 代码 | B2: 000940.OF | C2: 001513.OF | D2: 001480.OF | E2: 001323.OF | G2: 007466.OF | H2: 090010.OF | I2: 020866.OF | K2: 090007.OF | L2: 161222.OF | M2: 003957.OF | N2: 007044.OF | O2: 001556.OF | P2: 006593.OF | Q2: 017953.OF | R2: 015867.OF | S2: 019923.OF | T2: 019918.OF | V2: 161119.OF | W2: 000216.OF
A3: =[1]!HX_AutoDate(1,"2020-01-01","2026-10-16",-1,-1,0,0,0,0,0,"SSE",1643,0) -> 日期 | B3: 富国曹晋 | C3: 易方达郑希 | D3: 财通金梓才 | E3: 东吴刘元海 | F3: 产业趋势 | G3: 红利低波 | H3: 中证红利 | I3: 华安恒生港股通中国央企红利ETF发起式联接A | J3: 红利低波100 | K3: 大成徐彦 | L3: 国投瑞银綦缚鹏 | M3: 安信量化精选沪深300指数增强A | N3: 博道沪深300指数增强A | O3: 天弘中证500指数增强A | P3: 博道中证500指数增强A | Q3: 汇添富中证1000指数增强A | R3: 国泰海通中证1000指数增强A | S3: 华泰柏瑞中证2000指数增强A | T3: 招商中证2000指数增强A | U3: 指增组合 | V3: 中债新综合 | W3: 华安黄金 | X3: 红利组合
A4: 43832 | B4: 0.25 | C4: 0.25 | D4: 0.25 | E4: 0.25 | F4: 1.0025 | G4: =[1]!thsiFinD("ths_adjustment_nv_fund",G$2,$A4) -> 1.0877 | H4: =[1]!thsiFinD("ths_adjustment_nv_fund",H$2,$A4) -> 1.8779556 | I4: =[1]!thsiFinD("ths_close_price_index",I$1,$A4) -> 3071.11 | J4: =[1]!thsiFinD("ths_close_price_index",J$1,$A4) -> 9138.0556 | K4: =[1]!thsiFinD("ths_adjustment_nv_fund",K$2,$A4) -> 4.9057783 | L4: =[1]!thsiFinD("ths_adjustment_nv_fund",L$2,$A4) -> 1.4145101 | M4: 0.125 | N4: 0.125 | O4: 0.125 | P4: 0.125 | Q4: 0.125 | R4: 0.125 | S4: 0.125 | T4: 0.125 | U4: 1.0173101 | V4: 1.4008 | W4: 1.2499 | X4: ='2080回测'!$O$13*G4/$G$4+'2080回测'!$O$14*H4/$H$4+'2080回测'!$O$15*I4/$I$4+'2080回测'!$O$17*K4/$K$4+'2080回测'!$O$18*L4/$L$4+'2080回测'!$O$16*J4/$J$4 -> 1
A5: 43833 | B5: 0.6752609 | C5: 0.5107832 | D5: 1 | E5: 0.29296875 | F5: 1.0061975 | G5: =[1]!thsiFinD("ths_adjustment_nv_fund",G$2,$A5) -> 1.0863 | H5: =[1]!thsiFinD("ths_adjustment_nv_fund",H$2,$A5) -> 1.8779556 | I5: 3070.7 | J5: =[1]!thsiFinD("ths_close_price_index",J$1,$A5) -> 9153.8172 | K5: =[1]!thsiFinD("ths_adjustment_nv_fund",K$2,$A5) -> 4.9015124 | L5: =[1]!thsiFinD("ths_adjustment_nv_fund",L$2,$A5) -> 1.4155198 | M5: 0.013267263 | N5: 0.010251064 | O5: 0.017852864 | P5: 0.016333026 | Q5: 0.019673837 | R5: 0.019673837 | S5: 0.020714398 | T5: 0.020714398 | U5: 1.0202139 | V5: 1.4011 | W5: 1.269 | X5: ='2080回测'!$O$13*G5/$G$4+'2080回测'!$O$14*H5/$H$4+'2080回测'!$O$15*I5/$I$4+'2080回测'!$O$17*K5/$K$4+'2080回测'!$O$18*L5/$L$4+'2080回测'!$O$16*J5/$J$4 -> 0.99895473
A6: 43836 | B6: 1.2891344 | C6: 2.4971623 | D6: 1.8461538 | E6: 0.9765625 | F6: 1.0165225 | G6: =[1]!thsiFinD("ths_adjustment_nv_fund",G$2,$A6) -> 1.0818 | H6: =[1]!thsiFinD("ths_adjustment_nv_fund",H$2,$A6) -> 1.8713778 | I6: 3047.35 | J6: =[1]!thsiFinD("ths_close_price_index",J$1,$A6) -> 9132.1408 | K6: =[1]!thsiFinD("ths_adjustment_nv_fund",K$2,$A6) -> 4.9057783 | L6: =[1]!thsiFinD("ths_adjustment_nv_fund",L$2,$A6) -> 1.4235969 | M6: 0.011508951 | N6: 0.0050386587 | O6: 0.020848311 | P6: 0.019013318 | Q6: 0.024970357 | R6: 0.024970357 | S6: 0.027680657 | T6: 0.027680657 | U6: 1.0263972 | V6: 1.4023 | W6: 1.2957 | X6: ='2080回测'!$O$13*G6/$G$4+'2080回测'!$O$14*H6/$H$4+'2080回测'!$O$15*I6/$I$4+'2080回测'!$O$17*K6/$K$4+'2080回测'!$O$18*L6/$L$4+'2080回测'!$O$16*J6/$J$4 -> 0.99630297
A7: 43837 | B7: 1.7188459 | C7: 2.6674234 | D7: 2.2307692 | E7: 1.7578125 | F7: 1.0209371 | G7: =[1]!thsiFinD("ths_adjustment_nv_fund",G$2,$A7) -> 1.0883 | H7: =[1]!thsiFinD("ths_adjustment_nv_fund",H$2,$A7) -> 1.8856296 | I7: 3043.95 | J7: =[1]!thsiFinD("ths_close_price_index",J$1,$A7) -> 9171.6918 | K7: =[1]!thsiFinD("ths_adjustment_nv_fund",K$2,$A7) -> 4.9484372 | L7: =[1]!thsiFinD("ths_adjustment_nv_fund",L$2,$A7) -> 1.4326837 | M7: 0.0085517903 | N7: 0.00078186083 | O7: 0.03330937 | P7: 0.025127733 | Q7: 0.035512705 | R7: 0.035512705 | S7: 0.036190635 | T7: 0.036190635 | U7: 1.0393231 | V7: 1.4024 | W7: 1.2848 | X7: ='2080回测'!$O$13*G7/$G$4+'2080回测'!$O$14*H7/$H$4+'2080回测'!$O$15*I7/$I$4+'2080回测'!$O$17*K7/$K$4+'2080回测'!$O$18*L7/$L$4+'2080回测'!$O$16*J7/$J$4 -> 1.0025957
A8: 43838 | B8: 0.85942296 | C8: 1.4755959 | D8: -0.53846154 | E8: 0.390625 | F8: 1.005468 | G8: =[1]!thsiFinD("ths_adjustment_nv_fund",G$2,$A8) -> 1.0744 | H8: =[1]!thsiFinD("ths_adjustment_nv_fund",H$2,$A8) -> 1.8648 | I8: 3003.43 | J8: =[1]!thsiFinD("ths_close_price_index",J$1,$A8) -> 9070.8142 | K8: =[1]!thsiFinD("ths_adjustment_nv_fund",K$2,$A8) -> 4.9015124 | L8: =[1]!thsiFinD("ths_adjustment_nv_fund",L$2,$A8) -> 1.4195583 | M8: 0.015105499 | N8: 0.010251064 | O8: 0.048286604 | P8: 0.037356563 | Q8: 0.051253136 | R8: 0.051253136 | S8: 0.050539517 | T8: 0.050539517 | U8: 1.0261808 | V8: 1.403 | W8: 1.3041 | X8: ='2080回测'!$O$13*G8/$G$4+'2080回测'!$O$14*H8/$H$4+'2080回测'!$O$15*I8/$I$4+'2080回测'!$O$17*K8/$K$4+'2080回测'!$O$18*L8/$L$4+'2080回测'!$O$16*J8/$J$4 -> 0.99048782
A9: 43839 | B9: 3.4376918 | C9: 3.6322361 | D9: 3.2307692 | E9: 2.34375 | F9: 1.0316111 | G9: =[1]!thsiFinD("ths_adjustment_nv_fund",G$2,$A9) -> 1.0843 | H9: =[1]!thsiFinD("ths_adjustment_nv_fund",H$2,$A9) -> 1.8867259 | I9: 3038.85 | J9: =[1]!thsiFinD("ths_close_price_index",J$1,$A9) -> 9117.9626 | K9: =[1]!thsiFinD("ths_adjustment_nv_fund",K$2,$A9) -> 4.9782985 | L9: =[1]!thsiFinD("ths_adjustment_nv_fund",L$2,$A9) -> 1.4336933 | M9: 0.0041560102 | N9: -0.0013899748 | O9: 0.039300264 | P9: 0.024122623 | Q9: 0.036903176 | R9: 0.036903176 | S9: 0.034725679 | T9: 0.034725679 | U9: 1.0416767 | V9: 1.4036 | W9: 1.2656 | X9: ='2080回测'!$O$13*G9/$G$4+'2080回测'!$O$14*H9/$H$4+'2080回测'!$O$15*I9/$I$4+'2080回测'!$O$17*K9/$K$4+'2080回测'!$O$18*L9/$L$4+'2080回测'!$O$16*J9/$J$4 -> 1.0003337
A10: 43840 | B10: 3.7446286 | C10: 4.0862656 | D10: 4.9230769 | E10: 2.8320312 | F10: 1.038965 | G10: =[1]!thsiFinD("ths_adjustment_nv_fund",G$2,$A10) -> 1.0806 | H10: =[1]!thsiFinD("ths_adjustment_nv_fund",H$2,$A10) -> 1.8801481 | I10: 3034.57 | J10: =[1]!thsiFinD("ths_close_price_index",J$1,$A10) -> 9097.1204 | K10: =[1]!thsiFinD("ths_adjustment_nv_fund",K$2,$A10) -> 4.956969 | L10: =[1]!thsiFinD("ths_adjustment_nv_fund",L$2,$A10) -> 1.4316741 | M10: 0.016464194 | N10: 0.012075406 | O10: 0.052600048 | P10: 0.039031745 | Q10: 0.053376565 | R10: 0.053376565 | S10: 0.053244578 | T10: 0.053244578 | U10: 1.0406964 | V10: 1.4048 | W10: 1.2682 | X10: ='2080回测'!$O$13*G10/$G$4+'2080回测'!$O$14*H10/$H$4+'2080回测'!$O$15*I10/$I$4+'2080回测'!$O$17*K10/$K$4+'2080回测'!$O$18*L10/$L$4+'2080回测'!$O$16*J10/$J$4 -> 0.99703487
A11: 43843 | B11: 6.3842848 | C11: 6.8671964 | D11: 9.0769231 | E11: 4.6875 | F11: 1.0675398 | G11: =[1]!thsiFinD("ths_adjustment_nv_fund",G$2,$A11) -> 1.0836 | H11: =[1]!thsiFinD("ths_adjustment_nv_fund",H$2,$A11) -> 1.8922074 | I11: 3055.16 | J11: =[1]!thsiFinD("ths_close_price_index",J$1,$A11) -> 9115.9816 | K11: =[1]!thsiFinD("ths_adjustment_nv_fund",K$2,$A11) -> 5.0081597 | L11: =[1]!thsiFinD("ths_adjustment_nv_fund",L$2,$A11) -> 1.4397512 | M11: 0.016624041 | N11: 0.013726001 | O11: 0.055475677 | P11: 0.03668649 | Q11: 0.051169052 | R11: 0.051169052 | S11: 0.050360639 | T11: 0.050360639 | U11: 1.0533907 | V11: 1.4055 | W11: 1.2646 | X11: ='2080回测'!$O$13*G11/$G$4+'2080回测'!$O$14*H11/$H$4+'2080回测'!$O$15*I11/$I$4+'2080回测'!$O$17*K11/$K$4+'2080回测'!$O$18*L11/$L$4+'2080回测'!$O$16*J11/$J$4 -> 1.0008559
A12: 43844 | B12: 6.0773481 | C12: 7.2077185 | D12: 8.0769231 | E12: 4.5898438 | F12: 1.0648796 | G12: =[1]!thsiFinD("ths_adjustment_nv_fund",G$2,$A12) -> 1.0845 | H12: =[1]!thsiFinD("ths_adjustment_nv_fund",H$2,$A12) -> 1.8944 | I12: 3050 | J12: =[1]!thsiFinD("ths_close_price_index",J$1,$A12) -> 9115.0753 | K12: =[1]!thsiFinD("ths_adjustment_nv_fund",K$2,$A12) -> 4.9953621 | L12: =[1]!thsiFinD("ths_adjustment_nv_fund",L$2,$A12) -> 1.4336933 | M12: 0.025895141 | N12: 0.025453914 | O12: 0.070812365 | P12: 0.04891532 | Q12: 0.064610574 | R12: 0.064610574 | S12: 0.063413966 | T12: 0.063413966 | U12: 1.0518627 | V12: 1.4057 | W12: 1.2542 | X12: ='2080回测'!$O$13*G12/$G$4+'2080回测'!$O$14*H12/$H$4+'2080回测'!$O$15*I12/$I$4+'2080回测'!$O$17*K12/$K$4+'2080回测'!$O$18*L12/$L$4+'2080回测'!$O$16*J12/$J$4 -> 1.0008287
A13: 43845 | B13: 7.3050952 | C13: 7.3779796 | D13: 8.6153846 | E13: 4.9804688 | F13: 1.0706973 | G13: =[1]!thsiFinD("ths_adjustment_nv_fund",G$2,$A13) -> 1.0782 | H13: =[1]!thsiFinD("ths_adjustment_nv_fund",H$2,$A13) -> 1.8856296 | I13: 3038.13 | J13: =[1]!thsiFinD("ths_close_price_index",J$1,$A13) -> 9034.9692 | K13: =[1]!thsiFinD("ths_adjustment_nv_fund",K$2,$A13) -> 4.9740326 | L13: =[1]!thsiFinD("ths_adjustment_nv_fund",L$2,$A13) -> 1.4296548 | M13: 0.022538363 | N13: 0.023021458 | O13: 0.069734004 | P13: 0.047658933 | Q13: 0.062345616 | R13: 0.062345616 | S13: 0.063628957 | T13: 0.063628957 | U13: 1.0491022 | V13: 1.4059 | W13: 1.2616 | X13: ='2080回测'!$O$13*G13/$G$4+'2080回测'!$O$14*H13/$H$4+'2080回测'!$O$15*I13/$I$4+'2080回测'!$O$17*K13/$K$4+'2080回测'!$O$18*L13/$L$4+'2080回测'!$O$16*J13/$J$4 -> 0.99547475
A14: 43846 | B14: 8.7170043 | C14: 7.2077185 | D14: 8.4615385 | E14: 5.3710938 | F14: 1.0743934 | G14: =[1]!thsiFinD("ths_adjustment_nv_fund",G$2,$A14) -> 1.0716 | H14: =[1]!thsiFinD("ths_adjustment_nv_fund",H$2,$A14) -> 1.8768593 | I14: 3044.85 | J14: =[1]!thsiFinD("ths_close_price_index",J$1,$A14) -> 8984.4832 | K14: =[1]!thsiFinD("ths_adjustment_nv_fund",K$2,$A14) -> 4.9612349 | L14: =[1]!thsiFinD("ths_adjustment_nv_fund",L$2,$A14) -> 1.4246066 | M14: 0.017663043 | N14: 0.01850404 | O14: 0.068535826 | P14: 0.044392328 | Q14: 0.062238719 | R14: 0.062238719 | S14: 0.059622622 | T14: 0.059622622 | U14: 1.0476066 | V14: 1.4061 | W14: 1.2635 | X14: ='2080回测'!$O$13*G14/$G$4+'2080回测'!$O$14*H14/$H$4+'2080回测'!$O$15*I14/$I$4+'2080回测'!$O$17*K14/$K$4+'2080回测'!$O$18*L14/$L$4+'2080回测'!$O$16*J14/$J$4 -> 0.99000271
A15: 43847 | B15: 9.699202 | C15: 7.3212259 | D15: 8.0769231 | E15: 5.2734375 | F15: 1.075927 | G15: =[1]!thsiFinD("ths_adjustment_nv_fund",G$2,$A15) -> 1.0713 | H15: =[1]!thsiFinD("ths_adjustment_nv_fund",H$2,$A15) -> 1.8779556 | I15: 3069.12 | J15: =[1]!thsiFinD("ths_close_price_index",J$1,$A15) -> 8973.546 | K15: =[1]!thsiFinD("ths_adjustment_nv_fund",K$2,$A15) -> 4.9520982 | L15: =[1]!thsiFinD("ths_adjustment_nv_fund",L$2,$A15) -> 1.4326837 | M15: 0.015025575 | N15: 0.019199027 | O15: 0.067577283 | P15: 0.045313678 | Q15: 0.060193428 | R15: 0.060193428 | S15: 0.056675335 | T15: 0.056675335 | U15: 1.0448327 | V15: 1.4064 | W15: 1.261 | X15: ='2080回测'!$O$13*G15/$G$4+'2080回测'!$O$14*H15/$H$4+'2080回测'!$O$15*I15/$I$4+'2080回测'!$O$17*K15/$K$4+'2080回测'!$O$18*L15/$L$4+'2080回测'!$O$16*J15/$J$4 -> 0.99016684
A16: 43850 | B16: 12.277471 | C16: 10.385925 | D16: 12.846154 | E16: 7.7148438 | F16: 1.108061 | G16: =[1]!thsiFinD("ths_adjustment_nv_fund",G$2,$A16) -> 1.0707 | H16: =[1]!thsiFinD("ths_adjustment_nv_fund",H$2,$A16) -> 1.8801481 | I16: 3032.52 | J16: =[1]!thsiFinD("ths_close_price_index",J$1,$A16) -> 8989.6308 | K16: =[1]!thsiFinD("ths_adjustment_nv_fund",K$2,$A16) -> 4.9292564 | L16: =[1]!thsiFinD("ths_adjustment_nv_fund",L$2,$A16) -> 1.4518669 | M16: 0.017902813 | N16: 0.018851533 | O16: 0.063862928 | P16: 0.041963314 | Q16: 0.056112313 | R16: 0.056112313 | S16: 0.051928052 | T16: 0.051928052 | U16: 1.0570593 | V16: 1.4078 | W16: 1.2626 | X16: ='2080回测'!$O$13*G16/$G$4+'2080回测'!$O$14*H16/$H$4+'2080回测'!$O$15*I16/$I$4+'2080回测'!$O$17*K16/$K$4+'2080回测'!$O$18*L16/$L$4+'2080回测'!$O$16*J16/$J$4 -> 0.9906161
... A1618: 46265 | B1618: 315.89932 | C1618: 373.87759 | D1618: 474.30769 | E1618: 549.63867 | F1618: 5.2843082 | G1618: =[1]!thsiFinD("ths_adjustment_nv_fund",G$2,$A1618) -> 2.0223912 | H1618: =[1]!thsiFinD("ths_adjustment_nv_fund",H$2,$A1618) -> 3.065683 | I1618: 4152.25 | J1618: =[1]!thsiFinD("ths_close_price_index",J$1,$A1618) -> 11317.654 | K1618: =[1]!thsiFinD("ths_adjustment_nv_fund",K$2,$A1618) -> 9.9149172 | L1618: =[1]!thsiFinD("ths_adjustment_nv_fund",L$2,$A1618) -> 3.0625507 | M1618: 0.66032609 | N1618: 0.65311441 | O1618: 1.1345555 | P1618: 1.4517597 | Q1618: 1.028359 | R1618: 0.88242983 | S1618: 0.98510325 | T1618: 1.3005591 | U1618: 2.0341362 | V1618: 1.8006 | W1618: 3.3302 | X1618: ='2080回测'!$O$13*G1618/$G$4+'2080回测'!$O$14*H1618/$H$4+'2080回测'!$O$15*I1618/$I$4+'2080回测'!$O$17*K1618/$K$4+'2080回测'!$O$18*L1618/$L$4+'2080回测'!$O$16*J1618/$J$4 -> 1.906079
A1619: 46266 | G1619: =[1]!thsiFinD("ths_adjustment_nv_fund",G$2,$A1619) -> 2.0450358 | H1619: =[1]!thsiFinD("ths_adjustment_nv_fund",H$2,$A1619) -> 3.0664504 | I1619: 4153.25 | J1619: =[1]!thsiFinD("ths_close_price_index",J$1,$A1619) -> 11441.462 | K1619: =[1]!thsiFinD("ths_adjustment_nv_fund",K$2,$A1619) -> 9.9513404 | L1619: =[1]!thsiFinD("ths_adjustment_nv_fund",L$2,$A1619) -> 3.0526562 | M1619: 0.66032609 | N1619: 0.65311441 | O1619: 1.1345555 | P1619: 1.4517597 | Q1619: 1.028359 | R1619: 0.88242983 | S1619: 0.98510325 | T1619: 1.3005591 | U1619: 2.0341362 | V1619: 1.8006 | W1619: 3.3302 | X1619: ='2080回测'!$O$13*G1619/$G$4+'2080回测'!$O$14*H1619/$H$4+'2080回测'!$O$15*I1619/$I$4+'2080回测'!$O$17*K1619/$K$4+'2080回测'!$O$18*L1619/$L$4+'2080回测'!$O$16*J1619/$J$4 -> 1.9227771
A1620: 46267 | G1620: =[1]!thsiFinD("ths_adjustment_nv_fund",G$2,$A1620) -> 2.0340827 | H1620: =[1]!thsiFinD("ths_adjustment_nv_fund",H$2,$A1620) -> 3.0236948 | I1620: 4154.25 | J1620: =[1]!thsiFinD("ths_close_price_index",J$1,$A1620) -> 11343.653 | K1620: =[1]!thsiFinD("ths_adjustment_nv_fund",K$2,$A1620) -> 9.8836973 | L1620: =[1]!thsiFinD("ths_adjustment_nv_fund",L$2,$A1620) -> 3.0214582 | M1620: 0.66032609 | N1620: 0.65311441 | O1620: 1.1345555 | P1620: 1.4517597 | Q1620: 1.028359 | R1620: 0.88242983 | S1620: 0.98510325 | T1620: 1.3005591 | U1620: 2.0341362 | V1620: 1.8006 | W1620: 3.3302 | X1620: ='2080回测'!$O$13*G1620/$G$4+'2080回测'!$O$14*H1620/$H$4+'2080回测'!$O$15*I1620/$I$4+'2080回测'!$O$17*K1620/$K$4+'2080回测'!$O$18*L1620/$L$4+'2080回测'!$O$16*J1620/$J$4 -> 1.9111367
A1621: 46268 | G1621: =[1]!thsiFinD("ths_adjustment_nv_fund",G$2,$A1621) -> 2.0318608 | H1621: =[1]!thsiFinD("ths_adjustment_nv_fund",H$2,$A1621) -> 3.0246815 | I1621: 4155.25 | J1621: =[1]!thsiFinD("ths_close_price_index",J$1,$A1621) -> 11353.766 | K1621: =[1]!thsiFinD("ths_adjustment_nv_fund",K$2,$A1621) -> 9.8767596 | L1621: =[1]!thsiFinD("ths_adjustment_nv_fund",L$2,$A1621) -> 3.0396318 | M1621: 0.66032609 | N1621: 0.65311441 | O1621: 1.1345555 | P1621: 1.4517597 | Q1621: 1.028359 | R1621: 0.88242983 | S1621: 0.98510325 | T1621: 1.3005591 | U1621: 2.0341362 | V1621: 1.8006 | W1621: 3.3302 | X1621: ='2080回测'!$O$13*G1621/$G$4+'2080回测'!$O$14*H1621/$H$4+'2080回测'!$O$15*I1621/$I$4+'2080回测'!$O$17*K1621/$K$4+'2080回测'!$O$18*L1621/$L$4+'2080回测'!$O$16*J1621/$J$4 -> 1.9106458
A1622: 46269 | G1622: =[1]!thsiFinD("ths_adjustment_nv_fund",G$2,$A1622) -> 2.0407486 | H1622: =[1]!thsiFinD("ths_adjustment_nv_fund",H$2,$A1622) -> 3.0318074 | I1622: 4156.25 | J1622: =[1]!thsiFinD("ths_close_price_index",J$1,$A1622) -> 11412.755 | K1622: =[1]!thsiFinD("ths_adjustment_nv_fund",K$2,$A1622) -> 9.9123156 | L1622: =[1]!thsiFinD("ths_adjustment_nv_fund",L$2,$A1622) -> 3.0369058 | M1622: 0.66032609 | N1622: 0.65311441 | O1622: 1.1345555 | P1622: 1.4517597 | Q1622: 1.028359 | R1622: 0.88242983 | S1622: 0.98510325 | T1622: 1.3005591 | U1622: 2.0341362 | V1622: 1.8006 | W1622: 3.3302 | X1622: ='2080回测'!$O$13*G1622/$G$4+'2080回测'!$O$14*H1622/$H$4+'2080回测'!$O$15*I1622/$I$4+'2080回测'!$O$17*K1622/$K$4+'2080回测'!$O$18*L1622/$L$4+'2080回测'!$O$16*J1622/$J$4 -> 1.9177148
A1623: 46272 | G1623: =[1]!thsiFinD("ths_adjustment_nv_fund",G$2,$A1623) -> 2.0223557 | H1623: =[1]!thsiFinD("ths_adjustment_nv_fund",H$2,$A1623) -> 2.9974933 | I1623: 4157.25 | J1623: =[1]!thsiFinD("ths_close_price_index",J$1,$A1623) -> 11326.557 | K1623: =[1]!thsiFinD("ths_adjustment_nv_fund",K$2,$A1623) -> 9.8984401 | L1623: =[1]!thsiFinD("ths_adjustment_nv_fund",L$2,$A1623) -> 3.0021741 | M1623: 0.66032609 | N1623: 0.65311441 | O1623: 1.1345555 | P1623: 1.4517597 | Q1623: 1.028359 | R1623: 0.88242983 | S1623: 0.98510325 | T1623: 1.3005591 | U1623: 2.0341362 | V1623: 1.8006 | W1623: 3.3302 | X1623: ='2080回测'!$O$13*G1623/$G$4+'2080回测'!$O$14*H1623/$H$4+'2080回测'!$O$15*I1623/$I$4+'2080回测'!$O$17*K1623/$K$4+'2080回测'!$O$18*L1623/$L$4+'2080回测'!$O$16*J1623/$J$4 -> 1.9014487
A1624: 46273 | G1624: =[1]!thsiFinD("ths_adjustment_nv_fund",G$2,$A1624) -> 2.0403783 | H1624: =[1]!thsiFinD("ths_adjustment_nv_fund",H$2,$A1624) -> 3.0345481 | I1624: 4158.25 | J1624: =[1]!thsiFinD("ths_close_price_index",J$1,$A1624) -> 11385.808 | K1624: =[1]!thsiFinD("ths_adjustment_nv_fund",K$2,$A1624) -> 9.9322616 | L1624: =[1]!thsiFinD("ths_adjustment_nv_fund",L$2,$A1624) -> 3.0034866 | M1624: 0.66032609 | N1624: 0.65311441 | O1624: 1.1345555 | P1624: 1.4517597 | Q1624: 1.028359 | R1624: 0.88242983 | S1624: 0.98510325 | T1624: 1.3005591 | U1624: 2.0341362 | V1624: 1.8006 | W1624: 3.3302 | X1624: ='2080回测'!$O$13*G1624/$G$4+'2080回测'!$O$14*H1624/$H$4+'2080回测'!$O$15*I1624/$I$4+'2080回测'!$O$17*K1624/$K$4+'2080回测'!$O$18*L1624/$L$4+'2080回测'!$O$16*J1624/$J$4 -> 1.9154865
A1625: 46274 | G1625: =[1]!thsiFinD("ths_adjustment_nv_fund",G$2,$A1625) -> 2.0465504 | H1625: =[1]!thsiFinD("ths_adjustment_nv_fund",H$2,$A1625) -> 3.0662311 | I1625: 4159.25 | J1625: =[1]!thsiFinD("ths_close_price_index",J$1,$A1625) -> 11357.327 | K1625: =[1]!thsiFinD("ths_adjustment_nv_fund",K$2,$A1625) -> 9.9079795 | L1625: =[1]!thsiFinD("ths_adjustment_nv_fund",L$2,$A1625) -> 3.0151985 | M1625: 0.66032609 | N1625: 0.65311441 | O1625: 1.1345555 | P1625: 1.4517597 | Q1625: 1.028359 | R1625: 0.88242983 | S1625: 0.98510325 | T1625: 1.3005591 | U1625: 2.0341362 | V1625: 1.8006 | W1625: 3.3302 | X1625: ='2080回测'!$O$13*G1625/$G$4+'2080回测'!$O$14*H1625/$H$4+'2080回测'!$O$15*I1625/$I$4+'2080回测'!$O$17*K1625/$K$4+'2080回测'!$O$18*L1625/$L$4+'2080回测'!$O$16*J1625/$J$4 -> 1.920359
A1626: 46275 | G1626: =[1]!thsiFinD("ths_adjustment_nv_fund",G$2,$A1626) -> 2.0535866 | H1626: =[1]!thsiFinD("ths_adjustment_nv_fund",H$2,$A1626) -> 3.0470459 | I1626: 4160.25 | J1626: =[1]!thsiFinD("ths_close_price_index",J$1,$A1626) -> 11346.491 | K1626: =[1]!thsiFinD("ths_adjustment_nv_fund",K$2,$A1626) -> 9.8455397 | L1626: =[1]!thsiFinD("ths_adjustment_nv_fund",L$2,$A1626) -> 2.990967 | M1626: 0.66032609 | N1626: 0.65311441 | O1626: 1.1345555 | P1626: 1.4517597 | Q1626: 1.028359 | R1626: 0.88242983 | S1626: 0.98510325 | T1626: 1.3005591 | U1626: 2.0341362 | V1626: 1.8006 | W1626: 3.3302 | X1626: ='2080回测'!$O$13*G1626/$G$4+'2080回测'!$O$14*H1626/$H$4+'2080回测'!$O$15*I1626/$I$4+'2080回测'!$O$17*K1626/$K$4+'2080回测'!$O$18*L1626/$L$4+'2080回测'!$O$16*J1626/$J$4 -> 1.9225483
A1627: 46276 | G1627: =[1]!thsiFinD("ths_adjustment_nv_fund",G$2,$A1627) -> 2.0356875 | H1627: =[1]!thsiFinD("ths_adjustment_nv_fund",H$2,$A1627) -> 2.9978222 | I1627: 4161.25 | J1627: =[1]!thsiFinD("ths_close_price_index",J$1,$A1627) -> 11264.393 | K1627: =[1]!thsiFinD("ths_adjustment_nv_fund",K$2,$A1627) -> 9.7614194 | L1627: =[1]!thsiFinD("ths_adjustment_nv_fund",L$2,$A1627) -> 2.9474514 | M1627: 0.66032609 | N1627: 0.65311441 | O1627: 1.1345555 | P1627: 1.4517597 | Q1627: 1.028359 | R1627: 0.88242983 | S1627: 0.98510325 | T1627: 1.3005591 | U1627: 2.0341362 | V1627: 1.8006 | W1627: 3.3302 | X1627: ='2080回测'!$O$13*G1627/$G$4+'2080回测'!$O$14*H1627/$H$4+'2080回测'!$O$15*I1627/$I$4+'2080回测'!$O$17*K1627/$K$4+'2080回测'!$O$18*L1627/$L$4+'2080回测'!$O$16*J1627/$J$4 -> 1.9045925
A1628: 46279 | G1628: =[1]!thsiFinD("ths_adjustment_nv_fund",G$2,$A1628) -> 2.0428471 | H1628: =[1]!thsiFinD("ths_adjustment_nv_fund",H$2,$A1628) -> 2.9917926 | I1628: 4162.25 | J1628: =[1]!thsiFinD("ths_close_price_index",J$1,$A1628) -> 11360.786 | K1628: =[1]!thsiFinD("ths_adjustment_nv_fund",K$2,$A1628) -> 9.8117181 | L1628: =[1]!thsiFinD("ths_adjustment_nv_fund",L$2,$A1628) -> 2.937254 | M1628: 0.66032609 | N1628: 0.65311441 | O1628: 1.1345555 | P1628: 1.4517597 | Q1628: 1.028359 | R1628: 0.88242983 | S1628: 0.98510325 | T1628: 1.3005591 | U1628: 2.0341362 | V1628: 1.8006 | W1628: 3.3302 | X1628: ='2080回测'!$O$13*G1628/$G$4+'2080回测'!$O$14*H1628/$H$4+'2080回测'!$O$15*I1628/$I$4+'2080回测'!$O$17*K1628/$K$4+'2080回测'!$O$18*L1628/$L$4+'2080回测'!$O$16*J1628/$J$4 -> 1.9101627
A1629: 46280 | G1629: =[1]!thsiFinD("ths_adjustment_nv_fund",G$2,$A1629) -> 2.0270465 | H1629: =[1]!thsiFinD("ths_adjustment_nv_fund",H$2,$A1629) -> 2.9752385 | I1629: 4163.25 | J1629: =[1]!thsiFinD("ths_close_price_index",J$1,$A1629) -> 11265.743 | K1629: =[1]!thsiFinD("ths_adjustment_nv_fund",K$2,$A1629) -> 9.7744277 | L1629: =[1]!thsiFinD("ths_adjustment_nv_fund",L$2,$A1629) -> 2.9249364 | M1629: 0.66032609 | N1629: 0.65311441 | O1629: 1.1345555 | P1629: 1.4517597 | Q1629: 1.028359 | R1629: 0.88242983 | S1629: 0.98510325 | T1629: 1.3005591 | U1629: 2.0341362 | V1629: 1.8006 | W1629: 3.3302 | X1629: ='2080回测'!$O$13*G1629/$G$4+'2080回测'!$O$14*H1629/$H$4+'2080回测'!$O$15*I1629/$I$4+'2080回测'!$O$17*K1629/$K$4+'2080回测'!$O$18*L1629/$L$4+'2080回测'!$O$16*J1629/$J$4 -> 1.8969105
A1630: 46281 | G1630: =[1]!thsiFinD("ths_adjustment_nv_fund",G$2,$A1630) -> 2.0128506 | H1630: =[1]!thsiFinD("ths_adjustment_nv_fund",H$2,$A1630) -> 2.9613156 | I1630: 4164.25 | J1630: =[1]!thsiFinD("ths_close_price_index",J$1,$A1630) -> 11197.995 | K1630: =[1]!thsiFinD("ths_adjustment_nv_fund",K$2,$A1630) -> 9.7778966 | L1630: =[1]!thsiFinD("ths_adjustment_nv_fund",L$2,$A1630) -> 2.9272585 | M1630: 0.66032609 | N1630: 0.65311441 | O1630: 1.1345555 | P1630: 1.4517597 | Q1630: 1.028359 | R1630: 0.88242983 | S1630: 0.98510325 | T1630: 1.3005591 | U1630: 2.0341362 | V1630: 1.8006 | W1630: 3.3302 | X1630: ='2080回测'!$O$13*G1630/$G$4+'2080回测'!$O$14*H1630/$H$4+'2080回测'!$O$15*I1630/$I$4+'2080回测'!$O$17*K1630/$K$4+'2080回测'!$O$18*L1630/$L$4+'2080回测'!$O$16*J1630/$J$4 -> 1.8867044
A1631: 46282 | G1631: =[1]!thsiFinD("ths_adjustment_nv_fund",G$2,$A1631) -> 2.0055675 | H1631: =[1]!thsiFinD("ths_adjustment_nv_fund",H$2,$A1631) -> 2.9459674 | I1631: 4165.25 | J1631: =[1]!thsiFinD("ths_close_price_index",J$1,$A1631) -> 11175.115 | K1631: =[1]!thsiFinD("ths_adjustment_nv_fund",K$2,$A1631) -> 9.7961082 | L1631: =[1]!thsiFinD("ths_adjustment_nv_fund",L$2,$A1631) -> 2.9330135 | M1631: 0.66032609 | N1631: 0.65311441 | O1631: 1.1345555 | P1631: 1.4517597 | Q1631: 1.028359 | R1631: 0.88242983 | S1631: 0.98510325 | T1631: 1.3005591 | U1631: 2.0341362 | V1631: 1.8006 | W1631: 3.3302 | X1631: ='2080回测'!$O$13*G1631/$G$4+'2080回测'!$O$14*H1631/$H$4+'2080回测'!$O$15*I1631/$I$4+'2080回测'!$O$17*K1631/$K$4+'2080回测'!$O$18*L1631/$L$4+'2080回测'!$O$16*J1631/$J$4 -> 1.8821257
A1632: 46283
A1633: 46286
A1634: 46287
A1635: 46288
A1636: 46289
A1637: 46293
A1638: 46294
A1639: 46295
A1640: 46303
A1641: 46304
...

Sheet 2080回测
A1: 可编辑红利组合｜2080回测模型
A2: ="数据区间："&TEXT($A$43,"yyyy-mm-dd")&" 至 "&TEXT($A$1657,"yyyy-mm-dd")&"｜红利输入：净值底稿 W｜指增/债券/黄金：T/U/V｜净值基准：费后" -> 数据区间：2020-01-02 至 2026-08-31｜红利输入：净值底稿 W｜指增/债券/黄金：T/U/V｜净值基准：费后
A4: 初始配置 | D4: 再平衡参数 | G4: 费率与绩效参数 | J4: 模型检查与口径
A5: 红利组合 | B5: 0.1 | D5: 权益目标权重 | E5: 0.2 | G5: 年化费率 | H5: 0.005 | J5: 初始权重合计 | K5: =SUM($B$5:$B$8) -> 1 | L5: 应为100% | N5: 只需修改下方黄底蓝字的5项红利持仓权重，合计必须为100%。红利组合按起始权重买入并持有；2080外层仍按年末、季末和15%/25%权益阈值触发再平衡，年化费率0.5%。
A6: 指增组合 | B6: 0.1 | D6: 权益下限 | E6: 0.15 | G6: 年化交易日 | H6: 250 | J6: 阈值关系 | K6: =AND($E$6<$E$5,$E$5<$E$7) -> TRUE | L6: 下限 < 目标 < 上限
A7: 中债新综合 | B7: 0.75 | D7: 权益上限 | E7: 0.25 | G7: 无风险收益率 | H7: 0 | J7: 黄色数据完整性 | K7: =AND(COUNT($B$43:$E$1657)=ROWS($B$43:$B$1657)*4,MIN($B$43:$E$1657)>0) -> TRUE | L7: 四列全为正数
A8: 黄金 | B8: 0.05 | D8: 最短间隔（日） | E8: 7 | G8: 计费日基准 | H8: 365 | J8: 模型状态 | K8: =IF(AND(ABS($K$5-1)<0.0000001,$K$6,$K$7,ABS($O$19-1)<0.0000001),"OK","检查参数/数据") -> OK | L8: 仅OK时使用结果
A10: 可编辑说明：黄底蓝字为参数输入；绿字为对“净值底稿”的链接；黑字为计算公式。绩效及图表会随参数自动更新。
J12: 组合整体绩效 | N12: 红利持仓权重
J13: 累计收益率 | K13: =$AD$1657/$AD$43-1 -> 0.44164174 | N13: 红利低波 | O13: 0.8
J14: 算术年化收益率 | K14: =AVERAGE($AG$44:$AG$1657)*$H$6 -> 0.057350931 | N14: 中证红利 | O14: 0
J15: 年化波动率 | K15: =STDEV($AG$44:$AG$1657)*SQRT($H$6) -> 0.037045038 | N15: 港股通央企红利 | O15: 0
J16: 最大回撤 | K16: =MIN($AF$43:$AF$1657) -> -0.041737507 | N16: 红利低波100 | O16: 0
J17: Sharpe Ratio | K17: =IFERROR((K14-$H$7)/K15,"") -> 1.5481407 | N17: 徐彦 | O17: 0.1
J18: Calmar Ratio | K18: =IFERROR((POWER($AD$1657/$AD$43,$H$8/($A$1657-$A$43))-1)/ABS(K16),"") -> 1.351505 | N18: 綦缚鹏 | O18: 0.1
J19: 动平衡统计 | N19: 权重合计 | O19: =SUM(O13:O18) -> 1 | P19: =IF(ABS(O19-1)<0.0000001,"OK","权重需=100%") -> OK
J20: 定幅动平衡 | K20: =COUNTIF($T$43:$T$1657,"动态") -> 0
J21: 季度权益动平衡 | K21: =COUNTIF($T$43:$T$1657,"季度") -> 20
J22: 年末定期动平衡 | K22: =COUNTIF($T$43:$T$1657,"年末+季度") -> 6
J23: 期末权益权重 | K23: =($Z$1657+$AA$1657)/$AD$1657 -> 0.2078763
J24: 期末费后净值 | K24: =$AD$1657 -> 1.4416417
A28: 年度收益与月度胜率
A29: 年份 | B29: 1月 | C29: 2月 | D29: 3月 | E29: 4月 | F29: 5月 | G29: 6月 | H29: 7月 | I29: 8月 | J29: 9月 | K29: 10月 | L29: 11月 | M29: 12月 | N29: 年收益 | O29: 月胜率 | P29: 最大回撤
A30: 2020 | B30: =IF(COUNTIFS($AI$43:$AI$1657,$A30,$AJ$43:$AJ$1657,COLUMN()-1,$AK$43:$AK$1657,1)=0,"",SUMIFS($AM$43:$AM$1657,$AI$43:$AI$1657,$A30,$AJ$43:$AJ$1657,COLUMN()-1,$AK$43:$AK$1657,1)) -> 0.00096359723 | C30: =IF(COUNTIFS($AI$43:$AI$1657,$A30,$AJ$43:$AJ$1657,COLUMN()-1,$AK$43:$AK$1657,1)=0,"",SUMIFS($AM$43:$AM$1657,$AI$43:$AI$1657,$A30,$AJ$43:$AJ$1657,COLUMN()-1,$AK$43:$AK$1657,1)) -> 0.0112913 | D30: =IF(COUNTIFS($AI$43:$AI$1657,$A30,$AJ$43:$AJ$1657,COLUMN()-1,$AK$43:$AK$1657,1)=0,"",SUMIFS($AM$43:$AM$1657,$AI$43:$AI$1657,$A30,$AJ$43:$AJ$1657,COLUMN()-1,$AK$43:$AK$1657,1)) -> -0.0060703821 | E30: =IF(COUNTIFS($AI$43:$AI$1657,$A30,$AJ$43:$AJ$1657,COLUMN()-1,$AK$43:$AK$1657,1)=0,"",SUMIFS($AM$43:$AM$1657,$AI$43:$AI$1657,$A30,$AJ$43:$AJ$1657,COLUMN()-1,$AK$43:$AK$1657,1)) -> 0.023954077 | F30: =IF(COUNTIFS($AI$43:$AI$1657,$A30,$AJ$43:$AJ$1657,COLUMN()-1,$AK$43:$AK$1657,1)=0,"",SUMIFS($AM$43:$AM$1657,$AI$43:$AI$1657,$A30,$AJ$43:$AJ$1657,COLUMN()-1,$AK$43:$AK$1657,1)) -> -0.0062005489 | G30: =IF(COUNTIFS($AI$43:$AI$1657,$A30,$AJ$43:$AJ$1657,COLUMN()-1,$AK$43:$AK$1657,1)=0,"",SUMIFS($AM$43:$AM$1657,$AI$43:$AI$1657,$A30,$AJ$43:$AJ$1657,COLUMN()-1,$AK$43:$AK$1657,1)) -> 0.0044553895 | H30: =IF(COUNTIFS($AI$43:$AI$1657,$A30,$AJ$43:$AJ$1657,COLUMN()-1,$AK$43:$AK$1657,1)=0,"",SUMIFS($AM$43:$AM$1657,$AI$43:$AI$1657,$A30,$AJ$43:$AJ$1657,COLUMN()-1,$AK$43:$AK$1657,1)) -> 0.029688304 | I30: =IF(COUNTIFS($AI$43:$AI$1657,$A30,$AJ$43:$AJ$1657,COLUMN()-1,$AK$43:$AK$1657,1)=0,"",SUMIFS($AM$43:$AM$1657,$AI$43:$AI$1657,$A30,$AJ$43:$AJ$1657,COLUMN()-1,$AK$43:$AK$1657,1)) -> 0.0044158553 | ... M30: =IF(COUNTIFS($AI$43:$AI$1657,$A30,$AJ$43:$AJ$1657,COLUMN()-1,$AK$43:$AK$1657,1)=0,"",SUMIFS($AM$43:$AM$1657,$AI$43:$AI$1657,$A30,$AJ$43:$AJ$1657,COLUMN()-1,$AK$43:$AK$1657,1)) -> 0.0056641863 | N30: =IF(COUNT(B30:M30)=0,"",(1+B30)*(1+C30)*(1+D30)*(1+E30)*(1+F30)*(1+G30)*(1+H30)*(1+I30)*(1+J30)*(1+K30)*(1+L30)*(1+M30)-1) -> 0.063177012 | O30: =IFERROR(COUNTIF(B30:M30,">0")/COUNT(B30:M30),"") -> 0.75 | P30: =IF(COUNT($AO$43:$AO$285)=0,"",MIN($AO$43:$AO$285)) -> -0.030532648
A31: 2021 | B31: =IF(COUNTIFS($AI$43:$AI$1657,$A31,$AJ$43:$AJ$1657,COLUMN()-1,$AK$43:$AK$1657,1)=0,"",SUMIFS($AM$43:$AM$1657,$AI$43:$AI$1657,$A31,$AJ$43:$AJ$1657,COLUMN()-1,$AK$43:$AK$1657,1)) -> -0.0033357464 | C31: =IF(COUNTIFS($AI$43:$AI$1657,$A31,$AJ$43:$AJ$1657,COLUMN()-1,$AK$43:$AK$1657,1)=0,"",SUMIFS($AM$43:$AM$1657,$AI$43:$AI$1657,$A31,$AJ$43:$AJ$1657,COLUMN()-1,$AK$43:$AK$1657,1)) -> 0.004330097 | D31: =IF(COUNTIFS($AI$43:$AI$1657,$A31,$AJ$43:$AJ$1657,COLUMN()-1,$AK$43:$AK$1657,1)=0,"",SUMIFS($AM$43:$AM$1657,$AI$43:$AI$1657,$A31,$AJ$43:$AJ$1657,COLUMN()-1,$AK$43:$AK$1657,1)) -> 0.0045903649 | E31: =IF(COUNTIFS($AI$43:$AI$1657,$A31,$AJ$43:$AJ$1657,COLUMN()-1,$AK$43:$AK$1657,1)=0,"",SUMIFS($AM$43:$AM$1657,$AI$43:$AI$1657,$A31,$AJ$43:$AJ$1657,COLUMN()-1,$AK$43:$AK$1657,1)) -> 0.0089239742 | F31: =IF(COUNTIFS($AI$43:$AI$1657,$A31,$AJ$43:$AJ$1657,COLUMN()-1,$AK$43:$AK$1657,1)=0,"",SUMIFS($AM$43:$AM$1657,$AI$43:$AI$1657,$A31,$AJ$43:$AJ$1657,COLUMN()-1,$AK$43:$AK$1657,1)) -> 0.018065134 | G31: =IF(COUNTIFS($AI$43:$AI$1657,$A31,$AJ$43:$AJ$1657,COLUMN()-1,$AK$43:$AK$1657,1)=0,"",SUMIFS($AM$43:$AM$1657,$AI$43:$AI$1657,$A31,$AJ$43:$AJ$1657,COLUMN()-1,$AK$43:$AK$1657,1)) -> -0.0010621854 | H31: =IF(COUNTIFS($AI$43:$AI$1657,$A31,$AJ$43:$AJ$1657,COLUMN()-1,$AK$43:$AK$1657,1)=0,"",SUMIFS($AM$43:$AM$1657,$AI$43:$AI$1657,$A31,$AJ$43:$AJ$1657,COLUMN()-1,$AK$43:$AK$1657,1)) -> 0.0074235867 | I31: =IF(COUNTIFS($AI$43:$AI$1657,$A31,$AJ$43:$AJ$1657,COLUMN()-1,$AK$43:$AK$1657,1)=0,"",SUMIFS($AM$43:$AM$1657,$AI$43:$AI$1657,$A31,$AJ$43:$AJ$1657,COLUMN()-1,$AK$43:$AK$1657,1)) -> 0.017639723 | ... M31: =IF(COUNTIFS($AI$43:$AI$1657,$A31,$AJ$43:$AJ$1657,COLUMN()-1,$AK$43:$AK$1657,1)=0,"",SUMIFS($AM$43:$AM$1657,$AI$43:$AI$1657,$A31,$AJ$43:$AJ$1657,COLUMN()-1,$AK$43:$AK$1657,1)) -> 0.010624957 | N31: =IF(COUNT(B31:M31)=0,"",(1+B31)*(1+C31)*(1+D31)*(1+E31)*(1+F31)*(1+G31)*(1+H31)*(1+I31)*(1+J31)*(1+K31)*(1+L31)*(1+M31)-1) -> 0.070077553 | O31: =IFERROR(COUNTIF(B31:M31,">0")/COUNT(B31:M31),"") -> 0.66666667 | P31: =IF(COUNT($AO$286:$AO$528)=0,"",MIN($AO$286:$AO$528)) -> -0.024596451
A32: 2022 | B32: =IF(COUNTIFS($AI$43:$AI$1657,$A32,$AJ$43:$AJ$1657,COLUMN()-1,$AK$43:$AK$1657,1)=0,"",SUMIFS($AM$43:$AM$1657,$AI$43:$AI$1657,$A32,$AJ$43:$AJ$1657,COLUMN()-1,$AK$43:$AK$1657,1)) -> -0.007282286 | C32: =IF(COUNTIFS($AI$43:$AI$1657,$A32,$AJ$43:$AJ$1657,COLUMN()-1,$AK$43:$AK$1657,1)=0,"",SUMIFS($AM$43:$AM$1657,$AI$43:$AI$1657,$A32,$AJ$43:$AJ$1657,COLUMN()-1,$AK$43:$AK$1657,1)) -> 0.0066829471 | D32: =IF(COUNTIFS($AI$43:$AI$1657,$A32,$AJ$43:$AJ$1657,COLUMN()-1,$AK$43:$AK$1657,1)=0,"",SUMIFS($AM$43:$AM$1657,$AI$43:$AI$1657,$A32,$AJ$43:$AJ$1657,COLUMN()-1,$AK$43:$AK$1657,1)) -> -0.0054066174 | E32: =IF(COUNTIFS($AI$43:$AI$1657,$A32,$AJ$43:$AJ$1657,COLUMN()-1,$AK$43:$AK$1657,1)=0,"",SUMIFS($AM$43:$AM$1657,$AI$43:$AI$1657,$A32,$AJ$43:$AJ$1657,COLUMN()-1,$AK$43:$AK$1657,1)) -> -0.0081474496 | F32: =IF(COUNTIFS($AI$43:$AI$1657,$A32,$AJ$43:$AJ$1657,COLUMN()-1,$AK$43:$AK$1657,1)=0,"",SUMIFS($AM$43:$AM$1657,$AI$43:$AI$1657,$A32,$AJ$43:$AJ$1657,COLUMN()-1,$AK$43:$AK$1657,1)) -> 0.011586914 | G32: =IF(COUNTIFS($AI$43:$AI$1657,$A32,$AJ$43:$AJ$1657,COLUMN()-1,$AK$43:$AK$1657,1)=0,"",SUMIFS($AM$43:$AM$1657,$AI$43:$AI$1657,$A32,$AJ$43:$AJ$1657,COLUMN()-1,$AK$43:$AK$1657,1)) -> 0.0074979779 | H32: =IF(COUNTIFS($AI$43:$AI$1657,$A32,$AJ$43:$AJ$1657,COLUMN()-1,$AK$43:$AK$1657,1)=0,"",SUMIFS($AM$43:$AM$1657,$AI$43:$AI$1657,$A32,$AJ$43:$AJ$1657,COLUMN()-1,$AK$43:$AK$1657,1)) -> 0.0011161724 | I32: =IF(COUNTIFS($AI$43:$AI$1657,$A32,$AJ$43:$AJ$1657,COLUMN()-1,$AK$43:$AK$1657,1)=0,"",SUMIFS($AM$43:$AM$1657,$AI$43:$AI$1657,$A32,$AJ$43:$AJ$1657,COLUMN()-1,$AK$43:$AK$1657,1)) -> 0.0047231574 | ... M32: =IF(COUNTIFS($AI$43:$AI$1657,$A32,$AJ$43:$AJ$1657,COLUMN()-1,$AK$43:$AK$1657,1)=0,"",SUMIFS($AM$43:$AM$1657,$AI$43:$AI$1657,$A32,$AJ$43:$AJ$1657,COLUMN()-1,$AK$43:$AK$1657,1)) -> -0.006159832 | N32: =IF(COUNT(B32:M32)=0,"",(1+B32)*(1+C32)*(1+D32)*(1+E32)*(1+F32)*(1+G32)*(1+H32)*(1+I32)*(1+J32)*(1+K32)*(1+L32)*(1+M32)-1) -> 0.0015535467 | O32: =IFERROR(COUNTIF(B32:M32,">0")/COUNT(B32:M32),"") -> 0.5 | P32: =IF(COUNT($AO$529:$AO$770)=0,"",MIN($AO$529:$AO$770)) -> -0.027286743
A33: 2023 | B33: =IF(COUNTIFS($AI$43:$AI$1657,$A33,$AJ$43:$AJ$1657,COLUMN()-1,$AK$43:$AK$1657,1)=0,"",SUMIFS($AM$43:$AM$1657,$AI$43:$AI$1657,$A33,$AJ$43:$AJ$1657,COLUMN()-1,$AK$43:$AK$1657,1)) -> 0.012674431 | C33: =IF(COUNTIFS($AI$43:$AI$1657,$A33,$AJ$43:$AJ$1657,COLUMN()-1,$AK$43:$AK$1657,1)=0,"",SUMIFS($AM$43:$AM$1657,$AI$43:$AI$1657,$A33,$AJ$43:$AJ$1657,COLUMN()-1,$AK$43:$AK$1657,1)) -> 0.0057608021 | D33: =IF(COUNTIFS($AI$43:$AI$1657,$A33,$AJ$43:$AJ$1657,COLUMN()-1,$AK$43:$AK$1657,1)=0,"",SUMIFS($AM$43:$AM$1657,$AI$43:$AI$1657,$A33,$AJ$43:$AJ$1657,COLUMN()-1,$AK$43:$AK$1657,1)) -> 0.006764364 | E33: =IF(COUNTIFS($AI$43:$AI$1657,$A33,$AJ$43:$AJ$1657,COLUMN()-1,$AK$43:$AK$1657,1)=0,"",SUMIFS($AM$43:$AM$1657,$AI$43:$AI$1657,$A33,$AJ$43:$AJ$1657,COLUMN()-1,$AK$43:$AK$1657,1)) -> 0.0083588869 | F33: =IF(COUNTIFS($AI$43:$AI$1657,$A33,$AJ$43:$AJ$1657,COLUMN()-1,$AK$43:$AK$1657,1)=0,"",SUMIFS($AM$43:$AM$1657,$AI$43:$AI$1657,$A33,$AJ$43:$AJ$1657,COLUMN()-1,$AK$43:$AK$1657,1)) -> -0.00020804953 | G33: =IF(COUNTIFS($AI$43:$AI$1657,$A33,$AJ$43:$AJ$1657,COLUMN()-1,$AK$43:$AK$1657,1)=0,"",SUMIFS($AM$43:$AM$1657,$AI$43:$AI$1657,$A33,$AJ$43:$AJ$1657,COLUMN()-1,$AK$43:$AK$1657,1)) -> 0.0035596835 | H33: =IF(COUNTIFS($AI$43:$AI$1657,$A33,$AJ$43:$AJ$1657,COLUMN()-1,$AK$43:$AK$1657,1)=0,"",SUMIFS($AM$43:$AM$1657,$AI$43:$AI$1657,$A33,$AJ$43:$AJ$1657,COLUMN()-1,$AK$43:$AK$1657,1)) -> 0.008833121 | I33: =IF(COUNTIFS($AI$43:$AI$1657,$A33,$AJ$43:$AJ$1657,COLUMN()-1,$AK$43:$AK$1657,1)=0,"",SUMIFS($AM$43:$AM$1657,$AI$43:$AI$1657,$A33,$AJ$43:$AJ$1657,COLUMN()-1,$AK$43:$AK$1657,1)) -> -0.0031052515 | ... M33: =IF(COUNTIFS($AI$43:$AI$1657,$A33,$AJ$43:$AJ$1657,COLUMN()-1,$AK$43:$AK$1657,1)=0,"",SUMIFS($AM$43:$AM$1657,$AI$43:$AI$1657,$A33,$AJ$43:$AJ$1657,COLUMN()-1,$AK$43:$AK$1657,1)) -> 0.0053617026 | N33: =IF(COUNT(B33:M33)=0,"",(1+B33)*(1+C33)*(1+D33)*(1+E33)*(1+F33)*(1+G33)*(1+H33)*(1+I33)*(1+J33)*(1+K33)*(1+L33)*(1+M33)-1) -> 0.045220711 | O33: =IFERROR(COUNTIF(B33:M33,">0")/COUNT(B33:M33),"") -> 0.66666667 | P33: =IF(COUNT($AO$771:$AO$1012)=0,"",MIN($AO$771:$AO$1012)) -> -0.017723311
A34: 2024 | B34: =IF(COUNTIFS($AI$43:$AI$1657,$A34,$AJ$43:$AJ$1657,COLUMN()-1,$AK$43:$AK$1657,1)=0,"",SUMIFS($AM$43:$AM$1657,$AI$43:$AI$1657,$A34,$AJ$43:$AJ$1657,COLUMN()-1,$AK$43:$AK$1657,1)) -> -0.0066473448 | C34: =IF(COUNTIFS($AI$43:$AI$1657,$A34,$AJ$43:$AJ$1657,COLUMN()-1,$AK$43:$AK$1657,1)=0,"",SUMIFS($AM$43:$AM$1657,$AI$43:$AI$1657,$A34,$AJ$43:$AJ$1657,COLUMN()-1,$AK$43:$AK$1657,1)) -> 0.017839135 | D34: =IF(COUNTIFS($AI$43:$AI$1657,$A34,$AJ$43:$AJ$1657,COLUMN()-1,$AK$43:$AK$1657,1)=0,"",SUMIFS($AM$43:$AM$1657,$AI$43:$AI$1657,$A34,$AJ$43:$AJ$1657,COLUMN()-1,$AK$43:$AK$1657,1)) -> 0.0092416276 | E34: =IF(COUNTIFS($AI$43:$AI$1657,$A34,$AJ$43:$AJ$1657,COLUMN()-1,$AK$43:$AK$1657,1)=0,"",SUMIFS($AM$43:$AM$1657,$AI$43:$AI$1657,$A34,$AJ$43:$AJ$1657,COLUMN()-1,$AK$43:$AK$1657,1)) -> 0.0089521037 | F34: =IF(COUNTIFS($AI$43:$AI$1657,$A34,$AJ$43:$AJ$1657,COLUMN()-1,$AK$43:$AK$1657,1)=0,"",SUMIFS($AM$43:$AM$1657,$AI$43:$AI$1657,$A34,$AJ$43:$AJ$1657,COLUMN()-1,$AK$43:$AK$1657,1)) -> 0.0064669991 | G34: =IF(COUNTIFS($AI$43:$AI$1657,$A34,$AJ$43:$AJ$1657,COLUMN()-1,$AK$43:$AK$1657,1)=0,"",SUMIFS($AM$43:$AM$1657,$AI$43:$AI$1657,$A34,$AJ$43:$AJ$1657,COLUMN()-1,$AK$43:$AK$1657,1)) -> -0.003046566 | H34: =IF(COUNTIFS($AI$43:$AI$1657,$A34,$AJ$43:$AJ$1657,COLUMN()-1,$AK$43:$AK$1657,1)=0,"",SUMIFS($AM$43:$AM$1657,$AI$43:$AI$1657,$A34,$AJ$43:$AJ$1657,COLUMN()-1,$AK$43:$AK$1657,1)) -> 0.0028398787 | I34: =IF(COUNTIFS($AI$43:$AI$1657,$A34,$AJ$43:$AJ$1657,COLUMN()-1,$AK$43:$AK$1657,1)=0,"",SUMIFS($AM$43:$AM$1657,$AI$43:$AI$1657,$A34,$AJ$43:$AJ$1657,COLUMN()-1,$AK$43:$AK$1657,1)) -> -0.004809862 | ... M34: =IF(COUNTIFS($AI$43:$AI$1657,$A34,$AJ$43:$AJ$1657,COLUMN()-1,$AK$43:$AK$1657,1)=0,"",SUMIFS($AM$43:$AM$1657,$AI$43:$AI$1657,$A34,$AJ$43:$AJ$1657,COLUMN()-1,$AK$43:$AK$1657,1)) -> 0.014460184 | N34: =IF(COUNT(B34:M34)=0,"",(1+B34)*(1+C34)*(1+D34)*(1+E34)*(1+F34)*(1+G34)*(1+H34)*(1+I34)*(1+J34)*(1+K34)*(1+L34)*(1+M34)-1) -> 0.090598365 | O34: =IFERROR(COUNTIF(B34:M34,">0")/COUNT(B34:M34),"") -> 0.75 | P34: =IF(COUNT($AO$1013:$AO$1254)=0,"",MIN($AO$1013:$AO$1254)) -> -0.01603913
A35: 2025 | B35: =IF(COUNTIFS($AI$43:$AI$1657,$A35,$AJ$43:$AJ$1657,COLUMN()-1,$AK$43:$AK$1657,1)=0,"",SUMIFS($AM$43:$AM$1657,$AI$43:$AI$1657,$A35,$AJ$43:$AJ$1657,COLUMN()-1,$AK$43:$AK$1657,1)) -> 0.0032113089 | C35: =IF(COUNTIFS($AI$43:$AI$1657,$A35,$AJ$43:$AJ$1657,COLUMN()-1,$AK$43:$AK$1657,1)=0,"",SUMIFS($AM$43:$AM$1657,$AI$43:$AI$1657,$A35,$AJ$43:$AJ$1657,COLUMN()-1,$AK$43:$AK$1657,1)) -> -0.00069684713 | D35: =IF(COUNTIFS($AI$43:$AI$1657,$A35,$AJ$43:$AJ$1657,COLUMN()-1,$AK$43:$AK$1657,1)=0,"",SUMIFS($AM$43:$AM$1657,$AI$43:$AI$1657,$A35,$AJ$43:$AJ$1657,COLUMN()-1,$AK$43:$AK$1657,1)) -> 0.0084246851 | E35: =IF(COUNTIFS($AI$43:$AI$1657,$A35,$AJ$43:$AJ$1657,COLUMN()-1,$AK$43:$AK$1657,1)=0,"",SUMIFS($AM$43:$AM$1657,$AI$43:$AI$1657,$A35,$AJ$43:$AJ$1657,COLUMN()-1,$AK$43:$AK$1657,1)) -> 0.0093598074 | F35: =IF(COUNTIFS($AI$43:$AI$1657,$A35,$AJ$43:$AJ$1657,COLUMN()-1,$AK$43:$AK$1657,1)=0,"",SUMIFS($AM$43:$AM$1657,$AI$43:$AI$1657,$A35,$AJ$43:$AJ$1657,COLUMN()-1,$AK$43:$AK$1657,1)) -> 0.0053420523 | G35: =IF(COUNTIFS($AI$43:$AI$1657,$A35,$AJ$43:$AJ$1657,COLUMN()-1,$AK$43:$AK$1657,1)=0,"",SUMIFS($AM$43:$AM$1657,$AI$43:$AI$1657,$A35,$AJ$43:$AJ$1657,COLUMN()-1,$AK$43:$AK$1657,1)) -> 0.010633644 | H35: =IF(COUNTIFS($AI$43:$AI$1657,$A35,$AJ$43:$AJ$1657,COLUMN()-1,$AK$43:$AK$1657,1)=0,"",SUMIFS($AM$43:$AM$1657,$AI$43:$AI$1657,$A35,$AJ$43:$AJ$1657,COLUMN()-1,$AK$43:$AK$1657,1)) -> 0.0057259672 | I35: =IF(COUNTIFS($AI$43:$AI$1657,$A35,$AJ$43:$AJ$1657,COLUMN()-1,$AK$43:$AK$1657,1)=0,"",SUMIFS($AM$43:$AM$1657,$AI$43:$AI$1657,$A35,$AJ$43:$AJ$1657,COLUMN()-1,$AK$43:$AK$1657,1)) -> 0.010183832 | ... M35: =IF(COUNTIFS($AI$43:$AI$1657,$A35,$AJ$43:$AJ$1657,COLUMN()-1,$AK$43:$AK$1657,1)=0,"",SUMIFS($AM$43:$AM$1657,$AI$43:$AI$1657,$A35,$AJ$43:$AJ$1657,COLUMN()-1,$AK$43:$AK$1657,1)) -> 0.0045875477 | N35: =IF(COUNT(B35:M35)=0,"",(1+B35)*(1+C35)*(1+D35)*(1+E35)*(1+F35)*(1+G35)*(1+H35)*(1+I35)*(1+J35)*(1+K35)*(1+L35)*(1+M35)-1) -> 0.078462842 | O35: =IFERROR(COUNTIF(B35:M35,">0")/COUNT(B35:M35),"") -> 0.91666667 | P35: =IF(COUNT($AO$1255:$AO$1497)=0,"",MIN($AO$1255:$AO$1497)) -> -0.014943698
A36: 2026 | B36: =IF(COUNTIFS($AI$43:$AI$1657,$A36,$AJ$43:$AJ$1657,COLUMN()-1,$AK$43:$AK$1657,1)=0,"",SUMIFS($AM$43:$AM$1657,$AI$43:$AI$1657,$A36,$AJ$43:$AJ$1657,COLUMN()-1,$AK$43:$AK$1657,1)) -> 0.031115759 | C36: =IF(COUNTIFS($AI$43:$AI$1657,$A36,$AJ$43:$AJ$1657,COLUMN()-1,$AK$43:$AK$1657,1)=0,"",SUMIFS($AM$43:$AM$1657,$AI$43:$AI$1657,$A36,$AJ$43:$AJ$1657,COLUMN()-1,$AK$43:$AK$1657,1)) -> 0.0027197385 | D36: =IF(COUNTIFS($AI$43:$AI$1657,$A36,$AJ$43:$AJ$1657,COLUMN()-1,$AK$43:$AK$1657,1)=0,"",SUMIFS($AM$43:$AM$1657,$AI$43:$AI$1657,$A36,$AJ$43:$AJ$1657,COLUMN()-1,$AK$43:$AK$1657,1)) -> -0.019590338 | E36: =IF(COUNTIFS($AI$43:$AI$1657,$A36,$AJ$43:$AJ$1657,COLUMN()-1,$AK$43:$AK$1657,1)=0,"",SUMIFS($AM$43:$AM$1657,$AI$43:$AI$1657,$A36,$AJ$43:$AJ$1657,COLUMN()-1,$AK$43:$AK$1657,1)) -> 0.012613208 | F36: =IF(COUNTIFS($AI$43:$AI$1657,$A36,$AJ$43:$AJ$1657,COLUMN()-1,$AK$43:$AK$1657,1)=0,"",SUMIFS($AM$43:$AM$1657,$AI$43:$AI$1657,$A36,$AJ$43:$AJ$1657,COLUMN()-1,$AK$43:$AK$1657,1)) -> -0.00045978072 | G36: =IF(COUNTIFS($AI$43:$AI$1657,$A36,$AJ$43:$AJ$1657,COLUMN()-1,$AK$43:$AK$1657,1)=0,"",SUMIFS($AM$43:$AM$1657,$AI$43:$AI$1657,$A36,$AJ$43:$AJ$1657,COLUMN()-1,$AK$43:$AK$1657,1)) -> -0.011497386 | H36: =IF(COUNTIFS($AI$43:$AI$1657,$A36,$AJ$43:$AJ$1657,COLUMN()-1,$AK$43:$AK$1657,1)=0,"",SUMIFS($AM$43:$AM$1657,$AI$43:$AI$1657,$A36,$AJ$43:$AJ$1657,COLUMN()-1,$AK$43:$AK$1657,1)) -> -0.0033978789 | I36: =IF(COUNTIFS($AI$43:$AI$1657,$A36,$AJ$43:$AJ$1657,COLUMN()-1,$AK$43:$AK$1657,1)=0,"",SUMIFS($AM$43:$AM$1657,$AI$43:$AI$1657,$A36,$AJ$43:$AJ$1657,COLUMN()-1,$AK$43:$AK$1657,1)) -> 0.018230838 | ... M36: =IF(COUNTIFS($AI$43:$AI$1657,$A36,$AJ$43:$AJ$1657,COLUMN()-1,$AK$43:$AK$1657,1)=0,"",SUMIFS($AM$43:$AM$1657,$AI$43:$AI$1657,$A36,$AJ$43:$AJ$1657,COLUMN()-1,$AK$43:$AK$1657,1)) | N36: =IF(COUNT(B36:M36)=0,"",(1+B36)*(1+C36)*(1+D36)*(1+E36)*(1+F36)*(1+G36)*(1+H36)*(1+I36)-1) -> 0.029163341 | O36: =IFERROR(COUNTIF(B36:M36,">0")/COUNT(B36:M36),"") -> 0.5 | P36: =IF(COUNT($AO$1498:$AO$1657)=0,"",MIN($AO$1498:$AO$1657)) -> -0.041737507
A37: 成立以来 | N37: =$AD$1657/$AD$43-1 -> 0.44164174 | O37: =IFERROR(COUNTIF($AM$43:$AM$1657,">0")/COUNT($AM$43:$AM$1657),"") -> 0.6875 | P37: =MIN($AF$43:$AF$1657) -> -0.041737507
A40: 逐日回测计算（全公式，可追溯）
A41: 流程：读取黄色净值→计算单资产日收益→当日涨跌后权重→再平衡判断→持仓调整→按实际日历天数扣费→费后净值与回撤。
A42: 日期 | B42: 红利净值 | C42: 指增净值 | D42: 中债净值 | E42: 黄金净值 | F42: 红利日收益 | G42: 指增日收益 | H42: 中债日收益 | I42: 黄金日收益 | J42: 红利调前持仓 | K42: 指增调前持仓 | L42: 中债调前持仓 | M42: 黄金调前持仓 | N42: 费前组合价值 | O42: 调前权益权重 | P42: 年末标记 | Q42: 季末标记 | R42: 动态触发 | S42: 间隔允许 | T42: 再平衡动作 | U42: 红利费前 | V42: 指增调后费前 | W42: 中债调后费前 | X42: 黄金调后费前 | Y42: 扣费因子 | Z42: 红利费后持仓 | AA42: 指增费后持仓 | AB42: 中债费后持仓 | AC42: 黄金费后持仓 | AD42: 费后净值 | AE42: 历史峰值 | AF42: 回撤 | AG42: 组合日收益 | AH42: 最近调仓日 | AI42: 年 | AJ42: 月 | AK42: 月末标记 | AL42: 上月末净值 | AM42: 月收益 | AN42: 年内峰值 | AO42: 年内回撤 | AP42: 权重合计 | AQ42: 数据有效 | AR42: 月份日期 | AS42: 月份标签 | AT42: 月末费后净值
A43: =净值底稿!A4 -> 43832 | B43: =净值底稿!X4 -> 1 | C43: =净值底稿!U4 -> 1.0173101 | D43: =净值底稿!V4 -> 1.4008 | E43: =净值底稿!W4 -> 1.2499 | F43: 0 | G43: 0 | H43: 0 | I43: 0 | J43: =$B$5 -> 0.1 | K43: =$B$6 -> 0.1 | L43: =$B$7 -> 0.75 | M43: =$B$8 -> 0.05 | N43: =SUM(J43:M43) -> 1 | O43: =IFERROR((J43+K43)/N43,0) -> 0.2 | P43: =AND(MONTH(A43)=12,OR(A44="",YEAR(A43)<>YEAR(A44))) -> FALSE | Q43: =AND(MOD(MONTH(A43),3)=0,OR(A44="",MONTH(A43)<>MONTH(A44))) -> FALSE | R43: =OR(O43>$E$7,O43<$E$6) -> FALSE | S43: =FALSE() -> FALSE | T43: 初始配置 | U43: =IF(OR(T43="年末+季度",T43="季度+动态"),N43*$E$5/2,IF(T43="季度",(J43+K43)/2,IF(T43="动态",N43*$E$5*IF(J43+K43=0,0.5,J43/(J43+K43)),J43))) -> 0.1 | V43: =IF(OR(T43="年末+季度",T43="季度+动态"),N43*$E$5/2,IF(T43="季度",(J43+K43)/2,IF(T43="动态",N43*$E$5*IF(J43+K43=0,0.5,K43/(J43+K43)),K43))) -> 0.1 | W43: =IF(OR(T43="年末+季度",T43="季度+动态",T43="动态"),N43*(1-$E$5)*IF(L43+M43=0,$B$7/($B$7+$B$8),L43/(L43+M43)),L43) -> 0.75 | X43: =IF(OR(T43="年末+季度",T43="季度+动态",T43="动态"),N43*(1-$E$5)*IF(L43+M43=0,$B$8/($B$7+$B$8),M43/(L43+M43)),M43) -> 0.05 | Y43: 1 | Z43: =U43*Y43 -> 0.1 | AA43: =V43*Y43 -> 0.1 | AB43: =W43*Y43 -> 0.75 | AC43: =X43*Y43 -> 0.05 | AD43: =SUM(Z43:AC43) -> 1 | AE43: =AD43 -> 1 | AF43: =AD43/AE43-1 -> 0 | AH43: =A43 -> 43832 | AI43: =YEAR(A43) -> 2020 | AJ43: =MONTH(A43) -> 1 | AK43: =IF(MONTH(A43)<>MONTH(A44),1,0) -> 0 | AL43: =AD43 -> 1 | AM43: =IF(AK43,AD43/AL43-1,"") | AN43: =AD43 -> 1 | AO43: =AD43/AN43-1 -> 0 | AP43: =IFERROR(SUM(Z43:AC43)/AD43,0) -> 1 | AQ43: =AND(B43>0,C43>0,D43>0,E43>0) -> TRUE | AR43: =DATE(YEAR($A$43),MONTH($A$43),1) -> 43831 | AS43: =TEXT(AR43,"yyyy-mm") -> 2020-01 | AT43: =IF(AR43>DATE(YEAR($A$1657),MONTH($A$1657),1),"",SUMIFS($AD$43:$AD$1657,$AI$43:$AI$1657,YEAR(AR43),$AJ$43:$AJ$1657,MONTH(AR43),$AK$43:$AK$1657,1)) -> 1.0009636
A44: =净值底稿!A5 -> 43833 | B44: =净值底稿!X5 -> 0.99895473 | C44: =净值底稿!U5 -> 1.0202139 | D44: =净值底稿!V5 -> 1.4011 | E44: =净值底稿!W5 -> 1.269 | F44: =IFERROR(B44/B43-1,0) -> -0.0010452746 | G44: =IFERROR(C44/C43-1,0) -> 0.0028544122 | H44: =IFERROR(D44/D43-1,0) -> 0.00021416334 | I44: =IFERROR(E44/E43-1,0) -> 0.015281222 | J44: =Z43*(1+F44) -> 0.099895473 | K44: =AA43*(1+G44) -> 0.10028544 | L44: =AB43*(1+H44) -> 0.75016062 | M44: =AC43*(1+I44) -> 0.050764061 | N44: =SUM(J44:M44) -> 1.0011056 | O44: =IFERROR((J44+K44)/N44,0) -> 0.19995984 | P44: =AND(MONTH(A44)=12,OR(A45="",YEAR(A44)<>YEAR(A45))) -> FALSE | Q44: =AND(MOD(MONTH(A44),3)=0,OR(A45="",MONTH(A44)<>MONTH(A45))) -> FALSE | R44: =OR(O44>$E$7,O44<$E$6) -> FALSE | S44: =AND(OR(P44,Q44,R44),A44-AH43>$E$8) -> FALSE | T44: =IF(NOT(OR(P44,Q44,R44)),"不调",IF(NOT(S44),"间隔规则跳过",IF(P44,"年末+季度",IF(AND(Q44,R44),"季度+动态",IF(Q44,"季度","动态"))))) -> 不调 | U44: =IF(OR(T44="年末+季度",T44="季度+动态"),N44*$E$5/2,IF(T44="季度",(J44+K44)/2,IF(T44="动态",N44*$E$5*IF(J44+K44=0,0.5,J44/(J44+K44)),J44))) -> 0.099895473 | V44: =IF(OR(T44="年末+季度",T44="季度+动态"),N44*$E$5/2,IF(T44="季度",(J44+K44)/2,IF(T44="动态",N44*$E$5*IF(J44+K44=0,0.5,K44/(J44+K44)),K44))) -> 0.10028544 | W44: =IF(OR(T44="年末+季度",T44="季度+动态",T44="动态"),N44*(1-$E$5)*IF(L44+M44=0,$B$7/($B$7+$B$8),L44/(L44+M44)),L44) -> 0.75016062 | X44: =IF(OR(T44="年末+季度",T44="季度+动态",T44="动态"),N44*(1-$E$5)*IF(L44+M44=0,$B$8/($B$7+$B$8),M44/(L44+M44)),M44) -> 0.050764061 | Y44: =POWER(1-$H$5,(A44-A43)/$H$8) -> 0.99998627 | Z44: =U44*Y44 -> 0.099894101 | AA44: =V44*Y44 -> 0.10028406 | AB44: =W44*Y44 -> 0.75015032 | AC44: =X44*Y44 -> 0.050763364 | AD44: =SUM(Z44:AC44) -> 1.0010918 | AE44: =MAX(AE43,AD44) -> 1.0010918 | AF44: =AD44/AE44-1 -> 0 | AG44: =AD44/AD43-1 -> 0.0010918493 | AH44: =IF(OR(T44="年末+季度",T44="季度+动态",T44="季度",T44="动态"),A44,AH43) -> 43832 | AI44: =YEAR(A44) -> 2020 | AJ44: =MONTH(A44) -> 1 | AK44: =IF(MONTH(A44)<>MONTH(A45),1,0) -> 0 | AL44: =IF(AK43,AD43,AL43) -> 1 | AM44: =IF(AK44,AD44/AL44-1,"") | AN44: =IF(AI44<>AI43,AD44,MAX(AN43,AD44)) -> 1.0010918 | AO44: =AD44/AN44-1 -> 0 | AP44: =IFERROR(SUM(Z44:AC44)/AD44,0) -> 1 | AQ44: =AND(B44>0,C44>0,D44>0,E44>0) -> TRUE | AR44: =EDATE(AR43,1) -> 43862 | AS44: =TEXT(AR44,"yyyy-mm") -> 2020-02 | AT44: =IF(AR44>DATE(YEAR($A$1657),MONTH($A$1657),1),"",SUMIFS($AD$43:$AD$1657,$AI$43:$AI$1657,YEAR(AR44),$AJ$43:$AJ$1657,MONTH(AR44),$AK$43:$AK$1657,1)) -> 1.0122658
A45: =净值底稿!A6 -> 43836 | B45: =净值底稿!X6 -> 0.99630297 | C45: =净值底稿!U6 -> 1.0263972 | D45: =净值底稿!V6 -> 1.4023 | E45: =净值底稿!W6 -> 1.2957 | F45: =IFERROR(B45/B44-1,0) -> -0.0026545336 | G45: =IFERROR(C45/C44-1,0) -> 0.0060607591 | H45: =IFERROR(D45/D44-1,0) -> 0.00085646992 | I45: =IFERROR(E45/E44-1,0) -> 0.021040189 | J45: =Z44*(1+F45) -> 0.099628928 | K45: =AA44*(1+G45) -> 0.10089186 | L45: =AB44*(1+H45) -> 0.7507928 | M45: =AC44*(1+I45) -> 0.051831435 | N45: =SUM(J45:M45) -> 1.003145 | O45: =IFERROR((J45+K45)/N45,0) -> 0.19989212 | P45: =AND(MONTH(A45)=12,OR(A46="",YEAR(A45)<>YEAR(A46))) -> FALSE | Q45: =AND(MOD(MONTH(A45),3)=0,OR(A46="",MONTH(A45)<>MONTH(A46))) -> FALSE | R45: =OR(O45>$E$7,O45<$E$6) -> FALSE | S45: =AND(OR(P45,Q45,R45),A45-AH44>$E$8) -> FALSE | T45: =IF(NOT(OR(P45,Q45,R45)),"不调",IF(NOT(S45),"间隔规则跳过",IF(P45,"年末+季度",IF(AND(Q45,R45),"季度+动态",IF(Q45,"季度","动态"))))) -> 不调 | U45: =IF(OR(T45="年末+季度",T45="季度+动态"),N45*$E$5/2,IF(T45="季度",(J45+K45)/2,IF(T45="动态",N45*$E$5*IF(J45+K45=0,0.5,J45/(J45+K45)),J45))) -> 0.099628928 | V45: =IF(OR(T45="年末+季度",T45="季度+动态"),N45*$E$5/2,IF(T45="季度",(J45+K45)/2,IF(T45="动态",N45*$E$5*IF(J45+K45=0,0.5,K45/(J45+K45)),K45))) -> 0.10089186 | W45: =IF(OR(T45="年末+季度",T45="季度+动态",T45="动态"),N45*(1-$E$5)*IF(L45+M45=0,$B$7/($B$7+$B$8),L45/(L45+M45)),L45) -> 0.7507928 | X45: =IF(OR(T45="年末+季度",T45="季度+动态",T45="动态"),N45*(1-$E$5)*IF(L45+M45=0,$B$8/($B$7+$B$8),M45/(L45+M45)),M45) -> 0.051831435 | Y45: =POWER(1-$H$5,(A45-A44)/$H$8) -> 0.9999588 | Z45: =U45*Y45 -> 0.099624824 | AA45: =V45*Y45 -> 0.10088771 | AB45: =W45*Y45 -> 0.75076187 | AC45: =X45*Y45 -> 0.051829299 | AD45: =SUM(Z45:AC45) -> 1.0031037 | AE45: =MAX(AE44,AD45) -> 1.0031037 | AF45: =AD45/AE45-1 -> 0 | AG45: =AD45/AD44-1 -> 0.0020096553 | AH45: =IF(OR(T45="年末+季度",T45="季度+动态",T45="季度",T45="动态"),A45,AH44) -> 43832 | AI45: =YEAR(A45) -> 2020 | AJ45: =MONTH(A45) -> 1 | AK45: =IF(MONTH(A45)<>MONTH(A46),1,0) -> 0 | AL45: =IF(AK44,AD44,AL44) -> 1 | AM45: =IF(AK45,AD45/AL45-1,"") | AN45: =IF(AI45<>AI44,AD45,MAX(AN44,AD45)) -> 1.0031037 | AO45: =AD45/AN45-1 -> 0 | AP45: =IFERROR(SUM(Z45:AC45)/AD45,0) -> 1 | AQ45: =AND(B45>0,C45>0,D45>0,E45>0) -> TRUE | AR45: =EDATE(AR44,1) -> 43891 | AS45: =TEXT(AR45,"yyyy-mm") -> 2020-03 | AT45: =IF(AR45>DATE(YEAR($A$1657),MONTH($A$1657),1),"",SUMIFS($AD$43:$AD$1657,$AI$43:$AI$1657,YEAR(AR45),$AJ$43:$AJ$1657,MONTH(AR45),$AK$43:$AK$1657,1)) -> 1.0061209
A46: =净值底稿!A7 -> 43837 | B46: =净值底稿!X7 -> 1.0025957 | C46: =净值底稿!U7 -> 1.0393231 | D46: =净值底稿!V7 -> 1.4024 | E46: =净值底稿!W7 -> 1.2848 | F46: =IFERROR(B46/B45-1,0) -> 0.0063160441 | G46: =IFERROR(C46/C45-1,0) -> 0.012593517 | H46: =IFERROR(D46/D45-1,0) -> 7.1311417e-05 | I46: =IFERROR(E46/E45-1,0) -> -0.0084124412 | J46: =Z45*(1+F46) -> 0.10025406 | K46: =AA45*(1+G46) -> 0.10215824 | L46: =AB45*(1+H46) -> 0.75081541 | M46: =AC45*(1+I46) -> 0.051393288 | N46: =SUM(J46:M46) -> 1.004621 | O46: =IFERROR((J46+K46)/N46,0) -> 0.20148125 | P46: =AND(MONTH(A46)=12,OR(A47="",YEAR(A46)<>YEAR(A47))) -> FALSE | Q46: =AND(MOD(MONTH(A46),3)=0,OR(A47="",MONTH(A46)<>MONTH(A47))) -> FALSE | R46: =OR(O46>$E$7,O46<$E$6) -> FALSE | S46: =AND(OR(P46,Q46,R46),A46-AH45>$E$8) -> FALSE | T46: =IF(NOT(OR(P46,Q46,R46)),"不调",IF(NOT(S46),"间隔规则跳过",IF(P46,"年末+季度",IF(AND(Q46,R46),"季度+动态",IF(Q46,"季度","动态"))))) -> 不调 | U46: =IF(OR(T46="年末+季度",T46="季度+动态"),N46*$E$5/2,IF(T46="季度",(J46+K46)/2,IF(T46="动态",N46*$E$5*IF(J46+K46=0,0.5,J46/(J46+K46)),J46))) -> 0.10025406 | V46: =IF(OR(T46="年末+季度",T46="季度+动态"),N46*$E$5/2,IF(T46="季度",(J46+K46)/2,IF(T46="动态",N46*$E$5*IF(J46+K46=0,0.5,K46/(J46+K46)),K46))) -> 0.10215824 | W46: =IF(OR(T46="年末+季度",T46="季度+动态",T46="动态"),N46*(1-$E$5)*IF(L46+M46=0,$B$7/($B$7+$B$8),L46/(L46+M46)),L46) -> 0.75081541 | X46: =IF(OR(T46="年末+季度",T46="季度+动态",T46="动态"),N46*(1-$E$5)*IF(L46+M46=0,$B$8/($B$7+$B$8),M46/(L46+M46)),M46) -> 0.051393288 | Y46: =POWER(1-$H$5,(A46-A45)/$H$8) -> 0.99998627 | Z46: =U46*Y46 -> 0.10025268 | AA46: =V46*Y46 -> 0.10215683 | AB46: =W46*Y46 -> 0.7508051 | AC46: =X46*Y46 -> 0.051392583 | AD46: =SUM(Z46:AC46) -> 1.0046072 | AE46: =MAX(AE45,AD46) -> 1.0046072 | AF46: =AD46/AE46-1 -> 0 | AG46: =AD46/AD45-1 -> 0.0014988445 | AH46: =IF(OR(T46="年末+季度",T46="季度+动态",T46="季度",T46="动态"),A46,AH45) -> 43832 | AI46: =YEAR(A46) -> 2020 | AJ46: =MONTH(A46) -> 1 | AK46: =IF(MONTH(A46)<>MONTH(A47),1,0) -> 0 | AL46: =IF(AK45,AD45,AL45) -> 1 | AM46: =IF(AK46,AD46/AL46-1,"") | AN46: =IF(AI46<>AI45,AD46,MAX(AN45,AD46)) -> 1.0046072 | AO46: =AD46/AN46-1 -> 0 | AP46: =IFERROR(SUM(Z46:AC46)/AD46,0) -> 1 | AQ46: =AND(B46>0,C46>0,D46>0,E46>0) -> TRUE | AR46: =EDATE(AR45,1) -> 43922 | AS46: =TEXT(AR46,"yyyy-mm") -> 2020-04 | AT46: =IF(AR46>DATE(YEAR($A$1657),MONTH($A$1657),1),"",SUMIFS($AD$43:$AD$1657,$AI$43:$AI$1657,YEAR(AR46),$AJ$43:$AJ$1657,MONTH(AR46),$AK$43:$AK$1657,1)) -> 1.0302216
A47: =净值底稿!A8 -> 43838 | B47: =净值底稿!X8 -> 0.99048782 | C47: =净值底稿!U8 -> 1.0261808 | D47: =净值底稿!V8 -> 1.403 | E47: =净值底稿!W8 -> 1.3041 | F47: =IFERROR(B47/B46-1,0) -> -0.012076491 | G47: =IFERROR(C47/C46-1,0) -> -0.012645057 | H47: =IFERROR(D47/D46-1,0) -> 0.00042783799 | I47: =IFERROR(E47/E46-1,0) -> 0.015021793 | J47: =Z46*(1+F47) -> 0.099041981 | K47: =AA46*(1+G47) -> 0.10086505 | L47: =AB46*(1+H47) -> 0.75112632 | M47: =AC46*(1+I47) -> 0.052164591 | N47: =SUM(J47:M47) -> 1.0031979 | O47: =IFERROR((J47+K47)/N47,0) -> 0.19926978 | P47: =AND(MONTH(A47)=12,OR(A48="",YEAR(A47)<>YEAR(A48))) -> FALSE | Q47: =AND(MOD(MONTH(A47),3)=0,OR(A48="",MONTH(A47)<>MONTH(A48))) -> FALSE | R47: =OR(O47>$E$7,O47<$E$6) -> FALSE | S47: =AND(OR(P47,Q47,R47),A47-AH46>$E$8) -> FALSE | T47: =IF(NOT(OR(P47,Q47,R47)),"不调",IF(NOT(S47),"间隔规则跳过",IF(P47,"年末+季度",IF(AND(Q47,R47),"季度+动态",IF(Q47,"季度","动态"))))) -> 不调 | U47: =IF(OR(T47="年末+季度",T47="季度+动态"),N47*$E$5/2,IF(T47="季度",(J47+K47)/2,IF(T47="动态",N47*$E$5*IF(J47+K47=0,0.5,J47/(J47+K47)),J47))) -> 0.099041981 | V47: =IF(OR(T47="年末+季度",T47="季度+动态"),N47*$E$5/2,IF(T47="季度",(J47+K47)/2,IF(T47="动态",N47*$E$5*IF(J47+K47=0,0.5,K47/(J47+K47)),K47))) -> 0.10086505 | W47: =IF(OR(T47="年末+季度",T47="季度+动态",T47="动态"),N47*(1-$E$5)*IF(L47+M47=0,$B$7/($B$7+$B$8),L47/(L47+M47)),L47) -> 0.75112632 | X47: =IF(OR(T47="年末+季度",T47="季度+动态",T47="动态"),N47*(1-$E$5)*IF(L47+M47=0,$B$8/($B$7+$B$8),M47/(L47+M47)),M47) -> 0.052164591 | Y47: =POWER(1-$H$5,(A47-A46)/$H$8) -> 0.99998627 | Z47: =U47*Y47 -> 0.099040621 | AA47: =V47*Y47 -> 0.10086367 | AB47: =W47*Y47 -> 0.75111601 | AC47: =X47*Y47 -> 0.052163875 | AD47: =SUM(Z47:AC47) -> 1.0031842 | AE47: =MAX(AE46,AD47) -> 1.0046072 | AF47: =AD47/AE47-1 -> -0.0014164986 | AG47: =AD47/AD46-1 -> -0.0014164986 | AH47: =IF(OR(T47="年末+季度",T47="季度+动态",T47="季度",T47="动态"),A47,AH46) -> 43832 | AI47: =YEAR(A47) -> 2020 | AJ47: =MONTH(A47) -> 1 | AK47: =IF(MONTH(A47)<>MONTH(A48),1,0) -> 0 | AL47: =IF(AK46,AD46,AL46) -> 1 | AM47: =IF(AK47,AD47/AL47-1,"") | AN47: =IF(AI47<>AI46,AD47,MAX(AN46,AD47)) -> 1.0046072 | AO47: =AD47/AN47-1 -> -0.0014164986 | AP47: =IFERROR(SUM(Z47:AC47)/AD47,0) -> 1 | AQ47: =AND(B47>0,C47>0,D47>0,E47>0) -> TRUE | AR47: =EDATE(AR46,1) -> 43952 | AS47: =TEXT(AR47,"yyyy-mm") -> 2020-05 | AT47: =IF(AR47>DATE(YEAR($A$1657),MONTH($A$1657),1),"",SUMIFS($AD$43:$AD$1657,$AI$43:$AI$1657,YEAR(AR47),$AJ$43:$AJ$1657,MONTH(AR47),$AK$43:$AK$1657,1)) -> 1.0238337
A48: =净值底稿!A9 -> 43839 | B48: =净值底稿!X9 -> 1.0003337 | C48: =净值底稿!U9 -> 1.0416767 | D48: =净值底稿!V9 -> 1.4036 | E48: =净值底稿!W9 -> 1.2656 | F48: =IFERROR(B48/B47-1,0) -> 0.0099404787 | G48: =IFERROR(C48/C47-1,0) -> 0.015100536 | H48: =IFERROR(D48/D47-1,0) -> 0.00042765502 | I48: =IFERROR(E48/E47-1,0) -> -0.029522276 | J48: =Z47*(1+F48) -> 0.10002513 | K48: =AA47*(1+G48) -> 0.10238676 | L48: =AB47*(1+H48) -> 0.75143722 | M48: =AC47*(1+I48) -> 0.050623879 | N48: =SUM(J48:M48) -> 1.004473 | O48: =IFERROR((J48+K48)/N48,0) -> 0.20151054 | P48: =AND(MONTH(A48)=12,OR(A49="",YEAR(A48)<>YEAR(A49))) -> FALSE | Q48: =AND(MOD(MONTH(A48),3)=0,OR(A49="",MONTH(A48)<>MONTH(A49))) -> FALSE | R48: =OR(O48>$E$7,O48<$E$6) -> FALSE | S48: =AND(OR(P48,Q48,R48),A48-AH47>$E$8) -> FALSE | T48: =IF(NOT(OR(P48,Q48,R48)),"不调",IF(NOT(S48),"间隔规则跳过",IF(P48,"年末+季度",IF(AND(Q48,R48),"季度+动态",IF(Q48,"季度","动态"))))) -> 不调 | U48: =IF(OR(T48="年末+季度",T48="季度+动态"),N48*$E$5/2,IF(T48="季度",(J48+K48)/2,IF(T48="动态",N48*$E$5*IF(J48+K48=0,0.5,J48/(J48+K48)),J48))) -> 0.10002513 | V48: =IF(OR(T48="年末+季度",T48="季度+动态"),N48*$E$5/2,IF(T48="季度",(J48+K48)/2,IF(T48="动态",N48*$E$5*IF(J48+K48=0,0.5,K48/(J48+K48)),K48))) -> 0.10238676 | W48: =IF(OR(T48="年末+季度",T48="季度+动态",T48="动态"),N48*(1-$E$5)*IF(L48+M48=0,$B$7/($B$7+$B$8),L48/(L48+M48)),L48) -> 0.75143722 | X48: =IF(OR(T48="年末+季度",T48="季度+动态",T48="动态"),N48*(1-$E$5)*IF(L48+M48=0,$B$8/($B$7+$B$8),M48/(L48+M48)),M48) -> 0.050623879 | Y48: =POWER(1-$H$5,(A48-A47)/$H$8) -> 0.99998627 | Z48: =U48*Y48 -> 0.10002376 | AA48: =V48*Y48 -> 0.10238536 | AB48: =W48*Y48 -> 0.7514269 | AC48: =X48*Y48 -> 0.050623184 | AD48: =SUM(Z48:AC48) -> 1.0044592 | AE48: =MAX(AE47,AD48) -> 1.0046072 | AF48: =AD48/AE48-1 -> -0.00014731146 | AG48: =AD48/AD47-1 -> 0.0012709875 | AH48: =IF(OR(T48="年末+季度",T48="季度+动态",T48="季度",T48="动态"),A48,AH47) -> 43832 | AI48: =YEAR(A48) -> 2020 | AJ48: =MONTH(A48) -> 1 | AK48: =IF(MONTH(A48)<>MONTH(A49),1,0) -> 0 | AL48: =IF(AK47,AD47,AL47) -> 1 | AM48: =IF(AK48,AD48/AL48-1,"") | AN48: =IF(AI48<>AI47,AD48,MAX(AN47,AD48)) -> 1.0046072 | AO48: =AD48/AN48-1 -> -0.00014731146 | AP48: =IFERROR(SUM(Z48:AC48)/AD48,0) -> 1 | AQ48: =AND(B48>0,C48>0,D48>0,E48>0) -> TRUE | AR48: =EDATE(AR47,1) -> 43983 | AS48: =TEXT(AR48,"yyyy-mm") -> 2020-06 | AT48: =IF(AR48>DATE(YEAR($A$1657),MONTH($A$1657),1),"",SUMIFS($AD$43:$AD$1657,$AI$43:$AI$1657,YEAR(AR48),$AJ$43:$AJ$1657,MONTH(AR48),$AK$43:$AK$1657,1)) -> 1.0283953
...
