Workbook
Name _ChartDates: 实盘组合净值!$A$8:INDEX(实盘组合净值!$A$8:$A$1000,MATCH(9.99999999999999E+307,实盘组合净值!$A$8:$A$1000))
Name _ChartDates: 实盘组合净值!$A$5:INDEX(实盘组合净值!$A$5:$A$1000,MATCH(9.99999999999999E+307,实盘组合净值!$A$5:$A$1000))
Name _ChartDates: 实盘组合净值!$A$8:INDEX(实盘组合净值!$A$8:$A$1000,MATCH(9.99999999999999E+307,实盘组合净值!$A$8:$A$1000))
Name _ChartDates: 实盘组合净值!$A$6:INDEX(实盘组合净值!$A$6:$A$1000,MATCH(9.99999999999999E+307,实盘组合净值!$A$6:$A$1000))
Name _ChartDates: 实盘组合净值!$A$7:INDEX(实盘组合净值!$A$7:$A$1000,MATCH(9.99999999999999E+307,实盘组合净值!$A$7:$A$1000))
Name _ChartDates: 实盘组合净值!$A$5:INDEX(实盘组合净值!$A$5:$A$1000,MATCH(9.99999999999999E+307,实盘组合净值!$A$5:$A$1000))
Name _ChartValues: 实盘组合净值!$K$8:INDEX(实盘组合净值!$K$8:$K$1000,MATCH(9.99999999999999E+307,实盘组合净值!$A$8:$A$1000))
Name _ChartValues: 实盘组合净值!$N$5:INDEX(实盘组合净值!$N$5:$N$1000,MATCH(9.99999999999999E+307,实盘组合净值!$A$5:$A$1000))
Name _ChartValues: 实盘组合净值!$Q$8:INDEX(实盘组合净值!$Q$8:$Q$1000,MATCH(9.99999999999999E+307,实盘组合净值!$A$8:$A$1000))
Name _ChartValues: 实盘组合净值!$B$6:INDEX(实盘组合净值!$B$6:$B$1000,MATCH(9.99999999999999E+307,实盘组合净值!$A$6:$A$1000))
Name _ChartValues: 实盘组合净值!$H$7:INDEX(实盘组合净值!$H$7:$H$1000,MATCH(9.99999999999999E+307,实盘组合净值!$A$7:$A$1000))
Name _ChartValues: 实盘组合净值!$E$5:INDEX(实盘组合净值!$E$5:$E$1000,MATCH(9.99999999999999E+307,实盘组合净值!$A$5:$A$1000))

Sheet 实盘持仓初始配置
A1: 持仓配置（实盘·初始权重）
A2: 基金简称 | B2: 华安黄金ETF联接A | C2: 嘉实快线货币A | D2: 宏利复兴混合A | E2: 博道沪深300增强A | F2: 博道沪深300指增C | G2: 国泰通信设备ETF联接A | H2: 国泰通信设备C | I2: 嘉实前沿科技创新 | J2: 银华集成电路混合A | K2: 银华集成电路混合C | L2: 天弘中证1000指增A | M2: 天弘中证1000指增C | N2: 中欧中证500指增A | O2: 中欧中证500指增C | P2: 信澳业绩驱动A | Q2: 嘉实信息产业A | R2: 嘉实信息产业C | S2: 宏利复兴伟业C | T2: 国泰半导体材料设备ETF联接A | U2: 国泰半导体材料设备C | V2: 华泰柏瑞中证2000指增A | W2: 华泰柏瑞中证2000指增C | X2: 易方达中债新综指LOFA | Y2: 合计 | Z2: 年化费率 | AA2: 净值起始日
A3: 基金代码 | B3: 000216.OF | C3: 000917.OF | D3: 001170.OF | E3: 007044.OF | F3: 007045.OF | G3: 007817.OF | H3: 007818.OF | I3: 009993.OF | J3: 013840.OF | K3: 013841.OF | L3: 014201.OF | M3: 014202.OF | N3: 015453.OF | O3: 015454.OF | P3: 016370.OF | Q3: 017488.OF | R3: 017489.OF | S3: 017612.OF | T3: 019632.OF | U3: 019633.OF | V3: 019923.OF | W3: 019924.OF | X3: 161119.OF
A4: 产业趋势 权重 | B4: 0 | C4: 0.02 | D4: 0.19 | E4: 0 | F4: 0 | G4: 0.11 | H4: 0 | I4: 0 | J4: 0.19 | K4: 0 | L4: 0 | M4: 0 | N4: 0 | O4: 0 | P4: 0.19 | Q4: 0.19 | R4: 0 | S4: 0 | T4: 0.11 | U4: 0 | V4: 0 | W4: 0 | X4: 0 | Y4: =SUM(B4:X4) -> 1 | Z4: 0.015 | AA4: 46195
A5: 产业趋势基石 权重 | B5: 0 | C5: 0.02 | D5: 0.19 | E5: 0 | F5: 0 | G5: 0.11 | H5: 0 | I5: 0 | J5: 0.19 | K5: 0 | L5: 0 | M5: 0 | N5: 0 | O5: 0 | P5: 0.19 | Q5: 0.19 | R5: 0 | S5: 0 | T5: 0.11 | U5: 0 | V5: 0 | W5: 0 | X5: 0 | Y5: =SUM(B5:X5) -> 1 | Z5: 0.012 | AA5: 46191
A6: 产业趋势2号 权重 | B6: 0 | C6: 0.02 | D6: 0 | E6: 0 | F6: 0 | G6: 0 | H6: 0.11 | I6: 0.19 | J6: 0 | K6: 0.19 | L6: 0 | M6: 0 | N6: 0 | O6: 0 | P6: 0 | Q6: 0 | R6: 0.19 | S6: 0.19 | T6: 0 | U6: 0.11 | V6: 0 | W6: 0 | X6: 0 | Y6: =SUM(B6:X6) -> 1 | Z6: 0.015 | AA6: 46196
A7: 10-90 权重 | B7: 0.05 | C7: 0.02 | D7: 0 | E7: 0 | F7: 0.0125 | G7: 0 | H7: 0.005 | I7: 0.01 | J7: 0 | K7: 0.01 | L7: 0 | M7: 0.0125 | N7: 0 | O7: 0.0125 | P7: 0 | Q7: 0 | R7: 0.01 | S7: 0.01 | T7: 0 | U7: 0.005 | V7: 0 | W7: 0.0125 | X7: 0.83 | Y7: =SUM(B7:X7) -> 1 | Z7: 0.008 | AA7: 46197
A8: 10-90基石 权重 | B8: 0.05 | C8: 0.02 | D8: 0.01 | E8: 0.0125 | F8: 0 | G8: 0.005 | H8: 0 | I8: 0 | J8: 0.01 | K8: 0 | L8: 0.0125 | M8: 0 | N8: 0.0125 | O8: 0 | P8: 0.01 | Q8: 0.01 | R8: 0 | S8: 0 | T8: 0.005 | U8: 0 | V8: 0.0125 | W8: 0 | X8: 0.83 | Y8: =SUM(B8:X8) -> 1 | Z8: 0.005 | AA8: 46191
A9: 30-70 权重 | B9: 0.1 | C9: 0.02 | D9: 0 | E9: 0 | F9: 0.0375 | G9: 0 | H9: 0.015 | I9: 0.03 | J9: 0 | K9: 0.03 | L9: 0 | M9: 0.0375 | N9: 0 | O9: 0.0375 | P9: 0 | Q9: 0 | R9: 0.03 | S9: 0.03 | T9: 0 | U9: 0.015 | V9: 0 | W9: 0.0375 | X9: 0.58 | Y9: =SUM(B9:X9) -> 1 | Z9: 0.012 | AA9: 46197
A11: 权重蓝色输入；Z列为各组合年化费率、AA列为各组合净值起始日(当日净值=1)。新增交易日下拉填充，下游净值与看板自动重算。

Sheet 偏离度监控
A1: 样板间投顾组合 · 偏离度监控
A2: 净值截止日 | B2: =$B$82 -> 46251 | C2: 权重口径 | D2: 上一完整交易日（避免当日净值更新不同步） | I2: 配比预警阈值 | J2: 0.02 | K2: 主动基金上限 | L2: 0.2
A3: 三个产业趋势组合展示全部最新持仓；10-90（含基石）及30-70的结构偏离按目标配比监控。红色表示超过约束或预警阈值。
A5: 1. 产业趋势组合详细持仓及集中度风险 | F5: 数据截止日 | G5: =$B$82 -> 46251
A6: 组合 | B6: 基金代码 | C6: 基金简称 | D6: 基金类型 | E6: 当前权重 | F6: 是否超限 | G6: 调仓生效日
A7: =IF(B7<>"","产业趋势","") -> 产业趋势 | B7: =IFERROR(INDEX($A$53:$A$76,MATCH(1,M$53:M$76,0)),"") -> 000917.OF | C7: =IFERROR(INDEX($B$53:$B$76,MATCH(1,M$53:M$76,0)),"") -> 嘉实快线货币A | D7: =IFERROR(INDEX($E$53:$E$76,MATCH(1,M$53:M$76,0)),"") -> 货币 | E7: =IFERROR(INDEX(G$53:G$76,MATCH(1,M$53:M$76,0)),"") -> 0.050270537 | F7: =IF(B7="","",IF(D7<>"主动","不适用",IF(E7>$L$2,"超限","正常"))) -> 不适用 | G7: =IF(B7<>"",G$84,"") -> 46213
A8: =IF(B8<>"","产业趋势","") -> 产业趋势 | B8: =IFERROR(INDEX($A$53:$A$76,MATCH(2,M$53:M$76,0)),"") -> 001170.OF | C8: =IFERROR(INDEX($B$53:$B$76,MATCH(2,M$53:M$76,0)),"") -> 宏利复兴混合A | D8: =IFERROR(INDEX($E$53:$E$76,MATCH(2,M$53:M$76,0)),"") -> 主动 | E8: =IFERROR(INDEX(G$53:G$76,MATCH(2,M$53:M$76,0)),"") -> 0.16924382 | F8: =IF(B8="","",IF(D8<>"主动","不适用",IF(E8>$L$2,"超限","正常"))) -> 正常 | G8: =IF(B8<>"",G$84,"") -> 46213
A9: =IF(B9<>"","产业趋势","") -> 产业趋势 | B9: =IFERROR(INDEX($A$53:$A$76,MATCH(3,M$53:M$76,0)),"") -> 013840.OF | C9: =IFERROR(INDEX($B$53:$B$76,MATCH(3,M$53:M$76,0)),"") -> 银华集成电路混合A | D9: =IFERROR(INDEX($E$53:$E$76,MATCH(3,M$53:M$76,0)),"") -> 主动 | E9: =IFERROR(INDEX(G$53:G$76,MATCH(3,M$53:M$76,0)),"") -> 0.24137329 | F9: =IF(B9="","",IF(D9<>"主动","不适用",IF(E9>$L$2,"超限","正常"))) -> 超限 | G9: =IF(B9<>"",G$84,"") -> 46213
A10: =IF(B10<>"","产业趋势","") -> 产业趋势 | B10: =IFERROR(INDEX($A$53:$A$76,MATCH(4,M$53:M$76,0)),"") -> 016370.OF | C10: =IFERROR(INDEX($B$53:$B$76,MATCH(4,M$53:M$76,0)),"") -> 信澳业绩驱动A | D10: =IFERROR(INDEX($E$53:$E$76,MATCH(4,M$53:M$76,0)),"") -> 主动 | E10: =IFERROR(INDEX(G$53:G$76,MATCH(4,M$53:M$76,0)),"") -> 0.16943218 | F10: =IF(B10="","",IF(D10<>"主动","不适用",IF(E10>$L$2,"超限","正常"))) -> 正常 | G10: =IF(B10<>"",G$84,"") -> 46213
A11: =IF(B11<>"","产业趋势","") -> 产业趋势 | B11: =IFERROR(INDEX($A$53:$A$76,MATCH(5,M$53:M$76,0)),"") -> 017488.OF | C11: =IFERROR(INDEX($B$53:$B$76,MATCH(5,M$53:M$76,0)),"") -> 嘉实信息产业A | D11: =IFERROR(INDEX($E$53:$E$76,MATCH(5,M$53:M$76,0)),"") -> 主动 | E11: =IFERROR(INDEX(G$53:G$76,MATCH(5,M$53:M$76,0)),"") -> 0.17413271 | F11: =IF(B11="","",IF(D11<>"主动","不适用",IF(E11>$L$2,"超限","正常"))) -> 正常 | G11: =IF(B11<>"",G$84,"") -> 46213
A12: =IF(B12<>"","产业趋势","") -> 产业趋势 | B12: =IFERROR(INDEX($A$53:$A$76,MATCH(6,M$53:M$76,0)),"") -> 019632.OF | C12: =IFERROR(INDEX($B$53:$B$76,MATCH(6,M$53:M$76,0)),"") -> 国泰半导体材料设备ETF联接A | D12: =IFERROR(INDEX($E$53:$E$76,MATCH(6,M$53:M$76,0)),"") -> 指数 | E12: =IFERROR(INDEX(G$53:G$76,MATCH(6,M$53:M$76,0)),"") -> 0.12784444 | F12: =IF(B12="","",IF(D12<>"主动","不适用",IF(E12>$L$2,"超限","正常"))) -> 不适用 | G12: =IF(B12<>"",G$84,"") -> 46213
A13: =IF(B13<>"","产业趋势","") -> 产业趋势 | B13: =IFERROR(INDEX($A$53:$A$76,MATCH(7,M$53:M$76,0)),"") -> 162214.OF | C13: =IFERROR(INDEX($B$53:$B$76,MATCH(7,M$53:M$76,0)),"") -> 宏利领先中小盘混合 | D13: =IFERROR(INDEX($E$53:$E$76,MATCH(7,M$53:M$76,0)),"") -> 主动 | E13: =IFERROR(INDEX(G$53:G$76,MATCH(7,M$53:M$76,0)),"") -> 0.067703021 | F13: =IF(B13="","",IF(D13<>"主动","不适用",IF(E13>$L$2,"超限","正常"))) -> 正常 | G13: =IF(B13<>"",G$84,"") -> 46213
A14: =IF(B14<>"","产业趋势","") | B14: =IFERROR(INDEX($A$53:$A$76,MATCH(8,M$53:M$76,0)),"") | C14: =IFERROR(INDEX($B$53:$B$76,MATCH(8,M$53:M$76,0)),"") | D14: =IFERROR(INDEX($E$53:$E$76,MATCH(8,M$53:M$76,0)),"") | E14: =IFERROR(INDEX(G$53:G$76,MATCH(8,M$53:M$76,0)),"") | F14: =IF(B14="","",IF(D14<>"主动","不适用",IF(E14>$L$2,"超限","正常"))) | G14: =IF(B14<>"",G$84,"")
A15: =IF(B15<>"","产业趋势基石","") -> 产业趋势基石 | B15: =IFERROR(INDEX($A$53:$A$76,MATCH(1,N$53:N$76,0)),"") -> 000917.OF | C15: =IFERROR(INDEX($B$53:$B$76,MATCH(1,N$53:N$76,0)),"") -> 嘉实快线货币A | D15: =IFERROR(INDEX($E$53:$E$76,MATCH(1,N$53:N$76,0)),"") -> 货币 | E15: =IFERROR(INDEX(H$53:H$76,MATCH(1,N$53:N$76,0)),"") -> 0.049149446 | F15: =IF(B15="","",IF(D15<>"主动","不适用",IF(E15>$L$2,"超限","正常"))) -> 不适用 | G15: =IF(B15<>"",H$84,"") -> 46213
A16: =IF(B16<>"","产业趋势基石","") -> 产业趋势基石 | B16: =IFERROR(INDEX($A$53:$A$76,MATCH(2,N$53:N$76,0)),"") -> 001170.OF | C16: =IFERROR(INDEX($B$53:$B$76,MATCH(2,N$53:N$76,0)),"") -> 宏利复兴混合A | D16: =IFERROR(INDEX($E$53:$E$76,MATCH(2,N$53:N$76,0)),"") -> 主动 | E16: =IFERROR(INDEX(H$53:H$76,MATCH(2,N$53:N$76,0)),"") -> 0.17080957 | F16: =IF(B16="","",IF(D16<>"主动","不适用",IF(E16>$L$2,"超限","正常"))) -> 正常 | G16: =IF(B16<>"",H$84,"") -> 46213
A17: =IF(B17<>"","产业趋势基石","") -> 产业趋势基石 | B17: =IFERROR(INDEX($A$53:$A$76,MATCH(3,N$53:N$76,0)),"") -> 013840.OF | C17: =IFERROR(INDEX($B$53:$B$76,MATCH(3,N$53:N$76,0)),"") -> 银华集成电路混合A | D17: =IFERROR(INDEX($E$53:$E$76,MATCH(3,N$53:N$76,0)),"") -> 主动 | E17: =IFERROR(INDEX(H$53:H$76,MATCH(3,N$53:N$76,0)),"") -> 0.23964714 | F17: =IF(B17="","",IF(D17<>"主动","不适用",IF(E17>$L$2,"超限","正常"))) -> 超限 | G17: =IF(B17<>"",H$84,"") -> 46213
A18: =IF(B18<>"","产业趋势基石","") -> 产业趋势基石 | B18: =IFERROR(INDEX($A$53:$A$76,MATCH(4,N$53:N$76,0)),"") -> 016370.OF | C18: =IFERROR(INDEX($B$53:$B$76,MATCH(4,N$53:N$76,0)),"") -> 信澳业绩驱动A | D18: =IFERROR(INDEX($E$53:$E$76,MATCH(4,N$53:N$76,0)),"") -> 主动 | E18: =IFERROR(INDEX(H$53:H$76,MATCH(4,N$53:N$76,0)),"") -> 0.16930521 | F18: =IF(B18="","",IF(D18<>"主动","不适用",IF(E18>$L$2,"超限","正常"))) -> 正常 | G18: =IF(B18<>"",H$84,"") -> 46213
A19: =IF(B19<>"","产业趋势基石","") -> 产业趋势基石 | B19: =IFERROR(INDEX($A$53:$A$76,MATCH(5,N$53:N$76,0)),"") -> 017488.OF | C19: =IFERROR(INDEX($B$53:$B$76,MATCH(5,N$53:N$76,0)),"") -> 嘉实信息产业A | D19: =IFERROR(INDEX($E$53:$E$76,MATCH(5,N$53:N$76,0)),"") -> 主动 | E19: =IFERROR(INDEX(H$53:H$76,MATCH(5,N$53:N$76,0)),"") -> 0.1749248 | F19: =IF(B19="","",IF(D19<>"主动","不适用",IF(E19>$L$2,"超限","正常"))) -> 正常 | G19: =IF(B19<>"",H$84,"") -> 46213
A20: =IF(B20<>"","产业趋势基石","") -> 产业趋势基石 | B20: =IFERROR(INDEX($A$53:$A$76,MATCH(6,N$53:N$76,0)),"") -> 019632.OF | C20: =IFERROR(INDEX($B$53:$B$76,MATCH(6,N$53:N$76,0)),"") -> 国泰半导体材料设备ETF联接A | D20: =IFERROR(INDEX($E$53:$E$76,MATCH(6,N$53:N$76,0)),"") -> 指数 | E20: =IFERROR(INDEX(H$53:H$76,MATCH(6,N$53:N$76,0)),"") -> 0.1284589 | F20: =IF(B20="","",IF(D20<>"主动","不适用",IF(E20>$L$2,"超限","正常"))) -> 不适用 | G20: =IF(B20<>"",H$84,"") -> 46213
A21: =IF(B21<>"","产业趋势基石","") -> 产业趋势基石 | B21: =IFERROR(INDEX($A$53:$A$76,MATCH(7,N$53:N$76,0)),"") -> 162214.OF | C21: =IFERROR(INDEX($B$53:$B$76,MATCH(7,N$53:N$76,0)),"") -> 宏利领先中小盘混合 | D21: =IFERROR(INDEX($E$53:$E$76,MATCH(7,N$53:N$76,0)),"") -> 主动 | E21: =IFERROR(INDEX(H$53:H$76,MATCH(7,N$53:N$76,0)),"") -> 0.067704935 | F21: =IF(B21="","",IF(D21<>"主动","不适用",IF(E21>$L$2,"超限","正常"))) -> 正常 | G21: =IF(B21<>"",H$84,"") -> 46213
A22: =IF(B22<>"","产业趋势基石","") | B22: =IFERROR(INDEX($A$53:$A$76,MATCH(8,N$53:N$76,0)),"") | C22: =IFERROR(INDEX($B$53:$B$76,MATCH(8,N$53:N$76,0)),"") | D22: =IFERROR(INDEX($E$53:$E$76,MATCH(8,N$53:N$76,0)),"") | E22: =IFERROR(INDEX(H$53:H$76,MATCH(8,N$53:N$76,0)),"") | F22: =IF(B22="","",IF(D22<>"主动","不适用",IF(E22>$L$2,"超限","正常"))) | G22: =IF(B22<>"",H$84,"")
A23: =IF(B23<>"","产业趋势2号","") -> 产业趋势2号 | B23: =IFERROR(INDEX($A$53:$A$76,MATCH(1,O$53:O$76,0)),"") -> 000917.OF | C23: =IFERROR(INDEX($B$53:$B$76,MATCH(1,O$53:O$76,0)),"") -> 嘉实快线货币A | D23: =IFERROR(INDEX($E$53:$E$76,MATCH(1,O$53:O$76,0)),"") -> 货币 | E23: =IFERROR(INDEX(I$53:I$76,MATCH(1,O$53:O$76,0)),"") -> 0.048176915 | F23: =IF(B23="","",IF(D23<>"主动","不适用",IF(E23>$L$2,"超限","正常"))) -> 不适用 | G23: =IF(B23<>"",I$84,"") -> 46213
A24: =IF(B24<>"","产业趋势2号","") -> 产业趋势2号 | B24: =IFERROR(INDEX($A$53:$A$76,MATCH(2,O$53:O$76,0)),"") -> 009993.OF | C24: =IFERROR(INDEX($B$53:$B$76,MATCH(2,O$53:O$76,0)),"") -> 嘉实前沿科技创新 | D24: =IFERROR(INDEX($E$53:$E$76,MATCH(2,O$53:O$76,0)),"") -> 主动 | E24: =IFERROR(INDEX(I$53:I$76,MATCH(2,O$53:O$76,0)),"") -> 0.1836748 | F24: =IF(B24="","",IF(D24<>"主动","不适用",IF(E24>$L$2,"超限","正常"))) -> 正常 | G24: =IF(B24<>"",I$84,"") -> 46213
A25: =IF(B25<>"","产业趋势2号","") -> 产业趋势2号 | B25: =IFERROR(INDEX($A$53:$A$76,MATCH(3,O$53:O$76,0)),"") -> 013841.OF | C25: =IFERROR(INDEX($B$53:$B$76,MATCH(3,O$53:O$76,0)),"") -> 银华集成电路混合C | D25: =IFERROR(INDEX($E$53:$E$76,MATCH(3,O$53:O$76,0)),"") -> 主动 | E25: =IFERROR(INDEX(I$53:I$76,MATCH(3,O$53:O$76,0)),"") -> 0.23202409 | F25: =IF(B25="","",IF(D25<>"主动","不适用",IF(E25>$L$2,"超限","正常"))) -> 超限 | G25: =IF(B25<>"",I$84,"") -> 46213
A26: =IF(B26<>"","产业趋势2号","") -> 产业趋势2号 | B26: =IFERROR(INDEX($A$53:$A$76,MATCH(4,O$53:O$76,0)),"") -> 017489.OF | C26: =IFERROR(INDEX($B$53:$B$76,MATCH(4,O$53:O$76,0)),"") -> 嘉实信息产业C | D26: =IFERROR(INDEX($E$53:$E$76,MATCH(4,O$53:O$76,0)),"") -> 主动 | E26: =IFERROR(INDEX(I$53:I$76,MATCH(4,O$53:O$76,0)),"") -> 0.17253291 | F26: =IF(B26="","",IF(D26<>"主动","不适用",IF(E26>$L$2,"超限","正常"))) -> 正常 | G26: =IF(B26<>"",I$84,"") -> 46213
A27: =IF(B27<>"","产业趋势2号","") -> 产业趋势2号 | B27: =IFERROR(INDEX($A$53:$A$76,MATCH(5,O$53:O$76,0)),"") -> 017612.OF | C27: =IFERROR(INDEX($B$53:$B$76,MATCH(5,O$53:O$76,0)),"") -> 宏利复兴伟业C | D27: =IFERROR(INDEX($E$53:$E$76,MATCH(5,O$53:O$76,0)),"") -> 主动 | E27: =IFERROR(INDEX(I$53:I$76,MATCH(5,O$53:O$76,0)),"") -> 0.17110179 | F27: =IF(B27="","",IF(D27<>"主动","不适用",IF(E27>$L$2,"超限","正常"))) -> 正常 | G27: =IF(B27<>"",I$84,"") -> 46213
A28: =IF(B28<>"","产业趋势2号","") -> 产业趋势2号 | B28: =IFERROR(INDEX($A$53:$A$76,MATCH(6,O$53:O$76,0)),"") -> 019633.OF | C28: =IFERROR(INDEX($B$53:$B$76,MATCH(6,O$53:O$76,0)),"") -> 国泰半导体材料设备C | D28: =IFERROR(INDEX($E$53:$E$76,MATCH(6,O$53:O$76,0)),"") -> 指数 | E28: =IFERROR(INDEX(I$53:I$76,MATCH(6,O$53:O$76,0)),"") -> 0.12382021 | F28: =IF(B28="","",IF(D28<>"主动","不适用",IF(E28>$L$2,"超限","正常"))) -> 不适用 | G28: =IF(B28<>"",I$84,"") -> 46213
A29: =IF(B29<>"","产业趋势2号","") -> 产业趋势2号 | B29: =IFERROR(INDEX($A$53:$A$76,MATCH(7,O$53:O$76,0)),"") -> 162214.OF | C29: =IFERROR(INDEX($B$53:$B$76,MATCH(7,O$53:O$76,0)),"") -> 宏利领先中小盘混合 | D29: =IFERROR(INDEX($E$53:$E$76,MATCH(7,O$53:O$76,0)),"") -> 主动 | E29: =IFERROR(INDEX(I$53:I$76,MATCH(7,O$53:O$76,0)),"") -> 0.068669281 | F29: =IF(B29="","",IF(D29<>"主动","不适用",IF(E29>$L$2,"超限","正常"))) -> 正常 | G29: =IF(B29<>"",I$84,"") -> 46213
A30: =IF(B30<>"","产业趋势2号","") | B30: =IFERROR(INDEX($A$53:$A$76,MATCH(8,O$53:O$76,0)),"") | C30: =IFERROR(INDEX($B$53:$B$76,MATCH(8,O$53:O$76,0)),"") | D30: =IFERROR(INDEX($E$53:$E$76,MATCH(8,O$53:O$76,0)),"") | E30: =IFERROR(INDEX(I$53:I$76,MATCH(8,O$53:O$76,0)),"") | F30: =IF(B30="","",IF(D30<>"主动","不适用",IF(E30>$L$2,"超限","正常"))) | G30: =IF(B30<>"",I$84,"")
A31: 约束口径：仅“主动”基金适用单只20%上限；主题指数、指增、货币、债券及保障基金不纳入该上限。超限基金整行标红。
A33: 2. 组合内部增值 / 生息配比偏离（10-90/30-70） | G33: 数据截止日 | H33: =$B$82 -> 46251
A34: 组合 | B34: 增值目标 | C34: 增值当前 | D34: 偏离度 | E34: 生息目标 | F34: 生息当前 | G34: 偏离度 | H34: 调仓生效日
A35: 10-90 | B35: 0.1 | C35: =SUMIF($C$53:$C$76,"增值",J$53:J$76) -> 0.10895626 | D35: =C35-B35 -> 0.0089562638 | E35: =1-B35 -> 0.9 | F35: =SUMIF($C$53:$C$76,"生息",J$53:J$76) -> 0.89104374 | G35: =F35-E35 -> -0.0089562638 | H35: =J$84 -> 46220
A36: 10-90基石 | B36: 0.1 | C36: =SUMIF($C$53:$C$76,"增值",K$53:K$76) -> 0.1110844 | D36: =C36-B36 -> 0.011084404 | E36: =1-B36 -> 0.9 | F36: =SUMIF($C$53:$C$76,"生息",K$53:K$76) -> 0.8889156 | G36: =F36-E36 -> -0.011084404 | H36: =K$84 -> 46220
A37: 30-70 | B37: 0.3 | C37: =SUMIF($C$53:$C$76,"增值",L$53:L$76) -> 0.32448435 | D37: =C37-B37 -> 0.024484353 | E37: =1-B37 -> 0.7 | F37: =SUMIF($C$53:$C$76,"生息",L$53:L$76) -> 0.67551565 | G37: =F37-E37 -> -0.024484353 | H37: =L$84 -> 46220
A38: 生息含债券、货币及保障类基金；默认预警阈值为±2个百分点，可在J2直接修改。偏离度=当前配比−目标配比。
A40: 3. 增值部分内部产业趋势 / 指增当前配比 | D40: 数据截止日 | E40: =$B$82 -> 46251
A41: 组合 | B41: 产业趋势当前权重 | C41: 指增部分当前权重 | D41: 增值部分总权重 | E41: 调仓生效日
A42: 10-90 | B42: =IFERROR(SUMIF($D$53:$D$76,"产业趋势",J$53:J$76)/SUMIF($C$53:$C$76,"增值",J$53:J$76),0) -> 0.51550464 | C42: =IFERROR(SUMIF($D$53:$D$76,"指增",J$53:J$76)/SUMIF($C$53:$C$76,"增值",J$53:J$76),0) -> 0.48449536 | D42: =SUMIF($C$53:$C$76,"增值",J$53:J$76) -> 0.10895626 | E42: =J$84 -> 46220
A43: 10-90基石 | B43: =IFERROR(SUMIF($D$53:$D$76,"产业趋势",K$53:K$76)/SUMIF($C$53:$C$76,"增值",K$53:K$76),0) -> 0.52052902 | C43: =IFERROR(SUMIF($D$53:$D$76,"指增",K$53:K$76)/SUMIF($C$53:$C$76,"增值",K$53:K$76),0) -> 0.47947098 | D43: =SUMIF($C$53:$C$76,"增值",K$53:K$76) -> 0.1110844 | E43: =K$84 -> 46220
...

Sheet vs固收+对比
E1: =VLOOKUP(E3,实盘组合净值!$A:$P,14) -> 1 | F1: =VLOOKUP(F3,实盘组合净值!$A:$P,14) -> 1 | G1: =VLOOKUP(G3,实盘组合净值!$A:$P,14) -> 0.97719837
E2: =VLOOKUP(E5,实盘组合净值!$A:$P,14) -> 0.9986547 | F2: =VLOOKUP(F5,实盘组合净值!$A:$P,14) -> 0.97390321 | G2: =VLOOKUP(G5,实盘组合净值!$A:$P,14) -> 0.9986547
E3: 46191 | F3: 46191 | G3: 46234
E4: 46195 | F4: 46195 | G4: 46237
E5: =偏离度监控!B2 -> 46251 | F5: 46233 | G5: =E5 -> 46251
C6: 公募固收+规模前十（2026Q2）基金表现
A7: 序号 | B7: 基金代码 | C7: 产品/基金名称 | D7: 26Q2规模（亿元） | E7: 上线以来 | F7: 6/22-7/30 | G7: 7.31至今 | H7: 最大回撤（上线以来）
A8: 组合 | C8: 10/90基石投顾组合 | E8: =E$2/E$1-1 -> -0.0013453011 | F8: =F$2/F$1-1 -> -0.02609679 | G8: =G$2/G$1-1 -> 0.021956981 | H8: ='看板-10-90基石'!$F$7 -> -0.028729069
A9: 1 | B9: 003504.OF | C9: 景顺长城景颐丰利债券 | D9: 712 | E9: =[1]!thsiFinD("ths_adjustment_nvg_ratio_fund",$B9,E$4,E$5,101)/100 -> -0.02989781 | F9: =[1]!thsiFinD("ths_adjustment_nvg_ratio_fund",$B9,F$4,F$5,101)/100 -> -0.07340146 | G9: =[1]!thsiFinD("ths_adjustment_nvg_ratio_fund",$B9,G$4,G$5,101)/100 -> 0.037210464 | H9: =-[1]!thsiFinD("ths_max_retrace_rate_all_fund",$B9,E$3,E$5)/100 -> -0.078192169
A10: 2 | B10: 000143.OF | C10: 鹏华双债加利债券 | D10: 584 | E10: =[1]!thsiFinD("ths_adjustment_nvg_ratio_fund",$B10,E$4,E$5,101)/100 -> -0.017138566 | F10: =[1]!thsiFinD("ths_adjustment_nvg_ratio_fund",$B10,F$4,F$5,101)/100 -> -0.051945757 | G10: =[1]!thsiFinD("ths_adjustment_nvg_ratio_fund",$B10,G$4,G$5,101)/100 -> 0.029424011 | H10: =-[1]!thsiFinD("ths_max_retrace_rate_all_fund",$B10,E$3,E$5)/100 -> -0.06090571
A11: 3 | B11: 000385.OF | C11: 景顺长城景颐双利债券 | D11: 576 | E11: =[1]!thsiFinD("ths_adjustment_nvg_ratio_fund",$B11,E$4,E$5,101)/100 -> -0.00052438383 | F11: =[1]!thsiFinD("ths_adjustment_nvg_ratio_fund",$B11,F$4,F$5,101)/100 -> -0.01363398 | G11: =[1]!thsiFinD("ths_adjustment_nvg_ratio_fund",$B11,G$4,G$5,101)/100 -> 0.011677282 | H11: =-[1]!thsiFinD("ths_max_retrace_rate_all_fund",$B11,E$3,E$5)/100 -> -0.024530271
A12: 4 | B12: 002065.OF | C12: 景顺长城景盛双息收益债券 | D12: 393 | E12: =[1]!thsiFinD("ths_adjustment_nvg_ratio_fund",$B12,E$4,E$5,101)/100 -> 0.027932961 | F12: =[1]!thsiFinD("ths_adjustment_nvg_ratio_fund",$B12,F$4,F$5,101)/100 -> 0.015961692 | G12: =[1]!thsiFinD("ths_adjustment_nvg_ratio_fund",$B12,G$4,G$5,101)/100 -> 0.0094043887 | H12: =-[1]!thsiFinD("ths_max_retrace_rate_all_fund",$B12,E$3,E$5)/100 -> -0.019857029
A13: 5 | B13: 002969.OF | C13: 易方达丰和债券 | D13: 391 | E13: =[1]!thsiFinD("ths_adjustment_nvg_ratio_fund",$B13,E$4,E$5,101)/100 -> -0.011805271 | F13: =[1]!thsiFinD("ths_adjustment_nvg_ratio_fund",$B13,F$4,F$5,101)/100 -> -0.056454912 | G13: =[1]!thsiFinD("ths_adjustment_nvg_ratio_fund",$B13,G$4,G$5,101)/100 -> 0.037935056 | H13: =-[1]!thsiFinD("ths_max_retrace_rate_all_fund",$B13,E$3,E$5)/100 -> -0.070577399
A14: 6 | B14: 014088.OF | C14: 永赢稳健增强债券 | D14: 365 | E14: =[1]!thsiFinD("ths_adjustment_nvg_ratio_fund",$B14,E$4,E$5,101)/100 -> -0.018100272 | F14: =[1]!thsiFinD("ths_adjustment_nvg_ratio_fund",$B14,F$4,F$5,101)/100 -> -0.039484222 | G14: =[1]!thsiFinD("ths_adjustment_nvg_ratio_fund",$B14,G$4,G$5,101)/100 -> 0.016836692 | H14: =-[1]!thsiFinD("ths_max_retrace_rate_all_fund",$B14,E$3,E$5)/100 -> -0.045758396
A15: 7 | B15: 001751.OF | C15: 华商信用增强债券 | D15: 361 | E15: =[1]!thsiFinD("ths_adjustment_nvg_ratio_fund",$B15,E$4,E$5,101)/100 -> 0.017039922 | F15: =[1]!thsiFinD("ths_adjustment_nvg_ratio_fund",$B15,F$4,F$5,101)/100 -> -0.02872444 | G15: =[1]!thsiFinD("ths_adjustment_nvg_ratio_fund",$B15,G$4,G$5,101)/100 -> 0.038270378 | H15: =-[1]!thsiFinD("ths_max_retrace_rate_all_fund",$B15,E$3,E$5)/100 -> -0.052405908
A16: 8 | B16: 014846.OF | C16: 博时恒乐债券 | D16: 359 | E16: =[1]!thsiFinD("ths_adjustment_nvg_ratio_fund",$B16,E$4,E$5,101)/100 -> -0.01010101 | F16: =[1]!thsiFinD("ths_adjustment_nvg_ratio_fund",$B16,F$4,F$5,101)/100 -> -0.016463851 | G16: =[1]!thsiFinD("ths_adjustment_nvg_ratio_fund",$B16,G$4,G$5,101)/100 -> 0.0054936177 | H16: =-[1]!thsiFinD("ths_max_retrace_rate_all_fund",$B16,E$3,E$5)/100 -> -0.030877743
A17: 9 | B17: 000171.OF | C17: 易方达裕丰回报债券 | D17: 342 | E17: =[1]!thsiFinD("ths_adjustment_nvg_ratio_fund",$B17,E$4,E$5,101)/100 -> -0.018097448 | F17: =[1]!thsiFinD("ths_adjustment_nvg_ratio_fund",$B17,F$4,F$5,101)/100 -> -0.048259861 | G17: =[1]!thsiFinD("ths_adjustment_nvg_ratio_fund",$B17,G$4,G$5,101)/100 -> 0.026188167 | H17: =-[1]!thsiFinD("ths_max_retrace_rate_all_fund",$B17,E$3,E$5)/100 -> -0.06347032
A18: 10 | B18: 202101.OF | C18: 南方宝元债券 | D18: 314 | E18: =[1]!thsiFinD("ths_adjustment_nvg_ratio_fund",$B18,E$4,E$5,101)/100 -> 0.0029280055 | F18: =[1]!thsiFinD("ths_adjustment_nvg_ratio_fund",$B18,F$4,F$5,101)/100 -> -0.00072338959 | G18: =[1]!thsiFinD("ths_adjustment_nvg_ratio_fund",$B18,G$4,G$5,101)/100 -> 0.0032736044 | H18: =-[1]!thsiFinD("ths_max_retrace_rate_all_fund",$B18,E$3,E$5)/100 -> -0.026377751
C21: 公募固收+Q2规模增长前十基金表现
A22: =表3[[#Headers],[序号]] -> 序号 | B22: =表3[[#Headers],[基金代码]] -> 基金代码 | C22: =表3[[#Headers],[产品/基金名称]] -> 产品/基金名称 | D22: =表3[[#Headers],[26Q2规模（亿元）]] -> 26Q2规模（亿元） | E22: =表3[[#Headers],[上线以来]] -> 上线以来 | F22: =表3[[#Headers],[6/22-7/30]] -> 6/22-7/30 | G22: =表3[[#Headers],[7.31至今]] -> 7.31至今 | H22: =表3[[#Headers],[最大回撤（上线以来）]] -> 最大回撤（上线以来）
A23: 组合 | C23: =C8 -> 10/90基石投顾组合 | E23: =E$2/E$1-1 -> -0.0013453011 | F23: =F$2/F$1-1 -> -0.02609679 | G23: =G$2/G$1-1 -> 0.021956981 | H23: ='看板-10-90基石'!$F$7 -> -0.028729069
A24: 1 | B24: 003504.OF | C24: 景顺长城景颐丰利债券 | D24: 391 | E24: =[1]!thsiFinD("ths_adjustment_nvg_ratio_fund",$B24,E$4,E$5,101)/100 -> -0.02989781 | F24: =[1]!thsiFinD("ths_adjustment_nvg_ratio_fund",$B24,F$4,F$5,101)/100 -> -0.07340146 | G24: =[1]!thsiFinD("ths_adjustment_nvg_ratio_fund",$B24,G$4,G$5,101)/100 -> 0.037210464 | H24: =-[1]!thsiFinD("ths_max_retrace_rate_all_fund",$B24,E$3,E$5)/100 -> -0.078192169
A25: 2 | B25: 002969.OF | C25: 易方达丰和债券 | D25: 347 | E25: =[1]!thsiFinD("ths_adjustment_nvg_ratio_fund",$B25,E$4,E$5,101)/100 -> -0.011805271 | F25: =[1]!thsiFinD("ths_adjustment_nvg_ratio_fund",$B25,F$4,F$5,101)/100 -> -0.056454912 | G25: =[1]!thsiFinD("ths_adjustment_nvg_ratio_fund",$B25,G$4,G$5,101)/100 -> 0.037935056 | H25: =-[1]!thsiFinD("ths_max_retrace_rate_all_fund",$B25,E$3,E$5)/100 -> -0.070577399
A26: 3 | B26: 470010.OF | C26: 汇添富多元收益债券 | D26: 255 | E26: =[1]!thsiFinD("ths_adjustment_nvg_ratio_fund",$B26,E$4,E$5,101)/100 -> -0.028318811 | F26: =[1]!thsiFinD("ths_adjustment_nvg_ratio_fund",$B26,F$4,F$5,101)/100 -> -0.053754485 | G26: =[1]!thsiFinD("ths_adjustment_nvg_ratio_fund",$B26,G$4,G$5,101)/100 -> 0.020111657 | H26: =-[1]!thsiFinD("ths_max_retrace_rate_all_fund",$B26,E$3,E$5)/100 -> -0.066198786
A27: 4 | B27: 000143.OF | C27: 鹏华双债加利债券 | D27: 228 | E27: =[1]!thsiFinD("ths_adjustment_nvg_ratio_fund",$B27,E$4,E$5,101)/100 -> -0.017138566 | F27: =[1]!thsiFinD("ths_adjustment_nvg_ratio_fund",$B27,F$4,F$5,101)/100 -> -0.051945757 | G27: =[1]!thsiFinD("ths_adjustment_nvg_ratio_fund",$B27,G$4,G$5,101)/100 -> 0.029424011 | H27: =-[1]!thsiFinD("ths_max_retrace_rate_all_fund",$B27,E$3,E$5)/100 -> -0.06090571
A28: 5 | B28: 000406.OF | C28: 汇添富双利增强债券 | D28: 172 | E28: =[1]!thsiFinD("ths_adjustment_nvg_ratio_fund",$B28,E$4,E$5,101)/100 -> -0.01863354 | F28: =[1]!thsiFinD("ths_adjustment_nvg_ratio_fund",$B28,F$4,F$5,101)/100 -> -0.04058934 | G28: =[1]!thsiFinD("ths_adjustment_nvg_ratio_fund",$B28,G$4,G$5,101)/100 -> 0.021116706 | H28: =-[1]!thsiFinD("ths_max_retrace_rate_all_fund",$B28,E$3,E$5)/100 -> -0.050897344
A29: 6 | B29: 000171.OF | C29: 易方达裕丰回报债券 | D29: 146 | E29: =[1]!thsiFinD("ths_adjustment_nvg_ratio_fund",$B29,E$4,E$5,101)/100 -> -0.018097448 | F29: =[1]!thsiFinD("ths_adjustment_nvg_ratio_fund",$B29,F$4,F$5,101)/100 -> -0.048259861 | G29: =[1]!thsiFinD("ths_adjustment_nvg_ratio_fund",$B29,G$4,G$5,101)/100 -> 0.026188167 | H29: =-[1]!thsiFinD("ths_max_retrace_rate_all_fund",$B29,E$3,E$5)/100 -> -0.06347032
A30: 7 | B30: 018595.OF | C30: 华商利欣回报债券 | D30: 130 | E30: =[1]!thsiFinD("ths_adjustment_nvg_ratio_fund",$B30,E$4,E$5,101)/100 -> 0.020602219 | F30: =[1]!thsiFinD("ths_adjustment_nvg_ratio_fund",$B30,F$4,F$5,101)/100 -> -0.022028526 | G30: =[1]!thsiFinD("ths_adjustment_nvg_ratio_fund",$B30,G$4,G$5,101)/100 -> 0.036870069 | H30: =-[1]!thsiFinD("ths_max_retrace_rate_all_fund",$B30,E$3,E$5)/100 -> -0.04644491
A31: 8 | B31: 001751.OF | C31: 华商信用增强债券 | D31: 123 | E31: =[1]!thsiFinD("ths_adjustment_nvg_ratio_fund",$B31,E$4,E$5,101)/100 -> 0.017039922 | F31: =[1]!thsiFinD("ths_adjustment_nvg_ratio_fund",$B31,F$4,F$5,101)/100 -> -0.02872444 | G31: =[1]!thsiFinD("ths_adjustment_nvg_ratio_fund",$B31,G$4,G$5,101)/100 -> 0.038270378 | H31: =-[1]!thsiFinD("ths_max_retrace_rate_all_fund",$B31,E$3,E$5)/100 -> -0.052405908
A32: 9 | B32: 020218.OF | C32: 万家锦利债券发起式 | D32: 120 | E32: =[1]!thsiFinD("ths_adjustment_nvg_ratio_fund",$B32,E$4,E$5,101)/100 -> -0.025978243 | F32: =[1]!thsiFinD("ths_adjustment_nvg_ratio_fund",$B32,F$4,F$5,101)/100 -> -0.047978568 | G32: =[1]!thsiFinD("ths_adjustment_nvg_ratio_fund",$B32,G$4,G$5,101)/100 -> 0.01902497 | H32: =-[1]!thsiFinD("ths_max_retrace_rate_all_fund",$B32,E$3,E$5)/100 -> -0.057478667
A33: 10 | B33: 014846.OF | C33: 博时恒乐债券 | D33: 114 | E33: =[1]!thsiFinD("ths_adjustment_nvg_ratio_fund",$B33,E$4,E$5,101)/100 -> -0.01010101 | F33: =[1]!thsiFinD("ths_adjustment_nvg_ratio_fund",$B33,F$4,F$5,101)/100 -> -0.016463851 | G33: =[1]!thsiFinD("ths_adjustment_nvg_ratio_fund",$B33,G$4,G$5,101)/100 -> 0.0054936177 | H33: =-[1]!thsiFinD("ths_max_retrace_rate_all_fund",$B33,E$3,E$5)/100 -> -0.030877743
C36: 公司公募固收+保有前十基金表现（2026Q2）
A37: =A22 -> 序号 | B37: =B22 -> 基金代码 | C37: =C22 -> 产品/基金名称 | D37: 公司固收加保有前十（万元） | E37: =E22 -> 上线以来 | F37: =F22 -> 6/22-7/30 | G37: =G22 -> 7.31至今 | H37: =H22 -> 最大回撤（上线以来）
A38: 组合 | C38: =C8 -> 10/90基石投顾组合 | E38: =E$2/E$1-1 -> -0.0013453011 | F38: =F$2/F$1-1 -> -0.02609679 | G38: =G$2/G$1-1 -> 0.021956981 | H38: ='看板-10-90基石'!$F$7 -> -0.028729069
A39: 1 | B39: 009355.OF | C39: 宏利泰和稳健养老目标一年持有期混合(FOF) | D39: 5265 | E39: =[1]!thsiFinD("ths_adjustment_nvg_ratio_fund",$B39,E$4,E$5,101)/100 -> -0.0068749004 | F39: =[1]!thsiFinD("ths_adjustment_nvg_ratio_fund",$B39,F$4,F$5,101)/100 -> -0.018110759 | G39: =[1]!thsiFinD("ths_adjustment_nvg_ratio_fund",$B39,G$4,G$5,101)/100 -> 0.0077821012 | H39: =-[1]!thsiFinD("ths_max_retrace_rate_all_fund",$B39,E$3,E$5)/100 -> -0.018873622
A40: 2 | B40: 024057.OF | C40: 宏利鼎森稳健3个月持有期混合(FOF) | D40: 896 | E40: =[1]!thsiFinD("ths_adjustment_nvg_ratio_fund",$B40,E$4,E$5,101)/100 -> 0 | F40: =[1]!thsiFinD("ths_adjustment_nvg_ratio_fund",$B40,F$4,F$5,101)/100 -> -0.012397914 | G40: =[1]!thsiFinD("ths_adjustment_nvg_ratio_fund",$B40,G$4,G$5,101)/100 -> 0.0095361081 | H40: =-[1]!thsiFinD("ths_max_retrace_rate_all_fund",$B40,E$3,E$5)/100 -> -0.013283479
A41: 3 | B41: 011168.OF | C41: 嘉实睿享安久双利18个月持有期债券 | D41: 239 | E41: =[1]!thsiFinD("ths_adjustment_nvg_ratio_fund",$B41,E$4,E$5,101)/100 -> -0.013638578 | F41: =[1]!thsiFinD("ths_adjustment_nvg_ratio_fund",$B41,F$4,F$5,101)/100 -> -0.026627699 | G41: =[1]!thsiFinD("ths_adjustment_nvg_ratio_fund",$B41,G$4,G$5,101)/100 -> 0.011320127 | H41: =-[1]!thsiFinD("ths_max_retrace_rate_all_fund",$B41,E$3,E$5)/100 -> -0.04941999
A42: 4 | B42: 002969.OF | C42: 易方达丰和债券 | D42: 225 | E42: =[1]!thsiFinD("ths_adjustment_nvg_ratio_fund",$B42,E$4,E$5,101)/100 -> -0.011805271 | F42: =[1]!thsiFinD("ths_adjustment_nvg_ratio_fund",$B42,F$4,F$5,101)/100 -> -0.056454912 | G42: =[1]!thsiFinD("ths_adjustment_nvg_ratio_fund",$B42,G$4,G$5,101)/100 -> 0.037935056 | H42: =-[1]!thsiFinD("ths_max_retrace_rate_all_fund",$B42,E$3,E$5)/100 -> -0.070577399
A43: 5 | B43: 014738.OF | C43: 广发恒祥债券 | D43: 205 | E43: =[1]!thsiFinD("ths_adjustment_nvg_ratio_fund",$B43,E$4,E$5,101)/100 -> -0.023467721 | F43: =[1]!thsiFinD("ths_adjustment_nvg_ratio_fund",$B43,F$4,F$5,101)/100 -> -0.029313161 | G43: =[1]!thsiFinD("ths_adjustment_nvg_ratio_fund",$B43,G$4,G$5,101)/100 -> 0.0081647142 | H43: =-[1]!thsiFinD("ths_max_retrace_rate_all_fund",$B43,E$3,E$5)/100 -> -0.056883967
A44: 6 | B44: 006307.OF | C44: 嘉实养老目标日期2040五年持有期混合(FOF) | D44: 190 | E44: =[1]!thsiFinD("ths_adjustment_nvg_ratio_fund",$B44,E$4,E$5,101)/100 -> -0.039890261 | F44: =[1]!thsiFinD("ths_adjustment_nvg_ratio_fund",$B44,F$4,F$5,101)/100 -> -0.093443073 | G44: =[1]!thsiFinD("ths_adjustment_nvg_ratio_fund",$B44,G$4,G$5,101)/100 -> 0.046781527 | H44: =-[1]!thsiFinD("ths_max_retrace_rate_all_fund",$B44,E$3,E$5)/100 -> -0.11736738
...

Sheet 实盘净值数据(iFinD公式)
A1: 净值数据 * 实盘
A2: =TODAY() -> 46252
A3: 基金代码→ | B3: =实盘持仓初始配置!B3 -> 000216.OF | C3: =实盘持仓初始配置!C3 -> 000917.OF | D3: =实盘持仓初始配置!D3 -> 001170.OF | E3: =实盘持仓初始配置!E3 -> 007044.OF | F3: =实盘持仓初始配置!F3 -> 007045.OF | G3: =实盘持仓初始配置!G3 -> 007817.OF | H3: =实盘持仓初始配置!H3 -> 007818.OF | I3: =实盘持仓初始配置!I3 -> 009993.OF | ... X3: =实盘持仓初始配置!X3 -> 161119.OF | Y3: 162214.OF
A4: =[1]!HX_AutoDate(1,"2026-06-18",A2,-1,-1,0,0,0,0,0,"SSE",43,0) -> 日期 | B4: 华安黄金ETF联接A | C4: 嘉实快线货币A | D4: 宏利复兴混合A | E4: 博道沪深300增强A | F4: 博道沪深300指增C | G4: 国泰通信设备ETF联接A | H4: 国泰通信设备C | I4: 嘉实前沿科技创新 | J4: 银华集成电路混合A | K4: 银华集成电路混合C | L4: 天弘中证1000指增A | M4: 天弘中证1000指增C | N4: 中欧中证500指增A | O4: 中欧中证500指增C | P4: 信澳业绩驱动A | Q4: 嘉实信息产业A | R4: 嘉实信息产业C | S4: 宏利复兴伟业C | T4: 国泰半导体材料设备ETF联接A | U4: 国泰半导体材料设备C | V4: 华泰柏瑞中证2000指增A | W4: 华泰柏瑞中证2000指增C | X4: 易方达中债新综指LOFA | Y4: 宏利领先中小盘混合
A5: 46191 | B5: =IF($A5="","",[1]!thsiFinD("ths_adjustment_nv_fund",B$3,$A5)) -> 3.2441 | C5: =IF($A5="","",[1]!thsiFinD("ths_adjustment_nv_fund",C$3,$A5)) -> 1.3172785 | D5: =IF($A5="","",[1]!thsiFinD("ths_adjustment_nv_fund",D$3,$A5)) -> 6.062 | E5: =IF($A5="","",[1]!thsiFinD("ths_adjustment_nv_fund",E$3,$A5)) -> 1.9904 | F5: =IF($A5="","",[1]!thsiFinD("ths_adjustment_nv_fund",F$3,$A5)) -> 1.9344 | G5: =IF($A5="","",[1]!thsiFinD("ths_adjustment_nv_fund",G$3,$A5)) -> 5.0275 | H5: =IF($A5="","",[1]!thsiFinD("ths_adjustment_nv_fund",H$3,$A5)) -> 4.9215 | I5: =IF($A5="","",[1]!thsiFinD("ths_adjustment_nv_fund",I$3,$A5)) -> 2.9226 | ... Y5: =IF($A5="","",[1]!thsiFinD("ths_adjustment_nv_fund",Y$3,$A5)) -> 2.39
A6: 46195 | B6: =IF($A6="","",[1]!thsiFinD("ths_adjustment_nv_fund",B$3,$A6)) -> 3.168 | C6: =IF($A6="","",[1]!thsiFinD("ths_adjustment_nv_fund",C$3,$A6)) -> 1.3174604 | D6: =IF($A6="","",[1]!thsiFinD("ths_adjustment_nv_fund",D$3,$A6)) -> 6.259 | E6: =IF($A6="","",[1]!thsiFinD("ths_adjustment_nv_fund",E$3,$A6)) -> 2.0345 | F6: =IF($A6="","",[1]!thsiFinD("ths_adjustment_nv_fund",F$3,$A6)) -> 1.9772 | G6: =IF($A6="","",[1]!thsiFinD("ths_adjustment_nv_fund",G$3,$A6)) -> 5.1121 | H6: =IF($A6="","",[1]!thsiFinD("ths_adjustment_nv_fund",H$3,$A6)) -> 5.0042 | I6: =IF($A6="","",[1]!thsiFinD("ths_adjustment_nv_fund",I$3,$A6)) -> 2.9905 | ... Y6: =IF($A6="","",[1]!thsiFinD("ths_adjustment_nv_fund",Y$3,$A6)) -> 2.428
A7: 46196 | B7: =IF($A7="","",[1]!thsiFinD("ths_adjustment_nv_fund",B$3,$A7)) -> 3.116 | C7: =IF($A7="","",[1]!thsiFinD("ths_adjustment_nv_fund",C$3,$A7)) -> 1.3175125 | D7: =IF($A7="","",[1]!thsiFinD("ths_adjustment_nv_fund",D$3,$A7)) -> 5.996 | E7: =IF($A7="","",[1]!thsiFinD("ths_adjustment_nv_fund",E$3,$A7)) -> 1.9837 | F7: =IF($A7="","",[1]!thsiFinD("ths_adjustment_nv_fund",F$3,$A7)) -> 1.9278 | G7: =IF($A7="","",[1]!thsiFinD("ths_adjustment_nv_fund",G$3,$A7)) -> 4.9665 | H7: =IF($A7="","",[1]!thsiFinD("ths_adjustment_nv_fund",H$3,$A7)) -> 4.8616 | I7: =IF($A7="","",[1]!thsiFinD("ths_adjustment_nv_fund",I$3,$A7)) -> 2.9276 | ... Y7: =IF($A7="","",[1]!thsiFinD("ths_adjustment_nv_fund",Y$3,$A7)) -> 2.458
A8: 46197 | B8: =IF($A8="","",[1]!thsiFinD("ths_adjustment_nv_fund",B$3,$A8)) -> 3.0984 | C8: =IF($A8="","",[1]!thsiFinD("ths_adjustment_nv_fund",C$3,$A8)) -> 1.3175573 | D8: =IF($A8="","",[1]!thsiFinD("ths_adjustment_nv_fund",D$3,$A8)) -> 6.113 | E8: =IF($A8="","",[1]!thsiFinD("ths_adjustment_nv_fund",E$3,$A8)) -> 1.9931 | F8: =IF($A8="","",[1]!thsiFinD("ths_adjustment_nv_fund",F$3,$A8)) -> 1.9369 | G8: =IF($A8="","",[1]!thsiFinD("ths_adjustment_nv_fund",G$3,$A8)) -> 5.0423 | H8: =IF($A8="","",[1]!thsiFinD("ths_adjustment_nv_fund",H$3,$A8)) -> 4.9357 | I8: =IF($A8="","",[1]!thsiFinD("ths_adjustment_nv_fund",I$3,$A8)) -> 3.0529 | ... Y8: =IF($A8="","",[1]!thsiFinD("ths_adjustment_nv_fund",Y$3,$A8)) -> 2.633
A9: 46198 | B9: =IF($A9="","",[1]!thsiFinD("ths_adjustment_nv_fund",B$3,$A9)) -> 3.0309 | C9: =IF($A9="","",[1]!thsiFinD("ths_adjustment_nv_fund",C$3,$A9)) -> 1.3176051 | D9: =IF($A9="","",[1]!thsiFinD("ths_adjustment_nv_fund",D$3,$A9)) -> 6.312 | E9: =IF($A9="","",[1]!thsiFinD("ths_adjustment_nv_fund",E$3,$A9)) -> 2.0205 | F9: =IF($A9="","",[1]!thsiFinD("ths_adjustment_nv_fund",F$3,$A9)) -> 1.9635 | G9: =IF($A9="","",[1]!thsiFinD("ths_adjustment_nv_fund",G$3,$A9)) -> 5.1945 | H9: =IF($A9="","",[1]!thsiFinD("ths_adjustment_nv_fund",H$3,$A9)) -> 5.0848 | I9: =IF($A9="","",[1]!thsiFinD("ths_adjustment_nv_fund",I$3,$A9)) -> 3.1735 | ... Y9: =IF($A9="","",[1]!thsiFinD("ths_adjustment_nv_fund",Y$3,$A9)) -> 2.692
A10: 46199 | B10: =IF($A10="","",[1]!thsiFinD("ths_adjustment_nv_fund",B$3,$A10)) -> 3.0598 | C10: =IF($A10="","",[1]!thsiFinD("ths_adjustment_nv_fund",C$3,$A10)) -> 1.3176497 | D10: =IF($A10="","",[1]!thsiFinD("ths_adjustment_nv_fund",D$3,$A10)) -> 5.99 | E10: =IF($A10="","",[1]!thsiFinD("ths_adjustment_nv_fund",E$3,$A10)) -> 1.9618 | F10: =IF($A10="","",[1]!thsiFinD("ths_adjustment_nv_fund",F$3,$A10)) -> 1.9065 | G10: =IF($A10="","",[1]!thsiFinD("ths_adjustment_nv_fund",G$3,$A10)) -> 4.8685 | H10: =IF($A10="","",[1]!thsiFinD("ths_adjustment_nv_fund",H$3,$A10)) -> 4.7655 | I10: =IF($A10="","",[1]!thsiFinD("ths_adjustment_nv_fund",I$3,$A10)) -> 3.0956 | ... Y10: =IF($A10="","",[1]!thsiFinD("ths_adjustment_nv_fund",Y$3,$A10)) -> 2.767
A11: 46202 | B11: =IF($A11="","",[1]!thsiFinD("ths_adjustment_nv_fund",B$3,$A11)) -> 3.0723 | C11: =IF($A11="","",[1]!thsiFinD("ths_adjustment_nv_fund",C$3,$A11)) -> 1.3177908 | D11: =IF($A11="","",[1]!thsiFinD("ths_adjustment_nv_fund",D$3,$A11)) -> 5.795 | E11: =IF($A11="","",[1]!thsiFinD("ths_adjustment_nv_fund",E$3,$A11)) -> 1.9811 | F11: =IF($A11="","",[1]!thsiFinD("ths_adjustment_nv_fund",F$3,$A11)) -> 1.9252 | G11: =IF($A11="","",[1]!thsiFinD("ths_adjustment_nv_fund",G$3,$A11)) -> 4.7592 | H11: =IF($A11="","",[1]!thsiFinD("ths_adjustment_nv_fund",H$3,$A11)) -> 4.6585 | I11: =IF($A11="","",[1]!thsiFinD("ths_adjustment_nv_fund",I$3,$A11)) -> 3.1442 | ... Y11: =IF($A11="","",[1]!thsiFinD("ths_adjustment_nv_fund",Y$3,$A11)) -> 2.968
A12: 46203 | B12: =IF($A12="","",[1]!thsiFinD("ths_adjustment_nv_fund",B$3,$A12)) -> 3.0429 | C12: =IF($A12="","",[1]!thsiFinD("ths_adjustment_nv_fund",C$3,$A12)) -> 1.3178318 | D12: =IF($A12="","",[1]!thsiFinD("ths_adjustment_nv_fund",D$3,$A12)) -> 6.024 | E12: =IF($A12="","",[1]!thsiFinD("ths_adjustment_nv_fund",E$3,$A12)) -> 2.0032 | F12: =IF($A12="","",[1]!thsiFinD("ths_adjustment_nv_fund",F$3,$A12)) -> 1.9466 | G12: =IF($A12="","",[1]!thsiFinD("ths_adjustment_nv_fund",G$3,$A12)) -> 4.9737 | H12: =IF($A12="","",[1]!thsiFinD("ths_adjustment_nv_fund",H$3,$A12)) -> 4.8684 | I12: =IF($A12="","",[1]!thsiFinD("ths_adjustment_nv_fund",I$3,$A12)) -> 3.2499 | ... Y12: =IF($A12="","",[1]!thsiFinD("ths_adjustment_nv_fund",Y$3,$A12)) -> 3.087
A13: 46204 | B13: =IF($A13="","",[1]!thsiFinD("ths_adjustment_nv_fund",B$3,$A13)) -> 3.0102 | C13: =IF($A13="","",[1]!thsiFinD("ths_adjustment_nv_fund",C$3,$A13)) -> 1.3178766 | D13: =IF($A13="","",[1]!thsiFinD("ths_adjustment_nv_fund",D$3,$A13)) -> 5.777 | E13: =IF($A13="","",[1]!thsiFinD("ths_adjustment_nv_fund",E$3,$A13)) -> 1.9953 | F13: =IF($A13="","",[1]!thsiFinD("ths_adjustment_nv_fund",F$3,$A13)) -> 1.9389 | G13: =IF($A13="","",[1]!thsiFinD("ths_adjustment_nv_fund",G$3,$A13)) -> 4.77 | H13: =IF($A13="","",[1]!thsiFinD("ths_adjustment_nv_fund",H$3,$A13)) -> 4.6689 | I13: =IF($A13="","",[1]!thsiFinD("ths_adjustment_nv_fund",I$3,$A13)) -> 3.1869 | ... Y13: =IF($A13="","",[1]!thsiFinD("ths_adjustment_nv_fund",Y$3,$A13)) -> 3.037
A14: 46205 | B14: =IF($A14="","",[1]!thsiFinD("ths_adjustment_nv_fund",B$3,$A14)) -> 3.0728 | C14: =IF($A14="","",[1]!thsiFinD("ths_adjustment_nv_fund",C$3,$A14)) -> 1.3179215 | D14: =IF($A14="","",[1]!thsiFinD("ths_adjustment_nv_fund",D$3,$A14)) -> 5.363 | E14: =IF($A14="","",[1]!thsiFinD("ths_adjustment_nv_fund",E$3,$A14)) -> 1.9341 | F14: =IF($A14="","",[1]!thsiFinD("ths_adjustment_nv_fund",F$3,$A14)) -> 1.8795 | G14: =IF($A14="","",[1]!thsiFinD("ths_adjustment_nv_fund",G$3,$A14)) -> 4.4049 | H14: =IF($A14="","",[1]!thsiFinD("ths_adjustment_nv_fund",H$3,$A14)) -> 4.3115 | I14: =IF($A14="","",[1]!thsiFinD("ths_adjustment_nv_fund",I$3,$A14)) -> 2.9271 | ... Y14: =IF($A14="","",[1]!thsiFinD("ths_adjustment_nv_fund",Y$3,$A14)) -> 2.777
A15: 46206 | B15: =IF($A15="","",[1]!thsiFinD("ths_adjustment_nv_fund",B$3,$A15)) -> 3.1547 | C15: =IF($A15="","",[1]!thsiFinD("ths_adjustment_nv_fund",C$3,$A15)) -> 1.3179685 | D15: =IF($A15="","",[1]!thsiFinD("ths_adjustment_nv_fund",D$3,$A15)) -> 5.405 | E15: =IF($A15="","",[1]!thsiFinD("ths_adjustment_nv_fund",E$3,$A15)) -> 1.9475 | F15: =IF($A15="","",[1]!thsiFinD("ths_adjustment_nv_fund",F$3,$A15)) -> 1.8924 | G15: =IF($A15="","",[1]!thsiFinD("ths_adjustment_nv_fund",G$3,$A15)) -> 4.4033 | H15: =IF($A15="","",[1]!thsiFinD("ths_adjustment_nv_fund",H$3,$A15)) -> 4.3099 | I15: =IF($A15="","",[1]!thsiFinD("ths_adjustment_nv_fund",I$3,$A15)) -> 2.9794 | ... Y15: =IF($A15="","",[1]!thsiFinD("ths_adjustment_nv_fund",Y$3,$A15)) -> 2.741
A16: 46209 | B16: =IF($A16="","",[1]!thsiFinD("ths_adjustment_nv_fund",B$3,$A16)) -> 3.145 | C16: =IF($A16="","",[1]!thsiFinD("ths_adjustment_nv_fund",C$3,$A16)) -> 1.3181065 | D16: =IF($A16="","",[1]!thsiFinD("ths_adjustment_nv_fund",D$3,$A16)) -> 5.234 | E16: =IF($A16="","",[1]!thsiFinD("ths_adjustment_nv_fund",E$3,$A16)) -> 1.9455 | F16: =IF($A16="","",[1]!thsiFinD("ths_adjustment_nv_fund",F$3,$A16)) -> 1.8904 | G16: =IF($A16="","",[1]!thsiFinD("ths_adjustment_nv_fund",G$3,$A16)) -> 4.2539 | H16: =IF($A16="","",[1]!thsiFinD("ths_adjustment_nv_fund",H$3,$A16)) -> 4.1636 | I16: =IF($A16="","",[1]!thsiFinD("ths_adjustment_nv_fund",I$3,$A16)) -> 2.9168 | ... Y16: =IF($A16="","",[1]!thsiFinD("ths_adjustment_nv_fund",Y$3,$A16)) -> 2.759
... A47: 46252 | B47: =IF($A47="","",[1]!thsiFinD("ths_adjustment_nv_fund",B$3,$A47)) -> 3.2962 | C47: =IF($A47="","",[1]!thsiFinD("ths_adjustment_nv_fund",C$3,$A47)) -> 1.319977 | D47: =IF($A47="","",[1]!thsiFinD("ths_adjustment_nv_fund",D$3,$A47)) -> 4.904 | E47: =IF($A47="","",[1]!thsiFinD("ths_adjustment_nv_fund",E$3,$A47)) -> 1.9381 | F47: =IF($A47="","",[1]!thsiFinD("ths_adjustment_nv_fund",F$3,$A47)) -> 1.8823 | G47: =IF($A47="","",[1]!thsiFinD("ths_adjustment_nv_fund",G$3,$A47)) -> 4.0641 | H47: =IF($A47="","",[1]!thsiFinD("ths_adjustment_nv_fund",H$3,$A47)) -> 3.9764 | I47: =IF($A47="","",[1]!thsiFinD("ths_adjustment_nv_fund",I$3,$A47)) -> 2.5301 | ... Y47: =IF($A47="","",[1]!thsiFinD("ths_adjustment_nv_fund",Y$3,$A47)) -> 2.656
B48: =IF($A48="","",[1]!thsiFinD("ths_adjustment_nv_fund",B$3,$A48)) | C48: =IF($A48="","",[1]!thsiFinD("ths_adjustment_nv_fund",C$3,$A48)) | D48: =IF($A48="","",[1]!thsiFinD("ths_adjustment_nv_fund",D$3,$A48)) | E48: =IF($A48="","",[1]!thsiFinD("ths_adjustment_nv_fund",E$3,$A48)) | F48: =IF($A48="","",[1]!thsiFinD("ths_adjustment_nv_fund",F$3,$A48)) | G48: =IF($A48="","",[1]!thsiFinD("ths_adjustment_nv_fund",G$3,$A48)) | H48: =IF($A48="","",[1]!thsiFinD("ths_adjustment_nv_fund",H$3,$A48)) | I48: =IF($A48="","",[1]!thsiFinD("ths_adjustment_nv_fund",I$3,$A48)) | ... Y48: =IF($A48="","",[1]!thsiFinD("ths_adjustment_nv_fund",Y$3,$A48))
B49: =IF($A49="","",[1]!thsiFinD("ths_adjustment_nv_fund",B$3,$A49)) | C49: =IF($A49="","",[1]!thsiFinD("ths_adjustment_nv_fund",C$3,$A49)) | D49: =IF($A49="","",[1]!thsiFinD("ths_adjustment_nv_fund",D$3,$A49)) | E49: =IF($A49="","",[1]!thsiFinD("ths_adjustment_nv_fund",E$3,$A49)) | F49: =IF($A49="","",[1]!thsiFinD("ths_adjustment_nv_fund",F$3,$A49)) | G49: =IF($A49="","",[1]!thsiFinD("ths_adjustment_nv_fund",G$3,$A49)) | H49: =IF($A49="","",[1]!thsiFinD("ths_adjustment_nv_fund",H$3,$A49)) | I49: =IF($A49="","",[1]!thsiFinD("ths_adjustment_nv_fund",I$3,$A49)) | ... Y49: =IF($A49="","",[1]!thsiFinD("ths_adjustment_nv_fund",Y$3,$A49))
B50: =IF($A50="","",[1]!thsiFinD("ths_adjustment_nv_fund",B$3,$A50)) | C50: =IF($A50="","",[1]!thsiFinD("ths_adjustment_nv_fund",C$3,$A50)) | D50: =IF($A50="","",[1]!thsiFinD("ths_adjustment_nv_fund",D$3,$A50)) | E50: =IF($A50="","",[1]!thsiFinD("ths_adjustment_nv_fund",E$3,$A50)) | F50: =IF($A50="","",[1]!thsiFinD("ths_adjustment_nv_fund",F$3,$A50)) | G50: =IF($A50="","",[1]!thsiFinD("ths_adjustment_nv_fund",G$3,$A50)) | H50: =IF($A50="","",[1]!thsiFinD("ths_adjustment_nv_fund",H$3,$A50)) | I50: =IF($A50="","",[1]!thsiFinD("ths_adjustment_nv_fund",I$3,$A50)) | ... Y50: =IF($A50="","",[1]!thsiFinD("ths_adjustment_nv_fund",Y$3,$A50))
B51: =IF($A51="","",[1]!thsiFinD("ths_adjustment_nv_fund",B$3,$A51)) | C51: =IF($A51="","",[1]!thsiFinD("ths_adjustment_nv_fund",C$3,$A51)) | D51: =IF($A51="","",[1]!thsiFinD("ths_adjustment_nv_fund",D$3,$A51)) | E51: =IF($A51="","",[1]!thsiFinD("ths_adjustment_nv_fund",E$3,$A51)) | F51: =IF($A51="","",[1]!thsiFinD("ths_adjustment_nv_fund",F$3,$A51)) | G51: =IF($A51="","",[1]!thsiFinD("ths_adjustment_nv_fund",G$3,$A51)) | H51: =IF($A51="","",[1]!thsiFinD("ths_adjustment_nv_fund",H$3,$A51)) | I51: =IF($A51="","",[1]!thsiFinD("ths_adjustment_nv_fund",I$3,$A51)) | ... Y51: =IF($A51="","",[1]!thsiFinD("ths_adjustment_nv_fund",Y$3,$A51))
B52: =IF($A52="","",[1]!thsiFinD("ths_adjustment_nv_fund",B$3,$A52)) | C52: =IF($A52="","",[1]!thsiFinD("ths_adjustment_nv_fund",C$3,$A52)) | D52: =IF($A52="","",[1]!thsiFinD("ths_adjustment_nv_fund",D$3,$A52)) | E52: =IF($A52="","",[1]!thsiFinD("ths_adjustment_nv_fund",E$3,$A52)) | F52: =IF($A52="","",[1]!thsiFinD("ths_adjustment_nv_fund",F$3,$A52)) | G52: =IF($A52="","",[1]!thsiFinD("ths_adjustment_nv_fund",G$3,$A52)) | H52: =IF($A52="","",[1]!thsiFinD("ths_adjustment_nv_fund",H$3,$A52)) | I52: =IF($A52="","",[1]!thsiFinD("ths_adjustment_nv_fund",I$3,$A52)) | ... Y52: =IF($A52="","",[1]!thsiFinD("ths_adjustment_nv_fund",Y$3,$A52))
B53: =IF($A53="","",[1]!thsiFinD("ths_adjustment_nv_fund",B$3,$A53)) | C53: =IF($A53="","",[1]!thsiFinD("ths_adjustment_nv_fund",C$3,$A53)) | D53: =IF($A53="","",[1]!thsiFinD("ths_adjustment_nv_fund",D$3,$A53)) | E53: =IF($A53="","",[1]!thsiFinD("ths_adjustment_nv_fund",E$3,$A53)) | F53: =IF($A53="","",[1]!thsiFinD("ths_adjustment_nv_fund",F$3,$A53)) | G53: =IF($A53="","",[1]!thsiFinD("ths_adjustment_nv_fund",G$3,$A53)) | H53: =IF($A53="","",[1]!thsiFinD("ths_adjustment_nv_fund",H$3,$A53)) | I53: =IF($A53="","",[1]!thsiFinD("ths_adjustment_nv_fund",I$3,$A53)) | ... Y53: =IF($A53="","",[1]!thsiFinD("ths_adjustment_nv_fund",Y$3,$A53))
B54: =IF($A54="","",[1]!thsiFinD("ths_adjustment_nv_fund",B$3,$A54)) | C54: =IF($A54="","",[1]!thsiFinD("ths_adjustment_nv_fund",C$3,$A54)) | D54: =IF($A54="","",[1]!thsiFinD("ths_adjustment_nv_fund",D$3,$A54)) | E54: =IF($A54="","",[1]!thsiFinD("ths_adjustment_nv_fund",E$3,$A54)) | F54: =IF($A54="","",[1]!thsiFinD("ths_adjustment_nv_fund",F$3,$A54)) | G54: =IF($A54="","",[1]!thsiFinD("ths_adjustment_nv_fund",G$3,$A54)) | H54: =IF($A54="","",[1]!thsiFinD("ths_adjustment_nv_fund",H$3,$A54)) | I54: =IF($A54="","",[1]!thsiFinD("ths_adjustment_nv_fund",I$3,$A54)) | ... Y54: =IF($A54="","",[1]!thsiFinD("ths_adjustment_nv_fund",Y$3,$A54))
B55: =IF($A55="","",[1]!thsiFinD("ths_adjustment_nv_fund",B$3,$A55)) | C55: =IF($A55="","",[1]!thsiFinD("ths_adjustment_nv_fund",C$3,$A55)) | D55: =IF($A55="","",[1]!thsiFinD("ths_adjustment_nv_fund",D$3,$A55)) | E55: =IF($A55="","",[1]!thsiFinD("ths_adjustment_nv_fund",E$3,$A55)) | F55: =IF($A55="","",[1]!thsiFinD("ths_adjustment_nv_fund",F$3,$A55)) | G55: =IF($A55="","",[1]!thsiFinD("ths_adjustment_nv_fund",G$3,$A55)) | H55: =IF($A55="","",[1]!thsiFinD("ths_adjustment_nv_fund",H$3,$A55)) | I55: =IF($A55="","",[1]!thsiFinD("ths_adjustment_nv_fund",I$3,$A55)) | ... Y55: =IF($A55="","",[1]!thsiFinD("ths_adjustment_nv_fund",Y$3,$A55))
B56: =IF($A56="","",[1]!thsiFinD("ths_adjustment_nv_fund",B$3,$A56)) | C56: =IF($A56="","",[1]!thsiFinD("ths_adjustment_nv_fund",C$3,$A56)) | D56: =IF($A56="","",[1]!thsiFinD("ths_adjustment_nv_fund",D$3,$A56)) | E56: =IF($A56="","",[1]!thsiFinD("ths_adjustment_nv_fund",E$3,$A56)) | F56: =IF($A56="","",[1]!thsiFinD("ths_adjustment_nv_fund",F$3,$A56)) | G56: =IF($A56="","",[1]!thsiFinD("ths_adjustment_nv_fund",G$3,$A56)) | H56: =IF($A56="","",[1]!thsiFinD("ths_adjustment_nv_fund",H$3,$A56)) | I56: =IF($A56="","",[1]!thsiFinD("ths_adjustment_nv_fund",I$3,$A56)) | ... Y56: =IF($A56="","",[1]!thsiFinD("ths_adjustment_nv_fund",Y$3,$A56))
B57: =IF($A57="","",[1]!thsiFinD("ths_adjustment_nv_fund",B$3,$A57)) | C57: =IF($A57="","",[1]!thsiFinD("ths_adjustment_nv_fund",C$3,$A57)) | D57: =IF($A57="","",[1]!thsiFinD("ths_adjustment_nv_fund",D$3,$A57)) | E57: =IF($A57="","",[1]!thsiFinD("ths_adjustment_nv_fund",E$3,$A57)) | F57: =IF($A57="","",[1]!thsiFinD("ths_adjustment_nv_fund",F$3,$A57)) | G57: =IF($A57="","",[1]!thsiFinD("ths_adjustment_nv_fund",G$3,$A57)) | H57: =IF($A57="","",[1]!thsiFinD("ths_adjustment_nv_fund",H$3,$A57)) | I57: =IF($A57="","",[1]!thsiFinD("ths_adjustment_nv_fund",I$3,$A57)) | ... Y57: =IF($A57="","",[1]!thsiFinD("ths_adjustment_nv_fund",Y$3,$A57))
B58: =IF($A58="","",[1]!thsiFinD("ths_adjustment_nv_fund",B$3,$A58)) | C58: =IF($A58="","",[1]!thsiFinD("ths_adjustment_nv_fund",C$3,$A58)) | D58: =IF($A58="","",[1]!thsiFinD("ths_adjustment_nv_fund",D$3,$A58)) | E58: =IF($A58="","",[1]!thsiFinD("ths_adjustment_nv_fund",E$3,$A58)) | F58: =IF($A58="","",[1]!thsiFinD("ths_adjustment_nv_fund",F$3,$A58)) | G58: =IF($A58="","",[1]!thsiFinD("ths_adjustment_nv_fund",G$3,$A58)) | H58: =IF($A58="","",[1]!thsiFinD("ths_adjustment_nv_fund",H$3,$A58)) | I58: =IF($A58="","",[1]!thsiFinD("ths_adjustment_nv_fund",I$3,$A58)) | ... Y58: =IF($A58="","",[1]!thsiFinD("ths_adjustment_nv_fund",Y$3,$A58))
B59: =IF($A59="","",[1]!thsiFinD("ths_adjustment_nv_fund",B$3,$A59)) | C59: =IF($A59="","",[1]!thsiFinD("ths_adjustment_nv_fund",C$3,$A59)) | D59: =IF($A59="","",[1]!thsiFinD("ths_adjustment_nv_fund",D$3,$A59)) | E59: =IF($A59="","",[1]!thsiFinD("ths_adjustment_nv_fund",E$3,$A59)) | F59: =IF($A59="","",[1]!thsiFinD("ths_adjustment_nv_fund",F$3,$A59)) | G59: =IF($A59="","",[1]!thsiFinD("ths_adjustment_nv_fund",G$3,$A59)) | H59: =IF($A59="","",[1]!thsiFinD("ths_adjustment_nv_fund",H$3,$A59)) | I59: =IF($A59="","",[1]!thsiFinD("ths_adjustment_nv_fund",I$3,$A59)) | ... Y59: =IF($A59="","",[1]!thsiFinD("ths_adjustment_nv_fund",Y$3,$A59))
B60: =IF($A60="","",[1]!thsiFinD("ths_adjustment_nv_fund",B$3,$A60)) | C60: =IF($A60="","",[1]!thsiFinD("ths_adjustment_nv_fund",C$3,$A60)) | D60: =IF($A60="","",[1]!thsiFinD("ths_adjustment_nv_fund",D$3,$A60)) | E60: =IF($A60="","",[1]!thsiFinD("ths_adjustment_nv_fund",E$3,$A60)) | F60: =IF($A60="","",[1]!thsiFinD("ths_adjustment_nv_fund",F$3,$A60)) | G60: =IF($A60="","",[1]!thsiFinD("ths_adjustment_nv_fund",G$3,$A60)) | H60: =IF($A60="","",[1]!thsiFinD("ths_adjustment_nv_fund",H$3,$A60)) | I60: =IF($A60="","",[1]!thsiFinD("ths_adjustment_nv_fund",I$3,$A60)) | ... X60: =IF($A60="","",[1]!thsiFinD("ths_adjustment_nv_fund",X$3,$A60))

Sheet 实盘组合净值
A1: 组合净值
B3: 组合 产业趋势 | E3: 组合 产业趋势基石 | H3: 组合 产业趋势2号 | K3: 组合 10-90 | N3: 组合 10-90基石 | Q3: 组合 30-70
A4: 日期 | B4: 净值 | C4: 日收益 | D4: 回撤 | E4: 净值 | F4: 日收益 | G4: 回撤 | H4: 净值 | I4: 日收益 | J4: 回撤 | K4: 净值 | L4: 日收益 | M4: 回撤 | N4: 净值 | O4: 日收益 | P4: 回撤 | Q4: 净值 | R4: 日收益 | S4: 回撤
A5: =IF('实盘净值数据(iFinD公式)'!A5="","",'实盘净值数据(iFinD公式)'!A5) -> 46191 | B5: =IF(OR((ROW()-1)<6,'实盘净值数据(iFinD公式)'!$A5="",'实盘净值数据(iFinD公式)'!$B5=""),"",SUMPRODUCT(实盘持仓初始配置!$B$4:$X$4,'实盘净值数据(iFinD公式)'!$B5:$X5/'实盘净值数据(iFinD公式)'!$B$6:$X$6)*(1-实盘持仓初始配置!$Z$4)^(('实盘净值数据(iFinD公式)'!$A5-'实盘净值数据(iFinD公式)'!$A$6)/365)) | D5: =IF(B5="","",B5/MAX(B$5:B5)-1) | E5: 1 | G5: =IF(E5="","",E5/MAX(E$5:E5)-1) -> 0 | H5: =IF(OR((ROW()-1)<7,'实盘净值数据(iFinD公式)'!$A5="",'实盘净值数据(iFinD公式)'!$B5=""),"",SUMPRODUCT(实盘持仓初始配置!$B$6:$X$6,'实盘净值数据(iFinD公式)'!$B5:$X5/'实盘净值数据(iFinD公式)'!$B$7:$X$7)*(1-实盘持仓初始配置!$Z$6)^(('实盘净值数据(iFinD公式)'!$A5-'实盘净值数据(iFinD公式)'!$A$7)/365)) | J5: =IF(H5="","",H5/MAX(H$5:H5)-1) | K5: =IF(OR((ROW()-1)<8,'实盘净值数据(iFinD公式)'!$A5="",'实盘净值数据(iFinD公式)'!$B5=""),"",SUMPRODUCT(实盘持仓初始配置!$B$7:$X$7,'实盘净值数据(iFinD公式)'!$B5:$X5/'实盘净值数据(iFinD公式)'!$B$8:$X$8)*(1-实盘持仓初始配置!$Z$7)^(('实盘净值数据(iFinD公式)'!$A5-'实盘净值数据(iFinD公式)'!$A$8)/365)) | M5: =IF(K5="","",K5/MAX(K$5:K5)-1) | N5: 1 | P5: =IF(N5="","",N5/MAX(N$5:N5)-1) -> 0 | Q5: =IF(OR((ROW()-1)<8,'实盘净值数据(iFinD公式)'!$A5="",'实盘净值数据(iFinD公式)'!$B5=""),"",SUMPRODUCT(实盘持仓初始配置!$B$9:$X$9,'实盘净值数据(iFinD公式)'!$B5:$X5/'实盘净值数据(iFinD公式)'!$B$8:$X$8)*(1-实盘持仓初始配置!$Z$9)^(('实盘净值数据(iFinD公式)'!$A5-'实盘净值数据(iFinD公式)'!$A$8)/365)) | S5: =IF(Q5="","",Q5/MAX(Q$5:Q5)-1)
A6: =IF('实盘净值数据(iFinD公式)'!A6="","",'实盘净值数据(iFinD公式)'!A6) -> 46195 | B6: 1 | C6: =IF(OR(B5="",'实盘净值数据(iFinD公式)'!$A6="",'实盘净值数据(iFinD公式)'!$B6=""),"",(SUMPRODUCT(实盘持仓初始配置!$B$4:$X$4,'实盘净值数据(iFinD公式)'!$B5:$X5/'实盘净值数据(iFinD公式)'!$B$6:$X$6,'实盘净值数据(iFinD公式)'!$B6:$X6/'实盘净值数据(iFinD公式)'!$B5:$X5)/SUMPRODUCT(实盘持仓初始配置!$B$4:$X$4,'实盘净值数据(iFinD公式)'!$B5:$X5/'实盘净值数据(iFinD公式)'!$B$6:$X$6))*(1-实盘持仓初始配置!$Z$4)^(('实盘净值数据(iFinD公式)'!$A6-'实盘净值数据(iFinD公式)'!$A5)/365)-1) | D6: =IF(B6="","",B6/MAX(B$5:B6)-1) -> 0 | E6: =IF(OR((ROW()-1)<5,'实盘净值数据(iFinD公式)'!$A6="",'实盘净值数据(iFinD公式)'!$B6=""),"",SUMPRODUCT(实盘持仓初始配置!$B$5:$X$5,'实盘净值数据(iFinD公式)'!$B6:$X6/'实盘净值数据(iFinD公式)'!$B$5:$X$5)*(1-实盘持仓初始配置!$Z$5)^(('实盘净值数据(iFinD公式)'!$A6-'实盘净值数据(iFinD公式)'!$A$5)/365)) -> 1.0234375 | F6: =IF(OR(E5="",'实盘净值数据(iFinD公式)'!$A6="",'实盘净值数据(iFinD公式)'!$B6=""),"",(SUMPRODUCT(实盘持仓初始配置!$B$5:$X$5,'实盘净值数据(iFinD公式)'!$B5:$X5/'实盘净值数据(iFinD公式)'!$B$5:$X$5,'实盘净值数据(iFinD公式)'!$B6:$X6/'实盘净值数据(iFinD公式)'!$B5:$X5)/SUMPRODUCT(实盘持仓初始配置!$B$5:$X$5,'实盘净值数据(iFinD公式)'!$B5:$X5/'实盘净值数据(iFinD公式)'!$B$5:$X$5))*(1-实盘持仓初始配置!$Z$5)^(('实盘净值数据(iFinD公式)'!$A6-'实盘净值数据(iFinD公式)'!$A5)/365)-1) -> 0.023437473 | G6: =IF(E6="","",E6/MAX(E$5:E6)-1) -> 0 | H6: =IF(OR((ROW()-1)<7,'实盘净值数据(iFinD公式)'!$A6="",'实盘净值数据(iFinD公式)'!$B6=""),"",SUMPRODUCT(实盘持仓初始配置!$B$6:$X$6,'实盘净值数据(iFinD公式)'!$B6:$X6/'实盘净值数据(iFinD公式)'!$B$7:$X$7)*(1-实盘持仓初始配置!$Z$6)^(('实盘净值数据(iFinD公式)'!$A6-'实盘净值数据(iFinD公式)'!$A$7)/365)) | I6: =IF(OR(H5="",'实盘净值数据(iFinD公式)'!$A6="",'实盘净值数据(iFinD公式)'!$B6=""),"",(SUMPRODUCT(实盘持仓初始配置!$B$6:$X$6,'实盘净值数据(iFinD公式)'!$B5:$X5/'实盘净值数据(iFinD公式)'!$B$7:$X$7,'实盘净值数据(iFinD公式)'!$B6:$X6/'实盘净值数据(iFinD公式)'!$B5:$X5)/SUMPRODUCT(实盘持仓初始配置!$B$6:$X$6,'实盘净值数据(iFinD公式)'!$B5:$X5/'实盘净值数据(iFinD公式)'!$B$7:$X$7))*(1-实盘持仓初始配置!$Z$6)^(('实盘净值数据(iFinD公式)'!$A6-'实盘净值数据(iFinD公式)'!$A5)/365)-1) | J6: =IF(H6="","",H6/MAX(H$5:H6)-1) | K6: =IF(OR((ROW()-1)<8,'实盘净值数据(iFinD公式)'!$A6="",'实盘净值数据(iFinD公式)'!$B6=""),"",SUMPRODUCT(实盘持仓初始配置!$B$7:$X$7,'实盘净值数据(iFinD公式)'!$B6:$X6/'实盘净值数据(iFinD公式)'!$B$8:$X$8)*(1-实盘持仓初始配置!$Z$7)^(('实盘净值数据(iFinD公式)'!$A6-'实盘净值数据(iFinD公式)'!$A$8)/365)) | L6: =IF(OR(K5="",'实盘净值数据(iFinD公式)'!$A6="",'实盘净值数据(iFinD公式)'!$B6=""),"",(SUMPRODUCT(实盘持仓初始配置!$B$7:$X$7,'实盘净值数据(iFinD公式)'!$B5:$X5/'实盘净值数据(iFinD公式)'!$B$8:$X$8,'实盘净值数据(iFinD公式)'!$B6:$X6/'实盘净值数据(iFinD公式)'!$B5:$X5)/SUMPRODUCT(实盘持仓初始配置!$B$7:$X$7,'实盘净值数据(iFinD公式)'!$B5:$X5/'实盘净值数据(iFinD公式)'!$B$8:$X$8))*(1-实盘持仓初始配置!$Z$7)^(('实盘净值数据(iFinD公式)'!$A6-'实盘净值数据(iFinD公式)'!$A5)/365)-1) | M6: =IF(K6="","",K6/MAX(K$5:K6)-1) | N6: =IF(OR((ROW()-1)<5,'实盘净值数据(iFinD公式)'!$A6="",'实盘净值数据(iFinD公式)'!$B6=""),"",SUMPRODUCT(实盘持仓初始配置!$B$8:$X$8,'实盘净值数据(iFinD公式)'!$B6:$X6/'实盘净值数据(iFinD公式)'!$B$5:$X$5)*(1-实盘持仓初始配置!$Z$8)^(('实盘净值数据(iFinD公式)'!$A6-'实盘净值数据(iFinD公式)'!$A$5)/365)) -> 1.0008955 | O6: =IF(OR(N5="",'实盘净值数据(iFinD公式)'!$A6="",'实盘净值数据(iFinD公式)'!$B6=""),"",(SUMPRODUCT(实盘持仓初始配置!$B$8:$X$8,'实盘净值数据(iFinD公式)'!$B5:$X5/'实盘净值数据(iFinD公式)'!$B$5:$X$5,'实盘净值数据(iFinD公式)'!$B6:$X6/'实盘净值数据(iFinD公式)'!$B5:$X5)/SUMPRODUCT(实盘持仓初始配置!$B$8:$X$8,'实盘净值数据(iFinD公式)'!$B5:$X5/'实盘净值数据(iFinD公式)'!$B$5:$X$5))*(1-实盘持仓初始配置!$Z$8)^(('实盘净值数据(iFinD公式)'!$A6-'实盘净值数据(iFinD公式)'!$A5)/365)-1) -> 0.00089553164 | P6: =IF(N6="","",N6/MAX(N$5:N6)-1) -> 0 | Q6: =IF(OR((ROW()-1)<8,'实盘净值数据(iFinD公式)'!$A6="",'实盘净值数据(iFinD公式)'!$B6=""),"",SUMPRODUCT(实盘持仓初始配置!$B$9:$X$9,'实盘净值数据(iFinD公式)'!$B6:$X6/'实盘净值数据(iFinD公式)'!$B$8:$X$8)*(1-实盘持仓初始配置!$Z$9)^(('实盘净值数据(iFinD公式)'!$A6-'实盘净值数据(iFinD公式)'!$A$8)/365)) | R6: =IF(OR(Q5="",'实盘净值数据(iFinD公式)'!$A6="",'实盘净值数据(iFinD公式)'!$B6=""),"",(SUMPRODUCT(实盘持仓初始配置!$B$9:$X$9,'实盘净值数据(iFinD公式)'!$B5:$X5/'实盘净值数据(iFinD公式)'!$B$8:$X$8,'实盘净值数据(iFinD公式)'!$B6:$X6/'实盘净值数据(iFinD公式)'!$B5:$X5)/SUMPRODUCT(实盘持仓初始配置!$B$9:$X$9,'实盘净值数据(iFinD公式)'!$B5:$X5/'实盘净值数据(iFinD公式)'!$B$8:$X$8))*(1-实盘持仓初始配置!$Z$9)^(('实盘净值数据(iFinD公式)'!$A6-'实盘净值数据(iFinD公式)'!$A5)/365)-1) | S6: =IF(Q6="","",Q6/MAX(Q$5:Q6)-1)
A7: =IF('实盘净值数据(iFinD公式)'!A7="","",'实盘净值数据(iFinD公式)'!A7) -> 46196 | B7: =IF(OR((ROW()-1)<6,'实盘净值数据(iFinD公式)'!$A7="",'实盘净值数据(iFinD公式)'!$B7=""),"",SUMPRODUCT(实盘持仓初始配置!$B$4:$X$4,'实盘净值数据(iFinD公式)'!$B7:$X7/'实盘净值数据(iFinD公式)'!$B$6:$X$6)*(1-实盘持仓初始配置!$Z$4)^(('实盘净值数据(iFinD公式)'!$A7-'实盘净值数据(iFinD公式)'!$A$6)/365)) -> 0.98042319 | C7: =IF(OR(B6="",'实盘净值数据(iFinD公式)'!$A7="",'实盘净值数据(iFinD公式)'!$B7=""),"",(SUMPRODUCT(实盘持仓初始配置!$B$4:$X$4,'实盘净值数据(iFinD公式)'!$B6:$X6/'实盘净值数据(iFinD公式)'!$B$6:$X$6,'实盘净值数据(iFinD公式)'!$B7:$X7/'实盘净值数据(iFinD公式)'!$B6:$X6)/SUMPRODUCT(实盘持仓初始配置!$B$4:$X$4,'实盘净值数据(iFinD公式)'!$B6:$X6/'实盘净值数据(iFinD公式)'!$B$6:$X$6))*(1-实盘持仓初始配置!$Z$4)^(('实盘净值数据(iFinD公式)'!$A7-'实盘净值数据(iFinD公式)'!$A6)/365)-1) -> -0.019576812 | D7: =IF(B7="","",B7/MAX(B$5:B7)-1) -> -0.019576812 | E7: =IF(OR((ROW()-1)<5,'实盘净值数据(iFinD公式)'!$A7="",'实盘净值数据(iFinD公式)'!$B7=""),"",SUMPRODUCT(实盘持仓初始配置!$B$5:$X$5,'实盘净值数据(iFinD公式)'!$B7:$X7/'实盘净值数据(iFinD公式)'!$B$5:$X$5)*(1-实盘持仓初始配置!$Z$5)^(('实盘净值数据(iFinD公式)'!$A7-'实盘净值数据(iFinD公式)'!$A$5)/365)) -> 1.0033379 | F7: =IF(OR(E6="",'实盘净值数据(iFinD公式)'!$A7="",'实盘净值数据(iFinD公式)'!$B7=""),"",(SUMPRODUCT(实盘持仓初始配置!$B$5:$X$5,'实盘净值数据(iFinD公式)'!$B6:$X6/'实盘净值数据(iFinD公式)'!$B$5:$X$5,'实盘净值数据(iFinD公式)'!$B7:$X7/'实盘净值数据(iFinD公式)'!$B6:$X6)/SUMPRODUCT(实盘持仓初始配置!$B$5:$X$5,'实盘净值数据(iFinD公式)'!$B6:$X6/'实盘净值数据(iFinD公式)'!$B$5:$X$5))*(1-实盘持仓初始配置!$Z$5)^(('实盘净值数据(iFinD公式)'!$A7-'实盘净值数据(iFinD公式)'!$A6)/365)-1) -> -0.019639287 | G7: =IF(E7="","",E7/MAX(E$5:E7)-1) -> -0.019639287 | H7: 1 | I7: =IF(OR(H6="",'实盘净值数据(iFinD公式)'!$A7="",'实盘净值数据(iFinD公式)'!$B7=""),"",(SUMPRODUCT(实盘持仓初始配置!$B$6:$X$6,'实盘净值数据(iFinD公式)'!$B6:$X6/'实盘净值数据(iFinD公式)'!$B$7:$X$7,'实盘净值数据(iFinD公式)'!$B7:$X7/'实盘净值数据(iFinD公式)'!$B6:$X6)/SUMPRODUCT(实盘持仓初始配置!$B$6:$X$6,'实盘净值数据(iFinD公式)'!$B6:$X6/'实盘净值数据(iFinD公式)'!$B$7:$X$7))*(1-实盘持仓初始配置!$Z$6)^(('实盘净值数据(iFinD公式)'!$A7-'实盘净值数据(iFinD公式)'!$A6)/365)-1) | J7: =IF(H7="","",H7/MAX(H$5:H7)-1) -> 0 | K7: =IF(OR((ROW()-1)<8,'实盘净值数据(iFinD公式)'!$A7="",'实盘净值数据(iFinD公式)'!$B7=""),"",SUMPRODUCT(实盘持仓初始配置!$B$7:$X$7,'实盘净值数据(iFinD公式)'!$B7:$X7/'实盘净值数据(iFinD公式)'!$B$8:$X$8)*(1-实盘持仓初始配置!$Z$7)^(('实盘净值数据(iFinD公式)'!$A7-'实盘净值数据(iFinD公式)'!$A$8)/365)) | L7: =IF(OR(K6="",'实盘净值数据(iFinD公式)'!$A7="",'实盘净值数据(iFinD公式)'!$B7=""),"",(SUMPRODUCT(实盘持仓初始配置!$B$7:$X$7,'实盘净值数据(iFinD公式)'!$B6:$X6/'实盘净值数据(iFinD公式)'!$B$8:$X$8,'实盘净值数据(iFinD公式)'!$B7:$X7/'实盘净值数据(iFinD公式)'!$B6:$X6)/SUMPRODUCT(实盘持仓初始配置!$B$7:$X$7,'实盘净值数据(iFinD公式)'!$B6:$X6/'实盘净值数据(iFinD公式)'!$B$8:$X$8))*(1-实盘持仓初始配置!$Z$7)^(('实盘净值数据(iFinD公式)'!$A7-'实盘净值数据(iFinD公式)'!$A6)/365)-1) | M7: =IF(K7="","",K7/MAX(K$5:K7)-1) | N7: =IF(OR((ROW()-1)<5,'实盘净值数据(iFinD公式)'!$A7="",'实盘净值数据(iFinD公式)'!$B7=""),"",SUMPRODUCT(实盘持仓初始配置!$B$8:$X$8,'实盘净值数据(iFinD公式)'!$B7:$X7/'实盘净值数据(iFinD公式)'!$B$5:$X$5)*(1-实盘持仓初始配置!$Z$8)^(('实盘净值数据(iFinD公式)'!$A7-'实盘净值数据(iFinD公式)'!$A$5)/365)) -> 0.99782264 | O7: =IF(OR(N6="",'实盘净值数据(iFinD公式)'!$A7="",'实盘净值数据(iFinD公式)'!$B7=""),"",(SUMPRODUCT(实盘持仓初始配置!$B$8:$X$8,'实盘净值数据(iFinD公式)'!$B6:$X6/'实盘净值数据(iFinD公式)'!$B$5:$X$5,'实盘净值数据(iFinD公式)'!$B7:$X7/'实盘净值数据(iFinD公式)'!$B6:$X6)/SUMPRODUCT(实盘持仓初始配置!$B$8:$X$8,'实盘净值数据(iFinD公式)'!$B6:$X6/'实盘净值数据(iFinD公式)'!$B$5:$X$5))*(1-实盘持仓初始配置!$Z$8)^(('实盘净值数据(iFinD公式)'!$A7-'实盘净值数据(iFinD公式)'!$A6)/365)-1) -> -0.0030701438 | P7: =IF(N7="","",N7/MAX(N$5:N7)-1) -> -0.0030701438 | Q7: =IF(OR((ROW()-1)<8,'实盘净值数据(iFinD公式)'!$A7="",'实盘净值数据(iFinD公式)'!$B7=""),"",SUMPRODUCT(实盘持仓初始配置!$B$9:$X$9,'实盘净值数据(iFinD公式)'!$B7:$X7/'实盘净值数据(iFinD公式)'!$B$8:$X$8)*(1-实盘持仓初始配置!$Z$9)^(('实盘净值数据(iFinD公式)'!$A7-'实盘净值数据(iFinD公式)'!$A$8)/365)) | R7: =IF(OR(Q6="",'实盘净值数据(iFinD公式)'!$A7="",'实盘净值数据(iFinD公式)'!$B7=""),"",(SUMPRODUCT(实盘持仓初始配置!$B$9:$X$9,'实盘净值数据(iFinD公式)'!$B6:$X6/'实盘净值数据(iFinD公式)'!$B$8:$X$8,'实盘净值数据(iFinD公式)'!$B7:$X7/'实盘净值数据(iFinD公式)'!$B6:$X6)/SUMPRODUCT(实盘持仓初始配置!$B$9:$X$9,'实盘净值数据(iFinD公式)'!$B6:$X6/'实盘净值数据(iFinD公式)'!$B$8:$X$8))*(1-实盘持仓初始配置!$Z$9)^(('实盘净值数据(iFinD公式)'!$A7-'实盘净值数据(iFinD公式)'!$A6)/365)-1) | S7: =IF(Q7="","",Q7/MAX(Q$5:Q7)-1)
A8: =IF('实盘净值数据(iFinD公式)'!A8="","",'实盘净值数据(iFinD公式)'!A8) -> 46197 | B8: =IF(OR((ROW()-1)<6,'实盘净值数据(iFinD公式)'!$A8="",'实盘净值数据(iFinD公式)'!$B8=""),"",SUMPRODUCT(实盘持仓初始配置!$B$4:$X$4,'实盘净值数据(iFinD公式)'!$B8:$X8/'实盘净值数据(iFinD公式)'!$B$6:$X$6)*(1-实盘持仓初始配置!$Z$4)^(('实盘净值数据(iFinD公式)'!$A8-'实盘净值数据(iFinD公式)'!$A$6)/365)) -> 1.0160197 | C8: =IF(OR(B7="",'实盘净值数据(iFinD公式)'!$A8="",'实盘净值数据(iFinD公式)'!$B8=""),"",(SUMPRODUCT(实盘持仓初始配置!$B$4:$X$4,'实盘净值数据(iFinD公式)'!$B7:$X7/'实盘净值数据(iFinD公式)'!$B$6:$X$6,'实盘净值数据(iFinD公式)'!$B8:$X8/'实盘净值数据(iFinD公式)'!$B7:$X7)/SUMPRODUCT(实盘持仓初始配置!$B$4:$X$4,'实盘净值数据(iFinD公式)'!$B7:$X7/'实盘净值数据(iFinD公式)'!$B$6:$X$6))*(1-实盘持仓初始配置!$Z$4)^(('实盘净值数据(iFinD公式)'!$A8-'实盘净值数据(iFinD公式)'!$A7)/365)-1) -> 0.036307314 | D8: =IF(B8="","",B8/MAX(B$5:B8)-1) -> 0 | E8: =IF(OR((ROW()-1)<5,'实盘净值数据(iFinD公式)'!$A8="",'实盘净值数据(iFinD公式)'!$B8=""),"",SUMPRODUCT(实盘持仓初始配置!$B$5:$X$5,'实盘净值数据(iFinD公式)'!$B8:$X8/'实盘净值数据(iFinD公式)'!$B$5:$X$5)*(1-实盘持仓初始配置!$Z$5)^(('实盘净值数据(iFinD公式)'!$A8-'实盘净值数据(iFinD公式)'!$A$5)/365)) -> 1.0397127 | F8: =IF(OR(E7="",'实盘净值数据(iFinD公式)'!$A8="",'实盘净值数据(iFinD公式)'!$B8=""),"",(SUMPRODUCT(实盘持仓初始配置!$B$5:$X$5,'实盘净值数据(iFinD公式)'!$B7:$X7/'实盘净值数据(iFinD公式)'!$B$5:$X$5,'实盘净值数据(iFinD公式)'!$B8:$X8/'实盘净值数据(iFinD公式)'!$B7:$X7)/SUMPRODUCT(实盘持仓初始配置!$B$5:$X$5,'实盘净值数据(iFinD公式)'!$B7:$X7/'实盘净值数据(iFinD公式)'!$B$5:$X$5))*(1-实盘持仓初始配置!$Z$5)^(('实盘净值数据(iFinD公式)'!$A8-'实盘净值数据(iFinD公式)'!$A7)/365)-1) -> 0.036253775 | G8: =IF(E8="","",E8/MAX(E$5:E8)-1) -> 0 | H8: =IF(OR((ROW()-1)<7,'实盘净值数据(iFinD公式)'!$A8="",'实盘净值数据(iFinD公式)'!$B8=""),"",SUMPRODUCT(实盘持仓初始配置!$B$6:$X$6,'实盘净值数据(iFinD公式)'!$B8:$X8/'实盘净值数据(iFinD公式)'!$B$7:$X$7)*(1-实盘持仓初始配置!$Z$6)^(('实盘净值数据(iFinD公式)'!$A8-'实盘净值数据(iFinD公式)'!$A$7)/365)) -> 1.039203 | I8: =IF(OR(H7="",'实盘净值数据(iFinD公式)'!$A8="",'实盘净值数据(iFinD公式)'!$B8=""),"",(SUMPRODUCT(实盘持仓初始配置!$B$6:$X$6,'实盘净值数据(iFinD公式)'!$B7:$X7/'实盘净值数据(iFinD公式)'!$B$7:$X$7,'实盘净值数据(iFinD公式)'!$B8:$X8/'实盘净值数据(iFinD公式)'!$B7:$X7)/SUMPRODUCT(实盘持仓初始配置!$B$6:$X$6,'实盘净值数据(iFinD公式)'!$B7:$X7/'实盘净值数据(iFinD公式)'!$B$7:$X$7))*(1-实盘持仓初始配置!$Z$6)^(('实盘净值数据(iFinD公式)'!$A8-'实盘净值数据(iFinD公式)'!$A7)/365)-1) -> 0.039202963 | J8: =IF(H8="","",H8/MAX(H$5:H8)-1) -> 0 | K8: 1 | L8: =IF(OR(K7="",'实盘净值数据(iFinD公式)'!$A8="",'实盘净值数据(iFinD公式)'!$B8=""),"",(SUMPRODUCT(实盘持仓初始配置!$B$7:$X$7,'实盘净值数据(iFinD公式)'!$B7:$X7/'实盘净值数据(iFinD公式)'!$B$8:$X$8,'实盘净值数据(iFinD公式)'!$B8:$X8/'实盘净值数据(iFinD公式)'!$B7:$X7)/SUMPRODUCT(实盘持仓初始配置!$B$7:$X$7,'实盘净值数据(iFinD公式)'!$B7:$X7/'实盘净值数据(iFinD公式)'!$B$8:$X$8))*(1-实盘持仓初始配置!$Z$7)^(('实盘净值数据(iFinD公式)'!$A8-'实盘净值数据(iFinD公式)'!$A7)/365)-1) | M8: =IF(K8="","",K8/MAX(K$5:K8)-1) -> 0 | N8: =IF(OR((ROW()-1)<5,'实盘净值数据(iFinD公式)'!$A8="",'实盘净值数据(iFinD公式)'!$B8=""),"",SUMPRODUCT(实盘持仓初始配置!$B$8:$X$8,'实盘净值数据(iFinD公式)'!$B8:$X8/'实盘净值数据(iFinD公式)'!$B$5:$X$5)*(1-实盘持仓初始配置!$Z$8)^(('实盘净值数据(iFinD公式)'!$A8-'实盘净值数据(iFinD公式)'!$A$5)/365)) -> 0.99977057 | O8: =IF(OR(N7="",'实盘净值数据(iFinD公式)'!$A8="",'实盘净值数据(iFinD公式)'!$B8=""),"",(SUMPRODUCT(实盘持仓初始配置!$B$8:$X$8,'实盘净值数据(iFinD公式)'!$B7:$X7/'实盘净值数据(iFinD公式)'!$B$5:$X$5,'实盘净值数据(iFinD公式)'!$B8:$X8/'实盘净值数据(iFinD公式)'!$B7:$X7)/SUMPRODUCT(实盘持仓初始配置!$B$8:$X$8,'实盘净值数据(iFinD公式)'!$B7:$X7/'实盘净值数据(iFinD公式)'!$B$5:$X$5))*(1-实盘持仓初始配置!$Z$8)^(('实盘净值数据(iFinD公式)'!$A8-'实盘净值数据(iFinD公式)'!$A7)/365)-1) -> 0.001952181 | P8: =IF(N8="","",N8/MAX(N$5:N8)-1) -> -0.0011239563 | Q8: 1 | R8: =IF(OR(Q7="",'实盘净值数据(iFinD公式)'!$A8="",'实盘净值数据(iFinD公式)'!$B8=""),"",(SUMPRODUCT(实盘持仓初始配置!$B$9:$X$9,'实盘净值数据(iFinD公式)'!$B7:$X7/'实盘净值数据(iFinD公式)'!$B$8:$X$8,'实盘净值数据(iFinD公式)'!$B8:$X8/'实盘净值数据(iFinD公式)'!$B7:$X7)/SUMPRODUCT(实盘持仓初始配置!$B$9:$X$9,'实盘净值数据(iFinD公式)'!$B7:$X7/'实盘净值数据(iFinD公式)'!$B$8:$X$8))*(1-实盘持仓初始配置!$Z$9)^(('实盘净值数据(iFinD公式)'!$A8-'实盘净值数据(iFinD公式)'!$A7)/365)-1) | S8: =IF(Q8="","",Q8/MAX(Q$5:Q8)-1) -> 0
