Workbook
Name chtB: OFFSET('组合净值（模拟）'!$B$6,0,0,COUNT('组合净值（模拟）'!$B$6:$B$2000),1)
Name chtDate: OFFSET('组合净值（模拟）'!$A$6,0,0,COUNT('组合净值（模拟）'!$B$6:$B$2000),1)
Name chtE: OFFSET('组合净值（模拟）'!$E$6,0,0,COUNT('组合净值（模拟）'!$E$6:$E$2000),1)
Name chtH: OFFSET('组合净值（模拟）'!$H$6,0,0,COUNT('组合净值（模拟）'!$H$6:$H$2000),1)
Name chtK: OFFSET('组合净值（模拟）'!$K$6,0,0,COUNT('组合净值（模拟）'!$K$6:$K$2000),1)

Sheet 持仓配置
A1: 持仓配置（初始权重）
A2: 基金简称 | B2: 宏利复兴混合A | C2: 信澳业绩驱动A | D2: 嘉实信息产业A | E2: 银华集成电路混合A | F2: 中欧中证500指增A | G2: 天弘中证1000指增A | H2: 华泰柏瑞中证2000指增A | I2: 博道沪深300指增A | J2: 易方达中债新综指LOFA | K2: 华安黄金ETF联接A | L2: 国泰半导体材料设备ETF联接A | M2: 国泰通信设备ETF联接A | N2: 嘉实快线货币A | O2: 合计 | P2: 年化费率(年)
A3: 基金代码 | B3: 001170.OF | C3: 016370.OF | D3: 017488.OF | E3: 013840.OF | F3: 015453.OF | G3: 014201.OF | H3: 019923.OF | I3: 007044.OF | J3: 161119.OF | K3: 000216.OF | L3: 019632.OF | M3: 007817.OF | N3: 000917.OF
A4: 10-90 权重 | B4: 0.01 | C4: 0.01 | D4: 0.01 | E4: 0.01 | F4: 0.0125 | G4: 0.0125 | H4: 0.0125 | I4: 0.0125 | J4: 0.83 | K4: 0.05 | L4: 0.005 | M4: 0.005 | N4: 0.02 | O4: =SUM(B4:N4) -> 1 | P4: 0.005
A5: 20-80 权重 | B5: 0.02 | C5: 0.02 | D5: 0.02 | E5: 0.02 | F5: 0.025 | G5: 0.025 | H5: 0.025 | I5: 0.025 | J5: 0.73 | K5: 0.05 | L5: 0.01 | M5: 0.01 | N5: 0.02 | O5: =SUM(B5:N5) -> 1 | P5: 0.01
A6: 30-70 权重 | B6: 0.03 | C6: 0.03 | D6: 0.03 | E6: 0.03 | F6: 0.0375 | G6: 0.0375 | H6: 0.0375 | I6: 0.0375 | J6: 0.58 | K6: 0.1 | L6: 0.015 | M6: 0.015 | N6: 0.02 | O6: =SUM(B6:N6) -> 1 | P6: 0.012
A7: 增值 权重 | B7: 0.19 | C7: 0.19 | D7: 0.19 | E7: 0.19 | F7: 0 | G7: 0 | H7: 0 | I7: 0 | J7: 0 | K7: 0 | L7: 0.11 | M7: 0.11 | N7: 0.02 | O7: =SUM(B7:N7) -> 1 | P7: 0.012
A8: 基准指数(参考，不计入组合)
A9: 科创创业50等权 | B9: 932381.CSI
A10: 中证800 | B10: 000906.SH
A11: 沪深300 | B11: 000300.SH
A12: 中证500 | B12: 000905.SH
A13: 中证1000 | B13: 000852.SH
A14: 中证2000 | B14: 932000.CSI
A16: 权重为蓝色输入；P列为各组合年化费率(蓝色输入，已折每日扣减)。下游净值与看板自动重算。

Sheet 净值数据(iFinD公式)
A1: 净值数据 · iFinD 实时拉取（复权单位净值）
A2: =TODAY()-1 -> 46210
A3: 基金代码→ | B3: =持仓配置!B3 -> 001170.OF | C3: =持仓配置!C3 -> 016370.OF | D3: =持仓配置!D3 -> 017488.OF | E3: =持仓配置!E3 -> 013840.OF | F3: =持仓配置!F3 -> 015453.OF | G3: =持仓配置!G3 -> 014201.OF | H3: =持仓配置!H3 -> 019923.OF | I3: =持仓配置!I3 -> 007044.OF | ... N3: =持仓配置!N3 -> 000917.OF
A4: =[1]!HX_AutoDate(1,"2026-05-29",A2,-1,-1,0,0,0,0,0,"SSE",27,0) -> 日期 | B4: 宏利复兴混合A | C4: 信澳业绩驱动A | D4: 嘉实信息产业A | E4: 银华集成电路混合A | F4: 中欧中证500指增A | G4: 天弘中证1000指增A | H4: 华泰柏瑞中证2000指增A | I4: 博道沪深300指增A | J4: 易方达中债新综指LOFA | K4: 华安黄金ETF联接A | L4: 国泰半导体材料设备ETF联接A | M4: 国泰通信设备ETF联接A | N4: 嘉实快线货币A
A5: 46171 | B5: =IF($A5="","",[1]!thsiFinD("ths_adjustment_nv_fund",B$3,$A5)) -> 4.925 | C5: =IF($A5="","",[1]!thsiFinD("ths_adjustment_nv_fund",C$3,$A5)) -> 3.1015 | D5: =IF($A5="","",[1]!thsiFinD("ths_adjustment_nv_fund",D$3,$A5)) -> 3.892 | E5: =IF($A5="","",[1]!thsiFinD("ths_adjustment_nv_fund",E$3,$A5)) -> 2.6235 | F5: =IF($A5="","",[1]!thsiFinD("ths_adjustment_nv_fund",F$3,$A5)) -> 1.5841 | G5: =IF($A5="","",[1]!thsiFinD("ths_adjustment_nv_fund",G$3,$A5)) -> 1.6332 | H5: =IF($A5="","",[1]!thsiFinD("ths_adjustment_nv_fund",H$3,$A5)) -> 2.066 | I5: =IF($A5="","",[1]!thsiFinD("ths_adjustment_nv_fund",I$3,$A5)) -> 1.9417 | ... N5: =IF($A5="","",[1]!thsiFinD("ths_adjustment_nv_fund",N$3,$A5)) -> 1.3163422
A6: 46174 | B6: =IF($A6="","",[1]!thsiFinD("ths_adjustment_nv_fund",B$3,$A6)) -> 4.698 | C6: =IF($A6="","",[1]!thsiFinD("ths_adjustment_nv_fund",C$3,$A6)) -> 2.9096 | D6: =IF($A6="","",[1]!thsiFinD("ths_adjustment_nv_fund",D$3,$A6)) -> 3.687 | E6: =IF($A6="","",[1]!thsiFinD("ths_adjustment_nv_fund",E$3,$A6)) -> 2.4715 | F6: =IF($A6="","",[1]!thsiFinD("ths_adjustment_nv_fund",F$3,$A6)) -> 1.578 | G6: =IF($A6="","",[1]!thsiFinD("ths_adjustment_nv_fund",G$3,$A6)) -> 1.6247 | H6: =IF($A6="","",[1]!thsiFinD("ths_adjustment_nv_fund",H$3,$A6)) -> 2.0661 | I6: =IF($A6="","",[1]!thsiFinD("ths_adjustment_nv_fund",I$3,$A6)) -> 1.9205 | ... N6: =IF($A6="","",[1]!thsiFinD("ths_adjustment_nv_fund",N$3,$A6)) -> 1.3164814
A7: 46175 | B7: =IF($A7="","",[1]!thsiFinD("ths_adjustment_nv_fund",B$3,$A7)) -> 4.97 | C7: =IF($A7="","",[1]!thsiFinD("ths_adjustment_nv_fund",C$3,$A7)) -> 3.1175 | D7: =IF($A7="","",[1]!thsiFinD("ths_adjustment_nv_fund",D$3,$A7)) -> 3.9251 | E7: =IF($A7="","",[1]!thsiFinD("ths_adjustment_nv_fund",E$3,$A7)) -> 2.5108 | F7: =IF($A7="","",[1]!thsiFinD("ths_adjustment_nv_fund",F$3,$A7)) -> 1.5838 | G7: =IF($A7="","",[1]!thsiFinD("ths_adjustment_nv_fund",G$3,$A7)) -> 1.6241 | H7: =IF($A7="","",[1]!thsiFinD("ths_adjustment_nv_fund",H$3,$A7)) -> 2.0552 | I7: =IF($A7="","",[1]!thsiFinD("ths_adjustment_nv_fund",I$3,$A7)) -> 1.9491 | ... N7: =IF($A7="","",[1]!thsiFinD("ths_adjustment_nv_fund",N$3,$A7)) -> 1.316531
A8: 46176 | B8: =IF($A8="","",[1]!thsiFinD("ths_adjustment_nv_fund",B$3,$A8)) -> 5.215 | C8: =IF($A8="","",[1]!thsiFinD("ths_adjustment_nv_fund",C$3,$A8)) -> 3.3028 | D8: =IF($A8="","",[1]!thsiFinD("ths_adjustment_nv_fund",D$3,$A8)) -> 4.1267 | E8: =IF($A8="","",[1]!thsiFinD("ths_adjustment_nv_fund",E$3,$A8)) -> 2.5747 | F8: =IF($A8="","",[1]!thsiFinD("ths_adjustment_nv_fund",F$3,$A8)) -> 1.5894 | G8: =IF($A8="","",[1]!thsiFinD("ths_adjustment_nv_fund",G$3,$A8)) -> 1.6348 | H8: =IF($A8="","",[1]!thsiFinD("ths_adjustment_nv_fund",H$3,$A8)) -> 2.0617 | I8: =IF($A8="","",[1]!thsiFinD("ths_adjustment_nv_fund",I$3,$A8)) -> 1.9628 | ... N8: =IF($A8="","",[1]!thsiFinD("ths_adjustment_nv_fund",N$3,$A8)) -> 1.3165753
A9: 46177 | B9: =IF($A9="","",[1]!thsiFinD("ths_adjustment_nv_fund",B$3,$A9)) -> 5.262 | C9: =IF($A9="","",[1]!thsiFinD("ths_adjustment_nv_fund",C$3,$A9)) -> 3.2991 | D9: =IF($A9="","",[1]!thsiFinD("ths_adjustment_nv_fund",D$3,$A9)) -> 4.113 | E9: =IF($A9="","",[1]!thsiFinD("ths_adjustment_nv_fund",E$3,$A9)) -> 2.6434 | F9: =IF($A9="","",[1]!thsiFinD("ths_adjustment_nv_fund",F$3,$A9)) -> 1.5815 | G9: =IF($A9="","",[1]!thsiFinD("ths_adjustment_nv_fund",G$3,$A9)) -> 1.6266 | H9: =IF($A9="","",[1]!thsiFinD("ths_adjustment_nv_fund",H$3,$A9)) -> 2.0603 | I9: =IF($A9="","",[1]!thsiFinD("ths_adjustment_nv_fund",I$3,$A9)) -> 1.9539 | ... N9: =IF($A9="","",[1]!thsiFinD("ths_adjustment_nv_fund",N$3,$A9)) -> 1.3166246
A10: 46178 | B10: =IF($A10="","",[1]!thsiFinD("ths_adjustment_nv_fund",B$3,$A10)) -> 5.099 | C10: =IF($A10="","",[1]!thsiFinD("ths_adjustment_nv_fund",C$3,$A10)) -> 3.1932 | D10: =IF($A10="","",[1]!thsiFinD("ths_adjustment_nv_fund",D$3,$A10)) -> 3.9333 | E10: =IF($A10="","",[1]!thsiFinD("ths_adjustment_nv_fund",E$3,$A10)) -> 2.5176 | F10: =IF($A10="","",[1]!thsiFinD("ths_adjustment_nv_fund",F$3,$A10)) -> 1.5605 | G10: =IF($A10="","",[1]!thsiFinD("ths_adjustment_nv_fund",G$3,$A10)) -> 1.608 | H10: =IF($A10="","",[1]!thsiFinD("ths_adjustment_nv_fund",H$3,$A10)) -> 2.0581 | I10: =IF($A10="","",[1]!thsiFinD("ths_adjustment_nv_fund",I$3,$A10)) -> 1.9209 | ... N10: =IF($A10="","",[1]!thsiFinD("ths_adjustment_nv_fund",N$3,$A10)) -> 1.316669
A11: 46181 | B11: =IF($A11="","",[1]!thsiFinD("ths_adjustment_nv_fund",B$3,$A11)) -> 5.009 | C11: =IF($A11="","",[1]!thsiFinD("ths_adjustment_nv_fund",C$3,$A11)) -> 3.0775 | D11: =IF($A11="","",[1]!thsiFinD("ths_adjustment_nv_fund",D$3,$A11)) -> 3.8208 | E11: =IF($A11="","",[1]!thsiFinD("ths_adjustment_nv_fund",E$3,$A11)) -> 2.4054 | F11: =IF($A11="","",[1]!thsiFinD("ths_adjustment_nv_fund",F$3,$A11)) -> 1.506 | G11: =IF($A11="","",[1]!thsiFinD("ths_adjustment_nv_fund",G$3,$A11)) -> 1.5555 | H11: =IF($A11="","",[1]!thsiFinD("ths_adjustment_nv_fund",H$3,$A11)) -> 1.9891 | I11: =IF($A11="","",[1]!thsiFinD("ths_adjustment_nv_fund",I$3,$A11)) -> 1.8813 | ... N11: =IF($A11="","",[1]!thsiFinD("ths_adjustment_nv_fund",N$3,$A11)) -> 1.316808
A12: 46182 | B12: =IF($A12="","",[1]!thsiFinD("ths_adjustment_nv_fund",B$3,$A12)) -> 5.303 | C12: =IF($A12="","",[1]!thsiFinD("ths_adjustment_nv_fund",C$3,$A12)) -> 3.2503 | D12: =IF($A12="","",[1]!thsiFinD("ths_adjustment_nv_fund",D$3,$A12)) -> 4.0078 | E12: =IF($A12="","",[1]!thsiFinD("ths_adjustment_nv_fund",E$3,$A12)) -> 2.5471 | F12: =IF($A12="","",[1]!thsiFinD("ths_adjustment_nv_fund",F$3,$A12)) -> 1.541 | G12: =IF($A12="","",[1]!thsiFinD("ths_adjustment_nv_fund",G$3,$A12)) -> 1.6001 | H12: =IF($A12="","",[1]!thsiFinD("ths_adjustment_nv_fund",H$3,$A12)) -> 2.0379 | I12: =IF($A12="","",[1]!thsiFinD("ths_adjustment_nv_fund",I$3,$A12)) -> 1.9145 | ... N12: =IF($A12="","",[1]!thsiFinD("ths_adjustment_nv_fund",N$3,$A12)) -> 1.3168572
A13: 46183 | B13: =IF($A13="","",[1]!thsiFinD("ths_adjustment_nv_fund",B$3,$A13)) -> 5.184 | C13: =IF($A13="","",[1]!thsiFinD("ths_adjustment_nv_fund",C$3,$A13)) -> 3.1173 | D13: =IF($A13="","",[1]!thsiFinD("ths_adjustment_nv_fund",D$3,$A13)) -> 3.867 | E13: =IF($A13="","",[1]!thsiFinD("ths_adjustment_nv_fund",E$3,$A13)) -> 2.5436 | F13: =IF($A13="","",[1]!thsiFinD("ths_adjustment_nv_fund",F$3,$A13)) -> 1.5274 | G13: =IF($A13="","",[1]!thsiFinD("ths_adjustment_nv_fund",G$3,$A13)) -> 1.5778 | H13: =IF($A13="","",[1]!thsiFinD("ths_adjustment_nv_fund",H$3,$A13)) -> 2.008 | I13: =IF($A13="","",[1]!thsiFinD("ths_adjustment_nv_fund",I$3,$A13)) -> 1.8953 | ... N13: =IF($A13="","",[1]!thsiFinD("ths_adjustment_nv_fund",N$3,$A13)) -> 1.3169026
A14: 46184 | B14: =IF($A14="","",[1]!thsiFinD("ths_adjustment_nv_fund",B$3,$A14)) -> 5.168 | C14: =IF($A14="","",[1]!thsiFinD("ths_adjustment_nv_fund",C$3,$A14)) -> 3.125 | D14: =IF($A14="","",[1]!thsiFinD("ths_adjustment_nv_fund",D$3,$A14)) -> 3.8191 | E14: =IF($A14="","",[1]!thsiFinD("ths_adjustment_nv_fund",E$3,$A14)) -> 2.6281 | F14: =IF($A14="","",[1]!thsiFinD("ths_adjustment_nv_fund",F$3,$A14)) -> 1.5225 | G14: =IF($A14="","",[1]!thsiFinD("ths_adjustment_nv_fund",G$3,$A14)) -> 1.5741 | H14: =IF($A14="","",[1]!thsiFinD("ths_adjustment_nv_fund",H$3,$A14)) -> 2.0013 | I14: =IF($A14="","",[1]!thsiFinD("ths_adjustment_nv_fund",I$3,$A14)) -> 1.8852 | ... N14: =IF($A14="","",[1]!thsiFinD("ths_adjustment_nv_fund",N$3,$A14)) -> 1.3169519
A15: 46185 | B15: =IF($A15="","",[1]!thsiFinD("ths_adjustment_nv_fund",B$3,$A15)) -> 5.147 | C15: =IF($A15="","",[1]!thsiFinD("ths_adjustment_nv_fund",C$3,$A15)) -> 3.0912 | D15: =IF($A15="","",[1]!thsiFinD("ths_adjustment_nv_fund",D$3,$A15)) -> 3.7906 | E15: =IF($A15="","",[1]!thsiFinD("ths_adjustment_nv_fund",E$3,$A15)) -> 2.6555 | F15: =IF($A15="","",[1]!thsiFinD("ths_adjustment_nv_fund",F$3,$A15)) -> 1.5447 | G15: =IF($A15="","",[1]!thsiFinD("ths_adjustment_nv_fund",G$3,$A15)) -> 1.588 | H15: =IF($A15="","",[1]!thsiFinD("ths_adjustment_nv_fund",H$3,$A15)) -> 2.0092 | I15: =IF($A15="","",[1]!thsiFinD("ths_adjustment_nv_fund",I$3,$A15)) -> 1.91 | ... N15: =IF($A15="","",[1]!thsiFinD("ths_adjustment_nv_fund",N$3,$A15)) -> 1.3169953
A16: 46188 | B16: =IF($A16="","",[1]!thsiFinD("ths_adjustment_nv_fund",B$3,$A16)) -> 5.55 | C16: =IF($A16="","",[1]!thsiFinD("ths_adjustment_nv_fund",C$3,$A16)) -> 3.3568 | D16: =IF($A16="","",[1]!thsiFinD("ths_adjustment_nv_fund",D$3,$A16)) -> 4.0604 | E16: =IF($A16="","",[1]!thsiFinD("ths_adjustment_nv_fund",E$3,$A16)) -> 2.7901 | F16: =IF($A16="","",[1]!thsiFinD("ths_adjustment_nv_fund",F$3,$A16)) -> 1.5955 | G16: =IF($A16="","",[1]!thsiFinD("ths_adjustment_nv_fund",G$3,$A16)) -> 1.6477 | H16: =IF($A16="","",[1]!thsiFinD("ths_adjustment_nv_fund",H$3,$A16)) -> 2.0804 | I16: =IF($A16="","",[1]!thsiFinD("ths_adjustment_nv_fund",I$3,$A16)) -> 1.9591 | ... N16: =IF($A16="","",[1]!thsiFinD("ths_adjustment_nv_fund",N$3,$A16)) -> 1.3171341
... A31: 46210 | B31: =IF($A31="","",[1]!thsiFinD("ths_adjustment_nv_fund",B$3,$A31)) -> 5.26 | C31: =IF($A31="","",[1]!thsiFinD("ths_adjustment_nv_fund",C$3,$A31)) -> 3.0265 | D31: =IF($A31="","",[1]!thsiFinD("ths_adjustment_nv_fund",D$3,$A31)) -> 3.8613 | E31: =IF($A31="","",[1]!thsiFinD("ths_adjustment_nv_fund",E$3,$A31)) -> 3.5808 | F31: =IF($A31="","",[1]!thsiFinD("ths_adjustment_nv_fund",F$3,$A31)) -> 1.6017 | G31: =IF($A31="","",[1]!thsiFinD("ths_adjustment_nv_fund",G$3,$A31)) -> 1.6538 | H31: =IF($A31="","",[1]!thsiFinD("ths_adjustment_nv_fund",H$3,$A31)) -> 2.0247 | I31: =IF($A31="","",[1]!thsiFinD("ths_adjustment_nv_fund",I$3,$A31)) -> 1.9216 | ... N31: =IF($A31="","",[1]!thsiFinD("ths_adjustment_nv_fund",N$3,$A31)) -> 1.3181508
B32: =IF($A32="","",[1]!thsiFinD("ths_adjustment_nv_fund",B$3,$A32)) | C32: =IF($A32="","",[1]!thsiFinD("ths_adjustment_nv_fund",C$3,$A32)) | D32: =IF($A32="","",[1]!thsiFinD("ths_adjustment_nv_fund",D$3,$A32)) | E32: =IF($A32="","",[1]!thsiFinD("ths_adjustment_nv_fund",E$3,$A32)) | F32: =IF($A32="","",[1]!thsiFinD("ths_adjustment_nv_fund",F$3,$A32)) | G32: =IF($A32="","",[1]!thsiFinD("ths_adjustment_nv_fund",G$3,$A32)) | H32: =IF($A32="","",[1]!thsiFinD("ths_adjustment_nv_fund",H$3,$A32)) | I32: =IF($A32="","",[1]!thsiFinD("ths_adjustment_nv_fund",I$3,$A32)) | ... N32: =IF($A32="","",[1]!thsiFinD("ths_adjustment_nv_fund",N$3,$A32))
B33: =IF($A33="","",[1]!thsiFinD("ths_adjustment_nv_fund",B$3,$A33)) | C33: =IF($A33="","",[1]!thsiFinD("ths_adjustment_nv_fund",C$3,$A33)) | D33: =IF($A33="","",[1]!thsiFinD("ths_adjustment_nv_fund",D$3,$A33)) | E33: =IF($A33="","",[1]!thsiFinD("ths_adjustment_nv_fund",E$3,$A33)) | F33: =IF($A33="","",[1]!thsiFinD("ths_adjustment_nv_fund",F$3,$A33)) | G33: =IF($A33="","",[1]!thsiFinD("ths_adjustment_nv_fund",G$3,$A33)) | H33: =IF($A33="","",[1]!thsiFinD("ths_adjustment_nv_fund",H$3,$A33)) | I33: =IF($A33="","",[1]!thsiFinD("ths_adjustment_nv_fund",I$3,$A33)) | ... N33: =IF($A33="","",[1]!thsiFinD("ths_adjustment_nv_fund",N$3,$A33))
B34: =IF($A34="","",[1]!thsiFinD("ths_adjustment_nv_fund",B$3,$A34)) | C34: =IF($A34="","",[1]!thsiFinD("ths_adjustment_nv_fund",C$3,$A34)) | D34: =IF($A34="","",[1]!thsiFinD("ths_adjustment_nv_fund",D$3,$A34)) | E34: =IF($A34="","",[1]!thsiFinD("ths_adjustment_nv_fund",E$3,$A34)) | F34: =IF($A34="","",[1]!thsiFinD("ths_adjustment_nv_fund",F$3,$A34)) | G34: =IF($A34="","",[1]!thsiFinD("ths_adjustment_nv_fund",G$3,$A34)) | H34: =IF($A34="","",[1]!thsiFinD("ths_adjustment_nv_fund",H$3,$A34)) | I34: =IF($A34="","",[1]!thsiFinD("ths_adjustment_nv_fund",I$3,$A34)) | ... N34: =IF($A34="","",[1]!thsiFinD("ths_adjustment_nv_fund",N$3,$A34))
B35: =IF($A35="","",[1]!thsiFinD("ths_adjustment_nv_fund",B$3,$A35)) | C35: =IF($A35="","",[1]!thsiFinD("ths_adjustment_nv_fund",C$3,$A35)) | D35: =IF($A35="","",[1]!thsiFinD("ths_adjustment_nv_fund",D$3,$A35)) | E35: =IF($A35="","",[1]!thsiFinD("ths_adjustment_nv_fund",E$3,$A35)) | F35: =IF($A35="","",[1]!thsiFinD("ths_adjustment_nv_fund",F$3,$A35)) | G35: =IF($A35="","",[1]!thsiFinD("ths_adjustment_nv_fund",G$3,$A35)) | H35: =IF($A35="","",[1]!thsiFinD("ths_adjustment_nv_fund",H$3,$A35)) | I35: =IF($A35="","",[1]!thsiFinD("ths_adjustment_nv_fund",I$3,$A35)) | ... N35: =IF($A35="","",[1]!thsiFinD("ths_adjustment_nv_fund",N$3,$A35))
B36: =IF($A36="","",[1]!thsiFinD("ths_adjustment_nv_fund",B$3,$A36)) | C36: =IF($A36="","",[1]!thsiFinD("ths_adjustment_nv_fund",C$3,$A36)) | D36: =IF($A36="","",[1]!thsiFinD("ths_adjustment_nv_fund",D$3,$A36)) | E36: =IF($A36="","",[1]!thsiFinD("ths_adjustment_nv_fund",E$3,$A36)) | F36: =IF($A36="","",[1]!thsiFinD("ths_adjustment_nv_fund",F$3,$A36)) | G36: =IF($A36="","",[1]!thsiFinD("ths_adjustment_nv_fund",G$3,$A36)) | H36: =IF($A36="","",[1]!thsiFinD("ths_adjustment_nv_fund",H$3,$A36)) | I36: =IF($A36="","",[1]!thsiFinD("ths_adjustment_nv_fund",I$3,$A36)) | ... N36: =IF($A36="","",[1]!thsiFinD("ths_adjustment_nv_fund",N$3,$A36))
B37: =IF($A37="","",[1]!thsiFinD("ths_adjustment_nv_fund",B$3,$A37)) | C37: =IF($A37="","",[1]!thsiFinD("ths_adjustment_nv_fund",C$3,$A37)) | D37: =IF($A37="","",[1]!thsiFinD("ths_adjustment_nv_fund",D$3,$A37)) | E37: =IF($A37="","",[1]!thsiFinD("ths_adjustment_nv_fund",E$3,$A37)) | F37: =IF($A37="","",[1]!thsiFinD("ths_adjustment_nv_fund",F$3,$A37)) | G37: =IF($A37="","",[1]!thsiFinD("ths_adjustment_nv_fund",G$3,$A37)) | H37: =IF($A37="","",[1]!thsiFinD("ths_adjustment_nv_fund",H$3,$A37)) | I37: =IF($A37="","",[1]!thsiFinD("ths_adjustment_nv_fund",I$3,$A37)) | ... N37: =IF($A37="","",[1]!thsiFinD("ths_adjustment_nv_fund",N$3,$A37))
B38: =IF($A38="","",[1]!thsiFinD("ths_adjustment_nv_fund",B$3,$A38)) | C38: =IF($A38="","",[1]!thsiFinD("ths_adjustment_nv_fund",C$3,$A38)) | D38: =IF($A38="","",[1]!thsiFinD("ths_adjustment_nv_fund",D$3,$A38)) | E38: =IF($A38="","",[1]!thsiFinD("ths_adjustment_nv_fund",E$3,$A38)) | F38: =IF($A38="","",[1]!thsiFinD("ths_adjustment_nv_fund",F$3,$A38)) | G38: =IF($A38="","",[1]!thsiFinD("ths_adjustment_nv_fund",G$3,$A38)) | H38: =IF($A38="","",[1]!thsiFinD("ths_adjustment_nv_fund",H$3,$A38)) | I38: =IF($A38="","",[1]!thsiFinD("ths_adjustment_nv_fund",I$3,$A38)) | ... N38: =IF($A38="","",[1]!thsiFinD("ths_adjustment_nv_fund",N$3,$A38))
B39: =IF($A39="","",[1]!thsiFinD("ths_adjustment_nv_fund",B$3,$A39)) | C39: =IF($A39="","",[1]!thsiFinD("ths_adjustment_nv_fund",C$3,$A39)) | D39: =IF($A39="","",[1]!thsiFinD("ths_adjustment_nv_fund",D$3,$A39)) | E39: =IF($A39="","",[1]!thsiFinD("ths_adjustment_nv_fund",E$3,$A39)) | F39: =IF($A39="","",[1]!thsiFinD("ths_adjustment_nv_fund",F$3,$A39)) | G39: =IF($A39="","",[1]!thsiFinD("ths_adjustment_nv_fund",G$3,$A39)) | H39: =IF($A39="","",[1]!thsiFinD("ths_adjustment_nv_fund",H$3,$A39)) | I39: =IF($A39="","",[1]!thsiFinD("ths_adjustment_nv_fund",I$3,$A39)) | ... N39: =IF($A39="","",[1]!thsiFinD("ths_adjustment_nv_fund",N$3,$A39))
B40: =IF($A40="","",[1]!thsiFinD("ths_adjustment_nv_fund",B$3,$A40)) | C40: =IF($A40="","",[1]!thsiFinD("ths_adjustment_nv_fund",C$3,$A40)) | D40: =IF($A40="","",[1]!thsiFinD("ths_adjustment_nv_fund",D$3,$A40)) | E40: =IF($A40="","",[1]!thsiFinD("ths_adjustment_nv_fund",E$3,$A40)) | F40: =IF($A40="","",[1]!thsiFinD("ths_adjustment_nv_fund",F$3,$A40)) | G40: =IF($A40="","",[1]!thsiFinD("ths_adjustment_nv_fund",G$3,$A40)) | H40: =IF($A40="","",[1]!thsiFinD("ths_adjustment_nv_fund",H$3,$A40)) | I40: =IF($A40="","",[1]!thsiFinD("ths_adjustment_nv_fund",I$3,$A40)) | ... N40: =IF($A40="","",[1]!thsiFinD("ths_adjustment_nv_fund",N$3,$A40))
B41: =IF($A41="","",[1]!thsiFinD("ths_adjustment_nv_fund",B$3,$A41)) | C41: =IF($A41="","",[1]!thsiFinD("ths_adjustment_nv_fund",C$3,$A41)) | D41: =IF($A41="","",[1]!thsiFinD("ths_adjustment_nv_fund",D$3,$A41)) | E41: =IF($A41="","",[1]!thsiFinD("ths_adjustment_nv_fund",E$3,$A41)) | F41: =IF($A41="","",[1]!thsiFinD("ths_adjustment_nv_fund",F$3,$A41)) | G41: =IF($A41="","",[1]!thsiFinD("ths_adjustment_nv_fund",G$3,$A41)) | H41: =IF($A41="","",[1]!thsiFinD("ths_adjustment_nv_fund",H$3,$A41)) | I41: =IF($A41="","",[1]!thsiFinD("ths_adjustment_nv_fund",I$3,$A41)) | ... N41: =IF($A41="","",[1]!thsiFinD("ths_adjustment_nv_fund",N$3,$A41))
B42: =IF($A42="","",[1]!thsiFinD("ths_adjustment_nv_fund",B$3,$A42)) | C42: =IF($A42="","",[1]!thsiFinD("ths_adjustment_nv_fund",C$3,$A42)) | D42: =IF($A42="","",[1]!thsiFinD("ths_adjustment_nv_fund",D$3,$A42)) | E42: =IF($A42="","",[1]!thsiFinD("ths_adjustment_nv_fund",E$3,$A42)) | F42: =IF($A42="","",[1]!thsiFinD("ths_adjustment_nv_fund",F$3,$A42)) | G42: =IF($A42="","",[1]!thsiFinD("ths_adjustment_nv_fund",G$3,$A42)) | H42: =IF($A42="","",[1]!thsiFinD("ths_adjustment_nv_fund",H$3,$A42)) | I42: =IF($A42="","",[1]!thsiFinD("ths_adjustment_nv_fund",I$3,$A42)) | ... N42: =IF($A42="","",[1]!thsiFinD("ths_adjustment_nv_fund",N$3,$A42))
B43: =IF($A43="","",[1]!thsiFinD("ths_adjustment_nv_fund",B$3,$A43)) | C43: =IF($A43="","",[1]!thsiFinD("ths_adjustment_nv_fund",C$3,$A43)) | D43: =IF($A43="","",[1]!thsiFinD("ths_adjustment_nv_fund",D$3,$A43)) | E43: =IF($A43="","",[1]!thsiFinD("ths_adjustment_nv_fund",E$3,$A43)) | F43: =IF($A43="","",[1]!thsiFinD("ths_adjustment_nv_fund",F$3,$A43)) | G43: =IF($A43="","",[1]!thsiFinD("ths_adjustment_nv_fund",G$3,$A43)) | H43: =IF($A43="","",[1]!thsiFinD("ths_adjustment_nv_fund",H$3,$A43)) | I43: =IF($A43="","",[1]!thsiFinD("ths_adjustment_nv_fund",I$3,$A43)) | ... N43: =IF($A43="","",[1]!thsiFinD("ths_adjustment_nv_fund",N$3,$A43))
... B59: =IF($A59="","",[1]!thsiFinD("ths_adjustment_nv_fund",B$3,$A59)) | C59: =IF($A59="","",[1]!thsiFinD("ths_adjustment_nv_fund",C$3,$A59)) | D59: =IF($A59="","",[1]!thsiFinD("ths_adjustment_nv_fund",D$3,$A59)) | E59: =IF($A59="","",[1]!thsiFinD("ths_adjustment_nv_fund",E$3,$A59)) | F59: =IF($A59="","",[1]!thsiFinD("ths_adjustment_nv_fund",F$3,$A59)) | G59: =IF($A59="","",[1]!thsiFinD("ths_adjustment_nv_fund",G$3,$A59)) | H59: =IF($A59="","",[1]!thsiFinD("ths_adjustment_nv_fund",H$3,$A59)) | I59: =IF($A59="","",[1]!thsiFinD("ths_adjustment_nv_fund",I$3,$A59)) | ... N59: =IF($A59="","",[1]!thsiFinD("ths_adjustment_nv_fund",N$3,$A59))

Sheet 组合净值（模拟）
A1: 组合净值 · 买入持有逐日计算
B4: 组合 10-90 | E4: 组合 20-80 | H4: 组合 30-70 | K4: 组合 增值
A5: 日期 | B5: 净值 | C5: 日收益 | D5: 回撤 | E5: 净值 | F5: 日收益 | G5: 回撤 | H5: 净值 | I5: 日收益 | J5: 回撤 | K5: 净值 | L5: 日收益 | M5: 回撤
A6: =IF('净值数据(iFinD公式)'!A5="","",'净值数据(iFinD公式)'!A5) -> 46171 | B6: =IF(OR('净值数据(iFinD公式)'!$A5="",'净值数据(iFinD公式)'!$B5=""),"",SUMPRODUCT(持仓配置!$B$4:$N$4,'净值数据(iFinD公式)'!$B5:$N5/'净值数据(iFinD公式)'!$B$5:$N$5)*(1-持仓配置!$P$4)^((ROW()-6)/说明!$C$17)) -> 1 | D6: =IF(B6="","",B6/MAX(B$6:B6)-1) -> 0 | E6: =IF(OR('净值数据(iFinD公式)'!$A5="",'净值数据(iFinD公式)'!$B5=""),"",SUMPRODUCT(持仓配置!$B$5:$N$5,'净值数据(iFinD公式)'!$B5:$N5/'净值数据(iFinD公式)'!$B$5:$N$5)*(1-持仓配置!$P$5)^((ROW()-6)/说明!$C$17)) -> 1 | G6: =IF(E6="","",E6/MAX(E$6:E6)-1) -> 0 | H6: =IF(OR('净值数据(iFinD公式)'!$A5="",'净值数据(iFinD公式)'!$B5=""),"",SUMPRODUCT(持仓配置!$B$6:$N$6,'净值数据(iFinD公式)'!$B5:$N5/'净值数据(iFinD公式)'!$B$5:$N$5)*(1-持仓配置!$P$6)^((ROW()-6)/说明!$C$17)) -> 1 | J6: =IF(H6="","",H6/MAX(H$6:H6)-1) -> 0 | K6: =IF(OR('净值数据(iFinD公式)'!$A5="",'净值数据(iFinD公式)'!$B5=""),"",SUMPRODUCT(持仓配置!$B$7:$N$7,'净值数据(iFinD公式)'!$B5:$N5/'净值数据(iFinD公式)'!$B$5:$N$5)*(1-持仓配置!$P$7)^((ROW()-6)/说明!$C$17)) -> 1 | M6: =IF(K6="","",K6/MAX(K$6:K6)-1) -> 0
A7: =IF('净值数据(iFinD公式)'!A6="","",'净值数据(iFinD公式)'!A6) -> 46174 | B7: =IF(OR('净值数据(iFinD公式)'!$A6="",'净值数据(iFinD公式)'!$B6=""),"",SUMPRODUCT(持仓配置!$B$4:$N$4,'净值数据(iFinD公式)'!$B6:$N6/'净值数据(iFinD公式)'!$B$5:$N$5)*(1-持仓配置!$P$4)^((ROW()-6)/说明!$C$17)) -> 0.99765643 | C7: =IF(OR(B7="",B6=""),"",B7/B6-1) -> -0.0023435666 | D7: =IF(B7="","",B7/MAX(B$6:B7)-1) -> -0.0023435666 | E7: =IF(OR('净值数据(iFinD公式)'!$A6="",'净值数据(iFinD公式)'!$B6=""),"",SUMPRODUCT(持仓配置!$B$5:$N$5,'净值数据(iFinD公式)'!$B6:$N6/'净值数据(iFinD公式)'!$B$5:$N$5)*(1-持仓配置!$P$5)^((ROW()-6)/说明!$C$17)) -> 0.99470984 | F7: =IF(OR(E7="",E6=""),"",E7/E6-1) -> -0.0052901552 | G7: =IF(E7="","",E7/MAX(E$6:E7)-1) -> -0.0052901552 | H7: =IF(OR('净值数据(iFinD公式)'!$A6="",'净值数据(iFinD公式)'!$B6=""),"",SUMPRODUCT(持仓配置!$B$6:$N$6,'净值数据(iFinD公式)'!$B6:$N6/'净值数据(iFinD公式)'!$B$5:$N$5)*(1-持仓配置!$P$6)^((ROW()-6)/说明!$C$17)) -> 0.99155316 | I7: =IF(OR(H7="",H6=""),"",H7/H6-1) -> -0.0084468409 | J7: =IF(H7="","",H7/MAX(H$6:H7)-1) -> -0.0084468409 | K7: =IF(OR('净值数据(iFinD公式)'!$A6="",'净值数据(iFinD公式)'!$B6=""),"",SUMPRODUCT(持仓配置!$B$7:$N$7,'净值数据(iFinD公式)'!$B6:$N6/'净值数据(iFinD公式)'!$B$5:$N$5)*(1-持仓配置!$P$7)^((ROW()-6)/说明!$C$17)) -> 0.94945547 | L7: =IF(OR(K7="",K6=""),"",K7/K6-1) -> -0.050544531 | M7: =IF(K7="","",K7/MAX(K$6:K7)-1) -> -0.050544531
A8: =IF('净值数据(iFinD公式)'!A7="","",'净值数据(iFinD公式)'!A7) -> 46175 | B8: =IF(OR('净值数据(iFinD公式)'!$A7="",'净值数据(iFinD公式)'!$B7=""),"",SUMPRODUCT(持仓配置!$B$4:$N$4,'净值数据(iFinD公式)'!$B7:$N7/'净值数据(iFinD公式)'!$B$5:$N$5)*(1-持仓配置!$P$4)^((ROW()-6)/说明!$C$17)) -> 1.0004874 | C8: =IF(OR(B8="",B7=""),"",B8/B7-1) -> 0.0028376156 | D8: =IF(B8="","",B8/MAX(B$6:B8)-1) -> 0 | E8: =IF(OR('净值数据(iFinD公式)'!$A7="",'净值数据(iFinD公式)'!$B7=""),"",SUMPRODUCT(持仓配置!$B$5:$N$5,'净值数据(iFinD公式)'!$B7:$N7/'净值数据(iFinD公式)'!$B$5:$N$5)*(1-持仓配置!$P$5)^((ROW()-6)/说明!$C$17)) -> 1.0000346 | F8: =IF(OR(E8="",E7=""),"",E8/E7-1) -> 0.0053530279 | G8: =IF(E8="","",E8/MAX(E$6:E8)-1) -> 0 | H8: =IF(OR('净值数据(iFinD公式)'!$A7="",'净值数据(iFinD公式)'!$B7=""),"",SUMPRODUCT(持仓配置!$B$6:$N$6,'净值数据(iFinD公式)'!$B7:$N7/'净值数据(iFinD公式)'!$B$5:$N$5)*(1-持仓配置!$P$6)^((ROW()-6)/说明!$C$17)) -> 0.99966507 | I8: =IF(OR(H8="",H7=""),"",H8/H7-1) -> 0.008181017 | J8: =IF(H8="","",H8/MAX(H$6:H8)-1) -> -0.00033492765 | K8: =IF(OR('净值数据(iFinD公式)'!$A7="",'净值数据(iFinD公式)'!$B7=""),"",SUMPRODUCT(持仓配置!$B$7:$N$7,'净值数据(iFinD公式)'!$B7:$N7/'净值数据(iFinD公式)'!$B$5:$N$5)*(1-持仓配置!$P$7)^((ROW()-6)/说明!$C$17)) -> 0.99538006 | L8: =IF(OR(K8="",K7=""),"",K8/K7-1) -> 0.048369402 | M8: =IF(K8="","",K8/MAX(K$6:K8)-1) -> -0.0046199376
A9: =IF('净值数据(iFinD公式)'!A8="","",'净值数据(iFinD公式)'!A8) -> 46176 | B9: =IF(OR('净值数据(iFinD公式)'!$A8="",'净值数据(iFinD公式)'!$B8=""),"",SUMPRODUCT(持仓配置!$B$4:$N$4,'净值数据(iFinD公式)'!$B8:$N8/'净值数据(iFinD公式)'!$B$5:$N$5)*(1-持仓配置!$P$4)^((ROW()-6)/说明!$C$17)) -> 1.0019149 | C9: =IF(OR(B9="",B8=""),"",B9/B8-1) -> 0.001426845 | D9: =IF(B9="","",B9/MAX(B$6:B9)-1) -> 0 | E9: =IF(OR('净值数据(iFinD公式)'!$A8="",'净值数据(iFinD公式)'!$B8=""),"",SUMPRODUCT(持仓配置!$B$5:$N$5,'净值数据(iFinD公式)'!$B8:$N8/'净值数据(iFinD公式)'!$B$5:$N$5)*(1-持仓配置!$P$5)^((ROW()-6)/说明!$C$17)) -> 1.003949 | F9: =IF(OR(E9="",E8=""),"",E9/E8-1) -> 0.0039142782 | G9: =IF(E9="","",E9/MAX(E$6:E9)-1) -> 0 | H9: =IF(OR('净值数据(iFinD公式)'!$A8="",'净值数据(iFinD公式)'!$B8=""),"",SUMPRODUCT(持仓配置!$B$6:$N$6,'净值数据(iFinD公式)'!$B8:$N8/'净值数据(iFinD公式)'!$B$5:$N$5)*(1-持仓配置!$P$6)^((ROW()-6)/说明!$C$17)) -> 1.0054022 | I9: =IF(OR(H9="",H8=""),"",H9/H8-1) -> 0.0057390377 | J9: =IF(H9="","",H9/MAX(H$6:H9)-1) -> 0 | K9: =IF(OR('净值数据(iFinD公式)'!$A8="",'净值数据(iFinD公式)'!$B8=""),"",SUMPRODUCT(持仓配置!$B$7:$N$7,'净值数据(iFinD公式)'!$B8:$N8/'净值数据(iFinD公式)'!$B$5:$N$5)*(1-持仓配置!$P$7)^((ROW()-6)/说明!$C$17)) -> 1.0384783 | L9: =IF(OR(K9="",K8=""),"",K9/K8-1) -> 0.043298242 | M9: =IF(K9="","",K9/MAX(K$6:K9)-1) -> 0
A10: =IF('净值数据(iFinD公式)'!A9="","",'净值数据(iFinD公式)'!A9) -> 46177 | B10: =IF(OR('净值数据(iFinD公式)'!$A9="",'净值数据(iFinD公式)'!$B9=""),"",SUMPRODUCT(持仓配置!$B$4:$N$4,'净值数据(iFinD公式)'!$B9:$N9/'净值数据(iFinD公式)'!$B$5:$N$5)*(1-持仓配置!$P$4)^((ROW()-6)/说明!$C$17)) -> 1.0027653 | C10: =IF(OR(B10="",B9=""),"",B10/B9-1) -> 0.00084874508 | D10: =IF(B10="","",B10/MAX(B$6:B10)-1) -> 0 | E10: =IF(OR('净值数据(iFinD公式)'!$A9="",'净值数据(iFinD公式)'!$B9=""),"",SUMPRODUCT(持仓配置!$B$5:$N$5,'净值数据(iFinD公式)'!$B9:$N9/'净值数据(iFinD公式)'!$B$5:$N$5)*(1-持仓配置!$P$5)^((ROW()-6)/说明!$C$17)) -> 1.0050041 | F10: =IF(OR(E10="",E9=""),"",E10/E9-1) -> 0.0010510185 | G10: =IF(E10="","",E10/MAX(E$6:E10)-1) -> 0 | H10: =IF(OR('净值数据(iFinD公式)'!$A9="",'净值数据(iFinD公式)'!$B9=""),"",SUMPRODUCT(持仓配置!$B$6:$N$6,'净值数据(iFinD公式)'!$B9:$N9/'净值数据(iFinD公式)'!$B$5:$N$5)*(1-持仓配置!$P$6)^((ROW()-6)/说明!$C$17)) -> 1.0067152 | I10: =IF(OR(H10="",H9=""),"",H10/H9-1) -> 0.0013059995 | J10: =IF(H10="","",H10/MAX(H$6:H10)-1) -> 0 | K10: =IF(OR('净值数据(iFinD公式)'!$A9="",'净值数据(iFinD公式)'!$B9=""),"",SUMPRODUCT(持仓配置!$B$7:$N$7,'净值数据(iFinD公式)'!$B9:$N9/'净值数据(iFinD公式)'!$B$5:$N$5)*(1-持仓配置!$P$7)^((ROW()-6)/说明!$C$17)) -> 1.0480045 | L10: =IF(OR(K10="",K9=""),"",K10/K9-1) -> 0.0091732227 | M10: =IF(K10="","",K10/MAX(K$6:K10)-1) -> 0
A11: =IF('净值数据(iFinD公式)'!A10="","",'净值数据(iFinD公式)'!A10) -> 46178 | B11: =IF(OR('净值数据(iFinD公式)'!$A10="",'净值数据(iFinD公式)'!$B10=""),"",SUMPRODUCT(持仓配置!$B$4:$N$4,'净值数据(iFinD公式)'!$B10:$N10/'净值数据(iFinD公式)'!$B$5:$N$5)*(1-持仓配置!$P$4)^((ROW()-6)/说明!$C$17)) -> 0.9997837 | C11: =IF(OR(B11="",B10=""),"",B11/B10-1) -> -0.0029733862 | D11: =IF(B11="","",B11/MAX(B$6:B11)-1) -> -0.0029733862 | E11: =IF(OR('净值数据(iFinD公式)'!$A10="",'净值数据(iFinD公式)'!$B10=""),"",SUMPRODUCT(持仓配置!$B$5:$N$5,'净值数据(iFinD公式)'!$B10:$N10/'净值数据(iFinD公式)'!$B$5:$N$5)*(1-持仓配置!$P$5)^((ROW()-6)/说明!$C$17)) -> 0.99963093 | F11: =IF(OR(E11="",E10=""),"",E11/E10-1) -> -0.0053464509 | G11: =IF(E11="","",E11/MAX(E$6:E11)-1) -> -0.0053464509 | H11: =IF(OR('净值数据(iFinD公式)'!$A10="",'净值数据(iFinD公式)'!$B10=""),"",SUMPRODUCT(持仓配置!$B$6:$N$6,'净值数据(iFinD公式)'!$B10:$N10/'净值数据(iFinD公式)'!$B$5:$N$5)*(1-持仓配置!$P$6)^((ROW()-6)/说明!$C$17)) -> 0.99897575 | I11: =IF(OR(H11="",H10=""),"",H11/H10-1) -> -0.0076878646 | J11: =IF(H11="","",H11/MAX(H$6:H11)-1) -> -0.0076878646 | K11: =IF(OR('净值数据(iFinD公式)'!$A10="",'净值数据(iFinD公式)'!$B10=""),"",SUMPRODUCT(持仓配置!$B$7:$N$7,'净值数据(iFinD公式)'!$B10:$N10/'净值数据(iFinD公式)'!$B$5:$N$5)*(1-持仓配置!$P$7)^((ROW()-6)/说明!$C$17)) -> 1.0110077 | L11: =IF(OR(K11="",K10=""),"",K11/K10-1) -> -0.035302084 | M11: =IF(K11="","",K11/MAX(K$6:K11)-1) -> -0.035302084
A12: =IF('净值数据(iFinD公式)'!A11="","",'净值数据(iFinD公式)'!A11) -> 46181 | B12: =IF(OR('净值数据(iFinD公式)'!$A11="",'净值数据(iFinD公式)'!$B11=""),"",SUMPRODUCT(持仓配置!$B$4:$N$4,'净值数据(iFinD公式)'!$B11:$N11/'净值数据(iFinD公式)'!$B$5:$N$5)*(1-持仓配置!$P$4)^((ROW()-6)/说明!$C$17)) -> 0.99463804 | C12: =IF(OR(B12="",B11=""),"",B12/B11-1) -> -0.0051467771 | D12: =IF(B12="","",B12/MAX(B$6:B12)-1) -> -0.00810486 | E12: =IF(OR('净值数据(iFinD公式)'!$A11="",'净值数据(iFinD公式)'!$B11=""),"",SUMPRODUCT(持仓配置!$B$5:$N$5,'净值数据(iFinD公式)'!$B11:$N11/'净值数据(iFinD公式)'!$B$5:$N$5)*(1-持仓配置!$P$5)^((ROW()-6)/说明!$C$17)) -> 0.99141603 | F12: =IF(OR(E12="",E11=""),"",E12/E11-1) -> -0.0082179367 | G12: =IF(E12="","",E12/MAX(E$6:E12)-1) -> -0.013520451 | H12: =IF(OR('净值数据(iFinD公式)'!$A11="",'净值数据(iFinD公式)'!$B11=""),"",SUMPRODUCT(持仓配置!$B$6:$N$6,'净值数据(iFinD公式)'!$B11:$N11/'净值数据(iFinD公式)'!$B$5:$N$5)*(1-持仓配置!$P$6)^((ROW()-6)/说明!$C$17)) -> 0.9860652 | I12: =IF(OR(H12="",H11=""),"",H12/H11-1) -> -0.012923792 | J12: =IF(H12="","",H12/MAX(H$6:H12)-1) -> -0.0205123 | K12: =IF(OR('净值数据(iFinD公式)'!$A11="",'净值数据(iFinD公式)'!$B11=""),"",SUMPRODUCT(持仓配置!$B$7:$N$7,'净值数据(iFinD公式)'!$B11:$N11/'净值数据(iFinD公式)'!$B$5:$N$5)*(1-持仓配置!$P$7)^((ROW()-6)/说明!$C$17)) -> 0.97978619 | L12: =IF(OR(K12="",K11=""),"",K12/K11-1) -> -0.030881592 | M12: =IF(K12="","",K12/MAX(K$6:K12)-1) -> -0.065093491
A13: =IF('净值数据(iFinD公式)'!A12="","",'净值数据(iFinD公式)'!A12) -> 46182 | B13: =IF(OR('净值数据(iFinD公式)'!$A12="",'净值数据(iFinD公式)'!$B12=""),"",SUMPRODUCT(持仓配置!$B$4:$N$4,'净值数据(iFinD公式)'!$B12:$N12/'净值数据(iFinD公式)'!$B$5:$N$5)*(1-持仓配置!$P$4)^((ROW()-6)/说明!$C$17)) -> 0.9981093 | C13: =IF(OR(B13="",B12=""),"",B13/B12-1) -> 0.0034899767 | D13: =IF(B13="","",B13/MAX(B$6:B13)-1) -> -0.004643169 | E13: =IF(OR('净值数据(iFinD公式)'!$A12="",'净值数据(iFinD公式)'!$B12=""),"",SUMPRODUCT(持仓配置!$B$5:$N$5,'净值数据(iFinD公式)'!$B12:$N12/'净值数据(iFinD公式)'!$B$5:$N$5)*(1-持仓配置!$P$5)^((ROW()-6)/说明!$C$17)) -> 0.99885349 | F13: =IF(OR(E13="",E12=""),"",E13/E12-1) -> 0.0075018579 | G13: =IF(E13="","",E13/MAX(E$6:E13)-1) -> -0.0061200214 | H13: =IF(OR('净值数据(iFinD公式)'!$A12="",'净值数据(iFinD公式)'!$B12=""),"",SUMPRODUCT(持仓配置!$B$6:$N$6,'净值数据(iFinD公式)'!$B12:$N12/'净值数据(iFinD公式)'!$B$5:$N$5)*(1-持仓配置!$P$6)^((ROW()-6)/说明!$C$17)) -> 0.99769737 | I13: =IF(OR(H13="",H12=""),"",H13/H12-1) -> 0.011796555 | J13: =IF(H13="","",H13/MAX(H$6:H13)-1) -> -0.0089577195 | K13: =IF(OR('净值数据(iFinD公式)'!$A12="",'净值数据(iFinD公式)'!$B12=""),"",SUMPRODUCT(持仓配置!$B$7:$N$7,'净值数据(iFinD公式)'!$B12:$N12/'净值数据(iFinD公式)'!$B$5:$N$5)*(1-持仓配置!$P$7)^((ROW()-6)/说明!$C$17)) -> 1.034542 | L13: =IF(OR(K13="",K12=""),"",K13/K12-1) -> 0.055885507 | M13: =IF(K13="","",K13/MAX(K$6:K13)-1) -> -0.012845767
A14: =IF('净值数据(iFinD公式)'!A13="","",'净值数据(iFinD公式)'!A13) -> 46183 | B14: =IF(OR('净值数据(iFinD公式)'!$A13="",'净值数据(iFinD公式)'!$B13=""),"",SUMPRODUCT(持仓配置!$B$4:$N$4,'净值数据(iFinD公式)'!$B13:$N13/'净值数据(iFinD公式)'!$B$5:$N$5)*(1-持仓配置!$P$4)^((ROW()-6)/说明!$C$17)) -> 0.99416737 | C14: =IF(OR(B14="",B13=""),"",B14/B13-1) -> -0.0039494012 | D14: =IF(B14="","",B14/MAX(B$6:B14)-1) -> -0.0085742325 | E14: =IF(OR('净值数据(iFinD公式)'!$A13="",'净值数据(iFinD公式)'!$B13=""),"",SUMPRODUCT(持仓配置!$B$5:$N$5,'净值数据(iFinD公式)'!$B13:$N13/'净值数据(iFinD公式)'!$B$5:$N$5)*(1-持仓配置!$P$5)^((ROW()-6)/说明!$C$17)) -> 0.99329826 | F14: =IF(OR(E14="",E13=""),"",E14/E13-1) -> -0.0055616046 | G14: =IF(E14="","",E14/MAX(E$6:E14)-1) -> -0.011647589 | H14: =IF(OR('净值数据(iFinD公式)'!$A13="",'净值数据(iFinD公式)'!$B13=""),"",SUMPRODUCT(持仓配置!$B$6:$N$6,'净值数据(iFinD公式)'!$B13:$N13/'净值数据(iFinD公式)'!$B$5:$N$5)*(1-持仓配置!$P$6)^((ROW()-6)/说明!$C$17)) -> 0.9890904 | I14: =IF(OR(H14="",H13=""),"",H14/H13-1) -> -0.0086268357 | J14: =IF(H14="","",H14/MAX(H$6:H14)-1) -> -0.017507278 | K14: =IF(OR('净值数据(iFinD公式)'!$A13="",'净值数据(iFinD公式)'!$B13=""),"",SUMPRODUCT(持仓配置!$B$7:$N$7,'净值数据(iFinD公式)'!$B13:$N13/'净值数据(iFinD公式)'!$B$5:$N$5)*(1-持仓配置!$P$7)^((ROW()-6)/说明!$C$17)) -> 1.0134071 | L14: =IF(OR(K14="",K13=""),"",K14/K13-1) -> -0.020429257 | M14: =IF(K14="","",K14/MAX(K$6:K14)-1) -> -0.033012594
A15: =IF('净值数据(iFinD公式)'!A14="","",'净值数据(iFinD公式)'!A14) -> 46184 | B15: =IF(OR('净值数据(iFinD公式)'!$A14="",'净值数据(iFinD公式)'!$B14=""),"",SUMPRODUCT(持仓配置!$B$4:$N$4,'净值数据(iFinD公式)'!$B14:$N14/'净值数据(iFinD公式)'!$B$5:$N$5)*(1-持仓配置!$P$4)^((ROW()-6)/说明!$C$17)) -> 0.99283271 | C15: =IF(OR(B15="",B14=""),"",B15/B14-1) -> -0.001342484 | D15: =IF(B15="","",B15/MAX(B$6:B15)-1) -> -0.0099052057 | E15: =IF(OR('净值数据(iFinD公式)'!$A14="",'净值数据(iFinD公式)'!$B14=""),"",SUMPRODUCT(持仓配置!$B$5:$N$5,'净值数据(iFinD公式)'!$B14:$N14/'净值数据(iFinD公式)'!$B$5:$N$5)*(1-持仓配置!$P$5)^((ROW()-6)/说明!$C$17)) -> 0.99221024 | F15: =IF(OR(E15="",E14=""),"",E15/E14-1) -> -0.0010953616 | G15: =IF(E15="","",E15/MAX(E$6:E15)-1) -> -0.012730192 | H15: =IF(OR('净值数据(iFinD公式)'!$A14="",'净值数据(iFinD公式)'!$B14=""),"",SUMPRODUCT(持仓配置!$B$6:$N$6,'净值数据(iFinD公式)'!$B14:$N14/'净值数据(iFinD公式)'!$B$5:$N$5)*(1-持仓配置!$P$6)^((ROW()-6)/说明!$C$17)) -> 0.98728284 | I15: =IF(OR(H15="",H14=""),"",H15/H14-1) -> -0.0018274936 | J15: =IF(H15="","",H15/MAX(H$6:H15)-1) -> -0.019302778 | K15: =IF(OR('净值数据(iFinD公式)'!$A14="",'净值数据(iFinD公式)'!$B14=""),"",SUMPRODUCT(持仓配置!$B$7:$N$7,'净值数据(iFinD公式)'!$B14:$N14/'净值数据(iFinD公式)'!$B$5:$N$5)*(1-持仓配置!$P$7)^((ROW()-6)/说明!$C$17)) -> 1.0210851 | L15: =IF(OR(K15="",K14=""),"",K15/K14-1) -> 0.007576428 | M15: =IF(K15="","",K15/MAX(K$6:K15)-1) -> -0.025686284
A16: =IF('净值数据(iFinD公式)'!A15="","",'净值数据(iFinD公式)'!A15) -> 46185 | B16: =IF(OR('净值数据(iFinD公式)'!$A15="",'净值数据(iFinD公式)'!$B15=""),"",SUMPRODUCT(持仓配置!$B$4:$N$4,'净值数据(iFinD公式)'!$B15:$N15/'净值数据(iFinD公式)'!$B$5:$N$5)*(1-持仓配置!$P$4)^((ROW()-6)/说明!$C$17)) -> 0.99406258 | C16: =IF(OR(B16="",B15=""),"",B16/B15-1) -> 0.0012387484 | D16: =IF(B16="","",B16/MAX(B$6:B16)-1) -> -0.0086787273 | E16: =IF(OR('净值数据(iFinD公式)'!$A15="",'净值数据(iFinD公式)'!$B15=""),"",SUMPRODUCT(持仓配置!$B$5:$N$5,'净值数据(iFinD公式)'!$B15:$N15/'净值数据(iFinD公式)'!$B$5:$N$5)*(1-持仓配置!$P$5)^((ROW()-6)/说明!$C$17)) -> 0.9935522 | F16: =IF(OR(E16="",E15=""),"",E16/E15-1) -> 0.0013524923 | G16: =IF(E16="","",E16/MAX(E$6:E16)-1) -> -0.011394917 | H16: =IF(OR('净值数据(iFinD公式)'!$A15="",'净值数据(iFinD公式)'!$B15=""),"",SUMPRODUCT(持仓配置!$B$6:$N$6,'净值数据(iFinD公式)'!$B15:$N15/'净值数据(iFinD公式)'!$B$5:$N$5)*(1-持仓配置!$P$6)^((ROW()-6)/说明!$C$17)) -> 0.98931719 | I16: =IF(OR(H16="",H15=""),"",H16/H15-1) -> 0.0020605487 | J16: =IF(H16="","",H16/MAX(H$6:H16)-1) -> -0.017282003 | K16: =IF(OR('净值数据(iFinD公式)'!$A15="",'净值数据(iFinD公式)'!$B15=""),"",SUMPRODUCT(持仓配置!$B$7:$N$7,'净值数据(iFinD公式)'!$B15:$N15/'净值数据(iFinD公式)'!$B$5:$N$5)*(1-持仓配置!$P$7)^((ROW()-6)/说明!$C$17)) -> 1.0147864 | L16: =IF(OR(K16="",K15=""),"",K16/K15-1) -> -0.006168628 | M16: =IF(K16="","",K16/MAX(K$6:K16)-1) -> -0.031696463
A17: =IF('净值数据(iFinD公式)'!A16="","",'净值数据(iFinD公式)'!A16) -> 46188 | B17: =IF(OR('净值数据(iFinD公式)'!$A16="",'净值数据(iFinD公式)'!$B16=""),"",SUMPRODUCT(持仓配置!$B$4:$N$4,'净值数据(iFinD公式)'!$B16:$N16/'净值数据(iFinD公式)'!$B$5:$N$5)*(1-持仓配置!$P$4)^((ROW()-6)/说明!$C$17)) -> 1.0008242 | C17: =IF(OR(B17="",B16=""),"",B17/B16-1) -> 0.0068020094 | D17: =IF(B17="","",B17/MAX(B$6:B17)-1) -> -0.0019357507 | E17: =IF(OR('净值数据(iFinD公式)'!$A16="",'净值数据(iFinD公式)'!$B16=""),"",SUMPRODUCT(持仓配置!$B$5:$N$5,'净值数据(iFinD公式)'!$B16:$N16/'净值数据(iFinD公式)'!$B$5:$N$5)*(1-持仓配置!$P$5)^((ROW()-6)/说明!$C$17)) -> 1.0052614 | F17: =IF(OR(E17="",E16=""),"",E17/E16-1) -> 0.011785176 | G17: =IF(E17="","",E17/MAX(E$6:E17)-1) -> 0 | H17: =IF(OR('净值数据(iFinD公式)'!$A16="",'净值数据(iFinD公式)'!$B16=""),"",SUMPRODUCT(持仓配置!$B$6:$N$6,'净值数据(iFinD公式)'!$B16:$N16/'净值数据(iFinD公式)'!$B$5:$N$5)*(1-持仓配置!$P$6)^((ROW()-6)/说明!$C$17)) -> 1.0074658 | I17: =IF(OR(H17="",H16=""),"",H17/H16-1) -> 0.01834455 | J17: =IF(H17="","",H17/MAX(H$6:H17)-1) -> 0 | K17: =IF(OR('净值数据(iFinD公式)'!$A16="",'净值数据(iFinD公式)'!$B16=""),"",SUMPRODUCT(持仓配置!$B$7:$N$7,'净值数据(iFinD公式)'!$B16:$N16/'净值数据(iFinD公式)'!$B$5:$N$5)*(1-持仓配置!$P$7)^((ROW()-6)/说明!$C$17)) -> 1.0808664 | L17: =IF(OR(K17="",K16=""),"",K17/K16-1) -> 0.065117147 | M17: =IF(K17="","",K17/MAX(K$6:K17)-1) -> 0
A18: =IF('净值数据(iFinD公式)'!A17="","",'净值数据(iFinD公式)'!A17) -> 46189 | B18: =IF(OR('净值数据(iFinD公式)'!$A17="",'净值数据(iFinD公式)'!$B17=""),"",SUMPRODUCT(持仓配置!$B$4:$N$4,'净值数据(iFinD公式)'!$B17:$N17/'净值数据(iFinD公式)'!$B$5:$N$5)*(1-持仓配置!$P$4)^((ROW()-6)/说明!$C$17)) -> 1.003562 | C18: =IF(OR(B18="",B17=""),"",B18/B17-1) -> 0.0027355394 | D18: =IF(B18="","",B18/MAX(B$6:B18)-1) -> 0 | E18: =IF(OR('净值数据(iFinD公式)'!$A17="",'净值数据(iFinD公式)'!$B17=""),"",SUMPRODUCT(持仓配置!$B$5:$N$5,'净值数据(iFinD公式)'!$B17:$N17/'净值数据(iFinD公式)'!$B$5:$N$5)*(1-持仓配置!$P$5)^((ROW()-6)/说明!$C$17)) -> 1.0097217 | F18: =IF(OR(E18="",E17=""),"",E18/E17-1) -> 0.0044369691 | G18: =IF(E18="","",E18/MAX(E$6:E18)-1) -> 0 | H18: =IF(OR('净值数据(iFinD公式)'!$A17="",'净值数据(iFinD公式)'!$B17=""),"",SUMPRODUCT(持仓配置!$B$6:$N$6,'净值数据(iFinD公式)'!$B17:$N17/'净值数据(iFinD公式)'!$B$5:$N$5)*(1-持仓配置!$P$6)^((ROW()-6)/说明!$C$17)) -> 1.0137961 | I18: =IF(OR(H18="",H17=""),"",H18/H17-1) -> 0.0062834111 | J18: =IF(H18="","",H18/MAX(H$6:H18)-1) -> 0 | K18: =IF(OR('净值数据(iFinD公式)'!$A17="",'净值数据(iFinD公式)'!$B17=""),"",SUMPRODUCT(持仓配置!$B$7:$N$7,'净值数据(iFinD公式)'!$B17:$N17/'净值数据(iFinD公式)'!$B$5:$N$5)*(1-持仓配置!$P$7)^((ROW()-6)/说明!$C$17)) -> 1.1061052 | L18: =IF(OR(K18="",K17=""),"",K18/K17-1) -> 0.023350539 | M18: =IF(K18="","",K18/MAX(K$6:K18)-1) -> 0
... A26: =IF('净值数据(iFinD公式)'!A25="","",'净值数据(iFinD公式)'!A25) -> 46202 | B26: =IF(OR('净值数据(iFinD公式)'!$A25="",'净值数据(iFinD公式)'!$B25=""),"",SUMPRODUCT(持仓配置!$B$4:$N$4,'净值数据(iFinD公式)'!$B25:$N25/'净值数据(iFinD公式)'!$B$5:$N$5)*(1-持仓配置!$P$4)^((ROW()-6)/说明!$C$17)) -> 1.0092716 | C26: =IF(OR(B26="",B25=""),"",B26/B25-1) -> 0.0016853386 | D26: =IF(B26="","",B26/MAX(B$6:B26)-1) -> -0.00097520704 | E26: =IF(OR('净值数据(iFinD公式)'!$A25="",'净值数据(iFinD公式)'!$B25=""),"",SUMPRODUCT(持仓配置!$B$5:$N$5,'净值数据(iFinD公式)'!$B25:$N25/'净值数据(iFinD公式)'!$B$5:$N$5)*(1-持仓配置!$P$5)^((ROW()-6)/说明!$C$17)) -> 1.0215215 | F26: =IF(OR(E26="",E25=""),"",E26/E25-1) -> 0.0022807927 | G26: =IF(E26="","",E26/MAX(E$6:E26)-1) -> -0.0036329055 | H26: =IF(OR('净值数据(iFinD公式)'!$A25="",'净值数据(iFinD公式)'!$B25=""),"",SUMPRODUCT(持仓配置!$B$6:$N$6,'净值数据(iFinD公式)'!$B25:$N25/'净值数据(iFinD公式)'!$B$5:$N$5)*(1-持仓配置!$P$6)^((ROW()-6)/说明!$C$17)) -> 1.028918 | I26: =IF(OR(H26="",H25=""),"",H26/H25-1) -> 0.003020864 | J26: =IF(H26="","",H26/MAX(H$6:H26)-1) -> -0.0056962923 | K26: =IF(OR('净值数据(iFinD公式)'!$A25="",'净值数据(iFinD公式)'!$B25=""),"",SUMPRODUCT(持仓配置!$B$7:$N$7,'净值数据(iFinD公式)'!$B25:$N25/'净值数据(iFinD公式)'!$B$5:$N$5)*(1-持仓配置!$P$7)^((ROW()-6)/说明!$C$17)) -> 1.2352096 | L26: =IF(OR(K26="",K25=""),"",K26/K25-1) -> 0.0099522555 | M26: =IF(K26="","",K26/MAX(K$6:K26)-1) -> -0.018751931
A27: =IF('净值数据(iFinD公式)'!A26="","",'净值数据(iFinD公式)'!A26) -> 46203 | B27: =IF(OR('净值数据(iFinD公式)'!$A26="",'净值数据(iFinD公式)'!$B26=""),"",SUMPRODUCT(持仓配置!$B$4:$N$4,'净值数据(iFinD公式)'!$B26:$N26/'净值数据(iFinD公式)'!$B$5:$N$5)*(1-持仓配置!$P$4)^((ROW()-6)/说明!$C$17)) -> 1.0119135 | C27: =IF(OR(B27="",B26=""),"",B27/B26-1) -> 0.0026176935 | D27: =IF(B27="","",B27/MAX(B$6:B27)-1) -> 0 | E27: =IF(OR('净值数据(iFinD公式)'!$A26="",'净值数据(iFinD公式)'!$B26=""),"",SUMPRODUCT(持仓配置!$B$5:$N$5,'净值数据(iFinD公式)'!$B26:$N26/'净值数据(iFinD公式)'!$B$5:$N$5)*(1-持仓配置!$P$5)^((ROW()-6)/说明!$C$17)) -> 1.0280127 | F27: =IF(OR(E27="",E26=""),"",E27/E26-1) -> 0.0063545029 | G27: =IF(E27="","",E27/MAX(E$6:E27)-1) -> 0 | H27: =IF(OR('净值数据(iFinD公式)'!$A26="",'净值数据(iFinD公式)'!$B26=""),"",SUMPRODUCT(持仓配置!$B$6:$N$6,'净值数据(iFinD公式)'!$B26:$N26/'净值数据(iFinD公式)'!$B$5:$N$5)*(1-持仓配置!$P$6)^((ROW()-6)/说明!$C$17)) -> 1.0388818 | I27: =IF(OR(H27="",H26=""),"",H27/H26-1) -> 0.0096837753 | J27: =IF(H27="","",H27/MAX(H$6:H27)-1) -> 0 | K27: =IF(OR('净值数据(iFinD公式)'!$A26="",'净值数据(iFinD公式)'!$B26=""),"",SUMPRODUCT(持仓配置!$B$7:$N$7,'净值数据(iFinD公式)'!$B26:$N26/'净值数据(iFinD公式)'!$B$5:$N$5)*(1-持仓配置!$P$7)^((ROW()-6)/说明!$C$17)) -> 1.2895492 | L27: =IF(OR(K27="",K26=""),"",K27/K26-1) -> 0.0439922 | M27: =IF(K27="","",K27/MAX(K$6:K27)-1) -> 0 | O27: =B25/B6-1 -> 0.0075734673
A28: =IF('净值数据(iFinD公式)'!A27="","",'净值数据(iFinD公式)'!A27) -> 46204 | B28: =IF(OR('净值数据(iFinD公式)'!$A27="",'净值数据(iFinD公式)'!$B27=""),"",SUMPRODUCT(持仓配置!$B$4:$N$4,'净值数据(iFinD公式)'!$B27:$N27/'净值数据(iFinD公式)'!$B$5:$N$5)*(1-持仓配置!$P$4)^((ROW()-6)/说明!$C$17)) -> 1.0089265 | C28: =IF(OR(B28="",B27=""),"",B28/B27-1) -> -0.0029519081 | D28: =IF(B28="","",B28/MAX(B$6:B28)-1) -> -0.0029519081 | E28: =IF(OR('净值数据(iFinD公式)'!$A27="",'净值数据(iFinD公式)'!$B27=""),"",SUMPRODUCT(持仓配置!$B$5:$N$5,'净值数据(iFinD公式)'!$B27:$N27/'净值数据(iFinD公式)'!$B$5:$N$5)*(1-持仓配置!$P$5)^((ROW()-6)/说明!$C$17)) -> 1.0234029 | F28: =IF(OR(E28="",E27=""),"",E28/E27-1) -> -0.0044842236 | G28: =IF(E28="","",E28/MAX(E$6:E28)-1) -> -0.0044842236 | H28: =IF(OR('净值数据(iFinD公式)'!$A27="",'净值数据(iFinD公式)'!$B27=""),"",SUMPRODUCT(持仓配置!$B$6:$N$6,'净值数据(iFinD公式)'!$B27:$N27/'净值数据(iFinD公式)'!$B$5:$N$5)*(1-持仓配置!$P$6)^((ROW()-6)/说明!$C$17)) -> 1.0322302 | I28: =IF(OR(H28="",H27=""),"",H28/H27-1) -> -0.0064026708 | J28: =IF(H28="","",H28/MAX(H$6:H28)-1) -> -0.0064026708 | K28: =IF(OR('净值数据(iFinD公式)'!$A27="",'净值数据(iFinD公式)'!$B27=""),"",SUMPRODUCT(持仓配置!$B$7:$N$7,'净值数据(iFinD公式)'!$B27:$N27/'净值数据(iFinD公式)'!$B$5:$N$5)*(1-持仓配置!$P$7)^((ROW()-6)/说明!$C$17)) -> 1.249937 | L28: =IF(OR(K28="",K27=""),"",K28/K27-1) -> -0.030717848 | M28: =IF(K28="","",K28/MAX(K$6:K28)-1) -> -0.030717848
A29: =IF('净值数据(iFinD公式)'!A28="","",'净值数据(iFinD公式)'!A28) -> 46205 | B29: =IF(OR('净值数据(iFinD公式)'!$A28="",'净值数据(iFinD公式)'!$B28=""),"",SUMPRODUCT(持仓配置!$B$4:$N$4,'净值数据(iFinD公式)'!$B28:$N28/'净值数据(iFinD公式)'!$B$5:$N$5)*(1-持仓配置!$P$4)^((ROW()-6)/说明!$C$17)) -> 1.003031 | C29: =IF(OR(B29="",B28=""),"",B29/B28-1) -> -0.005843289 | D29: =IF(B29="","",B29/MAX(B$6:B29)-1) -> -0.0087779482 | E29: =IF(OR('净值数据(iFinD公式)'!$A28="",'净值数据(iFinD公式)'!$B28=""),"",SUMPRODUCT(持仓配置!$B$5:$N$5,'净值数据(iFinD公式)'!$B28:$N28/'净值数据(iFinD公式)'!$B$5:$N$5)*(1-持仓配置!$P$5)^((ROW()-6)/说明!$C$17)) -> 1.0105958 | F29: =IF(OR(E29="",E28=""),"",E29/E28-1) -> -0.012514236 | G29: =IF(E29="","",E29/MAX(E$6:E29)-1) -> -0.016942343 | H29: =IF(OR('净值数据(iFinD公式)'!$A28="",'净值数据(iFinD公式)'!$B28=""),"",SUMPRODUCT(持仓配置!$B$6:$N$6,'净值数据(iFinD公式)'!$B28:$N28/'净值数据(iFinD公式)'!$B$5:$N$5)*(1-持仓配置!$P$6)^((ROW()-6)/说明!$C$17)) -> 1.0134351 | I29: =IF(OR(H29="",H28=""),"",H29/H28-1) -> -0.01820829 | J29: =IF(H29="","",H29/MAX(H$6:H29)-1) -> -0.024494379 | K29: =IF(OR('净值数据(iFinD公式)'!$A28="",'净值数据(iFinD公式)'!$B28=""),"",SUMPRODUCT(持仓配置!$B$7:$N$7,'净值数据(iFinD公式)'!$B28:$N28/'净值数据(iFinD公式)'!$B$5:$N$5)*(1-持仓配置!$P$7)^((ROW()-6)/说明!$C$17)) -> 1.1401462 | L29: =IF(OR(K29="",K28=""),"",K29/K28-1) -> -0.087837069 | M29: =IF(K29="","",K29/MAX(K$6:K29)-1) -> -0.11585675
A30: =IF('净值数据(iFinD公式)'!A29="","",'净值数据(iFinD公式)'!A29) -> 46206 | B30: =IF(OR('净值数据(iFinD公式)'!$A29="",'净值数据(iFinD公式)'!$B29=""),"",SUMPRODUCT(持仓配置!$B$4:$N$4,'净值数据(iFinD公式)'!$B29:$N29/'净值数据(iFinD公式)'!$B$5:$N$5)*(1-持仓配置!$P$4)^((ROW()-6)/说明!$C$17)) -> 1.0038981 | C30: =IF(OR(B30="",B29=""),"",B30/B29-1) -> 0.00086451351 | D30: =IF(B30="","",B30/MAX(B$6:B30)-1) -> -0.0079210234 | E30: =IF(OR('净值数据(iFinD公式)'!$A29="",'净值数据(iFinD公式)'!$B29=""),"",SUMPRODUCT(持仓配置!$B$5:$N$5,'净值数据(iFinD公式)'!$B29:$N29/'净值数据(iFinD公式)'!$B$5:$N$5)*(1-持仓配置!$P$5)^((ROW()-6)/说明!$C$17)) -> 1.0113375 | F30: =IF(OR(E30="",E29=""),"",E30/E29-1) -> 0.00073394516 | G30: =IF(E30="","",E30/MAX(E$6:E30)-1) -> -0.016220832 | H30: =IF(OR('净值数据(iFinD公式)'!$A29="",'净值数据(iFinD公式)'!$B29=""),"",SUMPRODUCT(持仓配置!$B$6:$N$6,'净值数据(iFinD公式)'!$B29:$N29/'净值数据(iFinD公式)'!$B$5:$N$5)*(1-持仓配置!$P$6)^((ROW()-6)/说明!$C$17)) -> 1.0152735 | I30: =IF(OR(H30="",H29=""),"",H30/H29-1) -> 0.0018140599 | J30: =IF(H30="","",H30/MAX(H$6:H30)-1) -> -0.022724753 | K30: =IF(OR('净值数据(iFinD公式)'!$A29="",'净值数据(iFinD公式)'!$B29=""),"",SUMPRODUCT(持仓配置!$B$7:$N$7,'净值数据(iFinD公式)'!$B29:$N29/'净值数据(iFinD公式)'!$B$5:$N$5)*(1-持仓配置!$P$7)^((ROW()-6)/说明!$C$17)) -> 1.1316225 | L30: =IF(OR(K30="",K29=""),"",K30/K29-1) -> -0.0074759634 | M30: =IF(K30="","",K30/MAX(K$6:K30)-1) -> -0.12246657
A31: =IF('净值数据(iFinD公式)'!A30="","",'净值数据(iFinD公式)'!A30) -> 46209 | B31: =IF(OR('净值数据(iFinD公式)'!$A30="",'净值数据(iFinD公式)'!$B30=""),"",SUMPRODUCT(持仓配置!$B$4:$N$4,'净值数据(iFinD公式)'!$B30:$N30/'净值数据(iFinD公式)'!$B$5:$N$5)*(1-持仓配置!$P$4)^((ROW()-6)/说明!$C$17)) -> 1.0027798 | C31: =IF(OR(B31="",B30=""),"",B31/B30-1) -> -0.00111401 | D31: =IF(B31="","",B31/MAX(B$6:B31)-1) -> -0.0090262092 | E31: =IF(OR('净值数据(iFinD公式)'!$A30="",'净值数据(iFinD公式)'!$B30=""),"",SUMPRODUCT(持仓配置!$B$5:$N$5,'净值数据(iFinD公式)'!$B30:$N30/'净值数据(iFinD公式)'!$B$5:$N$5)*(1-持仓配置!$P$5)^((ROW()-6)/说明!$C$17)) -> 1.0085651 | F31: =IF(OR(E31="",E30=""),"",E31/E30-1) -> -0.0027413421 | G31: =IF(E31="","",E31/MAX(E$6:E31)-1) -> -0.018917708 | H31: =IF(OR('净值数据(iFinD公式)'!$A30="",'净值数据(iFinD公式)'!$B30=""),"",SUMPRODUCT(持仓配置!$B$6:$N$6,'净值数据(iFinD公式)'!$B30:$N30/'净值数据(iFinD公式)'!$B$5:$N$5)*(1-持仓配置!$P$6)^((ROW()-6)/说明!$C$17)) -> 1.0106812 | I31: =IF(OR(H31="",H30=""),"",H31/H30-1) -> -0.0045232035 | J31: =IF(H31="","",H31/MAX(H$6:H31)-1) -> -0.027145168 | K31: =IF(OR('净值数据(iFinD公式)'!$A30="",'净值数据(iFinD公式)'!$B30=""),"",SUMPRODUCT(持仓配置!$B$7:$N$7,'净值数据(iFinD公式)'!$B30:$N30/'净值数据(iFinD公式)'!$B$5:$N$5)*(1-持仓配置!$P$7)^((ROW()-6)/说明!$C$17)) -> 1.1091831 | L31: =IF(OR(K31="",K30=""),"",K31/K30-1) -> -0.019829481 | M31: =IF(K31="","",K31/MAX(K$6:K31)-1) -> -0.13986761
A32: =IF('净值数据(iFinD公式)'!A31="","",'净值数据(iFinD公式)'!A31) -> 46210 | B32: =IF(OR('净值数据(iFinD公式)'!$A31="",'净值数据(iFinD公式)'!$B31=""),"",SUMPRODUCT(持仓配置!$B$4:$N$4,'净值数据(iFinD公式)'!$B31:$N31/'净值数据(iFinD公式)'!$B$5:$N$5)*(1-持仓配置!$P$4)^((ROW()-6)/说明!$C$17)) -> 1.0020308 | C32: =IF(OR(B32="",B31=""),"",B32/B31-1) -> -0.00074692569 | D32: =IF(B32="","",B32/MAX(B$6:B32)-1) -> -0.009766393 | E32: =IF(OR('净值数据(iFinD公式)'!$A31="",'净值数据(iFinD公式)'!$B31=""),"",SUMPRODUCT(持仓配置!$B$5:$N$5,'净值数据(iFinD公式)'!$B31:$N31/'净值数据(iFinD公式)'!$B$5:$N$5)*(1-持仓配置!$P$5)^((ROW()-6)/说明!$C$17)) -> 1.0072335 | F32: =IF(OR(E32="",E31=""),"",E32/E31-1) -> -0.0013202402 | G32: =IF(E32="","",E32/MAX(E$6:E32)-1) -> -0.020212972 | H32: =IF(OR('净值数据(iFinD公式)'!$A31="",'净值数据(iFinD公式)'!$B31=""),"",SUMPRODUCT(持仓配置!$B$6:$N$6,'净值数据(iFinD公式)'!$B31:$N31/'净值数据(iFinD公式)'!$B$5:$N$5)*(1-持仓配置!$P$6)^((ROW()-6)/说明!$C$17)) -> 1.008503 | I32: =IF(OR(H32="",H31=""),"",H32/H31-1) -> -0.0021551624 | J32: =IF(H32="","",H32/MAX(H$6:H32)-1) -> -0.029241828 | K32: =IF(OR('净值数据(iFinD公式)'!$A31="",'净值数据(iFinD公式)'!$B31=""),"",SUMPRODUCT(持仓配置!$B$7:$N$7,'净值数据(iFinD公式)'!$B31:$N31/'净值数据(iFinD公式)'!$B$5:$N$5)*(1-持仓配置!$P$7)^((ROW()-6)/说明!$C$17)) -> 1.1168983 | L32: =IF(OR(K32="",K31=""),"",K32/K31-1) -> 0.0069557665 | M32: =IF(K32="","",K32/MAX(K$6:K32)-1) -> -0.13388473
A33: =IF('净值数据(iFinD公式)'!A32="","",'净值数据(iFinD公式)'!A32) | B33: =IF(OR('净值数据(iFinD公式)'!$A32="",'净值数据(iFinD公式)'!$B32=""),"",SUMPRODUCT(持仓配置!$B$4:$N$4,'净值数据(iFinD公式)'!$B32:$N32/'净值数据(iFinD公式)'!$B$5:$N$5)*(1-持仓配置!$P$4)^((ROW()-6)/说明!$C$17)) | C33: =IF(OR(B33="",B32=""),"",B33/B32-1) | D33: =IF(B33="","",B33/MAX(B$6:B33)-1) | E33: =IF(OR('净值数据(iFinD公式)'!$A32="",'净值数据(iFinD公式)'!$B32=""),"",SUMPRODUCT(持仓配置!$B$5:$N$5,'净值数据(iFinD公式)'!$B32:$N32/'净值数据(iFinD公式)'!$B$5:$N$5)*(1-持仓配置!$P$5)^((ROW()-6)/说明!$C$17)) | F33: =IF(OR(E33="",E32=""),"",E33/E32-1) | G33: =IF(E33="","",E33/MAX(E$6:E33)-1) | H33: =IF(OR('净值数据(iFinD公式)'!$A32="",'净值数据(iFinD公式)'!$B32=""),"",SUMPRODUCT(持仓配置!$B$6:$N$6,'净值数据(iFinD公式)'!$B32:$N32/'净值数据(iFinD公式)'!$B$5:$N$5)*(1-持仓配置!$P$6)^((ROW()-6)/说明!$C$17)) | I33: =IF(OR(H33="",H32=""),"",H33/H32-1) | J33: =IF(H33="","",H33/MAX(H$6:H33)-1) | K33: =IF(OR('净值数据(iFinD公式)'!$A32="",'净值数据(iFinD公式)'!$B32=""),"",SUMPRODUCT(持仓配置!$B$7:$N$7,'净值数据(iFinD公式)'!$B32:$N32/'净值数据(iFinD公式)'!$B$5:$N$5)*(1-持仓配置!$P$7)^((ROW()-6)/说明!$C$17)) | L33: =IF(OR(K33="",K32=""),"",K33/K32-1) | M33: =IF(K33="","",K33/MAX(K$6:K33)-1)
A34: =IF('净值数据(iFinD公式)'!A33="","",'净值数据(iFinD公式)'!A33) | B34: =IF(OR('净值数据(iFinD公式)'!$A33="",'净值数据(iFinD公式)'!$B33=""),"",SUMPRODUCT(持仓配置!$B$4:$N$4,'净值数据(iFinD公式)'!$B33:$N33/'净值数据(iFinD公式)'!$B$5:$N$5)*(1-持仓配置!$P$4)^((ROW()-6)/说明!$C$17)) | C34: =IF(OR(B34="",B33=""),"",B34/B33-1) | D34: =IF(B34="","",B34/MAX(B$6:B34)-1) | E34: =IF(OR('净值数据(iFinD公式)'!$A33="",'净值数据(iFinD公式)'!$B33=""),"",SUMPRODUCT(持仓配置!$B$5:$N$5,'净值数据(iFinD公式)'!$B33:$N33/'净值数据(iFinD公式)'!$B$5:$N$5)*(1-持仓配置!$P$5)^((ROW()-6)/说明!$C$17)) | F34: =IF(OR(E34="",E33=""),"",E34/E33-1) | G34: =IF(E34="","",E34/MAX(E$6:E34)-1) | H34: =IF(OR('净值数据(iFinD公式)'!$A33="",'净值数据(iFinD公式)'!$B33=""),"",SUMPRODUCT(持仓配置!$B$6:$N$6,'净值数据(iFinD公式)'!$B33:$N33/'净值数据(iFinD公式)'!$B$5:$N$5)*(1-持仓配置!$P$6)^((ROW()-6)/说明!$C$17)) | I34: =IF(OR(H34="",H33=""),"",H34/H33-1) | J34: =IF(H34="","",H34/MAX(H$6:H34)-1) | K34: =IF(OR('净值数据(iFinD公式)'!$A33="",'净值数据(iFinD公式)'!$B33=""),"",SUMPRODUCT(持仓配置!$B$7:$N$7,'净值数据(iFinD公式)'!$B33:$N33/'净值数据(iFinD公式)'!$B$5:$N$5)*(1-持仓配置!$P$7)^((ROW()-6)/说明!$C$17)) | L34: =IF(OR(K34="",K33=""),"",K34/K33-1) | M34: =IF(K34="","",K34/MAX(K$6:K34)-1)
A35: =IF('净值数据(iFinD公式)'!A34="","",'净值数据(iFinD公式)'!A34) | B35: =IF(OR('净值数据(iFinD公式)'!$A34="",'净值数据(iFinD公式)'!$B34=""),"",SUMPRODUCT(持仓配置!$B$4:$N$4,'净值数据(iFinD公式)'!$B34:$N34/'净值数据(iFinD公式)'!$B$5:$N$5)*(1-持仓配置!$P$4)^((ROW()-6)/说明!$C$17)) | C35: =IF(OR(B35="",B34=""),"",B35/B34-1) | D35: =IF(B35="","",B35/MAX(B$6:B35)-1) | E35: =IF(OR('净值数据(iFinD公式)'!$A34="",'净值数据(iFinD公式)'!$B34=""),"",SUMPRODUCT(持仓配置!$B$5:$N$5,'净值数据(iFinD公式)'!$B34:$N34/'净值数据(iFinD公式)'!$B$5:$N$5)*(1-持仓配置!$P$5)^((ROW()-6)/说明!$C$17)) | F35: =IF(OR(E35="",E34=""),"",E35/E34-1) | G35: =IF(E35="","",E35/MAX(E$6:E35)-1) | H35: =IF(OR('净值数据(iFinD公式)'!$A34="",'净值数据(iFinD公式)'!$B34=""),"",SUMPRODUCT(持仓配置!$B$6:$N$6,'净值数据(iFinD公式)'!$B34:$N34/'净值数据(iFinD公式)'!$B$5:$N$5)*(1-持仓配置!$P$6)^((ROW()-6)/说明!$C$17)) | I35: =IF(OR(H35="",H34=""),"",H35/H34-1) | J35: =IF(H35="","",H35/MAX(H$6:H35)-1) | K35: =IF(OR('净值数据(iFinD公式)'!$A34="",'净值数据(iFinD公式)'!$B34=""),"",SUMPRODUCT(持仓配置!$B$7:$N$7,'净值数据(iFinD公式)'!$B34:$N34/'净值数据(iFinD公式)'!$B$5:$N$5)*(1-持仓配置!$P$7)^((ROW()-6)/说明!$C$17)) | L35: =IF(OR(K35="",K34=""),"",K35/K34-1) | M35: =IF(K35="","",K35/MAX(K$6:K35)-1)
A36: =IF('净值数据(iFinD公式)'!A35="","",'净值数据(iFinD公式)'!A35) | B36: =IF(OR('净值数据(iFinD公式)'!$A35="",'净值数据(iFinD公式)'!$B35=""),"",SUMPRODUCT(持仓配置!$B$4:$N$4,'净值数据(iFinD公式)'!$B35:$N35/'净值数据(iFinD公式)'!$B$5:$N$5)*(1-持仓配置!$P$4)^((ROW()-6)/说明!$C$17)) | C36: =IF(OR(B36="",B35=""),"",B36/B35-1) | D36: =IF(B36="","",B36/MAX(B$6:B36)-1) | E36: =IF(OR('净值数据(iFinD公式)'!$A35="",'净值数据(iFinD公式)'!$B35=""),"",SUMPRODUCT(持仓配置!$B$5:$N$5,'净值数据(iFinD公式)'!$B35:$N35/'净值数据(iFinD公式)'!$B$5:$N$5)*(1-持仓配置!$P$5)^((ROW()-6)/说明!$C$17)) | F36: =IF(OR(E36="",E35=""),"",E36/E35-1) | G36: =IF(E36="","",E36/MAX(E$6:E36)-1) | H36: =IF(OR('净值数据(iFinD公式)'!$A35="",'净值数据(iFinD公式)'!$B35=""),"",SUMPRODUCT(持仓配置!$B$6:$N$6,'净值数据(iFinD公式)'!$B35:$N35/'净值数据(iFinD公式)'!$B$5:$N$5)*(1-持仓配置!$P$6)^((ROW()-6)/说明!$C$17)) | I36: =IF(OR(H36="",H35=""),"",H36/H35-1) | J36: =IF(H36="","",H36/MAX(H$6:H36)-1) | K36: =IF(OR('净值数据(iFinD公式)'!$A35="",'净值数据(iFinD公式)'!$B35=""),"",SUMPRODUCT(持仓配置!$B$7:$N$7,'净值数据(iFinD公式)'!$B35:$N35/'净值数据(iFinD公式)'!$B$5:$N$5)*(1-持仓配置!$P$7)^((ROW()-6)/说明!$C$17)) | L36: =IF(OR(K36="",K35=""),"",K36/K35-1) | M36: =IF(K36="","",K36/MAX(K$6:K36)-1)
A37: =IF('净值数据(iFinD公式)'!A36="","",'净值数据(iFinD公式)'!A36) | B37: =IF(OR('净值数据(iFinD公式)'!$A36="",'净值数据(iFinD公式)'!$B36=""),"",SUMPRODUCT(持仓配置!$B$4:$N$4,'净值数据(iFinD公式)'!$B36:$N36/'净值数据(iFinD公式)'!$B$5:$N$5)*(1-持仓配置!$P$4)^((ROW()-6)/说明!$C$17)) | C37: =IF(OR(B37="",B36=""),"",B37/B36-1) | D37: =IF(B37="","",B37/MAX(B$6:B37)-1) | E37: =IF(OR('净值数据(iFinD公式)'!$A36="",'净值数据(iFinD公式)'!$B36=""),"",SUMPRODUCT(持仓配置!$B$5:$N$5,'净值数据(iFinD公式)'!$B36:$N36/'净值数据(iFinD公式)'!$B$5:$N$5)*(1-持仓配置!$P$5)^((ROW()-6)/说明!$C$17)) | F37: =IF(OR(E37="",E36=""),"",E37/E36-1) | G37: =IF(E37="","",E37/MAX(E$6:E37)-1) | H37: =IF(OR('净值数据(iFinD公式)'!$A36="",'净值数据(iFinD公式)'!$B36=""),"",SUMPRODUCT(持仓配置!$B$6:$N$6,'净值数据(iFinD公式)'!$B36:$N36/'净值数据(iFinD公式)'!$B$5:$N$5)*(1-持仓配置!$P$6)^((ROW()-6)/说明!$C$17)) | I37: =IF(OR(H37="",H36=""),"",H37/H36-1) | J37: =IF(H37="","",H37/MAX(H$6:H37)-1) | K37: =IF(OR('净值数据(iFinD公式)'!$A36="",'净值数据(iFinD公式)'!$B36=""),"",SUMPRODUCT(持仓配置!$B$7:$N$7,'净值数据(iFinD公式)'!$B36:$N36/'净值数据(iFinD公式)'!$B$5:$N$5)*(1-持仓配置!$P$7)^((ROW()-6)/说明!$C$17)) | L37: =IF(OR(K37="",K36=""),"",K37/K36-1) | M37: =IF(K37="","",K37/MAX(K$6:K37)-1)
A38: =IF('净值数据(iFinD公式)'!A37="","",'净值数据(iFinD公式)'!A37) | B38: =IF(OR('净值数据(iFinD公式)'!$A37="",'净值数据(iFinD公式)'!$B37=""),"",SUMPRODUCT(持仓配置!$B$4:$N$4,'净值数据(iFinD公式)'!$B37:$N37/'净值数据(iFinD公式)'!$B$5:$N$5)*(1-持仓配置!$P$4)^((ROW()-6)/说明!$C$17)) | C38: =IF(OR(B38="",B37=""),"",B38/B37-1) | D38: =IF(B38="","",B38/MAX(B$6:B38)-1) | E38: =IF(OR('净值数据(iFinD公式)'!$A37="",'净值数据(iFinD公式)'!$B37=""),"",SUMPRODUCT(持仓配置!$B$5:$N$5,'净值数据(iFinD公式)'!$B37:$N37/'净值数据(iFinD公式)'!$B$5:$N$5)*(1-持仓配置!$P$5)^((ROW()-6)/说明!$C$17)) | F38: =IF(OR(E38="",E37=""),"",E38/E37-1) | G38: =IF(E38="","",E38/MAX(E$6:E38)-1) | H38: =IF(OR('净值数据(iFinD公式)'!$A37="",'净值数据(iFinD公式)'!$B37=""),"",SUMPRODUCT(持仓配置!$B$6:$N$6,'净值数据(iFinD公式)'!$B37:$N37/'净值数据(iFinD公式)'!$B$5:$N$5)*(1-持仓配置!$P$6)^((ROW()-6)/说明!$C$17)) | I38: =IF(OR(H38="",H37=""),"",H38/H37-1) | J38: =IF(H38="","",H38/MAX(H$6:H38)-1) | K38: =IF(OR('净值数据(iFinD公式)'!$A37="",'净值数据(iFinD公式)'!$B37=""),"",SUMPRODUCT(持仓配置!$B$7:$N$7,'净值数据(iFinD公式)'!$B37:$N37/'净值数据(iFinD公式)'!$B$5:$N$5)*(1-持仓配置!$P$7)^((ROW()-6)/说明!$C$17)) | L38: =IF(OR(K38="",K37=""),"",K38/K37-1) | M38: =IF(K38="","",K38/MAX(K$6:K38)-1)
A39: =IF('净值数据(iFinD公式)'!A38="","",'净值数据(iFinD公式)'!A38) | B39: =IF(OR('净值数据(iFinD公式)'!$A38="",'净值数据(iFinD公式)'!$B38=""),"",SUMPRODUCT(持仓配置!$B$4:$N$4,'净值数据(iFinD公式)'!$B38:$N38/'净值数据(iFinD公式)'!$B$5:$N$5)*(1-持仓配置!$P$4)^((ROW()-6)/说明!$C$17)) | C39: =IF(OR(B39="",B38=""),"",B39/B38-1) | D39: =IF(B39="","",B39/MAX(B$6:B39)-1) | E39: =IF(OR('净值数据(iFinD公式)'!$A38="",'净值数据(iFinD公式)'!$B38=""),"",SUMPRODUCT(持仓配置!$B$5:$N$5,'净值数据(iFinD公式)'!$B38:$N38/'净值数据(iFinD公式)'!$B$5:$N$5)*(1-持仓配置!$P$5)^((ROW()-6)/说明!$C$17)) | F39: =IF(OR(E39="",E38=""),"",E39/E38-1) | G39: =IF(E39="","",E39/MAX(E$6:E39)-1) | H39: =IF(OR('净值数据(iFinD公式)'!$A38="",'净值数据(iFinD公式)'!$B38=""),"",SUMPRODUCT(持仓配置!$B$6:$N$6,'净值数据(iFinD公式)'!$B38:$N38/'净值数据(iFinD公式)'!$B$5:$N$5)*(1-持仓配置!$P$6)^((ROW()-6)/说明!$C$17)) | I39: =IF(OR(H39="",H38=""),"",H39/H38-1) | J39: =IF(H39="","",H39/MAX(H$6:H39)-1) | K39: =IF(OR('净值数据(iFinD公式)'!$A38="",'净值数据(iFinD公式)'!$B38=""),"",SUMPRODUCT(持仓配置!$B$7:$N$7,'净值数据(iFinD公式)'!$B38:$N38/'净值数据(iFinD公式)'!$B$5:$N$5)*(1-持仓配置!$P$7)^((ROW()-6)/说明!$C$17)) | L39: =IF(OR(K39="",K38=""),"",K39/K38-1) | M39: =IF(K39="","",K39/MAX(K$6:K39)-1)
... A60: =IF('净值数据(iFinD公式)'!A59="","",'净值数据(iFinD公式)'!A59) | B60: =IF(OR('净值数据(iFinD公式)'!$A59="",'净值数据(iFinD公式)'!$B59=""),"",SUMPRODUCT(持仓配置!$B$4:$N$4,'净值数据(iFinD公式)'!$B59:$N59/'净值数据(iFinD公式)'!$B$5:$N$5)*(1-持仓配置!$P$4)^((ROW()-6)/说明!$C$17)) | C60: =IF(OR(B60="",B59=""),"",B60/B59-1) | D60: =IF(B60="","",B60/MAX(B$6:B60)-1) | E60: =IF(OR('净值数据(iFinD公式)'!$A59="",'净值数据(iFinD公式)'!$B59=""),"",SUMPRODUCT(持仓配置!$B$5:$N$5,'净值数据(iFinD公式)'!$B59:$N59/'净值数据(iFinD公式)'!$B$5:$N$5)*(1-持仓配置!$P$5)^((ROW()-6)/说明!$C$17)) | F60: =IF(OR(E60="",E59=""),"",E60/E59-1) | G60: =IF(E60="","",E60/MAX(E$6:E60)-1) | H60: =IF(OR('净值数据(iFinD公式)'!$A59="",'净值数据(iFinD公式)'!$B59=""),"",SUMPRODUCT(持仓配置!$B$6:$N$6,'净值数据(iFinD公式)'!$B59:$N59/'净值数据(iFinD公式)'!$B$5:$N$5)*(1-持仓配置!$P$6)^((ROW()-6)/说明!$C$17)) | I60: =IF(OR(H60="",H59=""),"",H60/H59-1) | J60: =IF(H60="","",H60/MAX(H$6:H60)-1) | K60: =IF(OR('净值数据(iFinD公式)'!$A59="",'净值数据(iFinD公式)'!$B59=""),"",SUMPRODUCT(持仓配置!$B$7:$N$7,'净值数据(iFinD公式)'!$B59:$N59/'净值数据(iFinD公式)'!$B$5:$N$5)*(1-持仓配置!$P$7)^((ROW()-6)/说明!$C$17)) | L60: =IF(OR(K60="",K59=""),"",K60/K59-1) | M60: =IF(K60="","",K60/MAX(K$6:K60)-1)
A62: 组合净值起始=1.0000；买入持有，权重随涨跌漂移；净值已按年化费率折每日扣费。新增日期下拉填充。

Sheet 看板-10-90
B2: 样板间组合走势看板（10-90 账户）
B3: ="买入持有 · 已扣年化费率 "&TEXT(持仓配置!$M$4,"0.0%")&"（折每日计入净值）" -> 买入持有 · 已扣年化费率 0.5%（折每日计入净值） | E3: ="净值日期："&TEXT(LOOKUP(2,1/('组合净值（模拟）'!$B$6:$B$60<>""),'组合净值（模拟）'!$A$6:$A$60),"yyyy-mm-dd") -> 净值日期：2026-07-07
B5: 产品业绩表现（历史表现不代表未来收益承诺）
B6: 最新净值 | C6: 累计收益 | D6: 年化收益 | E6: 年化波动率 | F6: 最大回撤 | G6: 夏普比率
B7: =LOOKUP(2,1/('组合净值（模拟）'!$B$6:$B$60<>""),'组合净值（模拟）'!$B$6:$B$60) -> 1.0020308 | C7: =(LOOKUP(2,1/('组合净值（模拟）'!$B$6:$B$60<>""),'组合净值（模拟）'!$B$6:$B$60))/'组合净值（模拟）'!$B$6-1 -> 0.0020307881 | D7: =(LOOKUP(2,1/('组合净值（模拟）'!$B$6:$B$60<>""),'组合净值（模拟）'!$B$6:$B$60)/'组合净值（模拟）'!$B$6)^(说明!$C$17/MAX(COUNT('组合净值（模拟）'!$C$6:$C$60),1))-1 -> 0.019698513 | E7: =STDEV('组合净值（模拟）'!$C$6:$C$60)*SQRT(说明!$C$17) -> 0.047915986 | F7: =MIN('组合净值（模拟）'!$D$6:$D$60) -> -0.0099052057 | G7: =(((LOOKUP(2,1/('组合净值（模拟）'!$B$6:$B$60<>""),'组合净值（模拟）'!$B$6:$B$60)/'组合净值（模拟）'!$B$6)^(说明!$C$17/MAX(COUNT('组合净值（模拟）'!$C$6:$C$60),1))-1)-说明!$C$16)/IF((STDEV('组合净值（模拟）'!$C$6:$C$60)*SQRT(说明!$C$17))=0,"",(STDEV('组合净值（模拟）'!$C$6:$C$60)*SQRT(说明!$C$17))) -> 0.41110524
B9: 收益表现 | E9: 风险特征
B10: 区间 | C10: 累计收益 | D10: 年化收益 | E10: 指标 | G10: 数值
B11: 起始以来 | C11: =IFERROR((LOOKUP(2,1/('组合净值（模拟）'!$B$6:$B$60<>""),'组合净值（模拟）'!$B$6:$B$60))/('组合净值（模拟）'!$B$6)-1,"") -> 0.0020307881 | D11: =IFERROR((LOOKUP(2,1/('组合净值（模拟）'!$B$6:$B$60<>""),'组合净值（模拟）'!$B$6:$B$60)/('组合净值（模拟）'!$B$6))^(说明!$C$17/COUNT('组合净值（模拟）'!$C$6:$C$60))-1,"") -> 0.019698513 | E11: 最大回撤 | G11: =MIN('组合净值（模拟）'!$D$6:$D$60) -> -0.0099052057
B12: 2026YTD | C12: =IFERROR((LOOKUP(2,1/('组合净值（模拟）'!$B$6:$B$60<>""),'组合净值（模拟）'!$B$6:$B$60))/(IFERROR(LOOKUP(DATE(2026,1,1),'组合净值（模拟）'!$A$6:$A$60,'组合净值（模拟）'!$B$6:$B$60),'组合净值（模拟）'!$B$6))-1,"") -> 0.0020307881 | D12: =IFERROR((LOOKUP(2,1/('组合净值（模拟）'!$B$6:$B$60<>""),'组合净值（模拟）'!$B$6:$B$60)/(IFERROR(LOOKUP(DATE(2026,1,1),'组合净值（模拟）'!$A$6:$A$60,'组合净值（模拟）'!$B$6:$B$60),'组合净值（模拟）'!$B$6)))^(说明!$C$17/MAX(COUNTIF('组合净值（模拟）'!$A$6:$A$60,">="&(DATE(2026,1,1))),1))-1,"") -> 0.018962066 | E12: 回撤修复天数(未创新高) | G12: =IFERROR((LOOKUP(2,1/('组合净值（模拟）'!$B$6:$B$60<>""),ROW('组合净值（模拟）'!$B$6:$B$60)))-(LOOKUP(2,1/('组合净值（模拟）'!$D$6:$D$60=0),ROW('组合净值（模拟）'!$D$6:$D$60))),"") -> 5
B13: 近3个月 | C13: =IFERROR((LOOKUP(2,1/('组合净值（模拟）'!$B$6:$B$60<>""),'组合净值（模拟）'!$B$6:$B$60))/(IFERROR(LOOKUP(EDATE(LOOKUP(2,1/('组合净值（模拟）'!$B$6:$B$60<>""),'组合净值（模拟）'!$A$6:$A$60),-3),'组合净值（模拟）'!$A$6:$A$60,'组合净值（模拟）'!$B$6:$B$60),'组合净值（模拟）'!$B$6))-1,"") -> 0.0020307881 | D13: =IFERROR((LOOKUP(2,1/('组合净值（模拟）'!$B$6:$B$60<>""),'组合净值（模拟）'!$B$6:$B$60)/(IFERROR(LOOKUP(EDATE(LOOKUP(2,1/('组合净值（模拟）'!$B$6:$B$60<>""),'组合净值（模拟）'!$A$6:$A$60),-3),'组合净值（模拟）'!$A$6:$A$60,'组合净值（模拟）'!$B$6:$B$60),'组合净值（模拟）'!$B$6)))^(说明!$C$17/MAX(COUNTIF('组合净值（模拟）'!$A$6:$A$60,">="&(EDATE(LOOKUP(2,1/('组合净值（模拟）'!$B$6:$B$60<>""),'组合净值（模拟）'!$A$6:$A$60),-3))),1))-1,"") -> 0.018962066 | E13: 正收益占比 | G13: =COUNTIF('组合净值（模拟）'!$C$6:$C$60,">0")/MAX(COUNT('组合净值（模拟）'!$C$6:$C$60),1) -> 0.57692308
B14: 近6个月 | C14: =IFERROR((LOOKUP(2,1/('组合净值（模拟）'!$B$6:$B$60<>""),'组合净值（模拟）'!$B$6:$B$60))/(IFERROR(LOOKUP(EDATE(LOOKUP(2,1/('组合净值（模拟）'!$B$6:$B$60<>""),'组合净值（模拟）'!$A$6:$A$60),-6),'组合净值（模拟）'!$A$6:$A$60,'组合净值（模拟）'!$B$6:$B$60),'组合净值（模拟）'!$B$6))-1,"") -> 0.0020307881 | D14: =IFERROR((LOOKUP(2,1/('组合净值（模拟）'!$B$6:$B$60<>""),'组合净值（模拟）'!$B$6:$B$60)/(IFERROR(LOOKUP(EDATE(LOOKUP(2,1/('组合净值（模拟）'!$B$6:$B$60<>""),'组合净值（模拟）'!$A$6:$A$60),-6),'组合净值（模拟）'!$A$6:$A$60,'组合净值（模拟）'!$B$6:$B$60),'组合净值（模拟）'!$B$6)))^(说明!$C$17/MAX(COUNTIF('组合净值（模拟）'!$A$6:$A$60,">="&(EDATE(LOOKUP(2,1/('组合净值（模拟）'!$B$6:$B$60<>""),'组合净值（模拟）'!$A$6:$A$60),-6))),1))-1,"") -> 0.018962066 | E14: 年化波动率 | G14: =STDEV('组合净值（模拟）'!$C$6:$C$60)*SQRT(说明!$C$17) -> 0.047915986
B15: 近1年 | C15: =IFERROR((LOOKUP(2,1/('组合净值（模拟）'!$B$6:$B$60<>""),'组合净值（模拟）'!$B$6:$B$60))/(IFERROR(LOOKUP(EDATE(LOOKUP(2,1/('组合净值（模拟）'!$B$6:$B$60<>""),'组合净值（模拟）'!$A$6:$A$60),-12),'组合净值（模拟）'!$A$6:$A$60,'组合净值（模拟）'!$B$6:$B$60),'组合净值（模拟）'!$B$6))-1,"") -> 0.0020307881 | D15: =IFERROR((LOOKUP(2,1/('组合净值（模拟）'!$B$6:$B$60<>""),'组合净值（模拟）'!$B$6:$B$60)/(IFERROR(LOOKUP(EDATE(LOOKUP(2,1/('组合净值（模拟）'!$B$6:$B$60<>""),'组合净值（模拟）'!$A$6:$A$60),-12),'组合净值（模拟）'!$A$6:$A$60,'组合净值（模拟）'!$B$6:$B$60),'组合净值（模拟）'!$B$6)))^(说明!$C$17/MAX(COUNTIF('组合净值（模拟）'!$A$6:$A$60,">="&(EDATE(LOOKUP(2,1/('组合净值（模拟）'!$B$6:$B$60<>""),'组合净值（模拟）'!$A$6:$A$60),-12))),1))-1,"") -> 0.018962066 | E15: 夏普比率 | G15: =(((LOOKUP(2,1/('组合净值（模拟）'!$B$6:$B$60<>""),'组合净值（模拟）'!$B$6:$B$60)/'组合净值（模拟）'!$B$6)^(说明!$C$17/MAX(COUNT('组合净值（模拟）'!$C$6:$C$60),1))-1)-说明!$C$16)/IF((STDEV('组合净值（模拟）'!$C$6:$C$60)*SQRT(说明!$C$17))=0,"",(STDEV('组合净值（模拟）'!$C$6:$C$60)*SQRT(说明!$C$17))) -> 0.41110524
E16: 卡玛比率 | G16: =IFERROR(((LOOKUP(2,1/('组合净值（模拟）'!$B$6:$B$60<>""),'组合净值（模拟）'!$B$6:$B$60)/'组合净值（模拟）'!$B$6)^(说明!$C$17/MAX(COUNT('组合净值（模拟）'!$C$6:$C$60),1))-1)/ABS(MIN('组合净值（模拟）'!$D$6:$D$60)),"") -> 1.9887031
B18: 产品运作情况 · 组合净值曲线
B35: 统计区间自2026/6/1起；运作初期样本少，年化类指标仅供参考。新增交易日后请同步扩展本图数据区。

Sheet 看板-20-80
B2: 样板间组合走势看板（20-80 账户）
