Workbook

Sheet vs招行
G1: 46191 | H1: 46234 | L1: 10-90
E2: 46239 | F2: 0.98421564 | G2: 46195 | H2: 46237 | I2: 46174 | M2: 0.9860267 | N2: 1
F3: 0.98658983 | G3: 46240 | H3: 46240 | I3: 46240 | M3: 0.99521566 | N3: 0.98658983
B4: 产品类型 | C4: 权益中枢 | D4: 列2 | E4: 组合/基金 | F4: 46240 | G4: 上线以来（截止8.6） | H4: 8月以来 | I4: 最大回撤 | J4: 年化波动率 | K4: 夏普比率 | L4: 卡玛比率 | N4: 最新净值日期
B5: 10/90配置样板间 | C5: 0.1 | E5: 10-90基石投顾账户 | F5: 0.0024122661 | G5: -0.01341017 | H5: 0.0093191778 | I5: -0.028644983 | J5: 0.054286232 | K5: -0.012125278 | L5: -0.056589243 | N5: 46245
B6: 招行长盈计划-安稳盈 | C6: ≤15% | D6: 016768.OF | E6: 华安盈瑞稳健优选6个月持有混合(FOF)A | F6: 0 | G6: -0.0061755262 | H6: 0.00054995416 | I6: -0.0090448692 | J6: 0.021162671 | K6: -0.069308314 | L6: -1.5088106 | N6: 2026-08-06
D7: 025218.OF | E7: 中欧盈欣稳健6个月持有混合(FOF)A | F7: -0.00029871552 | G7: 0.0025963651 | H7: 0.0017960487 | I7: -0.0081478537 | J7: 0.020977263 | K7: -0.042833024 | L7: -0.53139352 | N7: 2026-08-06
D8: 022978.OF | E8: 博时臻选楚汇三个月持有债券(FOF)B | F8: 0.00045833711 | G8: -0.0017600174 | H8: 0.0050649231 | I8: -0.013933642 | J8: 0.03091274 | K8: -0.072275485 | L8: -1.8905145 | N8: 2026-08-06
D9: 017587.OF | E9: 中欧盈选稳健6个月持有混合发起(FOF)A | F9: -0.00056996298 | G9: 0.0031428742 | H9: 0.0015230842 | I9: -0.0080059579 | J9: 0.020701304 | K9: -0.035805866 | L9: -0.21613371 | N9: 2026-08-06
D10: 026682.OF | E10: 博时盈泰臻选6个月持有期混合(FOF)A | F10: 0.00070056045 | G10: -0.00089928058 | H10: 0.0063405797 | I10: -0.012357983 | J10: 0.031887226 | K10: -0.039000674 | L10: -0.8325521 | N10: 2026-08-06
B11: 招行长盈计划-安定盈 | C11: ≤25% | D11: 025822.OF | E11: 易方达如意盈安6个月持有混合发起式(FOF)A | F11: 0.00049402233 | G11: -0.0085185548 | H11: 0.0067607874 | I11: -0.022235225 | J11: 0.058733756 | K11: -0.03411059 | L11: -1.0733788 | N11: 2026-08-06
D12: 018312.OF | E12: 易方达如意安诚六个月持有混合(FOF)A | F12: 0.00035984163 | G12: -0.0102284 | H12: 0.0065170167 | I12: -0.023234627 | J12: 0.057751632 | K12: -0.050196079 | L12: -1.6424457 | N12: 2026-08-06
B13: 注：1090基石投顾组合2026/06/18上线，FOF权益中枢数据取自招行银行官网。投顾数据均为扣费后数据。

Sheet vs固收+
G1: 日涨跌 | H1: 46241 | I1: 46191 | J1: 46191 | K1: 46234 | P1: 本周 | Q1: LTD | R1: 622-731 | S1: 8月以来
C2: 46203 | F2: 46241 | G2: 0.98977590 | H2: 46244 | I2: 46195 | J2: 46195 | K2: 46237 | L2: 46174 | P2: 0.98977590 | Q2: 1 | R2: 1 | S2: 0.97705802
G3: 0.99185254 | H3: 46244 | I3: 46244 | J3: 46234 | K3: 46244 | L3: 46244 | P3: 0.99185254 | Q3: 0.99185254 | R3: 0.97705802 | S3: 0.99185254
B5: 产品类型 | C5: 权益中枢 /股票仓位 | D5: 转债仓位 | E5: 基金代码 | F5: 46244 | G5: 日涨跌 | H5: 本周以来 | I5: 上线以来 | J5: 6.22-7.31 | K5: 8.3-8.10 | L5: 最大回撤 | M5: 年化波动率 | N5: 夏普比率 | O5: 卡玛比率 | Q5: 上线以来（截止8.10）
B6: 10/90配置样板间 | C6: 0.1 | D6: - | F6: 10-90基石投顾账户 | G6: 0.0020980911 | H6: 0.0020980911 | I6: -0.00814746 | J6: -0.02294198 | K6: 0.015141905 | L6: -0.028644983 | M6: 0.054286232 | N6: -0.012125278 | O6: -0.056589243
B7: 公募固收+关注池 | C7: 0.12115928 | D7: 0.049 | E7: 110017.OF | F7: 易方达增强回报债券A | G7: 0.0021321961 | H7: 0.0021321961 | I7: 0.01511879 | J7: 0.014398848 | K7: 0.0007097232 | L7: -0.010007148 | M7: 0.022428952 | N7: 0.11242864 | O7: 5.2599935
C8: 0.15757628 | D8: 0.0011 | E8: 001316.OF | F8: 安信稳健增值混合A | G8: 0.0025815665 | H8: 0.0025815665 | I8: 0.014675635 | J8: 0.013841792 | K8: 0.00082245859 | L8: -0.020400329 | M8: 0.034824288 | N8: 0.025806508 | O8: 1.218888
C9: 0.14024614 | D9: 0 | E9: 004010.OF | F9: 华泰柏瑞鼎利混合A | G9: 0.0027137042 | H9: 0.0027137042 | I9: 0.0055724746 | J9: -0.0011663319 | K9: 0.0067466753 | L9: -0.019559902 | M9: 0.034177386 | N9: -0.028082166 | O9: -0.28694169
C10: 0.17127469 | D10: 0.0587 | E10: 009089.OF | F10: 嘉实稳固收益债券A | G10: 0.0044584955 | H10: 0.0044584955 | I10: 0.010437903 | J10: -0.0075837886 | K10: 0.018159408 | L10: -0.022026787 | M10: 0.058374514 | N10: 0.045168293 | O10: 2.409111
C11: 0.14695484 | D11: 0.0552 | E11: 000385.OF | F11: 景顺长城景颐双利债券A类 | G11: 0.0015822785 | H11: 0.0015822785 | I11: -0.0041950708 | J11: -0.012060828 | K11: 0.0079617834 | L11: -0.024530271 | M11: 0.055741266 | N11: -0.0069407525 | O11: 0.11053751
C12: 0.19870188 | D12: 0.0177 | E12: 162210.OF | F12: 宏利集利债券A | G12: -0.0010168507 | H12: -0.0010168507 | I12: 0.0034289049 | J12: -0.015612461 | K12: 0.019343363 | L12: -0.039228342 | M12: 0.11131754 | N12: 0.047839559 | O12: 2.4251508
C13: 0.15196269 | D13: 0 | E13: 018595.OF | F13: 华商利欣回报债券A | G13: -0.0020390558 | H13: -0.0020390558 | I13: 0.0083201268 | J13: -0.015689382 | K13: 0.024392207 | L13: -0.04644491 | M13: 0.096696156 | N13: 0.067739604 | O13: 2.5593191
C14: 0.17988114 | D14: 0 | E14: 015931.OF | F14: 金鹰恒润债券发起式A | G14: 0.00087138379 | H14: 0.00087138379 | I14: -0.027845958 | J14: -0.036732967 | K14: 0.0092259029 | L14: -0.049761247 | M14: 0.079448626 | N14: -0.049135766 | O14: -1.0961032
C15: 0.17522979 | D15: 0 | E15: 014088.OF | F15: 永赢稳健增强债券A | G15: -0.00024618415 | H15: -0.00024618415 | I15: -0.024267179 | J15: -0.034358481 | K15: 0.010450361 | L15: -0.045758396 | M15: 0.088104619 | N15: -0.0578555 | O15: -1.6040167
C16: 0.1816567 | D16: 0.0546 | E16: 002961.OF | F16: 中欧双利债券A | G16: -0.0024114419 | H16: -0.0024114419 | I16: -0.02033317 | J16: -0.038134901 | K16: 0.018507513 | L16: -0.050748211 | M16: 0.091296033 | N16: -0.063810975 | O16: -1.6665537
C17: 0.16691488 | D17: 0.0212 | E17: 002969.OF | F17: 易方达丰和债券A | G17: -0.0047886987 | H17: -0.0047886987 | I17: -0.02834434 | J17: -0.047922389 | K17: 0.020563501 | L17: -0.070577399 | M17: 0.11837256 | N17: -0.010481109 | O17: -0.23423711
C18: 0.18988203 | D18: 0.0644 | E18: 000143.OF | F18: 鹏华双债加利债券A | G18: -0.00040814477 | H18: -0.00040814477 | I18: -0.026370423 | J18: -0.04523168 | K18: 0.0197548 | L18: -0.06090571 | M18: 0.10634192 | N18: -0.026461826 | O18: -0.65775196
C19: 0.18120795 | D19: 0 | E19: 470010.OF | F19: 汇添富多元收益债券A | G19: 0.001065956 | H19: 0.001065956 | I19: -0.03728857 | J19: -0.047475654 | K19: 0.010694827 | L19: -0.066198786 | M19: 0.1073132 | N19: -0.016423718 | O19: -0.35665756
... C21: 0.20399724 | D21: 0.0779 | E21: 003504.OF | F21: 景顺长城景颐丰利债券A类 | G21: -0.0034807035 | H21: -0.0034807035 | I21: -0.047065693 | J21: -0.06470073 | K21: 0.018854967 | L21: -0.078192169 | M21: 0.14797795 | N21: -0.044117187 | O21: -1.2934357
C22: 0.45369425 | D22: 0.0001 | E22: 501073.OF | F22: 华安智联混合(LOF)A | G22: -0.01014573 | I22: -0.12295182 | K22: 0.058957028 | L22: -0.22297994 | M22: 0.37666826 | N22: -0.012128071 | O22: -0.56715484
C23: 0.50088498 | D23: 0.0893 | E23: 014158.OF | F23: 博时浦惠一年持有期混合A | G23: 0.0013802622 | I23: -0.054038392 | K23: 0.08815932 | L23: -0.21116342 | M23: 0.33944886 | N23: -0.013304141 | O23: -0.53968069
C24: 0.40001187 | D24: 0.2066 | E24: 004657.OF | F24: 金鹰民富收益混合A | G24: -0.0041189931 | I24: -0.062634617 | K24: 0.058159891 | L24: -0.21978799 | M24: 0.42245758 | N24: 0.022308391 | O24: 0.34830662
C25: 0.39952505 | D25: 0.2009 | E25: 011351.OF | F25: 金鹰年年邮益一年持有混合A | G25: -0.0038020137 | I25: -0.061612946 | K25: 0.059056886 | L25: -0.21886724 | M25: 0.42075131 | N25: 0.022046578 | O25: 0.34149264
C26: 0.47537299 | D26: 0.1917 | E26: 012740.OF | F26: 工银平衡回报6个月持有期债券A | G26: 0.0032229965 | I26: 0.031527094 | K26: -0.015135967 | L26: -0.056528869 | M26: 0.095338523 | N26: -0.0015563089 | O26: 0.06330553
B27: 注：1090基石投顾组合2026/06/18上线，基金股票、转债仓位最新季报数据。投顾数据均为扣费后数据。

Sheet 1090实盘净值
B1: 1090账户基石投顾组合 | C1: 百灵全天候 | D1: 46244
A2: 日期 | B2: 投资组合(扣除投顾费,申赎费)
A3: 46191 | B3: 1 | C3: 1.22249400
A4: 46195 | B4: 1.0008957 | C4: 1.22478515
A5: 46196 | B5: 0.99782281 | C5: 1.22020249
A6: 46197 | B6: 0.9997708 | C6: 1.22109262
A7: 46198 | B7: 1.0012783 | C7: 1.22217105
A8: 46199 | B8: 0.99893009 | C8: 1.21873214
A9: 46202 | B9: 1.0005215 | C9: 1.22107212
A10: 46203 | B10: 1.0027107 | C10: 1.22189376
A11: 46204 | B11: 0.99998488 | C11: 1.22119814
A12: 46205 | B12: 0.99402933 | C12: 1.21840063
A13: 46206 | B13: 0.99491237 | C13: 1.22049236
A14: 46209 | B14: 0.99396984 | C14: 1.22071445
A15: 46210 | B15: 0.99336489 | C15: 1.21832166
A16: 46211 | B16: 0.99351509 | C16: 1.21705562
A17: 46212 | B17: 0.99860982 | C17: 1.21999960
A18: 46213 | B18: 0.99488466 | C18: 1.21804670
A19: 46216 | B19: 0.98970134 | C19: 1.21385354
A20: 46217 | B20: 0.99245271 | C20: 1.21643676
A21: 46218 | B21: 0.99005834 | C21: 1.21602034
A22: 46219 | B22: 0.98597556 | C22: 1.21303342
A23: 46220 | B23: 0.97886372 | C23: 1.20810291
A24: 46223 | B24: 0.9753755 | C24: 1.20951756
A25: 46224 | B25: 0.98437008 | C25: 1.21420067
A26: 46225 | B26: 0.98402324 | C26: 1.21548727
A27: 46226 | B27: 0.98279921 | C27: 1.21581151
A28: 46227 | B28: 0.98152946 | C28: 1.21280736
A29: 46230 | B29: 0.98516413 | C29: 1.21537245
A30: 46231 | B30: 0.97865577 | C30: 1.21157522
A31: 46232 | B31: 0.97811843 | C31: 1.21261346
A32: 46233 | B32: 0.97376326 | C32: 1.21208310
A33: 46234 | B33: 0.97705802 | C33: 1.21389655
A34: 46237 | B34: 0.97469599 | C34: 1.21256812
A35: 46238 | B35: 0.97954497 | C35: 1.21399454
A36: 46239 | B36: 0.98421564 | C36: 1.21716409
A37: 46240 | B37: 0.98658983 | C37: 1.21858475
A38: 46241 | B38: 0.98977590 | C38: 1.22070196
A39: 46244 | B39: 0.99185254 | C39: 1.22254650

Sheet 固收+基金对比
A1: 固收+基金对比（1090基石组合） | J1: 净值明细（辅助计算区）
A2: 日期参数（黄色蓝字单元格可编辑；三张表和最大回撤会随之更新） | J2: 代码 | K2: 产品/基金名称 | L2: 日期 | M2: 复权净值 | N2: 运行高点 | O2: 回撤
A3: 上线以来起始 | B3: 46191 | C3: 上线以来结束 | D3: 46244 | E3: 输入提示 | F3: 日期需存在于净值明细 | J3: 1090 | K3: 1090基石组合 | L3: ='1090实盘净值'!A3+0 -> 46191 | M3: ='1090实盘净值'!B3+0 -> 1 | N3: =IF(OR(L3<$B$3,L3>$D$3),"",M3) -> 1 | O3: =IF(N3="","",M3/N3-1) -> 0
A4: 区间1起始 | B4: 46191 | C4: 区间1结束 | D4: 46234 | E4: 基金净值覆盖 | F4: 2026-06-18 至 2026-08-10 | J4: 1090 | K4: 1090基石组合 | L4: ='1090实盘净值'!A4+0 -> 46195 | M4: ='1090实盘净值'!B4+0 -> 1.0008957 | N4: =IF(OR(L4<$B$3,L4>$D$3),"",IF(AND(J4=J3,N3<>""),MAX(M4,N3),M4)) -> 1.0008957 | O4: =IF(N4="","",M4/N4-1) -> 0
A5: 区间2起始 | B5: 46237 | C5: 区间2结束 | D5: 46244 | E5: 1090净值来源 | F5: “1090实盘净值”B列 | J5: 1090 | K5: 1090基石组合 | L5: ='1090实盘净值'!A5+0 -> 46196 | M5: ='1090实盘净值'!B5+0 -> 0.99782281 | N5: =IF(OR(L5<$B$3,L5>$D$3),"",IF(AND(J5=J4,N4<>""),MAX(M5,N4),M5)) -> 1.0008957 | O5: =IF(N5="","",M5/N5-1) -> -0.00307015
A6: 基金代码与复权单位净值来源：同花顺 iFinD（https://www.51ifind.com）；同名基金按 A 类/主份额匹配。 | J6: 1090 | K6: 1090基石组合 | L6: ='1090实盘净值'!A6+0 -> 46197 | M6: ='1090实盘净值'!B6+0 -> 0.9997708 | N6: =IF(OR(L6<$B$3,L6>$D$3),"",IF(AND(J6=J5,N5<>""),MAX(M6,N5),M6)) -> 1.0008957 | O6: =IF(N6="","",M6/N6-1) -> -0.0011239033
J7: 1090 | K7: 1090基石组合 | L7: ='1090实盘净值'!A7+0 -> 46198 | M7: ='1090实盘净值'!B7+0 -> 1.0012783 | N7: =IF(OR(L7<$B$3,L7>$D$3),"",IF(AND(J7=J6,N6<>""),MAX(M7,N6),M7)) -> 1.0012783 | O7: =IF(N7="","",M7/N7-1) -> 0
A8: 1090基石组合与全市场固收+保有前十基金对比 | J8: 1090 | K8: 1090基石组合 | L8: ='1090实盘净值'!A8+0 -> 46199 | M8: ='1090实盘净值'!B8+0 -> 0.99893009 | N8: =IF(OR(L8<$B$3,L8>$D$3),"",IF(AND(J8=J7,N7<>""),MAX(M8,N7),M8)) -> 1.0012783 | O8: =IF(N8="","",M8/N8-1) -> -0.0023451822
A9: 序号 | B9: 基金代码 | C9: 产品/基金名称 | D9: 上线以来收益率 | E9: 区间1收益率 | F9: 区间2收益率 | G9: 最大回撤（上线以来） | J9: 1090 | K9: 1090基石组合 | L9: ='1090实盘净值'!A9+0 -> 46202 | M9: ='1090实盘净值'!B9+0 -> 1.0005215 | N9: =IF(OR(L9<$B$3,L9>$D$3),"",IF(AND(J9=J8,N8<>""),MAX(M9,N8),M9)) -> 1.0012783 | O9: =IF(N9="","",M9/N9-1) -> -0.00075579389
A10: 组合 | B10: 1090 | C10: 1090基石组合 | D10: =IF(OR(COUNTIFS($J$3:$J$1281,$B10,$L$3:$L$1281,$B$3)=0,COUNTIFS($J$3:$J$1281,$B10,$L$3:$L$1281,$D$3)=0),"",SUMIFS($M$3:$M$1281,$J$3:$J$1281,$B10,$L$3:$L$1281,$D$3)/SUMIFS($M$3:$M$1281,$J$3:$J$1281,$B10,$L$3:$L$1281,$B$3)-1) -> -0.00814746 | E10: =IF(OR(COUNTIFS($J$3:$J$1281,$B10,$L$3:$L$1281,$B$4)=0,COUNTIFS($J$3:$J$1281,$B10,$L$3:$L$1281,$D$4)=0),"",SUMIFS($M$3:$M$1281,$J$3:$J$1281,$B10,$L$3:$L$1281,$D$4)/SUMIFS($M$3:$M$1281,$J$3:$J$1281,$B10,$L$3:$L$1281,$B$4)-1) -> -0.02294198 | F10: =IF(OR(COUNTIFS($J$3:$J$1281,$B10,$L$3:$L$1281,$B$5)=0,COUNTIFS($J$3:$J$1281,$B10,$L$3:$L$1281,$D$5)=0),"",SUMIFS($M$3:$M$1281,$J$3:$J$1281,$B10,$L$3:$L$1281,$D$5)/SUMIFS($M$3:$M$1281,$J$3:$J$1281,$B10,$L$3:$L$1281,$B$5)-1) -> 0.01760195 | G10: =IFERROR(MINIFS($O$3:$O$1281,$J$3:$J$1281,$B10,$L$3:$L$1281,">="&$B$3,$L$3:$L$1281,"<="&$D$3),"") -> -0.028869146 | J10: 1090 | K10: 1090基石组合 | L10: ='1090实盘净值'!A10+0 -> 46203 | M10: ='1090实盘净值'!B10+0 -> 1.0027107 | N10: =IF(OR(L10<$B$3,L10>$D$3),"",IF(AND(J10=J9,N9<>""),MAX(M10,N9),M10)) -> 1.0027107 | O10: =IF(N10="","",M10/N10-1) -> 0
A11: 1 | B11: 003504.OF | C11: 景顺长城景颐丰利债券A | D11: =IF(OR(COUNTIFS($J$3:$J$1281,$B11,$L$3:$L$1281,$B$3)=0,COUNTIFS($J$3:$J$1281,$B11,$L$3:$L$1281,$D$3)=0),"",SUMIFS($M$3:$M$1281,$J$3:$J$1281,$B11,$L$3:$L$1281,$D$3)/SUMIFS($M$3:$M$1281,$J$3:$J$1281,$B11,$L$3:$L$1281,$B$3)-1) -> -0.047103261 | E11: =IF(OR(COUNTIFS($J$3:$J$1281,$B11,$L$3:$L$1281,$B$4)=0,COUNTIFS($J$3:$J$1281,$B11,$L$3:$L$1281,$D$4)=0),"",SUMIFS($M$3:$M$1281,$J$3:$J$1281,$B11,$L$3:$L$1281,$D$4)/SUMIFS($M$3:$M$1281,$J$3:$J$1281,$B11,$L$3:$L$1281,$B$4)-1) -> -0.064711437 | F11: =IF(OR(COUNTIFS($J$3:$J$1281,$B11,$L$3:$L$1281,$B$5)=0,COUNTIFS($J$3:$J$1281,$B11,$L$3:$L$1281,$D$5)=0),"",SUMIFS($M$3:$M$1281,$J$3:$J$1281,$B11,$L$3:$L$1281,$D$5)/SUMIFS($M$3:$M$1281,$J$3:$J$1281,$B11,$L$3:$L$1281,$B$5)-1) -> 0.024179104 | G11: =IFERROR(MINIFS($O$3:$O$1281,$J$3:$J$1281,$B11,$L$3:$L$1281,">="&$B$3,$L$3:$L$1281,"<="&$D$3),"") -> -0.078194076 | J11: 1090 | K11: 1090基石组合 | L11: ='1090实盘净值'!A11+0 -> 46204 | M11: ='1090实盘净值'!B11+0 -> 0.99998488 | N11: =IF(OR(L11<$B$3,L11>$D$3),"",IF(AND(J11=J10,N10<>""),MAX(M11,N10),M11)) -> 1.0027107 | O11: =IF(N11="","",M11/N11-1) -> -0.0027184113
A12: 2 | B12: 000143.OF | C12: 鹏华双债加利债券A | D12: =IF(OR(COUNTIFS($J$3:$J$1281,$B12,$L$3:$L$1281,$B$3)=0,COUNTIFS($J$3:$J$1281,$B12,$L$3:$L$1281,$D$3)=0),"",SUMIFS($M$3:$M$1281,$J$3:$J$1281,$B12,$L$3:$L$1281,$D$3)/SUMIFS($M$3:$M$1281,$J$3:$J$1281,$B12,$L$3:$L$1281,$B$3)-1) -> -0.026357488 | E12: =IF(OR(COUNTIFS($J$3:$J$1281,$B12,$L$3:$L$1281,$B$4)=0,COUNTIFS($J$3:$J$1281,$B12,$L$3:$L$1281,$D$4)=0),"",SUMIFS($M$3:$M$1281,$J$3:$J$1281,$B12,$L$3:$L$1281,$D$4)/SUMIFS($M$3:$M$1281,$J$3:$J$1281,$B12,$L$3:$L$1281,$B$4)-1) -> -0.045217391 | F12: =IF(OR(COUNTIFS($J$3:$J$1281,$B12,$L$3:$L$1281,$B$5)=0,COUNTIFS($J$3:$J$1281,$B12,$L$3:$L$1281,$D$5)=0),"",SUMIFS($M$3:$M$1281,$J$3:$J$1281,$B12,$L$3:$L$1281,$D$5)/SUMIFS($M$3:$M$1281,$J$3:$J$1281,$B12,$L$3:$L$1281,$B$5)-1) -> 0.026191446 | G12: =IFERROR(MINIFS($O$3:$O$1281,$J$3:$J$1281,$B12,$L$3:$L$1281,">="&$B$3,$L$3:$L$1281,"<="&$D$3),"") -> -0.060906516 | J12: 1090 | K12: 1090基石组合 | L12: ='1090实盘净值'!A12+0 -> 46205 | M12: ='1090实盘净值'!B12+0 -> 0.99402933 | N12: =IF(OR(L12<$B$3,L12>$D$3),"",IF(AND(J12=J11,N11<>""),MAX(M12,N11),M12)) -> 1.0027107 | O12: =IF(N12="","",M12/N12-1) -> -0.0086578615
A13: 3 | B13: 000385.OF | C13: 景顺长城景颐双利债券A | D13: =IF(OR(COUNTIFS($J$3:$J$1281,$B13,$L$3:$L$1281,$B$3)=0,COUNTIFS($J$3:$J$1281,$B13,$L$3:$L$1281,$D$3)=0),"",SUMIFS($M$3:$M$1281,$J$3:$J$1281,$B13,$L$3:$L$1281,$D$3)/SUMIFS($M$3:$M$1281,$J$3:$J$1281,$B13,$L$3:$L$1281,$B$3)-1) -> -0.0041959876 | E13: =IF(OR(COUNTIFS($J$3:$J$1281,$B13,$L$3:$L$1281,$B$4)=0,COUNTIFS($J$3:$J$1281,$B13,$L$3:$L$1281,$D$4)=0),"",SUMIFS($M$3:$M$1281,$J$3:$J$1281,$B13,$L$3:$L$1281,$D$4)/SUMIFS($M$3:$M$1281,$J$3:$J$1281,$B13,$L$3:$L$1281,$B$4)-1) -> -0.012063464 | F13: =IF(OR(COUNTIFS($J$3:$J$1281,$B13,$L$3:$L$1281,$B$5)=0,COUNTIFS($J$3:$J$1281,$B13,$L$3:$L$1281,$D$5)=0),"",SUMIFS($M$3:$M$1281,$J$3:$J$1281,$B13,$L$3:$L$1281,$D$5)/SUMIFS($M$3:$M$1281,$J$3:$J$1281,$B13,$L$3:$L$1281,$B$5)-1) -> 0.010108623 | G13: =IFERROR(MINIFS($O$3:$O$1281,$J$3:$J$1281,$B13,$L$3:$L$1281,">="&$B$3,$L$3:$L$1281,"<="&$D$3),"") -> -0.024535607 | J13: 1090 | K13: 1090基石组合 | L13: ='1090实盘净值'!A13+0 -> 46206 | M13: ='1090实盘净值'!B13+0 -> 0.99491237 | N13: =IF(OR(L13<$B$3,L13>$D$3),"",IF(AND(J13=J12,N12<>""),MAX(M13,N12),M13)) -> 1.0027107 | O13: =IF(N13="","",M13/N13-1) -> -0.0077772086
A14: 4 | B14: 002065.OF | C14: 景顺长城景盛双息收益债券A | D14: =IF(OR(COUNTIFS($J$3:$J$1281,$B14,$L$3:$L$1281,$B$3)=0,COUNTIFS($J$3:$J$1281,$B14,$L$3:$L$1281,$D$3)=0),"",SUMIFS($M$3:$M$1281,$J$3:$J$1281,$B14,$L$3:$L$1281,$D$3)/SUMIFS($M$3:$M$1281,$J$3:$J$1281,$B14,$L$3:$L$1281,$B$3)-1) -> 0.032769849 | E14: =IF(OR(COUNTIFS($J$3:$J$1281,$B14,$L$3:$L$1281,$B$4)=0,COUNTIFS($J$3:$J$1281,$B14,$L$3:$L$1281,$D$4)=0),"",SUMIFS($M$3:$M$1281,$J$3:$J$1281,$B14,$L$3:$L$1281,$D$4)/SUMIFS($M$3:$M$1281,$J$3:$J$1281,$B14,$L$3:$L$1281,$B$4)-1) -> 0.018359429 | F14: =IF(OR(COUNTIFS($J$3:$J$1281,$B14,$L$3:$L$1281,$B$5)=0,COUNTIFS($J$3:$J$1281,$B14,$L$3:$L$1281,$D$5)=0),"",SUMIFS($M$3:$M$1281,$J$3:$J$1281,$B14,$L$3:$L$1281,$D$5)/SUMIFS($M$3:$M$1281,$J$3:$J$1281,$B14,$L$3:$L$1281,$B$5)-1) -> 0.015739984 | G14: =IFERROR(MINIFS($O$3:$O$1281,$J$3:$J$1281,$B14,$L$3:$L$1281,">="&$B$3,$L$3:$L$1281,"<="&$D$3),"") -> -0.01985796 | J14: 1090 | K14: 1090基石组合 | L14: ='1090实盘净值'!A14+0 -> 46209 | M14: ='1090实盘净值'!B14+0 -> 0.99396984 | N14: =IF(OR(L14<$B$3,L14>$D$3),"",IF(AND(J14=J13,N13<>""),MAX(M14,N13),M14)) -> 1.0027107 | O14: =IF(N14="","",M14/N14-1) -> -0.0087171907
A15: 5 | B15: 002969.OF | C15: 易方达丰和债券A | D15: =IF(OR(COUNTIFS($J$3:$J$1281,$B15,$L$3:$L$1281,$B$3)=0,COUNTIFS($J$3:$J$1281,$B15,$L$3:$L$1281,$D$3)=0),"",SUMIFS($M$3:$M$1281,$J$3:$J$1281,$B15,$L$3:$L$1281,$D$3)/SUMIFS($M$3:$M$1281,$J$3:$J$1281,$B15,$L$3:$L$1281,$B$3)-1) -> -0.02833045 | E15: =IF(OR(COUNTIFS($J$3:$J$1281,$B15,$L$3:$L$1281,$B$4)=0,COUNTIFS($J$3:$J$1281,$B15,$L$3:$L$1281,$D$4)=0),"",SUMIFS($M$3:$M$1281,$J$3:$J$1281,$B15,$L$3:$L$1281,$D$4)/SUMIFS($M$3:$M$1281,$J$3:$J$1281,$B15,$L$3:$L$1281,$B$4)-1) -> -0.047902249 | F15: =IF(OR(COUNTIFS($J$3:$J$1281,$B15,$L$3:$L$1281,$B$5)=0,COUNTIFS($J$3:$J$1281,$B15,$L$3:$L$1281,$D$5)=0),"",SUMIFS($M$3:$M$1281,$J$3:$J$1281,$B15,$L$3:$L$1281,$D$5)/SUMIFS($M$3:$M$1281,$J$3:$J$1281,$B15,$L$3:$L$1281,$B$5)-1) -> 0.024045584 | G15: =IFERROR(MINIFS($O$3:$O$1281,$J$3:$J$1281,$B15,$L$3:$L$1281,">="&$B$3,$L$3:$L$1281,"<="&$D$3),"") -> -0.070565053 | J15: 1090 | K15: 1090基石组合 | L15: ='1090实盘净值'!A15+0 -> 46210 | M15: ='1090实盘净值'!B15+0 -> 0.99336489 | N15: =IF(OR(L15<$B$3,L15>$D$3),"",IF(AND(J15=J14,N14<>""),MAX(M15,N14),M15)) -> 1.0027107 | O15: =IF(N15="","",M15/N15-1) -> -0.0093205053
A16: 6 | B16: 014088.OF | C16: 永赢稳健增强债券A | D16: =IF(OR(COUNTIFS($J$3:$J$1281,$B16,$L$3:$L$1281,$B$3)=0,COUNTIFS($J$3:$J$1281,$B16,$L$3:$L$1281,$D$3)=0),"",SUMIFS($M$3:$M$1281,$J$3:$J$1281,$B16,$L$3:$L$1281,$D$3)/SUMIFS($M$3:$M$1281,$J$3:$J$1281,$B16,$L$3:$L$1281,$B$3)-1) -> -0.024267179 | E16: =IF(OR(COUNTIFS($J$3:$J$1281,$B16,$L$3:$L$1281,$B$4)=0,COUNTIFS($J$3:$J$1281,$B16,$L$3:$L$1281,$D$4)=0),"",SUMIFS($M$3:$M$1281,$J$3:$J$1281,$B16,$L$3:$L$1281,$D$4)/SUMIFS($M$3:$M$1281,$J$3:$J$1281,$B16,$L$3:$L$1281,$B$4)-1) -> -0.034358481 | F16: =IF(OR(COUNTIFS($J$3:$J$1281,$B16,$L$3:$L$1281,$B$5)=0,COUNTIFS($J$3:$J$1281,$B16,$L$3:$L$1281,$D$5)=0),"",SUMIFS($M$3:$M$1281,$J$3:$J$1281,$B16,$L$3:$L$1281,$D$5)/SUMIFS($M$3:$M$1281,$J$3:$J$1281,$B16,$L$3:$L$1281,$B$5)-1) -> 0.016012009 | G16: =IFERROR(MINIFS($O$3:$O$1281,$J$3:$J$1281,$B16,$L$3:$L$1281,">="&$B$3,$L$3:$L$1281,"<="&$D$3),"") -> -0.045758396 | J16: 1090 | K16: 1090基石组合 | L16: ='1090实盘净值'!A16+0 -> 46211 | M16: ='1090实盘净值'!B16+0 -> 0.99351509 | N16: =IF(OR(L16<$B$3,L16>$D$3),"",IF(AND(J16=J15,N15<>""),MAX(M16,N15),M16)) -> 1.0027107 | O16: =IF(N16="","",M16/N16-1) -> -0.0091707113
A17: 7 | B17: 001751.OF | C17: 华商信用增强债券A | D17: =IF(OR(COUNTIFS($J$3:$J$1281,$B17,$L$3:$L$1281,$B$3)=0,COUNTIFS($J$3:$J$1281,$B17,$L$3:$L$1281,$D$3)=0),"",SUMIFS($M$3:$M$1281,$J$3:$J$1281,$B17,$L$3:$L$1281,$D$3)/SUMIFS($M$3:$M$1281,$J$3:$J$1281,$B17,$L$3:$L$1281,$B$3)-1) -> 0.0048685492 | E17: =IF(OR(COUNTIFS($J$3:$J$1281,$B17,$L$3:$L$1281,$B$4)=0,COUNTIFS($J$3:$J$1281,$B17,$L$3:$L$1281,$D$4)=0),"",SUMIFS($M$3:$M$1281,$J$3:$J$1281,$B17,$L$3:$L$1281,$D$4)/SUMIFS($M$3:$M$1281,$J$3:$J$1281,$B17,$L$3:$L$1281,$B$4)-1) -> -0.020447907 | F17: =IF(OR(COUNTIFS($J$3:$J$1281,$B17,$L$3:$L$1281,$B$5)=0,COUNTIFS($J$3:$J$1281,$B17,$L$3:$L$1281,$D$5)=0),"",SUMIFS($M$3:$M$1281,$J$3:$J$1281,$B17,$L$3:$L$1281,$D$5)/SUMIFS($M$3:$M$1281,$J$3:$J$1281,$B17,$L$3:$L$1281,$B$5)-1) -> 0.037707391 | G17: =IFERROR(MINIFS($O$3:$O$1281,$J$3:$J$1281,$B17,$L$3:$L$1281,">="&$B$3,$L$3:$L$1281,"<="&$D$3),"") -> -0.052405908 | J17: 1090 | K17: 1090基石组合 | L17: ='1090实盘净值'!A17+0 -> 46212 | M17: ='1090实盘净值'!B17+0 -> 0.99860982 | N17: =IF(OR(L17<$B$3,L17>$D$3),"",IF(AND(J17=J16,N16<>""),MAX(M17,N16),M17)) -> 1.0027107 | O17: =IF(N17="","",M17/N17-1) -> -0.0040897541
A18: 8 | B18: 014846.OF | C18: 博时恒乐债券A | D18: =IF(OR(COUNTIFS($J$3:$J$1281,$B18,$L$3:$L$1281,$B$3)=0,COUNTIFS($J$3:$J$1281,$B18,$L$3:$L$1281,$D$3)=0),"",SUMIFS($M$3:$M$1281,$J$3:$J$1281,$B18,$L$3:$L$1281,$D$3)/SUMIFS($M$3:$M$1281,$J$3:$J$1281,$B18,$L$3:$L$1281,$B$3)-1) -> -0.011699605 | E18: =IF(OR(COUNTIFS($J$3:$J$1281,$B18,$L$3:$L$1281,$B$4)=0,COUNTIFS($J$3:$J$1281,$B18,$L$3:$L$1281,$D$4)=0),"",SUMIFS($M$3:$M$1281,$J$3:$J$1281,$B18,$L$3:$L$1281,$D$4)/SUMIFS($M$3:$M$1281,$J$3:$J$1281,$B18,$L$3:$L$1281,$B$4)-1) -> -0.015573123 | F18: =IF(OR(COUNTIFS($J$3:$J$1281,$B18,$L$3:$L$1281,$B$5)=0,COUNTIFS($J$3:$J$1281,$B18,$L$3:$L$1281,$D$5)=0),"",SUMIFS($M$3:$M$1281,$J$3:$J$1281,$B18,$L$3:$L$1281,$D$5)/SUMIFS($M$3:$M$1281,$J$3:$J$1281,$B18,$L$3:$L$1281,$B$5)-1) -> 0.0046608807 | G18: =IFERROR(MINIFS($O$3:$O$1281,$J$3:$J$1281,$B18,$L$3:$L$1281,">="&$B$3,$L$3:$L$1281,"<="&$D$3),"") -> -0.03092382 | J18: 1090 | K18: 1090基石组合 | L18: ='1090实盘净值'!A18+0 -> 46213 | M18: ='1090实盘净值'!B18+0 -> 0.99488466 | N18: =IF(OR(L18<$B$3,L18>$D$3),"",IF(AND(J18=J17,N17<>""),MAX(M18,N17),M18)) -> 1.0027107 | O18: =IF(N18="","",M18/N18-1) -> -0.0078048437
A19: 9 | B19: 000171.OF | C19: 易方达裕丰回报债券A | D19: =IF(OR(COUNTIFS($J$3:$J$1281,$B19,$L$3:$L$1281,$B$3)=0,COUNTIFS($J$3:$J$1281,$B19,$L$3:$L$1281,$D$3)=0),"",SUMIFS($M$3:$M$1281,$J$3:$J$1281,$B19,$L$3:$L$1281,$D$3)/SUMIFS($M$3:$M$1281,$J$3:$J$1281,$B19,$L$3:$L$1281,$B$3)-1) -> -0.035719493 | E19: =IF(OR(COUNTIFS($J$3:$J$1281,$B19,$L$3:$L$1281,$B$4)=0,COUNTIFS($J$3:$J$1281,$B19,$L$3:$L$1281,$D$4)=0),"",SUMIFS($M$3:$M$1281,$J$3:$J$1281,$B19,$L$3:$L$1281,$D$4)/SUMIFS($M$3:$M$1281,$J$3:$J$1281,$B19,$L$3:$L$1281,$B$4)-1) -> -0.043154979 | F19: =IF(OR(COUNTIFS($J$3:$J$1281,$B19,$L$3:$L$1281,$B$5)=0,COUNTIFS($J$3:$J$1281,$B19,$L$3:$L$1281,$D$5)=0),"",SUMIFS($M$3:$M$1281,$J$3:$J$1281,$B19,$L$3:$L$1281,$D$5)/SUMIFS($M$3:$M$1281,$J$3:$J$1281,$B19,$L$3:$L$1281,$B$5)-1) -> 0.012166195 | G19: =IFERROR(MINIFS($O$3:$O$1281,$J$3:$J$1281,$B19,$L$3:$L$1281,">="&$B$3,$L$3:$L$1281,"<="&$D$3),"") -> -0.063481816 | J19: 1090 | K19: 1090基石组合 | L19: ='1090实盘净值'!A19+0 -> 46216 | M19: ='1090实盘净值'!B19+0 -> 0.98970134 | N19: =IF(OR(L19<$B$3,L19>$D$3),"",IF(AND(J19=J18,N18<>""),MAX(M19,N18),M19)) -> 1.0027107 | O19: =IF(N19="","",M19/N19-1) -> -0.012974151
A20: 10 | B20: 202101.OF | C20: 南方宝元债券A | D20: =IF(OR(COUNTIFS($J$3:$J$1281,$B20,$L$3:$L$1281,$B$3)=0,COUNTIFS($J$3:$J$1281,$B20,$L$3:$L$1281,$D$3)=0),"",SUMIFS($M$3:$M$1281,$J$3:$J$1281,$B20,$L$3:$L$1281,$D$3)/SUMIFS($M$3:$M$1281,$J$3:$J$1281,$B20,$L$3:$L$1281,$B$3)-1) -> 0.0049992807 | E20: =IF(OR(COUNTIFS($J$3:$J$1281,$B20,$L$3:$L$1281,$B$4)=0,COUNTIFS($J$3:$J$1281,$B20,$L$3:$L$1281,$D$4)=0),"",SUMIFS($M$3:$M$1281,$J$3:$J$1281,$B20,$L$3:$L$1281,$D$4)/SUMIFS($M$3:$M$1281,$J$3:$J$1281,$B20,$L$3:$L$1281,$B$4)-1) -> -0.0003476718 | F20: =IF(OR(COUNTIFS($J$3:$J$1281,$B20,$L$3:$L$1281,$B$5)=0,COUNTIFS($J$3:$J$1281,$B20,$L$3:$L$1281,$D$5)=0),"",SUMIFS($M$3:$M$1281,$J$3:$J$1281,$B20,$L$3:$L$1281,$D$5)/SUMIFS($M$3:$M$1281,$J$3:$J$1281,$B20,$L$3:$L$1281,$B$5)-1) -> 0.0070154364 | G20: =IFERROR(MINIFS($O$3:$O$1281,$J$3:$J$1281,$B20,$L$3:$L$1281,">="&$B$3,$L$3:$L$1281,"<="&$D$3),"") -> -0.026377046 | J20: 1090 | K20: 1090基石组合 | L20: ='1090实盘净值'!A20+0 -> 46217 | M20: ='1090实盘净值'!B20+0 -> 0.99245271 | N20: =IF(OR(L20<$B$3,L20>$D$3),"",IF(AND(J20=J19,N19<>""),MAX(M20,N19),M20)) -> 1.0027107 | O20: =IF(N20="","",M20/N20-1) -> -0.010230219
J21: 1090 | K21: 1090基石组合 | L21: ='1090实盘净值'!A21+0 -> 46218 | M21: ='1090实盘净值'!B21+0 -> 0.99005834 | N21: =IF(OR(L21<$B$3,L21>$D$3),"",IF(AND(J21=J20,N20<>""),MAX(M21,N20),M21)) -> 1.0027107 | O21: =IF(N21="","",M21/N21-1) -> -0.012618117
J22: 1090 | K22: 1090基石组合 | L22: ='1090实盘净值'!A22+0 -> 46219 | M22: ='1090实盘净值'!B22+0 -> 0.98597556 | N22: =IF(OR(L22<$B$3,L22>$D$3),"",IF(AND(J22=J21,N21<>""),MAX(M22,N21),M22)) -> 1.0027107 | O22: =IF(N22="","",M22/N22-1) -> -0.016689859
A23: 1090基石组合与二季度固收+增长排名前十基金对比 | J23: 1090 | K23: 1090基石组合 | L23: ='1090实盘净值'!A23+0 -> 46220 | M23: ='1090实盘净值'!B23+0 -> 0.97886372 | N23: =IF(OR(L23<$B$3,L23>$D$3),"",IF(AND(J23=J22,N22<>""),MAX(M23,N22),M23)) -> 1.0027107 | O23: =IF(N23="","",M23/N23-1) -> -0.023782474
A24: 序号 | B24: 基金代码 | C24: 产品/基金名称 | D24: 上线以来收益率 | E24: 区间1收益率 | F24: 区间2收益率 | G24: 最大回撤（上线以来） | J24: 1090 | K24: 1090基石组合 | L24: ='1090实盘净值'!A24+0 -> 46223 | M24: ='1090实盘净值'!B24+0 -> 0.9753755 | N24: =IF(OR(L24<$B$3,L24>$D$3),"",IF(AND(J24=J23,N23<>""),MAX(M24,N23),M24)) -> 1.0027107 | O24: =IF(N24="","",M24/N24-1) -> -0.027261264
A25: 组合 | B25: 1090 | C25: 1090基石组合 | D25: =IF(OR(COUNTIFS($J$3:$J$1281,$B25,$L$3:$L$1281,$B$3)=0,COUNTIFS($J$3:$J$1281,$B25,$L$3:$L$1281,$D$3)=0),"",SUMIFS($M$3:$M$1281,$J$3:$J$1281,$B25,$L$3:$L$1281,$D$3)/SUMIFS($M$3:$M$1281,$J$3:$J$1281,$B25,$L$3:$L$1281,$B$3)-1) -> -0.00814746 | E25: =IF(OR(COUNTIFS($J$3:$J$1281,$B25,$L$3:$L$1281,$B$4)=0,COUNTIFS($J$3:$J$1281,$B25,$L$3:$L$1281,$D$4)=0),"",SUMIFS($M$3:$M$1281,$J$3:$J$1281,$B25,$L$3:$L$1281,$D$4)/SUMIFS($M$3:$M$1281,$J$3:$J$1281,$B25,$L$3:$L$1281,$B$4)-1) -> -0.02294198 | F25: =IF(OR(COUNTIFS($J$3:$J$1281,$B25,$L$3:$L$1281,$B$5)=0,COUNTIFS($J$3:$J$1281,$B25,$L$3:$L$1281,$D$5)=0),"",SUMIFS($M$3:$M$1281,$J$3:$J$1281,$B25,$L$3:$L$1281,$D$5)/SUMIFS($M$3:$M$1281,$J$3:$J$1281,$B25,$L$3:$L$1281,$B$5)-1) -> 0.01760195 | G25: =IFERROR(MINIFS($O$3:$O$1281,$J$3:$J$1281,$B25,$L$3:$L$1281,">="&$B$3,$L$3:$L$1281,"<="&$D$3),"") -> -0.028869146 | J25: 1090 | K25: 1090基石组合 | L25: ='1090实盘净值'!A25+0 -> 46224 | M25: ='1090实盘净值'!B25+0 -> 0.98437008 | N25: =IF(OR(L25<$B$3,L25>$D$3),"",IF(AND(J25=J24,N24<>""),MAX(M25,N24),M25)) -> 1.0027107 | O25: =IF(N25="","",M25/N25-1) -> -0.018290999
A26: 1 | B26: 003504.OF | C26: 景顺长城景颐丰利债券A | D26: =IF(OR(COUNTIFS($J$3:$J$1281,$B26,$L$3:$L$1281,$B$3)=0,COUNTIFS($J$3:$J$1281,$B26,$L$3:$L$1281,$D$3)=0),"",SUMIFS($M$3:$M$1281,$J$3:$J$1281,$B26,$L$3:$L$1281,$D$3)/SUMIFS($M$3:$M$1281,$J$3:$J$1281,$B26,$L$3:$L$1281,$B$3)-1) -> -0.047103261 | E26: =IF(OR(COUNTIFS($J$3:$J$1281,$B26,$L$3:$L$1281,$B$4)=0,COUNTIFS($J$3:$J$1281,$B26,$L$3:$L$1281,$D$4)=0),"",SUMIFS($M$3:$M$1281,$J$3:$J$1281,$B26,$L$3:$L$1281,$D$4)/SUMIFS($M$3:$M$1281,$J$3:$J$1281,$B26,$L$3:$L$1281,$B$4)-1) -> -0.064711437 | F26: =IF(OR(COUNTIFS($J$3:$J$1281,$B26,$L$3:$L$1281,$B$5)=0,COUNTIFS($J$3:$J$1281,$B26,$L$3:$L$1281,$D$5)=0),"",SUMIFS($M$3:$M$1281,$J$3:$J$1281,$B26,$L$3:$L$1281,$D$5)/SUMIFS($M$3:$M$1281,$J$3:$J$1281,$B26,$L$3:$L$1281,$B$5)-1) -> 0.024179104 | G26: =IFERROR(MINIFS($O$3:$O$1281,$J$3:$J$1281,$B26,$L$3:$L$1281,">="&$B$3,$L$3:$L$1281,"<="&$D$3),"") -> -0.078194076 | J26: 1090 | K26: 1090基石组合 | L26: ='1090实盘净值'!A26+0 -> 46225 | M26: ='1090实盘净值'!B26+0 -> 0.98402324 | N26: =IF(OR(L26<$B$3,L26>$D$3),"",IF(AND(J26=J25,N25<>""),MAX(M26,N25),M26)) -> 1.0027107 | O26: =IF(N26="","",M26/N26-1) -> -0.018636902
A27: 2 | B27: 002969.OF | C27: 易方达丰和债券A | D27: =IF(OR(COUNTIFS($J$3:$J$1281,$B27,$L$3:$L$1281,$B$3)=0,COUNTIFS($J$3:$J$1281,$B27,$L$3:$L$1281,$D$3)=0),"",SUMIFS($M$3:$M$1281,$J$3:$J$1281,$B27,$L$3:$L$1281,$D$3)/SUMIFS($M$3:$M$1281,$J$3:$J$1281,$B27,$L$3:$L$1281,$B$3)-1) -> -0.02833045 | E27: =IF(OR(COUNTIFS($J$3:$J$1281,$B27,$L$3:$L$1281,$B$4)=0,COUNTIFS($J$3:$J$1281,$B27,$L$3:$L$1281,$D$4)=0),"",SUMIFS($M$3:$M$1281,$J$3:$J$1281,$B27,$L$3:$L$1281,$D$4)/SUMIFS($M$3:$M$1281,$J$3:$J$1281,$B27,$L$3:$L$1281,$B$4)-1) -> -0.047902249 | F27: =IF(OR(COUNTIFS($J$3:$J$1281,$B27,$L$3:$L$1281,$B$5)=0,COUNTIFS($J$3:$J$1281,$B27,$L$3:$L$1281,$D$5)=0),"",SUMIFS($M$3:$M$1281,$J$3:$J$1281,$B27,$L$3:$L$1281,$D$5)/SUMIFS($M$3:$M$1281,$J$3:$J$1281,$B27,$L$3:$L$1281,$B$5)-1) -> 0.024045584 | G27: =IFERROR(MINIFS($O$3:$O$1281,$J$3:$J$1281,$B27,$L$3:$L$1281,">="&$B$3,$L$3:$L$1281,"<="&$D$3),"") -> -0.070565053 | J27: 1090 | K27: 1090基石组合 | L27: ='1090实盘净值'!A27+0 -> 46226 | M27: ='1090实盘净值'!B27+0 -> 0.98279921 | N27: =IF(OR(L27<$B$3,L27>$D$3),"",IF(AND(J27=J26,N26<>""),MAX(M27,N26),M27)) -> 1.0027107 | O27: =IF(N27="","",M27/N27-1) -> -0.019857623
A28: 3 | B28: 470010.OF | C28: 汇添富多元收益债券A | D28: =IF(OR(COUNTIFS($J$3:$J$1281,$B28,$L$3:$L$1281,$B$3)=0,COUNTIFS($J$3:$J$1281,$B28,$L$3:$L$1281,$D$3)=0),"",SUMIFS($M$3:$M$1281,$J$3:$J$1281,$B28,$L$3:$L$1281,$D$3)/SUMIFS($M$3:$M$1281,$J$3:$J$1281,$B28,$L$3:$L$1281,$B$3)-1) -> -0.037305375 | E28: =IF(OR(COUNTIFS($J$3:$J$1281,$B28,$L$3:$L$1281,$B$4)=0,COUNTIFS($J$3:$J$1281,$B28,$L$3:$L$1281,$D$4)=0),"",SUMIFS($M$3:$M$1281,$J$3:$J$1281,$B28,$L$3:$L$1281,$D$4)/SUMIFS($M$3:$M$1281,$J$3:$J$1281,$B28,$L$3:$L$1281,$B$4)-1) -> -0.047476401 | F28: =IF(OR(COUNTIFS($J$3:$J$1281,$B28,$L$3:$L$1281,$B$5)=0,COUNTIFS($J$3:$J$1281,$B28,$L$3:$L$1281,$D$5)=0),"",SUMIFS($M$3:$M$1281,$J$3:$J$1281,$B28,$L$3:$L$1281,$D$5)/SUMIFS($M$3:$M$1281,$J$3:$J$1281,$B28,$L$3:$L$1281,$B$5)-1) -> 0.016102941 | G28: =IFERROR(MINIFS($O$3:$O$1281,$J$3:$J$1281,$B28,$L$3:$L$1281,">="&$B$3,$L$3:$L$1281,"<="&$D$3),"") -> -0.066206043 | J28: 1090 | K28: 1090基石组合 | L28: ='1090实盘净值'!A28+0 -> 46227 | M28: ='1090实盘净值'!B28+0 -> 0.98152946 | N28: =IF(OR(L28<$B$3,L28>$D$3),"",IF(AND(J28=J27,N27<>""),MAX(M28,N27),M28)) -> 1.0027107 | O28: =IF(N28="","",M28/N28-1) -> -0.02112394
A29: 4 | B29: 000143.OF | C29: 鹏华双债加利债券A | D29: =IF(OR(COUNTIFS($J$3:$J$1281,$B29,$L$3:$L$1281,$B$3)=0,COUNTIFS($J$3:$J$1281,$B29,$L$3:$L$1281,$D$3)=0),"",SUMIFS($M$3:$M$1281,$J$3:$J$1281,$B29,$L$3:$L$1281,$D$3)/SUMIFS($M$3:$M$1281,$J$3:$J$1281,$B29,$L$3:$L$1281,$B$3)-1) -> -0.026357488 | E29: =IF(OR(COUNTIFS($J$3:$J$1281,$B29,$L$3:$L$1281,$B$4)=0,COUNTIFS($J$3:$J$1281,$B29,$L$3:$L$1281,$D$4)=0),"",SUMIFS($M$3:$M$1281,$J$3:$J$1281,$B29,$L$3:$L$1281,$D$4)/SUMIFS($M$3:$M$1281,$J$3:$J$1281,$B29,$L$3:$L$1281,$B$4)-1) -> -0.045217391 | F29: =IF(OR(COUNTIFS($J$3:$J$1281,$B29,$L$3:$L$1281,$B$5)=0,COUNTIFS($J$3:$J$1281,$B29,$L$3:$L$1281,$D$5)=0),"",SUMIFS($M$3:$M$1281,$J$3:$J$1281,$B29,$L$3:$L$1281,$D$5)/SUMIFS($M$3:$M$1281,$J$3:$J$1281,$B29,$L$3:$L$1281,$B$5)-1) -> 0.026191446 | G29: =IFERROR(MINIFS($O$3:$O$1281,$J$3:$J$1281,$B29,$L$3:$L$1281,">="&$B$3,$L$3:$L$1281,"<="&$D$3),"") -> -0.060906516 | J29: 1090 | K29: 1090基石组合 | L29: ='1090实盘净值'!A29+0 -> 46230 | M29: ='1090实盘净值'!B29+0 -> 0.98516413 | N29: =IF(OR(L29<$B$3,L29>$D$3),"",IF(AND(J29=J28,N28<>""),MAX(M29,N28),M29)) -> 1.0027107 | O29: =IF(N29="","",M29/N29-1) -> -0.017499096
A30: 5 | B30: 000406.OF | C30: 汇添富双利增强债券A | D30: =IF(OR(COUNTIFS($J$3:$J$1281,$B30,$L$3:$L$1281,$B$3)=0,COUNTIFS($J$3:$J$1281,$B30,$L$3:$L$1281,$D$3)=0),"",SUMIFS($M$3:$M$1281,$J$3:$J$1281,$B30,$L$3:$L$1281,$D$3)/SUMIFS($M$3:$M$1281,$J$3:$J$1281,$B30,$L$3:$L$1281,$B$3)-1) -> -0.023269343 | E30: =IF(OR(COUNTIFS($J$3:$J$1281,$B30,$L$3:$L$1281,$B$4)=0,COUNTIFS($J$3:$J$1281,$B30,$L$3:$L$1281,$D$4)=0),"",SUMIFS($M$3:$M$1281,$J$3:$J$1281,$B30,$L$3:$L$1281,$D$4)/SUMIFS($M$3:$M$1281,$J$3:$J$1281,$B30,$L$3:$L$1281,$B$4)-1) -> -0.038927671 | F30: =IF(OR(COUNTIFS($J$3:$J$1281,$B30,$L$3:$L$1281,$B$5)=0,COUNTIFS($J$3:$J$1281,$B30,$L$3:$L$1281,$D$5)=0),"",SUMIFS($M$3:$M$1281,$J$3:$J$1281,$B30,$L$3:$L$1281,$D$5)/SUMIFS($M$3:$M$1281,$J$3:$J$1281,$B30,$L$3:$L$1281,$B$5)-1) -> 0.015421832 | G30: =IFERROR(MINIFS($O$3:$O$1281,$J$3:$J$1281,$B30,$L$3:$L$1281,">="&$B$3,$L$3:$L$1281,"<="&$D$3),"") -> -0.050932395 | J30: 1090 | K30: 1090基石组合 | L30: ='1090实盘净值'!A30+0 -> 46231 | M30: ='1090实盘净值'!B30+0 -> 0.97865577 | N30: =IF(OR(L30<$B$3,L30>$D$3),"",IF(AND(J30=J29,N29<>""),MAX(M30,N29),M30)) -> 1.0027107 | O30: =IF(N30="","",M30/N30-1) -> -0.023989862
A31: 6 | B31: 000171.OF | C31: 易方达裕丰回报债券A | D31: =IF(OR(COUNTIFS($J$3:$J$1281,$B31,$L$3:$L$1281,$B$3)=0,COUNTIFS($J$3:$J$1281,$B31,$L$3:$L$1281,$D$3)=0),"",SUMIFS($M$3:$M$1281,$J$3:$J$1281,$B31,$L$3:$L$1281,$D$3)/SUMIFS($M$3:$M$1281,$J$3:$J$1281,$B31,$L$3:$L$1281,$B$3)-1) -> -0.035719493 | E31: =IF(OR(COUNTIFS($J$3:$J$1281,$B31,$L$3:$L$1281,$B$4)=0,COUNTIFS($J$3:$J$1281,$B31,$L$3:$L$1281,$D$4)=0),"",SUMIFS($M$3:$M$1281,$J$3:$J$1281,$B31,$L$3:$L$1281,$D$4)/SUMIFS($M$3:$M$1281,$J$3:$J$1281,$B31,$L$3:$L$1281,$B$4)-1) -> -0.043154979 | F31: =IF(OR(COUNTIFS($J$3:$J$1281,$B31,$L$3:$L$1281,$B$5)=0,COUNTIFS($J$3:$J$1281,$B31,$L$3:$L$1281,$D$5)=0),"",SUMIFS($M$3:$M$1281,$J$3:$J$1281,$B31,$L$3:$L$1281,$D$5)/SUMIFS($M$3:$M$1281,$J$3:$J$1281,$B31,$L$3:$L$1281,$B$5)-1) -> 0.012166195 | G31: =IFERROR(MINIFS($O$3:$O$1281,$J$3:$J$1281,$B31,$L$3:$L$1281,">="&$B$3,$L$3:$L$1281,"<="&$D$3),"") -> -0.063481816 | J31: 1090 | K31: 1090基石组合 | L31: ='1090实盘净值'!A31+0 -> 46232 | M31: ='1090实盘净值'!B31+0 -> 0.97811843 | N31: =IF(OR(L31<$B$3,L31>$D$3),"",IF(AND(J31=J30,N30<>""),MAX(M31,N30),M31)) -> 1.0027107 | O31: =IF(N31="","",M31/N31-1) -> -0.024525749
A32: 7 | B32: 018595.OF | C32: 华商利欣回报债券A | D32: =IF(OR(COUNTIFS($J$3:$J$1281,$B32,$L$3:$L$1281,$B$3)=0,COUNTIFS($J$3:$J$1281,$B32,$L$3:$L$1281,$D$3)=0),"",SUMIFS($M$3:$M$1281,$J$3:$J$1281,$B32,$L$3:$L$1281,$D$3)/SUMIFS($M$3:$M$1281,$J$3:$J$1281,$B32,$L$3:$L$1281,$B$3)-1) -> 0.0083201268 | E32: =IF(OR(COUNTIFS($J$3:$J$1281,$B32,$L$3:$L$1281,$B$4)=0,COUNTIFS($J$3:$J$1281,$B32,$L$3:$L$1281,$D$4)=0),"",SUMIFS($M$3:$M$1281,$J$3:$J$1281,$B32,$L$3:$L$1281,$D$4)/SUMIFS($M$3:$M$1281,$J$3:$J$1281,$B32,$L$3:$L$1281,$B$4)-1) -> -0.015689382 | F32: =IF(OR(COUNTIFS($J$3:$J$1281,$B32,$L$3:$L$1281,$B$5)=0,COUNTIFS($J$3:$J$1281,$B32,$L$3:$L$1281,$D$5)=0),"",SUMIFS($M$3:$M$1281,$J$3:$J$1281,$B32,$L$3:$L$1281,$D$5)/SUMIFS($M$3:$M$1281,$J$3:$J$1281,$B32,$L$3:$L$1281,$B$5)-1) -> 0.034721093 | G32: =IFERROR(MINIFS($O$3:$O$1281,$J$3:$J$1281,$B32,$L$3:$L$1281,">="&$B$3,$L$3:$L$1281,"<="&$D$3),"") -> -0.04644491 | J32: 1090 | K32: 1090基石组合 | L32: ='1090实盘净值'!A32+0 -> 46233 | M32: ='1090实盘净值'!B32+0 -> 0.97376326 | N32: =IF(OR(L32<$B$3,L32>$D$3),"",IF(AND(J32=J31,N31<>""),MAX(M32,N31),M32)) -> 1.0027107 | O32: =IF(N32="","",M32/N32-1) -> -0.028869146
A33: 8 | B33: 001751.OF | C33: 华商信用增强债券A | D33: =IF(OR(COUNTIFS($J$3:$J$1281,$B33,$L$3:$L$1281,$B$3)=0,COUNTIFS($J$3:$J$1281,$B33,$L$3:$L$1281,$D$3)=0),"",SUMIFS($M$3:$M$1281,$J$3:$J$1281,$B33,$L$3:$L$1281,$D$3)/SUMIFS($M$3:$M$1281,$J$3:$J$1281,$B33,$L$3:$L$1281,$B$3)-1) -> 0.0048685492 | E33: =IF(OR(COUNTIFS($J$3:$J$1281,$B33,$L$3:$L$1281,$B$4)=0,COUNTIFS($J$3:$J$1281,$B33,$L$3:$L$1281,$D$4)=0),"",SUMIFS($M$3:$M$1281,$J$3:$J$1281,$B33,$L$3:$L$1281,$D$4)/SUMIFS($M$3:$M$1281,$J$3:$J$1281,$B33,$L$3:$L$1281,$B$4)-1) -> -0.020447907 | F33: =IF(OR(COUNTIFS($J$3:$J$1281,$B33,$L$3:$L$1281,$B$5)=0,COUNTIFS($J$3:$J$1281,$B33,$L$3:$L$1281,$D$5)=0),"",SUMIFS($M$3:$M$1281,$J$3:$J$1281,$B33,$L$3:$L$1281,$D$5)/SUMIFS($M$3:$M$1281,$J$3:$J$1281,$B33,$L$3:$L$1281,$B$5)-1) -> 0.037707391 | G33: =IFERROR(MINIFS($O$3:$O$1281,$J$3:$J$1281,$B33,$L$3:$L$1281,">="&$B$3,$L$3:$L$1281,"<="&$D$3),"") -> -0.052405908 | J33: 1090 | K33: 1090基石组合 | L33: ='1090实盘净值'!A33+0 -> 46234 | M33: ='1090实盘净值'!B33+0 -> 0.97705802 | N33: =IF(OR(L33<$B$3,L33>$D$3),"",IF(AND(J33=J32,N32<>""),MAX(M33,N32),M33)) -> 1.0027107 | O33: =IF(N33="","",M33/N33-1) -> -0.025583292
A34: 9 | B34: 020218.OF | C34: 万家锦利债券发起式A | D34: =IF(OR(COUNTIFS($J$3:$J$1281,$B34,$L$3:$L$1281,$B$3)=0,COUNTIFS($J$3:$J$1281,$B34,$L$3:$L$1281,$D$3)=0),"",SUMIFS($M$3:$M$1281,$J$3:$J$1281,$B34,$L$3:$L$1281,$D$3)/SUMIFS($M$3:$M$1281,$J$3:$J$1281,$B34,$L$3:$L$1281,$B$3)-1) -> -0.032229258 | E34: =IF(OR(COUNTIFS($J$3:$J$1281,$B34,$L$3:$L$1281,$B$4)=0,COUNTIFS($J$3:$J$1281,$B34,$L$3:$L$1281,$D$4)=0),"",SUMIFS($M$3:$M$1281,$J$3:$J$1281,$B34,$L$3:$L$1281,$D$4)/SUMIFS($M$3:$M$1281,$J$3:$J$1281,$B34,$L$3:$L$1281,$B$4)-1) -> -0.044163013 | F34: =IF(OR(COUNTIFS($J$3:$J$1281,$B34,$L$3:$L$1281,$B$5)=0,COUNTIFS($J$3:$J$1281,$B34,$L$3:$L$1281,$D$5)=0),"",SUMIFS($M$3:$M$1281,$J$3:$J$1281,$B34,$L$3:$L$1281,$D$5)/SUMIFS($M$3:$M$1281,$J$3:$J$1281,$B34,$L$3:$L$1281,$B$5)-1) -> 0.018192689 | G34: =IFERROR(MINIFS($O$3:$O$1281,$J$3:$J$1281,$B34,$L$3:$L$1281,">="&$B$3,$L$3:$L$1281,"<="&$D$3),"") -> -0.057478667 | J34: 1090 | K34: 1090基石组合 | L34: ='1090实盘净值'!A34+0 -> 46237 | M34: ='1090实盘净值'!B34+0 -> 0.97469599 | N34: =IF(OR(L34<$B$3,L34>$D$3),"",IF(AND(J34=J33,N33<>""),MAX(M34,N33),M34)) -> 1.0027107 | O34: =IF(N34="","",M34/N34-1) -> -0.027938937
A35: 10 | B35: 014846.OF | C35: 博时恒乐债券A | D35: =IF(OR(COUNTIFS($J$3:$J$1281,$B35,$L$3:$L$1281,$B$3)=0,COUNTIFS($J$3:$J$1281,$B35,$L$3:$L$1281,$D$3)=0),"",SUMIFS($M$3:$M$1281,$J$3:$J$1281,$B35,$L$3:$L$1281,$D$3)/SUMIFS($M$3:$M$1281,$J$3:$J$1281,$B35,$L$3:$L$1281,$B$3)-1) -> -0.011699605 | E35: =IF(OR(COUNTIFS($J$3:$J$1281,$B35,$L$3:$L$1281,$B$4)=0,COUNTIFS($J$3:$J$1281,$B35,$L$3:$L$1281,$D$4)=0),"",SUMIFS($M$3:$M$1281,$J$3:$J$1281,$B35,$L$3:$L$1281,$D$4)/SUMIFS($M$3:$M$1281,$J$3:$J$1281,$B35,$L$3:$L$1281,$B$4)-1) -> -0.015573123 | F35: =IF(OR(COUNTIFS($J$3:$J$1281,$B35,$L$3:$L$1281,$B$5)=0,COUNTIFS($J$3:$J$1281,$B35,$L$3:$L$1281,$D$5)=0),"",SUMIFS($M$3:$M$1281,$J$3:$J$1281,$B35,$L$3:$L$1281,$D$5)/SUMIFS($M$3:$M$1281,$J$3:$J$1281,$B35,$L$3:$L$1281,$B$5)-1) -> 0.0046608807 | G35: =IFERROR(MINIFS($O$3:$O$1281,$J$3:$J$1281,$B35,$L$3:$L$1281,">="&$B$3,$L$3:$L$1281,"<="&$D$3),"") -> -0.03092382 | J35: 1090 | K35: 1090基石组合 | L35: ='1090实盘净值'!A35+0 -> 46238 | M35: ='1090实盘净值'!B35+0 -> 0.97954497 | N35: =IF(OR(L35<$B$3,L35>$D$3),"",IF(AND(J35=J34,N34<>""),MAX(M35,N34),M35)) -> 1.0027107 | O35: =IF(N35="","",M35/N35-1) -> -0.023103065
J36: 1090 | K36: 1090基石组合 | L36: ='1090实盘净值'!A36+0 -> 46239 | M36: ='1090实盘净值'!B36+0 -> 0.98421564 | N36: =IF(OR(L36<$B$3,L36>$D$3),"",IF(AND(J36=J35,N35<>""),MAX(M36,N35),M36)) -> 1.0027107 | O36: =IF(N36="","",M36/N36-1) -> -0.018445022
J37: 1090 | K37: 1090基石组合 | L37: ='1090实盘净值'!A37+0 -> 46240 | M37: ='1090实盘净值'!B37+0 -> 0.98658983 | N37: =IF(OR(L37<$B$3,L37>$D$3),"",IF(AND(J37=J36,N36<>""),MAX(M37,N36),M37)) -> 1.0027107 | O37: =IF(N37="","",M37/N37-1) -> -0.01607725
A38: 1090基石组合与公司固收+保有前十基金对比 | J38: 1090 | K38: 1090基石组合 | L38: ='1090实盘净值'!A38+0 -> 46241 | M38: ='1090实盘净值'!B38+0 -> 0.9897759 | N38: =IF(OR(L38<$B$3,L38>$D$3),"",IF(AND(J38=J37,N37<>""),MAX(M38,N37),M38)) -> 1.0027107 | O38: =IF(N38="","",M38/N38-1) -> -0.012899793
A39: 序号 | B39: 基金代码 | C39: 产品/基金名称 | D39: 上线以来收益率 | E39: 区间1收益率 | F39: 区间2收益率 | G39: 最大回撤（上线以来） | J39: 1090 | K39: 1090基石组合 | L39: ='1090实盘净值'!A39+0 -> 46244 | M39: ='1090实盘净值'!B39+0 -> 0.99185254 | N39: =IF(OR(L39<$B$3,L39>$D$3),"",IF(AND(J39=J38,N38<>""),MAX(M39,N38),M39)) -> 1.0027107 | O39: =IF(N39="","",M39/N39-1) -> -0.010828767
A40: 组合 | B40: 1090 | C40: 1090基石组合 | D40: =IF(OR(COUNTIFS($J$3:$J$1281,$B40,$L$3:$L$1281,$B$3)=0,COUNTIFS($J$3:$J$1281,$B40,$L$3:$L$1281,$D$3)=0),"",SUMIFS($M$3:$M$1281,$J$3:$J$1281,$B40,$L$3:$L$1281,$D$3)/SUMIFS($M$3:$M$1281,$J$3:$J$1281,$B40,$L$3:$L$1281,$B$3)-1) -> -0.00814746 | E40: =IF(OR(COUNTIFS($J$3:$J$1281,$B40,$L$3:$L$1281,$B$4)=0,COUNTIFS($J$3:$J$1281,$B40,$L$3:$L$1281,$D$4)=0),"",SUMIFS($M$3:$M$1281,$J$3:$J$1281,$B40,$L$3:$L$1281,$D$4)/SUMIFS($M$3:$M$1281,$J$3:$J$1281,$B40,$L$3:$L$1281,$B$4)-1) -> -0.02294198 | F40: =IF(OR(COUNTIFS($J$3:$J$1281,$B40,$L$3:$L$1281,$B$5)=0,COUNTIFS($J$3:$J$1281,$B40,$L$3:$L$1281,$D$5)=0),"",SUMIFS($M$3:$M$1281,$J$3:$J$1281,$B40,$L$3:$L$1281,$D$5)/SUMIFS($M$3:$M$1281,$J$3:$J$1281,$B40,$L$3:$L$1281,$B$5)-1) -> 0.01760195 | G40: =IFERROR(MINIFS($O$3:$O$1281,$J$3:$J$1281,$B40,$L$3:$L$1281,">="&$B$3,$L$3:$L$1281,"<="&$D$3),"") -> -0.028869146 | J40: 110027.OF | K40: 易方达安心回报债券A | L40: 46191 | M40: 4.547 | N40: =IF(OR(L40<$B$3,L40>$D$3),"",IF(AND(J40=J39,N39<>""),MAX(M40,N39),M40)) -> 4.547 | O40: =IF(N40="","",M40/N40-1) -> 0
...
