Workbook
Name _ChartDates: 实盘组合净值!$A$7:INDEX(实盘组合净值!$A$7:$A$1000,MATCH(9.99999999999999E+307,实盘组合净值!$A$7:$A$1000))
Name _ChartValues: 实盘组合净值!$H$7:INDEX(实盘组合净值!$H$7:$H$1000,MATCH(9.99999999999999E+307,实盘组合净值!$A$7:$A$1000))

Sheet 日期页
B1: 同花顺交易日 | C1: 自然日
A2: 最新交易日 | B2: =[1]!thsiFinD("ths_new_forward_nearest_trade_date_func",C2,100) -> 46304 | C2: =E2 -> 46304 | D2: 今日 | E2: =TODAY() -> 46304
A3: 上一交易日 | B3: =[1]!thsiFinD("ths_new_forward_nearest_trade_date_func",C3,100) -> 46303 | C3: =B2-1 -> 46303 | D3: 昨日
A4: 本周第一个交易日 | B4: =[1]!thsiFinD("ths_new_backward_nearest_trade_date_func",C4,100) -> 46303 | C4: =B2- WEEKDAY(B2, 2)+1 -> 46300 | D4: 本周一
A5: 上周最后一个交易日 | B5: =[1]!thsiFinD("ths_new_forward_nearest_trade_date_func",C5,100) -> 46295 | C5: =B2- WEEKDAY(B2, 2) - 2 -> 46297 | D5: 上周五
A6: 上线后第一个交易日 | B6: =[1]!thsiFinD("ths_new_backward_nearest_trade_date_func",C6+1,100) -> 46195 | C6: 46191 | D6: 上线日
A8: FOF估值
A9: 前1个交易日 | B9: =[1]!thsiFinD("ths_new_forward_nearest_trade_date_func",B10-1,100) -> 46294
A10: 上2个交易日 | B10: =[1]!thsiFinD("ths_new_forward_nearest_trade_date_func",B3-1,100) -> 46295

Sheet 每日组合
A1: 样板间投顾组合业绩预估 | D1: ="更新日期："&TEXT(H4,"yyyy-mm-dd") -> 更新日期：2026-10-09 | G1: 上线以来 | H1: =日期页!C6 -> 46191 | I1: 46195 | J1: 46282
A2: 注：收益率数据根据相关组合的持仓、费率估算，仅供内部参考，请勿外发 | G2: 上周五/本周初 | H2: =日期页!B5 -> 46295 | I2: =日期页!B4 -> 46303
A3: 组合名称 | B3: 日涨跌 | C3: 本周以来 | D3: 累计涨跌 | E3: 上线日期 | F3: 年费率 | G3: 上一个交易日 | H3: =日期页!B3 -> 46303
A4: 10/90策略 | G4: 最新交易日 | H4: =日期页!B2 -> 46304 | I4: =H3 -> 46303 | J4: =H2 -> 46295 | K4: 日涨跌幅 | L4: 本周以来 | M4: 累计涨跌幅
A5: 10/90基石 | B5: =K5 -> -1.3732897e-05 | C5: =L5 -> -0.0045361692 | D5: =M5 -> -0.016245733 | E5: 46191 | F5: 0.005 | H5: =VLOOKUP(H$4,实盘组合净值!$A:$S,14,0) -> 0.98375427 | I5: =VLOOKUP(I$4,实盘组合净值!$A:$S,14,0) -> 0.98376778 | J5: =VLOOKUP(J$4,实盘组合净值!$A:$S,14,0) -> 0.98823708 | K5: =H5/I5-1 -> -1.3732897e-05 | L5: =H5/J5-1 -> -0.0045361692 | M5: =H5-1 -> -0.016245733
A6: 10/90 | B6: =K6 -> -2.2005708e-05 | C6: =L6 -> -0.0043694913 | D6: =M6 -> -0.017093031 | E6: 46197 | F6: 0.008 | H6: =VLOOKUP(H$4,实盘组合净值!$A:$S,11,0) -> 0.98290697 | I6: =VLOOKUP(I$4,实盘组合净值!$A:$S,11,0) -> 0.9829286 | J6: =VLOOKUP(J$4,实盘组合净值!$A:$S,11,0) -> 0.98722062 | K6: =H6/I6-1 -> -2.2005708e-05 | L6: =H6/J6-1 -> -0.0043694913 | M6: =H6-1 -> -0.017093031
A7: 20/80策略
A8: 20/80 | B8: =K8 -> -2.2005708e-05 | C8: =L8 -> -0.0019100001 | D8: =M8 -> -0.0031930669 | E8: 46282 | F8: 0.008 | H8: =VLOOKUP(H$4,实盘组合净值!$A:$V,20,0) -> 0.99680693 | I8: =VLOOKUP(I$4,实盘组合净值!$A:$V,20,0) -> 0.99682887 | J8: =VLOOKUP(J$4,实盘组合净值!$A:$V,20,0) -> 0.99871448 | K8: =H8/I8-1 -> -2.2005708e-05 | L8: =H8/J8-1 -> -0.0019100001 | M8: =H8-1 -> -0.0031930669
A9: 30/70策略
A10: 30/70 | B10: =K10 -> -3.3075018e-05 | C10: =L10 -> -0.011892183 | D10: =M10 -> -0.066274013 | E10: 46197 | F10: 0.012 | H10: =VLOOKUP(H$4,实盘组合净值!$A:$S,17,0) -> 0.93372599 | I10: =VLOOKUP(I$4,实盘组合净值!$A:$S,17,0) -> 0.93375687 | J10: =VLOOKUP(J$4,实盘组合净值!$A:$S,17,0) -> 0.94496367 | K10: =H10/I10-1 -> -3.3075018e-05 | L10: =H10/J10-1 -> -0.011892183 | M10: =H10-1 -> -0.066274013
A11: 产业趋势策略
A12: 产业趋势基石 | B12: =K12 -> -3.3075018e-05 | C12: =L12 -> -0.051912754 | D12: =M12 -> -0.24909217 | E12: 46191 | F12: 0.012 | H12: =VLOOKUP(H$4,实盘组合净值!$A:$S,5,0) -> 0.75090783 | I12: =VLOOKUP(I$4,实盘组合净值!$A:$S,5,0) -> 0.75093267 | J12: =VLOOKUP(J$4,实盘组合净值!$A:$S,5,0) -> 0.79202398 | K12: =H12/I12-1 -> -3.3075018e-05 | L12: =H12/J12-1 -> -0.051912754 | M12: =H12-1 -> -0.24909217
A13: 产业趋势 | B13: =K13 -> -4.140637e-05 | C13: =L13 -> -0.051897011 | D13: =M13 -> -0.26639482 | E13: 46195 | F13: 0.015 | H13: =VLOOKUP(H$4,实盘组合净值!$A:$S,2,0) -> 0.73360518 | I13: =VLOOKUP(I$4,实盘组合净值!$A:$S,2,0) -> 0.73363556 | J13: =VLOOKUP(J$4,实盘组合净值!$A:$S,2,0) -> 0.77376107 | K13: =H13/I13-1 -> -4.140637e-05 | L13: =H13/J13-1 -> -0.051897011 | M13: =H13-1 -> -0.26639482
A14: 产业趋势2号 | B14: =K14 -> -4.140637e-05 | C14: =L14 -> -0.045766704 | D14: =M14 -> -0.25213502 | E14: 46197 | F14: 0.015 | H14: =VLOOKUP(H$4,实盘组合净值!$A:$S,8,0) -> 0.74786498 | I14: =VLOOKUP(I$4,实盘组合净值!$A:$S,8,0) -> 0.74789595 | J14: =VLOOKUP(J$4,实盘组合净值!$A:$S,8,0) -> 0.7837339 | K14: =H14/I14-1 -> -4.140637e-05 | L14: =H14/J14-1 -> -0.045766704 | M14: =H14-1 -> -0.25213502

Sheet 每日1090
B1: 10/90投顾组合业绩预估 | E1: =每日组合!D1 -> 更新日期：2026-10-09 | H1: =每日组合!G1 -> 上线以来 | I1: =每日组合!H1 -> 46191 | J1: =每日组合!I1 -> 46195
B2: 注：收益率数据根据相关组合的持仓、费率估算，仅供内部参考，请勿外发 | H2: =每日组合!G2 -> 上周五/本周初 | I2: =每日组合!H2 -> 46295 | J2: =每日组合!I2 -> 46303
B3: 一、组合总览 | H3: =每日组合!G3 -> 上一个交易日 | I3: =每日组合!H3 -> 46303
B4: 组合名称 | C4: 日涨跌 | D4: 本周以来 | E4: 上线以来 | F4: 上线日期 | H4: =每日组合!G4 -> 最新交易日 | I4: =每日组合!H4 -> 46304 | J4: =每日组合!I4 -> 46303 | K4: =每日组合!J4 -> 46295
B5: 10/90基石 | C5: =每日组合!B5 -> -1.3732897e-05 | D5: =每日组合!C5 -> -0.0045361692 | E5: =每日组合!D5 -> -0.016245733 | F5: =每日组合!E5 -> 46191
B6: 10/90 | C6: =每日组合!B6 -> -2.2005708e-05 | D6: =每日组合!C6 -> -0.0043694913 | E6: =每日组合!D6 -> -0.017093031 | F6: =每日组合!E6 -> 46197
B7: 二、持仓基金表现
A8: 基金代码 | B8: 10/90基石 | C8: 今日涨跌 | D8: 本周以来 | E8: 上线以来 | F8: 比例 | H8: 46195
A9: 007044.OF | B9: =[1]!thsiFinD("ths_fund_short_name_fund",A9) -> 博道沪深300指数增强A | C9: =[1]!thsiFinD("ths_adjustment_nvg_ratio_fund",$A9,$I$4,$I$4,101)/100 -> 0 | D9: =[1]!thsiFinD("ths_adjustment_nvg_ratio_fund",$A9,$J$2,$I$4,101)/100 -> -0.0091393755 | E9: =[1]!thsiFinD("ths_adjustment_nvg_ratio_fund",$A9,$H$8,$I$4,101)/100 -> -0.084907556 | F9: 0.0125
A10: 015453.OF | B10: =[1]!thsiFinD("ths_fund_short_name_fund",A10) -> 中欧中证500指数增强A | C10: =[1]!thsiFinD("ths_adjustment_nvg_ratio_fund",$A10,$I$4,$I$4,101)/100 -> 0 | D10: =[1]!thsiFinD("ths_adjustment_nvg_ratio_fund",$A10,$J$2,$I$4,101)/100 -> -0.022110004 | E10: =[1]!thsiFinD("ths_adjustment_nvg_ratio_fund",$A10,$H$8,$I$4,101)/100 -> -0.11950845 | F10: 0.0125
A11: 014201.OF | B11: =[1]!thsiFinD("ths_fund_short_name_fund",A11) -> 天弘中证1000指数增强A | C11: =[1]!thsiFinD("ths_adjustment_nvg_ratio_fund",$A11,$I$4,$I$4,101)/100 -> 0 | D11: =[1]!thsiFinD("ths_adjustment_nvg_ratio_fund",$A11,$J$2,$I$4,101)/100 -> -0.019130435 | E11: =[1]!thsiFinD("ths_adjustment_nvg_ratio_fund",$A11,$H$8,$I$4,101)/100 -> -0.13812155 | F11: 0.0125
A12: 019923.OF | B12: =[1]!thsiFinD("ths_fund_short_name_fund",A12) -> 华泰柏瑞中证2000指数增强A | C12: =[1]!thsiFinD("ths_adjustment_nvg_ratio_fund",$A12,$I$4,$I$4,101)/100 -> 0 | D12: =[1]!thsiFinD("ths_adjustment_nvg_ratio_fund",$A12,$J$2,$I$4,101)/100 -> -0.014104446 | E12: =[1]!thsiFinD("ths_adjustment_nvg_ratio_fund",$A12,$H$8,$I$4,101)/100 -> -0.12077995 | F12: 0.0125
A13: 001170.OF | B13: =[1]!thsiFinD("ths_fund_short_name_fund",A13) -> 宏利复兴伟业混合A | C13: =[1]!thsiFinD("ths_adjustment_nvg_ratio_fund",$A13,$I$4,$I$4,101)/100 -> 0 | D13: =[1]!thsiFinD("ths_adjustment_nvg_ratio_fund",$A13,$J$2,$I$4,101)/100 -> -0.054136396 | E13: =[1]!thsiFinD("ths_adjustment_nvg_ratio_fund",$A13,$H$8,$I$4,101)/100 -> -0.33421313 | F13: 0.01
A14: 013840.OF | B14: =[1]!thsiFinD("ths_fund_short_name_fund",A14) -> 银华集成电路混合A | C14: =[1]!thsiFinD("ths_adjustment_nvg_ratio_fund",$A14,$I$4,$I$4,101)/100 -> 0 | D14: =[1]!thsiFinD("ths_adjustment_nvg_ratio_fund",$A14,$J$2,$I$4,101)/100 -> -0.041502596 | E14: =[1]!thsiFinD("ths_adjustment_nvg_ratio_fund",$A14,$H$8,$I$4,101)/100 -> -0.092301092 | F14: 0.01
A15: 016370.OF | B15: =[1]!thsiFinD("ths_fund_short_name_fund",A15) -> 信澳业绩驱动混合A | C15: =[1]!thsiFinD("ths_adjustment_nvg_ratio_fund",$A15,$I$4,$I$4,101)/100 -> 0 | D15: =[1]!thsiFinD("ths_adjustment_nvg_ratio_fund",$A15,$J$2,$I$4,101)/100 -> -0.075628123 | E15: =[1]!thsiFinD("ths_adjustment_nvg_ratio_fund",$A15,$H$8,$I$4,101)/100 -> -0.2985825 | F15: 0.01
A16: 017488.OF | B16: =[1]!thsiFinD("ths_fund_short_name_fund",A16) -> 嘉实信息产业股票发起式A | C16: =[1]!thsiFinD("ths_adjustment_nvg_ratio_fund",$A16,$I$4,$I$4,101)/100 -> 0 | D16: =[1]!thsiFinD("ths_adjustment_nvg_ratio_fund",$A16,$J$2,$I$4,101)/100 -> -0.073526279 | E16: =[1]!thsiFinD("ths_adjustment_nvg_ratio_fund",$A16,$H$8,$I$4,101)/100 -> -0.30596845 | F16: 0.01
A17: 162214.OF | B17: =[1]!thsiFinD("ths_fund_short_name_fund",A17) -> 宏利领先中小盘混合 | C17: =[1]!thsiFinD("ths_adjustment_nvg_ratio_fund",$A17,$I$4,$I$4,101)/100 -> 0 | D17: =[1]!thsiFinD("ths_adjustment_nvg_ratio_fund",$A17,$J$2,$I$4,101)/100 -> -0.043612335 | E17: =[1]!thsiFinD("ths_adjustment_nvg_ratio_fund",$A17,$H$8,$I$4,101)/100 -> -0.091631799 | F17: 0.01
A18: 008015.OF | B18: =[1]!thsiFinD("ths_fund_short_name_fund",A18) -> 嘉实中债3-5年国开行债券指数A | C18: =[1]!thsiFinD("ths_adjustment_nvg_ratio_fund",$A18,$I$4,$I$4,101)/100 -> 0 | D18: =[1]!thsiFinD("ths_adjustment_nvg_ratio_fund",$A18,$J$2,$I$4,101)/100 -> -9.5492773e-05 | E18: =[1]!thsiFinD("ths_adjustment_nvg_ratio_fund",$A18,$H$8,$I$4,101)/100 -> 0.0064216327 | F18: 0.15
A19: 003376.OF | B19: =[1]!thsiFinD("ths_fund_short_name_fund",A19) -> 广发中债7-10年期国开行债券指数A | C19: =[1]!thsiFinD("ths_adjustment_nvg_ratio_fund",$A19,$I$4,$I$4,101)/100 -> 0 | D19: =[1]!thsiFinD("ths_adjustment_nvg_ratio_fund",$A19,$J$2,$I$4,101)/100 -> -7.2155293e-05 | E19: =[1]!thsiFinD("ths_adjustment_nvg_ratio_fund",$A19,$H$8,$I$4,101)/100 -> 0.0088817705 | F19: 0.15
A20: 161119.OF | B20: =[1]!thsiFinD("ths_fund_short_name_fund",A20) -> 易方达中债新综合债券指数发起式(LOF)A | C20: =[1]!thsiFinD("ths_adjustment_nvg_ratio_fund",$A20,$I$4,$I$4,101)/100 -> 0 | D20: =[1]!thsiFinD("ths_adjustment_nvg_ratio_fund",$A20,$J$2,$I$4,101)/100 -> -5.5306676e-05 | E20: =[1]!thsiFinD("ths_adjustment_nvg_ratio_fund",$A20,$H$8,$I$4,101)/100 -> 0.011808159 | F20: 0.5
... A22: 000917.OF | B22: =[1]!thsiFinD("ths_fund_short_name_fund",A22) -> 嘉实快线货币A | C22: =[1]!thsiFinD("ths_adjustment_nvg_ratio_fund",$A22,$I$4,$I$4,101)/100 -> 0 | D22: =[1]!thsiFinD("ths_adjustment_nvg_ratio_fund",$A22,$J$2,$I$4,101)/100 -> 3.312994e-05 | E22: =[1]!thsiFinD("ths_adjustment_nvg_ratio_fund",$A22,$H$8,$I$4,101)/100 -> 0.0036889351 | F22: 0.05
A23: 基金代码 | B23: 10/90 | C23: 日涨跌 | D23: =D8 -> 本周以来 | E23: =E8 -> 上线以来 | F23: 比例 | H23: 46198
A24: 007045.OF | B24: =[1]!thsiFinD("ths_fund_short_name_fund",A24) -> 博道沪深300指数增强C | C24: =[1]!thsiFinD("ths_adjustment_nvg_ratio_fund",$A24,$I$4,$I$4,101)/100 -> 0 | D24: =[1]!thsiFinD("ths_adjustment_nvg_ratio_fund",$A24,$J$2,$I$4,101)/100 -> -0.0091907644 | E24: =[1]!thsiFinD("ths_adjustment_nvg_ratio_fund",$A24,$H$23,$I$4,101)/100 -> -0.087201198 | F24: 0.0125
A25: 015454.OF | B25: =[1]!thsiFinD("ths_fund_short_name_fund",A25) -> 中欧中证500指数增强C | C25: =[1]!thsiFinD("ths_adjustment_nvg_ratio_fund",$A25,$I$4,$I$4,101)/100 -> 0 | D25: =[1]!thsiFinD("ths_adjustment_nvg_ratio_fund",$A25,$J$2,$I$4,101)/100 -> -0.022209767 | E25: =[1]!thsiFinD("ths_adjustment_nvg_ratio_fund",$A25,$H$23,$I$4,101)/100 -> -0.13926237 | F25: 0.0125
A26: 014202.OF | B26: =[1]!thsiFinD("ths_fund_short_name_fund",A26) -> 天弘中证1000指数增强C | C26: =[1]!thsiFinD("ths_adjustment_nvg_ratio_fund",$A26,$I$4,$I$4,101)/100 -> 0 | D26: =[1]!thsiFinD("ths_adjustment_nvg_ratio_fund",$A26,$J$2,$I$4,101)/100 -> -0.019199457 | E26: =[1]!thsiFinD("ths_adjustment_nvg_ratio_fund",$A26,$H$23,$I$4,101)/100 -> -0.14883721 | F26: 0.0125
A27: 019924.OF | B27: =[1]!thsiFinD("ths_fund_short_name_fund",A27) -> 华泰柏瑞中证2000指数增强C | C27: =[1]!thsiFinD("ths_adjustment_nvg_ratio_fund",$A27,$I$4,$I$4,101)/100 -> 0 | D27: =[1]!thsiFinD("ths_adjustment_nvg_ratio_fund",$A27,$J$2,$I$4,101)/100 -> -0.014151693 | E27: =[1]!thsiFinD("ths_adjustment_nvg_ratio_fund",$A27,$H$23,$I$4,101)/100 -> -0.11877576 | F27: 0.0125
A28: 017612.OF | B28: =[1]!thsiFinD("ths_fund_short_name_fund",A28) -> 宏利复兴伟业混合C | C28: =[1]!thsiFinD("ths_adjustment_nvg_ratio_fund",$A28,$I$4,$I$4,101)/100 -> 0 | D28: =[1]!thsiFinD("ths_adjustment_nvg_ratio_fund",$A28,$J$2,$I$4,101)/100 -> -0.054028436 | E28: =[1]!thsiFinD("ths_adjustment_nvg_ratio_fund",$A28,$H$23,$I$4,101)/100 -> -0.34027433 | F28: 0.0125
A29: 017489.OF | B29: =[1]!thsiFinD("ths_fund_short_name_fund",A29) -> 嘉实信息产业股票发起式C | C29: =[1]!thsiFinD("ths_adjustment_nvg_ratio_fund",$A29,$I$4,$I$4,101)/100 -> 0 | D29: =[1]!thsiFinD("ths_adjustment_nvg_ratio_fund",$A29,$J$2,$I$4,101)/100 -> -0.073671761 | E29: =[1]!thsiFinD("ths_adjustment_nvg_ratio_fund",$A29,$H$23,$I$4,101)/100 -> -0.32630102 | F29: 0.0125
A30: 009993.OF | B30: =[1]!thsiFinD("ths_fund_short_name_fund",A30) -> 嘉实前沿创新混合 | C30: =[1]!thsiFinD("ths_adjustment_nvg_ratio_fund",$A30,$I$4,$I$4,101)/100 -> 0 | D30: =[1]!thsiFinD("ths_adjustment_nvg_ratio_fund",$A30,$J$2,$I$4,101)/100 -> -0.040539922 | E30: =[1]!thsiFinD("ths_adjustment_nvg_ratio_fund",$A30,$H$23,$I$4,101)/100 -> -0.31314488 | F30: 0.01
A31: 013841.OF | B31: =[1]!thsiFinD("ths_fund_short_name_fund",A31) -> 银华集成电路混合C | C31: =[1]!thsiFinD("ths_adjustment_nvg_ratio_fund",$A31,$I$4,$I$4,101)/100 -> 0 | D31: =[1]!thsiFinD("ths_adjustment_nvg_ratio_fund",$A31,$J$2,$I$4,101)/100 -> -0.041587503 | E31: =[1]!thsiFinD("ths_adjustment_nvg_ratio_fund",$A31,$H$23,$I$4,101)/100 -> -0.18016012 | F31: 0.0075
A32: 162214.OF | B32: =[1]!thsiFinD("ths_fund_short_name_fund",A32) -> 宏利领先中小盘混合 | C32: =[1]!thsiFinD("ths_adjustment_nvg_ratio_fund",$A32,$I$4,$I$4,101)/100 -> 0 | D32: =[1]!thsiFinD("ths_adjustment_nvg_ratio_fund",$A32,$J$2,$I$4,101)/100 -> -0.043612335 | E32: =[1]!thsiFinD("ths_adjustment_nvg_ratio_fund",$A32,$H$23,$I$4,101)/100 -> -0.17546525 | F32: 0.0075
A33: 008015.OF | B33: =[1]!thsiFinD("ths_fund_short_name_fund",A33) -> 嘉实中债3-5年国开行债券指数A | C33: =[1]!thsiFinD("ths_adjustment_nvg_ratio_fund",$A33,$I$4,$I$4,101)/100 -> 0 | D33: =[1]!thsiFinD("ths_adjustment_nvg_ratio_fund",$A33,$J$2,$I$4,101)/100 -> -9.5492773e-05 | E33: =[1]!thsiFinD("ths_adjustment_nvg_ratio_fund",$A33,$H$23,$I$4,101)/100 -> 0.0066142677 | F33: 0.15
A34: 003376.OF | B34: =[1]!thsiFinD("ths_fund_short_name_fund",A34) -> 广发中债7-10年期国开行债券指数A | C34: =[1]!thsiFinD("ths_adjustment_nvg_ratio_fund",$A34,$I$4,$I$4,101)/100 -> 0 | D34: =[1]!thsiFinD("ths_adjustment_nvg_ratio_fund",$A34,$J$2,$I$4,101)/100 -> -7.2155293e-05 | E34: =[1]!thsiFinD("ths_adjustment_nvg_ratio_fund",$A34,$H$23,$I$4,101)/100 -> 0.009690346 | F34: 0.15
A35: 161119.OF | B35: =[1]!thsiFinD("ths_fund_short_name_fund",A35) -> 易方达中债新综合债券指数发起式(LOF)A | C35: =[1]!thsiFinD("ths_adjustment_nvg_ratio_fund",$A35,$I$4,$I$4,101)/100 -> 0 | D35: =[1]!thsiFinD("ths_adjustment_nvg_ratio_fund",$A35,$J$2,$I$4,101)/100 -> -5.5306676e-05 | E35: =[1]!thsiFinD("ths_adjustment_nvg_ratio_fund",$A35,$H$23,$I$4,101)/100 -> 0.01220468 | F35: 0.5
... A37: 000917.OF | B37: =[1]!thsiFinD("ths_fund_short_name_fund",A37) -> 嘉实快线货币A | C37: =[1]!thsiFinD("ths_adjustment_nvg_ratio_fund",$A37,$I$4,$I$4,101)/100 -> 0 | D37: =[1]!thsiFinD("ths_adjustment_nvg_ratio_fund",$A37,$J$2,$I$4,101)/100 -> 3.312994e-05 | E37: =[1]!thsiFinD("ths_adjustment_nvg_ratio_fund",$A37,$H$23,$I$4,101)/100 -> 0.0035774135 | F37: 0.05

Sheet 每日2080 
B1: 20/80投顾组合业绩预估 | E1: =每日组合!D1 -> 更新日期：2026-10-09 | H1: =每日组合!G1 -> 上线以来 | I1: =每日组合!J1 -> 46282 | J1: =每日组合!I1 -> 46195
B2: 注：收益率数据根据相关组合的持仓、费率估算，仅供内部参考，请勿外发 | H2: =每日组合!G2 -> 上周五/本周初 | I2: =每日组合!H2 -> 46295 | J2: =每日组合!I2 -> 46303
B3: 一、组合总览 | H3: =每日组合!G3 -> 上一个交易日 | I3: =每日组合!H3 -> 46303
B4: 组合名称 | C4: 日涨跌 | D4: 本周以来 | E4: 上线以来 | F4: 上线日期 | H4: =每日组合!G4 -> 最新交易日 | I4: =每日组合!H4 -> 46304 | J4: =每日组合!I4 -> 46303 | K4: =每日组合!J4 -> 46295
B5: 20/80 | C5: =每日组合!B8 -> -2.2005708e-05 | D5: =每日组合!C8 -> -0.0019100001 | E5: =每日组合!D8 -> -0.0031930669 | F5: =每日组合!E8 -> 46282
B6: 二、持仓基金表现
A7: 基金代码 | B7: 20/80 | C7: 日涨跌 | D7: 本周以来 | E7: 上线以来 | F7: 比例 | H7: 46283
A8: 007045.OF | B8: =[1]!thsiFinD("ths_fund_short_name_fund",A8) -> 博道沪深300指数增强C | C8: =[1]!thsiFinD("ths_adjustment_nvg_ratio_fund",$A8,$I$4,$I$4,101)/100 -> 0 | D8: =[1]!thsiFinD("ths_adjustment_nvg_ratio_fund",$A8,$J$2,$I$4,101)/100 -> -0.0091907644 | E8: =[1]!thsiFinD("ths_adjustment_nvg_ratio_fund",$A8,$H$7,$I$4,101)/100 -> -0.026967529 | F8: 0.025
A9: 008779.OF | B9: =[1]!thsiFinD("ths_fund_short_name_fund",A9) -> 嘉实中证500指数增强C | C9: =[1]!thsiFinD("ths_adjustment_nvg_ratio_fund",$A9,$I$4,$I$4,101)/100 -> 0 | D9: =[1]!thsiFinD("ths_adjustment_nvg_ratio_fund",$A9,$J$2,$I$4,101)/100 -> -0.025130955 | E9: =[1]!thsiFinD("ths_adjustment_nvg_ratio_fund",$A9,$H$7,$I$4,101)/100 -> -0.055978261 | F9: 0.0125
A10: 006594.OF | B10: =[1]!thsiFinD("ths_fund_short_name_fund",A10) -> 博道中证500指数增强C | C10: =[1]!thsiFinD("ths_adjustment_nvg_ratio_fund",$A10,$I$4,$I$4,101)/100 -> 0 | D10: =[1]!thsiFinD("ths_adjustment_nvg_ratio_fund",$A10,$J$2,$I$4,101)/100 -> -0.016455542 | E10: =[1]!thsiFinD("ths_adjustment_nvg_ratio_fund",$A10,$H$7,$I$4,101)/100 -> -0.040491139 | F10: 0.0125
A11: 017954.OF | B11: =[1]!thsiFinD("ths_fund_short_name_fund",A11) -> 汇添富中证1000指数增强C | C11: =[1]!thsiFinD("ths_adjustment_nvg_ratio_fund",$A11,$I$4,$I$4,101)/100 -> 0 | D11: =[1]!thsiFinD("ths_adjustment_nvg_ratio_fund",$A11,$J$2,$I$4,101)/100 -> -0.020800675 | E11: =[1]!thsiFinD("ths_adjustment_nvg_ratio_fund",$A11,$H$7,$I$4,101)/100 -> -0.04307094 | F11: 0.0125
A12: 014202.OF | B12: =[1]!thsiFinD("ths_fund_short_name_fund",A12) -> 天弘中证1000指数增强C | C12: =[1]!thsiFinD("ths_adjustment_nvg_ratio_fund",$A12,$I$4,$I$4,101)/100 -> 0 | D12: =[1]!thsiFinD("ths_adjustment_nvg_ratio_fund",$A12,$J$2,$I$4,101)/100 -> -0.019199457 | E12: =[1]!thsiFinD("ths_adjustment_nvg_ratio_fund",$A12,$H$7,$I$4,101)/100 -> -0.041312997 | F12: 0.0125
A13: 019924.OF | B13: =[1]!thsiFinD("ths_fund_short_name_fund",A13) -> 华泰柏瑞中证2000指数增强C | C13: =[1]!thsiFinD("ths_adjustment_nvg_ratio_fund",$A13,$I$4,$I$4,101)/100 -> 0 | D13: =[1]!thsiFinD("ths_adjustment_nvg_ratio_fund",$A13,$J$2,$I$4,101)/100 -> -0.014151693 | E13: =[1]!thsiFinD("ths_adjustment_nvg_ratio_fund",$A13,$H$7,$I$4,101)/100 -> -0.020175947 | F13: 0.0125
A14: 019919.OF | B14: =[1]!thsiFinD("ths_fund_short_name_fund",A14) -> 招商中证2000指数增强C | C14: =[1]!thsiFinD("ths_adjustment_nvg_ratio_fund",$A14,$I$4,$I$4,101)/100 -> 0 | D14: =[1]!thsiFinD("ths_adjustment_nvg_ratio_fund",$A14,$J$2,$I$4,101)/100 -> -0.012809426 | E14: =[1]!thsiFinD("ths_adjustment_nvg_ratio_fund",$A14,$H$7,$I$4,101)/100 -> -0.02153533 | F14: 0.0125
A15: 070019.OF | B15: =[1]!thsiFinD("ths_fund_short_name_fund",A15) -> 嘉实价值优势混合A | C15: =[1]!thsiFinD("ths_adjustment_nvg_ratio_fund",$A15,$I$4,$I$4,101)/100 -> 0 | D15: =[1]!thsiFinD("ths_adjustment_nvg_ratio_fund",$A15,$J$2,$I$4,101)/100 -> 0.0017123288 | E15: =[1]!thsiFinD("ths_adjustment_nvg_ratio_fund",$A15,$H$7,$I$4,101)/100 -> 0.0051546392 | F15: 0.005
A16: 000884.OF | B16: =[1]!thsiFinD("ths_fund_short_name_fund",A16) -> 民生加银优选股票 | C16: =[1]!thsiFinD("ths_adjustment_nvg_ratio_fund",$A16,$I$4,$I$4,101)/100 -> 0 | D16: =[1]!thsiFinD("ths_adjustment_nvg_ratio_fund",$A16,$J$2,$I$4,101)/100 -> 0.0082808877 | E16: =[1]!thsiFinD("ths_adjustment_nvg_ratio_fund",$A16,$H$7,$I$4,101)/100 -> 0.0057490253 | F16: 0.005
A17: 090013.OF | B17: =[1]!thsiFinD("ths_fund_short_name_fund",A17) -> 大成竞争优势混合A | C17: =[1]!thsiFinD("ths_adjustment_nvg_ratio_fund",$A17,$I$4,$I$4,101)/100 -> 0 | D17: =[1]!thsiFinD("ths_adjustment_nvg_ratio_fund",$A17,$J$2,$I$4,101)/100 -> -0.0086429185 | E17: =[1]!thsiFinD("ths_adjustment_nvg_ratio_fund",$A17,$H$7,$I$4,101)/100 -> 0.0094816688 | F17: 0.005
A18: 121010.OF | B18: =[1]!thsiFinD("ths_fund_short_name_fund",A18) -> 国投瑞银瑞源混合A | C18: =[1]!thsiFinD("ths_adjustment_nvg_ratio_fund",$A18,$I$4,$I$4,101)/100 -> 0 | D18: =[1]!thsiFinD("ths_adjustment_nvg_ratio_fund",$A18,$J$2,$I$4,101)/100 -> -0.0043724949 | E18: =[1]!thsiFinD("ths_adjustment_nvg_ratio_fund",$A18,$H$7,$I$4,101)/100 -> -0.011039011 | F18: 0.005
A19: 007466.OF | B19: =[1]!thsiFinD("ths_fund_short_name_fund",A19) -> 华泰柏瑞中证红利低波动ETF联接A | C19: =[1]!thsiFinD("ths_adjustment_nvg_ratio_fund",$A19,$I$4,$I$4,101)/100 -> 0 | D19: =[1]!thsiFinD("ths_adjustment_nvg_ratio_fund",$A19,$J$2,$I$4,101)/100 -> 0.010783478 | E19: =[1]!thsiFinD("ths_adjustment_nvg_ratio_fund",$A19,$H$7,$I$4,101)/100 -> 0.02117314 | F19: 0.06
... A25: 000917.OF | B25: =[1]!thsiFinD("ths_fund_short_name_fund",A25) -> 嘉实快线货币A | C25: =[1]!thsiFinD("ths_adjustment_nvg_ratio_fund",$A25,$I$4,$I$4,101)/100 -> 0 | D25: =[1]!thsiFinD("ths_adjustment_nvg_ratio_fund",$A25,$J$2,$I$4,101)/100 -> 3.312994e-05 | E25: =[1]!thsiFinD("ths_adjustment_nvg_ratio_fund",$A25,$H$7,$I$4,101)/100 -> 0.0007065376 | F25: 0.05

Sheet 每日3070
B1: 30/70投顾组合业绩预估 | E1: =每日组合!D1 -> 更新日期：2026-10-09 | H1: =每日组合!G1 -> 上线以来 | I1: =每日组合!H1 -> 46191 | J1: =每日组合!I1 -> 46195
B2: 注：收益率数据根据相关组合的持仓、费率估算，仅供内部参考，请勿外发 | H2: =每日组合!G2 -> 上周五/本周初 | I2: =每日组合!H2 -> 46295 | J2: =每日组合!I2 -> 46303
B3: 一、组合总览 | H3: =每日组合!G3 -> 上一个交易日 | I3: =每日组合!H3 -> 46303
B4: 组合名称 | C4: 日涨跌 | D4: 本周以来 | E4: 上线以来 | F4: 上线日期 | H4: =每日组合!G4 -> 最新交易日 | I4: =每日组合!H4 -> 46304 | J4: =每日组合!I4 -> 46303 | K4: =每日组合!J4 -> 46295
B5: 30/70 | C5: =每日组合!B10 -> -3.3075018e-05 | D5: =每日组合!C10 -> -0.011892183 | E5: =每日组合!D10 -> -0.066274013 | F5: =每日组合!E10 -> 46197
B6: 二、持仓基金表现
A7: 基金代码 | B7: 30/70 | C7: 日涨跌 | D7: 本周以来 | E7: 上线以来 | F7: 比例 | H7: 46198
A8: 007045.OF | B8: =[1]!thsiFinD("ths_fund_short_name_fund",A8) -> 博道沪深300指数增强C | C8: =[1]!thsiFinD("ths_adjustment_nvg_ratio_fund",$A8,$I$4,$I$4,101)/100 -> 0 | D8: =[1]!thsiFinD("ths_adjustment_nvg_ratio_fund",$A8,$J$2,$I$4,101)/100 -> -0.0091907644 | E8: =[1]!thsiFinD("ths_adjustment_nvg_ratio_fund",$A8,$H$7,$I$4,101)/100 -> -0.087201198 | F8: 0.0375
A9: 015454.OF | B9: =[1]!thsiFinD("ths_fund_short_name_fund",A9) -> 中欧中证500指数增强C | C9: =[1]!thsiFinD("ths_adjustment_nvg_ratio_fund",$A9,$I$4,$I$4,101)/100 -> 0 | D9: =[1]!thsiFinD("ths_adjustment_nvg_ratio_fund",$A9,$J$2,$I$4,101)/100 -> -0.022209767 | E9: =[1]!thsiFinD("ths_adjustment_nvg_ratio_fund",$A9,$H$7,$I$4,101)/100 -> -0.13926237 | F9: 0.0375
A10: 014202.OF | B10: =[1]!thsiFinD("ths_fund_short_name_fund",A10) -> 天弘中证1000指数增强C | C10: =[1]!thsiFinD("ths_adjustment_nvg_ratio_fund",$A10,$I$4,$I$4,101)/100 -> 0 | D10: =[1]!thsiFinD("ths_adjustment_nvg_ratio_fund",$A10,$J$2,$I$4,101)/100 -> -0.019199457 | E10: =[1]!thsiFinD("ths_adjustment_nvg_ratio_fund",$A10,$H$7,$I$4,101)/100 -> -0.14883721 | F10: 0.0375
A11: 019924.OF | B11: =[1]!thsiFinD("ths_fund_short_name_fund",A11) -> 华泰柏瑞中证2000指数增强C | C11: =[1]!thsiFinD("ths_adjustment_nvg_ratio_fund",$A11,$I$4,$I$4,101)/100 -> 0 | D11: =[1]!thsiFinD("ths_adjustment_nvg_ratio_fund",$A11,$J$2,$I$4,101)/100 -> -0.014151693 | E11: =[1]!thsiFinD("ths_adjustment_nvg_ratio_fund",$A11,$H$7,$I$4,101)/100 -> -0.11877576 | F11: 0.0375
A12: 017612.OF | B12: =[1]!thsiFinD("ths_fund_short_name_fund",A12) -> 宏利复兴伟业混合C | C12: =[1]!thsiFinD("ths_adjustment_nvg_ratio_fund",$A12,$I$4,$I$4,101)/100 -> 0 | D12: =[1]!thsiFinD("ths_adjustment_nvg_ratio_fund",$A12,$J$2,$I$4,101)/100 -> -0.054028436 | E12: =[1]!thsiFinD("ths_adjustment_nvg_ratio_fund",$A12,$H$7,$I$4,101)/100 -> -0.34027433 | F12: 0.035
A13: 017489.OF | B13: =[1]!thsiFinD("ths_fund_short_name_fund",A13) -> 嘉实信息产业股票发起式C | C13: =[1]!thsiFinD("ths_adjustment_nvg_ratio_fund",$A13,$I$4,$I$4,101)/100 -> 0 | D13: =[1]!thsiFinD("ths_adjustment_nvg_ratio_fund",$A13,$J$2,$I$4,101)/100 -> -0.073671761 | E13: =[1]!thsiFinD("ths_adjustment_nvg_ratio_fund",$A13,$H$7,$I$4,101)/100 -> -0.32630102 | F13: 0.035
A14: 009993.OF | B14: =[1]!thsiFinD("ths_fund_short_name_fund",A14) -> 嘉实前沿创新混合 | C14: =[1]!thsiFinD("ths_adjustment_nvg_ratio_fund",$A14,$I$4,$I$4,101)/100 -> 0 | D14: =[1]!thsiFinD("ths_adjustment_nvg_ratio_fund",$A14,$J$2,$I$4,101)/100 -> -0.040539922 | E14: =[1]!thsiFinD("ths_adjustment_nvg_ratio_fund",$A14,$H$7,$I$4,101)/100 -> -0.31314488 | F14: 0.03
A15: 013841.OF | B15: =[1]!thsiFinD("ths_fund_short_name_fund",A15) -> 银华集成电路混合C | C15: =[1]!thsiFinD("ths_adjustment_nvg_ratio_fund",$A15,$I$4,$I$4,101)/100 -> 0 | D15: =[1]!thsiFinD("ths_adjustment_nvg_ratio_fund",$A15,$J$2,$I$4,101)/100 -> -0.041587503 | E15: =[1]!thsiFinD("ths_adjustment_nvg_ratio_fund",$A15,$H$7,$I$4,101)/100 -> -0.18016012 | F15: 0.025
A16: 162214.OF | B16: =[1]!thsiFinD("ths_fund_short_name_fund",A16) -> 宏利领先中小盘混合 | C16: =[1]!thsiFinD("ths_adjustment_nvg_ratio_fund",$A16,$I$4,$I$4,101)/100 -> 0 | D16: =[1]!thsiFinD("ths_adjustment_nvg_ratio_fund",$A16,$J$2,$I$4,101)/100 -> -0.043612335 | E16: =[1]!thsiFinD("ths_adjustment_nvg_ratio_fund",$A16,$H$7,$I$4,101)/100 -> -0.17546525 | F16: 0.025
A17: 008015.OF | B17: =[1]!thsiFinD("ths_fund_short_name_fund",A17) -> 嘉实中债3-5年国开行债券指数A | C17: =[1]!thsiFinD("ths_adjustment_nvg_ratio_fund",$A17,$I$4,$I$4,101)/100 -> 0 | D17: =[1]!thsiFinD("ths_adjustment_nvg_ratio_fund",$A17,$J$2,$I$4,101)/100 -> -9.5492773e-05 | E17: =[1]!thsiFinD("ths_adjustment_nvg_ratio_fund",$A17,$H$7,$I$4,101)/100 -> 0.0066142677 | F17: 0.1
A18: 003376.OF | B18: =[1]!thsiFinD("ths_fund_short_name_fund",A18) -> 广发中债7-10年期国开行债券指数A | C18: =[1]!thsiFinD("ths_adjustment_nvg_ratio_fund",$A18,$I$4,$I$4,101)/100 -> 0 | D18: =[1]!thsiFinD("ths_adjustment_nvg_ratio_fund",$A18,$J$2,$I$4,101)/100 -> -7.2155293e-05 | E18: =[1]!thsiFinD("ths_adjustment_nvg_ratio_fund",$A18,$H$7,$I$4,101)/100 -> 0.009690346 | F18: 0.1
A19: 161119.OF | B19: =[1]!thsiFinD("ths_fund_short_name_fund",A19) -> 易方达中债新综合债券指数发起式(LOF)A | C19: =[1]!thsiFinD("ths_adjustment_nvg_ratio_fund",$A19,$I$4,$I$4,101)/100 -> 0 | D19: =[1]!thsiFinD("ths_adjustment_nvg_ratio_fund",$A19,$J$2,$I$4,101)/100 -> -5.5306676e-05 | E19: =[1]!thsiFinD("ths_adjustment_nvg_ratio_fund",$A19,$H$7,$I$4,101)/100 -> 0.01220468 | F19: 0.3
... A21: 000917.OF | B21: =[1]!thsiFinD("ths_fund_short_name_fund",A21) -> 嘉实快线货币A | C21: =[1]!thsiFinD("ths_adjustment_nvg_ratio_fund",$A21,$I$4,$I$4,101)/100 -> 0 | D21: =[1]!thsiFinD("ths_adjustment_nvg_ratio_fund",$A21,$J$2,$I$4,101)/100 -> 3.312994e-05 | E21: =[1]!thsiFinD("ths_adjustment_nvg_ratio_fund",$A21,$H$7,$I$4,101)/100 -> 0.0035774135 | F21: 0.1

Sheet 每日产业趋势
B1: 产业趋势投顾业绩组合预估 | E1: =每日组合!D1 -> 更新日期：2026-10-09 | H1: =每日组合!G1 -> 上线以来 | I1: =每日组合!H1 -> 46191 | J1: =每日组合!I1 -> 46195
B2: 注：收益率数据根据相关组合的持仓、费率估算，仅供内部参考，请勿外发 | H2: =每日组合!G2 -> 上周五/本周初 | I2: =每日组合!H2 -> 46295 | J2: =每日组合!I2 -> 46303
B3: 一、组合总览 | H3: =每日组合!G3 -> 上一个交易日 | I3: =每日组合!H3 -> 46303
B4: 组合名称 | C4: 日涨跌 | D4: 本周以来 | E4: 上线以来 | F4: 上线日期 | H4: =每日组合!G4 -> 最新交易日 | I4: =每日组合!H4 -> 46304 | J4: =每日组合!I4 -> 46303 | K4: =每日组合!J4 -> 46295
B5: 产业趋势基石 | C5: =每日组合!B12 -> -3.3075018e-05 | D5: =每日组合!C12 -> -0.051912754 | E5: =每日组合!D12 -> -0.24909217 | F5: =每日组合!E12 -> 46191
B6: 产业趋势 | C6: =每日组合!B13 -> -4.140637e-05 | D6: =每日组合!C13 -> -0.051897011 | E6: =每日组合!D13 -> -0.26639482 | F6: =每日组合!E13 -> 46195
B7: 产业趋势2号 | C7: =每日组合!B14 -> -4.140637e-05 | D7: =每日组合!C14 -> -0.045766704 | E7: =每日组合!D14 -> -0.25213502 | F7: =每日组合!E14 -> 46197
B8: 二、持仓基金表现
A9: 基金代码 | B9: 产业趋势基石/产业趋势 | C9: 日涨跌 | D9: 本周以来 | E9: 上线以来 | F9: 比例 | H9: 46195
A10: 001170.OF | B10: 宏利复兴混合A | C10: =[1]!thsiFinD("ths_adjustment_nvg_ratio_fund",$A10,$I$4,$I$4,101)/100 -> 0 | D10: =[1]!thsiFinD("ths_adjustment_nvg_ratio_fund",$A10,$J$2,$I$4,101)/100 -> -0.054136396 | E10: =[1]!thsiFinD("ths_adjustment_nvg_ratio_fund",$A10,$H$9,$I$4,101)/100 -> -0.33421313 | F10: 0.166095
A11: 017488.OF | B11: 嘉实信息产业A | C11: =[1]!thsiFinD("ths_adjustment_nvg_ratio_fund",$A11,$I$4,$I$4,101)/100 -> 0 | D11: =[1]!thsiFinD("ths_adjustment_nvg_ratio_fund",$A11,$J$2,$I$4,101)/100 -> -0.073526279 | E11: =[1]!thsiFinD("ths_adjustment_nvg_ratio_fund",$A11,$H$9,$I$4,101)/100 -> -0.30596845 | F11: 0.173431
A12: 016370.OF | B12: 信澳业绩驱动A | C12: =[1]!thsiFinD("ths_adjustment_nvg_ratio_fund",$A12,$I$4,$I$4,101)/100 -> 0 | D12: =[1]!thsiFinD("ths_adjustment_nvg_ratio_fund",$A12,$J$2,$I$4,101)/100 -> -0.075628123 | E12: =[1]!thsiFinD("ths_adjustment_nvg_ratio_fund",$A12,$H$9,$I$4,101)/100 -> -0.2985825 | F12: 0.163849
A13: 013840.OF | B13: 银华集成电路混合A | C13: =[1]!thsiFinD("ths_adjustment_nvg_ratio_fund",$A13,$I$4,$I$4,101)/100 -> 0 | D13: =[1]!thsiFinD("ths_adjustment_nvg_ratio_fund",$A13,$J$2,$I$4,101)/100 -> -0.041502596 | E13: =[1]!thsiFinD("ths_adjustment_nvg_ratio_fund",$A13,$H$9,$I$4,101)/100 -> -0.092301092 | F13: 0.245429
A14: 162214.OF | B14: 宏利领先中小盘 | C14: =[1]!thsiFinD("ths_adjustment_nvg_ratio_fund",$A14,$I$4,$I$4,101)/100 -> 0 | D14: =[1]!thsiFinD("ths_adjustment_nvg_ratio_fund",$A14,$J$2,$I$4,101)/100 -> -0.043612335 | E14: =[1]!thsiFinD("ths_adjustment_nvg_ratio_fund",$A14,$H$9,$I$4,101)/100 -> -0.091631799 | F14: 0.07
A15: 019632.OF | B15: 国泰半导体设备ETF联接A | C15: =[1]!thsiFinD("ths_adjustment_nvg_ratio_fund",$A15,$I$4,$I$4,101)/100 -> 0 | D15: =[1]!thsiFinD("ths_adjustment_nvg_ratio_fund",$A15,$J$2,$I$4,101)/100 -> -0.027793685 | E15: =[1]!thsiFinD("ths_adjustment_nvg_ratio_fund",$A15,$H$9,$I$4,101)/100 -> -0.14884016 | F15: 0.135904
A16: 000917.OF | B16: 嘉实快线货币A | C16: =[1]!thsiFinD("ths_adjustment_nvg_ratio_fund",$A16,$I$4,$I$4,101)/100 -> 0 | D16: =[1]!thsiFinD("ths_adjustment_nvg_ratio_fund",$A16,$J$2,$I$4,101)/100 -> 3.312994e-05 | E16: =[1]!thsiFinD("ths_adjustment_nvg_ratio_fund",$A16,$H$9,$I$4,101)/100 -> 0.0036889351 | F16: 0.045292
A17: 基金代码 | B17: 产业趋势2号 | C17: =C9 -> 日涨跌 | D17: =D9 -> 本周以来 | E17: =E9 -> 上线以来 | F17: 比例 | H17: 46198
A18: 017612.OF | B18: 宏利复兴混合C | C18: =[1]!thsiFinD("ths_adjustment_nvg_ratio_fund",$A18,$I$4,$I$4,101)/100 -> 0 | D18: =[1]!thsiFinD("ths_adjustment_nvg_ratio_fund",$A18,$J$2,$I$4,101)/100 -> -0.054028436 | E18: =[1]!thsiFinD("ths_adjustment_nvg_ratio_fund",$A18,$H$17,$I$4,101)/100 -> -0.34027433 | F18: 0.164034
A19: 017489.OF | B19: 嘉实信息产业C | C19: =[1]!thsiFinD("ths_adjustment_nvg_ratio_fund",$A19,$I$4,$I$4,101)/100 -> 0 | D19: =[1]!thsiFinD("ths_adjustment_nvg_ratio_fund",$A19,$J$2,$I$4,101)/100 -> -0.073671761 | E19: =[1]!thsiFinD("ths_adjustment_nvg_ratio_fund",$A19,$H$17,$I$4,101)/100 -> -0.32630102 | F19: 0.168764
A20: 009993.OF | B20: 嘉实前沿创新 | C20: =[1]!thsiFinD("ths_adjustment_nvg_ratio_fund",$A20,$I$4,$I$4,101)/100 -> 0 | D20: =[1]!thsiFinD("ths_adjustment_nvg_ratio_fund",$A20,$J$2,$I$4,101)/100 -> -0.040539922 | E20: =[1]!thsiFinD("ths_adjustment_nvg_ratio_fund",$A20,$H$17,$I$4,101)/100 -> -0.31314488 | F20: 0.189913
A21: 013841.OF | B21: 银华集成电路混合C | C21: =[1]!thsiFinD("ths_adjustment_nvg_ratio_fund",$A21,$I$4,$I$4,101)/100 -> 0 | D21: =[1]!thsiFinD("ths_adjustment_nvg_ratio_fund",$A21,$J$2,$I$4,101)/100 -> -0.041587503 | E21: =[1]!thsiFinD("ths_adjustment_nvg_ratio_fund",$A21,$H$17,$I$4,101)/100 -> -0.18016012 | F21: 0.234328
A22: 162214.OF | B22: 宏利领先中小盘 | C22: =[1]!thsiFinD("ths_adjustment_nvg_ratio_fund",$A22,$I$4,$I$4,101)/100 -> 0 | D22: =[1]!thsiFinD("ths_adjustment_nvg_ratio_fund",$A22,$J$2,$I$4,101)/100 -> -0.043612335 | E22: =[1]!thsiFinD("ths_adjustment_nvg_ratio_fund",$A22,$H$17,$I$4,101)/100 -> -0.17546525 | F22: 0.07
A23: 019633.OF | B23: 国泰半导体设备ETF联接C | C23: =[1]!thsiFinD("ths_adjustment_nvg_ratio_fund",$A23,$I$4,$I$4,101)/100 -> 0 | D23: =[1]!thsiFinD("ths_adjustment_nvg_ratio_fund",$A23,$J$2,$I$4,101)/100 -> -0.027837506 | E23: =[1]!thsiFinD("ths_adjustment_nvg_ratio_fund",$A23,$H$17,$I$4,101)/100 -> -0.21225226 | F23: 0.129189
A24: 000917.OF | B24: 嘉实快线货币A | C24: =[1]!thsiFinD("ths_adjustment_nvg_ratio_fund",$A24,$I$4,$I$4,101)/100 -> 0 | D24: =[1]!thsiFinD("ths_adjustment_nvg_ratio_fund",$A24,$J$2,$I$4,101)/100 -> 3.312994e-05 | E24: =[1]!thsiFinD("ths_adjustment_nvg_ratio_fund",$A24,$H$17,$I$4,101)/100 -> 0.0035774135 | F24: 0.043772

Sheet vs固收+
B3: =日期页!B5 -> 46295 | C3: =VLOOKUP(B3,实盘组合净值!$A:$S,14,0) -> 0.98823708
B4: =日期页!B3 -> 46303 | C4: =VLOOKUP(B4,实盘组合净值!$A:$S,14,0) -> 0.98376778 | D4: =日期页!B4 -> 46303 | E4: =日期页!B6 -> 46195 | F4: =E4 -> 46195 | J4: 46203
B5: =日期页!B2 -> 46304 | C5: =VLOOKUP(B5,实盘组合净值!$A:$S,14,0) -> 0.98375427 | D5: =B5 -> 46304 | E5: =B5 -> 46304 | F5: =B5 -> 46304
A6: 基金代码 | B6: =B5 -> 46304 | C6: 日涨跌 | D6: 本周以来 | E6: 上线以来 | F6: 最大回撤 | I6: 类型 | J6: 权益中枢 /股票仓位 | K6: 转债仓位
B7: 10/90基石投顾账户 | C7: =C5/C4-1 -> -1.3732897e-05 | D7: =C5/C3-1 -> -0.0045361692 | E7: =C5-1 -> -0.016245733 | F7: =MIN(实盘组合净值!P:P) -> -0.028729069 | I7: 10/90配置样板间 | J7: 0.1 | K7: 5%黄金
A8: 110017.OF | B8: 易方达增强回报A | C8: =[1]!thsiFinD("ths_adjustment_nvg_ratio_fund",$A8,B$5,B$5,101)/100 -> 0 | D8: =[1]!thsiFinD("ths_adjustment_nvg_ratio_fund",$A8,D$4,D$5,101)/100 -> 7.1500064e-05 | E8: =[1]!thsiFinD("ths_adjustment_nvg_ratio_fund",$A8,E$4,E$5,101)/100 -> 0.016327328 | F8: =-[1]!thsiFinD("ths_max_retrace_rate_all_fund",$A8,F$4,F$5)/100 -> -0.0050287356 | J8: =[1]!thsiFinD("ths_stock_mv_to_fanv_fund",$A8,$J$4)/100 -> 0.12115928 | K8: =[1]!thsiFinD("ths_cb_mv_to_fanv_fund",A8,$J$4)/100 -> 0.049
A9: 001316.OF | B9: 安信稳健增值A | C9: =[1]!thsiFinD("ths_adjustment_nvg_ratio_fund",$A9,B$5,B$5,101)/100 -> 0 | D9: =[1]!thsiFinD("ths_adjustment_nvg_ratio_fund",$A9,D$4,D$5,101)/100 -> 0.0013138446 | E9: =[1]!thsiFinD("ths_adjustment_nvg_ratio_fund",$A9,E$4,E$5,101)/100 -> 0.016788037 | F9: =-[1]!thsiFinD("ths_max_retrace_rate_all_fund",$A9,F$4,F$5)/100 -> -0.0089875173 | J9: =[1]!thsiFinD("ths_stock_mv_to_fanv_fund",$A9,$J$4)/100 -> 0.15757628 | K9: =[1]!thsiFinD("ths_cb_mv_to_fanv_fund",A9,$J$4)/100 -> 0.0011
A10: 004010.OF | B10: 华泰柏瑞鼎利A | C10: =[1]!thsiFinD("ths_adjustment_nvg_ratio_fund",$A10,B$5,B$5,101)/100 -> 0 | D10: =[1]!thsiFinD("ths_adjustment_nvg_ratio_fund",$A10,D$4,D$5,101)/100 -> 0.0019414962 | E10: =[1]!thsiFinD("ths_adjustment_nvg_ratio_fund",$A10,E$4,E$5,101)/100 -> 0.0031750146 | F10: =-[1]!thsiFinD("ths_max_retrace_rate_all_fund",$A10,F$4,F$5)/100 -> -0.015124095 | J10: =[1]!thsiFinD("ths_stock_mv_to_fanv_fund",$A10,$J$4)/100 -> 0.14024614 | K10: =[1]!thsiFinD("ths_cb_mv_to_fanv_fund",A10,$J$4)/100 -> 0
A11: 009089.OF | B11: 嘉实稳固收益A | C11: =[1]!thsiFinD("ths_adjustment_nvg_ratio_fund",$A11,B$5,B$5,101)/100 -> 0 | D11: =[1]!thsiFinD("ths_adjustment_nvg_ratio_fund",$A11,D$4,D$5,101)/100 -> -0.00089928055 | E11: =[1]!thsiFinD("ths_adjustment_nvg_ratio_fund",$A11,E$4,E$5,101)/100 -> -0.0034249368 | F11: =-[1]!thsiFinD("ths_max_retrace_rate_all_fund",$A11,F$4,F$5)/100 -> -0.022026787 | J11: =1794.92740631104%/100 -> 0.17949274 | K11: =632.57851600647%/100 -> 0.063257852
A12: 000385.OF | B12: 景顺长城景颐双利A | C12: =[1]!thsiFinD("ths_adjustment_nvg_ratio_fund",$A12,B$5,B$5,101)/100 -> 0 | D12: =[1]!thsiFinD("ths_adjustment_nvg_ratio_fund",$A12,D$4,D$5,101)/100 -> -0.0021299255 | E12: =[1]!thsiFinD("ths_adjustment_nvg_ratio_fund",$A12,E$4,E$5,101)/100 -> -0.017304667 | F12: =-[1]!thsiFinD("ths_max_retrace_rate_all_fund",$A12,F$4,F$5)/100 -> -0.024530271 | J12: =[1]!thsiFinD("ths_stock_mv_to_fanv_fund",$A12,$J$4)/100 -> 0.14695484 | K12: =[1]!thsiFinD("ths_cb_mv_to_fanv_fund",A12,$J$4)/100 -> 0.0552
A13: 162210.OF | B13: 宏利集利A | C13: =[1]!thsiFinD("ths_adjustment_nvg_ratio_fund",$A13,B$5,B$5,101)/100 -> 0 | D13: =[1]!thsiFinD("ths_adjustment_nvg_ratio_fund",$A13,D$4,D$5,101)/100 -> -0.0060704768 | E13: =[1]!thsiFinD("ths_adjustment_nvg_ratio_fund",$A13,E$4,E$5,101)/100 -> -0.020500474 | F13: =-[1]!thsiFinD("ths_max_retrace_rate_all_fund",$A13,F$4,F$5)/100 -> -0.039228342 | J13: =[1]!thsiFinD("ths_stock_mv_to_fanv_fund",$A13,$J$4)/100 -> 0.19870188 | K13: =[1]!thsiFinD("ths_cb_mv_to_fanv_fund",A13,$J$4)/100 -> 0.0177
A14: 018595.OF | B14: 华商利欣回报A | C14: =[1]!thsiFinD("ths_adjustment_nvg_ratio_fund",$A14,B$5,B$5,101)/100 -> 0 | D14: =[1]!thsiFinD("ths_adjustment_nvg_ratio_fund",$A14,D$4,D$5,101)/100 -> -0.006322023 | E14: =[1]!thsiFinD("ths_adjustment_nvg_ratio_fund",$A14,E$4,E$5,101)/100 -> -0.016085578 | F14: =-[1]!thsiFinD("ths_max_retrace_rate_all_fund",$A14,F$4,F$5)/100 -> -0.04644491 | J14: =1336.14416122437%/100 -> 0.13361442 | K14: =438.473033905029%/100 -> 0.043847303
A15: 015931.OF | B15: 金鹰恒润A | C15: =[1]!thsiFinD("ths_adjustment_nvg_ratio_fund",$A15,B$5,B$5,101)/100 -> 0 | D15: =[1]!thsiFinD("ths_adjustment_nvg_ratio_fund",$A15,D$4,D$5,101)/100 -> -0.0024726245 | E15: =[1]!thsiFinD("ths_adjustment_nvg_ratio_fund",$A15,E$4,E$5,101)/100 -> -0.043927211 | F15: =-[1]!thsiFinD("ths_max_retrace_rate_all_fund",$A15,F$4,F$5)/100 -> -0.053698584 | J15: =[1]!thsiFinD("ths_stock_mv_to_fanv_fund",$A15,$J$4)/100 -> 0.17988114 | K15: =[1]!thsiFinD("ths_cb_mv_to_fanv_fund",A15,$J$4)/100 -> 0
A16: 014088.OF | B16: 永赢稳健增强A | C16: =[1]!thsiFinD("ths_adjustment_nvg_ratio_fund",$A16,B$5,B$5,101)/100 -> 0 | D16: =[1]!thsiFinD("ths_adjustment_nvg_ratio_fund",$A16,D$4,D$5,101)/100 -> -0.0039104751 | E16: =[1]!thsiFinD("ths_adjustment_nvg_ratio_fund",$A16,E$4,E$5,101)/100 -> -0.041166106 | F16: =-[1]!thsiFinD("ths_max_retrace_rate_all_fund",$A16,F$4,F$5)/100 -> -0.047270412 | J16: =[1]!thsiFinD("ths_stock_mv_to_fanv_fund",$A16,$J$4)/100 -> 0.17522979 | K16: =[1]!thsiFinD("ths_cb_mv_to_fanv_fund",A16,$J$4)/100 -> 0
A17: 002961.OF | B17: 中欧双利A | C17: =[1]!thsiFinD("ths_adjustment_nvg_ratio_fund",$A17,B$5,B$5,101)/100 -> 0 | D17: =[1]!thsiFinD("ths_adjustment_nvg_ratio_fund",$A17,D$4,D$5,101)/100 -> -0.0092592592 | E17: =[1]!thsiFinD("ths_adjustment_nvg_ratio_fund",$A17,E$4,E$5,101)/100 -> -0.047607382 | F17: =-[1]!thsiFinD("ths_max_retrace_rate_all_fund",$A17,F$4,F$5)/100 -> -0.051480156 | J17: =15.2221393585205/100 -> 0.15222139 | K17: =0.108927257359028/100 -> 0.0010892726
A18: 002969.OF | B18: 易方达丰和A | C18: =[1]!thsiFinD("ths_adjustment_nvg_ratio_fund",$A18,B$5,B$5,101)/100 -> 0 | D18: =[1]!thsiFinD("ths_adjustment_nvg_ratio_fund",$A18,D$4,D$5,101)/100 -> -0.0072749318 | E18: =[1]!thsiFinD("ths_adjustment_nvg_ratio_fund",$A18,E$4,E$5,101)/100 -> -0.043013266 | F18: =-[1]!thsiFinD("ths_max_retrace_rate_all_fund",$A18,F$4,F$5)/100 -> -0.070577399 | J18: =[1]!thsiFinD("ths_stock_mv_to_fanv_fund",$A18,$J$4)/100 -> 0.16691488 | K18: =[1]!thsiFinD("ths_cb_mv_to_fanv_fund",A18,$J$4)/100 -> 0.0212
A19: 000143.OF | B19: 鹏华双债加利A | C19: =[1]!thsiFinD("ths_adjustment_nvg_ratio_fund",$A19,B$5,B$5,101)/100 -> 0 | D19: =[1]!thsiFinD("ths_adjustment_nvg_ratio_fund",$A19,D$4,D$5,101)/100 -> -0.0051326704 | E19: =[1]!thsiFinD("ths_adjustment_nvg_ratio_fund",$A19,E$4,E$5,101)/100 -> -0.041079553 | F19: =-[1]!thsiFinD("ths_max_retrace_rate_all_fund",$A19,F$4,F$5)/100 -> -0.06090571 | J19: =[1]!thsiFinD("ths_stock_mv_to_fanv_fund",$A19,$J$4)/100 -> 0.18988203 | K19: =[1]!thsiFinD("ths_cb_mv_to_fanv_fund",A19,$J$4)/100 -> 0.0644
A20: 470010.OF | B20: 汇添富多元收益A | C20: =[1]!thsiFinD("ths_adjustment_nvg_ratio_fund",$A20,B$5,B$5,101)/100 -> 0 | D20: =[1]!thsiFinD("ths_adjustment_nvg_ratio_fund",$A20,D$4,D$5,101)/100 -> -0.0074683632 | E20: =[1]!thsiFinD("ths_adjustment_nvg_ratio_fund",$A20,E$4,E$5,101)/100 -> -0.067911322 | F20: =-[1]!thsiFinD("ths_max_retrace_rate_all_fund",$A20,F$4,F$5)/100 -> -0.080169443 | J20: =1336.14416122437%/100 -> 0.13361442 | K20: =438.473033905029%/100 -> 0.043847303
A21: 160718.OF | B21: 嘉实多利收益A | C21: =[1]!thsiFinD("ths_adjustment_nvg_ratio_fund",$A21,B$5,B$5,101)/100 -> 0 | D21: =[1]!thsiFinD("ths_adjustment_nvg_ratio_fund",$A21,D$4,D$5,101)/100 -> -0.012644365 | E21: =[1]!thsiFinD("ths_adjustment_nvg_ratio_fund",$A21,E$4,E$5,101)/100 -> -0.063196675 | F21: =-[1]!thsiFinD("ths_max_retrace_rate_all_fund",$A21,F$4,F$5)/100 -> -0.079686479 | J21: =[1]!thsiFinD("ths_stock_mv_to_fanv_fund",$A21,$J$4)/100 -> 0.2003817 | K21: =[1]!thsiFinD("ths_cb_mv_to_fanv_fund",A21,$J$4)/100 -> 0.1094
A22: 003504.OF | B22: 景顺长城景颐丰利A | C22: =[1]!thsiFinD("ths_adjustment_nvg_ratio_fund",$A22,B$5,B$5,101)/100 -> 0 | D22: =[1]!thsiFinD("ths_adjustment_nvg_ratio_fund",$A22,D$4,D$5,101)/100 -> -0.010266302 | E22: =[1]!thsiFinD("ths_adjustment_nvg_ratio_fund",$A22,E$4,E$5,101)/100 -> -0.071124088 | F22: =-[1]!thsiFinD("ths_max_retrace_rate_all_fund",$A22,F$4,F$5)/100 -> -0.078192169 | J22: =[1]!thsiFinD("ths_stock_mv_to_fanv_fund",$A22,$J$4)/100 -> 0.20399724 | K22: =[1]!thsiFinD("ths_cb_mv_to_fanv_fund",A22,$J$4)/100 -> 0.0779
B23: 注：1090基石投顾组合2026/06/18上线，内部数据请勿外发，历史数据仅供参考，不代表未来收益

Sheet vs红利固收+
B3: =日期页!B5 -> 46295 | C3: =VLOOKUP(B3,实盘组合净值!$A:$V,20,0) -> 0.99871448
B4: =日期页!B3 -> 46303 | C4: =VLOOKUP(B4,实盘组合净值!$A:$V,20,0) -> 0.99682887 | D4: =日期页!B4 -> 46303 | E4: 46282 | F4: =E4 -> 46282 | J4: 46203
B5: =日期页!B2 -> 46304 | C5: =VLOOKUP(B5,实盘组合净值!$A:$V,20,0) -> 0.99680693 | D5: =B5 -> 46304 | E5: =B5 -> 46304 | F5: =B5 -> 46304
A6: 基金代码 | B6: =B5 -> 46304 | C6: 日涨跌 | D6: 本周以来 | E6: 上线以来 | F6: 最大回撤 | I6: 类型 | J6: 权益中枢 /股票仓位 | K6: 转债仓位
B7: 20/80基石投顾账户 | C7: =C5/C4-1 -> -2.2005708e-05 | D7: =C5/C3-1 -> -0.0019100001 | E7: =C5-1 -> -0.0031930669 | F7: =MIN(实盘组合净值!V:V) -> -0.0071263838 | I7: 20/80配置样板间 | J7: 0.2 | K7: 5%黄金
A8: 002065.OF | B8: =[1]!thsiFinD("ths_fund_short_name_fund",A8) -> 景顺长城景盛双息收益债券A | C8: =[1]!thsiFinD("ths_adjustment_nvg_ratio_fund",$A8,B$5,B$5,101)/100 -> 0 | D8: =[1]!thsiFinD("ths_adjustment_nvg_ratio_fund",$A8,D$4,D$5,101)/100 -> 0 | E8: =[1]!thsiFinD("ths_adjustment_nvg_ratio_fund",$A8,E$4,E$5,101)/100 -> -0.004691165 | F8: =-[1]!thsiFinD("ths_max_retrace_rate_all_fund",$A8,F$4,F$5)/100 -> -0.006245121 | J8: =[1]!thsiFinD("ths_stock_mv_to_fanv_fund",$A8,$J$4)/100 -> 0.1366676 | K8: =[1]!thsiFinD("ths_cb_mv_to_fanv_fund",A8,$J$4)/100 -> 0.0564
A9: 010011.OF | B9: =[1]!thsiFinD("ths_fund_short_name_fund",A9) -> 景顺长城景颐招利6个月持有期债券A | C9: =[1]!thsiFinD("ths_adjustment_nvg_ratio_fund",$A9,B$5,B$5,101)/100 -> 0 | D9: =[1]!thsiFinD("ths_adjustment_nvg_ratio_fund",$A9,D$4,D$5,101)/100 -> 0.00022466866 | E9: =[1]!thsiFinD("ths_adjustment_nvg_ratio_fund",$A9,E$4,E$5,101)/100 -> -0.0019429083 | F9: =-[1]!thsiFinD("ths_max_retrace_rate_all_fund",$A9,F$4,F$5)/100 -> -0.0041803524 | J9: =[1]!thsiFinD("ths_stock_mv_to_fanv_fund",$A9,$J$4)/100 -> 0.13889673 | K9: =[1]!thsiFinD("ths_cb_mv_to_fanv_fund",A9,$J$4)/100 -> 0.0454
A10: 010118.OF | B10: =[1]!thsiFinD("ths_fund_short_name_fund",A10) -> 天弘多元收益债券A | C10: =[1]!thsiFinD("ths_adjustment_nvg_ratio_fund",$A10,B$5,B$5,101)/100 -> 0 | D10: =[1]!thsiFinD("ths_adjustment_nvg_ratio_fund",$A10,D$4,D$5,101)/100 -> 0.00077931279 | E10: =[1]!thsiFinD("ths_adjustment_nvg_ratio_fund",$A10,E$4,E$5,101)/100 -> 0.0026261623 | F10: =-[1]!thsiFinD("ths_max_retrace_rate_all_fund",$A10,F$4,F$5)/100 -> -0.0028399006 | J10: =[1]!thsiFinD("ths_stock_mv_to_fanv_fund",$A10,$J$4)/100 -> 0.19775965 | K10: =[1]!thsiFinD("ths_cb_mv_to_fanv_fund",A10,$J$4)/100 -> 0.1863
A11: 002925.OF | B11: =[1]!thsiFinD("ths_fund_short_name_fund",A11) -> 广发集源债券A | C11: =[1]!thsiFinD("ths_adjustment_nvg_ratio_fund",$A11,B$5,B$5,101)/100 -> 0 | D11: =[1]!thsiFinD("ths_adjustment_nvg_ratio_fund",$A11,D$4,D$5,101)/100 -> 0.00083759108 | E11: =[1]!thsiFinD("ths_adjustment_nvg_ratio_fund",$A11,E$4,E$5,101)/100 -> 0.0025169896 | F11: =-[1]!thsiFinD("ths_max_retrace_rate_all_fund",$A11,F$4,F$5)/100 -> -0.0014254569 | J11: =1794.92740631104%/100 -> 0.17949274 | K11: =632.57851600647%/100 -> 0.063257852
A12: 110008.OF | B12: =[1]!thsiFinD("ths_fund_short_name_fund",A12) -> 易方达稳健收益债券B | C12: =[1]!thsiFinD("ths_adjustment_nvg_ratio_fund",$A12,B$5,B$5,101)/100 -> 0 | D12: =[1]!thsiFinD("ths_adjustment_nvg_ratio_fund",$A12,D$4,D$5,101)/100 -> -0.0023913349 | E12: =[1]!thsiFinD("ths_adjustment_nvg_ratio_fund",$A12,E$4,E$5,101)/100 -> 0.0016949153 | F12: =-[1]!thsiFinD("ths_max_retrace_rate_all_fund",$A12,F$4,F$5)/100 -> -0.0047014245 | J12: =[1]!thsiFinD("ths_stock_mv_to_fanv_fund",$A12,$J$4)/100 -> 0.19788436 | K12: =[1]!thsiFinD("ths_cb_mv_to_fanv_fund",A12,$J$4)/100 -> 0.0393
A13: 110017.OF | B13: =[1]!thsiFinD("ths_fund_short_name_fund",A13) -> 易方达增强回报债券A | C13: =[1]!thsiFinD("ths_adjustment_nvg_ratio_fund",$A13,B$5,B$5,101)/100 -> 0 | D13: =[1]!thsiFinD("ths_adjustment_nvg_ratio_fund",$A13,D$4,D$5,101)/100 -> 7.1500064e-05 | E13: =[1]!thsiFinD("ths_adjustment_nvg_ratio_fund",$A13,E$4,E$5,101)/100 -> 0.0012168933 | F13: =-[1]!thsiFinD("ths_max_retrace_rate_all_fund",$A13,F$4,F$5)/100 -> -0.0021428571 | J13: =1794.92740631104%/100 -> 0.17949274 | K13: =632.57851600647%/100 -> 0.063257852
B14: 注：2080基石投顾组合2026/09/17上线，内部数据请勿外发，历史数据仅供参考，不代表未来收益

Sheet vs招行
B2: 本周一 | D2: =日期页!B4 -> 46303 | E2: =VLOOKUP(D2,实盘组合净值!$A:$S,14,0) -> 0.98376778
B3: 上周五 | D3: =日期页!B5 -> 46295 | E3: =VLOOKUP(D3,实盘组合净值!$A:$S,14,0) -> 0.98823708
D4: =日期页!B9 -> 46294 | E4: =VLOOKUP(D4,实盘组合净值!$A:$S,14,0) -> 0.98955409 | F4: =D2 -> 46303 | G4: =日期页!B6 -> 46195 | H4: =G4 -> 46195
D5: =日期页!B10 -> 46295 | E5: =VLOOKUP(D5,实盘组合净值!$A:$S,14,0) -> 0.98823708 | F5: =D5 -> 46295 | G5: =D5 -> 46295 | H5: =D5 -> 46295
A6: 类型 | B6: 权益中枢 | C6: 基金代码 | D6: =D5 -> 46295 | E6: 日涨跌 | F6: 本周以来 | G6: 上线以来 | H6: 最大回撤
A7: 10/90投顾样板间 | B7: 0.1 | D7: 10-90基石投顾账户 | E7: =E5/E4-1 -> -0.0013309119 | F7: =E5/E3-1 -> 0 | G7: =E5-1 -> -0.011762923 | H7: =MIN(实盘组合净值!P:P) -> -0.028729069
A8: 招行长盈计划-安稳盈 | B8: ≤15% | C8: 016768.OF | D8: =[1]!thsiFinD("ths_fund_official_short_name_fund",C8) -> 华安盈瑞稳健优选6个月持有混合(FOF)A | E8: =[1]!thsiFinD("ths_adjustment_nvg_rate_fund",C8,$D$5)/100 -> 0.00064208401 | F8: =[1]!thsiFinD("ths_adjustment_nvg_ratio_fund",$C8,F$4,F$5,101)/100 -> 0 | G8: =[1]!thsiFinD("ths_adjustment_nvg_ratio_fund",$C8,G$4,G$5,101)/100 -> -0.0068128266 | H8: =-[1]!thsiFinD("ths_max_retrace_rate_all_fund",$C8,H$4,H$5)/100 -> -0.0097720423
C9: 025218.OF | D9: =[1]!thsiFinD("ths_fund_official_short_name_fund",C9) -> 中欧盈欣稳健6个月持有混合(FOF)A | E9: =[1]!thsiFinD("ths_adjustment_nvg_rate_fund",C9,$D$5)/100 -> 0.00039932115 | F9: =[1]!thsiFinD("ths_adjustment_nvg_ratio_fund",$C9,F$4,F$5,101)/100 -> 0 | G9: =[1]!thsiFinD("ths_adjustment_nvg_ratio_fund",$C9,G$4,G$5,101)/100 -> 0.00069902137 | H9: =-[1]!thsiFinD("ths_max_retrace_rate_all_fund",$C9,H$4,H$5)/100 -> -0.0052631579
C10: 022978.OF | D10: =[1]!thsiFinD("ths_fund_official_short_name_fund",C10) -> 博时臻选楚汇三个月持有债券(FOF)B | E10: =[1]!thsiFinD("ths_adjustment_nvg_rate_fund",C10,$D$5)/100 -> 0.0011072153 | F10: =[1]!thsiFinD("ths_adjustment_nvg_ratio_fund",$C10,F$4,F$5,101)/100 -> 0 | G10: =[1]!thsiFinD("ths_adjustment_nvg_ratio_fund",$C10,G$4,G$5,101)/100 -> -0.0076137244 | H10: =-[1]!thsiFinD("ths_max_retrace_rate_all_fund",$C10,H$4,H$5)/100 -> -0.012392929
C11: 017587.OF | D11: =[1]!thsiFinD("ths_fund_official_short_name_fund",C11) -> 中欧盈选稳健6个月持有混合发起(FOF)A | E11: =[1]!thsiFinD("ths_adjustment_nvg_rate_fund",C11,$D$5)/100 -> 0.00038113386 | F11: =[1]!thsiFinD("ths_adjustment_nvg_ratio_fund",$C11,F$4,F$5,101)/100 -> 0 | G11: =[1]!thsiFinD("ths_adjustment_nvg_ratio_fund",$C11,G$4,G$5,101)/100 -> 0.0010452463 | H11: =-[1]!thsiFinD("ths_max_retrace_rate_all_fund",$C11,H$4,H$5)/100 -> -0.0052132702
C12: 026682.OF | D12: =[1]!thsiFinD("ths_fund_official_short_name_fund",C12) -> 博时盈泰臻选6个月持有期混合(FOF)A | E12: =[1]!thsiFinD("ths_adjustment_nvg_rate_fund",C12,$D$5)/100 -> 0.0014093014 | F12: =[1]!thsiFinD("ths_adjustment_nvg_ratio_fund",$C12,F$4,F$5,101)/100 -> 0 | G12: =[1]!thsiFinD("ths_adjustment_nvg_ratio_fund",$C12,G$4,G$5,101)/100 -> -0.0059952038 | H12: =-[1]!thsiFinD("ths_max_retrace_rate_all_fund",$C12,H$4,H$5)/100 -> -0.012328495
A13: 招行长盈计划-安定盈 | B13: ≤25% | C13: 025822.OF | D13: =[1]!thsiFinD("ths_fund_official_short_name_fund",C13) -> 易方达如意盈安6个月持有混合发起式(FOF)A | E13: =[1]!thsiFinD("ths_adjustment_nvg_rate_fund",C13,$D$5)/100 -> 0.00089534421 | F13: =[1]!thsiFinD("ths_adjustment_nvg_ratio_fund",$C13,F$4,F$5,101)/100 -> 0 | G13: =[1]!thsiFinD("ths_adjustment_nvg_ratio_fund",$C13,G$4,G$5,101)/100 -> -0.014882992 | H13: =-[1]!thsiFinD("ths_max_retrace_rate_all_fund",$C13,H$4,H$5)/100 -> -0.022235225
C14: 018312.OF | D14: =[1]!thsiFinD("ths_fund_official_short_name_fund",C14) -> 易方达如意安诚六个月持有混合(FOF)A | E14: =[1]!thsiFinD("ths_adjustment_nvg_rate_fund",C14,$D$5)/100 -> 0.00099619635 | F14: =[1]!thsiFinD("ths_adjustment_nvg_ratio_fund",$C14,F$4,F$5,101)/100 -> 0 | G14: =[1]!thsiFinD("ths_adjustment_nvg_ratio_fund",$C14,G$4,G$5,101)/100 -> -0.016191952 | H14: =-[1]!thsiFinD("ths_max_retrace_rate_all_fund",$C14,H$4,H$5)/100 -> -0.023234627
A15: 注：1090基石投顾组合2026/06/18上线，内部数据请勿外发，历史数据仅供参考，不代表未来收益

Sheet vs固收+对比
E1: =VLOOKUP(E4,实盘组合净值!$A:$P,14) -> 1.0008955 | F1: =VLOOKUP(F4,实盘组合净值!$A:$P,14) -> 1.0008955 | G1: =VLOOKUP(G4,实盘组合净值!$A:$P,14) -> 0.974836
E2: =VLOOKUP(E5,实盘组合净值!$A:$P,14) -> 0.98375427 | F2: =VLOOKUP(F5,实盘组合净值!$A:$P,14) -> 0.97390321 | G2: =VLOOKUP(G5,实盘组合净值!$A:$P,14) -> 0.98375427
E3: 46191 | F3: 46191 | G3: 46234
E4: 46195 | F4: 46195 | G4: 46237
E5: =日期页!B2 -> 46304 | F5: 46233 | G5: =E5 -> 46304
C6: 公募固收+规模前十（2026Q2）基金表现
A7: 序号 | B7: 基金代码 | C7: 产品/基金名称 | D7: 26Q2规模（亿元） | E7: 上线以来 | F7: 6/22-7/30 | G7: 7.31至今 | H7: 最大回撤（上线以来）
A8: 组合 | C8: 10/90基石投顾组合 | E8: =E$2/E$1-1 -> -0.017125928 | F8: =F$2/F$1-1 -> -0.026968171 | G8: =G$2/G$1-1 -> 0.0091484807 | H8: ='vs固收+'!F7 -> -0.028729069
A9: 1 | B9: 003504.OF | C9: 景顺长城景颐丰利债券 | D9: 712 | E9: =[1]!thsiFinD("ths_adjustment_nvg_ratio_fund",$B9,E$4,E$5,101)/100 -> -0.071124088 | F9: =[1]!thsiFinD("ths_adjustment_nvg_ratio_fund",$B9,F$4,F$5,101)/100 -> -0.07340146 | G9: =[1]!thsiFinD("ths_adjustment_nvg_ratio_fund",$B9,G$4,G$5,101)/100 -> -0.0068677031 | H9: =-[1]!thsiFinD("ths_max_retrace_rate_all_fund",$B9,E$3,E$5)/100 -> -0.078192169
A10: 2 | B10: 000143.OF | C10: 鹏华双债加利债券 | D10: 584 | E10: =[1]!thsiFinD("ths_adjustment_nvg_ratio_fund",$B10,E$4,E$5,101)/100 -> -0.041079553 | F10: =[1]!thsiFinD("ths_adjustment_nvg_ratio_fund",$B10,F$4,F$5,101)/100 -> -0.051945757 | G10: =[1]!thsiFinD("ths_adjustment_nvg_ratio_fund",$B10,G$4,G$5,101)/100 -> 0.0043488318 | H10: =-[1]!thsiFinD("ths_max_retrace_rate_all_fund",$B10,E$3,E$5)/100 -> -0.06090571
A11: 3 | B11: 000385.OF | C11: 景顺长城景颐双利债券 | D11: 576 | E11: =[1]!thsiFinD("ths_adjustment_nvg_ratio_fund",$B11,E$4,E$5,101)/100 -> -0.017304667 | F11: =[1]!thsiFinD("ths_adjustment_nvg_ratio_fund",$B11,F$4,F$5,101)/100 -> -0.01363398 | G11: =[1]!thsiFinD("ths_adjustment_nvg_ratio_fund",$B11,G$4,G$5,101)/100 -> -0.0053078556 | H11: =-[1]!thsiFinD("ths_max_retrace_rate_all_fund",$B11,E$3,E$5)/100 -> -0.024530271
A12: 4 | B12: 002065.OF | C12: 景顺长城景盛双息收益债券 | D12: 393 | E12: =[1]!thsiFinD("ths_adjustment_nvg_ratio_fund",$B12,E$4,E$5,101)/100 -> 0.015961692 | F12: =[1]!thsiFinD("ths_adjustment_nvg_ratio_fund",$B12,F$4,F$5,101)/100 -> 0.015961692 | G12: =[1]!thsiFinD("ths_adjustment_nvg_ratio_fund",$B12,G$4,G$5,101)/100 -> -0.0023510972 | H12: =-[1]!thsiFinD("ths_max_retrace_rate_all_fund",$B12,E$3,E$5)/100 -> -0.019857029
A13: 5 | B13: 002969.OF | C13: 易方达丰和债券 | D13: 391 | E13: =[1]!thsiFinD("ths_adjustment_nvg_ratio_fund",$B13,E$4,E$5,101)/100 -> -0.043013266 | F13: =[1]!thsiFinD("ths_adjustment_nvg_ratio_fund",$B13,F$4,F$5,101)/100 -> -0.056454912 | G13: =[1]!thsiFinD("ths_adjustment_nvg_ratio_fund",$B13,G$4,G$5,101)/100 -> 0.0051562212 | H13: =-[1]!thsiFinD("ths_max_retrace_rate_all_fund",$B13,E$3,E$5)/100 -> -0.070577399
A14: 6 | B14: 014088.OF | C14: 永赢稳健增强债券 | D14: 365 | E14: =[1]!thsiFinD("ths_adjustment_nvg_ratio_fund",$B14,E$4,E$5,101)/100 -> -0.041166106 | F14: =[1]!thsiFinD("ths_adjustment_nvg_ratio_fund",$B14,F$4,F$5,101)/100 -> -0.039484222 | G14: =[1]!thsiFinD("ths_adjustment_nvg_ratio_fund",$B14,G$4,G$5,101)/100 -> -0.0070498466 | H14: =-[1]!thsiFinD("ths_max_retrace_rate_all_fund",$B14,E$3,E$5)/100 -> -0.047270412
A15: 7 | B15: 001751.OF | C15: 华商信用增强债券 | D15: 361 | E15: =[1]!thsiFinD("ths_adjustment_nvg_ratio_fund",$B15,E$4,E$5,101)/100 -> -0.038948393 | F15: =[1]!thsiFinD("ths_adjustment_nvg_ratio_fund",$B15,F$4,F$5,101)/100 -> -0.02872444 | G15: =[1]!thsiFinD("ths_adjustment_nvg_ratio_fund",$B15,G$4,G$5,101)/100 -> -0.01888668 | H15: =-[1]!thsiFinD("ths_max_retrace_rate_all_fund",$B15,E$3,E$5)/100 -> -0.059552168
A16: 8 | B16: 014846.OF | C16: 博时恒乐债券 | D16: 359 | E16: =[1]!thsiFinD("ths_adjustment_nvg_ratio_fund",$B16,E$4,E$5,101)/100 -> -0.021633659 | F16: =[1]!thsiFinD("ths_adjustment_nvg_ratio_fund",$B16,F$4,F$5,101)/100 -> -0.016463851 | G16: =[1]!thsiFinD("ths_adjustment_nvg_ratio_fund",$B16,G$4,G$5,101)/100 -> -0.0062207142 | H16: =-[1]!thsiFinD("ths_max_retrace_rate_all_fund",$B16,E$3,E$5)/100 -> -0.035971787
A17: 9 | B17: 000171.OF | C17: 易方达裕丰回报债券 | D17: 342 | E17: =[1]!thsiFinD("ths_adjustment_nvg_ratio_fund",$B17,E$4,E$5,101)/100 -> -0.053317865 | F17: =[1]!thsiFinD("ths_adjustment_nvg_ratio_fund",$B17,F$4,F$5,101)/100 -> -0.048259861 | G17: =[1]!thsiFinD("ths_adjustment_nvg_ratio_fund",$B17,G$4,G$5,101)/100 -> -0.010620757 | H17: =-[1]!thsiFinD("ths_max_retrace_rate_all_fund",$B17,E$3,E$5)/100 -> -0.068447489
A18: 10 | B18: 202101.OF | C18: 南方宝元债券 | D18: 314 | E18: =[1]!thsiFinD("ths_adjustment_nvg_ratio_fund",$B18,E$4,E$5,101)/100 -> -0.017774716 | F18: =[1]!thsiFinD("ths_adjustment_nvg_ratio_fund",$B18,F$4,F$5,101)/100 -> -0.00072338959 | G18: =[1]!thsiFinD("ths_adjustment_nvg_ratio_fund",$B18,G$4,G$5,101)/100 -> -0.017436251 | H18: =-[1]!thsiFinD("ths_max_retrace_rate_all_fund",$B18,E$3,E$5)/100 -> -0.028083945
C21: 公募固收+Q2规模增长前十基金表现
A22: =表3[[#Headers],[序号]] -> 序号 | B22: =表3[[#Headers],[基金代码]] -> 基金代码 | C22: =表3[[#Headers],[产品/基金名称]] -> 产品/基金名称 | D22: =表3[[#Headers],[26Q2规模（亿元）]] -> 26Q2规模（亿元） | E22: =表3[[#Headers],[上线以来]] -> 上线以来 | F22: =表3[[#Headers],[6/22-7/30]] -> 6/22-7/30 | G22: =表3[[#Headers],[7.31至今]] -> 7.31至今 | H22: =表3[[#Headers],[最大回撤（上线以来）]] -> 最大回撤（上线以来）
A23: 组合 | C23: =C8 -> 10/90基石投顾组合 | E23: =E$2/E$1-1 -> -0.017125928 | F23: =F$2/F$1-1 -> -0.026968171 | G23: =G$2/G$1-1 -> 0.0091484807 | H23: ='vs固收+'!F7 -> -0.028729069
A24: 1 | B24: 003504.OF | C24: 景顺长城景颐丰利债券 | D24: 391 | E24: =[1]!thsiFinD("ths_adjustment_nvg_ratio_fund",$B24,E$4,E$5,101)/100 -> -0.071124088 | F24: =[1]!thsiFinD("ths_adjustment_nvg_ratio_fund",$B24,F$4,F$5,101)/100 -> -0.07340146 | G24: =[1]!thsiFinD("ths_adjustment_nvg_ratio_fund",$B24,G$4,G$5,101)/100 -> -0.0068677031 | H24: =-[1]!thsiFinD("ths_max_retrace_rate_all_fund",$B24,E$3,E$5)/100 -> -0.078192169
A25: 2 | B25: 002969.OF | C25: 易方达丰和债券 | D25: 347 | E25: =[1]!thsiFinD("ths_adjustment_nvg_ratio_fund",$B25,E$4,E$5,101)/100 -> -0.043013266 | F25: =[1]!thsiFinD("ths_adjustment_nvg_ratio_fund",$B25,F$4,F$5,101)/100 -> -0.056454912 | G25: =[1]!thsiFinD("ths_adjustment_nvg_ratio_fund",$B25,G$4,G$5,101)/100 -> 0.0051562212 | H25: =-[1]!thsiFinD("ths_max_retrace_rate_all_fund",$B25,E$3,E$5)/100 -> -0.070577399
A26: 3 | B26: 470010.OF | C26: 汇添富多元收益债券 | D26: 255 | E26: =[1]!thsiFinD("ths_adjustment_nvg_ratio_fund",$B26,E$4,E$5,101)/100 -> -0.067911322 | F26: =[1]!thsiFinD("ths_adjustment_nvg_ratio_fund",$B26,F$4,F$5,101)/100 -> -0.053754485 | G26: =[1]!thsiFinD("ths_adjustment_nvg_ratio_fund",$B26,G$4,G$5,101)/100 -> -0.021454222 | H26: =-[1]!thsiFinD("ths_max_retrace_rate_all_fund",$B26,E$3,E$5)/100 -> -0.080169443
A27: 4 | B27: 000143.OF | C27: 鹏华双债加利债券 | D27: 228 | E27: =[1]!thsiFinD("ths_adjustment_nvg_ratio_fund",$B27,E$4,E$5,101)/100 -> -0.041079553 | F27: =[1]!thsiFinD("ths_adjustment_nvg_ratio_fund",$B27,F$4,F$5,101)/100 -> -0.051945757 | G27: =[1]!thsiFinD("ths_adjustment_nvg_ratio_fund",$B27,G$4,G$5,101)/100 -> 0.0043488318 | H27: =-[1]!thsiFinD("ths_max_retrace_rate_all_fund",$B27,E$3,E$5)/100 -> -0.06090571
A28: 5 | B28: 000406.OF | C28: 汇添富双利增强债券 | D28: 172 | E28: =[1]!thsiFinD("ths_adjustment_nvg_ratio_fund",$B28,E$4,E$5,101)/100 -> -0.03271703 | F28: =[1]!thsiFinD("ths_adjustment_nvg_ratio_fund",$B28,F$4,F$5,101)/100 -> -0.04058934 | G28: =[1]!thsiFinD("ths_adjustment_nvg_ratio_fund",$B28,G$4,G$5,101)/100 -> 0.006462764 | H28: =-[1]!thsiFinD("ths_max_retrace_rate_all_fund",$B28,E$3,E$5)/100 -> -0.050897344
A29: 6 | B29: 000171.OF | C29: 易方达裕丰回报债券 | D29: 146 | E29: =[1]!thsiFinD("ths_adjustment_nvg_ratio_fund",$B29,E$4,E$5,101)/100 -> -0.053317865 | F29: =[1]!thsiFinD("ths_adjustment_nvg_ratio_fund",$B29,F$4,F$5,101)/100 -> -0.048259861 | G29: =[1]!thsiFinD("ths_adjustment_nvg_ratio_fund",$B29,G$4,G$5,101)/100 -> -0.010620757 | H29: =-[1]!thsiFinD("ths_max_retrace_rate_all_fund",$B29,E$3,E$5)/100 -> -0.068447489
A30: 7 | B30: 018595.OF | C30: 华商利欣回报债券 | D30: 130 | E30: =[1]!thsiFinD("ths_adjustment_nvg_ratio_fund",$B30,E$4,E$5,101)/100 -> -0.016085578 | F30: =[1]!thsiFinD("ths_adjustment_nvg_ratio_fund",$B30,F$4,F$5,101)/100 -> -0.022028526 | G30: =[1]!thsiFinD("ths_adjustment_nvg_ratio_fund",$B30,G$4,G$5,101)/100 -> -0.00040251167 | H30: =-[1]!thsiFinD("ths_max_retrace_rate_all_fund",$B30,E$3,E$5)/100 -> -0.04644491
A31: 8 | B31: 001751.OF | C31: 华商信用增强债券 | D31: 123 | E31: =[1]!thsiFinD("ths_adjustment_nvg_ratio_fund",$B31,E$4,E$5,101)/100 -> -0.038948393 | F31: =[1]!thsiFinD("ths_adjustment_nvg_ratio_fund",$B31,F$4,F$5,101)/100 -> -0.02872444 | G31: =[1]!thsiFinD("ths_adjustment_nvg_ratio_fund",$B31,G$4,G$5,101)/100 -> -0.01888668 | H31: =-[1]!thsiFinD("ths_max_retrace_rate_all_fund",$B31,E$3,E$5)/100 -> -0.059552168
A32: 9 | B32: 020218.OF | C32: 万家锦利债券发起式 | D32: 120 | E32: =[1]!thsiFinD("ths_adjustment_nvg_ratio_fund",$B32,E$4,E$5,101)/100 -> -0.055609677 | F32: =[1]!thsiFinD("ths_adjustment_nvg_ratio_fund",$B32,F$4,F$5,101)/100 -> -0.047978568 | G32: =[1]!thsiFinD("ths_adjustment_nvg_ratio_fund",$B32,G$4,G$5,101)/100 -> -0.011975539 | H32: =-[1]!thsiFinD("ths_max_retrace_rate_all_fund",$B32,E$3,E$5)/100 -> -0.063516342
A33: 10 | B33: 014846.OF | C33: 博时恒乐债券 | D33: 114 | E33: =[1]!thsiFinD("ths_adjustment_nvg_ratio_fund",$B33,E$4,E$5,101)/100 -> -0.021633659 | F33: =[1]!thsiFinD("ths_adjustment_nvg_ratio_fund",$B33,F$4,F$5,101)/100 -> -0.016463851 | G33: =[1]!thsiFinD("ths_adjustment_nvg_ratio_fund",$B33,G$4,G$5,101)/100 -> -0.0062207142 | H33: =-[1]!thsiFinD("ths_max_retrace_rate_all_fund",$B33,E$3,E$5)/100 -> -0.035971787
C36: 公司公募固收+保有前十基金表现（2026Q2）
A37: =A22 -> 序号 | B37: =B22 -> 基金代码 | C37: =C22 -> 产品/基金名称 | D37: 公司固收加保有前十（万元） | E37: =E22 -> 上线以来 | F37: =F22 -> 6/22-7/30 | G37: =G22 -> 7.31至今 | H37: =H22 -> 最大回撤（上线以来）
A38: 组合 | C38: =C8 -> 10/90基石投顾组合 | E38: =E$2/E$1-1 -> -0.017125928 | F38: =F$2/F$1-1 -> -0.026968171 | G38: =G$2/G$1-1 -> 0.0091484807 | H38: ='vs固收+'!F7 -> -0.028729069
A39: 1 | B39: 009355.OF | C39: 宏利泰和稳健养老目标一年持有期混合(FOF) | D39: 5265 | E39: =[1]!thsiFinD("ths_adjustment_nvg_ratio_fund",$B39,E$4,E$5,101)/100 -> -0.011868616 | F39: =[1]!thsiFinD("ths_adjustment_nvg_ratio_fund",$B39,F$4,F$5,101)/100 -> -0.018110759 | G39: =[1]!thsiFinD("ths_adjustment_nvg_ratio_fund",$B39,G$4,G$5,101)/100 -> 0.0027146865 | H39: =-[1]!thsiFinD("ths_max_retrace_rate_all_fund",$B39,E$3,E$5)/100 -> -0.018873622
A40: 2 | B40: 024057.OF | C40: 宏利鼎森稳健3个月持有期混合(FOF) | D40: 896 | E40: =[1]!thsiFinD("ths_adjustment_nvg_ratio_fund",$B40,E$4,E$5,101)/100 -> -0.0017711306 | F40: =[1]!thsiFinD("ths_adjustment_nvg_ratio_fund",$B40,F$4,F$5,101)/100 -> -0.012397914 | G40: =[1]!thsiFinD("ths_adjustment_nvg_ratio_fund",$B40,G$4,G$5,101)/100 -> 0.0077480878 | H40: =-[1]!thsiFinD("ths_max_retrace_rate_all_fund",$B40,E$3,E$5)/100 -> -0.013283479
A41: 3 | B41: 011168.OF | C41: 嘉实睿享安久双利18个月持有期债券 | D41: 239 | E41: =[1]!thsiFinD("ths_adjustment_nvg_ratio_fund",$B41,E$4,E$5,101)/100 -> -0.034421172 | F41: =[1]!thsiFinD("ths_adjustment_nvg_ratio_fund",$B41,F$4,F$5,101)/100 -> -0.026627699 | G41: =[1]!thsiFinD("ths_adjustment_nvg_ratio_fund",$B41,G$4,G$5,101)/100 -> -0.0099883469 | H41: =-[1]!thsiFinD("ths_max_retrace_rate_all_fund",$B41,E$3,E$5)/100 -> -0.054981726
A42: 4 | B42: 002969.OF | C42: 易方达丰和债券 | D42: 225 | E42: =[1]!thsiFinD("ths_adjustment_nvg_ratio_fund",$B42,E$4,E$5,101)/100 -> -0.043013266 | F42: =[1]!thsiFinD("ths_adjustment_nvg_ratio_fund",$B42,F$4,F$5,101)/100 -> -0.056454912 | G42: =[1]!thsiFinD("ths_adjustment_nvg_ratio_fund",$B42,G$4,G$5,101)/100 -> 0.0051562212 | H42: =-[1]!thsiFinD("ths_max_retrace_rate_all_fund",$B42,E$3,E$5)/100 -> -0.070577399
A43: 5 | B43: 014738.OF | C43: 广发恒祥债券 | D43: 205 | E43: =[1]!thsiFinD("ths_adjustment_nvg_ratio_fund",$B43,E$4,E$5,101)/100 -> -0.046935442 | F43: =[1]!thsiFinD("ths_adjustment_nvg_ratio_fund",$B43,F$4,F$5,101)/100 -> -0.029313161 | G43: =[1]!thsiFinD("ths_adjustment_nvg_ratio_fund",$B43,G$4,G$5,101)/100 -> -0.016063188 | H43: =-[1]!thsiFinD("ths_max_retrace_rate_all_fund",$B43,E$3,E$5)/100 -> -0.069804514
A44: 6 | B44: 006307.OF | C44: 嘉实养老目标日期2040五年持有期混合(FOF) | D44: 190 | E44: =[1]!thsiFinD("ths_adjustment_nvg_ratio_fund",$B44,E$4,E$5,101)/100 -> -0.07303155 | F44: =[1]!thsiFinD("ths_adjustment_nvg_ratio_fund",$B44,F$4,F$5,101)/100 -> -0.093443073 | G44: =[1]!thsiFinD("ths_adjustment_nvg_ratio_fund",$B44,G$4,G$5,101)/100 -> 0.01064848 | H44: =-[1]!thsiFinD("ths_max_retrace_rate_all_fund",$B44,E$3,E$5)/100 -> -0.11736738
...

Sheet 1090系统数据
B1: 1090账户基石投顾组合 | E1: =TODAY()-1 -> 46303 | J1: 策略名称： | K1: 1090账户基石投顾组合
A2: =[1]!HX_AutoDate(1,"2026-06-18",E1,-1,-1,0,0,0,0,0,"SSE",74,0) -> 日期 | B2: 投资组合(扣除投顾费,申赎费) | C2: 业绩基准 | J2: 日期 | K2: 投资组合(扣除投顾费,申赎费) | L2: 业绩基准 | M2: 组合每日回撤率 | N2: 组合每日收益 | O2: 组合年化收益率 | P2: 基准日涨跌 | Q2: 模拟净值 | R2: =MIN(S:S) -> -0.027261264
