Workbook

Sheet 实盘持仓配置
A1: 持仓配置（实盘·初始权重）
A2: 基金简称 | B2: 华安黄金ETF联接A | C2: 嘉实快线货币A | D2: 宏利复兴混合A | E2: 博道沪深300增强A | F2: 博道沪深300指增C | G2: 国泰通信设备ETF联接A | H2: 国泰通信设备C | I2: 嘉实前沿科技创新 | J2: 银华集成电路混合A | K2: 银华集成电路混合C | L2: 天弘中证1000指增A | M2: 天弘中证1000指增C | N2: 中欧中证500指增A | O2: 中欧中证500指增C | P2: 信澳业绩驱动A | Q2: 嘉实信息产业A | R2: 嘉实信息产业C | S2: 宏利复兴伟业C | T2: 国泰半导体材料设备ETF联接A | U2: 国泰半导体材料设备C | V2: 华泰柏瑞中证2000指增A | W2: 华泰柏瑞中证2000指增C | X2: 易方达中债新综指LOFA | Y2: 合计 | Z2: 年化费率 | AA2: 净值起始日
A3: 基金代码 | B3: 000216.OF | C3: 000917.OF | D3: 001170.OF | E3: 007044.OF | F3: 007045.OF | G3: 007817.OF | H3: 007818.OF | I3: 009993.OF | J3: 013840.OF | K3: 013841.OF | L3: 014201.OF | M3: 014202.OF | N3: 015453.OF | O3: 015454.OF | P3: 016370.OF | Q3: 017488.OF | R3: 017489.OF | S3: 017612.OF | T3: 019632.OF | U3: 019633.OF | V3: 019923.OF | W3: 019924.OF | X3: 161119.OF
A4: 产业趋势 权重 | B4: 0 | C4: 0.02 | D4: 0.19 | E4: 0 | F4: 0 | G4: 0.11 | H4: 0 | I4: 0 | J4: 0.19 | K4: 0 | L4: 0 | M4: 0 | N4: 0 | O4: 0 | P4: 0.19 | Q4: 0.19 | R4: 0 | S4: 0 | T4: 0.11 | U4: 0 | V4: 0 | W4: 0 | X4: 0 | Y4: =SUM(B4:X4) -> 1 | Z4: 0.015 | AA4: 46195
A5: 产业趋势基石 权重 | B5: 0 | C5: 0.02 | D5: 0.19 | E5: 0 | F5: 0 | G5: 0.11 | H5: 0 | I5: 0 | J5: 0.19 | K5: 0 | L5: 0 | M5: 0 | N5: 0 | O5: 0 | P5: 0.19 | Q5: 0.19 | R5: 0 | S5: 0 | T5: 0.11 | U5: 0 | V5: 0 | W5: 0 | X5: 0 | Y5: =SUM(B5:X5) -> 1 | Z5: 0.012 | AA5: 46191
A6: 产业趋势2号 权重 | B6: 0 | C6: 0.02 | D6: 0 | E6: 0 | F6: 0 | G6: 0 | H6: 0.11 | I6: 0.19 | J6: 0 | K6: 0.19 | L6: 0 | M6: 0 | N6: 0 | O6: 0 | P6: 0 | Q6: 0 | R6: 0.19 | S6: 0.19 | T6: 0 | U6: 0.11 | V6: 0 | W6: 0 | X6: 0 | Y6: =SUM(B6:X6) -> 1 | Z6: 0.015 | AA6: 46196
A7: 10-90 权重 | B7: 0.05 | C7: 0.02 | D7: 0 | E7: 0 | F7: 0.0125 | G7: 0 | H7: 0.005 | I7: 0.01 | J7: 0 | K7: 0.01 | L7: 0 | M7: 0.0125 | N7: 0 | O7: 0.0125 | P7: 0 | Q7: 0 | R7: 0.01 | S7: 0.01 | T7: 0 | U7: 0.005 | V7: 0 | W7: 0.0125 | X7: 0.83 | Y7: =SUM(B7:X7) -> 1 | Z7: 0.008 | AA7: 46197
A8: 10-90基石 权重 | B8: 0.05 | C8: 0.02 | D8: 0.01 | E8: 0.0125 | F8: 0 | G8: 0.005 | H8: 0 | I8: 0 | J8: 0.01 | K8: 0 | L8: 0.0125 | M8: 0 | N8: 0.0125 | O8: 0 | P8: 0.01 | Q8: 0.01 | R8: 0 | S8: 0 | T8: 0.005 | U8: 0 | V8: 0.0125 | W8: 0 | X8: 0.83 | Y8: =SUM(B8:X8) -> 1 | Z8: 0.005 | AA8: 46191
A9: 30-70 权重 | B9: 0.1 | C9: 0.02 | D9: 0 | E9: 0 | F9: 0.0375 | G9: 0 | H9: 0.015 | I9: 0.03 | J9: 0 | K9: 0.03 | L9: 0 | M9: 0.0375 | N9: 0 | O9: 0.0375 | P9: 0 | Q9: 0 | R9: 0.03 | S9: 0.03 | T9: 0 | U9: 0.015 | V9: 0 | W9: 0.0375 | X9: 0.58 | Y9: =SUM(B9:X9) -> 1 | Z9: 0.012 | AA9: 46197
A11: 权重蓝色输入；Z列为各组合年化费率、AA列为各组合净值起始日(当日净值=1)。新增交易日下拉填充，下游净值与看板自动重算。

Sheet 实盘净值数据(iFinD公式)
A1: 净值数据 * 实盘
A2: =TODAY() -> 46203
A3: 基金代码→ | B3: =实盘持仓配置!B3 -> 000216.OF | C3: =实盘持仓配置!C3 -> 000917.OF | D3: =实盘持仓配置!D3 -> 001170.OF | E3: =实盘持仓配置!E3 -> 007044.OF | F3: =实盘持仓配置!F3 -> 007045.OF | G3: =实盘持仓配置!G3 -> 007817.OF | H3: =实盘持仓配置!H3 -> 007818.OF | I3: =实盘持仓配置!I3 -> 009993.OF | ... X3: =实盘持仓配置!X3 -> 161119.OF
A4: =[1]!HX_AutoDate(1,"2026-06-18",A2,-1,-1,0,0,0,0,0,"SSE",8,0) -> 日期 | B4: 华安黄金ETF联接A | C4: 嘉实快线货币A | D4: 宏利复兴混合A | E4: 博道沪深300增强A | F4: 博道沪深300指增C | G4: 国泰通信设备ETF联接A | H4: 国泰通信设备C | I4: 嘉实前沿科技创新 | J4: 银华集成电路混合A | K4: 银华集成电路混合C | L4: 天弘中证1000指增A | M4: 天弘中证1000指增C | N4: 中欧中证500指增A | O4: 中欧中证500指增C | P4: 信澳业绩驱动A | Q4: 嘉实信息产业A | R4: 嘉实信息产业C | S4: 宏利复兴伟业C | T4: 国泰半导体材料设备ETF联接A | U4: 国泰半导体材料设备C | V4: 华泰柏瑞中证2000指增A | W4: 华泰柏瑞中证2000指增C | X4: 易方达中债新综指LOFA
A5: 46191 | B5: =IF($A5="","",[1]!thsiFinD("ths_adjustment_nv_fund",B$3,$A5)) -> 3.2441 | C5: =IF($A5="","",[1]!thsiFinD("ths_adjustment_nv_fund",C$3,$A5)) -> 1.3172785 | D5: =IF($A5="","",[1]!thsiFinD("ths_adjustment_nv_fund",D$3,$A5)) -> 6.062 | E5: =IF($A5="","",[1]!thsiFinD("ths_adjustment_nv_fund",E$3,$A5)) -> 1.9904 | F5: =IF($A5="","",[1]!thsiFinD("ths_adjustment_nv_fund",F$3,$A5)) -> 1.9344 | G5: =IF($A5="","",[1]!thsiFinD("ths_adjustment_nv_fund",G$3,$A5)) -> 5.0275 | H5: =IF($A5="","",[1]!thsiFinD("ths_adjustment_nv_fund",H$3,$A5)) -> 4.9215 | I5: =IF($A5="","",[1]!thsiFinD("ths_adjustment_nv_fund",I$3,$A5)) -> 2.9226 | ... X5: =IF($A5="","",[1]!thsiFinD("ths_adjustment_nv_fund",X$3,$A5)) -> 1.7869
A6: 46195 | B6: =IF($A6="","",[1]!thsiFinD("ths_adjustment_nv_fund",B$3,$A6)) -> 3.168 | C6: =IF($A6="","",[1]!thsiFinD("ths_adjustment_nv_fund",C$3,$A6)) -> 1.3174604 | D6: =IF($A6="","",[1]!thsiFinD("ths_adjustment_nv_fund",D$3,$A6)) -> 6.259 | E6: =IF($A6="","",[1]!thsiFinD("ths_adjustment_nv_fund",E$3,$A6)) -> 2.0345 | F6: =IF($A6="","",[1]!thsiFinD("ths_adjustment_nv_fund",F$3,$A6)) -> 1.9772 | G6: =IF($A6="","",[1]!thsiFinD("ths_adjustment_nv_fund",G$3,$A6)) -> 5.1121 | H6: =IF($A6="","",[1]!thsiFinD("ths_adjustment_nv_fund",H$3,$A6)) -> 5.0042 | I6: =IF($A6="","",[1]!thsiFinD("ths_adjustment_nv_fund",I$3,$A6)) -> 2.9905 | ... X6: =IF($A6="","",[1]!thsiFinD("ths_adjustment_nv_fund",X$3,$A6)) -> 1.7871
A7: 46196 | B7: =IF($A7="","",[1]!thsiFinD("ths_adjustment_nv_fund",B$3,$A7)) -> 3.116 | C7: =IF($A7="","",[1]!thsiFinD("ths_adjustment_nv_fund",C$3,$A7)) -> 1.3175125 | D7: =IF($A7="","",[1]!thsiFinD("ths_adjustment_nv_fund",D$3,$A7)) -> 5.996 | E7: =IF($A7="","",[1]!thsiFinD("ths_adjustment_nv_fund",E$3,$A7)) -> 1.9837 | F7: =IF($A7="","",[1]!thsiFinD("ths_adjustment_nv_fund",F$3,$A7)) -> 1.9278 | G7: =IF($A7="","",[1]!thsiFinD("ths_adjustment_nv_fund",G$3,$A7)) -> 4.9665 | H7: =IF($A7="","",[1]!thsiFinD("ths_adjustment_nv_fund",H$3,$A7)) -> 4.8616 | I7: =IF($A7="","",[1]!thsiFinD("ths_adjustment_nv_fund",I$3,$A7)) -> 2.9276 | ... X7: =IF($A7="","",[1]!thsiFinD("ths_adjustment_nv_fund",X$3,$A7)) -> 1.7863
A8: 46197 | B8: =IF($A8="","",[1]!thsiFinD("ths_adjustment_nv_fund",B$3,$A8)) -> 3.0984 | C8: =IF($A8="","",[1]!thsiFinD("ths_adjustment_nv_fund",C$3,$A8)) -> 1.3175573 | D8: =IF($A8="","",[1]!thsiFinD("ths_adjustment_nv_fund",D$3,$A8)) -> 6.113 | E8: =IF($A8="","",[1]!thsiFinD("ths_adjustment_nv_fund",E$3,$A8)) -> 1.9931 | F8: =IF($A8="","",[1]!thsiFinD("ths_adjustment_nv_fund",F$3,$A8)) -> 1.9369 | G8: =IF($A8="","",[1]!thsiFinD("ths_adjustment_nv_fund",G$3,$A8)) -> 5.0423 | H8: =IF($A8="","",[1]!thsiFinD("ths_adjustment_nv_fund",H$3,$A8)) -> 4.9357 | I8: =IF($A8="","",[1]!thsiFinD("ths_adjustment_nv_fund",I$3,$A8)) -> 3.0529 | ... X8: =IF($A8="","",[1]!thsiFinD("ths_adjustment_nv_fund",X$3,$A8)) -> 1.7862
A9: 46198 | B9: =IF($A9="","",[1]!thsiFinD("ths_adjustment_nv_fund",B$3,$A9)) -> 3.0309 | C9: =IF($A9="","",[1]!thsiFinD("ths_adjustment_nv_fund",C$3,$A9)) -> 1.3176051 | D9: =IF($A9="","",[1]!thsiFinD("ths_adjustment_nv_fund",D$3,$A9)) -> 6.312 | E9: =IF($A9="","",[1]!thsiFinD("ths_adjustment_nv_fund",E$3,$A9)) -> 2.0205 | F9: =IF($A9="","",[1]!thsiFinD("ths_adjustment_nv_fund",F$3,$A9)) -> 1.9635 | G9: =IF($A9="","",[1]!thsiFinD("ths_adjustment_nv_fund",G$3,$A9)) -> 5.1945 | H9: =IF($A9="","",[1]!thsiFinD("ths_adjustment_nv_fund",H$3,$A9)) -> 5.0848 | I9: =IF($A9="","",[1]!thsiFinD("ths_adjustment_nv_fund",I$3,$A9)) -> 3.1735 | ... X9: =IF($A9="","",[1]!thsiFinD("ths_adjustment_nv_fund",X$3,$A9)) -> 1.7875
A10: 46199 | B10: =IF($A10="","",[1]!thsiFinD("ths_adjustment_nv_fund",B$3,$A10)) -> 3.0598 | C10: =IF($A10="","",[1]!thsiFinD("ths_adjustment_nv_fund",C$3,$A10)) -> 1.3176497 | D10: =IF($A10="","",[1]!thsiFinD("ths_adjustment_nv_fund",D$3,$A10)) -> 5.99 | E10: =IF($A10="","",[1]!thsiFinD("ths_adjustment_nv_fund",E$3,$A10)) -> 1.9618 | F10: =IF($A10="","",[1]!thsiFinD("ths_adjustment_nv_fund",F$3,$A10)) -> 1.9065 | G10: =IF($A10="","",[1]!thsiFinD("ths_adjustment_nv_fund",G$3,$A10)) -> 4.8685 | H10: =IF($A10="","",[1]!thsiFinD("ths_adjustment_nv_fund",H$3,$A10)) -> 4.7655 | I10: =IF($A10="","",[1]!thsiFinD("ths_adjustment_nv_fund",I$3,$A10)) -> 3.0956 | ... X10: =IF($A10="","",[1]!thsiFinD("ths_adjustment_nv_fund",X$3,$A10)) -> 1.788
A11: 46202 | B11: =IF($A11="","",[1]!thsiFinD("ths_adjustment_nv_fund",B$3,$A11)) -> 3.0723 | C11: =IF($A11="","",[1]!thsiFinD("ths_adjustment_nv_fund",C$3,$A11)) -> 1.3177908 | D11: =IF($A11="","",[1]!thsiFinD("ths_adjustment_nv_fund",D$3,$A11)) -> 5.795 | E11: =IF($A11="","",[1]!thsiFinD("ths_adjustment_nv_fund",E$3,$A11)) -> 1.9811 | F11: =IF($A11="","",[1]!thsiFinD("ths_adjustment_nv_fund",F$3,$A11)) -> 1.9252 | G11: =IF($A11="","",[1]!thsiFinD("ths_adjustment_nv_fund",G$3,$A11)) -> 4.7592 | H11: =IF($A11="","",[1]!thsiFinD("ths_adjustment_nv_fund",H$3,$A11)) -> 4.6585 | I11: =IF($A11="","",[1]!thsiFinD("ths_adjustment_nv_fund",I$3,$A11)) -> 3.1442 | ... X11: =IF($A11="","",[1]!thsiFinD("ths_adjustment_nv_fund",X$3,$A11)) -> 1.7897
A12: 46203 | B12: =IF($A12="","",[1]!thsiFinD("ths_adjustment_nv_fund",B$3,$A12)) -> 3.0723 | C12: =IF($A12="","",[1]!thsiFinD("ths_adjustment_nv_fund",C$3,$A12)) -> 1.3177908 | D12: =IF($A12="","",[1]!thsiFinD("ths_adjustment_nv_fund",D$3,$A12)) -> 5.795 | E12: =IF($A12="","",[1]!thsiFinD("ths_adjustment_nv_fund",E$3,$A12)) -> 1.9811 | F12: =IF($A12="","",[1]!thsiFinD("ths_adjustment_nv_fund",F$3,$A12)) -> 1.9252 | G12: =IF($A12="","",[1]!thsiFinD("ths_adjustment_nv_fund",G$3,$A12)) -> 4.7592 | H12: =IF($A12="","",[1]!thsiFinD("ths_adjustment_nv_fund",H$3,$A12)) -> 4.6585 | I12: =IF($A12="","",[1]!thsiFinD("ths_adjustment_nv_fund",I$3,$A12)) -> 3.1442 | ... X12: =IF($A12="","",[1]!thsiFinD("ths_adjustment_nv_fund",X$3,$A12)) -> 1.7897
B13: =IF($A13="","",[1]!thsiFinD("ths_adjustment_nv_fund",B$3,$A13)) | C13: =IF($A13="","",[1]!thsiFinD("ths_adjustment_nv_fund",C$3,$A13)) | D13: =IF($A13="","",[1]!thsiFinD("ths_adjustment_nv_fund",D$3,$A13)) | E13: =IF($A13="","",[1]!thsiFinD("ths_adjustment_nv_fund",E$3,$A13)) | F13: =IF($A13="","",[1]!thsiFinD("ths_adjustment_nv_fund",F$3,$A13)) | G13: =IF($A13="","",[1]!thsiFinD("ths_adjustment_nv_fund",G$3,$A13)) | H13: =IF($A13="","",[1]!thsiFinD("ths_adjustment_nv_fund",H$3,$A13)) | I13: =IF($A13="","",[1]!thsiFinD("ths_adjustment_nv_fund",I$3,$A13)) | ... X13: =IF($A13="","",[1]!thsiFinD("ths_adjustment_nv_fund",X$3,$A13))
B14: =IF($A14="","",[1]!thsiFinD("ths_adjustment_nv_fund",B$3,$A14)) | C14: =IF($A14="","",[1]!thsiFinD("ths_adjustment_nv_fund",C$3,$A14)) | D14: =IF($A14="","",[1]!thsiFinD("ths_adjustment_nv_fund",D$3,$A14)) | E14: =IF($A14="","",[1]!thsiFinD("ths_adjustment_nv_fund",E$3,$A14)) | F14: =IF($A14="","",[1]!thsiFinD("ths_adjustment_nv_fund",F$3,$A14)) | G14: =IF($A14="","",[1]!thsiFinD("ths_adjustment_nv_fund",G$3,$A14)) | H14: =IF($A14="","",[1]!thsiFinD("ths_adjustment_nv_fund",H$3,$A14)) | I14: =IF($A14="","",[1]!thsiFinD("ths_adjustment_nv_fund",I$3,$A14)) | ... X14: =IF($A14="","",[1]!thsiFinD("ths_adjustment_nv_fund",X$3,$A14))
B15: =IF($A15="","",[1]!thsiFinD("ths_adjustment_nv_fund",B$3,$A15)) | C15: =IF($A15="","",[1]!thsiFinD("ths_adjustment_nv_fund",C$3,$A15)) | D15: =IF($A15="","",[1]!thsiFinD("ths_adjustment_nv_fund",D$3,$A15)) | E15: =IF($A15="","",[1]!thsiFinD("ths_adjustment_nv_fund",E$3,$A15)) | F15: =IF($A15="","",[1]!thsiFinD("ths_adjustment_nv_fund",F$3,$A15)) | G15: =IF($A15="","",[1]!thsiFinD("ths_adjustment_nv_fund",G$3,$A15)) | H15: =IF($A15="","",[1]!thsiFinD("ths_adjustment_nv_fund",H$3,$A15)) | I15: =IF($A15="","",[1]!thsiFinD("ths_adjustment_nv_fund",I$3,$A15)) | ... X15: =IF($A15="","",[1]!thsiFinD("ths_adjustment_nv_fund",X$3,$A15))
B16: =IF($A16="","",[1]!thsiFinD("ths_adjustment_nv_fund",B$3,$A16)) | C16: =IF($A16="","",[1]!thsiFinD("ths_adjustment_nv_fund",C$3,$A16)) | D16: =IF($A16="","",[1]!thsiFinD("ths_adjustment_nv_fund",D$3,$A16)) | E16: =IF($A16="","",[1]!thsiFinD("ths_adjustment_nv_fund",E$3,$A16)) | F16: =IF($A16="","",[1]!thsiFinD("ths_adjustment_nv_fund",F$3,$A16)) | G16: =IF($A16="","",[1]!thsiFinD("ths_adjustment_nv_fund",G$3,$A16)) | H16: =IF($A16="","",[1]!thsiFinD("ths_adjustment_nv_fund",H$3,$A16)) | I16: =IF($A16="","",[1]!thsiFinD("ths_adjustment_nv_fund",I$3,$A16)) | ... X16: =IF($A16="","",[1]!thsiFinD("ths_adjustment_nv_fund",X$3,$A16))
B17: =IF($A17="","",[1]!thsiFinD("ths_adjustment_nv_fund",B$3,$A17)) | C17: =IF($A17="","",[1]!thsiFinD("ths_adjustment_nv_fund",C$3,$A17)) | D17: =IF($A17="","",[1]!thsiFinD("ths_adjustment_nv_fund",D$3,$A17)) | E17: =IF($A17="","",[1]!thsiFinD("ths_adjustment_nv_fund",E$3,$A17)) | F17: =IF($A17="","",[1]!thsiFinD("ths_adjustment_nv_fund",F$3,$A17)) | G17: =IF($A17="","",[1]!thsiFinD("ths_adjustment_nv_fund",G$3,$A17)) | H17: =IF($A17="","",[1]!thsiFinD("ths_adjustment_nv_fund",H$3,$A17)) | I17: =IF($A17="","",[1]!thsiFinD("ths_adjustment_nv_fund",I$3,$A17)) | ... X17: =IF($A17="","",[1]!thsiFinD("ths_adjustment_nv_fund",X$3,$A17))
B18: =IF($A18="","",[1]!thsiFinD("ths_adjustment_nv_fund",B$3,$A18)) | C18: =IF($A18="","",[1]!thsiFinD("ths_adjustment_nv_fund",C$3,$A18)) | D18: =IF($A18="","",[1]!thsiFinD("ths_adjustment_nv_fund",D$3,$A18)) | E18: =IF($A18="","",[1]!thsiFinD("ths_adjustment_nv_fund",E$3,$A18)) | F18: =IF($A18="","",[1]!thsiFinD("ths_adjustment_nv_fund",F$3,$A18)) | G18: =IF($A18="","",[1]!thsiFinD("ths_adjustment_nv_fund",G$3,$A18)) | H18: =IF($A18="","",[1]!thsiFinD("ths_adjustment_nv_fund",H$3,$A18)) | I18: =IF($A18="","",[1]!thsiFinD("ths_adjustment_nv_fund",I$3,$A18)) | ... X18: =IF($A18="","",[1]!thsiFinD("ths_adjustment_nv_fund",X$3,$A18))
B19: =IF($A19="","",[1]!thsiFinD("ths_adjustment_nv_fund",B$3,$A19)) | C19: =IF($A19="","",[1]!thsiFinD("ths_adjustment_nv_fund",C$3,$A19)) | D19: =IF($A19="","",[1]!thsiFinD("ths_adjustment_nv_fund",D$3,$A19)) | E19: =IF($A19="","",[1]!thsiFinD("ths_adjustment_nv_fund",E$3,$A19)) | F19: =IF($A19="","",[1]!thsiFinD("ths_adjustment_nv_fund",F$3,$A19)) | G19: =IF($A19="","",[1]!thsiFinD("ths_adjustment_nv_fund",G$3,$A19)) | H19: =IF($A19="","",[1]!thsiFinD("ths_adjustment_nv_fund",H$3,$A19)) | I19: =IF($A19="","",[1]!thsiFinD("ths_adjustment_nv_fund",I$3,$A19)) | ... X19: =IF($A19="","",[1]!thsiFinD("ths_adjustment_nv_fund",X$3,$A19))
B20: =IF($A20="","",[1]!thsiFinD("ths_adjustment_nv_fund",B$3,$A20)) | C20: =IF($A20="","",[1]!thsiFinD("ths_adjustment_nv_fund",C$3,$A20)) | D20: =IF($A20="","",[1]!thsiFinD("ths_adjustment_nv_fund",D$3,$A20)) | E20: =IF($A20="","",[1]!thsiFinD("ths_adjustment_nv_fund",E$3,$A20)) | F20: =IF($A20="","",[1]!thsiFinD("ths_adjustment_nv_fund",F$3,$A20)) | G20: =IF($A20="","",[1]!thsiFinD("ths_adjustment_nv_fund",G$3,$A20)) | H20: =IF($A20="","",[1]!thsiFinD("ths_adjustment_nv_fund",H$3,$A20)) | I20: =IF($A20="","",[1]!thsiFinD("ths_adjustment_nv_fund",I$3,$A20)) | ... X20: =IF($A20="","",[1]!thsiFinD("ths_adjustment_nv_fund",X$3,$A20))
B21: =IF($A21="","",[1]!thsiFinD("ths_adjustment_nv_fund",B$3,$A21)) | C21: =IF($A21="","",[1]!thsiFinD("ths_adjustment_nv_fund",C$3,$A21)) | D21: =IF($A21="","",[1]!thsiFinD("ths_adjustment_nv_fund",D$3,$A21)) | E21: =IF($A21="","",[1]!thsiFinD("ths_adjustment_nv_fund",E$3,$A21)) | F21: =IF($A21="","",[1]!thsiFinD("ths_adjustment_nv_fund",F$3,$A21)) | G21: =IF($A21="","",[1]!thsiFinD("ths_adjustment_nv_fund",G$3,$A21)) | H21: =IF($A21="","",[1]!thsiFinD("ths_adjustment_nv_fund",H$3,$A21)) | I21: =IF($A21="","",[1]!thsiFinD("ths_adjustment_nv_fund",I$3,$A21)) | ... X21: =IF($A21="","",[1]!thsiFinD("ths_adjustment_nv_fund",X$3,$A21))
B22: =IF($A22="","",[1]!thsiFinD("ths_adjustment_nv_fund",B$3,$A22)) | C22: =IF($A22="","",[1]!thsiFinD("ths_adjustment_nv_fund",C$3,$A22)) | D22: =IF($A22="","",[1]!thsiFinD("ths_adjustment_nv_fund",D$3,$A22)) | E22: =IF($A22="","",[1]!thsiFinD("ths_adjustment_nv_fund",E$3,$A22)) | F22: =IF($A22="","",[1]!thsiFinD("ths_adjustment_nv_fund",F$3,$A22)) | G22: =IF($A22="","",[1]!thsiFinD("ths_adjustment_nv_fund",G$3,$A22)) | H22: =IF($A22="","",[1]!thsiFinD("ths_adjustment_nv_fund",H$3,$A22)) | I22: =IF($A22="","",[1]!thsiFinD("ths_adjustment_nv_fund",I$3,$A22)) | ... X22: =IF($A22="","",[1]!thsiFinD("ths_adjustment_nv_fund",X$3,$A22))
B23: =IF($A23="","",[1]!thsiFinD("ths_adjustment_nv_fund",B$3,$A23)) | C23: =IF($A23="","",[1]!thsiFinD("ths_adjustment_nv_fund",C$3,$A23)) | D23: =IF($A23="","",[1]!thsiFinD("ths_adjustment_nv_fund",D$3,$A23)) | E23: =IF($A23="","",[1]!thsiFinD("ths_adjustment_nv_fund",E$3,$A23)) | F23: =IF($A23="","",[1]!thsiFinD("ths_adjustment_nv_fund",F$3,$A23)) | G23: =IF($A23="","",[1]!thsiFinD("ths_adjustment_nv_fund",G$3,$A23)) | H23: =IF($A23="","",[1]!thsiFinD("ths_adjustment_nv_fund",H$3,$A23)) | I23: =IF($A23="","",[1]!thsiFinD("ths_adjustment_nv_fund",I$3,$A23)) | ... X23: =IF($A23="","",[1]!thsiFinD("ths_adjustment_nv_fund",X$3,$A23))
B24: =IF($A24="","",[1]!thsiFinD("ths_adjustment_nv_fund",B$3,$A24)) | C24: =IF($A24="","",[1]!thsiFinD("ths_adjustment_nv_fund",C$3,$A24)) | D24: =IF($A24="","",[1]!thsiFinD("ths_adjustment_nv_fund",D$3,$A24)) | E24: =IF($A24="","",[1]!thsiFinD("ths_adjustment_nv_fund",E$3,$A24)) | F24: =IF($A24="","",[1]!thsiFinD("ths_adjustment_nv_fund",F$3,$A24)) | G24: =IF($A24="","",[1]!thsiFinD("ths_adjustment_nv_fund",G$3,$A24)) | H24: =IF($A24="","",[1]!thsiFinD("ths_adjustment_nv_fund",H$3,$A24)) | I24: =IF($A24="","",[1]!thsiFinD("ths_adjustment_nv_fund",I$3,$A24)) | ... X24: =IF($A24="","",[1]!thsiFinD("ths_adjustment_nv_fund",X$3,$A24))
... B60: =IF($A60="","",[1]!thsiFinD("ths_adjustment_nv_fund",B$3,$A60)) | C60: =IF($A60="","",[1]!thsiFinD("ths_adjustment_nv_fund",C$3,$A60)) | D60: =IF($A60="","",[1]!thsiFinD("ths_adjustment_nv_fund",D$3,$A60)) | E60: =IF($A60="","",[1]!thsiFinD("ths_adjustment_nv_fund",E$3,$A60)) | F60: =IF($A60="","",[1]!thsiFinD("ths_adjustment_nv_fund",F$3,$A60)) | G60: =IF($A60="","",[1]!thsiFinD("ths_adjustment_nv_fund",G$3,$A60)) | H60: =IF($A60="","",[1]!thsiFinD("ths_adjustment_nv_fund",H$3,$A60)) | I60: =IF($A60="","",[1]!thsiFinD("ths_adjustment_nv_fund",I$3,$A60)) | ... X60: =IF($A60="","",[1]!thsiFinD("ths_adjustment_nv_fund",X$3,$A60))

Sheet 实盘组合净值
A1: 组合净值（实盘）· 各组合自起始日买入持有逐日计算
B3: 组合 产业趋势 | E3: 组合 产业趋势基石 | H3: 组合 产业趋势2号 | K3: 组合 10-90 | N3: 组合 10-90基石 | Q3: 组合 30-70
A4: 日期 | B4: 净值 | C4: 日收益 | D4: 回撤 | E4: 净值 | F4: 日收益 | G4: 回撤 | H4: 净值 | I4: 日收益 | J4: 回撤 | K4: 净值 | L4: 日收益 | M4: 回撤 | N4: 净值 | O4: 日收益 | P4: 回撤 | Q4: 净值 | R4: 日收益 | S4: 回撤
A5: =IF('实盘净值数据(iFinD公式)'!A5="","",'实盘净值数据(iFinD公式)'!A5) -> 46191 | B5: =IF(OR((ROW()-1)<6,'实盘净值数据(iFinD公式)'!$A5="",'实盘净值数据(iFinD公式)'!$B5=""),"",SUMPRODUCT(实盘持仓配置!$B$4:$X$4,'实盘净值数据(iFinD公式)'!$B5:$X5/'实盘净值数据(iFinD公式)'!$B$6:$X$6)*(1-实盘持仓配置!$Z$4)^(('实盘净值数据(iFinD公式)'!$A5-'实盘净值数据(iFinD公式)'!$A$6)/365)) | D5: =IF(B5="","",B5/MAX(B$5:B5)-1) | E5: 1 | G5: =IF(E5="","",E5/MAX(E$5:E5)-1) -> 0 | H5: =IF(OR((ROW()-1)<7,'实盘净值数据(iFinD公式)'!$A5="",'实盘净值数据(iFinD公式)'!$B5=""),"",SUMPRODUCT(实盘持仓配置!$B$6:$X$6,'实盘净值数据(iFinD公式)'!$B5:$X5/'实盘净值数据(iFinD公式)'!$B$7:$X$7)*(1-实盘持仓配置!$Z$6)^(('实盘净值数据(iFinD公式)'!$A5-'实盘净值数据(iFinD公式)'!$A$7)/365)) | J5: =IF(H5="","",H5/MAX(H$5:H5)-1) | K5: =IF(OR((ROW()-1)<8,'实盘净值数据(iFinD公式)'!$A5="",'实盘净值数据(iFinD公式)'!$B5=""),"",SUMPRODUCT(实盘持仓配置!$B$7:$X$7,'实盘净值数据(iFinD公式)'!$B5:$X5/'实盘净值数据(iFinD公式)'!$B$8:$X$8)*(1-实盘持仓配置!$Z$7)^(('实盘净值数据(iFinD公式)'!$A5-'实盘净值数据(iFinD公式)'!$A$8)/365)) | M5: =IF(K5="","",K5/MAX(K$5:K5)-1) | N5: 1 | P5: =IF(N5="","",N5/MAX(N$5:N5)-1) -> 0 | Q5: =IF(OR((ROW()-1)<8,'实盘净值数据(iFinD公式)'!$A5="",'实盘净值数据(iFinD公式)'!$B5=""),"",SUMPRODUCT(实盘持仓配置!$B$9:$X$9,'实盘净值数据(iFinD公式)'!$B5:$X5/'实盘净值数据(iFinD公式)'!$B$8:$X$8)*(1-实盘持仓配置!$Z$9)^(('实盘净值数据(iFinD公式)'!$A5-'实盘净值数据(iFinD公式)'!$A$8)/365)) | S5: =IF(Q5="","",Q5/MAX(Q$5:Q5)-1)
A6: =IF('实盘净值数据(iFinD公式)'!A6="","",'实盘净值数据(iFinD公式)'!A6) -> 46195 | B6: 1 | C6: =IF(OR(B5="",'实盘净值数据(iFinD公式)'!$A6="",'实盘净值数据(iFinD公式)'!$B6=""),"",SUMPRODUCT(实盘持仓配置!$B$4:$X$4,'实盘净值数据(iFinD公式)'!$B5:$X5/'实盘净值数据(iFinD公式)'!$B$6:$X$6,'实盘净值数据(iFinD公式)'!$B6:$X6/'实盘净值数据(iFinD公式)'!$B5:$X5)/SUMPRODUCT(实盘持仓配置!$B$4:$X$4,'实盘净值数据(iFinD公式)'!$B5:$X5/'实盘净值数据(iFinD公式)'!$B$6:$X$6)-1) | D6: =IF(B6="","",B6/MAX(B$5:B6)-1) -> 0 | E6: =IF(OR((ROW()-1)<5,'实盘净值数据(iFinD公式)'!$A6="",'实盘净值数据(iFinD公式)'!$B6=""),"",SUMPRODUCT(实盘持仓配置!$B$5:$X$5,'实盘净值数据(iFinD公式)'!$B6:$X6/'实盘净值数据(iFinD公式)'!$B$5:$X$5)*(1-实盘持仓配置!$Z$5)^(('实盘净值数据(iFinD公式)'!$A6-'实盘净值数据(iFinD公式)'!$A$5)/365)) | F6: =IF(OR(E5="",'实盘净值数据(iFinD公式)'!$A6="",'实盘净值数据(iFinD公式)'!$B6=""),"",SUMPRODUCT(实盘持仓配置!$B$5:$X$5,'实盘净值数据(iFinD公式)'!$B5:$X5/'实盘净值数据(iFinD公式)'!$B$5:$X$5,'实盘净值数据(iFinD公式)'!$B6:$X6/'实盘净值数据(iFinD公式)'!$B5:$X5)/SUMPRODUCT(实盘持仓配置!$B$5:$X$5,'实盘净值数据(iFinD公式)'!$B5:$X5/'实盘净值数据(iFinD公式)'!$B$5:$X$5)-1) | G6: =IF(E6="","",E6/MAX(E$5:E6)-1) -> 0 | H6: =IF(OR((ROW()-1)<7,'实盘净值数据(iFinD公式)'!$A6="",'实盘净值数据(iFinD公式)'!$B6=""),"",SUMPRODUCT(实盘持仓配置!$B$6:$X$6,'实盘净值数据(iFinD公式)'!$B6:$X6/'实盘净值数据(iFinD公式)'!$B$7:$X$7)*(1-实盘持仓配置!$Z$6)^(('实盘净值数据(iFinD公式)'!$A6-'实盘净值数据(iFinD公式)'!$A$7)/365)) | I6: =IF(OR(H5="",'实盘净值数据(iFinD公式)'!$A6="",'实盘净值数据(iFinD公式)'!$B6=""),"",SUMPRODUCT(实盘持仓配置!$B$6:$X$6,'实盘净值数据(iFinD公式)'!$B5:$X5/'实盘净值数据(iFinD公式)'!$B$7:$X$7,'实盘净值数据(iFinD公式)'!$B6:$X6/'实盘净值数据(iFinD公式)'!$B5:$X5)/SUMPRODUCT(实盘持仓配置!$B$6:$X$6,'实盘净值数据(iFinD公式)'!$B5:$X5/'实盘净值数据(iFinD公式)'!$B$7:$X$7)-1) | J6: =IF(H6="","",H6/MAX(H$5:H6)-1) | K6: =IF(OR((ROW()-1)<8,'实盘净值数据(iFinD公式)'!$A6="",'实盘净值数据(iFinD公式)'!$B6=""),"",SUMPRODUCT(实盘持仓配置!$B$7:$X$7,'实盘净值数据(iFinD公式)'!$B6:$X6/'实盘净值数据(iFinD公式)'!$B$8:$X$8)*(1-实盘持仓配置!$Z$7)^(('实盘净值数据(iFinD公式)'!$A6-'实盘净值数据(iFinD公式)'!$A$8)/365)) | L6: =IF(OR(K5="",'实盘净值数据(iFinD公式)'!$A6="",'实盘净值数据(iFinD公式)'!$B6=""),"",SUMPRODUCT(实盘持仓配置!$B$7:$X$7,'实盘净值数据(iFinD公式)'!$B5:$X5/'实盘净值数据(iFinD公式)'!$B$8:$X$8,'实盘净值数据(iFinD公式)'!$B6:$X6/'实盘净值数据(iFinD公式)'!$B5:$X5)/SUMPRODUCT(实盘持仓配置!$B$7:$X$7,'实盘净值数据(iFinD公式)'!$B5:$X5/'实盘净值数据(iFinD公式)'!$B$8:$X$8)-1) | M6: =IF(K6="","",K6/MAX(K$5:K6)-1) | N6: =IF(OR((ROW()-1)<5,'实盘净值数据(iFinD公式)'!$A6="",'实盘净值数据(iFinD公式)'!$B6=""),"",SUMPRODUCT(实盘持仓配置!$B$8:$X$8,'实盘净值数据(iFinD公式)'!$B6:$X6/'实盘净值数据(iFinD公式)'!$B$5:$X$5)*(1-实盘持仓配置!$Z$8)^(('实盘净值数据(iFinD公式)'!$A6-'实盘净值数据(iFinD公式)'!$A$5)/365)) | O6: =IF(OR(N5="",'实盘净值数据(iFinD公式)'!$A6="",'实盘净值数据(iFinD公式)'!$B6=""),"",SUMPRODUCT(实盘持仓配置!$B$8:$X$8,'实盘净值数据(iFinD公式)'!$B5:$X5/'实盘净值数据(iFinD公式)'!$B$5:$X$5,'实盘净值数据(iFinD公式)'!$B6:$X6/'实盘净值数据(iFinD公式)'!$B5:$X5)/SUMPRODUCT(实盘持仓配置!$B$8:$X$8,'实盘净值数据(iFinD公式)'!$B5:$X5/'实盘净值数据(iFinD公式)'!$B$5:$X$5)-1) | P6: =IF(N6="","",N6/MAX(N$5:N6)-1) -> 0 | Q6: =IF(OR((ROW()-1)<8,'实盘净值数据(iFinD公式)'!$A6="",'实盘净值数据(iFinD公式)'!$B6=""),"",SUMPRODUCT(实盘持仓配置!$B$9:$X$9,'实盘净值数据(iFinD公式)'!$B6:$X6/'实盘净值数据(iFinD公式)'!$B$8:$X$8)*(1-实盘持仓配置!$Z$9)^(('实盘净值数据(iFinD公式)'!$A6-'实盘净值数据(iFinD公式)'!$A$8)/365)) | R6: =IF(OR(Q5="",'实盘净值数据(iFinD公式)'!$A6="",'实盘净值数据(iFinD公式)'!$B6=""),"",SUMPRODUCT(实盘持仓配置!$B$9:$X$9,'实盘净值数据(iFinD公式)'!$B5:$X5/'实盘净值数据(iFinD公式)'!$B$8:$X$8,'实盘净值数据(iFinD公式)'!$B6:$X6/'实盘净值数据(iFinD公式)'!$B5:$X5)/SUMPRODUCT(实盘持仓配置!$B$9:$X$9,'实盘净值数据(iFinD公式)'!$B5:$X5/'实盘净值数据(iFinD公式)'!$B$8:$X$8)-1) | S6: =IF(Q6="","",Q6/MAX(Q$5:Q6)-1)
A7: =IF('实盘净值数据(iFinD公式)'!A7="","",'实盘净值数据(iFinD公式)'!A7) -> 46196 | B7: =IF(OR((ROW()-1)<6,'实盘净值数据(iFinD公式)'!$A7="",'实盘净值数据(iFinD公式)'!$B7=""),"",SUMPRODUCT(实盘持仓配置!$B$4:$X$4,'实盘净值数据(iFinD公式)'!$B7:$X7/'实盘净值数据(iFinD公式)'!$B$6:$X$6)*(1-实盘持仓配置!$Z$4)^(('实盘净值数据(iFinD公式)'!$A7-'实盘净值数据(iFinD公式)'!$A$6)/365)) | C7: =IF(OR(B6="",'实盘净值数据(iFinD公式)'!$A7="",'实盘净值数据(iFinD公式)'!$B7=""),"",SUMPRODUCT(实盘持仓配置!$B$4:$X$4,'实盘净值数据(iFinD公式)'!$B6:$X6/'实盘净值数据(iFinD公式)'!$B$6:$X$6,'实盘净值数据(iFinD公式)'!$B7:$X7/'实盘净值数据(iFinD公式)'!$B6:$X6)/SUMPRODUCT(实盘持仓配置!$B$4:$X$4,'实盘净值数据(iFinD公式)'!$B6:$X6/'实盘净值数据(iFinD公式)'!$B$6:$X$6)-1) | D7: =IF(B7="","",B7/MAX(B$5:B7)-1) -> -0.019536214 | E7: =IF(OR((ROW()-1)<5,'实盘净值数据(iFinD公式)'!$A7="",'实盘净值数据(iFinD公式)'!$B7=""),"",SUMPRODUCT(实盘持仓配置!$B$5:$X$5,'实盘净值数据(iFinD公式)'!$B7:$X7/'实盘净值数据(iFinD公式)'!$B$5:$X$5)*(1-实盘持仓配置!$Z$5)^(('实盘净值数据(iFinD公式)'!$A7-'实盘净值数据(iFinD公式)'!$A$5)/365)) | F7: =IF(OR(E6="",'实盘净值数据(iFinD公式)'!$A7="",'实盘净值数据(iFinD公式)'!$B7=""),"",SUMPRODUCT(实盘持仓配置!$B$5:$X$5,'实盘净值数据(iFinD公式)'!$B6:$X6/'实盘净值数据(iFinD公式)'!$B$5:$X$5,'实盘净值数据(iFinD公式)'!$B7:$X7/'实盘净值数据(iFinD公式)'!$B6:$X6)/SUMPRODUCT(实盘持仓配置!$B$5:$X$5,'实盘净值数据(iFinD公式)'!$B6:$X6/'实盘净值数据(iFinD公式)'!$B$5:$X$5)-1) | G7: =IF(E7="","",E7/MAX(E$5:E7)-1) -> -0.019655768 | H7: 1 | I7: =IF(OR(H6="",'实盘净值数据(iFinD公式)'!$A7="",'实盘净值数据(iFinD公式)'!$B7=""),"",SUMPRODUCT(实盘持仓配置!$B$6:$X$6,'实盘净值数据(iFinD公式)'!$B6:$X6/'实盘净值数据(iFinD公式)'!$B$7:$X$7,'实盘净值数据(iFinD公式)'!$B7:$X7/'实盘净值数据(iFinD公式)'!$B6:$X6)/SUMPRODUCT(实盘持仓配置!$B$6:$X$6,'实盘净值数据(iFinD公式)'!$B6:$X6/'实盘净值数据(iFinD公式)'!$B$7:$X$7)-1) | J7: =IF(H7="","",H7/MAX(H$5:H7)-1) -> 0 | K7: =IF(OR((ROW()-1)<8,'实盘净值数据(iFinD公式)'!$A7="",'实盘净值数据(iFinD公式)'!$B7=""),"",SUMPRODUCT(实盘持仓配置!$B$7:$X$7,'实盘净值数据(iFinD公式)'!$B7:$X7/'实盘净值数据(iFinD公式)'!$B$8:$X$8)*(1-实盘持仓配置!$Z$7)^(('实盘净值数据(iFinD公式)'!$A7-'实盘净值数据(iFinD公式)'!$A$8)/365)) | L7: =IF(OR(K6="",'实盘净值数据(iFinD公式)'!$A7="",'实盘净值数据(iFinD公式)'!$B7=""),"",SUMPRODUCT(实盘持仓配置!$B$7:$X$7,'实盘净值数据(iFinD公式)'!$B6:$X6/'实盘净值数据(iFinD公式)'!$B$8:$X$8,'实盘净值数据(iFinD公式)'!$B7:$X7/'实盘净值数据(iFinD公式)'!$B6:$X6)/SUMPRODUCT(实盘持仓配置!$B$7:$X$7,'实盘净值数据(iFinD公式)'!$B6:$X6/'实盘净值数据(iFinD公式)'!$B$8:$X$8)-1) | M7: =IF(K7="","",K7/MAX(K$5:K7)-1) | N7: =IF(OR((ROW()-1)<5,'实盘净值数据(iFinD公式)'!$A7="",'实盘净值数据(iFinD公式)'!$B7=""),"",SUMPRODUCT(实盘持仓配置!$B$8:$X$8,'实盘净值数据(iFinD公式)'!$B7:$X7/'实盘净值数据(iFinD公式)'!$B$5:$X$5)*(1-实盘持仓配置!$Z$8)^(('实盘净值数据(iFinD公式)'!$A7-'实盘净值数据(iFinD公式)'!$A$5)/365)) | O7: =IF(OR(N6="",'实盘净值数据(iFinD公式)'!$A7="",'实盘净值数据(iFinD公式)'!$B7=""),"",SUMPRODUCT(实盘持仓配置!$B$8:$X$8,'实盘净值数据(iFinD公式)'!$B6:$X6/'实盘净值数据(iFinD公式)'!$B$5:$X$5,'实盘净值数据(iFinD公式)'!$B7:$X7/'实盘净值数据(iFinD公式)'!$B6:$X6)/SUMPRODUCT(实盘持仓配置!$B$8:$X$8,'实盘净值数据(iFinD公式)'!$B6:$X6/'实盘净值数据(iFinD公式)'!$B$5:$X$5)-1) | P7: =IF(N7="","",N7/MAX(N$5:N7)-1) -> -0.0030771024 | Q7: =IF(OR((ROW()-1)<8,'实盘净值数据(iFinD公式)'!$A7="",'实盘净值数据(iFinD公式)'!$B7=""),"",SUMPRODUCT(实盘持仓配置!$B$9:$X$9,'实盘净值数据(iFinD公式)'!$B7:$X7/'实盘净值数据(iFinD公式)'!$B$8:$X$8)*(1-实盘持仓配置!$Z$9)^(('实盘净值数据(iFinD公式)'!$A7-'实盘净值数据(iFinD公式)'!$A$8)/365)) | R7: =IF(OR(Q6="",'实盘净值数据(iFinD公式)'!$A7="",'实盘净值数据(iFinD公式)'!$B7=""),"",SUMPRODUCT(实盘持仓配置!$B$9:$X$9,'实盘净值数据(iFinD公式)'!$B6:$X6/'实盘净值数据(iFinD公式)'!$B$8:$X$8,'实盘净值数据(iFinD公式)'!$B7:$X7/'实盘净值数据(iFinD公式)'!$B6:$X6)/SUMPRODUCT(实盘持仓配置!$B$9:$X$9,'实盘净值数据(iFinD公式)'!$B6:$X6/'实盘净值数据(iFinD公式)'!$B$8:$X$8)-1) | S7: =IF(Q7="","",Q7/MAX(Q$5:Q7)-1)
A8: =IF('实盘净值数据(iFinD公式)'!A8="","",'实盘净值数据(iFinD公式)'!A8) -> 46197 | B8: =IF(OR((ROW()-1)<6,'实盘净值数据(iFinD公式)'!$A8="",'实盘净值数据(iFinD公式)'!$B8=""),"",SUMPRODUCT(实盘持仓配置!$B$4:$X$4,'实盘净值数据(iFinD公式)'!$B8:$X8/'实盘净值数据(iFinD公式)'!$B$6:$X$6)*(1-实盘持仓配置!$Z$4)^(('实盘净值数据(iFinD公式)'!$A8-'实盘净值数据(iFinD公式)'!$A$6)/365)) | C8: =IF(OR(B7="",'实盘净值数据(iFinD公式)'!$A8="",'实盘净值数据(iFinD公式)'!$B8=""),"",SUMPRODUCT(实盘持仓配置!$B$4:$X$4,'实盘净值数据(iFinD公式)'!$B7:$X7/'实盘净值数据(iFinD公式)'!$B$6:$X$6,'实盘净值数据(iFinD公式)'!$B8:$X8/'实盘净值数据(iFinD公式)'!$B7:$X7)/SUMPRODUCT(实盘持仓配置!$B$4:$X$4,'实盘净值数据(iFinD公式)'!$B7:$X7/'实盘净值数据(iFinD公式)'!$B$6:$X$6)-1) | D8: =IF(B8="","",B8/MAX(B$5:B8)-1) -> 0 | E8: =IF(OR((ROW()-1)<5,'实盘净值数据(iFinD公式)'!$A8="",'实盘净值数据(iFinD公式)'!$B8=""),"",SUMPRODUCT(实盘持仓配置!$B$5:$X$5,'实盘净值数据(iFinD公式)'!$B8:$X8/'实盘净值数据(iFinD公式)'!$B$5:$X$5)*(1-实盘持仓配置!$Z$5)^(('实盘净值数据(iFinD公式)'!$A8-'实盘净值数据(iFinD公式)'!$A$5)/365)) | F8: =IF(OR(E7="",'实盘净值数据(iFinD公式)'!$A8="",'实盘净值数据(iFinD公式)'!$B8=""),"",SUMPRODUCT(实盘持仓配置!$B$5:$X$5,'实盘净值数据(iFinD公式)'!$B7:$X7/'实盘净值数据(iFinD公式)'!$B$5:$X$5,'实盘净值数据(iFinD公式)'!$B8:$X8/'实盘净值数据(iFinD公式)'!$B7:$X7)/SUMPRODUCT(实盘持仓配置!$B$5:$X$5,'实盘净值数据(iFinD公式)'!$B7:$X7/'实盘净值数据(iFinD公式)'!$B$5:$X$5)-1) | G8: =IF(E8="","",E8/MAX(E$5:E8)-1) -> 0 | H8: =IF(OR((ROW()-1)<7,'实盘净值数据(iFinD公式)'!$A8="",'实盘净值数据(iFinD公式)'!$B8=""),"",SUMPRODUCT(实盘持仓配置!$B$6:$X$6,'实盘净值数据(iFinD公式)'!$B8:$X8/'实盘净值数据(iFinD公式)'!$B$7:$X$7)*(1-实盘持仓配置!$Z$6)^(('实盘净值数据(iFinD公式)'!$A8-'实盘净值数据(iFinD公式)'!$A$7)/365)) | I8: =IF(OR(H7="",'实盘净值数据(iFinD公式)'!$A8="",'实盘净值数据(iFinD公式)'!$B8=""),"",SUMPRODUCT(实盘持仓配置!$B$6:$X$6,'实盘净值数据(iFinD公式)'!$B7:$X7/'实盘净值数据(iFinD公式)'!$B$7:$X$7,'实盘净值数据(iFinD公式)'!$B8:$X8/'实盘净值数据(iFinD公式)'!$B7:$X7)/SUMPRODUCT(实盘持仓配置!$B$6:$X$6,'实盘净值数据(iFinD公式)'!$B7:$X7/'实盘净值数据(iFinD公式)'!$B$7:$X$7)-1) | J8: =IF(H8="","",H8/MAX(H$5:H8)-1) -> 0 | K8: 1 | L8: =IF(OR(K7="",'实盘净值数据(iFinD公式)'!$A8="",'实盘净值数据(iFinD公式)'!$B8=""),"",SUMPRODUCT(实盘持仓配置!$B$7:$X$7,'实盘净值数据(iFinD公式)'!$B7:$X7/'实盘净值数据(iFinD公式)'!$B$8:$X$8,'实盘净值数据(iFinD公式)'!$B8:$X8/'实盘净值数据(iFinD公式)'!$B7:$X7)/SUMPRODUCT(实盘持仓配置!$B$7:$X$7,'实盘净值数据(iFinD公式)'!$B7:$X7/'实盘净值数据(iFinD公式)'!$B$8:$X$8)-1) | M8: =IF(K8="","",K8/MAX(K$5:K8)-1) -> 0 | N8: =IF(OR((ROW()-1)<5,'实盘净值数据(iFinD公式)'!$A8="",'实盘净值数据(iFinD公式)'!$B8=""),"",SUMPRODUCT(实盘持仓配置!$B$8:$X$8,'实盘净值数据(iFinD公式)'!$B8:$X8/'实盘净值数据(iFinD公式)'!$B$5:$X$5)*(1-实盘持仓配置!$Z$8)^(('实盘净值数据(iFinD公式)'!$A8-'实盘净值数据(iFinD公式)'!$A$5)/365)) | O8: =IF(OR(N7="",'实盘净值数据(iFinD公式)'!$A8="",'实盘净值数据(iFinD公式)'!$B8=""),"",SUMPRODUCT(实盘持仓配置!$B$8:$X$8,'实盘净值数据(iFinD公式)'!$B7:$X7/'实盘净值数据(iFinD公式)'!$B$5:$X$5,'实盘净值数据(iFinD公式)'!$B8:$X8/'实盘净值数据(iFinD公式)'!$B7:$X7)/SUMPRODUCT(实盘持仓配置!$B$8:$X$8,'实盘净值数据(iFinD公式)'!$B7:$X7/'实盘净值数据(iFinD公式)'!$B$5:$X$5)-1) | P8: =IF(N8="","",N8/MAX(N$5:N8)-1) -> -0.0011379005 | Q8: 1 | R8: =IF(OR(Q7="",'实盘净值数据(iFinD公式)'!$A8="",'实盘净值数据(iFinD公式)'!$B8=""),"",SUMPRODUCT(实盘持仓配置!$B$9:$X$9,'实盘净值数据(iFinD公式)'!$B7:$X7/'实盘净值数据(iFinD公式)'!$B$8:$X$8,'实盘净值数据(iFinD公式)'!$B8:$X8/'实盘净值数据(iFinD公式)'!$B7:$X7)/SUMPRODUCT(实盘持仓配置!$B$9:$X$9,'实盘净值数据(iFinD公式)'!$B7:$X7/'实盘净值数据(iFinD公式)'!$B$8:$X$8)-1) | S8: =IF(Q8="","",Q8/MAX(Q$5:Q8)-1) -> 0
A9: =IF('实盘净值数据(iFinD公式)'!A9="","",'实盘净值数据(iFinD公式)'!A9) -> 46198 | B9: =IF(OR((ROW()-1)<6,'实盘净值数据(iFinD公式)'!$A9="",'实盘净值数据(iFinD公式)'!$B9=""),"",SUMPRODUCT(实盘持仓配置!$B$4:$X$4,'实盘净值数据(iFinD公式)'!$B9:$X9/'实盘净值数据(iFinD公式)'!$B$6:$X$6)*(1-实盘持仓配置!$Z$4)^(('实盘净值数据(iFinD公式)'!$A9-'实盘净值数据(iFinD公式)'!$A$6)/365)) | C9: =IF(OR(B8="",'实盘净值数据(iFinD公式)'!$A9="",'实盘净值数据(iFinD公式)'!$B9=""),"",SUMPRODUCT(实盘持仓配置!$B$4:$X$4,'实盘净值数据(iFinD公式)'!$B8:$X8/'实盘净值数据(iFinD公式)'!$B$6:$X$6,'实盘净值数据(iFinD公式)'!$B9:$X9/'实盘净值数据(iFinD公式)'!$B8:$X8)/SUMPRODUCT(实盘持仓配置!$B$4:$X$4,'实盘净值数据(iFinD公式)'!$B8:$X8/'实盘净值数据(iFinD公式)'!$B$6:$X$6)-1) | D9: =IF(B9="","",B9/MAX(B$5:B9)-1) -> 0 | E9: =IF(OR((ROW()-1)<5,'实盘净值数据(iFinD公式)'!$A9="",'实盘净值数据(iFinD公式)'!$B9=""),"",SUMPRODUCT(实盘持仓配置!$B$5:$X$5,'实盘净值数据(iFinD公式)'!$B9:$X9/'实盘净值数据(iFinD公式)'!$B$5:$X$5)*(1-实盘持仓配置!$Z$5)^(('实盘净值数据(iFinD公式)'!$A9-'实盘净值数据(iFinD公式)'!$A$5)/365)) | F9: =IF(OR(E8="",'实盘净值数据(iFinD公式)'!$A9="",'实盘净值数据(iFinD公式)'!$B9=""),"",SUMPRODUCT(实盘持仓配置!$B$5:$X$5,'实盘净值数据(iFinD公式)'!$B8:$X8/'实盘净值数据(iFinD公式)'!$B$5:$X$5,'实盘净值数据(iFinD公式)'!$B9:$X9/'实盘净值数据(iFinD公式)'!$B8:$X8)/SUMPRODUCT(实盘持仓配置!$B$5:$X$5,'实盘净值数据(iFinD公式)'!$B8:$X8/'实盘净值数据(iFinD公式)'!$B$5:$X$5)-1) | G9: =IF(E9="","",E9/MAX(E$5:E9)-1) -> 0 | H9: =IF(OR((ROW()-1)<7,'实盘净值数据(iFinD公式)'!$A9="",'实盘净值数据(iFinD公式)'!$B9=""),"",SUMPRODUCT(实盘持仓配置!$B$6:$X$6,'实盘净值数据(iFinD公式)'!$B9:$X9/'实盘净值数据(iFinD公式)'!$B$7:$X$7)*(1-实盘持仓配置!$Z$6)^(('实盘净值数据(iFinD公式)'!$A9-'实盘净值数据(iFinD公式)'!$A$7)/365)) | I9: =IF(OR(H8="",'实盘净值数据(iFinD公式)'!$A9="",'实盘净值数据(iFinD公式)'!$B9=""),"",SUMPRODUCT(实盘持仓配置!$B$6:$X$6,'实盘净值数据(iFinD公式)'!$B8:$X8/'实盘净值数据(iFinD公式)'!$B$7:$X$7,'实盘净值数据(iFinD公式)'!$B9:$X9/'实盘净值数据(iFinD公式)'!$B8:$X8)/SUMPRODUCT(实盘持仓配置!$B$6:$X$6,'实盘净值数据(iFinD公式)'!$B8:$X8/'实盘净值数据(iFinD公式)'!$B$7:$X$7)-1) | J9: =IF(H9="","",H9/MAX(H$5:H9)-1) -> 0 | K9: =IF(OR((ROW()-1)<8,'实盘净值数据(iFinD公式)'!$A9="",'实盘净值数据(iFinD公式)'!$B9=""),"",SUMPRODUCT(实盘持仓配置!$B$7:$X$7,'实盘净值数据(iFinD公式)'!$B9:$X9/'实盘净值数据(iFinD公式)'!$B$8:$X$8)*(1-实盘持仓配置!$Z$7)^(('实盘净值数据(iFinD公式)'!$A9-'实盘净值数据(iFinD公式)'!$A$8)/365)) | L9: =IF(OR(K8="",'实盘净值数据(iFinD公式)'!$A9="",'实盘净值数据(iFinD公式)'!$B9=""),"",SUMPRODUCT(实盘持仓配置!$B$7:$X$7,'实盘净值数据(iFinD公式)'!$B8:$X8/'实盘净值数据(iFinD公式)'!$B$8:$X$8,'实盘净值数据(iFinD公式)'!$B9:$X9/'实盘净值数据(iFinD公式)'!$B8:$X8)/SUMPRODUCT(实盘持仓配置!$B$7:$X$7,'实盘净值数据(iFinD公式)'!$B8:$X8/'实盘净值数据(iFinD公式)'!$B$8:$X$8)-1) | M9: =IF(K9="","",K9/MAX(K$5:K9)-1) -> 0 | N9: =IF(OR((ROW()-1)<5,'实盘净值数据(iFinD公式)'!$A9="",'实盘净值数据(iFinD公式)'!$B9=""),"",SUMPRODUCT(实盘持仓配置!$B$8:$X$8,'实盘净值数据(iFinD公式)'!$B9:$X9/'实盘净值数据(iFinD公式)'!$B$5:$X$5)*(1-实盘持仓配置!$Z$8)^(('实盘净值数据(iFinD公式)'!$A9-'实盘净值数据(iFinD公式)'!$A$5)/365)) | O9: =IF(OR(N8="",'实盘净值数据(iFinD公式)'!$A9="",'实盘净值数据(iFinD公式)'!$B9=""),"",SUMPRODUCT(实盘持仓配置!$B$8:$X$8,'实盘净值数据(iFinD公式)'!$B8:$X8/'实盘净值数据(iFinD公式)'!$B$5:$X$5,'实盘净值数据(iFinD公式)'!$B9:$X9/'实盘净值数据(iFinD公式)'!$B8:$X8)/SUMPRODUCT(实盘持仓配置!$B$8:$X$8,'实盘净值数据(iFinD公式)'!$B8:$X8/'实盘净值数据(iFinD公式)'!$B$5:$X$5)-1) | P9: =IF(N9="","",N9/MAX(N$5:N9)-1) -> 0 | Q9: =IF(OR((ROW()-1)<8,'实盘净值数据(iFinD公式)'!$A9="",'实盘净值数据(iFinD公式)'!$B9=""),"",SUMPRODUCT(实盘持仓配置!$B$9:$X$9,'实盘净值数据(iFinD公式)'!$B9:$X9/'实盘净值数据(iFinD公式)'!$B$8:$X$8)*(1-实盘持仓配置!$Z$9)^(('实盘净值数据(iFinD公式)'!$A9-'实盘净值数据(iFinD公式)'!$A$8)/365)) | R9: =IF(OR(Q8="",'实盘净值数据(iFinD公式)'!$A9="",'实盘净值数据(iFinD公式)'!$B9=""),"",SUMPRODUCT(实盘持仓配置!$B$9:$X$9,'实盘净值数据(iFinD公式)'!$B8:$X8/'实盘净值数据(iFinD公式)'!$B$8:$X$8,'实盘净值数据(iFinD公式)'!$B9:$X9/'实盘净值数据(iFinD公式)'!$B8:$X8)/SUMPRODUCT(实盘持仓配置!$B$9:$X$9,'实盘净值数据(iFinD公式)'!$B8:$X8/'实盘净值数据(iFinD公式)'!$B$8:$X$8)-1) | S9: =IF(Q9="","",Q9/MAX(Q$5:Q9)-1) -> 0
A10: =IF('实盘净值数据(iFinD公式)'!A10="","",'实盘净值数据(iFinD公式)'!A10) -> 46199 | B10: =IF(OR((ROW()-1)<6,'实盘净值数据(iFinD公式)'!$A10="",'实盘净值数据(iFinD公式)'!$B10=""),"",SUMPRODUCT(实盘持仓配置!$B$4:$X$4,'实盘净值数据(iFinD公式)'!$B10:$X10/'实盘净值数据(iFinD公式)'!$B$6:$X$6)*(1-实盘持仓配置!$Z$4)^(('实盘净值数据(iFinD公式)'!$A10-'实盘净值数据(iFinD公式)'!$A$6)/365)) | C10: =IF(OR(B9="",'实盘净值数据(iFinD公式)'!$A10="",'实盘净值数据(iFinD公式)'!$B10=""),"",SUMPRODUCT(实盘持仓配置!$B$4:$X$4,'实盘净值数据(iFinD公式)'!$B9:$X9/'实盘净值数据(iFinD公式)'!$B$6:$X$6,'实盘净值数据(iFinD公式)'!$B10:$X10/'实盘净值数据(iFinD公式)'!$B9:$X9)/SUMPRODUCT(实盘持仓配置!$B$4:$X$4,'实盘净值数据(iFinD公式)'!$B9:$X9/'实盘净值数据(iFinD公式)'!$B$6:$X$6)-1) | D10: =IF(B10="","",B10/MAX(B$5:B10)-1) -> -0.028604573 | E10: =IF(OR((ROW()-1)<5,'实盘净值数据(iFinD公式)'!$A10="",'实盘净值数据(iFinD公式)'!$B10=""),"",SUMPRODUCT(实盘持仓配置!$B$5:$X$5,'实盘净值数据(iFinD公式)'!$B10:$X10/'实盘净值数据(iFinD公式)'!$B$5:$X$5)*(1-实盘持仓配置!$Z$5)^(('实盘净值数据(iFinD公式)'!$A10-'实盘净值数据(iFinD公式)'!$A$5)/365)) | F10: =IF(OR(E9="",'实盘净值数据(iFinD公式)'!$A10="",'实盘净值数据(iFinD公式)'!$B10=""),"",SUMPRODUCT(实盘持仓配置!$B$5:$X$5,'实盘净值数据(iFinD公式)'!$B9:$X9/'实盘净值数据(iFinD公式)'!$B$5:$X$5,'实盘净值数据(iFinD公式)'!$B10:$X10/'实盘净值数据(iFinD公式)'!$B9:$X9)/SUMPRODUCT(实盘持仓配置!$B$5:$X$5,'实盘净值数据(iFinD公式)'!$B9:$X9/'实盘净值数据(iFinD公式)'!$B$5:$X$5)-1) | G10: =IF(E10="","",E10/MAX(E$5:E10)-1) -> -0.028695044 | H10: =IF(OR((ROW()-1)<7,'实盘净值数据(iFinD公式)'!$A10="",'实盘净值数据(iFinD公式)'!$B10=""),"",SUMPRODUCT(实盘持仓配置!$B$6:$X$6,'实盘净值数据(iFinD公式)'!$B10:$X10/'实盘净值数据(iFinD公式)'!$B$7:$X$7)*(1-实盘持仓配置!$Z$6)^(('实盘净值数据(iFinD公式)'!$A10-'实盘净值数据(iFinD公式)'!$A$7)/365)) | I10: =IF(OR(H9="",'实盘净值数据(iFinD公式)'!$A10="",'实盘净值数据(iFinD公式)'!$B10=""),"",SUMPRODUCT(实盘持仓配置!$B$6:$X$6,'实盘净值数据(iFinD公式)'!$B9:$X9/'实盘净值数据(iFinD公式)'!$B$7:$X$7,'实盘净值数据(iFinD公式)'!$B10:$X10/'实盘净值数据(iFinD公式)'!$B9:$X9)/SUMPRODUCT(实盘持仓配置!$B$6:$X$6,'实盘净值数据(iFinD公式)'!$B9:$X9/'实盘净值数据(iFinD公式)'!$B$7:$X$7)-1) | J10: =IF(H10="","",H10/MAX(H$5:H10)-1) -> -0.02186381 | K10: =IF(OR((ROW()-1)<8,'实盘净值数据(iFinD公式)'!$A10="",'实盘净值数据(iFinD公式)'!$B10=""),"",SUMPRODUCT(实盘持仓配置!$B$7:$X$7,'实盘净值数据(iFinD公式)'!$B10:$X10/'实盘净值数据(iFinD公式)'!$B$8:$X$8)*(1-实盘持仓配置!$Z$7)^(('实盘净值数据(iFinD公式)'!$A10-'实盘净值数据(iFinD公式)'!$A$8)/365)) | L10: =IF(OR(K9="",'实盘净值数据(iFinD公式)'!$A10="",'实盘净值数据(iFinD公式)'!$B10=""),"",SUMPRODUCT(实盘持仓配置!$B$7:$X$7,'实盘净值数据(iFinD公式)'!$B9:$X9/'实盘净值数据(iFinD公式)'!$B$8:$X$8,'实盘净值数据(iFinD公式)'!$B10:$X10/'实盘净值数据(iFinD公式)'!$B9:$X9)/SUMPRODUCT(实盘持仓配置!$B$7:$X$7,'实盘净值数据(iFinD公式)'!$B9:$X9/'实盘净值数据(iFinD公式)'!$B$8:$X$8)-1) | M10: =IF(K10="","",K10/MAX(K$5:K10)-1) -> -0.001940396 | N10: =IF(OR((ROW()-1)<5,'实盘净值数据(iFinD公式)'!$A10="",'实盘净值数据(iFinD公式)'!$B10=""),"",SUMPRODUCT(实盘持仓配置!$B$8:$X$8,'实盘净值数据(iFinD公式)'!$B10:$X10/'实盘净值数据(iFinD公式)'!$B$5:$X$5)*(1-实盘持仓配置!$Z$8)^(('实盘净值数据(iFinD公式)'!$A10-'实盘净值数据(iFinD公式)'!$A$5)/365)) | O10: =IF(OR(N9="",'实盘净值数据(iFinD公式)'!$A10="",'实盘净值数据(iFinD公式)'!$B10=""),"",SUMPRODUCT(实盘持仓配置!$B$8:$X$8,'实盘净值数据(iFinD公式)'!$B9:$X9/'实盘净值数据(iFinD公式)'!$B$5:$X$5,'实盘净值数据(iFinD公式)'!$B10:$X10/'实盘净值数据(iFinD公式)'!$B9:$X9)/SUMPRODUCT(实盘持仓配置!$B$8:$X$8,'实盘净值数据(iFinD公式)'!$B9:$X9/'实盘净值数据(iFinD公式)'!$B$5:$X$5)-1) | P10: =IF(N10="","",N10/MAX(N$5:N10)-1) -> -0.0023521479 | Q10: =IF(OR((ROW()-1)<8,'实盘净值数据(iFinD公式)'!$A10="",'实盘净值数据(iFinD公式)'!$B10=""),"",SUMPRODUCT(实盘持仓配置!$B$9:$X$9,'实盘净值数据(iFinD公式)'!$B10:$X10/'实盘净值数据(iFinD公式)'!$B$8:$X$8)*(1-实盘持仓配置!$Z$9)^(('实盘净值数据(iFinD公式)'!$A10-'实盘净值数据(iFinD公式)'!$A$8)/365)) | R10: =IF(OR(Q9="",'实盘净值数据(iFinD公式)'!$A10="",'实盘净值数据(iFinD公式)'!$B10=""),"",SUMPRODUCT(实盘持仓配置!$B$9:$X$9,'实盘净值数据(iFinD公式)'!$B9:$X9/'实盘净值数据(iFinD公式)'!$B$8:$X$8,'实盘净值数据(iFinD公式)'!$B10:$X10/'实盘净值数据(iFinD公式)'!$B9:$X9)/SUMPRODUCT(实盘持仓配置!$B$9:$X$9,'实盘净值数据(iFinD公式)'!$B9:$X9/'实盘净值数据(iFinD公式)'!$B$8:$X$8)-1) | S10: =IF(Q10="","",Q10/MAX(Q$5:Q10)-1) -> -0.0067550899
A11: =IF('实盘净值数据(iFinD公式)'!A11="","",'实盘净值数据(iFinD公式)'!A11) -> 46202 | B11: =IF(OR((ROW()-1)<6,'实盘净值数据(iFinD公式)'!$A11="",'实盘净值数据(iFinD公式)'!$B11=""),"",SUMPRODUCT(实盘持仓配置!$B$4:$X$4,'实盘净值数据(iFinD公式)'!$B11:$X11/'实盘净值数据(iFinD公式)'!$B$6:$X$6)*(1-实盘持仓配置!$Z$4)^(('实盘净值数据(iFinD公式)'!$A11-'实盘净值数据(iFinD公式)'!$A$6)/365)) | C11: =IF(OR(B10="",'实盘净值数据(iFinD公式)'!$A11="",'实盘净值数据(iFinD公式)'!$B11=""),"",SUMPRODUCT(实盘持仓配置!$B$4:$X$4,'实盘净值数据(iFinD公式)'!$B10:$X10/'实盘净值数据(iFinD公式)'!$B$6:$X$6,'实盘净值数据(iFinD公式)'!$B11:$X11/'实盘净值数据(iFinD公式)'!$B10:$X10)/SUMPRODUCT(实盘持仓配置!$B$4:$X$4,'实盘净值数据(iFinD公式)'!$B10:$X10/'实盘净值数据(iFinD公式)'!$B$6:$X$6)-1) | D11: =IF(B11="","",B11/MAX(B$5:B11)-1) -> -0.019022057 | E11: =IF(OR((ROW()-1)<5,'实盘净值数据(iFinD公式)'!$A11="",'实盘净值数据(iFinD公式)'!$B11=""),"",SUMPRODUCT(实盘持仓配置!$B$5:$X$5,'实盘净值数据(iFinD公式)'!$B11:$X11/'实盘净值数据(iFinD公式)'!$B$5:$X$5)*(1-实盘持仓配置!$Z$5)^(('实盘净值数据(iFinD公式)'!$A11-'实盘净值数据(iFinD公式)'!$A$5)/365)) | F11: =IF(OR(E10="",'实盘净值数据(iFinD公式)'!$A11="",'实盘净值数据(iFinD公式)'!$B11=""),"",SUMPRODUCT(实盘持仓配置!$B$5:$X$5,'实盘净值数据(iFinD公式)'!$B10:$X10/'实盘净值数据(iFinD公式)'!$B$5:$X$5,'实盘净值数据(iFinD公式)'!$B11:$X11/'实盘净值数据(iFinD公式)'!$B10:$X10)/SUMPRODUCT(实盘持仓配置!$B$5:$X$5,'实盘净值数据(iFinD公式)'!$B10:$X10/'实盘净值数据(iFinD公式)'!$B$5:$X$5)-1) | G11: =IF(E11="","",E11/MAX(E$5:E11)-1) -> -0.019229931 | H11: =IF(OR((ROW()-1)<7,'实盘净值数据(iFinD公式)'!$A11="",'实盘净值数据(iFinD公式)'!$B11=""),"",SUMPRODUCT(实盘持仓配置!$B$6:$X$6,'实盘净值数据(iFinD公式)'!$B11:$X11/'实盘净值数据(iFinD公式)'!$B$7:$X$7)*(1-实盘持仓配置!$Z$6)^(('实盘净值数据(iFinD公式)'!$A11-'实盘净值数据(iFinD公式)'!$A$7)/365)) | I11: =IF(OR(H10="",'实盘净值数据(iFinD公式)'!$A11="",'实盘净值数据(iFinD公式)'!$B11=""),"",SUMPRODUCT(实盘持仓配置!$B$6:$X$6,'实盘净值数据(iFinD公式)'!$B10:$X10/'实盘净值数据(iFinD公式)'!$B$7:$X$7,'实盘净值数据(iFinD公式)'!$B11:$X11/'实盘净值数据(iFinD公式)'!$B10:$X10)/SUMPRODUCT(实盘持仓配置!$B$6:$X$6,'实盘净值数据(iFinD公式)'!$B10:$X10/'实盘净值数据(iFinD公式)'!$B$7:$X$7)-1) | J11: =IF(H11="","",H11/MAX(H$5:H11)-1) -> -0.0051710409 | K11: =IF(OR((ROW()-1)<8,'实盘净值数据(iFinD公式)'!$A11="",'实盘净值数据(iFinD公式)'!$B11=""),"",SUMPRODUCT(实盘持仓配置!$B$7:$X$7,'实盘净值数据(iFinD公式)'!$B11:$X11/'实盘净值数据(iFinD公式)'!$B$8:$X$8)*(1-实盘持仓配置!$Z$7)^(('实盘净值数据(iFinD公式)'!$A11-'实盘净值数据(iFinD公式)'!$A$8)/365)) | L11: =IF(OR(K10="",'实盘净值数据(iFinD公式)'!$A11="",'实盘净值数据(iFinD公式)'!$B11=""),"",SUMPRODUCT(实盘持仓配置!$B$7:$X$7,'实盘净值数据(iFinD公式)'!$B10:$X10/'实盘净值数据(iFinD公式)'!$B$8:$X$8,'实盘净值数据(iFinD公式)'!$B11:$X11/'实盘净值数据(iFinD公式)'!$B10:$X10)/SUMPRODUCT(实盘持仓配置!$B$7:$X$7,'实盘净值数据(iFinD公式)'!$B10:$X10/'实盘净值数据(iFinD公式)'!$B$8:$X$8)-1) | M11: =IF(K11="","",K11/MAX(K$5:K11)-1) -> -1.1146151e-05 | N11: =IF(OR((ROW()-1)<5,'实盘净值数据(iFinD公式)'!$A11="",'实盘净值数据(iFinD公式)'!$B11=""),"",SUMPRODUCT(实盘持仓配置!$B$8:$X$8,'实盘净值数据(iFinD公式)'!$B11:$X11/'实盘净值数据(iFinD公式)'!$B$5:$X$5)*(1-实盘持仓配置!$Z$8)^(('实盘净值数据(iFinD公式)'!$A11-'实盘净值数据(iFinD公式)'!$A$5)/365)) | O11: =IF(OR(N10="",'实盘净值数据(iFinD公式)'!$A11="",'实盘净值数据(iFinD公式)'!$B11=""),"",SUMPRODUCT(实盘持仓配置!$B$8:$X$8,'实盘净值数据(iFinD公式)'!$B10:$X10/'实盘净值数据(iFinD公式)'!$B$5:$X$5,'实盘净值数据(iFinD公式)'!$B11:$X11/'实盘净值数据(iFinD公式)'!$B10:$X10)/SUMPRODUCT(实盘持仓配置!$B$8:$X$8,'实盘净值数据(iFinD公式)'!$B10:$X10/'实盘净值数据(iFinD公式)'!$B$5:$X$5)-1) | P11: =IF(N11="","",N11/MAX(N$5:N11)-1) -> -0.00074247035 | Q11: =IF(OR((ROW()-1)<8,'实盘净值数据(iFinD公式)'!$A11="",'实盘净值数据(iFinD公式)'!$B11=""),"",SUMPRODUCT(实盘持仓配置!$B$9:$X$9,'实盘净值数据(iFinD公式)'!$B11:$X11/'实盘净值数据(iFinD公式)'!$B$8:$X$8)*(1-实盘持仓配置!$Z$9)^(('实盘净值数据(iFinD公式)'!$A11-'实盘净值数据(iFinD公式)'!$A$8)/365)) | R11: =IF(OR(Q10="",'实盘净值数据(iFinD公式)'!$A11="",'实盘净值数据(iFinD公式)'!$B11=""),"",SUMPRODUCT(实盘持仓配置!$B$9:$X$9,'实盘净值数据(iFinD公式)'!$B10:$X10/'实盘净值数据(iFinD公式)'!$B$8:$X$8,'实盘净值数据(iFinD公式)'!$B11:$X11/'实盘净值数据(iFinD公式)'!$B10:$X10)/SUMPRODUCT(实盘持仓配置!$B$9:$X$9,'实盘净值数据(iFinD公式)'!$B10:$X10/'实盘净值数据(iFinD公式)'!$B$8:$X$8)-1) | S11: =IF(Q11="","",Q11/MAX(Q$5:Q11)-1) -> -0.0029483272
A12: =IF('实盘净值数据(iFinD公式)'!A12="","",'实盘净值数据(iFinD公式)'!A12) -> 46203 | B12: =IF(OR((ROW()-1)<6,'实盘净值数据(iFinD公式)'!$A12="",'实盘净值数据(iFinD公式)'!$B12=""),"",SUMPRODUCT(实盘持仓配置!$B$4:$X$4,'实盘净值数据(iFinD公式)'!$B12:$X12/'实盘净值数据(iFinD公式)'!$B$6:$X$6)*(1-实盘持仓配置!$Z$4)^(('实盘净值数据(iFinD公式)'!$A12-'实盘净值数据(iFinD公式)'!$A$6)/365)) | C12: =IF(OR(B11="",'实盘净值数据(iFinD公式)'!$A12="",'实盘净值数据(iFinD公式)'!$B12=""),"",SUMPRODUCT(实盘持仓配置!$B$4:$X$4,'实盘净值数据(iFinD公式)'!$B11:$X11/'实盘净值数据(iFinD公式)'!$B$6:$X$6,'实盘净值数据(iFinD公式)'!$B12:$X12/'实盘净值数据(iFinD公式)'!$B11:$X11)/SUMPRODUCT(实盘持仓配置!$B$4:$X$4,'实盘净值数据(iFinD公式)'!$B11:$X11/'实盘净值数据(iFinD公式)'!$B$6:$X$6)-1) | D12: =IF(B12="","",B12/MAX(B$5:B12)-1) -> -0.01908332 | E12: =IF(OR((ROW()-1)<5,'实盘净值数据(iFinD公式)'!$A12="",'实盘净值数据(iFinD公式)'!$B12=""),"",SUMPRODUCT(实盘持仓配置!$B$5:$X$5,'实盘净值数据(iFinD公式)'!$B12:$X12/'实盘净值数据(iFinD公式)'!$B$5:$X$5)*(1-实盘持仓配置!$Z$5)^(('实盘净值数据(iFinD公式)'!$A12-'实盘净值数据(iFinD公式)'!$A$5)/365)) | F12: =IF(OR(E11="",'实盘净值数据(iFinD公式)'!$A12="",'实盘净值数据(iFinD公式)'!$B12=""),"",SUMPRODUCT(实盘持仓配置!$B$5:$X$5,'实盘净值数据(iFinD公式)'!$B11:$X11/'实盘净值数据(iFinD公式)'!$B$5:$X$5,'实盘净值数据(iFinD公式)'!$B12:$X12/'实盘净值数据(iFinD公式)'!$B11:$X11)/SUMPRODUCT(实盘持仓配置!$B$5:$X$5,'实盘净值数据(iFinD公式)'!$B11:$X11/'实盘净值数据(iFinD公式)'!$B$5:$X$5)-1) | G12: =IF(E12="","",E12/MAX(E$5:E12)-1) -> -0.019278857 | H12: =IF(OR((ROW()-1)<7,'实盘净值数据(iFinD公式)'!$A12="",'实盘净值数据(iFinD公式)'!$B12=""),"",SUMPRODUCT(实盘持仓配置!$B$6:$X$6,'实盘净值数据(iFinD公式)'!$B12:$X12/'实盘净值数据(iFinD公式)'!$B$7:$X$7)*(1-实盘持仓配置!$Z$6)^(('实盘净值数据(iFinD公式)'!$A12-'实盘净值数据(iFinD公式)'!$A$7)/365)) | I12: =IF(OR(H11="",'实盘净值数据(iFinD公式)'!$A12="",'实盘净值数据(iFinD公式)'!$B12=""),"",SUMPRODUCT(实盘持仓配置!$B$6:$X$6,'实盘净值数据(iFinD公式)'!$B11:$X11/'实盘净值数据(iFinD公式)'!$B$7:$X$7,'实盘净值数据(iFinD公式)'!$B12:$X12/'实盘净值数据(iFinD公式)'!$B11:$X11)/SUMPRODUCT(实盘持仓配置!$B$6:$X$6,'实盘净值数据(iFinD公式)'!$B11:$X11/'实盘净值数据(iFinD公式)'!$B$7:$X$7)-1) | J12: =IF(H12="","",H12/MAX(H$5:H12)-1) -> -0.005233169 | K12: =IF(OR((ROW()-1)<8,'实盘净值数据(iFinD公式)'!$A12="",'实盘净值数据(iFinD公式)'!$B12=""),"",SUMPRODUCT(实盘持仓配置!$B$7:$X$7,'实盘净值数据(iFinD公式)'!$B12:$X12/'实盘净值数据(iFinD公式)'!$B$8:$X$8)*(1-实盘持仓配置!$Z$7)^(('实盘净值数据(iFinD公式)'!$A12-'实盘净值数据(iFinD公式)'!$A$8)/365)) | L12: =IF(OR(K11="",'实盘净值数据(iFinD公式)'!$A12="",'实盘净值数据(iFinD公式)'!$B12=""),"",SUMPRODUCT(实盘持仓配置!$B$7:$X$7,'实盘净值数据(iFinD公式)'!$B11:$X11/'实盘净值数据(iFinD公式)'!$B$8:$X$8,'实盘净值数据(iFinD公式)'!$B12:$X12/'实盘净值数据(iFinD公式)'!$B11:$X11)/SUMPRODUCT(实盘持仓配置!$B$7:$X$7,'实盘净值数据(iFinD公式)'!$B11:$X11/'实盘净值数据(iFinD公式)'!$B$8:$X$8)-1) | M12: =IF(K12="","",K12/MAX(K$5:K12)-1) -> -4.4336022e-05 | N12: =IF(OR((ROW()-1)<5,'实盘净值数据(iFinD公式)'!$A12="",'实盘净值数据(iFinD公式)'!$B12=""),"",SUMPRODUCT(实盘持仓配置!$B$8:$X$8,'实盘净值数据(iFinD公式)'!$B12:$X12/'实盘净值数据(iFinD公式)'!$B$5:$X$5)*(1-实盘持仓配置!$Z$8)^(('实盘净值数据(iFinD公式)'!$A12-'实盘净值数据(iFinD公式)'!$A$5)/365)) | O12: =IF(OR(N11="",'实盘净值数据(iFinD公式)'!$A12="",'实盘净值数据(iFinD公式)'!$B12=""),"",SUMPRODUCT(实盘持仓配置!$B$8:$X$8,'实盘净值数据(iFinD公式)'!$B11:$X11/'实盘净值数据(iFinD公式)'!$B$5:$X$5,'实盘净值数据(iFinD公式)'!$B12:$X12/'实盘净值数据(iFinD公式)'!$B11:$X11)/SUMPRODUCT(实盘持仓配置!$B$8:$X$8,'实盘净值数据(iFinD公式)'!$B11:$X11/'实盘净值数据(iFinD公式)'!$B$5:$X$5)-1) | P12: =IF(N12="","",N12/MAX(N$5:N12)-1) -> -0.00076316774 | Q12: =IF(OR((ROW()-1)<8,'实盘净值数据(iFinD公式)'!$A12="",'实盘净值数据(iFinD公式)'!$B12=""),"",SUMPRODUCT(实盘持仓配置!$B$9:$X$9,'实盘净值数据(iFinD公式)'!$B12:$X12/'实盘净值数据(iFinD公式)'!$B$8:$X$8)*(1-实盘持仓配置!$Z$9)^(('实盘净值数据(iFinD公式)'!$A12-'实盘净值数据(iFinD公式)'!$A$8)/365)) | R12: =IF(OR(Q11="",'实盘净值数据(iFinD公式)'!$A12="",'实盘净值数据(iFinD公式)'!$B12=""),"",SUMPRODUCT(实盘持仓配置!$B$9:$X$9,'实盘净值数据(iFinD公式)'!$B11:$X11/'实盘净值数据(iFinD公式)'!$B$8:$X$8,'实盘净值数据(iFinD公式)'!$B12:$X12/'实盘净值数据(iFinD公式)'!$B11:$X11)/SUMPRODUCT(实盘持仓配置!$B$9:$X$9,'实盘净值数据(iFinD公式)'!$B11:$X11/'实盘净值数据(iFinD公式)'!$B$8:$X$8)-1) | S12: =IF(Q12="","",Q12/MAX(Q$5:Q12)-1) -> -0.0029980656
A13: =IF('实盘净值数据(iFinD公式)'!A13="","",'实盘净值数据(iFinD公式)'!A13) | B13: =IF(OR((ROW()-1)<6,'实盘净值数据(iFinD公式)'!$A13="",'实盘净值数据(iFinD公式)'!$B13=""),"",SUMPRODUCT(实盘持仓配置!$B$4:$X$4,'实盘净值数据(iFinD公式)'!$B13:$X13/'实盘净值数据(iFinD公式)'!$B$6:$X$6)*(1-实盘持仓配置!$Z$4)^(('实盘净值数据(iFinD公式)'!$A13-'实盘净值数据(iFinD公式)'!$A$6)/365)) | C13: =IF(OR(B12="",'实盘净值数据(iFinD公式)'!$A13="",'实盘净值数据(iFinD公式)'!$B13=""),"",SUMPRODUCT(实盘持仓配置!$B$4:$X$4,'实盘净值数据(iFinD公式)'!$B12:$X12/'实盘净值数据(iFinD公式)'!$B$6:$X$6,'实盘净值数据(iFinD公式)'!$B13:$X13/'实盘净值数据(iFinD公式)'!$B12:$X12)/SUMPRODUCT(实盘持仓配置!$B$4:$X$4,'实盘净值数据(iFinD公式)'!$B12:$X12/'实盘净值数据(iFinD公式)'!$B$6:$X$6)-1) | D13: =IF(B13="","",B13/MAX(B$5:B13)-1) | E13: =IF(OR((ROW()-1)<5,'实盘净值数据(iFinD公式)'!$A13="",'实盘净值数据(iFinD公式)'!$B13=""),"",SUMPRODUCT(实盘持仓配置!$B$5:$X$5,'实盘净值数据(iFinD公式)'!$B13:$X13/'实盘净值数据(iFinD公式)'!$B$5:$X$5)*(1-实盘持仓配置!$Z$5)^(('实盘净值数据(iFinD公式)'!$A13-'实盘净值数据(iFinD公式)'!$A$5)/365)) | F13: =IF(OR(E12="",'实盘净值数据(iFinD公式)'!$A13="",'实盘净值数据(iFinD公式)'!$B13=""),"",SUMPRODUCT(实盘持仓配置!$B$5:$X$5,'实盘净值数据(iFinD公式)'!$B12:$X12/'实盘净值数据(iFinD公式)'!$B$5:$X$5,'实盘净值数据(iFinD公式)'!$B13:$X13/'实盘净值数据(iFinD公式)'!$B12:$X12)/SUMPRODUCT(实盘持仓配置!$B$5:$X$5,'实盘净值数据(iFinD公式)'!$B12:$X12/'实盘净值数据(iFinD公式)'!$B$5:$X$5)-1) | G13: =IF(E13="","",E13/MAX(E$5:E13)-1) | H13: =IF(OR((ROW()-1)<7,'实盘净值数据(iFinD公式)'!$A13="",'实盘净值数据(iFinD公式)'!$B13=""),"",SUMPRODUCT(实盘持仓配置!$B$6:$X$6,'实盘净值数据(iFinD公式)'!$B13:$X13/'实盘净值数据(iFinD公式)'!$B$7:$X$7)*(1-实盘持仓配置!$Z$6)^(('实盘净值数据(iFinD公式)'!$A13-'实盘净值数据(iFinD公式)'!$A$7)/365)) | I13: =IF(OR(H12="",'实盘净值数据(iFinD公式)'!$A13="",'实盘净值数据(iFinD公式)'!$B13=""),"",SUMPRODUCT(实盘持仓配置!$B$6:$X$6,'实盘净值数据(iFinD公式)'!$B12:$X12/'实盘净值数据(iFinD公式)'!$B$7:$X$7,'实盘净值数据(iFinD公式)'!$B13:$X13/'实盘净值数据(iFinD公式)'!$B12:$X12)/SUMPRODUCT(实盘持仓配置!$B$6:$X$6,'实盘净值数据(iFinD公式)'!$B12:$X12/'实盘净值数据(iFinD公式)'!$B$7:$X$7)-1) | J13: =IF(H13="","",H13/MAX(H$5:H13)-1) | K13: =IF(OR((ROW()-1)<8,'实盘净值数据(iFinD公式)'!$A13="",'实盘净值数据(iFinD公式)'!$B13=""),"",SUMPRODUCT(实盘持仓配置!$B$7:$X$7,'实盘净值数据(iFinD公式)'!$B13:$X13/'实盘净值数据(iFinD公式)'!$B$8:$X$8)*(1-实盘持仓配置!$Z$7)^(('实盘净值数据(iFinD公式)'!$A13-'实盘净值数据(iFinD公式)'!$A$8)/365)) | L13: =IF(OR(K12="",'实盘净值数据(iFinD公式)'!$A13="",'实盘净值数据(iFinD公式)'!$B13=""),"",SUMPRODUCT(实盘持仓配置!$B$7:$X$7,'实盘净值数据(iFinD公式)'!$B12:$X12/'实盘净值数据(iFinD公式)'!$B$8:$X$8,'实盘净值数据(iFinD公式)'!$B13:$X13/'实盘净值数据(iFinD公式)'!$B12:$X12)/SUMPRODUCT(实盘持仓配置!$B$7:$X$7,'实盘净值数据(iFinD公式)'!$B12:$X12/'实盘净值数据(iFinD公式)'!$B$8:$X$8)-1) | M13: =IF(K13="","",K13/MAX(K$5:K13)-1) | N13: =IF(OR((ROW()-1)<5,'实盘净值数据(iFinD公式)'!$A13="",'实盘净值数据(iFinD公式)'!$B13=""),"",SUMPRODUCT(实盘持仓配置!$B$8:$X$8,'实盘净值数据(iFinD公式)'!$B13:$X13/'实盘净值数据(iFinD公式)'!$B$5:$X$5)*(1-实盘持仓配置!$Z$8)^(('实盘净值数据(iFinD公式)'!$A13-'实盘净值数据(iFinD公式)'!$A$5)/365)) | O13: =IF(OR(N12="",'实盘净值数据(iFinD公式)'!$A13="",'实盘净值数据(iFinD公式)'!$B13=""),"",SUMPRODUCT(实盘持仓配置!$B$8:$X$8,'实盘净值数据(iFinD公式)'!$B12:$X12/'实盘净值数据(iFinD公式)'!$B$5:$X$5,'实盘净值数据(iFinD公式)'!$B13:$X13/'实盘净值数据(iFinD公式)'!$B12:$X12)/SUMPRODUCT(实盘持仓配置!$B$8:$X$8,'实盘净值数据(iFinD公式)'!$B12:$X12/'实盘净值数据(iFinD公式)'!$B$5:$X$5)-1) | P13: =IF(N13="","",N13/MAX(N$5:N13)-1) | Q13: =IF(OR((ROW()-1)<8,'实盘净值数据(iFinD公式)'!$A13="",'实盘净值数据(iFinD公式)'!$B13=""),"",SUMPRODUCT(实盘持仓配置!$B$9:$X$9,'实盘净值数据(iFinD公式)'!$B13:$X13/'实盘净值数据(iFinD公式)'!$B$8:$X$8)*(1-实盘持仓配置!$Z$9)^(('实盘净值数据(iFinD公式)'!$A13-'实盘净值数据(iFinD公式)'!$A$8)/365)) | R13: =IF(OR(Q12="",'实盘净值数据(iFinD公式)'!$A13="",'实盘净值数据(iFinD公式)'!$B13=""),"",SUMPRODUCT(实盘持仓配置!$B$9:$X$9,'实盘净值数据(iFinD公式)'!$B12:$X12/'实盘净值数据(iFinD公式)'!$B$8:$X$8,'实盘净值数据(iFinD公式)'!$B13:$X13/'实盘净值数据(iFinD公式)'!$B12:$X12)/SUMPRODUCT(实盘持仓配置!$B$9:$X$9,'实盘净值数据(iFinD公式)'!$B12:$X12/'实盘净值数据(iFinD公式)'!$B$8:$X$8)-1) | S13: =IF(Q13="","",Q13/MAX(Q$5:Q13)-1)
A14: =IF('实盘净值数据(iFinD公式)'!A14="","",'实盘净值数据(iFinD公式)'!A14) | B14: =IF(OR((ROW()-1)<6,'实盘净值数据(iFinD公式)'!$A14="",'实盘净值数据(iFinD公式)'!$B14=""),"",SUMPRODUCT(实盘持仓配置!$B$4:$X$4,'实盘净值数据(iFinD公式)'!$B14:$X14/'实盘净值数据(iFinD公式)'!$B$6:$X$6)*(1-实盘持仓配置!$Z$4)^(('实盘净值数据(iFinD公式)'!$A14-'实盘净值数据(iFinD公式)'!$A$6)/365)) | C14: =IF(OR(B13="",'实盘净值数据(iFinD公式)'!$A14="",'实盘净值数据(iFinD公式)'!$B14=""),"",SUMPRODUCT(实盘持仓配置!$B$4:$X$4,'实盘净值数据(iFinD公式)'!$B13:$X13/'实盘净值数据(iFinD公式)'!$B$6:$X$6,'实盘净值数据(iFinD公式)'!$B14:$X14/'实盘净值数据(iFinD公式)'!$B13:$X13)/SUMPRODUCT(实盘持仓配置!$B$4:$X$4,'实盘净值数据(iFinD公式)'!$B13:$X13/'实盘净值数据(iFinD公式)'!$B$6:$X$6)-1) | D14: =IF(B14="","",B14/MAX(B$5:B14)-1) | E14: =IF(OR((ROW()-1)<5,'实盘净值数据(iFinD公式)'!$A14="",'实盘净值数据(iFinD公式)'!$B14=""),"",SUMPRODUCT(实盘持仓配置!$B$5:$X$5,'实盘净值数据(iFinD公式)'!$B14:$X14/'实盘净值数据(iFinD公式)'!$B$5:$X$5)*(1-实盘持仓配置!$Z$5)^(('实盘净值数据(iFinD公式)'!$A14-'实盘净值数据(iFinD公式)'!$A$5)/365)) | F14: =IF(OR(E13="",'实盘净值数据(iFinD公式)'!$A14="",'实盘净值数据(iFinD公式)'!$B14=""),"",SUMPRODUCT(实盘持仓配置!$B$5:$X$5,'实盘净值数据(iFinD公式)'!$B13:$X13/'实盘净值数据(iFinD公式)'!$B$5:$X$5,'实盘净值数据(iFinD公式)'!$B14:$X14/'实盘净值数据(iFinD公式)'!$B13:$X13)/SUMPRODUCT(实盘持仓配置!$B$5:$X$5,'实盘净值数据(iFinD公式)'!$B13:$X13/'实盘净值数据(iFinD公式)'!$B$5:$X$5)-1) | G14: =IF(E14="","",E14/MAX(E$5:E14)-1) | H14: =IF(OR((ROW()-1)<7,'实盘净值数据(iFinD公式)'!$A14="",'实盘净值数据(iFinD公式)'!$B14=""),"",SUMPRODUCT(实盘持仓配置!$B$6:$X$6,'实盘净值数据(iFinD公式)'!$B14:$X14/'实盘净值数据(iFinD公式)'!$B$7:$X$7)*(1-实盘持仓配置!$Z$6)^(('实盘净值数据(iFinD公式)'!$A14-'实盘净值数据(iFinD公式)'!$A$7)/365)) | I14: =IF(OR(H13="",'实盘净值数据(iFinD公式)'!$A14="",'实盘净值数据(iFinD公式)'!$B14=""),"",SUMPRODUCT(实盘持仓配置!$B$6:$X$6,'实盘净值数据(iFinD公式)'!$B13:$X13/'实盘净值数据(iFinD公式)'!$B$7:$X$7,'实盘净值数据(iFinD公式)'!$B14:$X14/'实盘净值数据(iFinD公式)'!$B13:$X13)/SUMPRODUCT(实盘持仓配置!$B$6:$X$6,'实盘净值数据(iFinD公式)'!$B13:$X13/'实盘净值数据(iFinD公式)'!$B$7:$X$7)-1) | J14: =IF(H14="","",H14/MAX(H$5:H14)-1) | K14: =IF(OR((ROW()-1)<8,'实盘净值数据(iFinD公式)'!$A14="",'实盘净值数据(iFinD公式)'!$B14=""),"",SUMPRODUCT(实盘持仓配置!$B$7:$X$7,'实盘净值数据(iFinD公式)'!$B14:$X14/'实盘净值数据(iFinD公式)'!$B$8:$X$8)*(1-实盘持仓配置!$Z$7)^(('实盘净值数据(iFinD公式)'!$A14-'实盘净值数据(iFinD公式)'!$A$8)/365)) | L14: =IF(OR(K13="",'实盘净值数据(iFinD公式)'!$A14="",'实盘净值数据(iFinD公式)'!$B14=""),"",SUMPRODUCT(实盘持仓配置!$B$7:$X$7,'实盘净值数据(iFinD公式)'!$B13:$X13/'实盘净值数据(iFinD公式)'!$B$8:$X$8,'实盘净值数据(iFinD公式)'!$B14:$X14/'实盘净值数据(iFinD公式)'!$B13:$X13)/SUMPRODUCT(实盘持仓配置!$B$7:$X$7,'实盘净值数据(iFinD公式)'!$B13:$X13/'实盘净值数据(iFinD公式)'!$B$8:$X$8)-1) | M14: =IF(K14="","",K14/MAX(K$5:K14)-1) | N14: =IF(OR((ROW()-1)<5,'实盘净值数据(iFinD公式)'!$A14="",'实盘净值数据(iFinD公式)'!$B14=""),"",SUMPRODUCT(实盘持仓配置!$B$8:$X$8,'实盘净值数据(iFinD公式)'!$B14:$X14/'实盘净值数据(iFinD公式)'!$B$5:$X$5)*(1-实盘持仓配置!$Z$8)^(('实盘净值数据(iFinD公式)'!$A14-'实盘净值数据(iFinD公式)'!$A$5)/365)) | O14: =IF(OR(N13="",'实盘净值数据(iFinD公式)'!$A14="",'实盘净值数据(iFinD公式)'!$B14=""),"",SUMPRODUCT(实盘持仓配置!$B$8:$X$8,'实盘净值数据(iFinD公式)'!$B13:$X13/'实盘净值数据(iFinD公式)'!$B$5:$X$5,'实盘净值数据(iFinD公式)'!$B14:$X14/'实盘净值数据(iFinD公式)'!$B13:$X13)/SUMPRODUCT(实盘持仓配置!$B$8:$X$8,'实盘净值数据(iFinD公式)'!$B13:$X13/'实盘净值数据(iFinD公式)'!$B$5:$X$5)-1) | P14: =IF(N14="","",N14/MAX(N$5:N14)-1) | Q14: =IF(OR((ROW()-1)<8,'实盘净值数据(iFinD公式)'!$A14="",'实盘净值数据(iFinD公式)'!$B14=""),"",SUMPRODUCT(实盘持仓配置!$B$9:$X$9,'实盘净值数据(iFinD公式)'!$B14:$X14/'实盘净值数据(iFinD公式)'!$B$8:$X$8)*(1-实盘持仓配置!$Z$9)^(('实盘净值数据(iFinD公式)'!$A14-'实盘净值数据(iFinD公式)'!$A$8)/365)) | R14: =IF(OR(Q13="",'实盘净值数据(iFinD公式)'!$A14="",'实盘净值数据(iFinD公式)'!$B14=""),"",SUMPRODUCT(实盘持仓配置!$B$9:$X$9,'实盘净值数据(iFinD公式)'!$B13:$X13/'实盘净值数据(iFinD公式)'!$B$8:$X$8,'实盘净值数据(iFinD公式)'!$B14:$X14/'实盘净值数据(iFinD公式)'!$B13:$X13)/SUMPRODUCT(实盘持仓配置!$B$9:$X$9,'实盘净值数据(iFinD公式)'!$B13:$X13/'实盘净值数据(iFinD公式)'!$B$8:$X$8)-1) | S14: =IF(Q14="","",Q14/MAX(Q$5:Q14)-1)
A15: =IF('实盘净值数据(iFinD公式)'!A15="","",'实盘净值数据(iFinD公式)'!A15) | B15: =IF(OR((ROW()-1)<6,'实盘净值数据(iFinD公式)'!$A15="",'实盘净值数据(iFinD公式)'!$B15=""),"",SUMPRODUCT(实盘持仓配置!$B$4:$X$4,'实盘净值数据(iFinD公式)'!$B15:$X15/'实盘净值数据(iFinD公式)'!$B$6:$X$6)*(1-实盘持仓配置!$Z$4)^(('实盘净值数据(iFinD公式)'!$A15-'实盘净值数据(iFinD公式)'!$A$6)/365)) | C15: =IF(OR(B14="",'实盘净值数据(iFinD公式)'!$A15="",'实盘净值数据(iFinD公式)'!$B15=""),"",SUMPRODUCT(实盘持仓配置!$B$4:$X$4,'实盘净值数据(iFinD公式)'!$B14:$X14/'实盘净值数据(iFinD公式)'!$B$6:$X$6,'实盘净值数据(iFinD公式)'!$B15:$X15/'实盘净值数据(iFinD公式)'!$B14:$X14)/SUMPRODUCT(实盘持仓配置!$B$4:$X$4,'实盘净值数据(iFinD公式)'!$B14:$X14/'实盘净值数据(iFinD公式)'!$B$6:$X$6)-1) | D15: =IF(B15="","",B15/MAX(B$5:B15)-1) | E15: =IF(OR((ROW()-1)<5,'实盘净值数据(iFinD公式)'!$A15="",'实盘净值数据(iFinD公式)'!$B15=""),"",SUMPRODUCT(实盘持仓配置!$B$5:$X$5,'实盘净值数据(iFinD公式)'!$B15:$X15/'实盘净值数据(iFinD公式)'!$B$5:$X$5)*(1-实盘持仓配置!$Z$5)^(('实盘净值数据(iFinD公式)'!$A15-'实盘净值数据(iFinD公式)'!$A$5)/365)) | F15: =IF(OR(E14="",'实盘净值数据(iFinD公式)'!$A15="",'实盘净值数据(iFinD公式)'!$B15=""),"",SUMPRODUCT(实盘持仓配置!$B$5:$X$5,'实盘净值数据(iFinD公式)'!$B14:$X14/'实盘净值数据(iFinD公式)'!$B$5:$X$5,'实盘净值数据(iFinD公式)'!$B15:$X15/'实盘净值数据(iFinD公式)'!$B14:$X14)/SUMPRODUCT(实盘持仓配置!$B$5:$X$5,'实盘净值数据(iFinD公式)'!$B14:$X14/'实盘净值数据(iFinD公式)'!$B$5:$X$5)-1) | G15: =IF(E15="","",E15/MAX(E$5:E15)-1) | H15: =IF(OR((ROW()-1)<7,'实盘净值数据(iFinD公式)'!$A15="",'实盘净值数据(iFinD公式)'!$B15=""),"",SUMPRODUCT(实盘持仓配置!$B$6:$X$6,'实盘净值数据(iFinD公式)'!$B15:$X15/'实盘净值数据(iFinD公式)'!$B$7:$X$7)*(1-实盘持仓配置!$Z$6)^(('实盘净值数据(iFinD公式)'!$A15-'实盘净值数据(iFinD公式)'!$A$7)/365)) | I15: =IF(OR(H14="",'实盘净值数据(iFinD公式)'!$A15="",'实盘净值数据(iFinD公式)'!$B15=""),"",SUMPRODUCT(实盘持仓配置!$B$6:$X$6,'实盘净值数据(iFinD公式)'!$B14:$X14/'实盘净值数据(iFinD公式)'!$B$7:$X$7,'实盘净值数据(iFinD公式)'!$B15:$X15/'实盘净值数据(iFinD公式)'!$B14:$X14)/SUMPRODUCT(实盘持仓配置!$B$6:$X$6,'实盘净值数据(iFinD公式)'!$B14:$X14/'实盘净值数据(iFinD公式)'!$B$7:$X$7)-1) | J15: =IF(H15="","",H15/MAX(H$5:H15)-1) | K15: =IF(OR((ROW()-1)<8,'实盘净值数据(iFinD公式)'!$A15="",'实盘净值数据(iFinD公式)'!$B15=""),"",SUMPRODUCT(实盘持仓配置!$B$7:$X$7,'实盘净值数据(iFinD公式)'!$B15:$X15/'实盘净值数据(iFinD公式)'!$B$8:$X$8)*(1-实盘持仓配置!$Z$7)^(('实盘净值数据(iFinD公式)'!$A15-'实盘净值数据(iFinD公式)'!$A$8)/365)) | L15: =IF(OR(K14="",'实盘净值数据(iFinD公式)'!$A15="",'实盘净值数据(iFinD公式)'!$B15=""),"",SUMPRODUCT(实盘持仓配置!$B$7:$X$7,'实盘净值数据(iFinD公式)'!$B14:$X14/'实盘净值数据(iFinD公式)'!$B$8:$X$8,'实盘净值数据(iFinD公式)'!$B15:$X15/'实盘净值数据(iFinD公式)'!$B14:$X14)/SUMPRODUCT(实盘持仓配置!$B$7:$X$7,'实盘净值数据(iFinD公式)'!$B14:$X14/'实盘净值数据(iFinD公式)'!$B$8:$X$8)-1) | M15: =IF(K15="","",K15/MAX(K$5:K15)-1) | N15: =IF(OR((ROW()-1)<5,'实盘净值数据(iFinD公式)'!$A15="",'实盘净值数据(iFinD公式)'!$B15=""),"",SUMPRODUCT(实盘持仓配置!$B$8:$X$8,'实盘净值数据(iFinD公式)'!$B15:$X15/'实盘净值数据(iFinD公式)'!$B$5:$X$5)*(1-实盘持仓配置!$Z$8)^(('实盘净值数据(iFinD公式)'!$A15-'实盘净值数据(iFinD公式)'!$A$5)/365)) | O15: =IF(OR(N14="",'实盘净值数据(iFinD公式)'!$A15="",'实盘净值数据(iFinD公式)'!$B15=""),"",SUMPRODUCT(实盘持仓配置!$B$8:$X$8,'实盘净值数据(iFinD公式)'!$B14:$X14/'实盘净值数据(iFinD公式)'!$B$5:$X$5,'实盘净值数据(iFinD公式)'!$B15:$X15/'实盘净值数据(iFinD公式)'!$B14:$X14)/SUMPRODUCT(实盘持仓配置!$B$8:$X$8,'实盘净值数据(iFinD公式)'!$B14:$X14/'实盘净值数据(iFinD公式)'!$B$5:$X$5)-1) | P15: =IF(N15="","",N15/MAX(N$5:N15)-1) | Q15: =IF(OR((ROW()-1)<8,'实盘净值数据(iFinD公式)'!$A15="",'实盘净值数据(iFinD公式)'!$B15=""),"",SUMPRODUCT(实盘持仓配置!$B$9:$X$9,'实盘净值数据(iFinD公式)'!$B15:$X15/'实盘净值数据(iFinD公式)'!$B$8:$X$8)*(1-实盘持仓配置!$Z$9)^(('实盘净值数据(iFinD公式)'!$A15-'实盘净值数据(iFinD公式)'!$A$8)/365)) | R15: =IF(OR(Q14="",'实盘净值数据(iFinD公式)'!$A15="",'实盘净值数据(iFinD公式)'!$B15=""),"",SUMPRODUCT(实盘持仓配置!$B$9:$X$9,'实盘净值数据(iFinD公式)'!$B14:$X14/'实盘净值数据(iFinD公式)'!$B$8:$X$8,'实盘净值数据(iFinD公式)'!$B15:$X15/'实盘净值数据(iFinD公式)'!$B14:$X14)/SUMPRODUCT(实盘持仓配置!$B$9:$X$9,'实盘净值数据(iFinD公式)'!$B14:$X14/'实盘净值数据(iFinD公式)'!$B$8:$X$8)-1) | S15: =IF(Q15="","",Q15/MAX(Q$5:Q15)-1)
A16: =IF('实盘净值数据(iFinD公式)'!A16="","",'实盘净值数据(iFinD公式)'!A16) | B16: =IF(OR((ROW()-1)<6,'实盘净值数据(iFinD公式)'!$A16="",'实盘净值数据(iFinD公式)'!$B16=""),"",SUMPRODUCT(实盘持仓配置!$B$4:$X$4,'实盘净值数据(iFinD公式)'!$B16:$X16/'实盘净值数据(iFinD公式)'!$B$6:$X$6)*(1-实盘持仓配置!$Z$4)^(('实盘净值数据(iFinD公式)'!$A16-'实盘净值数据(iFinD公式)'!$A$6)/365)) | C16: =IF(OR(B15="",'实盘净值数据(iFinD公式)'!$A16="",'实盘净值数据(iFinD公式)'!$B16=""),"",SUMPRODUCT(实盘持仓配置!$B$4:$X$4,'实盘净值数据(iFinD公式)'!$B15:$X15/'实盘净值数据(iFinD公式)'!$B$6:$X$6,'实盘净值数据(iFinD公式)'!$B16:$X16/'实盘净值数据(iFinD公式)'!$B15:$X15)/SUMPRODUCT(实盘持仓配置!$B$4:$X$4,'实盘净值数据(iFinD公式)'!$B15:$X15/'实盘净值数据(iFinD公式)'!$B$6:$X$6)-1) | D16: =IF(B16="","",B16/MAX(B$5:B16)-1) | E16: =IF(OR((ROW()-1)<5,'实盘净值数据(iFinD公式)'!$A16="",'实盘净值数据(iFinD公式)'!$B16=""),"",SUMPRODUCT(实盘持仓配置!$B$5:$X$5,'实盘净值数据(iFinD公式)'!$B16:$X16/'实盘净值数据(iFinD公式)'!$B$5:$X$5)*(1-实盘持仓配置!$Z$5)^(('实盘净值数据(iFinD公式)'!$A16-'实盘净值数据(iFinD公式)'!$A$5)/365)) | F16: =IF(OR(E15="",'实盘净值数据(iFinD公式)'!$A16="",'实盘净值数据(iFinD公式)'!$B16=""),"",SUMPRODUCT(实盘持仓配置!$B$5:$X$5,'实盘净值数据(iFinD公式)'!$B15:$X15/'实盘净值数据(iFinD公式)'!$B$5:$X$5,'实盘净值数据(iFinD公式)'!$B16:$X16/'实盘净值数据(iFinD公式)'!$B15:$X15)/SUMPRODUCT(实盘持仓配置!$B$5:$X$5,'实盘净值数据(iFinD公式)'!$B15:$X15/'实盘净值数据(iFinD公式)'!$B$5:$X$5)-1) | G16: =IF(E16="","",E16/MAX(E$5:E16)-1) | H16: =IF(OR((ROW()-1)<7,'实盘净值数据(iFinD公式)'!$A16="",'实盘净值数据(iFinD公式)'!$B16=""),"",SUMPRODUCT(实盘持仓配置!$B$6:$X$6,'实盘净值数据(iFinD公式)'!$B16:$X16/'实盘净值数据(iFinD公式)'!$B$7:$X$7)*(1-实盘持仓配置!$Z$6)^(('实盘净值数据(iFinD公式)'!$A16-'实盘净值数据(iFinD公式)'!$A$7)/365)) | I16: =IF(OR(H15="",'实盘净值数据(iFinD公式)'!$A16="",'实盘净值数据(iFinD公式)'!$B16=""),"",SUMPRODUCT(实盘持仓配置!$B$6:$X$6,'实盘净值数据(iFinD公式)'!$B15:$X15/'实盘净值数据(iFinD公式)'!$B$7:$X$7,'实盘净值数据(iFinD公式)'!$B16:$X16/'实盘净值数据(iFinD公式)'!$B15:$X15)/SUMPRODUCT(实盘持仓配置!$B$6:$X$6,'实盘净值数据(iFinD公式)'!$B15:$X15/'实盘净值数据(iFinD公式)'!$B$7:$X$7)-1) | J16: =IF(H16="","",H16/MAX(H$5:H16)-1) | K16: =IF(OR((ROW()-1)<8,'实盘净值数据(iFinD公式)'!$A16="",'实盘净值数据(iFinD公式)'!$B16=""),"",SUMPRODUCT(实盘持仓配置!$B$7:$X$7,'实盘净值数据(iFinD公式)'!$B16:$X16/'实盘净值数据(iFinD公式)'!$B$8:$X$8)*(1-实盘持仓配置!$Z$7)^(('实盘净值数据(iFinD公式)'!$A16-'实盘净值数据(iFinD公式)'!$A$8)/365)) | L16: =IF(OR(K15="",'实盘净值数据(iFinD公式)'!$A16="",'实盘净值数据(iFinD公式)'!$B16=""),"",SUMPRODUCT(实盘持仓配置!$B$7:$X$7,'实盘净值数据(iFinD公式)'!$B15:$X15/'实盘净值数据(iFinD公式)'!$B$8:$X$8,'实盘净值数据(iFinD公式)'!$B16:$X16/'实盘净值数据(iFinD公式)'!$B15:$X15)/SUMPRODUCT(实盘持仓配置!$B$7:$X$7,'实盘净值数据(iFinD公式)'!$B15:$X15/'实盘净值数据(iFinD公式)'!$B$8:$X$8)-1) | M16: =IF(K16="","",K16/MAX(K$5:K16)-1) | N16: =IF(OR((ROW()-1)<5,'实盘净值数据(iFinD公式)'!$A16="",'实盘净值数据(iFinD公式)'!$B16=""),"",SUMPRODUCT(实盘持仓配置!$B$8:$X$8,'实盘净值数据(iFinD公式)'!$B16:$X16/'实盘净值数据(iFinD公式)'!$B$5:$X$5)*(1-实盘持仓配置!$Z$8)^(('实盘净值数据(iFinD公式)'!$A16-'实盘净值数据(iFinD公式)'!$A$5)/365)) | O16: =IF(OR(N15="",'实盘净值数据(iFinD公式)'!$A16="",'实盘净值数据(iFinD公式)'!$B16=""),"",SUMPRODUCT(实盘持仓配置!$B$8:$X$8,'实盘净值数据(iFinD公式)'!$B15:$X15/'实盘净值数据(iFinD公式)'!$B$5:$X$5,'实盘净值数据(iFinD公式)'!$B16:$X16/'实盘净值数据(iFinD公式)'!$B15:$X15)/SUMPRODUCT(实盘持仓配置!$B$8:$X$8,'实盘净值数据(iFinD公式)'!$B15:$X15/'实盘净值数据(iFinD公式)'!$B$5:$X$5)-1) | P16: =IF(N16="","",N16/MAX(N$5:N16)-1) | Q16: =IF(OR((ROW()-1)<8,'实盘净值数据(iFinD公式)'!$A16="",'实盘净值数据(iFinD公式)'!$B16=""),"",SUMPRODUCT(实盘持仓配置!$B$9:$X$9,'实盘净值数据(iFinD公式)'!$B16:$X16/'实盘净值数据(iFinD公式)'!$B$8:$X$8)*(1-实盘持仓配置!$Z$9)^(('实盘净值数据(iFinD公式)'!$A16-'实盘净值数据(iFinD公式)'!$A$8)/365)) | R16: =IF(OR(Q15="",'实盘净值数据(iFinD公式)'!$A16="",'实盘净值数据(iFinD公式)'!$B16=""),"",SUMPRODUCT(实盘持仓配置!$B$9:$X$9,'实盘净值数据(iFinD公式)'!$B15:$X15/'实盘净值数据(iFinD公式)'!$B$8:$X$8,'实盘净值数据(iFinD公式)'!$B16:$X16/'实盘净值数据(iFinD公式)'!$B15:$X15)/SUMPRODUCT(实盘持仓配置!$B$9:$X$9,'实盘净值数据(iFinD公式)'!$B15:$X15/'实盘净值数据(iFinD公式)'!$B$8:$X$8)-1) | S16: =IF(Q16="","",Q16/MAX(Q$5:Q16)-1)
