Workbook
Name AccountMethod: [1]投资!$C$66
Name DebtFinancing: [1]筹资!$E$22
Name DepositRate: [1]筹资!$B$6
Name EndYear: [1]首页!$C$9
Name EstiDate: 首页!$C$7
Name FinancingMethod: [1]筹资!$B$18
Name ics: 非财务信息!$E$17
Name iRepType: 1
Name IsInitialization: 0
Name IssuePrice: [1]筹资!$E$24
Name LastEndYear: 2007
Name LastEstiDate: 40128
Name LastEstNum: 2
Name LastHasNew: "否"
Name LastReportList: "2004;2005;2006;2007"
Name LastStYear: 2004
Name LastTransitionYear: 0
Name LastWindCode: "600028.SH"
Name LDebtFinancing: [1]筹资!$E$23
Name LongBorrowRate: [1]筹资!$B$8
Name MinCashBalance: [1]筹资!$B$9
Name nrAfter: 假设表!$C$8:$C$162
Name nrBefore: 假设表!$C$4:$C$7
Name NRPredictWay: 假设表!$C:$C
Name PeriodGrowth: [1]绝对估值!$C$5
Name RepType: [1]首页!$C$11
Name ShortBorrowRate: [1]筹资!$B$7
Name StockCode: 首页!$C$6
Name ThisEndYear: 2008
Name ThisEstiDate: 40128
Name ThisEstNum: 3
Name ThisHasNew: "否"
Name ThisReportList: "2005;2006;2007;2008"
Name ThisStYear: 2005
Name ThisTransitionYear: 0
Name ThisWindCode: "600028.SH"
Name unit: 10000
Name 高6: #REF!
Name 高6: #REF!

Sheet 首页
B9: 估值模型插件首页
B11: 需要填写的数据 | E11: 自动生成的数据
B13: 需要检查的数据 | C13: 如有数值，说明可能存在未导出的会计科目
B15: 研究部财务估值系统 | C15: A股标准估值模型 | E15: 版本号： | F15: v3.0.0.2
B17: 证券代码 | C17: 300223 | E17: 证券简称 | F17: 北京君正
B18: 预测日期 | C18: 46140 | E18: 最新收盘价（元） | F18: 124.02
B19: 历史数据始于（年） | C19: 2021 | E19: 最新股本（千股） | F19: 482540.72
B20: 历史数据止于（年） | C20: 2025 | E20: 分析师姓名 | F20: 程子盈
B21: 预测年份数 | C21: 10 | E21: 所属行业 | F21: Unknown
B22: 货币单位 | C22: 百万元 | E22: 关联模型ID | F22: 0
B23: 是否A+H股 | C23: 否 | E23: 港股证券简称
B24: 港股代码 | E24: H股价格
B25: A股评级 | C25: 买入 | E25: A股目标价
B26: A股评级变动 | C26: 维持 | E26: H股评级
B27: H股目标价 | E27: H股评级变动
B28: 市值（百万元） | C28: 59844.7 | E28: EV | F28: =C28+历史数据及预测表!H51+历史数据及预测表!H62+历史数据及预测表!H72+历史数据及预测表!H71 -> 59853.115
B30: 首页 | C30: 设置公司模型的全局参数
B31: 历史数据（原始） | C31: WIND自动导入
B32: 经营模型 | C32: 分析师手动录入收入成本的分拆预测，汇总数据汇总到前几行
B33: 假设表 | C33: 历史数据自动生成，预测数据根据所选方法生成
B34: 关键项目预测 | C34: 折旧信息需分析师手动输入相关数据，其他数据自动生成
B35: 历史数据及预测表 | C35: 历史数据自动生成，预测数据根据假设表生成
B36: 估值表 | C36: 自动生成，不可修改
B37: 非财务信息 | C37: 自动生成，不可修改
B38: 关键比率 | C38: 自动生成，不可修改
B39: 输出表-首页用表 | C39: 自动生成，不可修改
B40: 输出表-利润表 | C40: 自动生成，不可修改
B41: 输出表-资产负债表 | C41: 自动生成，不可修改
... B52: 数据单位： | C52: 目前系统所有的数据单位都为百万元，如自行录入数据，要注意单位处理。

Sheet Financials at a glance
C1: =历史数据及预测表!G4 -> 2024 | D1: =历史数据及预测表!H4 -> 2025 | E1: =历史数据及预测表!I4 -> 2026 | F1: =历史数据及预测表!J4 -> 2027 | G1: =历史数据及预测表!K4 -> 2028
B2: Overview
B3: Operating income (Rmb mn) | C3: ='输出表-首页用表'!C3 -> 4212.6259 | D3: ='输出表-首页用表'!D3 -> 4741.0076 | E3: ='输出表-首页用表'!E3 -> 8307.8438 | F3: ='输出表-首页用表'!F3 -> 10593.134 | G3: ='输出表-首页用表'!G3 -> 12526.556
B4: Growth rate (YoY,%) | C4: ='输出表-首页用表'!C4 -> -0.070250496 | D4: ='输出表-首页用表'!D4 -> 0.12542811 | E4: ='输出表-首页用表'!E4 -> 0.75233716 | F4: ='输出表-首页用表'!F4 -> 0.27507621 | G4: ='输出表-首页用表'!G4 -> 0.18251654
B5: Net profits(Rmb mn) | C5: ='输出表-首页用表'!C5 -> 366.2021 | D5: ='输出表-首页用表'!D5 -> 376.22602 | E5: ='输出表-首页用表'!E5 -> 2509.6073 | F5: ='输出表-首页用表'!F5 -> 2865.056 | G5: ='输出表-首页用表'!G5 -> 2754.3684
B6: Growth rate (YoY,%) | C6: ='输出表-首页用表'!C6 -> -0.31838231 | D6: ='输出表-首页用表'!D6 -> 0.027372662 | E6: ='输出表-首页用表'!E6 -> 5.6704777 | F6: ='输出表-首页用表'!F6 -> 0.14163519 | G6: ='输出表-首页用表'!G6 -> -0.038633644
B7: EPS (Rmb, Basic) | C7: ='输出表-首页用表'!C7 -> 0.7604 | D7: ='输出表-首页用表'!D7 -> 0.7803 | E7: ='输出表-首页用表'!E7 -> 5.2008197 | F7: ='输出表-首页用表'!F7 -> 5.9374387 | G7: ='输出表-首页用表'!G7 -> 5.7080538
B8: Gross margin (%) | C8: ='输出表-首页用表'!C8 -> 0.36729198 | D8: ='输出表-首页用表'!D8 -> 0.34086456 | E8: ='输出表-首页用表'!E8 -> 0.49659152 | F8: ='输出表-首页用表'!F8 -> 0.46612794 | G8: ='输出表-首页用表'!G8 -> 0.40944851
B9: ROE (%) | C9: ='输出表-首页用表'!C9 -> 0.030380316 | D9: ='输出表-首页用表'!D9 -> 0.030221729 | E9: ='输出表-首页用表'!E9 -> 0.16872113 | F9: ='输出表-首页用表'!F9 -> 0.16186463 | G9: ='输出表-首页用表'!G9 -> 0.13486911
B10: BVPS (Rmb) | C10: ='输出表-首页用表'!C10 -> 24.980122 | D10: ='输出表-首页用表'!D10 -> 25.798565 | E10: ='输出表-首页用表'!E10 -> 30.824945 | F10: ='输出表-首页用表'!F10 -> 36.681508 | G10: ='输出表-首页用表'!G10 -> 42.322914
B11: PE (x) | C11: ='输出表-首页用表'!C11 -> 163.09837 | D11: ='输出表-首页用表'!D11 -> 158.93887 | E11: ='输出表-首页用表'!E11 -> 23.846241 | F11: ='输出表-首页用表'!F11 -> 20.887794 | G11: ='输出表-首页用表'!G11 -> 21.727195
B12: PB (x) | C12: ='输出表-首页用表'!C12 -> 4.9647475 | D12: ='输出表-首页用表'!D12 -> 4.8072441 | E12: ='输出表-首页用表'!E12 -> 4.0233649 | F12: ='输出表-首页用表'!F12 -> 3.3809951 | G12: ='输出表-首页用表'!G12 -> 2.9303275
B13: PS (x) | C13: ='输出表-首页用表'!C13 -> 14.206033 | D13: ='输出表-首页用表'!D13 -> 12.622781 | E13: ='输出表-首页用表'!E13 -> 7.2033974 | F13: ='输出表-首页用表'!F13 -> 5.6493858 | G13: ='输出表-首页用表'!G13 -> 4.7774265
B14: EV/EBITDA | C14: ='输出表-首页用表'!C14 -> 113.29726 | D14: ='输出表-首页用表'!D14 -> 120.83313 | E14: ='输出表-首页用表'!E14 -> 22.014455 | F14: ='输出表-首页用表'!F14 -> 18.951601 | G14: ='输出表-首页用表'!G14 -> 19.850602
B15: Income statement (mn)
B16: Operating income | C16: ='输出表-利润表'!C3 -> 4212.6259 | D16: ='输出表-利润表'!D3 -> 4741.0076 | E16: ='输出表-利润表'!E3 -> 8307.8438 | F16: ='输出表-利润表'!F3 -> 10593.134 | G16: ='输出表-利润表'!G3 -> 12526.556
B17: COGS | C17: ='输出表-利润表'!C4 -> 2665.3622 | D17: ='输出表-利润表'!D4 -> 3124.9661 | E17: ='输出表-利润表'!E4 -> 4182.239 | F17: ='输出表-利润表'!F4 -> 5655.3783 | G17: ='输出表-利润表'!G4 -> 7397.5763
B18: Gross profit margin | C18: ='输出表-利润表'!C5 -> 0.36729198 | D18: ='输出表-利润表'!D5 -> 0.34086456 | E18: ='输出表-利润表'!E5 -> 0.49659152 | F18: ='输出表-利润表'!F5 -> 0.46612794 | G18: ='输出表-利润表'!G5 -> 0.40944851
B19: Taxes and surcharges | C19: ='输出表-利润表'!C6 -> 8.6082334 | D19: ='输出表-利润表'!D6 -> 13.127126 | E19: ='输出表-利润表'!E6 -> 19.482823 | F19: ='输出表-利润表'!F6 -> 25.273084 | G19: ='输出表-利润表'!G6 -> 31.315379
B20: Selling expenses | C20: ='输出表-利润表'!C7 -> 294.59831 | D20: ='输出表-利润表'!D7 -> 319.8337 | E20: ='输出表-利润表'!E7 -> 383.80044 | F20: ='输出表-利润表'!F7 -> 452.88452 | G20: ='输出表-利润表'!G7 -> 525.34604
B21: Selling expenses ratio | C21: ='输出表-利润表'!C8 -> 0.069932226 | D21: ='输出表-利润表'!D8 -> 0.067461123 | E21: ='输出表-利润表'!E8 -> 0.046197359 | F21: ='输出表-利润表'!F8 -> 0.042752647 | G21: ='输出表-利润表'!G8 -> 0.041938585
B22: Administrative expenses | C22: ='输出表-利润表'!C9 -> 215.16816 | D22: ='输出表-利润表'!D9 -> 268.14405 | E22: ='输出表-利润表'!E9 -> 321.77286 | F22: ='输出表-利润表'!F9 -> 379.69197 | G22: ='输出表-利润表'!G9 -> 440.44269
B23: Administrative expenses ratio | C23: ='输出表-利润表'!C10 -> 0.051076969 | D23: ='输出表-利润表'!D10 -> 0.056558451 | E23: ='输出表-利润表'!E10 -> 0.038731212 | F23: ='输出表-利润表'!F10 -> 0.035843214 | G23: ='输出表-利润表'!G10 -> 0.035160716
B24: Finance expenses | C24: ='输出表-利润表'!C11 -> -74.751475 | D24: ='输出表-利润表'!D11 -> -103.8903 | E24: ='输出表-利润表'!E11 -> -86.408107 | F24: ='输出表-利润表'!F11 -> -93.430081 | G24: ='输出表-利润表'!G11 -> -116.31471
B25: Finance expenses ratio | C25: ='输出表-利润表'!C12 -> -0.017744627 | D25: ='输出表-利润表'!D12 -> -0.021913126 | E25: ='输出表-利润表'!E12 -> -0.010400786 | F25: ='输出表-利润表'!F12 -> -0.0088198716 | G25: ='输出表-利润表'!G12 -> -0.0092854502
B26: R&D expense | C26: ='输出表-利润表'!C13 -> 681.33896 | D26: ='输出表-利润表'!D13 -> 712.02656 | E26: ='输出表-利润表'!E13 -> 854.43187 | F26: ='输出表-利润表'!F13 -> 1025.3182 | G26: ='输出表-利润表'!G13 -> 1230.3819
B27: R&D ratio | C27: ='输出表-利润表'!C14 -> 0.16173735 | D27: ='输出表-利润表'!D14 -> 0.15018465 | E27: ='输出表-利润表'!E14 -> 0.10284641 | F27: ='输出表-利润表'!F14 -> 0.096790832 | G27: ='输出表-利润表'!G14 -> 0.098221881
... B39: Net profit margin | C39: ='输出表-利润表'!C26 -> 0.086929651 | D39: ='输出表-利润表'!D26 -> 0.07935571 | E39: ='输出表-利润表'!E26 -> 0.30207685 | F39: ='输出表-利润表'!F26 -> 0.27046349 | G39: ='输出表-利润表'!G26 -> 0.21988234
B40: Balance sheet (mn)
B41: Cash and cash equivalent | C41: ='输出表-资产负债表'!C3 -> 3716.6476 | D41: ='输出表-资产负债表'!D3 -> 4091.6442 | E41: ='输出表-资产负债表'!E3 -> 7233.5472 | F41: ='输出表-资产负债表'!F3 -> 9237.1612 | G41: ='输出表-资产负债表'!G3 -> 10880.219
B42: Inventories | C42: ='输出表-资产负债表'!C4 -> 2672.0205 | D42: ='输出表-资产负债表'!D4 -> 2974.6471 | E42: ='输出表-资产负债表'!E4 -> 3145.0437 | F42: ='输出表-资产负债表'!F4 -> 4252.8445 | G42: ='输出表-资产负债表'!G4 -> 5562.9774
B43: Account receivable | C43: ='输出表-资产负债表'!C5 -> 388.72856 | D43: ='输出表-资产负债表'!D5 -> 466.53246 | E43: ='输出表-资产负债表'!E5 -> 774.57337 | F43: ='输出表-资产负债表'!F5 -> 1002.5153 | G43: ='输出表-资产负债表'!G5 -> 1195.3502
B44: Other current assets | C44: ='输出表-资产负债表'!C6 -> 1271.0588 | D44: ='输出表-资产负债表'!D6 -> 1160.5334 | E44: ='输出表-资产负债表'!E6 -> 1516.2664 | F44: ='输出表-资产负债表'!F6 -> 1625.17 | G44: ='输出表-资产负债表'!G6 -> 1657.7298
B45: Current assets | C45: ='输出表-资产负债表'!C7 -> 8048.4555 | D45: ='输出表-资产负债表'!D7 -> 8693.3572 | E45: ='输出表-资产负债表'!E7 -> 12669.431 | F45: ='输出表-资产负债表'!F7 -> 16117.691 | G45: ='输出表-资产负债表'!G7 -> 19296.276
B46: Fixed assets | C46: ='输出表-资产负债表'!C8 -> 467.43575 | D46: ='输出表-资产负债表'!D8 -> 462.27066 | E46: ='输出表-资产负债表'!E8 -> 599.35495 | F46: ='输出表-资产负债表'!F8 -> 717.43923 | G46: ='输出表-资产负债表'!G8 -> 816.52352
B47: Long-term equity investment | C47: ='输出表-资产负债表'!C9 -> 0.58587464 | D47: ='输出表-资产负债表'!D9 -> 0.84342957 | E47: ='输出表-资产负债表'!E9 -> 0.84342957 | F47: ='输出表-资产负债表'!F9 -> 0.84342957 | G47: ='输出表-资产负债表'!G9 -> 0.84342957
B48: Intangible assets | C48: ='输出表-资产负债表'!C10 -> 554.23946 | D48: ='输出表-资产负债表'!D10 -> 467.16111 | E48: ='输出表-资产负债表'!E10 -> 467.16111 | F48: ='输出表-资产负债表'!F10 -> 467.16111 | G48: ='输出表-资产负债表'!G10 -> 467.16111
B49: Other non-current assets | C49: ='输出表-资产负债表'!C11 -> 3856.2285 | D49: ='输出表-资产负债表'!D11 -> 3949.5729 | E49: ='输出表-资产负债表'!E11 -> 4057.0898 | F49: ='输出表-资产负债表'!F11 -> 4166.3802 | G49: ='输出表-资产负债表'!G11 -> 4272.1975
B50: Non-current assets | C50: ='输出表-资产负债表'!C12 -> 4878.4896 | D50: ='输出表-资产负债表'!D12 -> 4879.8481 | E50: ='输出表-资产负债表'!E12 -> 5124.4493 | F50: ='输出表-资产负债表'!F12 -> 5351.824 | G50: ='输出表-资产负债表'!G12 -> 5556.7255
B51: Total asset | C51: ='输出表-资产负债表'!C13 -> 12926.945 | D51: ='输出表-资产负债表'!D13 -> 13573.205 | E51: ='输出表-资产负债表'!E13 -> 17793.88 | F51: ='输出表-资产负债表'!F13 -> 21469.515 | G51: ='输出表-资产负债表'!G13 -> 24853.001
...

Sheet 历史数据
B1: 财务年报年份 | C1: =首页!C19 -> 2021 | D1: =C1+1 -> 2022 | E1: =D1+1 -> 2023 | F1: =E1+1 -> 2024 | G1: =F1+1 -> 2025 | I1: 季报数据
B2: 利润表
A3: TTL_OPER_INC | B3: 一、营业总收入 | C3: =5274059129.97/1000000 -> 5274.0591 | D3: =5411867514.79/1000000 -> 5411.8675 | E3: =4530925656.37/1000000 -> 4530.9257 | F3: =4212625881.35/1000000 -> 4212.6259 | G3: =4741007597.96/1000000 -> 4741.0076
A4: OPER_INC | B4: 营业收入 | C4: =5274059129.97/1000000 -> 5274.0591 | D4: =5411867514.79/1000000 -> 5411.8675 | E4: =4530925656.37/1000000 -> 4530.9257 | F4: =4212625881.35/1000000 -> 4212.6259 | G4: =4741007597.96/1000000 -> 4741.0076
A5: INT_INC | B5: 利息收入 | C5: =0/1000000 -> 0 | D5: =0/1000000 -> 0 | E5: =0/1000000 -> 0 | F5: =0/1000000 -> 0 | G5: =0/1000000 -> 0
A6: IN_PREM_EARN | B6: 已赚保费 | C6: =0/1000000 -> 0 | D6: =0/1000000 -> 0 | E6: =0/1000000 -> 0 | F6: =0/1000000 -> 0 | G6: =0/1000000 -> 0
A7: INC_FEE_COMM | B7: 手续费及佣金收入 | C7: =0/1000000 -> 0 | D7: =0/1000000 -> 0 | E7: =0/1000000 -> 0 | F7: =0/1000000 -> 0 | G7: =0/1000000 -> 0
A8: TTL_OPER_COST | B8: 二、营业总成本 | C8: =4374370170.65/1000000 -> 4374.3702 | D8: =4641432866.3/1000000 -> 4641.4329 | E8: =4040530925.21/1000000 -> 4040.5309 | F8: =3864463078.61/1000000 -> 3864.4631 | G8: =4407680380.74/1000000 -> 4407.6804
A9: OPER_COST | B9: 营业成本 | C9: =3324947550.35/1000000 -> 3324.9476 | D9: =3325137649.79/1000000 -> 3325.1376 | E9: =2850000488.26/1000000 -> 2850.0005 | F9: =2665362168.81/1000000 -> 2665.3622 | G9: =3124966134.74/1000000 -> 3124.9661
A10: INT_EXP | B10: 利息支出 | C10: =0/1000000 -> 0 | D10: =0/1000000 -> 0 | E10: =0/1000000 -> 0 | F10: =0/1000000 -> 0 | G10: =0/1000000 -> 0
A11: EXP_FEE_COMM | B11: 手续费及佣金支出 | C11: =0/1000000 -> 0 | D11: =0/1000000 -> 0 | E11: =0/1000000 -> 0 | F11: =0/1000000 -> 0 | G11: =0/1000000 -> 0
A12: RFD_PREM | B12: 退保金 | C12: =0/1000000 -> 0 | D12: =0/1000000 -> 0 | E12: =0/1000000 -> 0 | F12: =0/1000000 -> 0 | G12: =0/1000000 -> 0
A13: COMP_PAY | B13: 赔付支出净额 | C13: =0/1000000 -> 0 | D13: =0/1000000 -> 0 | E13: =0/1000000 -> 0 | F13: =0/1000000 -> 0 | G13: =0/1000000 -> 0
A14: CHG_RSV | B14: 提取保险合同准备金净额 | C14: =0/1000000 -> 0 | D14: =0/1000000 -> 0 | E14: =0/1000000 -> 0 | F14: =0/1000000 -> 0 | G14: =0/1000000 -> 0
A15: PH_DVD_EXP | B15: 保单红利支出 | C15: =0/1000000 -> 0 | D15: =0/1000000 -> 0 | E15: =0/1000000 -> 0 | F15: =0/1000000 -> 0 | G15: =0/1000000 -> 0
A16: RIN_PREM_EXP | B16: 分保费用 | C16: =0/1000000 -> 0 | D16: =0/1000000 -> 0 | E16: =0/1000000 -> 0 | F16: =0/1000000 -> 0 | G16: =0/1000000 -> 0
A17: BIZ_TAX_SUR | B17: 税金及附加 | C17: =11305142.21/1000000 -> 11.305142 | D17: =6657646.68/1000000 -> 6.6576467 | E17: =10072483.48/1000000 -> 10.072483 | F17: =8608233.39/1000000 -> 8.6082334 | G17: =13127125.82/1000000 -> 13.127126
A18: SELL_EXP | B18: 销售费用 | C18: =258623991.98/1000000 -> 258.62399 | D18: =291342196.16/1000000 -> 291.3422 | E18: =313072501.21/1000000 -> 313.0725 | F18: =294598306.69/1000000 -> 294.59831 | G18: =319833698.94/1000000 -> 319.8337
A19: ADM_EXP | B19: 管理费用 | C19: =159620351.63/1000000 -> 159.62035 | D19: =166115463.65/1000000 -> 166.11546 | E19: =178849144.37/1000000 -> 178.84914 | F19: =215168160.04/1000000 -> 215.16816 | G19: =268144047.85/1000000 -> 268.14405
A20: R_D_EXP | B20: 研发费用 | C20: =521200919.41/1000000 -> 521.20092 | D20: =641629834.65/1000000 -> 641.62983 | E20: =708345090/1000000 -> 708.34509 | F20: =681338961.4/1000000 -> 681.33896 | G20: =712026562.17/1000000 -> 712.02656
A21: FIN_EXP | B21: 财务费用 | C21: =-19706705.54/1000000 -> -19.706706 | D21: =-67663031.77/1000000 -> -67.663032 | E21: =-92701810.9/1000000 -> -92.701811 | F21: =-74751474.5/1000000 -> -74.751475 | G21: =-103890297.65/1000000 -> -103.8903
A22: FIN_EXP_INT_INC | B22: 其中：利息收入 | C22: =19310772.45/1000000 -> 19.310772 | D22: =40733965.84/1000000 -> 40.733966 | E22: =67904103.32/1000000 -> 67.904103 | F22: =98688849.07/1000000 -> 98.688849 | G22: =90984362.54/1000000 -> 90.984363
A23: FIN_EXP_INT_FEE | B23: 利息费用 | C23: =800531.45/1000000 -> 0.80053145 | D23: =117139.83/1000000 -> 0.11713983 | E23: =141686.73/1000000 -> 0.14168673 | F23: =1083250.58/1000000 -> 1.0832506 | G23: =865703.21/1000000 -> 0.86570321
B24: 三、其他经营收益 | C24: 0 | D24: 0 | E24: 0 | F24: 0 | G24: 0
A25: OTH_INC | B25: 其他收益 | C25: =21504855.59/1000000 -> 21.504856 | D25: =27308135.8/1000000 -> 27.308136 | E25: =30369928.17/1000000 -> 30.369928 | F25: =32395579.86/1000000 -> 32.39558 | G25: =21326596.17/1000000 -> 21.326596
A26: AST_IMPR_LOSS | B26: 资产减值损失 | C26: =-118383667.51/1000000 -> -118.38367 | D26: =-278084891.46/1000000 -> -278.08489 | E26: =-72893028.79/1000000 -> -72.893029 | F26: =-74138722.78/1000000 -> -74.138723 | G26: =-73473108.87/1000000 -> -73.473109
A27: CRED_IMPR_LOSS | B27: 信用减值损失 | C27: =4746.9/1000000 -> 0.0047469 | D27: =-128215.68/1000000 -> -0.12821568 | E27: =0/1000000 -> 0 | F27: =0/1000000 -> 0 | G27: =0/1000000 -> 0
A28: FV_CHG_INC | B28: 公允价值变动净收益 | C28: =6362.95/1000000 -> 0.00636295 | D28: =755968.21/1000000 -> 0.75596821 | E28: =2530060.34/1000000 -> 2.5300603 | F28: =2722478/1000000 -> 2.722478 | G28: =2522389.88/1000000 -> 2.5223899
A29: INV_INC | B29: 投资净收益 | C29: =11269117.96/1000000 -> 11.269118 | D29: =14865805.07/1000000 -> 14.865805 | E29: =21185220.61/1000000 -> 21.185221 | F29: =25237234.61/1000000 -> 25.237235 | G29: =33204846.25/1000000 -> 33.204846
A30: INV_INC_JV_P | B30: 其中：对联营企业和合营企业的投资收益 | C30: =-25.12/1000000 -> -2.512e-05 | D30: =-53480.47/1000000 -> -0.05348047 | E30: =-908757.11/1000000 -> -0.90875711 | F30: =-355196.02/1000000 -> -0.35519602 | G30: =257554.93/1000000 -> 0.25755493
A31: NET_EXP_HED_BEN | B31: 净敞口套期收益 | C31: =0/1000000 -> 0 | D31: =0/1000000 -> 0 | E31: =0/1000000 -> 0 | F31: =0/1000000 -> 0 | G31: =0/1000000 -> 0
A32: AST_DSPL_INC | B32: 资产处置收益 | C32: =2058.6/1000000 -> 0.0020586 | D32: =364632.44/1000000 -> 0.36463244 | E32: =29120.05/1000000 -> 0.02912005 | F32: =8522.57/1000000 -> 0.00852257 | G32: =24130114.41/1000000 -> 24.130114
A33: FX_INC | B33: 汇兑净收益 | C33: =0/1000000 -> 0 | D33: =0/1000000 -> 0 | E33: =0/1000000 -> 0 | F33: =0/1000000 -> 0 | G33: =0/1000000 -> 0
B34: 加：营业利润差额(特殊报表科目) | C34: =C35-(C4+C5+C6+C7-C9-C10-C11-C12-C13-C14-C15-C16-C17-C18-C19-C20-C21+C26+C27+C25+C28+C29+C31+C32+C33) -> 0 | D34: =D35-(D4+D5+D6+D7-D9-D10-D11-D12-D13-D14-D15-D16-D17-D18-D19-D20-D21+D26+D27+D25+D28+D29+D31+D32+D33) -> 0 | E34: =E35-(E4+E5+E6+E7-E9-E10-E11-E12-E13-E14-E15-E16-E17-E18-E19-E20-E21+E26+E27+E25+E28+E29+E31+E32+E33) -> 0 | F34: =F35-(F4+F5+F6+F7-F9-F10-F11-F12-F13-F14-F15-F16-F17-F18-F19-F20-F21+F26+F27+F25+F28+F29+F31+F32+F33) -> 0 | G34: =G35-(G4+G5+G6+G7-G9-G10-G11-G12-G13-G14-G15-G16-G17-G18-G19-G20-G21+G26+G27+G25+G28+G29+G31+G32+G33) -> 0
A35: OPER_PROF | B35: 四、营业利润 | C35: =932471354.42/1000000 -> 932.47135 | D35: =813729190.01/1000000 -> 813.72919 | E35: =544509060.33/1000000 -> 544.50906 | F35: =408526617.78/1000000 -> 408.52662 | G35: =414511163.93/1000000 -> 414.51116
A36: NOPER_INC | B36: 加：营业外收入 | C36: =1609327.87/1000000 -> 1.6093279 | D36: =1458929.36/1000000 -> 1.4589294 | E36: =1140517.89/1000000 -> 1.1405179 | F36: =3050670.71/1000000 -> 3.0506707 | G36: =1119670.31/1000000 -> 1.1196703
A37: NOPER_EXP | B37: 减：营业外支出 | C37: =65686.68/1000000 -> 0.06568668 | D37: =192701.11/1000000 -> 0.19270111 | E37: =444660.41/1000000 -> 0.44466041 | F37: =1612472.3/1000000 -> 1.6124723 | G37: =1951303.39/1000000 -> 1.9513034
A38: LOSS_DSPL_NCUR_AST | B38: 其中：非流动资产处置净损失 | C38: =0/1000000 -> 0 | D38: =0/1000000 -> 0 | E38: =0/1000000 -> 0 | F38: =0/1000000 -> 0 | G38: =0/1000000 -> 0
B39: 加：利润总额差额(特殊报表科目) | C39: =C40-(C35+C36-C37) -> 0 | D39: =D40-(D35+D36-D37) -> 0 | E39: =E40-(E35+E36-E37) -> 0 | F39: =F40-(F35+F36-F37) -> 0 | G39: =G40-(G35+G36-G37) -> 0
A40: TTL_PROF | B40: 五、利润总额 | C40: =934014995.61/1000000 -> 934.015 | D40: =814995418.26/1000000 -> 814.99542 | E40: =545204917.81/1000000 -> 545.20492 | F40: =409964816.19/1000000 -> 409.96482 | G40: =413679530.85/1000000 -> 413.67953
...

Sheet 经营模型
K1: 单位：百万元
C2: 历史数据 | H2: 预测数据
C3: =历史数据!C1 -> 2021 | D3: =历史数据!D1 -> 2022 | E3: =历史数据!E1 -> 2023 | F3: =历史数据!F1 -> 2024 | G3: =历史数据!G1 -> 2025 | H3: =历史数据及预测表!I4 -> 2026 | I3: =历史数据及预测表!J4 -> 2027 | J3: =历史数据及预测表!K4 -> 2028 | K3: =历史数据及预测表!L4 -> 2029
B4: 营业收入合计 | C4: =历史数据及预测表!D107 -> 5274.0591 | D4: =历史数据及预测表!E107 -> 5411.8675 | E4: =历史数据及预测表!F107 -> 4530.9257 | F4: =历史数据及预测表!G107 -> 4212.6259 | G4: =历史数据及预测表!H107 -> 4741.0076 | H4: =经营模型拆分!H4 -> 8307.8438 | I4: =经营模型拆分!I4 -> 10593.134 | J4: =经营模型拆分!J4 -> 12526.556 | K4: =经营模型拆分!K4 -> 14734.016
B5: 营业成本合计 | C5: =历史数据及预测表!D110 -> 3324.9476 | D5: =历史数据及预测表!E110 -> 3325.1376 | E5: =历史数据及预测表!F110 -> 2850.0005 | F5: =历史数据及预测表!G110 -> 2665.3622 | G5: =历史数据及预测表!H110 -> 3124.9661 | H5: =经营模型拆分!H5 -> 4182.239 | I5: =经营模型拆分!I5 -> 5655.3783 | J5: =经营模型拆分!J5 -> 7397.5763 | K5: =经营模型拆分!K5 -> 8874.2543
B7: 其他业务收入（金融类） | C7: =历史数据及预测表!D108 -> 0 | D7: =历史数据及预测表!E108 -> 0 | E7: =历史数据及预测表!F108 -> 0 | F7: =历史数据及预测表!G108 -> 0 | G7: =历史数据及预测表!H108 -> 0 | H7: 1 | I7: 1 | J7: 1 | K7: 1
B8: 其他业务成本（金融类） | C8: =历史数据及预测表!D116 -> 0 | D8: =历史数据及预测表!E116 -> 0 | E8: =历史数据及预测表!F116 -> 0 | F8: =历史数据及预测表!G116 -> 0 | G8: =历史数据及预测表!H116 -> 0 | H8: 0 | I8: 0 | J8: 0 | K8: 0

Sheet 经营模型拆分
J1: 单位：百万元
B2: 历史数据 | G2: 预测数据
B3: 2020 | C3: 2021 | D3: 2022 | E3: 2023 | F3: 2024 | G3: 2025 | H3: =[2]历史数据及预测表!J4 -> 2026 | I3: =[2]历史数据及预测表!K4 -> 2027 | J3: =[2]历史数据及预测表!L4 -> 2028 | K3: =[2]历史数据及预测表!M4 -> 2029
A4: 营业收入合计 | B4: 2169.8011 | C4: 5274.0591 | D4: 5411.8675 | E4: 4530.9257 | F4: =经营模型!F4 -> 4212.6259 | G4: =经营模型!G4 -> 4741.0076 | H4: =H12 -> 8307.8438 | I4: =I12 -> 10593.134 | J4: =J12 -> 12526.556 | K4: =K12 -> 14734.016
A5: 营业成本合计 | B5: 1581.2153 | C5: 3324.9476 | D5: 3325.1376 | E5: 2850.0005 | F5: =经营模型!F5 -> 2665.3622 | G5: =经营模型!G5 -> 3124.9661 | H5: =H19 -> 4182.239 | I5: =I19 -> 5655.3783 | J5: =J19 -> 7397.5763 | K5: =K19 -> 8874.2543
A7: 其他业务收入（金融类） | H7: 1 | I7: 1 | J7: 1
A8: 其他业务成本（金融类） | H8: 0 | I8: 0 | J8: 0
A10: 红色为假设数据，蓝色为计算数据 | B10: 假设汇率按照6.5计算 | G10: =G18 -> 0.34086456 | H10: =H18 -> 0.49659152 | I10: =I18 -> 0.46612794 | J10: =J18 -> 0.40944851
B11: 2020 | C11: 2021 | D11: 2022 | E11: 2023 | F11: 2024 | G11: 2025 | H11: 2026 | I11: 2027 | J11: 2028 | K11: 2029 | M11: 说明 | N11: CAGR
A12: 营业收入 | B12: 2169.8011 | C12: 5274.0591 | D12: 5411.8675 | E12: 4530.9257 | F12: 4212.6259 | G12: =G4 -> 4741.0076 | H12: =H20+H103+H117+H119+H121 -> 8307.8438 | I12: =I20+I103+I117+I119+I121 -> 10593.134 | J12: =J20+J103+J117+J119+J121 -> 12526.556 | K12: =K20+K103+K117+K119+K121 -> 14734.016 | N12: =(I12/E12)^(1/4)-1 -> 0.23654345
A13: YoY | B13: =B12/#REF!-1 -> #REF! | C13: =C12/B12-1 -> 1.4306648 | D13: =D12/C12-1 -> 0.026129473 | E13: =E12/D12-1 -> -0.16277964 | F13: =F12/E12-1 -> -0.070250496 | G13: =G12/F12-1 -> 0.12542811 | H13: =H12/G12-1 -> 0.75233716 | I13: =I12/H12-1 -> 0.27507621 | J13: =J12/I12-1 -> 0.18251654 | K13: =K12/J12-1 -> 0.17622244
A14: 销量（百万颗） | B14: 21.236903 | C14: 414.08087 | D14: 994.31534
A15: YoY | B15: =B14/#REF!-1 -> #REF! | C15: =C14/B14-1 -> 18.498176 | D15: =D14/C14-1 -> 1.4012588
A16: 均价（元） | B16: =#REF!/B14 -> #REF! | C16: =#REF!/C14 -> #REF! | D16: =#REF!/D14 -> #REF!
A17: YoY | B17: =B16/#REF!-1 -> #REF! | C17: =C16/B16-1 -> #REF! | D17: =D16/C16-1 -> #REF!
A18: 毛利率 | B18: 0.27126256 | C18: 0.36956574 | D18: 0.38558406 | E18: 0.37098935 | F18: 0.36729198 | G18: =1-G5/G4 -> 0.34086456 | H18: =1-H5/H4 -> 0.49659152 | I18: =1-I5/I4 -> 0.46612794 | J18: =1-J5/J4 -> 0.40944851 | K18: =1-K5/K4 -> 0.39770297
A19: 营业成本 | B19: =B12*(1-B18) -> 1581.2153 | C19: =C12*(1-C18) -> 3324.9476 | D19: =D12*(1-D18) -> 3325.1376 | E19: =E12*(1-E18) -> 2850.0005 | F19: =F12*(1-F18) -> 2665.3622 | G19: =G12*(1-G18) -> 3124.9661 | H19: =H124 -> 4182.239 | I19: =I124 -> 5655.3783 | J19: =J124 -> 7397.5763 | K19: =K124 -> 8874.2543 | N19: =(I19/E19)^(1/4)-1 -> 0.18687281
A20: 1.北京矽成（仅芯片） | B20: =B30+B92 -> 1712.9356 | C20: =C30+C92 -> 4007.0977 | D20: =D30+D92 -> 4533.225 | E20: =E30+E92 -> 3320.48 | F20: =F30+F92 -> 3061.01 | G20: =G30+G92 -> 3416.89 | H20: =H30+H92 -> 6093.8969 | I20: =I30+I92 -> 7941.3757 | ... K20: =K30+K92 -> 10934.116
A21: YoY | C21: =C20/B20-1 -> 1.3393161 | D21: =D20/C20-1 -> 0.13129884 | E21: =E20/D20-1 -> -0.26752367 | F21: =F20/E20-1 -> -0.078142317 | G21: =G20/F20-1 -> 0.11626228 | H21: =H20/G20-1 -> 0.78346302 | I21: =I20/H20-1 -> 0.3031687 | J21: =J20/I20-1 -> 0.17760758 | K21: =K20/J20-1 -> 0.16919607
A22: 在公司总收入占比 | C22: =C20/D12 -> 0.7404279 | D22: =D20/D12 -> 0.83764523 | E22: =E20/E12 -> 0.73284804 | F22: =F20/F12 -> 0.72662754 | G22: =G20/G12 -> 0.72070967 | H22: =H20/H12 -> 0.73351126 | I22: =I20/I12 -> 0.74967198 | J22: =J20/J12 -> 0.74655988 | K22: =K20/K12 -> 0.74210018
A23: 收购备考口径 | B23: =B32+B94 -> 2805.2748
A24: YoY | B24: =B23/#REF!-1 -> #REF!
A25: 销量（百万颗）
A26: YoY
A27: 均价（元）
A28: YoY
A29: 毛利率 | C29: =(C30*C45+C92*C101)/C20 -> 0.32895246 | D29: =(D30*D45+D92*D101)/D20 -> 0.38554391 | E29: =(E30*E45+E92*E101)/E20 -> 0.38307715 | F29: =(F30*F45+F92*F101)/F20 -> 0.3687051 | G29: =1-G125/G20 -> 0.34783678 | H29: =1-H125/H20 -> 0.47979316 | I29: =1-I125/I20 -> 0.47294298 | J29: =1-J125/J20 -> 0.41101903 | K29: =1-K125/K20 -> 0.39571637
A30: 1.1存储芯片 | B30: 1525.4586 | C30: 3594.44 | D30: 4054.5031 | E30: 2911.56 | F30: 2589.49 | G30: 2911.25 | H30: =H46+H60+H74 -> 5487.1289 | I30: =I46+I60+I74 -> 7213.2541 | J30: =J46+J60+J74 -> 8478.0783 | K30: =K46+K60+K74 -> 9885.6211 | M30: =(H30/D30)^(1/4)-1 -> 0.078578806
A31: YoY | C31: =C30/B30-1 -> 1.3563013 | D31: =D30/C30-1 -> 0.12799298 | E31: =E30/D30-1 -> -0.28189474 | F31: =F30/E30-1 -> -0.11061768 | G31: =G30/F30-1 -> 0.12425613 | H31: =H30/G30-1 -> 0.8848017 | I31: =I30/H30-1 -> 0.31457711 | J31: =J30/I30-1 -> 0.17534724 | K31: =K30/J30-1 -> 0.16602144
A32: 收购备考口径 | B32: 2526.2536
A33: YoY | B33: =B32/#REF!-1 -> #REF!
A34: 在矽成占比 | B34: =B32/B23 -> 0.90053695 | C34: =C30/C20 -> 0.89701831 | D34: =D30/D20 -> 0.89439706 | E34: =E30/E20 -> 0.87684913 | F34: =F30/F20 -> 0.84595934 | G34: =G30/G20 -> 0.85201748 | H34: =H30/H20 -> 0.90043022 | I34: =I30/I20 -> 0.90831291 | J34: =J30/J20 -> 0.90656947 | K34: =K30/K20 -> 0.90410792
A35: 全球存储芯片市场规模（亿美元） | B35: 1174.82 | C35: 1538.38 | D35: 1826.61 | E35: =D35*(1+E36) -> 1278.627 | F35: =E35*(1+F36) -> 1342.5584 | G35: =F35*(1+G36) -> 1409.6863 | H35: =G35*(1+H36) -> 1480.1706 | I35: =H35*(1+I36) -> 1554.1791 | J35: =I35*(1+J36) -> 1631.8881 | K35: =J35*(1+K36) -> 1713.4825 | L35: 资料来源：WSTS
A36: YoY | B36: =B35/#REF!-1 -> #REF! | C36: =C35/B35-1 -> 0.30946017 | D36: =D35/C35-1 -> 0.18735943 | E36: -0.3 | F36: 0.05 | G36: 0.05 | H36: 0.05 | I36: 0.05 | J36: 0.05 | K36: 0.05
A37: 公司份额 | B37: =B32/100/6.5/B35 -> 0.0033082038 | C37: =C30/100/6.5/C35 -> 0.0035946305 | D37: =D30/100/6.5/D35 -> 0.0034149036 | E37: =E30/100/6.5/E35 -> 0.0035032289 | F37: =F30/100/6.5/F35 -> 0.0029673427 | G37: =G30/100/6.5/G35 -> 0.0031771936 | H37: =H30/100/6.5/H35 -> 0.0057032189 | I37: =I30/100/6.5/I35 -> 0.0071403058 | J37: =J30/100/6.5/J35 -> 0.0079927035 | K37: =K30/100/6.5/K35 -> 0.0088758701 | L37: 根据Trendforce，2020Q1-Q3，三星、SK海力士、美光份额分别为38%/21%/17%
A38: 全球车载存储市场规模（亿美元） | B38: =#REF!*(1+B39) -> #REF! | C38: =B38*(1+C39) -> #REF! | D38: =C38*(1+D39) -> #REF! | E38: =D38*(1+E39) -> #REF! | F38: =E38*(1+F39) -> #REF! | G38: 83 | H38: =G38*(1+H39) -> #REF! | I38: =H38*(1+I39) -> #REF! | J38: =I38*(1+J39) -> #REF! | K38: =J38*(1+K39) -> #REF! | L38: 资料来源：IHS
A39: YoY | B39: =POWER($G38/#REF!,1/6)-1 -> #REF! | C39: =POWER($G38/#REF!,1/6)-1 -> #REF! | D39: =POWER($G38/#REF!,1/6)-1 -> #REF! | E39: =POWER($G38/#REF!,1/6)-1 -> #REF! | F39: =POWER($G38/#REF!,1/6)-1 -> #REF! | G39: =POWER($G38/#REF!,1/6)-1 -> #REF! | H39: =POWER($G38/#REF!,1/6)-1 -> #REF! | I39: =POWER($G38/#REF!,1/6)-1 -> #REF! | ... K39: =POWER($G38/#REF!,1/6)-1 -> #REF!
A40: 公司份额 | B40: =B32*35%/100/6.5/B38 -> #REF! | C40: =C30*40%/100/6.5/C38 -> #REF! | D40: =D30*40%/100/6.5/D38 -> #REF! | E40: =E30*40%/100/6.5/E38 -> #REF! | F40: =F30*40%/100/6.5/F38 -> #REF! | G40: =G30*40%/100/6.5/G38 -> 0.021584801 | H40: =H30*40%/100/6.5/H38 -> #REF! | I40: =I30*40%/100/6.5/I38 -> #REF! | J40: =J30*40%/100/6.5/J38 -> #REF! | K40: =K30*40%/100/6.5/K38 -> #REF! | L40: 无
A41: 芯片销量（百万颗）
A42: YoY
...

Sheet 假设表
D1: 历史数据 | I1: 预测数据
C2: 预测值生成方式 | D2: =历史数据!C1 -> 2021 | E2: =历史数据!D1 -> 2022 | F2: =历史数据!E1 -> 2023 | G2: =历史数据!F1 -> 2024 | H2: =历史数据!G1 -> 2025 | I2: =H2+1 -> 2026 | J2: =I2+1 -> 2027 | K2: =J2+1 -> 2028 | L2: =K2+1 -> 2029 | M2: =L2+1 -> 2030 | N2: =M2+1 -> 2031 | O2: =N2+1 -> 2032 | P2: =O2+1 -> 2033 | ... T2: =S2+1 -> 2037
A3: 利润表假设
B4: 营业收入增长率 | C4: 前三年平均数据 | E4: =历史数据及预测表!E107/历史数据及预测表!D107-1 -> 0.026129473 | F4: =历史数据及预测表!F107/历史数据及预测表!E107-1 -> -0.16277964 | G4: =历史数据及预测表!G107/历史数据及预测表!F107-1 -> -0.070250496 | H4: =历史数据及预测表!H107/历史数据及预测表!G107-1 -> 0.12542811 | I4: =经营模型!H4/经营模型!G4-1 -> 0.75233716 | J4: =经营模型!I4/经营模型!H4-1 -> 0.27507621 | K4: =经营模型!J4/经营模型!I4-1 -> 0.18251654 | L4: =经营模型!K4/经营模型!J4-1 -> 0.17622244 | M4: =IF(ISERR(AVERAGE($J$4:$L$4)),0,AVERAGE($J$4:$L$4)) -> 0.21127173 | N4: =IF(ISERR(AVERAGE($K$4:$M$4)),0,AVERAGE($K$4:$M$4)) -> 0.19000357 | O4: =IF(ISERR(AVERAGE($L$4:$N$4)),0,AVERAGE($L$4:$N$4)) -> 0.19249925 | P4: =IF(ISERR(AVERAGE($M$4:$O$4)),0,AVERAGE($M$4:$O$4)) -> 0.19792485 | Q4: =IF(ISERR(AVERAGE($N$4:$P$4)),0,AVERAGE($N$4:$P$4)) -> 0.19347589 | R4: =IF(ISERR(AVERAGE($O$4:$Q$4)),0,AVERAGE($O$4:$Q$4)) -> 0.19463333 | S4: =IF(ISERR(AVERAGE($O$4:$Q$4)),0,AVERAGE($O$4:$Q$4)) -> 0.19463333 | T4: =IF(ISERR(AVERAGE($O$4:$Q$4)),0,AVERAGE($O$4:$Q$4)) -> 0.19463333
B5: 其他业务收入（金融类）增长率 | C5: 前三年平均数据 | E5: =IF(历史数据及预测表!E108=历史数据及预测表!D108,0%,历史数据及预测表!E108/历史数据及预测表!D108-1) -> 0 | F5: =IF(历史数据及预测表!F108=历史数据及预测表!E108,0%,历史数据及预测表!F108/历史数据及预测表!E108-1) -> 0 | G5: =IF(历史数据及预测表!G108=历史数据及预测表!F108,0%,历史数据及预测表!G108/历史数据及预测表!F108-1) -> 0 | H5: =IF(历史数据及预测表!H108=历史数据及预测表!G108,0%,历史数据及预测表!H108/历史数据及预测表!G108-1) -> 0 | I5: =IF(经营模型!G7=0,0%,经营模型!H7/经营模型!G7-1) -> 0 | J5: =IF(经营模型!H7=0,0%,经营模型!I7/经营模型!H7-1) -> 0 | K5: =IF(经营模型!I7=0,0%,经营模型!J7/经营模型!I7-1) -> 0 | L5: =IF(经营模型!J7=0,0%,经营模型!K7/经营模型!J7-1) -> 0 | M5: =IF(ISERR(AVERAGE($J$5:$L$5)),0,AVERAGE($J$5:$L$5)) -> 0 | N5: =IF(ISERR(AVERAGE($K$5:$M$5)),0,AVERAGE($K$5:$M$5)) -> 0 | O5: =IF(ISERR(AVERAGE($L$5:$N$5)),0,AVERAGE($L$5:$N$5)) -> 0 | P5: =IF(ISERR(AVERAGE($M$5:$O$5)),0,AVERAGE($M$5:$O$5)) -> 0 | Q5: =IF(ISERR(AVERAGE($N$5:$P$5)),0,AVERAGE($N$5:$P$5)) -> 0 | R5: =IF(ISERR(AVERAGE($O$5:$Q$5)),0,AVERAGE($O$5:$Q$5)) -> 0 | S5: =IF(ISERR(AVERAGE($O$5:$Q$5)),0,AVERAGE($O$5:$Q$5)) -> 0 | T5: =IF(ISERR(AVERAGE($O$5:$Q$5)),0,AVERAGE($O$5:$Q$5)) -> 0
B6: 营业成本/营业收入 | C6: 前三年平均数据 | D6: =历史数据及预测表!D110/历史数据及预测表!D107 -> 0.63043426 | E6: =历史数据及预测表!E110/历史数据及预测表!E107 -> 0.61441594 | F6: =历史数据及预测表!F110/历史数据及预测表!F107 -> 0.62901065 | G6: =历史数据及预测表!G110/历史数据及预测表!G107 -> 0.63270802 | H6: =历史数据及预测表!H110/历史数据及预测表!H107 -> 0.65913544 | I6: =经营模型!H5/经营模型!H4 -> 0.50340848 | J6: =经营模型!I5/经营模型!I4 -> 0.53387206 | K6: =经营模型!J5/经营模型!J4 -> 0.59055149 | L6: =经营模型!K5/经营模型!K4 -> 0.60229703 | M6: =IF(ISERR(AVERAGE($J$6:$L$6)),0,AVERAGE($J$6:$L$6)) -> 0.57557353 | N6: =IF(ISERR(AVERAGE($K$6:$M$6)),0,AVERAGE($K$6:$M$6)) -> 0.58947401 | O6: =IF(ISERR(AVERAGE($L$6:$N$6)),0,AVERAGE($L$6:$N$6)) -> 0.58911486 | P6: =IF(ISERR(AVERAGE($M$6:$O$6)),0,AVERAGE($M$6:$O$6)) -> 0.5847208 | Q6: =IF(ISERR(AVERAGE($N$6:$P$6)),0,AVERAGE($N$6:$P$6)) -> 0.58776989 | R6: =IF(ISERR(AVERAGE($O$6:$Q$6)),0,AVERAGE($O$6:$Q$6)) -> 0.58720185 | S6: =IF(ISERR(AVERAGE($O$6:$Q$6)),0,AVERAGE($O$6:$Q$6)) -> 0.58720185 | T6: =IF(ISERR(AVERAGE($O$6:$Q$6)),0,AVERAGE($O$6:$Q$6)) -> 0.58720185
B7: 其他业务成本/其他业务收入（金融类） | C7: 前三年平均数据 | D7: =IF(历史数据及预测表!D108=历史数据及预测表!D116,0%,历史数据及预测表!D116/历史数据及预测表!D108) -> 0 | E7: =IF(历史数据及预测表!E108=历史数据及预测表!E116,0%,历史数据及预测表!E116/历史数据及预测表!E108) -> 0 | F7: =IF(历史数据及预测表!F108=历史数据及预测表!F116,0%,历史数据及预测表!F116/历史数据及预测表!F108) -> 0 | G7: =IF(历史数据及预测表!G108=历史数据及预测表!G116,0%,历史数据及预测表!G116/历史数据及预测表!G108) -> 0 | H7: =IF(历史数据及预测表!H108=历史数据及预测表!H116,0%,历史数据及预测表!H116/历史数据及预测表!H108) -> 0 | I7: =IF(经营模型!G8=0,0%,经营模型!H8/经营模型!H7) -> 0 | J7: =IF(经营模型!H8=0,0%,经营模型!I8/经营模型!I7) -> 0 | K7: =IF(经营模型!I8=0,0%,经营模型!J8/经营模型!J7) -> 0 | L7: =IF(经营模型!J8=0,0%,经营模型!K8/经营模型!K7) -> 0 | M7: =IF(ISERR(AVERAGE($J$7:$L$7)),0,AVERAGE($J$7:$L$7)) -> 0 | N7: =IF(ISERR(AVERAGE($K$7:$M$7)),0,AVERAGE($K$7:$M$7)) -> 0 | O7: =IF(ISERR(AVERAGE($L$7:$N$7)),0,AVERAGE($L$7:$N$7)) -> 0 | P7: =IF(ISERR(AVERAGE($M$7:$O$7)),0,AVERAGE($M$7:$O$7)) -> 0 | Q7: =IF(ISERR(AVERAGE($N$7:$P$7)),0,AVERAGE($N$7:$P$7)) -> 0 | R7: =IF(ISERR(AVERAGE($O$7:$Q$7)),0,AVERAGE($O$7:$Q$7)) -> 0 | S7: =IF(ISERR(AVERAGE($O$7:$Q$7)),0,AVERAGE($O$7:$Q$7)) -> 0 | T7: =IF(ISERR(AVERAGE($O$7:$Q$7)),0,AVERAGE($O$7:$Q$7)) -> 0
B8: 营业税金及附加/营业收入 | C8: 前三年平均数据 | D8: =历史数据及预测表!D111/历史数据及预测表!D107 -> 0.0021435373 | E8: =历史数据及预测表!E111/历史数据及预测表!E107 -> 0.001230194 | F8: =历史数据及预测表!F111/历史数据及预测表!F107 -> 0.002223052 | G8: =历史数据及预测表!G111/历史数据及预测表!G107 -> 0.0020434365 | H8: =历史数据及预测表!H111/历史数据及预测表!H107 -> 0.0027688472 | I8: =IF(ISERR(AVERAGE($F$8:$H$8)),0,AVERAGE($F$8:$H$8)) -> 0.0023451119 | J8: =IF(ISERR(AVERAGE($G$8:$I$8)),0,AVERAGE($G$8:$I$8)) -> 0.0023857985 | K8: =IF(ISERR(AVERAGE($H$8:$J$8)),0,AVERAGE($H$8:$J$8)) -> 0.0024999192 | L8: =IF(ISERR(AVERAGE($I$8:$K$8)),0,AVERAGE($I$8:$K$8)) -> 0.0024102766 | M8: =IF(ISERR(AVERAGE($J$8:$L$8)),0,AVERAGE($J$8:$L$8)) -> 0.0024319981 | N8: =IF(ISERR(AVERAGE($K$8:$M$8)),0,AVERAGE($K$8:$M$8)) -> 0.002447398 | O8: =IF(ISERR(AVERAGE($L$8:$N$8)),0,AVERAGE($L$8:$N$8)) -> 0.0024298909 | P8: =IF(ISERR(AVERAGE($M$8:$O$8)),0,AVERAGE($M$8:$O$8)) -> 0.002436429 | Q8: =IF(ISERR(AVERAGE($N$8:$P$8)),0,AVERAGE($N$8:$P$8)) -> 0.0024379059 | R8: =IF(ISERR(AVERAGE($O$8:$Q$8)),0,AVERAGE($O$8:$Q$8)) -> 0.0024347419 | S8: =IF(ISERR(AVERAGE($O$8:$Q$8)),0,AVERAGE($O$8:$Q$8)) -> 0.0024347419 | T8: =IF(ISERR(AVERAGE($O$8:$Q$8)),0,AVERAGE($O$8:$Q$8)) -> 0.0024347419
B9: 销售费用/营业收入 | C9: 保持上一年数据 | D9: =历史数据及预测表!D112/历史数据及预测表!D107 -> 0.049036991 | E9: =历史数据及预测表!E112/历史数据及预测表!E107 -> 0.053833948 | F9: =历史数据及预测表!F112/历史数据及预测表!F107 -> 0.069096808 | G9: =历史数据及预测表!G112/历史数据及预测表!G107 -> 0.069932226 | H9: =历史数据及预测表!H112/历史数据及预测表!H107 -> 0.067461123 | I9: =历史数据及预测表!H112*(1+20%)/历史数据及预测表!I$106 -> 0.046197359 | J9: =历史数据及预测表!I112*(1+18%)/历史数据及预测表!J$106 -> 0.042752647 | K9: =历史数据及预测表!J112*(1+16%)/历史数据及预测表!K$106 -> 0.041938585 | L9: =$K$9 -> 0.041938585 | M9: =$L$9 -> 0.041938585 | N9: =$M$9 -> 0.041938585 | O9: =$N$9 -> 0.041938585 | P9: =$O$9 -> 0.041938585 | Q9: =$P$9 -> 0.041938585 | R9: =$Q$9 -> 0.041938585 | S9: =$R$9 -> 0.041938585 | T9: =$S$9 -> 0.041938585
B10: 管理费用/营业收入 | C10: 保持上一年数据 | D10: =历史数据及预测表!D113/历史数据及预测表!D107 -> 0.030265181 | E10: =历史数据及预测表!E113/历史数据及预测表!E107 -> 0.030694666 | F10: =历史数据及预测表!F113/历史数据及预测表!F107 -> 0.039472981 | G10: =历史数据及预测表!G113/历史数据及预测表!G107 -> 0.051076969 | H10: =历史数据及预测表!H113/历史数据及预测表!H107 -> 0.056558451 | I10: =历史数据及预测表!H113*(1+20%)/历史数据及预测表!I$106 -> 0.038731212 | J10: =历史数据及预测表!I113*(1+18%)/历史数据及预测表!J$106 -> 0.035843214 | K10: =历史数据及预测表!J113*(1+16%)/历史数据及预测表!K$106 -> 0.035160716 | L10: =$K$10 -> 0.035160716 | M10: =$L$10 -> 0.035160716 | N10: =$M$10 -> 0.035160716 | O10: =$N$10 -> 0.035160716 | P10: =$O$10 -> 0.035160716 | Q10: =$P$10 -> 0.035160716 | R10: =$Q$10 -> 0.035160716 | S10: =$R$10 -> 0.035160716 | T10: =$S$10 -> 0.035160716
B11: 研发费用/营业收入 | C11: 保持上一年数据 | D11: =历史数据及预测表!D114/历史数据及预测表!D107 -> 0.098823488 | E11: =历史数据及预测表!E114/历史数据及预测表!E107 -> 0.11855978 | F11: =历史数据及预测表!F114/历史数据及预测表!F107 -> 0.15633562 | G11: =历史数据及预测表!G114/历史数据及预测表!G107 -> 0.16173735 | H11: =历史数据及预测表!H114/历史数据及预测表!H107 -> 0.15018465 | I11: =历史数据及预测表!H114*(1+20%)/历史数据及预测表!I$106 -> 0.10284641 | J11: =历史数据及预测表!I114*(1+20%)/历史数据及预测表!J$106 -> 0.096790832 | K11: =历史数据及预测表!J114*(1+20%)/历史数据及预测表!K$106 -> 0.098221881 | L11: =$K$11 -> 0.098221881 | M11: =$L$11 -> 0.098221881 | N11: =$M$11 -> 0.098221881 | O11: =$N$11 -> 0.098221881 | P11: =$O$11 -> 0.098221881 | Q11: =$P$11 -> 0.098221881 | R11: =$Q$11 -> 0.098221881 | S11: =$R$11 -> 0.098221881 | T11: =$S$11 -> 0.098221881
B12: 公允价值变动净收益 | C12: 前三年平均数据 | D12: =历史数据及预测表!D117 -> 0.00636295 | E12: =历史数据及预测表!E117 -> 0.75596821 | F12: =历史数据及预测表!F117 -> 2.5300603 | G12: =历史数据及预测表!G117 -> 2.722478 | H12: =历史数据及预测表!H117 -> 2.5223899 | I12: =IF(ISERR(AVERAGE($F$12:$H$12)),0,AVERAGE($F$12:$H$12)) -> 2.5916427 | J12: =IF(ISERR(AVERAGE($G$12:$I$12)),0,AVERAGE($G$12:$I$12)) -> 2.6121702 | K12: =IF(ISERR(AVERAGE($H$12:$J$12)),0,AVERAGE($H$12:$J$12)) -> 2.5754009 | L12: =IF(ISERR(AVERAGE($I$12:$K$12)),0,AVERAGE($I$12:$K$12)) -> 2.5930713 | M12: =IF(ISERR(AVERAGE($J$12:$L$12)),0,AVERAGE($J$12:$L$12)) -> 2.5935475 | N12: =IF(ISERR(AVERAGE($K$12:$M$12)),0,AVERAGE($K$12:$M$12)) -> 2.5873399 | O12: =IF(ISERR(AVERAGE($L$12:$N$12)),0,AVERAGE($L$12:$N$12)) -> 2.5913196 | P12: =IF(ISERR(AVERAGE($M$12:$O$12)),0,AVERAGE($M$12:$O$12)) -> 2.5907357 | Q12: =IF(ISERR(AVERAGE($N$12:$P$12)),0,AVERAGE($N$12:$P$12)) -> 2.5897984 | R12: =IF(ISERR(AVERAGE($O$12:$Q$12)),0,AVERAGE($O$12:$Q$12)) -> 2.5906179 | S12: =IF(ISERR(AVERAGE($O$12:$Q$12)),0,AVERAGE($O$12:$Q$12)) -> 2.5906179 | T12: =IF(ISERR(AVERAGE($O$12:$Q$12)),0,AVERAGE($O$12:$Q$12)) -> 2.5906179
B13: 其他收益 | C13: 前三年平均数据 | D13: =历史数据及预测表!D120 -> 21.504856 | E13: =历史数据及预测表!E120 -> 27.308136 | F13: =历史数据及预测表!F120 -> 30.369928 | G13: =历史数据及预测表!G120 -> 32.39558 | H13: =历史数据及预测表!H120 -> 21.326596 | I13: =IF(ISERR(AVERAGE($F$13:$H$13)),0,AVERAGE($F$13:$H$13)) -> 28.030701 | J13: =IF(ISERR(AVERAGE($G$13:$I$13)),0,AVERAGE($G$13:$I$13)) -> 27.250959 | K13: =IF(ISERR(AVERAGE($H$13:$J$13)),0,AVERAGE($H$13:$J$13)) -> 25.536086 | L13: =IF(ISERR(AVERAGE($I$13:$K$13)),0,AVERAGE($I$13:$K$13)) -> 26.939249 | M13: =IF(ISERR(AVERAGE($J$13:$L$13)),0,AVERAGE($J$13:$L$13)) -> 26.575431 | N13: =IF(ISERR(AVERAGE($K$13:$M$13)),0,AVERAGE($K$13:$M$13)) -> 26.350255 | O13: =IF(ISERR(AVERAGE($L$13:$N$13)),0,AVERAGE($L$13:$N$13)) -> 26.621645 | P13: =IF(ISERR(AVERAGE($M$13:$O$13)),0,AVERAGE($M$13:$O$13)) -> 26.515777 | Q13: =IF(ISERR(AVERAGE($N$13:$P$13)),0,AVERAGE($N$13:$P$13)) -> 26.495892 | R13: =IF(ISERR(AVERAGE($O$13:$Q$13)),0,AVERAGE($O$13:$Q$13)) -> 26.544438 | S13: =IF(ISERR(AVERAGE($O$13:$Q$13)),0,AVERAGE($O$13:$Q$13)) -> 26.544438 | T13: =IF(ISERR(AVERAGE($O$13:$Q$13)),0,AVERAGE($O$13:$Q$13)) -> 26.544438
B14: 净敞口套期收益 | C14: 前三年平均数据 | D14: =历史数据及预测表!D121 -> 0 | E14: =历史数据及预测表!E121 -> 0 | F14: =历史数据及预测表!F121 -> 0 | G14: =历史数据及预测表!G121 -> 0 | H14: =历史数据及预测表!H121 -> 0 | I14: =IF(ISERR(AVERAGE($F$14:$H$14)),0,AVERAGE($F$14:$H$14)) -> 0 | J14: =IF(ISERR(AVERAGE($G$14:$I$14)),0,AVERAGE($G$14:$I$14)) -> 0 | K14: =IF(ISERR(AVERAGE($H$14:$J$14)),0,AVERAGE($H$14:$J$14)) -> 0 | L14: =IF(ISERR(AVERAGE($I$14:$K$14)),0,AVERAGE($I$14:$K$14)) -> 0 | M14: =IF(ISERR(AVERAGE($J$14:$L$14)),0,AVERAGE($J$14:$L$14)) -> 0 | N14: =IF(ISERR(AVERAGE($K$14:$M$14)),0,AVERAGE($K$14:$M$14)) -> 0 | O14: =IF(ISERR(AVERAGE($L$14:$N$14)),0,AVERAGE($L$14:$N$14)) -> 0 | P14: =IF(ISERR(AVERAGE($M$14:$O$14)),0,AVERAGE($M$14:$O$14)) -> 0 | Q14: =IF(ISERR(AVERAGE($N$14:$P$14)),0,AVERAGE($N$14:$P$14)) -> 0 | R14: =IF(ISERR(AVERAGE($O$14:$Q$14)),0,AVERAGE($O$14:$Q$14)) -> 0 | S14: =IF(ISERR(AVERAGE($O$14:$Q$14)),0,AVERAGE($O$14:$Q$14)) -> 0 | T14: =IF(ISERR(AVERAGE($O$14:$Q$14)),0,AVERAGE($O$14:$Q$14)) -> 0
B15: 资产处置收益 | C15: 前三年平均数据 | D15: =历史数据及预测表!D122 -> 0.0020586 | E15: =历史数据及预测表!E122 -> 0.36463244 | F15: =历史数据及预测表!F122 -> 0.02912005 | G15: =历史数据及预测表!G122 -> 0.00852257 | H15: =历史数据及预测表!H122 -> 24.130114 | I15: =IF(ISERR(AVERAGE($F$15:$H$15)),0,AVERAGE($F$15:$H$15)) -> 8.055919 | J15: =IF(ISERR(AVERAGE($G$15:$I$15)),0,AVERAGE($G$15:$I$15)) -> 10.731519 | K15: =IF(ISERR(AVERAGE($H$15:$J$15)),0,AVERAGE($H$15:$J$15)) -> 14.305851 | L15: =IF(ISERR(AVERAGE($I$15:$K$15)),0,AVERAGE($I$15:$K$15)) -> 11.031096 | M15: =IF(ISERR(AVERAGE($J$15:$L$15)),0,AVERAGE($J$15:$L$15)) -> 12.022822 | N15: =IF(ISERR(AVERAGE($K$15:$M$15)),0,AVERAGE($K$15:$M$15)) -> 12.453256 | O15: =IF(ISERR(AVERAGE($L$15:$N$15)),0,AVERAGE($L$15:$N$15)) -> 11.835725 | P15: =IF(ISERR(AVERAGE($M$15:$O$15)),0,AVERAGE($M$15:$O$15)) -> 12.103934 | Q15: =IF(ISERR(AVERAGE($N$15:$P$15)),0,AVERAGE($N$15:$P$15)) -> 12.130972 | R15: =IF(ISERR(AVERAGE($O$15:$Q$15)),0,AVERAGE($O$15:$Q$15)) -> 12.023544 | S15: =IF(ISERR(AVERAGE($O$15:$Q$15)),0,AVERAGE($O$15:$Q$15)) -> 12.023544 | T15: =IF(ISERR(AVERAGE($O$15:$Q$15)),0,AVERAGE($O$15:$Q$15)) -> 12.023544
B16: 投资净收益 | C16: 前三年平均数据 | D16: =历史数据及预测表!D123 -> 11.269118 | E16: =历史数据及预测表!E123 -> 14.865805 | F16: =历史数据及预测表!F123 -> 21.185221 | G16: =历史数据及预测表!G123 -> 25.237235 | H16: =历史数据及预测表!H123 -> 33.204846 | I16: =IF(ISERR(AVERAGE($F$16:$H$16)),0,AVERAGE($F$16:$H$16)) -> 26.542434 | J16: =IF(ISERR(AVERAGE($G$16:$I$16)),0,AVERAGE($G$16:$I$16)) -> 28.328172 | K16: =IF(ISERR(AVERAGE($H$16:$J$16)),0,AVERAGE($H$16:$J$16)) -> 29.358484 | L16: =IF(ISERR(AVERAGE($I$16:$K$16)),0,AVERAGE($I$16:$K$16)) -> 28.076363 | M16: =IF(ISERR(AVERAGE($J$16:$L$16)),0,AVERAGE($J$16:$L$16)) -> 28.587673 | N16: =IF(ISERR(AVERAGE($K$16:$M$16)),0,AVERAGE($K$16:$M$16)) -> 28.674173 | O16: =IF(ISERR(AVERAGE($L$16:$N$16)),0,AVERAGE($L$16:$N$16)) -> 28.44607 | P16: =IF(ISERR(AVERAGE($M$16:$O$16)),0,AVERAGE($M$16:$O$16)) -> 28.569305 | Q16: =IF(ISERR(AVERAGE($N$16:$P$16)),0,AVERAGE($N$16:$P$16)) -> 28.563183 | R16: =IF(ISERR(AVERAGE($O$16:$Q$16)),0,AVERAGE($O$16:$Q$16)) -> 28.526186 | S16: =IF(ISERR(AVERAGE($O$16:$Q$16)),0,AVERAGE($O$16:$Q$16)) -> 28.526186 | T16: =IF(ISERR(AVERAGE($O$16:$Q$16)),0,AVERAGE($O$16:$Q$16)) -> 28.526186
B17: 汇兑净收益 | C17: 前三年平均数据 | D17: =历史数据及预测表!D124 -> 0 | E17: =历史数据及预测表!E124 -> 0 | F17: =历史数据及预测表!F124 -> 0 | G17: =历史数据及预测表!G124 -> 0 | H17: =历史数据及预测表!H124 -> 0 | I17: =IF(ISERR(AVERAGE($F$17:$H$17)),0,AVERAGE($F$17:$H$17)) -> 0 | J17: =IF(ISERR(AVERAGE($G$17:$I$17)),0,AVERAGE($G$17:$I$17)) -> 0 | K17: =IF(ISERR(AVERAGE($H$17:$J$17)),0,AVERAGE($H$17:$J$17)) -> 0 | L17: =IF(ISERR(AVERAGE($I$17:$K$17)),0,AVERAGE($I$17:$K$17)) -> 0 | M17: =IF(ISERR(AVERAGE($J$17:$L$17)),0,AVERAGE($J$17:$L$17)) -> 0 | N17: =IF(ISERR(AVERAGE($K$17:$M$17)),0,AVERAGE($K$17:$M$17)) -> 0 | O17: =IF(ISERR(AVERAGE($L$17:$N$17)),0,AVERAGE($L$17:$N$17)) -> 0 | P17: =IF(ISERR(AVERAGE($M$17:$O$17)),0,AVERAGE($M$17:$O$17)) -> 0 | Q17: =IF(ISERR(AVERAGE($N$17:$P$17)),0,AVERAGE($N$17:$P$17)) -> 0 | R17: =IF(ISERR(AVERAGE($O$17:$Q$17)),0,AVERAGE($O$17:$Q$17)) -> 0 | S17: =IF(ISERR(AVERAGE($O$17:$Q$17)),0,AVERAGE($O$17:$Q$17)) -> 0 | T17: =IF(ISERR(AVERAGE($O$17:$Q$17)),0,AVERAGE($O$17:$Q$17)) -> 0
B18: 营业外收入 | C18: 前三年平均数据 | D18: =历史数据及预测表!D127 -> 1.6093279 | E18: =历史数据及预测表!E127 -> 1.4589294 | F18: =历史数据及预测表!F127 -> 1.1405179 | G18: =历史数据及预测表!G127 -> 3.0506707 | H18: =历史数据及预测表!H127 -> 1.1196703 | I18: =IF(ISERR(AVERAGE($F$18:$H$18)),0,AVERAGE($F$18:$H$18)) -> 1.7702863 | J18: =IF(ISERR(AVERAGE($G$18:$I$18)),0,AVERAGE($G$18:$I$18)) -> 1.9802091 | K18: =IF(ISERR(AVERAGE($H$18:$J$18)),0,AVERAGE($H$18:$J$18)) -> 1.6233886 | L18: =IF(ISERR(AVERAGE($I$18:$K$18)),0,AVERAGE($I$18:$K$18)) -> 1.7912947 | M18: =IF(ISERR(AVERAGE($J$18:$L$18)),0,AVERAGE($J$18:$L$18)) -> 1.7982974 | N18: =IF(ISERR(AVERAGE($K$18:$M$18)),0,AVERAGE($K$18:$M$18)) -> 1.7376602 | O18: =IF(ISERR(AVERAGE($L$18:$N$18)),0,AVERAGE($L$18:$N$18)) -> 1.7757508 | P18: =IF(ISERR(AVERAGE($M$18:$O$18)),0,AVERAGE($M$18:$O$18)) -> 1.7705695 | Q18: =IF(ISERR(AVERAGE($N$18:$P$18)),0,AVERAGE($N$18:$P$18)) -> 1.7613268 | R18: =IF(ISERR(AVERAGE($O$18:$Q$18)),0,AVERAGE($O$18:$Q$18)) -> 1.7692157 | S18: =IF(ISERR(AVERAGE($O$18:$Q$18)),0,AVERAGE($O$18:$Q$18)) -> 1.7692157 | T18: =IF(ISERR(AVERAGE($O$18:$Q$18)),0,AVERAGE($O$18:$Q$18)) -> 1.7692157
B19: 营业外支出 | C19: 前三年平均数据 | D19: =历史数据及预测表!D128 -> 0.06568668 | E19: =历史数据及预测表!E128 -> 0.19270111 | F19: =历史数据及预测表!F128 -> 0.44466041 | G19: =历史数据及预测表!G128 -> 1.6124723 | H19: =历史数据及预测表!H128 -> 1.9513034 | I19: =IF(ISERR(AVERAGE($F$19:$H$19)),0,AVERAGE($F$19:$H$19)) -> 1.3361454 | J19: =IF(ISERR(AVERAGE($G$19:$I$19)),0,AVERAGE($G$19:$I$19)) -> 1.633307 | K19: =IF(ISERR(AVERAGE($H$19:$J$19)),0,AVERAGE($H$19:$J$19)) -> 1.6402519 | L19: =IF(ISERR(AVERAGE($I$19:$K$19)),0,AVERAGE($I$19:$K$19)) -> 1.5365681 | M19: =IF(ISERR(AVERAGE($J$19:$L$19)),0,AVERAGE($J$19:$L$19)) -> 1.6033757 | N19: =IF(ISERR(AVERAGE($K$19:$M$19)),0,AVERAGE($K$19:$M$19)) -> 1.5933986 | O19: =IF(ISERR(AVERAGE($L$19:$N$19)),0,AVERAGE($L$19:$N$19)) -> 1.5777808 | P19: =IF(ISERR(AVERAGE($M$19:$O$19)),0,AVERAGE($M$19:$O$19)) -> 1.5915183 | Q19: =IF(ISERR(AVERAGE($N$19:$P$19)),0,AVERAGE($N$19:$P$19)) -> 1.5875659 | R19: =IF(ISERR(AVERAGE($O$19:$Q$19)),0,AVERAGE($O$19:$Q$19)) -> 1.5856217 | S19: =IF(ISERR(AVERAGE($O$19:$Q$19)),0,AVERAGE($O$19:$Q$19)) -> 1.5856217 | T19: =IF(ISERR(AVERAGE($O$19:$Q$19)),0,AVERAGE($O$19:$Q$19)) -> 1.5856217
B20: 实际所得税率 | C20: 前三年平均数据 | D20: =历史数据及预测表!D131/历史数据及预测表!D130 -> 0.013537259 | E20: =历史数据及预测表!E131/历史数据及预测表!E130 -> 0.044243944 | F20: =历史数据及预测表!F131/历史数据及预测表!F130 -> 0.054072299 | G20: =历史数据及预测表!G131/历史数据及预测表!G130 -> 0.1116365 | H20: =历史数据及预测表!H131/历史数据及预测表!H130 -> 0.092701643 | I20: =IF(ISERR(AVERAGE($F$20:$H$20)),0,AVERAGE($F$20:$H$20)) -> 0.086136813 | J20: =IF(ISERR(AVERAGE($G$20:$I$20)),0,AVERAGE($G$20:$I$20)) -> 0.096824985 | K20: =IF(ISERR(AVERAGE($H$20:$J$20)),0,AVERAGE($H$20:$J$20)) -> 0.091887814 | L20: =IF(ISERR(AVERAGE($I$20:$K$20)),0,AVERAGE($I$20:$K$20)) -> 0.091616537 | M20: =IF(ISERR(AVERAGE($J$20:$L$20)),0,AVERAGE($J$20:$L$20)) -> 0.093443112 | N20: =IF(ISERR(AVERAGE($K$20:$M$20)),0,AVERAGE($K$20:$M$20)) -> 0.092315821 | O20: =IF(ISERR(AVERAGE($L$20:$N$20)),0,AVERAGE($L$20:$N$20)) -> 0.09245849 | P20: =IF(ISERR(AVERAGE($M$20:$O$20)),0,AVERAGE($M$20:$O$20)) -> 0.092739141 | Q20: =IF(ISERR(AVERAGE($N$20:$P$20)),0,AVERAGE($N$20:$P$20)) -> 0.092504484 | R20: =IF(ISERR(AVERAGE($O$20:$Q$20)),0,AVERAGE($O$20:$Q$20)) -> 0.092567372 | S20: =IF(ISERR(AVERAGE($O$20:$Q$20)),0,AVERAGE($O$20:$Q$20)) -> 0.092567372 | T20: =IF(ISERR(AVERAGE($O$20:$Q$20)),0,AVERAGE($O$20:$Q$20)) -> 0.092567372
B21: 未确认的投资损失 | C21: 前三年平均数据 | D21: =历史数据及预测表!D132 -> 0 | E21: =历史数据及预测表!E132 -> 0 | F21: =历史数据及预测表!F132 -> 0 | G21: =历史数据及预测表!G132 -> 0 | H21: =历史数据及预测表!H132 -> 0 | I21: =IF(ISERR(AVERAGE($F$21:$H$21)),0,AVERAGE($F$21:$H$21)) -> 0 | J21: =IF(ISERR(AVERAGE($G$21:$I$21)),0,AVERAGE($G$21:$I$21)) -> 0 | K21: =IF(ISERR(AVERAGE($H$21:$J$21)),0,AVERAGE($H$21:$J$21)) -> 0 | L21: =IF(ISERR(AVERAGE($I$21:$K$21)),0,AVERAGE($I$21:$K$21)) -> 0 | M21: =IF(ISERR(AVERAGE($J$21:$L$21)),0,AVERAGE($J$21:$L$21)) -> 0 | N21: =IF(ISERR(AVERAGE($K$21:$M$21)),0,AVERAGE($K$21:$M$21)) -> 0 | O21: =IF(ISERR(AVERAGE($L$21:$N$21)),0,AVERAGE($L$21:$N$21)) -> 0 | P21: =IF(ISERR(AVERAGE($M$21:$O$21)),0,AVERAGE($M$21:$O$21)) -> 0 | Q21: =IF(ISERR(AVERAGE($N$21:$P$21)),0,AVERAGE($N$21:$P$21)) -> 0 | R21: =IF(ISERR(AVERAGE($O$21:$Q$21)),0,AVERAGE($O$21:$Q$21)) -> 0 | S21: =IF(ISERR(AVERAGE($O$21:$Q$21)),0,AVERAGE($O$21:$Q$21)) -> 0 | T21: =IF(ISERR(AVERAGE($O$21:$Q$21)),0,AVERAGE($O$21:$Q$21)) -> 0
B22: 少数股东损益/净利润 | C22: 前三年平均数据 | D22: =历史数据及预测表!D135/历史数据及预测表!D134 -> -0.005220674 | E22: =历史数据及预测表!E135/历史数据及预测表!E134 -> -0.013231822 | F22: =历史数据及预测表!F135/历史数据及预测表!F134 -> -0.041747011 | G22: =历史数据及预测表!G135/历史数据及预测表!G134 -> -0.0055033751 | H22: =历史数据及预测表!H135/历史数据及预测表!H134 -> -0.0023852678 | I22: =IF(ISERR(AVERAGE($F$22:$H$22)),0,AVERAGE($F$22:$H$22)) -> -0.016545218 | J22: =IF(ISERR(AVERAGE($G$22:$I$22)),0,AVERAGE($G$22:$I$22)) -> -0.0081446203 | K22: =IF(ISERR(AVERAGE($H$22:$J$22)),0,AVERAGE($H$22:$J$22)) -> -0.0090250353 | L22: =IF(ISERR(AVERAGE($I$22:$K$22)),0,AVERAGE($I$22:$K$22)) -> -0.011238291 | M22: =IF(ISERR(AVERAGE($J$22:$L$22)),0,AVERAGE($J$22:$L$22)) -> -0.0094693156 | N22: =IF(ISERR(AVERAGE($K$22:$M$22)),0,AVERAGE($K$22:$M$22)) -> -0.0099108807 | O22: =IF(ISERR(AVERAGE($L$22:$N$22)),0,AVERAGE($L$22:$N$22)) -> -0.010206162 | P22: =IF(ISERR(AVERAGE($M$22:$O$22)),0,AVERAGE($M$22:$O$22)) -> -0.0098621196 | Q22: =IF(ISERR(AVERAGE($N$22:$P$22)),0,AVERAGE($N$22:$P$22)) -> -0.0099930542 | R22: =IF(ISERR(AVERAGE($O$22:$Q$22)),0,AVERAGE($O$22:$Q$22)) -> -0.010020445 | S22: =IF(ISERR(AVERAGE($O$22:$Q$22)),0,AVERAGE($O$22:$Q$22)) -> -0.010020445 | T22: =IF(ISERR(AVERAGE($O$22:$Q$22)),0,AVERAGE($O$22:$Q$22)) -> -0.010020445
B23: 其他综合收益 | C23: 前三年平均数据 | D23: =历史数据及预测表!D137 -> -39.835859 | E23: =历史数据及预测表!E137 -> 224.78408 | F23: =历史数据及预测表!F137 -> 69.903818 | G23: =历史数据及预测表!G137 -> -59.621816 | H23: =历史数据及预测表!H137 -> -45.661901 | I23: =IF(ISERR(AVERAGE($F$23:$H$23)),0,AVERAGE($F$23:$H$23)) -> -11.7933 | J23: =IF(ISERR(AVERAGE($G$23:$I$23)),0,AVERAGE($G$23:$I$23)) -> -39.025672 | K23: =IF(ISERR(AVERAGE($H$23:$J$23)),0,AVERAGE($H$23:$J$23)) -> -32.160291 | L23: =IF(ISERR(AVERAGE($I$23:$K$23)),0,AVERAGE($I$23:$K$23)) -> -27.659754 | M23: =IF(ISERR(AVERAGE($J$23:$L$23)),0,AVERAGE($J$23:$L$23)) -> -32.948573 | N23: =IF(ISERR(AVERAGE($K$23:$M$23)),0,AVERAGE($K$23:$M$23)) -> -30.922873 | O23: =IF(ISERR(AVERAGE($L$23:$N$23)),0,AVERAGE($L$23:$N$23)) -> -30.5104 | P23: =IF(ISERR(AVERAGE($M$23:$O$23)),0,AVERAGE($M$23:$O$23)) -> -31.460615 | Q23: =IF(ISERR(AVERAGE($N$23:$P$23)),0,AVERAGE($N$23:$P$23)) -> -30.964629 | R23: =IF(ISERR(AVERAGE($O$23:$Q$23)),0,AVERAGE($O$23:$Q$23)) -> -30.978548 | S23: =IF(ISERR(AVERAGE($O$23:$Q$23)),0,AVERAGE($O$23:$Q$23)) -> -30.978548 | T23: =IF(ISERR(AVERAGE($O$23:$Q$23)),0,AVERAGE($O$23:$Q$23)) -> -30.978548
B24: 少数股东综合收益/综合收益总额 | C24: 前三年平均数据 | D24: =历史数据及预测表!D139/历史数据及预测表!D138 -> -0.0053567444 | E24: =历史数据及预测表!E139/历史数据及预测表!E138 -> -0.010032184 | F24: =历史数据及预测表!F139/历史数据及预测表!F138 -> -0.036046069 | G24: =历史数据及预测表!G139/历史数据及预测表!G138 -> -0.0091406212 | H24: =历史数据及预测表!H139/历史数据及预测表!H138 -> -0.0022920581 | I24: =IF(ISERR(AVERAGE($F$24:$H$24)),0,AVERAGE($F$24:$H$24)) -> -0.015826249 | J24: =IF(ISERR(AVERAGE($G$24:$I$24)),0,AVERAGE($G$24:$I$24)) -> -0.0090863096 | K24: =IF(ISERR(AVERAGE($H$24:$J$24)),0,AVERAGE($H$24:$J$24)) -> -0.0090682057 | L24: =IF(ISERR(AVERAGE($I$24:$K$24)),0,AVERAGE($I$24:$K$24)) -> -0.011326922 | M24: =IF(ISERR(AVERAGE($J$24:$L$24)),0,AVERAGE($J$24:$L$24)) -> -0.0098271456 | N24: =IF(ISERR(AVERAGE($K$24:$M$24)),0,AVERAGE($K$24:$M$24)) -> -0.010074091 | O24: =IF(ISERR(AVERAGE($L$24:$N$24)),0,AVERAGE($L$24:$N$24)) -> -0.010409386 | P24: =IF(ISERR(AVERAGE($M$24:$O$24)),0,AVERAGE($M$24:$O$24)) -> -0.010103541 | Q24: =IF(ISERR(AVERAGE($N$24:$P$24)),0,AVERAGE($N$24:$P$24)) -> -0.010195673 | R24: =IF(ISERR(AVERAGE($O$24:$Q$24)),0,AVERAGE($O$24:$Q$24)) -> -0.0102362 | S24: =IF(ISERR(AVERAGE($O$24:$Q$24)),0,AVERAGE($O$24:$Q$24)) -> -0.0102362 | T24: =IF(ISERR(AVERAGE($O$24:$Q$24)),0,AVERAGE($O$24:$Q$24)) -> -0.0102362
B25: DPS-Q1 | D25: =历史数据及预测表!D214 -> 0 | E25: =历史数据及预测表!E214 -> 0 | F25: =历史数据及预测表!F214 -> 0 | G25: =历史数据及预测表!G214 -> 0 | H25: =历史数据及预测表!H214 -> 0
B26: DPS-Q2/年中 | D26: =历史数据及预测表!D215 -> 0 | E26: =历史数据及预测表!E215 -> 0 | F26: =历史数据及预测表!F215 -> 0 | G26: =历史数据及预测表!G215 -> 0 | H26: =历史数据及预测表!H215 -> 0
B27: DPS-Q3 | D27: =历史数据及预测表!D216 -> 0 | E27: =历史数据及预测表!E216 -> 0 | F27: =历史数据及预测表!F216 -> 0 | G27: =历史数据及预测表!G216 -> 0 | H27: =历史数据及预测表!H216 -> 0
B28: DPS-Q4/年末 | D28: =历史数据及预测表!D217 -> 0.19 | E28: =历史数据及预测表!E217 -> 0.08 | F28: =历史数据及预测表!F217 -> 0.2 | G28: =历史数据及预测表!G217 -> 0.0998 | H28: =历史数据及预测表!H217 -> 0.15
B29: DPS-特殊 | D29: =历史数据及预测表!D218 -> 0 | E29: =历史数据及预测表!E218 -> 0 | F29: =历史数据及预测表!F218 -> 0 | G29: =历史数据及预测表!G218 -> 0 | H29: =历史数据及预测表!H218 -> 0
B30: 股利支付率 | D30: =历史数据及预测表!D226 -> 0.098790913 | E30: =历史数据及预测表!E226 -> 0.048813313 | F30: =历史数据及预测表!F226 -> 0.17927072 | G30: =历史数据及预测表!G226 -> 0.13124086 | H30: =历史数据及预测表!H226 -> 0.1923873 | I30: 0.2 | J30: 0.2 | K30: 0.2 | L30: 0.2 | M30: 0.2 | N30: 0.2 | O30: 0.2 | P30: 0.2 | Q30: 0.2 | R30: 0.2 | S30: 0.2 | T30: 0.2
A32: 营运资金假设
B33: 交易性金融资产本期增减 | C33: 默认值0 | E33: =历史数据及预测表!E8-历史数据及预测表!D8 -> -611.61648 | F33: =历史数据及预测表!F8-历史数据及预测表!E8 -> 43.258329 | G33: =历史数据及预测表!G8-历史数据及预测表!F8 -> 363.87195 | H33: =历史数据及预测表!H8-历史数据及预测表!G8 -> 141.96748 | I33: 0 | J33: 0 | K33: 0 | L33: 0 | M33: 0 | N33: 0 | O33: 0 | P33: 0 | Q33: 0 | R33: 0 | S33: 0 | T33: 0
B34: 衍生金融资产本期增减 | C34: 默认值0 | E34: =历史数据及预测表!E9-历史数据及预测表!D9 -> 0 | F34: =历史数据及预测表!F9-历史数据及预测表!E9 -> 0 | G34: =历史数据及预测表!G9-历史数据及预测表!F9 -> 0 | H34: =历史数据及预测表!H9-历史数据及预测表!G9 -> 0 | I34: 0 | J34: 0 | K34: 0 | L34: 0 | M34: 0 | N34: 0 | O34: 0 | P34: 0 | Q34: 0 | R34: 0 | S34: 0 | T34: 0
B35: 应收账款原值/营业收入 | C35: 前三年平均数据 | D35: =历史数据及预测表!D189/历史数据及预测表!D107 -> 0.12480499 | E35: =历史数据及预测表!E189/历史数据及预测表!E107 -> 0.095342456 | F35: =历史数据及预测表!F189/历史数据及预测表!F107 -> 0.089021279 | G35: =历史数据及预测表!G189/历史数据及预测表!G107 -> 0.09227702 | H35: =历史数据及预测表!H189/历史数据及预测表!H107 -> 0.098403652 | I35: =IF(ISERR(AVERAGE($F$35:$H$35)),0,AVERAGE($F$35:$H$35)) -> 0.093233983 | J35: =IF(ISERR(AVERAGE($G$35:$I$35)),0,AVERAGE($G$35:$I$35)) -> 0.094638218 | K35: =IF(ISERR(AVERAGE($H$35:$J$35)),0,AVERAGE($H$35:$J$35)) -> 0.095425284 | L35: =IF(ISERR(AVERAGE($I$35:$K$35)),0,AVERAGE($I$35:$K$35)) -> 0.094432495 | M35: =IF(ISERR(AVERAGE($J$35:$L$35)),0,AVERAGE($J$35:$L$35)) -> 0.094831999 | N35: =IF(ISERR(AVERAGE($K$35:$M$35)),0,AVERAGE($K$35:$M$35)) -> 0.094896593 | O35: =IF(ISERR(AVERAGE($L$35:$N$35)),0,AVERAGE($L$35:$N$35)) -> 0.094720363 | P35: =IF(ISERR(AVERAGE($M$35:$O$35)),0,AVERAGE($M$35:$O$35)) -> 0.094816318 | Q35: =IF(ISERR(AVERAGE($N$35:$P$35)),0,AVERAGE($N$35:$P$35)) -> 0.094811091 | R35: =IF(ISERR(AVERAGE($O$35:$Q$35)),0,AVERAGE($O$35:$Q$35)) -> 0.094782591 | S35: =IF(ISERR(AVERAGE($O$35:$Q$35)),0,AVERAGE($O$35:$Q$35)) -> 0.094782591 | T35: =IF(ISERR(AVERAGE($O$35:$Q$35)),0,AVERAGE($O$35:$Q$35)) -> 0.094782591
B36: 坏账准备/应收账款 | C36: 前三年平均数据 | D36: =历史数据及预测表!D190/历史数据及预测表!D189 -> 0 | E36: =历史数据及预测表!E190/历史数据及预测表!E189 -> 0 | F36: =历史数据及预测表!F190/历史数据及预测表!F189 -> 0 | G36: =历史数据及预测表!G190/历史数据及预测表!G189 -> 0 | H36: =历史数据及预测表!H190/历史数据及预测表!H189 -> 0 | I36: =IF(ISERR(AVERAGE($F$36:$H$36)),0,AVERAGE($F$36:$H$36)) -> 0 | J36: =IF(ISERR(AVERAGE($G$36:$I$36)),0,AVERAGE($G$36:$I$36)) -> 0 | K36: =IF(ISERR(AVERAGE($H$36:$J$36)),0,AVERAGE($H$36:$J$36)) -> 0 | L36: =IF(ISERR(AVERAGE($I$36:$K$36)),0,AVERAGE($I$36:$K$36)) -> 0 | M36: =IF(ISERR(AVERAGE($J$36:$L$36)),0,AVERAGE($J$36:$L$36)) -> 0 | N36: =IF(ISERR(AVERAGE($K$36:$M$36)),0,AVERAGE($K$36:$M$36)) -> 0 | O36: =IF(ISERR(AVERAGE($L$36:$N$36)),0,AVERAGE($L$36:$N$36)) -> 0 | P36: =IF(ISERR(AVERAGE($M$36:$O$36)),0,AVERAGE($M$36:$O$36)) -> 0 | Q36: =IF(ISERR(AVERAGE($N$36:$P$36)),0,AVERAGE($N$36:$P$36)) -> 0 | R36: =IF(ISERR(AVERAGE($O$36:$Q$36)),0,AVERAGE($O$36:$Q$36)) -> 0 | S36: =IF(ISERR(AVERAGE($O$36:$Q$36)),0,AVERAGE($O$36:$Q$36)) -> 0 | T36: =IF(ISERR(AVERAGE($O$36:$Q$36)),0,AVERAGE($O$36:$Q$36)) -> 0
B37: 应收票据/营业收入 | C37: 前三年平均数据 | D37: =历史数据及预测表!D11/历史数据及预测表!D107 -> 0.00051238879 | E37: =历史数据及预测表!E11/历史数据及预测表!E107 -> 0.00082078369 | F37: =历史数据及预测表!F11/历史数据及预测表!F107 -> 0.00087922083 | G37: =历史数据及预测表!G11/历史数据及预测表!G107 -> 0.00052765942 | H37: =历史数据及预测表!H11/历史数据及预测表!H107 -> 0.00089617997 | I37: =IF(ISERR(AVERAGE($F$37:$H$37)),0,AVERAGE($F$37:$H$37)) -> 0.00076768674 | J37: =IF(ISERR(AVERAGE($G$37:$I$37)),0,AVERAGE($G$37:$I$37)) -> 0.00073050871 | K37: =IF(ISERR(AVERAGE($H$37:$J$37)),0,AVERAGE($H$37:$J$37)) -> 0.00079812514 | L37: =IF(ISERR(AVERAGE($I$37:$K$37)),0,AVERAGE($I$37:$K$37)) -> 0.0007654402 | M37: =IF(ISERR(AVERAGE($J$37:$L$37)),0,AVERAGE($J$37:$L$37)) -> 0.00076469135 | N37: =IF(ISERR(AVERAGE($K$37:$M$37)),0,AVERAGE($K$37:$M$37)) -> 0.00077608556 | O37: =IF(ISERR(AVERAGE($L$37:$N$37)),0,AVERAGE($L$37:$N$37)) -> 0.00076873904 | P37: =IF(ISERR(AVERAGE($M$37:$O$37)),0,AVERAGE($M$37:$O$37)) -> 0.00076983865 | Q37: =IF(ISERR(AVERAGE($N$37:$P$37)),0,AVERAGE($N$37:$P$37)) -> 0.00077155442 | R37: =IF(ISERR(AVERAGE($O$37:$Q$37)),0,AVERAGE($O$37:$Q$37)) -> 0.00077004403 | S37: =IF(ISERR(AVERAGE($O$37:$Q$37)),0,AVERAGE($O$37:$Q$37)) -> 0.00077004403 | T37: =IF(ISERR(AVERAGE($O$37:$Q$37)),0,AVERAGE($O$37:$Q$37)) -> 0.00077004403
B38: 应收款项融资/营业收入 | C38: 前三年平均数据 | D38: =历史数据及预测表!D12/历史数据及预测表!D107 -> 0 | E38: =历史数据及预测表!E12/历史数据及预测表!E107 -> 0 | F38: =历史数据及预测表!F12/历史数据及预测表!F107 -> 0 | G38: =历史数据及预测表!G12/历史数据及预测表!G107 -> 0 | H38: =历史数据及预测表!H12/历史数据及预测表!H107 -> 0 | I38: =IF(ISERR(AVERAGE($F$38:$H$38)),0,AVERAGE($F$38:$H$38)) -> 0 | J38: =IF(ISERR(AVERAGE($G$38:$I$38)),0,AVERAGE($G$38:$I$38)) -> 0 | K38: =IF(ISERR(AVERAGE($H$38:$J$38)),0,AVERAGE($H$38:$J$38)) -> 0 | L38: =IF(ISERR(AVERAGE($I$38:$K$38)),0,AVERAGE($I$38:$K$38)) -> 0 | M38: =IF(ISERR(AVERAGE($J$38:$L$38)),0,AVERAGE($J$38:$L$38)) -> 0 | N38: =IF(ISERR(AVERAGE($K$38:$M$38)),0,AVERAGE($K$38:$M$38)) -> 0 | O38: =IF(ISERR(AVERAGE($L$38:$N$38)),0,AVERAGE($L$38:$N$38)) -> 0 | P38: =IF(ISERR(AVERAGE($M$38:$O$38)),0,AVERAGE($M$38:$O$38)) -> 0 | Q38: =IF(ISERR(AVERAGE($N$38:$P$38)),0,AVERAGE($N$38:$P$38)) -> 0 | R38: =IF(ISERR(AVERAGE($O$38:$Q$38)),0,AVERAGE($O$38:$Q$38)) -> 0 | S38: =IF(ISERR(AVERAGE($O$38:$Q$38)),0,AVERAGE($O$38:$Q$38)) -> 0 | T38: =IF(ISERR(AVERAGE($O$38:$Q$38)),0,AVERAGE($O$38:$Q$38)) -> 0
B39: 预付账款/营业成本 | C39: 前三年平均数据 | D39: =历史数据及预测表!D13/历史数据及预测表!D110 -> 0.0088032422 | E39: =历史数据及预测表!E13/历史数据及预测表!E110 -> 0.016304494 | F39: =历史数据及预测表!F13/历史数据及预测表!F110 -> 0.024213001 | G39: =历史数据及预测表!G13/历史数据及预测表!G110 -> 0.033685667 | H39: =历史数据及预测表!H13/历史数据及预测表!H110 -> 0.050412123 | I39: =IF(ISERR(AVERAGE($F$39:$H$39)),0,AVERAGE($F$39:$H$39)) -> 0.036103597 | J39: =IF(ISERR(AVERAGE($G$39:$I$39)),0,AVERAGE($G$39:$I$39)) -> 0.040067129 | K39: =IF(ISERR(AVERAGE($H$39:$J$39)),0,AVERAGE($H$39:$J$39)) -> 0.042194283 | L39: =IF(ISERR(AVERAGE($I$39:$K$39)),0,AVERAGE($I$39:$K$39)) -> 0.039455003 | M39: =IF(ISERR(AVERAGE($J$39:$L$39)),0,AVERAGE($J$39:$L$39)) -> 0.040572139 | N39: =IF(ISERR(AVERAGE($K$39:$M$39)),0,AVERAGE($K$39:$M$39)) -> 0.040740475 | O39: =IF(ISERR(AVERAGE($L$39:$N$39)),0,AVERAGE($L$39:$N$39)) -> 0.040255872 | P39: =IF(ISERR(AVERAGE($M$39:$O$39)),0,AVERAGE($M$39:$O$39)) -> 0.040522829 | Q39: =IF(ISERR(AVERAGE($N$39:$P$39)),0,AVERAGE($N$39:$P$39)) -> 0.040506392 | R39: =IF(ISERR(AVERAGE($O$39:$Q$39)),0,AVERAGE($O$39:$Q$39)) -> 0.040428364 | S39: =IF(ISERR(AVERAGE($O$39:$Q$39)),0,AVERAGE($O$39:$Q$39)) -> 0.040428364 | T39: =IF(ISERR(AVERAGE($O$39:$Q$39)),0,AVERAGE($O$39:$Q$39)) -> 0.040428364
B40: 其他应收款/营业收入 | C40: 前三年平均数据 | D40: =历史数据及预测表!D192/历史数据及预测表!D107 -> 0.017863873 | E40: =历史数据及预测表!E192/历史数据及预测表!E107 -> 0.018828519 | F40: =历史数据及预测表!F192/历史数据及预测表!F107 -> 0.062688853 | G40: =历史数据及预测表!G192/历史数据及预测表!G107 -> 0.067610494 | H40: =历史数据及预测表!H192/历史数据及预测表!H107 -> 0.00034955126 | I40: =IF(ISERR(AVERAGE($F$40:$H$40)),0,AVERAGE($F$40:$H$40)) -> 0.043549633 | J40: =IF(ISERR(AVERAGE($G$40:$I$40)),0,AVERAGE($G$40:$I$40)) -> 0.037169893 | K40: =IF(ISERR(AVERAGE($H$40:$J$40)),0,AVERAGE($H$40:$J$40)) -> 0.027023026 | L40: =IF(ISERR(AVERAGE($I$40:$K$40)),0,AVERAGE($I$40:$K$40)) -> 0.035914184 | M40: =IF(ISERR(AVERAGE($J$40:$L$40)),0,AVERAGE($J$40:$L$40)) -> 0.033369034 | N40: =IF(ISERR(AVERAGE($K$40:$M$40)),0,AVERAGE($K$40:$M$40)) -> 0.032102081 | O40: =IF(ISERR(AVERAGE($L$40:$N$40)),0,AVERAGE($L$40:$N$40)) -> 0.0337951 | P40: =IF(ISERR(AVERAGE($M$40:$O$40)),0,AVERAGE($M$40:$O$40)) -> 0.033088738 | Q40: =IF(ISERR(AVERAGE($N$40:$P$40)),0,AVERAGE($N$40:$P$40)) -> 0.032995306 | R40: =IF(ISERR(AVERAGE($O$40:$Q$40)),0,AVERAGE($O$40:$Q$40)) -> 0.033293048 | S40: =IF(ISERR(AVERAGE($O$40:$Q$40)),0,AVERAGE($O$40:$Q$40)) -> 0.033293048 | T40: =IF(ISERR(AVERAGE($O$40:$Q$40)),0,AVERAGE($O$40:$Q$40)) -> 0.033293048
B41: 其他应收款坏账准备/其他应收款 | C41: 前三年平均数据 | D41: =历史数据及预测表!D193/历史数据及预测表!D192 -> 0 | E41: =历史数据及预测表!E193/历史数据及预测表!E192 -> 0 | F41: =历史数据及预测表!F193/历史数据及预测表!F192 -> 0 | G41: =历史数据及预测表!G193/历史数据及预测表!G192 -> 0 | H41: =历史数据及预测表!H193/历史数据及预测表!H192 -> 0 | I41: =IF(ISERR(AVERAGE($F$41:$H$41)),0,AVERAGE($F$41:$H$41)) -> 0 | J41: =IF(ISERR(AVERAGE($G$41:$I$41)),0,AVERAGE($G$41:$I$41)) -> 0 | K41: =IF(ISERR(AVERAGE($H$41:$J$41)),0,AVERAGE($H$41:$J$41)) -> 0 | L41: =IF(ISERR(AVERAGE($I$41:$K$41)),0,AVERAGE($I$41:$K$41)) -> 0 | M41: =IF(ISERR(AVERAGE($J$41:$L$41)),0,AVERAGE($J$41:$L$41)) -> 0 | N41: =IF(ISERR(AVERAGE($K$41:$M$41)),0,AVERAGE($K$41:$M$41)) -> 0 | O41: =IF(ISERR(AVERAGE($L$41:$N$41)),0,AVERAGE($L$41:$N$41)) -> 0 | P41: =IF(ISERR(AVERAGE($M$41:$O$41)),0,AVERAGE($M$41:$O$41)) -> 0 | Q41: =IF(ISERR(AVERAGE($N$41:$P$41)),0,AVERAGE($N$41:$P$41)) -> 0 | R41: =IF(ISERR(AVERAGE($O$41:$Q$41)),0,AVERAGE($O$41:$Q$41)) -> 0 | S41: =IF(ISERR(AVERAGE($O$41:$Q$41)),0,AVERAGE($O$41:$Q$41)) -> 0 | T41: =IF(ISERR(AVERAGE($O$41:$Q$41)),0,AVERAGE($O$41:$Q$41)) -> 0
...

Sheet 关键项目预测
B1: 资本性支出预测
B3: 预测方法 | C3: 1 | E3: =IF(C3=1,NOT(ISBLANK(C10)),OR(NOT(ISBLANK(C31)),NOT(ISBLANK(C50)),NOT(ISBLANK(C69)),NOT(ISBLANK(C88)))) -> TRUE
B4: 方法1 | C4: 固定资产整体预测（整体预测+在建工程转入）
B5: 方法2 | C5: 固定资产分类别预测
A7: 方法1 | C7: 整体预测
B8: 固定资产
B9: 固定资产-整体预测
B10: 折旧年限 | C10: 10 | E10: 残值率 | F10: 0.05 | H10: 折旧率 | I10: =(1-F10)/C10 -> 0.095
E11: =假设表!I2 -> 2026 | F11: =假设表!J2 -> 2027 | G11: =假设表!K2 -> 2028 | H11: =假设表!L2 -> 2029 | I11: =假设表!M2 -> 2030 | J11: =假设表!N2 -> 2031 | K11: =假设表!O2 -> 2032 | L11: =假设表!P2 -> 2033 | ... P11: =假设表!T2 -> 2037
B12: 年份 | C12: 金额
B13: {=TRANSPOSE(历史数据及预测表!H4:T4)} -> 2025 | C13: 期末固定资产（账面原值） | D13: {=TRANSPOSE(假设表!H86:T86)} -> 462.27066 | E13: =IF(E$11-$B13<=$C$10,$I$10*$D13,0) -> 43.915713 | F13: =IF(F$11-$B13<=$C$10,$I$10*$D13,0) -> 43.915713 | G13: =IF(G$11-$B13<=$C$10,$I$10*$D13,0) -> 43.915713 | H13: =IF(H$11-$B13<=$C$10,$I$10*$D13,0) -> 43.915713 | I13: =IF(I$11-$B13<=$C$10,$I$10*$D13,0) -> 43.915713 | J13: =IF(J$11-$B13<=$C$10,$I$10*$D13,0) -> 43.915713 | K13: =IF(K$11-$B13<=$C$10,$I$10*$D13,0) -> 43.915713 | L13: =IF(L$11-$B13<=$C$10,$I$10*$D13,0) -> 43.915713 | ... P13: =IF(P$11-$B13<=$C$10,$I$10*$D13,0) -> 0
B14: 2026 | C14: 新增数 | D14: 200 | E14: =IF(E$11-$B14<=$C$10-1,$I$10*$D14,0) -> 19 | F14: =IF(F$11-$B14<=$C$10-1,$I$10*$D14,0) -> 19 | G14: =IF(G$11-$B14<=$C$10-1,$I$10*$D14,0) -> 19 | H14: =IF(H$11-$B14<=$C$10-1,$I$10*$D14,0) -> 19 | I14: =IF(I$11-$B14<=$C$10-1,$I$10*$D14,0) -> 19 | J14: =IF(J$11-$B14<=$C$10-1,$I$10*$D14,0) -> 19 | K14: =IF(K$11-$B14<=$C$10-1,$I$10*$D14,0) -> 19 | L14: =IF(L$11-$B14<=$C$10-1,$I$10*$D14,0) -> 19 | ... P14: =IF(P$11-$B14<=$C$10-1,$I$10*$D14,0) -> 0
B15: 2027 | C15: 新增数 | D15: 200 | F15: =IF(F$11-$B15<=$C$10-1,$I$10*$D15,0) -> 19 | G15: =IF(G$11-$B15<=$C$10-1,$I$10*$D15,0) -> 19 | H15: =IF(H$11-$B15<=$C$10-1,$I$10*$D15,0) -> 19 | I15: =IF(I$11-$B15<=$C$10-1,$I$10*$D15,0) -> 19 | J15: =IF(J$11-$B15<=$C$10-1,$I$10*$D15,0) -> 19 | K15: =IF(K$11-$B15<=$C$10-1,$I$10*$D15,0) -> 19 | L15: =IF(L$11-$B15<=$C$10-1,$I$10*$D15,0) -> 19 | M15: =IF(M$11-$B15<=$C$10-1,$I$10*$D15,0) -> 19 | ... P15: =IF(P$11-$B15<=$C$10-1,$I$10*$D15,0) -> 0
