Workbook

Sheet 中信三级行业指数热度
A1: 指数代码 | B1: 指数名称 | C1: 指数成分股数 | D1: YTD涨幅(%) | E1: 近一周涨跌幅(%) | F1: 近一月涨跌幅(%) | G1: 动量加速度 | H1: CR5合计权重(%) | I1: CR1代码 | J1: CR1名称 | K1: CR1自由流通市值(亿) | L1: CR1权重(%) | M1: CR2代码 | N1: CR2名称 | O1: CR2自由流通市值(亿) | P1: CR2权重(%) | Q1: CR3代码 | R1: CR3名称 | S1: CR3自由流通市值(亿) | T1: CR3权重(%) | U1: CR4代码 | V1: CR4名称 | W1: CR4自由流通市值(亿) | X1: CR4权重(%) | Y1: CR5代码 | Z1: CR5名称 | AA1: CR5自由流通市值(亿) | AB1: CR5权重(%) | AD1: 基准日:今天 | AE1: =TODAY()
A2: CI005381.CI | B2: 线缆指数 | C2: 12 | D2: =IFERROR((thsiFinD("ths_close_price_index",$A2,$AE$2,"","")/thsiFinD("ths_close_price_index",$A2,$AE$5,"","")-1)*100,"") | E2: =IFERROR((thsiFinD("ths_close_price_index",$A2,$AE$2,"","")/thsiFinD("ths_close_price_index",$A2,$AE$3,"","")-1)*100,"") | F2: =IFERROR((thsiFinD("ths_close_price_index",$A2,$AE$2,"","")/thsiFinD("ths_close_price_index",$A2,$AE$4,"","")-1)*100,"") | G2: =IFERROR(E2/5-F2/20,"") | H2: 89.69 | I2: 600487.SH | J2: 亨通光电 | K2: 2109.6284 | L2: 34.54 | M2: 600522.SH | N2: 中天科技 | O2: 1573.5354 | P2: 25.77 | Q2: 600105.SH | R2: 永鼎股份 | S2: 708.6299 | T2: 11.6 | U2: 601869.SH | V2: 长飞光纤 | W2: 558.5133 | X2: 9.15 | Y2: 688313.SH | Z2: 仕佳光子 | AA2: 527.2326 | AB2: 8.63 | AD2: 前一交易日T0(工作日近似) | AE2: =TEXT(WORKDAY($AE$1,-1),"yyyy-mm-dd")
A3: CI005543.CI | B3: 被动元件指数 | C3: 12 | D3: =IFERROR((thsiFinD("ths_close_price_index",$A3,$AE$2,"","")/thsiFinD("ths_close_price_index",$A3,$AE$5,"","")-1)*100,"") | E3: =IFERROR((thsiFinD("ths_close_price_index",$A3,$AE$2,"","")/thsiFinD("ths_close_price_index",$A3,$AE$3,"","")-1)*100,"") | F3: =IFERROR((thsiFinD("ths_close_price_index",$A3,$AE$2,"","")/thsiFinD("ths_close_price_index",$A3,$AE$4,"","")-1)*100,"") | G3: =IFERROR(E3/5-F3/20,"") | H3: 89.78 | I3: 300408.SZ | J3: 三环集团 | K3: 1890.5672 | L3: 44.56 | M3: 000636.SZ | N3: 风华高科 | O3: 645.2297 | P3: 15.21 | Q3: 002484.SZ | R3: 江海股份 | S3: 551.4655 | T3: 13 | U3: 002138.SZ | V3: 顺络电子 | W3: 498.1586 | X3: 11.74 | Y3: 600563.SH | Z3: 法拉电子 | AA3: 223.4035 | AB3: 5.27 | AD3: 一周前(T0前5交易日) | AE3: =TEXT(WORKDAY($AE$1,-6),"yyyy-mm-dd")
A4: CI005441.CI | B4: 玻璃纤维指数 | C4: 6 | D4: =IFERROR((thsiFinD("ths_close_price_index",$A4,$AE$2,"","")/thsiFinD("ths_close_price_index",$A4,$AE$5,"","")-1)*100,"") | E4: =IFERROR((thsiFinD("ths_close_price_index",$A4,$AE$2,"","")/thsiFinD("ths_close_price_index",$A4,$AE$3,"","")-1)*100,"") | F4: =IFERROR((thsiFinD("ths_close_price_index",$A4,$AE$2,"","")/thsiFinD("ths_close_price_index",$A4,$AE$4,"","")-1)*100,"") | G4: =IFERROR(E4/5-F4/20,"") | H4: 100 | I4: 600176.SH | J4: 中国巨石 | K4: 1218.3989 | L4: 62.72 | M4: 002080.SZ | N4: 中材科技 | O4: 562.6243 | P4: 28.96 | Q4: 300196.SZ | R4: 长海股份 | S4: 63.8381 | T4: 3.29 | U4: 002201.SZ | V4: 九鼎新材 | W4: 52.3386 | X4: 2.69 | Y4: 605006.SH | Z4: 山东玻纤 | AA4: 45.5259 | AB4: 2.34 | AD4: 一月前(T0前20交易日) | AE4: =TEXT(WORKDAY($AE$1,-21),"yyyy-mm-dd")
A5: CI005469.CI | B5: 激光加工设备指数 | C5: 10 | D5: =IFERROR((thsiFinD("ths_close_price_index",$A5,$AE$2,"","")/thsiFinD("ths_close_price_index",$A5,$AE$5,"","")-1)*100,"") | E5: =IFERROR((thsiFinD("ths_close_price_index",$A5,$AE$2,"","")/thsiFinD("ths_close_price_index",$A5,$AE$3,"","")-1)*100,"") | F5: =IFERROR((thsiFinD("ths_close_price_index",$A5,$AE$2,"","")/thsiFinD("ths_close_price_index",$A5,$AE$4,"","")-1)*100,"") | G5: =IFERROR(E5/5-F5/20,"") | H5: 89.2 | I5: 002008.SZ | J5: 大族激光 | K5: 1030.1521 | L5: 49.72 | M5: 688025.SH | N5: 杰普特 | O5: 273.465 | P5: 13.2 | Q5: 300776.SZ | R5: 帝尔激光 | S5: 253.0384 | T5: 12.21 | U5: 300747.SZ | V5: 锐科激光 | W5: 171.5275 | X5: 8.28 | Y5: 301021.SZ | Z5: 英诺激光 | AA5: 119.8984 | AB5: 5.79 | AD5: 年初基准(上年末交易日) | AE5: =TEXT(WORKDAY(DATE(YEAR($AE$1),1,1),-1),"yyyy-mm-dd")
A6: CI005401.CI | B6: 钨指数 | C6: 4 | D6: =IFERROR((thsiFinD("ths_close_price_index",$A6,$AE$2,"","")/thsiFinD("ths_close_price_index",$A6,$AE$5,"","")-1)*100,"") | E6: =IFERROR((thsiFinD("ths_close_price_index",$A6,$AE$2,"","")/thsiFinD("ths_close_price_index",$A6,$AE$3,"","")-1)*100,"") | F6: =IFERROR((thsiFinD("ths_close_price_index",$A6,$AE$2,"","")/thsiFinD("ths_close_price_index",$A6,$AE$4,"","")-1)*100,"") | G6: =IFERROR(E6/5-F6/20,"") | H6: 99.99 | I6: 000657.SZ | J6: 中钨高新 | K6: 968.7815 | L6: 43.73 | M6: 600549.SH | N6: 厦门钨业 | O6: 921.4659 | P6: 41.6 | Q6: 002378.SZ | R6: 章源钨业 | S6: 208.0448 | T6: 9.39 | U6: 002842.SZ | V6: 翔鹭钨业 | W6: 116.8404 | X6: 5.27
A7: CI005460.CI | B7: 3C设备指数 | C7: 7 | D7: =IFERROR((thsiFinD("ths_close_price_index",$A7,$AE$2,"","")/thsiFinD("ths_close_price_index",$A7,$AE$5,"","")-1)*100,"") | E7: =IFERROR((thsiFinD("ths_close_price_index",$A7,$AE$2,"","")/thsiFinD("ths_close_price_index",$A7,$AE$3,"","")-1)*100,"") | F7: =IFERROR((thsiFinD("ths_close_price_index",$A7,$AE$2,"","")/thsiFinD("ths_close_price_index",$A7,$AE$4,"","")-1)*100,"") | G7: =IFERROR(E7/5-F7/20,"") | H7: 91.95 | I7: 300567.SZ | J7: 精测电子 | K7: 424.6134 | L7: 44.43 | M7: 688559.SH | N7: 海目星 | O7: 141.7375 | P7: 14.83 | Q7: 301128.SZ | R7: 强瑞技术 | S7: 128.0478 | T7: 13.4 | U7: 688378.SH | V7: 奥来德 | W7: 100.2312 | X7: 10.49 | Y7: 301338.SZ | Z7: 凯格精机 | AA7: 84.0691 | AB7: 8.8
A8: CI005555.CI | B8: 网络接配及塔设指数 | C8: 19 | D8: =IFERROR((thsiFinD("ths_close_price_index",$A8,$AE$2,"","")/thsiFinD("ths_close_price_index",$A8,$AE$5,"","")-1)*100,"") | E8: =IFERROR((thsiFinD("ths_close_price_index",$A8,$AE$2,"","")/thsiFinD("ths_close_price_index",$A8,$AE$3,"","")-1)*100,"") | F8: =IFERROR((thsiFinD("ths_close_price_index",$A8,$AE$2,"","")/thsiFinD("ths_close_price_index",$A8,$AE$4,"","")-1)*100,"") | G8: =IFERROR(E8/5-F8/20,"") | H8: 91.95 | I8: 300308.SZ | J8: 中际旭创 | K8: 11411 | L8: 45.4 | M8: 300502.SZ | N8: 新易盛 | O8: 7004.6458 | P8: 27.87 | Q8: 300394.SZ | R8: 天孚通信 | S8: 1968.3028 | T8: 7.83 | U8: 000988.SZ | V8: 华工科技 | W8: 1421.7092 | X8: 5.66 | Y8: 002281.SZ | Z8: 光迅科技 | AA8: 1303.2598 | AB8: 5.19
A9: CI005540.CI | B9: 半导体材料指数 | C9: 22 | D9: =IFERROR((thsiFinD("ths_close_price_index",$A9,$AE$2,"","")/thsiFinD("ths_close_price_index",$A9,$AE$5,"","")-1)*100,"") | E9: =IFERROR((thsiFinD("ths_close_price_index",$A9,$AE$2,"","")/thsiFinD("ths_close_price_index",$A9,$AE$3,"","")-1)*100,"") | F9: =IFERROR((thsiFinD("ths_close_price_index",$A9,$AE$2,"","")/thsiFinD("ths_close_price_index",$A9,$AE$4,"","")-1)*100,"") | G9: =IFERROR(E9/5-F9/20,"") | H9: 54.76 | I9: 300666.SZ | J9: 江丰电子 | K9: 638.8789 | L9: 13.21 | M9: 688126.SH | N9: 沪硅产业 | O9: 600.2852 | P9: 12.41 | Q9: 688146.SH | R9: 中船特气 | S9: 565.3718 | T9: 11.69 | U9: 002409.SZ | V9: 雅克科技 | W9: 439.4687 | X9: 9.09 | Y9: 300346.SZ | Z9: 南大光电 | AA9: 404.2595 | AB9: 8.36
A10: CI005542.CI | B10: PCB指数 | C10: 39 | D10: =IFERROR((thsiFinD("ths_close_price_index",$A10,$AE$2,"","")/thsiFinD("ths_close_price_index",$A10,$AE$5,"","")-1)*100,"") | E10: =IFERROR((thsiFinD("ths_close_price_index",$A10,$AE$2,"","")/thsiFinD("ths_close_price_index",$A10,$AE$3,"","")-1)*100,"") | F10: =IFERROR((thsiFinD("ths_close_price_index",$A10,$AE$2,"","")/thsiFinD("ths_close_price_index",$A10,$AE$4,"","")-1)*100,"") | G10: =IFERROR(E10/5-F10/20,"") | H10: 64.38 | I10: 600183.SH | J10: 生益科技 | K10: 2229.5813 | L10: 17.53 | M10: 300476.SZ | N10: 胜宏科技 | O10: 2188.4747 | P10: 17.21 | Q10: 002463.SZ | R10: 沪电股份 | S10: 1909.4257 | T10: 15.01 | U10: 002916.SZ | V10: 深南电路 | W10: 1081.6468 | X10: 8.51 | Y10: 002436.SZ | Z10: 兴森科技 | AA10: 777.8148 | AB10: 6.12
A11: CI005541.CI | B11: 半导体设备指数 | C11: 29 | D11: =IFERROR((thsiFinD("ths_close_price_index",$A11,$AE$2,"","")/thsiFinD("ths_close_price_index",$A11,$AE$5,"","")-1)*100,"") | E11: =IFERROR((thsiFinD("ths_close_price_index",$A11,$AE$2,"","")/thsiFinD("ths_close_price_index",$A11,$AE$3,"","")-1)*100,"") | F11: =IFERROR((thsiFinD("ths_close_price_index",$A11,$AE$2,"","")/thsiFinD("ths_close_price_index",$A11,$AE$4,"","")-1)*100,"") | G11: =IFERROR(E11/5-F11/20,"") | H11: 71.44 | I11: 002371.SZ | J11: 北方华创 | K11: 3209.173 | L11: 24.23 | M11: 688012.SH | N11: 中微公司 | O11: 2697.3147 | P11: 20.37 | Q11: 688072.SH | R11: 拓荆科技 | S11: 1518.2949 | T11: 11.47 | U11: 300604.SZ | V11: 长川科技 | W11: 1199.3993 | X11: 9.06 | Y11: 688120.SH | Z11: 华海清科 | AA11: 835.7473 | AB11: 6.31
A12: CI005425.CI | B12: 电子化学品指数 | C12: 24 | D12: =IFERROR((thsiFinD("ths_close_price_index",$A12,$AE$2,"","")/thsiFinD("ths_close_price_index",$A12,$AE$5,"","")-1)*100,"") | E12: =IFERROR((thsiFinD("ths_close_price_index",$A12,$AE$2,"","")/thsiFinD("ths_close_price_index",$A12,$AE$3,"","")-1)*100,"") | F12: =IFERROR((thsiFinD("ths_close_price_index",$A12,$AE$2,"","")/thsiFinD("ths_close_price_index",$A12,$AE$4,"","")-1)*100,"") | G12: =IFERROR(E12/5-F12/20,"") | H12: 61.38 | I12: 300285.SZ | J12: 国瓷材料 | K12: 806.4518 | L12: 21.74 | M12: 300054.SZ | N12: 鼎龙股份 | O12: 615.6881 | P12: 16.6 | Q12: 688019.SH | R12: 安集科技 | S12: 412.0659 | T12: 11.11 | U12: 300236.SZ | V12: 上海新阳 | W12: 227.5715 | X12: 6.14 | Y12: 300398.SZ | Z12: 飞凯材料 | AA12: 214.6571 | AB12: 5.79
A13: CI005414.CI | B13: 碳纤维指数 | C13: 2 | D13: =IFERROR((thsiFinD("ths_close_price_index",$A13,$AE$2,"","")/thsiFinD("ths_close_price_index",$A13,$AE$5,"","")-1)*100,"") | E13: =IFERROR((thsiFinD("ths_close_price_index",$A13,$AE$2,"","")/thsiFinD("ths_close_price_index",$A13,$AE$3,"","")-1)*100,"") | F13: =IFERROR((thsiFinD("ths_close_price_index",$A13,$AE$2,"","")/thsiFinD("ths_close_price_index",$A13,$AE$4,"","")-1)*100,"") | G13: =IFERROR(E13/5-F13/20,"") | H13: 100 | I13: 688598.SH | J13: 金博股份 | K13: 111.1097 | L13: 56.73 | M13: 688295.SH | N13: 中复神鹰 | O13: 84.7332 | P13: 43.27
A14: CI005417.CI | B14: 无机盐指数 | C14: 8 | D14: =IFERROR((thsiFinD("ths_close_price_index",$A14,$AE$2,"","")/thsiFinD("ths_close_price_index",$A14,$AE$5,"","")-1)*100,"") | E14: =IFERROR((thsiFinD("ths_close_price_index",$A14,$AE$2,"","")/thsiFinD("ths_close_price_index",$A14,$AE$3,"","")-1)*100,"") | F14: =IFERROR((thsiFinD("ths_close_price_index",$A14,$AE$2,"","")/thsiFinD("ths_close_price_index",$A14,$AE$4,"","")-1)*100,"") | G14: =IFERROR(E14/5-F14/20,"") | H14: 97.5 | I14: 603067.SH | J14: 振华股份 | K14: 194.812 | L14: 32.8 | M14: 603663.SH | N14: 三祥新材 | O14: 174.5543 | P14: 29.39 | Q14: 600367.SH | R14: 红星发展 | S14: 134.9588 | T14: 22.72 | U14: 600714.SH | V14: 金瑞矿业 | W14: 47.1118 | X14: 7.93 | Y14: 603299.SH | Z14: 苏盐井神 | AA14: 27.6876 | AB14: 4.66
A15: CI005428.CI | B15: 膜材料指数 | C15: 22 | D15: =IFERROR((thsiFinD("ths_close_price_index",$A15,$AE$2,"","")/thsiFinD("ths_close_price_index",$A15,$AE$5,"","")-1)*100,"") | E15: =IFERROR((thsiFinD("ths_close_price_index",$A15,$AE$2,"","")/thsiFinD("ths_close_price_index",$A15,$AE$3,"","")-1)*100,"") | F15: =IFERROR((thsiFinD("ths_close_price_index",$A15,$AE$2,"","")/thsiFinD("ths_close_price_index",$A15,$AE$4,"","")-1)*100,"") | G15: =IFERROR(E15/5-F15/20,"") | H15: 98.75 | I15: 601208.SH | J15: 东材科技 | K15: 615.3608 | L15: 69.24 | M15: 002585.SZ | N15: 双星新材 | O15: 99.3182 | P15: 11.18 | Q15: 000859.SZ | R15: 国风新材 | S15: 71.5739 | T15: 8.05 | U15: 002263.SZ | V15: 大东南 | W15: 60.2613 | X15: 6.78 | Y15: 000920.SZ | Z15: 沃顿科技 | AA15: 31.1409 | AB15: 3.5
A16: CI005547.CI | B16: 显示零组指数 | C16: 28 | D16: =IFERROR((thsiFinD("ths_close_price_index",$A16,$AE$2,"","")/thsiFinD("ths_close_price_index",$A16,$AE$5,"","")-1)*100,"") | E16: =IFERROR((thsiFinD("ths_close_price_index",$A16,$AE$2,"","")/thsiFinD("ths_close_price_index",$A16,$AE$3,"","")-1)*100,"") | F16: =IFERROR((thsiFinD("ths_close_price_index",$A16,$AE$2,"","")/thsiFinD("ths_close_price_index",$A16,$AE$4,"","")-1)*100,"") | G16: =IFERROR(E16/5-F16/20,"") | H16: 58.15 | I16: 603629.SH | J16: 利通电子 | K16: 274.0956 | L16: 15.21 | M16: 603773.SH | N16: 沃格光电 | O16: 259.3009 | P16: 14.39 | Q16: 300088.SZ | R16: 长信科技 | S16: 230.0351 | T16: 12.77 | U16: 688127.SH | V16: 蓝特光学 | W16: 175.6906 | X16: 9.75 | Y16: 688150.SH | Z16: 莱特光电 | AA16: 108.5704 | AB16: 6.03
A17: CI005538.CI | B17: 集成电路指数 | C17: 110 | D17: =IFERROR((thsiFinD("ths_close_price_index",$A17,$AE$2,"","")/thsiFinD("ths_close_price_index",$A17,$AE$5,"","")-1)*100,"") | E17: =IFERROR((thsiFinD("ths_close_price_index",$A17,$AE$2,"","")/thsiFinD("ths_close_price_index",$A17,$AE$3,"","")-1)*100,"") | F17: =IFERROR((thsiFinD("ths_close_price_index",$A17,$AE$2,"","")/thsiFinD("ths_close_price_index",$A17,$AE$4,"","")-1)*100,"") | G17: =IFERROR(E17/5-F17/20,"") | H17: 49.59 | I17: 688256.SH | J17: 寒武纪 | K17: 4468.3271 | L17: 12.66 | M17: 603986.SH | N17: 兆易创新 | O17: 4272.3406 | P17: 12.11 | Q17: 688008.SH | R17: 澜起科技 | S17: 3012.5987 | T17: 8.54 | U17: 688041.SH | V17: 海光信息 | W17: 2939.7339 | X17: 8.33 | Y17: 688981.SH | Z17: 中芯国际 | AA17: 2805.6528 | AB17: 7.95
A18: CI005550.CI | B18: 其他电子零组件Ⅲ指数 | C18: 85 | D18: =IFERROR((thsiFinD("ths_close_price_index",$A18,$AE$2,"","")/thsiFinD("ths_close_price_index",$A18,$AE$5,"","")-1)*100,"") | E18: =IFERROR((thsiFinD("ths_close_price_index",$A18,$AE$2,"","")/thsiFinD("ths_close_price_index",$A18,$AE$3,"","")-1)*100,"") | F18: =IFERROR((thsiFinD("ths_close_price_index",$A18,$AE$2,"","")/thsiFinD("ths_close_price_index",$A18,$AE$4,"","")-1)*100,"") | G18: =IFERROR(E18/5-F18/20,"") | H18: 41.56 | I18: 300475.SZ | J18: 香农芯创 | K18: 1090.3851 | L18: 15.74 | M18: 301511.SZ | N18: 德福科技 | O18: 574.4754 | P18: 8.29 | Q18: 301217.SZ | R18: 铜冠铜箔 | S18: 450.0155 | T18: 6.49 | U18: 688167.SH | V18: 炬光科技 | W18: 421.1647 | X18: 6.08 | Y18: 003031.SZ | Z18: 中瓷电子 | AA18: 343.7429 | AB18: 4.96
A19: CI005457.CI | B19: 油气装备指数 | C19: 13 | D19: =IFERROR((thsiFinD("ths_close_price_index",$A19,$AE$2,"","")/thsiFinD("ths_close_price_index",$A19,$AE$5,"","")-1)*100,"") | E19: =IFERROR((thsiFinD("ths_close_price_index",$A19,$AE$2,"","")/thsiFinD("ths_close_price_index",$A19,$AE$3,"","")-1)*100,"") | F19: =IFERROR((thsiFinD("ths_close_price_index",$A19,$AE$2,"","")/thsiFinD("ths_close_price_index",$A19,$AE$4,"","")-1)*100,"") | G19: =IFERROR(E19/5-F19/20,"") | H19: 87.51 | I19: 002353.SZ | J19: 杰瑞股份 | K19: 997.6909 | L19: 75.23 | M19: 300164.SZ | N19: 通源石油 | O19: 47.1856 | P19: 3.56 | Q19: 300228.SZ | R19: 富瑞特装 | S19: 42.0129 | T19: 3.17 | U19: 300084.SZ | V19: 海默科技 | W19: 37.3796 | X19: 2.82 | Y19: 688377.SH | Z19: 迪威尔 | AA19: 36.2419 | AB19: 2.73
A20: CI005403.CI | B20: 其他稀有金属指数 | C20: 15 | D20: =IFERROR((thsiFinD("ths_close_price_index",$A20,$AE$2,"","")/thsiFinD("ths_close_price_index",$A20,$AE$5,"","")-1)*100,"") | E20: =IFERROR((thsiFinD("ths_close_price_index",$A20,$AE$2,"","")/thsiFinD("ths_close_price_index",$A20,$AE$3,"","")-1)*100,"") | F20: =IFERROR((thsiFinD("ths_close_price_index",$A20,$AE$2,"","")/thsiFinD("ths_close_price_index",$A20,$AE$4,"","")-1)*100,"") | G20: =IFERROR(E20/5-F20/20,"") | H20: 62.93 | I20: 002428.SZ | J20: 云南锗业 | K20: 577.1224 | L20: 25.38 | M20: 601958.SH | N20: 金钼股份 | O20: 271.7766 | P20: 11.95 | Q20: 000962.SZ | R20: 东方钽业 | S20: 205.7112 | T20: 9.05 | U20: 002716.SZ | V20: 湖南白银 | W20: 193.087 | X20: 8.49 | Y20: 002149.SZ | Z20: 西部材料 | AA20: 183.306 | AB20: 8.06
A21: CI005539.CI | B21: 分立器件指数 | C21: 16 | D21: =IFERROR((thsiFinD("ths_close_price_index",$A21,$AE$2,"","")/thsiFinD("ths_close_price_index",$A21,$AE$5,"","")-1)*100,"") | E21: =IFERROR((thsiFinD("ths_close_price_index",$A21,$AE$2,"","")/thsiFinD("ths_close_price_index",$A21,$AE$3,"","")-1)*100,"") | F21: =IFERROR((thsiFinD("ths_close_price_index",$A21,$AE$2,"","")/thsiFinD("ths_close_price_index",$A21,$AE$4,"","")-1)*100,"") | G21: =IFERROR(E21/5-F21/20,"") | H21: 67.2 | I21: 600460.SH | J21: 士兰微 | K21: 493.4561 | L21: 20.19 | M21: 688172.SH | N21: 燕东微 | O21: 371.7856 | P21: 15.21 | Q21: 300373.SZ | R21: 扬杰科技 | S21: 356.7835 | T21: 14.6 | U21: 605111.SH | V21: 新洁能 | W21: 236.6472 | X21: 9.68 | Y21: 300623.SZ | Z21: 捷捷微电 | AA21: 183.7881 | AB21: 7.52
A22: CI005548.CI | B22: 消费电子组件指数 | C22: 91 | D22: =IFERROR((thsiFinD("ths_close_price_index",$A22,$AE$2,"","")/thsiFinD("ths_close_price_index",$A22,$AE$5,"","")-1)*100,"") | E22: =IFERROR((thsiFinD("ths_close_price_index",$A22,$AE$2,"","")/thsiFinD("ths_close_price_index",$A22,$AE$3,"","")-1)*100,"") | F22: =IFERROR((thsiFinD("ths_close_price_index",$A22,$AE$2,"","")/thsiFinD("ths_close_price_index",$A22,$AE$4,"","")-1)*100,"") | G22: =IFERROR(E22/5-F22/20,"") | H22: 60.15 | I22: 002384.SZ | J22: 东山精密 | K22: 3304.4222 | L22: 21.57 | M22: 002475.SZ | N22: 立讯精密 | O22: 3103.8119 | P22: 20.26 | Q22: 300857.SZ | R22: 协创数据 | S22: 1021.0415 | T22: 6.67 | U22: 300433.SZ | V22: 蓝思科技 | W22: 1012.201 | X22: 6.61 | Y22: 002938.SZ | Z22: 鹏鼎控股 | AA22: 771.4252 | AB22: 5.04
A23: CI005292.CI | B23: 卡车指数 | C23: 8 | D23: =IFERROR((thsiFinD("ths_close_price_index",$A23,$AE$2,"","")/thsiFinD("ths_close_price_index",$A23,$AE$5,"","")-1)*100,"") | E23: =IFERROR((thsiFinD("ths_close_price_index",$A23,$AE$2,"","")/thsiFinD("ths_close_price_index",$A23,$AE$3,"","")-1)*100,"") | F23: =IFERROR((thsiFinD("ths_close_price_index",$A23,$AE$2,"","")/thsiFinD("ths_close_price_index",$A23,$AE$4,"","")-1)*100,"") | G23: =IFERROR(E23/5-F23/20,"") | H23: 93.99 | I23: 000338.SZ | J23: 潍柴动力 | K23: 1525.8845 | L23: 75.12 | M23: 600166.SH | N23: 福田汽车 | O23: 140.3812 | P23: 6.91 | Q23: 000951.SZ | R23: 中国重汽 | S23: 124.8397 | T23: 6.15 | U23: 000800.SZ | V23: 一汽解放 | W23: 66.0473 | X23: 3.25 | Y23: 301039.SZ | Z23: 中集车辆 | AA23: 52.0545 | AB23: 2.56
A24: CI005294.CI | B24: 专用汽车指数 | C24: 3 | D24: =IFERROR((thsiFinD("ths_close_price_index",$A24,$AE$2,"","")/thsiFinD("ths_close_price_index",$A24,$AE$5,"","")-1)*100,"") | E24: =IFERROR((thsiFinD("ths_close_price_index",$A24,$AE$2,"","")/thsiFinD("ths_close_price_index",$A24,$AE$3,"","")-1)*100,"") | F24: =IFERROR((thsiFinD("ths_close_price_index",$A24,$AE$2,"","")/thsiFinD("ths_close_price_index",$A24,$AE$4,"","")-1)*100,"") | G24: =IFERROR(E24/5-F24/20,"") | H24: 100 | I24: 601965.SH | J24: 中国汽研 | K24: 46.6219 | L24: 61.68 | M24: 603611.SH | N24: 诺力股份 | O24: 28.9697 | P24: 38.32
A25: CI005471.CI | B25: 仪器仪表Ⅲ指数 | C25: 68 | D25: =IFERROR((thsiFinD("ths_close_price_index",$A25,$AE$2,"","")/thsiFinD("ths_close_price_index",$A25,$AE$5,"","")-1)*100,"") | E25: =IFERROR((thsiFinD("ths_close_price_index",$A25,$AE$2,"","")/thsiFinD("ths_close_price_index",$A25,$AE$3,"","")-1)*100,"") | F25: =IFERROR((thsiFinD("ths_close_price_index",$A25,$AE$2,"","")/thsiFinD("ths_close_price_index",$A25,$AE$4,"","")-1)*100,"") | G25: =IFERROR(E25/5-F25/20,"") | H25: 88.2 | I25: 688808.SH | J25: 联讯仪器 | K25: 479.3162 | L25: 30.34 | M25: 688627.SH | N25: 精智达 | O25: 410.3143 | P25: 25.97 | Q25: 300012.SZ | R25: 华测检测 | S25: 199.7876 | T25: 12.65 | U25: 688531.SH | V25: 日联科技 | W25: 187.2937 | X25: 11.85 | Y25: 301013.SZ | Z25: 利和兴 | AA25: 116.7139 | AB25: 7.39
A26: CI005393.CI | B26: 体育及户外品牌指数 | C26: 4 | D26: =IFERROR((thsiFinD("ths_close_price_index",$A26,$AE$2,"","")/thsiFinD("ths_close_price_index",$A26,$AE$5,"","")-1)*100,"") | E26: =IFERROR((thsiFinD("ths_close_price_index",$A26,$AE$2,"","")/thsiFinD("ths_close_price_index",$A26,$AE$3,"","")-1)*100,"") | F26: =IFERROR((thsiFinD("ths_close_price_index",$A26,$AE$2,"","")/thsiFinD("ths_close_price_index",$A26,$AE$4,"","")-1)*100,"") | G26: =IFERROR(E26/5-F26/20,"") | H26: 100 | I26: 300005.SZ | J26: 探路者 | K26: 126.1021 | L26: 58.27 | M26: 002832.SZ | N26: 比音勒芬 | O26: 67.8096 | P26: 31.34 | Q26: 002780.SZ | R26: 三夫户外 | S26: 15.7304 | T26: 7.27 | U26: 603908.SH | V26: 牧高笛 | W26: 6.756 | X26: 3.12
A27: CI005423.CI | B27: 其他化学制品Ⅲ指数 | C27: 90 | D27: =IFERROR((thsiFinD("ths_close_price_index",$A27,$AE$2,"","")/thsiFinD("ths_close_price_index",$A27,$AE$5,"","")-1)*100,"") | E27: =IFERROR((thsiFinD("ths_close_price_index",$A27,$AE$2,"","")/thsiFinD("ths_close_price_index",$A27,$AE$3,"","")-1)*100,"") | F27: =IFERROR((thsiFinD("ths_close_price_index",$A27,$AE$2,"","")/thsiFinD("ths_close_price_index",$A27,$AE$4,"","")-1)*100,"") | G27: =IFERROR(E27/5-F27/20,"") | H27: 33.9 | I27: 603256.SH | J27: 宏和科技 | K27: 370.056 | L27: 10.94 | M27: 688548.SH | N27: 广钢气体 | O27: 265.286 | P27: 7.84 | Q27: 688503.SH | R27: 聚和材料 | S27: 192.5607 | T27: 5.69 | U27: 002326.SZ | V27: 永太科技 | W27: 161.0454 | X27: 4.76 | Y27: 688065.SH | Z27: 凯赛生物 | AA27: 157.907 | AB27: 4.67
A28: CI005459.CI | B28: 光伏设备指数 | C28: 10 | D28: =IFERROR((thsiFinD("ths_close_price_index",$A28,$AE$2,"","")/thsiFinD("ths_close_price_index",$A28,$AE$5,"","")-1)*100,"") | E28: =IFERROR((thsiFinD("ths_close_price_index",$A28,$AE$2,"","")/thsiFinD("ths_close_price_index",$A28,$AE$3,"","")-1)*100,"") | F28: =IFERROR((thsiFinD("ths_close_price_index",$A28,$AE$2,"","")/thsiFinD("ths_close_price_index",$A28,$AE$4,"","")-1)*100,"") | G28: =IFERROR(E28/5-F28/20,"") | H28: 89.26 | I28: 300316.SZ | J28: 晶盛机电 | K28: 338.2777 | L28: 27.71 | M28: 300751.SZ | N28: 迈为股份 | O28: 335.581 | P28: 27.48 | Q28: 300724.SZ | R28: 捷佳伟创 | S28: 188.9181 | T28: 15.47 | U28: 688726.SH | V28: 拉普拉斯 | W28: 124.7192 | X28: 10.21 | Y28: 688516.SH | Z28: 奥特维 | AA28: 102.3983 | AB28: 8.39
A29: CI005397.CI | B29: 工程服务指数 | C29: 6 | D29: =IFERROR((thsiFinD("ths_close_price_index",$A29,$AE$2,"","")/thsiFinD("ths_close_price_index",$A29,$AE$5,"","")-1)*100,"") | E29: =IFERROR((thsiFinD("ths_close_price_index",$A29,$AE$2,"","")/thsiFinD("ths_close_price_index",$A29,$AE$3,"","")-1)*100,"") | F29: =IFERROR((thsiFinD("ths_close_price_index",$A29,$AE$2,"","")/thsiFinD("ths_close_price_index",$A29,$AE$4,"","")-1)*100,"") | G29: =IFERROR(E29/5-F29/20,"") | H29: 96.86 | I29: 600378.SH | J29: 昊华科技 | K29: 335.8868 | L29: 54.76 | M29: 600583.SH | N29: 海油工程 | O29: 107.696 | P29: 17.56 | Q29: 600968.SH | R29: 海油发展 | S29: 71.4335 | T29: 11.65 | U29: 600339.SH | V29: 中油工程 | W29: 52.7741 | X29: 8.6 | Y29: 603727.SH | Z29: 博迈科 | AA29: 26.2897 | AB29: 4.29
A30: CI005455.CI | B30: 纺织服装机械指数 | C30: 8 | D30: =IFERROR((thsiFinD("ths_close_price_index",$A30,$AE$2,"","")/thsiFinD("ths_close_price_index",$A30,$AE$5,"","")-1)*100,"") | E30: =IFERROR((thsiFinD("ths_close_price_index",$A30,$AE$2,"","")/thsiFinD("ths_close_price_index",$A30,$AE$3,"","")-1)*100,"") | F30: =IFERROR((thsiFinD("ths_close_price_index",$A30,$AE$2,"","")/thsiFinD("ths_close_price_index",$A30,$AE$4,"","")-1)*100,"") | G30: =IFERROR(E30/5-F30/20,"") | H30: 83.72 | I30: 600545.SH | J30: 卓郎智能 | K30: 70.8293 | L30: 21.7 | M30: 603337.SH | N30: 杰克科技 | O30: 66.477 | P30: 20.37 | Q30: 003036.SZ | R30: 泰坦股份 | S30: 65.7532 | T30: 20.15 | U30: 300307.SZ | V30: 慈星股份 | W30: 41.81 | X30: 12.81 | Y30: 600843.SH | Z30: 上工申贝 | AA30: 28.3785 | AB30: 8.69
A31: CI005546.CI | B31: 面板指数 | C31: 12 | D31: =IFERROR((thsiFinD("ths_close_price_index",$A31,$AE$2,"","")/thsiFinD("ths_close_price_index",$A31,$AE$5,"","")-1)*100,"") | E31: =IFERROR((thsiFinD("ths_close_price_index",$A31,$AE$2,"","")/thsiFinD("ths_close_price_index",$A31,$AE$3,"","")-1)*100,"") | F31: =IFERROR((thsiFinD("ths_close_price_index",$A31,$AE$2,"","")/thsiFinD("ths_close_price_index",$A31,$AE$4,"","")-1)*100,"") | G31: =IFERROR(E31/5-F31/20,"") | H31: 95.92 | I31: 000725.SZ | J31: 京东方A | K31: 2150.3835 | L31: 59.43 | M31: 000100.SZ | N31: TCL科技 | O31: 925.1556 | P31: 25.57 | Q31: 600707.SH | R31: 彩虹股份 | S31: 164.1556 | T31: 4.54 | U31: 000050.SZ | V31: 深天马A | W31: 126.8056 | X31: 3.5 | Y31: 688538.SH | Z31: 和辉光电 | AA31: 104.1695 | AB31: 2.88
A32: CI005399.CI | B32: 稀土及磁性材料指数 | C32: 17 | D32: =IFERROR((thsiFinD("ths_close_price_index",$A32,$AE$2,"","")/thsiFinD("ths_close_price_index",$A32,$AE$5,"","")-1)*100,"") | E32: =IFERROR((thsiFinD("ths_close_price_index",$A32,$AE$2,"","")/thsiFinD("ths_close_price_index",$A32,$AE$3,"","")-1)*100,"") | F32: =IFERROR((thsiFinD("ths_close_price_index",$A32,$AE$2,"","")/thsiFinD("ths_close_price_index",$A32,$AE$4,"","")-1)*100,"") | G32: =IFERROR(E32/5-F32/20,"") | H32: 73.56 | I32: 600111.SH | J32: 北方稀土 | K32: 1213.1041 | L32: 33.17 | M32: 600392.SH | N32: 盛和资源 | O32: 450.4411 | P32: 12.32 | Q32: 000831.SZ | R32: 中国稀土 | S32: 435.9712 | T32: 11.92 | U32: 600330.SH | V32: 天通股份 | W32: 344.7228 | X32: 9.43 | Y32: 600259.SH | Z32: 中稀有色 | AA32: 245.7014 | AB32: 6.72
A33: CI005442.CI | B33: 其他专用材料指数 | C33: 13 | D33: =IFERROR((thsiFinD("ths_close_price_index",$A33,$AE$2,"","")/thsiFinD("ths_close_price_index",$A33,$AE$5,"","")-1)*100,"") | E33: =IFERROR((thsiFinD("ths_close_price_index",$A33,$AE$2,"","")/thsiFinD("ths_close_price_index",$A33,$AE$3,"","")-1)*100,"") | F33: =IFERROR((thsiFinD("ths_close_price_index",$A33,$AE$2,"","")/thsiFinD("ths_close_price_index",$A33,$AE$4,"","")-1)*100,"") | G33: =IFERROR(E33/5-F33/20,"") | H33: 69.09 | I33: 300179.SZ | J33: 四方达 | K33: 173.6464 | L33: 34.87 | M33: 002392.SZ | N33: 北京利尔 | O33: 72.5882 | P33: 14.58 | Q33: 002225.SZ | R33: 濮耐股份 | S33: 36.2324 | T33: 7.28 | U33: 300234.SZ | V33: 开尔新材 | W33: 31.796 | X33: 6.38 | Y33: 002066.SZ | Z33: 瑞泰科技 | AA33: 29.8042 | AB33: 5.98
A34: CI005427.CI | B34: 合成树脂指数 | C34: 13 | D34: =IFERROR((thsiFinD("ths_close_price_index",$A34,$AE$2,"","")/thsiFinD("ths_close_price_index",$A34,$AE$5,"","")-1)*100,"") | E34: =IFERROR((thsiFinD("ths_close_price_index",$A34,$AE$2,"","")/thsiFinD("ths_close_price_index",$A34,$AE$3,"","")-1)*100,"") | F34: =IFERROR((thsiFinD("ths_close_price_index",$A34,$AE$2,"","")/thsiFinD("ths_close_price_index",$A34,$AE$4,"","")-1)*100,"") | G34: =IFERROR(E34/5-F34/20,"") | H34: 91.16 | I34: 600989.SH | J34: 宝丰能源 | K34: 470.7047 | L34: 32.97 | M34: 605589.SH | N34: 圣泉集团 | O34: 464.0994 | P34: 32.51 | Q34: 300487.SZ | R34: 蓝晓科技 | S34: 156.0118 | T34: 10.93 | U34: 688585.SH | V34: 上纬新材 | W34: 107.4035 | X34: 7.52 | Y34: 002361.SZ | Z34: 神剑股份 | AA34: 103.208 | AB34: 7.23
A35: CI005465.CI | B35: 其他通用机械指数 | C35: 48 | D35: =IFERROR((thsiFinD("ths_close_price_index",$A35,$AE$2,"","")/thsiFinD("ths_close_price_index",$A35,$AE$5,"","")-1)*100,"") | E35: =IFERROR((thsiFinD("ths_close_price_index",$A35,$AE$2,"","")/thsiFinD("ths_close_price_index",$A35,$AE$3,"","")-1)*100,"") | F35: =IFERROR((thsiFinD("ths_close_price_index",$A35,$AE$2,"","")/thsiFinD("ths_close_price_index",$A35,$AE$4,"","")-1)*100,"") | G35: =IFERROR(E35/5-F35/20,"") | H35: 63.76 | I35: 688017.SH | J35: 绿的谐波 | K35: 471.6212 | L35: 23.43 | M35: 688308.SH | N35: 欧科亿 | O35: 241.4085 | P35: 11.99 | Q35: 688333.SH | R35: 铂力特 | S35: 206.3582 | T35: 10.25 | U35: 002444.SZ | V35: 巨星科技 | W35: 196.6358 | X35: 9.77 | Y35: 001696.SZ | Z35: 宗申动力 | AA35: 167.5844 | AB35: 8.32
A36: CI005422.CI | B36: 橡胶助剂指数 | C36: 5 | D36: =IFERROR((thsiFinD("ths_close_price_index",$A36,$AE$2,"","")/thsiFinD("ths_close_price_index",$A36,$AE$5,"","")-1)*100,"") | E36: =IFERROR((thsiFinD("ths_close_price_index",$A36,$AE$2,"","")/thsiFinD("ths_close_price_index",$A36,$AE$3,"","")-1)*100,"") | F36: =IFERROR((thsiFinD("ths_close_price_index",$A36,$AE$2,"","")/thsiFinD("ths_close_price_index",$A36,$AE$4,"","")-1)*100,"") | G36: =IFERROR(E36/5-F36/20,"") | H36: 100 | I36: 603650.SH | J36: 彤程新材 | K36: 165.2254 | L36: 57.1 | M36: 002068.SZ | N36: 黑猫股份 | O36: 53.5358 | P36: 18.5 | Q36: 300121.SZ | R36: 阳谷华泰 | S36: 37.2273 | T36: 12.87 | U36: 002442.SZ | V36: 龙星科技 | W36: 21.0056 | X36: 7.26 | Y36: 002753.SZ | Z36: 永东股份 | AA36: 12.3687 | AB36: 4.27
A37: CI005418.CI | B37: 其他化学原料指数 | C37: 23 | D37: =IFERROR((thsiFinD("ths_close_price_index",$A37,$AE$2,"","")/thsiFinD("ths_close_price_index",$A37,$AE$5,"","")-1)*100,"") | E37: =IFERROR((thsiFinD("ths_close_price_index",$A37,$AE$2,"","")/thsiFinD("ths_close_price_index",$A37,$AE$3,"","")-1)*100,"") | F37: =IFERROR((thsiFinD("ths_close_price_index",$A37,$AE$2,"","")/thsiFinD("ths_close_price_index",$A37,$AE$4,"","")-1)*100,"") | G37: =IFERROR(E37/5-F37/20,"") | H37: 75.44 | I37: 002648.SZ | J37: 卫星化学 | K37: 382.0021 | L37: 31.54 | M37: 688300.SH | N37: 联瑞新材 | O37: 257.3746 | P37: 21.25 | Q37: 002430.SZ | R37: 杭氧股份 | S37: 108.9079 | T37: 8.99 | U37: 003022.SZ | V37: 联泓新科 | W37: 99.1859 | X37: 8.19 | Y37: 002549.SZ | Z37: 凯美特气 | AA37: 66.2993 | AB37: 5.47
A38: CI005480.CI | B38: 燃料电池指数 | C38: 9 | D38: =IFERROR((thsiFinD("ths_close_price_index",$A38,$AE$2,"","")/thsiFinD("ths_close_price_index",$A38,$AE$5,"","")-1)*100,"") | E38: =IFERROR((thsiFinD("ths_close_price_index",$A38,$AE$2,"","")/thsiFinD("ths_close_price_index",$A38,$AE$3,"","")-1)*100,"") | F38: =IFERROR((thsiFinD("ths_close_price_index",$A38,$AE$2,"","")/thsiFinD("ths_close_price_index",$A38,$AE$4,"","")-1)*100,"") | G38: =IFERROR(E38/5-F38/20,"") | H38: 100 | I38: 000811.SZ | J38: 冰轮环境 | K38: 273.7642 | L38: 43.69 | M38: 000969.SZ | N38: 安泰科技 | O38: 178.9266 | P38: 28.55 | Q38: 002639.SZ | R38: 雪人集团 | S38: 88.1494 | T38: 14.07 | U38: 600273.SH | V38: 嘉化能源 | W38: 53.3992 | X38: 8.52 | Y38: 688339.SH | Z38: 亿华通 | AA38: 32.4103 | AB38: 5.17
... A57: CI005545.CI | B57: LED指数 | C57: 26 | D57: =IFERROR((thsiFinD("ths_close_price_index",$A57,$AE$2,"","")/thsiFinD("ths_close_price_index",$A57,$AE$5,"","")-1)*100,"") | E57: =IFERROR((thsiFinD("ths_close_price_index",$A57,$AE$2,"","")/thsiFinD("ths_close_price_index",$A57,$AE$3,"","")-1)*100,"") | F57: =IFERROR((thsiFinD("ths_close_price_index",$A57,$AE$2,"","")/thsiFinD("ths_close_price_index",$A57,$AE$4,"","")-1)*100,"") | G57: =IFERROR(E57/5-F57/20,"") | H57: 81.7 | I57: 600703.SH | J57: 三安光电 | K57: 654.6462 | L57: 56.05 | M57: 300303.SZ | N57: 聚飞光电 | O57: 111.7501 | P57: 9.57 | Q57: 002654.SZ | R57: 万润科技 | S57: 91.4079 | T57: 7.83 | U57: 300102.SZ | V57: 乾照光电 | W57: 54.2 | X57: 4.64 | Y57: 300219.SZ | Z57: 鸿利智汇 | AA57: 42.1244 | AB57: 3.61
A58: CI005509.CI | B58: 儿童品牌指数 | C58: 4 | D58: =IFERROR((thsiFinD("ths_close_price_index",$A58,$AE$2,"","")/thsiFinD("ths_close_price_index",$A58,$AE$5,"","")-1)*100,"") | E58: =IFERROR((thsiFinD("ths_close_price_index",$A58,$AE$2,"","")/thsiFinD("ths_close_price_index",$A58,$AE$3,"","")-1)*100,"") | F58: =IFERROR((thsiFinD("ths_close_price_index",$A58,$AE$2,"","")/thsiFinD("ths_close_price_index",$A58,$AE$4,"","")-1)*100,"") | G58: =IFERROR(E58/5-F58/20,"") | H58: 100.01 | I58: 002875.SZ | J58: 安奈儿 | K58: 22.2813 | L58: 33.87 | M58: 603557.SH | N58: *ST起步 | O58: 19.2024 | P58: 29.19 | Q58: 002762.SZ | R58: 金发拉比 | S58: 13.8462 | T58: 21.05 | U58: 301276.SZ | V58: 嘉曼服饰 | W58: 10.4626 | X58: 15.9
...

Sheet 热点热力图
B1: 中信三级行业指数 · 短期热点热力图
B2: 瓦片按【指数自由流通市值】从大到小、从左上到右下排列(市值大→越靠前越显眼)；颜色按【近一周涨跌幅】红涨绿跌、幅度越大越深。数据随上一页(中信三级行业指数热度)iFinD公式自动刷新。 | AG2: =IFERROR('中信三级行业指数热度'!G2+ROW()*0.0000000001,-9999)
B3: ='中信三级行业指数热度'!B17&CHAR(10)&TEXT('中信三级行业指数热度'!E17,"0.0")&"%" | C3: ='中信三级行业指数热度'!B8&CHAR(10)&TEXT('中信三级行业指数热度'!E8,"0.0")&"%" | D3: ='中信三级行业指数热度'!B176&CHAR(10)&TEXT('中信三级行业指数热度'!E176,"0.0")&"%" | E3: ='中信三级行业指数热度'!B22&CHAR(10)&TEXT('中信三级行业指数热度'!E22,"0.0")&"%" | F3: ='中信三级行业指数热度'!B75&CHAR(10)&TEXT('中信三级行业指数热度'!E75,"0.0")&"%" | G3: ='中信三级行业指数热度'!B11&CHAR(10)&TEXT('中信三级行业指数热度'!E11,"0.0")&"%" | H3: ='中信三级行业指数热度'!B10&CHAR(10)&TEXT('中信三级行业指数热度'!E10,"0.0")&"%" | I3: ='中信三级行业指数热度'!B162&CHAR(10)&TEXT('中信三级行业指数热度'!E162,"0.0")&"%" | J3: ='中信三级行业指数热度'!B212&CHAR(10)&TEXT('中信三级行业指数热度'!E212,"0.0")&"%" | K3: ='中信三级行业指数热度'!B42&CHAR(10)&TEXT('中信三级行业指数热度'!E42,"0.0")&"%" | L3: ='中信三级行业指数热度'!B136&CHAR(10)&TEXT('中信三级行业指数热度'!E136,"0.0")&"%" | M3: ='中信三级行业指数热度'!B244&CHAR(10)&TEXT('中信三级行业指数热度'!E244,"0.0")&"%" | N3: ='中信三级行业指数热度'!B122&CHAR(10)&TEXT('中信三级行业指数热度'!E122,"0.0")&"%" | O3: ='中信三级行业指数热度'!B18&CHAR(10)&TEXT('中信三级行业指数热度'!E18,"0.0")&"%" | R3: ='中信三级行业指数热度'!E17 | S3: ='中信三级行业指数热度'!E8 | T3: ='中信三级行业指数热度'!E176 | U3: ='中信三级行业指数热度'!E22 | V3: ='中信三级行业指数热度'!E75 | W3: ='中信三级行业指数热度'!E11 | X3: ='中信三级行业指数热度'!E10 | Y3: ='中信三级行业指数热度'!E162 | Z3: ='中信三级行业指数热度'!E212 | AA3: ='中信三级行业指数热度'!E42 | AB3: ='中信三级行业指数热度'!E136 | AC3: ='中信三级行业指数热度'!E244 | AD3: ='中信三级行业指数热度'!E122 | AE3: ='中信三级行业指数热度'!E18 | AG3: =IFERROR('中信三级行业指数热度'!G3+ROW()*0.0000000001,-9999)
B4: ='中信三级行业指数热度'!B121&CHAR(10)&TEXT('中信三级行业指数热度'!E121,"0.0")&"%" | C4: ='中信三级行业指数热度'!B2&CHAR(10)&TEXT('中信三级行业指数热度'!E2,"0.0")&"%" | D4: ='中信三级行业指数热度'!B119&CHAR(10)&TEXT('中信三级行业指数热度'!E119,"0.0")&"%" | E4: ='中信三级行业指数热度'!B90&CHAR(10)&TEXT('中信三级行业指数热度'!E90,"0.0")&"%" | F4: ='中信三级行业指数热度'!B107&CHAR(10)&TEXT('中信三级行业指数热度'!E107,"0.0")&"%" | G4: ='中信三级行业指数热度'!B157&CHAR(10)&TEXT('中信三级行业指数热度'!E157,"0.0")&"%" | H4: ='中信三级行业指数热度'!B9&CHAR(10)&TEXT('中信三级行业指数热度'!E9,"0.0")&"%" | I4: ='中信三级行业指数热度'!B139&CHAR(10)&TEXT('中信三级行业指数热度'!E139,"0.0")&"%" | J4: ='中信三级行业指数热度'!B51&CHAR(10)&TEXT('中信三级行业指数热度'!E51,"0.0")&"%" | K4: ='中信三级行业指数热度'!B151&CHAR(10)&TEXT('中信三级行业指数热度'!E151,"0.0")&"%" | L4: ='中信三级行业指数热度'!B3&CHAR(10)&TEXT('中信三级行业指数热度'!E3,"0.0")&"%" | M4: ='中信三级行业指数热度'!B231&CHAR(10)&TEXT('中信三级行业指数热度'!E231,"0.0")&"%" | N4: ='中信三级行业指数热度'!B52&CHAR(10)&TEXT('中信三级行业指数热度'!E52,"0.0")&"%" | O4: ='中信三级行业指数热度'!B179&CHAR(10)&TEXT('中信三级行业指数热度'!E179,"0.0")&"%" | R4: ='中信三级行业指数热度'!E121 | S4: ='中信三级行业指数热度'!E2 | T4: ='中信三级行业指数热度'!E119 | U4: ='中信三级行业指数热度'!E90 | V4: ='中信三级行业指数热度'!E107 | W4: ='中信三级行业指数热度'!E157 | X4: ='中信三级行业指数热度'!E9 | Y4: ='中信三级行业指数热度'!E139 | Z4: ='中信三级行业指数热度'!E51 | AA4: ='中信三级行业指数热度'!E151 | AB4: ='中信三级行业指数热度'!E3 | AC4: ='中信三级行业指数热度'!E231 | AD4: ='中信三级行业指数热度'!E52 | AE4: ='中信三级行业指数热度'!E179 | AG4: =IFERROR('中信三级行业指数热度'!G4+ROW()*0.0000000001,-9999)
B5: ='中信三级行业指数热度'!B246&CHAR(10)&TEXT('中信三级行业指数热度'!E246,"0.0")&"%" | C5: ='中信三级行业指数热度'!B146&CHAR(10)&TEXT('中信三级行业指数热度'!E146,"0.0")&"%" | D5: ='中信三级行业指数热度'!B94&CHAR(10)&TEXT('中信三级行业指数热度'!E94,"0.0")&"%" | E5: ='中信三级行业指数热度'!B12&CHAR(10)&TEXT('中信三级行业指数热度'!E12,"0.0")&"%" | F5: ='中信三级行业指数热度'!B32&CHAR(10)&TEXT('中信三级行业指数热度'!E32,"0.0")&"%" | G5: ='中信三级行业指数热度'!B31&CHAR(10)&TEXT('中信三级行业指数热度'!E31,"0.0")&"%" | H5: ='中信三级行业指数热度'!B49&CHAR(10)&TEXT('中信三级行业指数热度'!E49,"0.0")&"%" | I5: ='中信三级行业指数热度'!B27&CHAR(10)&TEXT('中信三级行业指数热度'!E27,"0.0")&"%" | J5: ='中信三级行业指数热度'!B103&CHAR(10)&TEXT('中信三级行业指数热度'!E103,"0.0")&"%" | K5: ='中信三级行业指数热度'!B79&CHAR(10)&TEXT('中信三级行业指数热度'!E79,"0.0")&"%" | L5: ='中信三级行业指数热度'!B196&CHAR(10)&TEXT('中信三级行业指数热度'!E196,"0.0")&"%" | M5: ='中信三级行业指数热度'!B144&CHAR(10)&TEXT('中信三级行业指数热度'!E144,"0.0")&"%" | N5: ='中信三级行业指数热度'!B59&CHAR(10)&TEXT('中信三级行业指数热度'!E59,"0.0")&"%" | O5: ='中信三级行业指数热度'!B240&CHAR(10)&TEXT('中信三级行业指数热度'!E240,"0.0")&"%" | R5: ='中信三级行业指数热度'!E246 | S5: ='中信三级行业指数热度'!E146 | T5: ='中信三级行业指数热度'!E94 | U5: ='中信三级行业指数热度'!E12 | V5: ='中信三级行业指数热度'!E32 | W5: ='中信三级行业指数热度'!E31 | X5: ='中信三级行业指数热度'!E49 | Y5: ='中信三级行业指数热度'!E27 | Z5: ='中信三级行业指数热度'!E103 | AA5: ='中信三级行业指数热度'!E79 | AB5: ='中信三级行业指数热度'!E196 | AC5: ='中信三级行业指数热度'!E144 | AD5: ='中信三级行业指数热度'!E59 | AE5: ='中信三级行业指数热度'!E240 | AG5: =IFERROR('中信三级行业指数热度'!G5+ROW()*0.0000000001,-9999)
B6: ='中信三级行业指数热度'!B40&CHAR(10)&TEXT('中信三级行业指数热度'!E40,"0.0")&"%" | C6: ='中信三级行业指数热度'!B173&CHAR(10)&TEXT('中信三级行业指数热度'!E173,"0.0")&"%" | D6: ='中信三级行业指数热度'!B91&CHAR(10)&TEXT('中信三级行业指数热度'!E91,"0.0")&"%" | E6: ='中信三级行业指数热度'!B210&CHAR(10)&TEXT('中信三级行业指数热度'!E210,"0.0")&"%" | F6: ='中信三级行业指数热度'!B181&CHAR(10)&TEXT('中信三级行业指数热度'!E181,"0.0")&"%" | G6: ='中信三级行业指数热度'!B152&CHAR(10)&TEXT('中信三级行业指数热度'!E152,"0.0")&"%" | H6: ='中信三级行业指数热度'!B108&CHAR(10)&TEXT('中信三级行业指数热度'!E108,"0.0")&"%" | I6: ='中信三级行业指数热度'!B21&CHAR(10)&TEXT('中信三级行业指数热度'!E21,"0.0")&"%" | J6: ='中信三级行业指数热度'!B189&CHAR(10)&TEXT('中信三级行业指数热度'!E189,"0.0")&"%" | K6: ='中信三级行业指数热度'!B77&CHAR(10)&TEXT('中信三级行业指数热度'!E77,"0.0")&"%" | L6: ='中信三级行业指数热度'!B53&CHAR(10)&TEXT('中信三级行业指数热度'!E53,"0.0")&"%" | M6: ='中信三级行业指数热度'!B20&CHAR(10)&TEXT('中信三级行业指数热度'!E20,"0.0")&"%" | N6: ='中信三级行业指数热度'!B46&CHAR(10)&TEXT('中信三级行业指数热度'!E46,"0.0")&"%" | O6: ='中信三级行业指数热度'!B48&CHAR(10)&TEXT('中信三级行业指数热度'!E48,"0.0")&"%" | R6: ='中信三级行业指数热度'!E40 | S6: ='中信三级行业指数热度'!E173 | T6: ='中信三级行业指数热度'!E91 | U6: ='中信三级行业指数热度'!E210 | V6: ='中信三级行业指数热度'!E181 | W6: ='中信三级行业指数热度'!E152 | X6: ='中信三级行业指数热度'!E108 | Y6: ='中信三级行业指数热度'!E21 | Z6: ='中信三级行业指数热度'!E189 | AA6: ='中信三级行业指数热度'!E77 | AB6: ='中信三级行业指数热度'!E53 | AC6: ='中信三级行业指数热度'!E20 | AD6: ='中信三级行业指数热度'!E46 | AE6: ='中信三级行业指数热度'!E48 | AG6: =IFERROR('中信三级行业指数热度'!G6+ROW()*0.0000000001,-9999)
B7: ='中信三级行业指数热度'!B6&CHAR(10)&TEXT('中信三级行业指数热度'!E6,"0.0")&"%" | C7: ='中信三级行业指数热度'!B47&CHAR(10)&TEXT('中信三级行业指数热度'!E47,"0.0")&"%" | D7: ='中信三级行业指数热度'!B62&CHAR(10)&TEXT('中信三级行业指数热度'!E62,"0.0")&"%" | E7: ='中信三级行业指数热度'!B80&CHAR(10)&TEXT('中信三级行业指数热度'!E80,"0.0")&"%" | F7: ='中信三级行业指数热度'!B5&CHAR(10)&TEXT('中信三级行业指数热度'!E5,"0.0")&"%" | G7: ='中信三级行业指数热度'!B74&CHAR(10)&TEXT('中信三级行业指数热度'!E74,"0.0")&"%" | H7: ='中信三级行业指数热度'!B23&CHAR(10)&TEXT('中信三级行业指数热度'!E23,"0.0")&"%" | I7: ='中信三级行业指数热度'!B35&CHAR(10)&TEXT('中信三级行业指数热度'!E35,"0.0")&"%" | J7: ='中信三级行业指数热度'!B71&CHAR(10)&TEXT('中信三级行业指数热度'!E71,"0.0")&"%" | K7: ='中信三级行业指数热度'!B88&CHAR(10)&TEXT('中信三级行业指数热度'!E88,"0.0")&"%" | L7: ='中信三级行业指数热度'!B4&CHAR(10)&TEXT('中信三级行业指数热度'!E4,"0.0")&"%" | M7: ='中信三级行业指数热度'!B245&CHAR(10)&TEXT('中信三级行业指数热度'!E245,"0.0")&"%" | N7: ='中信三级行业指数热度'!B16&CHAR(10)&TEXT('中信三级行业指数热度'!E16,"0.0")&"%" | O7: ='中信三级行业指数热度'!B66&CHAR(10)&TEXT('中信三级行业指数热度'!E66,"0.0")&"%" | R7: ='中信三级行业指数热度'!E6 | S7: ='中信三级行业指数热度'!E47 | T7: ='中信三级行业指数热度'!E62 | U7: ='中信三级行业指数热度'!E80 | V7: ='中信三级行业指数热度'!E5 | W7: ='中信三级行业指数热度'!E74 | X7: ='中信三级行业指数热度'!E23 | Y7: ='中信三级行业指数热度'!E35 | Z7: ='中信三级行业指数热度'!E71 | AA7: ='中信三级行业指数热度'!E88 | AB7: ='中信三级行业指数热度'!E4 | AC7: ='中信三级行业指数热度'!E245 | AD7: ='中信三级行业指数热度'!E16 | AE7: ='中信三级行业指数热度'!E66 | AG7: =IFERROR('中信三级行业指数热度'!G7+ROW()*0.0000000001,-9999)
B8: ='中信三级行业指数热度'!B184&CHAR(10)&TEXT('中信三级行业指数热度'!E184,"0.0")&"%" | C8: ='中信三级行业指数热度'!B99&CHAR(10)&TEXT('中信三级行业指数热度'!E99,"0.0")&"%" | D8: ='中信三级行业指数热度'!B123&CHAR(10)&TEXT('中信三级行业指数热度'!E123,"0.0")&"%" | E8: ='中信三级行业指数热度'!B142&CHAR(10)&TEXT('中信三级行业指数热度'!E142,"0.0")&"%" | F8: ='中信三级行业指数热度'!B182&CHAR(10)&TEXT('中信三级行业指数热度'!E182,"0.0")&"%" | G8: ='中信三级行业指数热度'!B43&CHAR(10)&TEXT('中信三级行业指数热度'!E43,"0.0")&"%" | H8: ='中信三级行业指数热度'!B67&CHAR(10)&TEXT('中信三级行业指数热度'!E67,"0.0")&"%" | I8: ='中信三级行业指数热度'!B124&CHAR(10)&TEXT('中信三级行业指数热度'!E124,"0.0")&"%" | J8: ='中信三级行业指数热度'!B25&CHAR(10)&TEXT('中信三级行业指数热度'!E25,"0.0")&"%" | K8: ='中信三级行业指数热度'!B56&CHAR(10)&TEXT('中信三级行业指数热度'!E56,"0.0")&"%" | L8: ='中信三级行业指数热度'!B60&CHAR(10)&TEXT('中信三级行业指数热度'!E60,"0.0")&"%" | M8: ='中信三级行业指数热度'!B253&CHAR(10)&TEXT('中信三级行业指数热度'!E253,"0.0")&"%" | N8: ='中信三级行业指数热度'!B140&CHAR(10)&TEXT('中信三级行业指数热度'!E140,"0.0")&"%" | O8: ='中信三级行业指数热度'!B205&CHAR(10)&TEXT('中信三级行业指数热度'!E205,"0.0")&"%" | R8: ='中信三级行业指数热度'!E184 | S8: ='中信三级行业指数热度'!E99 | T8: ='中信三级行业指数热度'!E123 | U8: ='中信三级行业指数热度'!E142 | V8: ='中信三级行业指数热度'!E182 | W8: ='中信三级行业指数热度'!E43 | X8: ='中信三级行业指数热度'!E67 | Y8: ='中信三级行业指数热度'!E124 | Z8: ='中信三级行业指数热度'!E25 | AA8: ='中信三级行业指数热度'!E56 | AB8: ='中信三级行业指数热度'!E60 | AC8: ='中信三级行业指数热度'!E253 | AD8: ='中信三级行业指数热度'!E140 | AE8: ='中信三级行业指数热度'!E205 | AG8: =IFERROR('中信三级行业指数热度'!G8+ROW()*0.0000000001,-9999)
B9: ='中信三级行业指数热度'!B150&CHAR(10)&TEXT('中信三级行业指数热度'!E150,"0.0")&"%" | C9: ='中信三级行业指数热度'!B34&CHAR(10)&TEXT('中信三级行业指数热度'!E34,"0.0")&"%" | D9: ='中信三级行业指数热度'!B137&CHAR(10)&TEXT('中信三级行业指数热度'!E137,"0.0")&"%" | E9: ='中信三级行业指数热度'!B19&CHAR(10)&TEXT('中信三级行业指数热度'!E19,"0.0")&"%" | F9: ='中信三级行业指数热度'!B165&CHAR(10)&TEXT('中信三级行业指数热度'!E165,"0.0")&"%" | G9: ='中信三级行业指数热度'!B82&CHAR(10)&TEXT('中信三级行业指数热度'!E82,"0.0")&"%" | H9: ='中信三级行业指数热度'!B69&CHAR(10)&TEXT('中信三级行业指数热度'!E69,"0.0")&"%" | I9: ='中信三级行业指数热度'!B101&CHAR(10)&TEXT('中信三级行业指数热度'!E101,"0.0")&"%" | J9: ='中信三级行业指数热度'!B28&CHAR(10)&TEXT('中信三级行业指数热度'!E28,"0.0")&"%" | K9: ='中信三级行业指数热度'!B131&CHAR(10)&TEXT('中信三级行业指数热度'!E131,"0.0")&"%" | L9: ='中信三级行业指数热度'!B37&CHAR(10)&TEXT('中信三级行业指数热度'!E37,"0.0")&"%" | M9: ='中信三级行业指数热度'!B61&CHAR(10)&TEXT('中信三级行业指数热度'!E61,"0.0")&"%" | N9: ='中信三级行业指数热度'!B57&CHAR(10)&TEXT('中信三级行业指数热度'!E57,"0.0")&"%" | O9: ='中信三级行业指数热度'!B166&CHAR(10)&TEXT('中信三级行业指数热度'!E166,"0.0")&"%" | R9: ='中信三级行业指数热度'!E150 | S9: ='中信三级行业指数热度'!E34 | T9: ='中信三级行业指数热度'!E137 | U9: ='中信三级行业指数热度'!E19 | V9: ='中信三级行业指数热度'!E165 | W9: ='中信三级行业指数热度'!E82 | X9: ='中信三级行业指数热度'!E69 | Y9: ='中信三级行业指数热度'!E101 | Z9: ='中信三级行业指数热度'!E28 | AA9: ='中信三级行业指数热度'!E131 | AB9: ='中信三级行业指数热度'!E37 | AC9: ='中信三级行业指数热度'!E61 | AD9: ='中信三级行业指数热度'!E57 | AE9: ='中信三级行业指数热度'!E166 | AG9: =IFERROR('中信三级行业指数热度'!G9+ROW()*0.0000000001,-9999)
B10: ='中信三级行业指数热度'!B172&CHAR(10)&TEXT('中信三级行业指数热度'!E172,"0.0")&"%" | C10: ='中信三级行业指数热度'!B158&CHAR(10)&TEXT('中信三级行业指数热度'!E158,"0.0")&"%" | D10: ='中信三级行业指数热度'!B87&CHAR(10)&TEXT('中信三级行业指数热度'!E87,"0.0")&"%" | E10: ='中信三级行业指数热度'!B86&CHAR(10)&TEXT('中信三级行业指数热度'!E86,"0.0")&"%" | F10: ='中信三级行业指数热度'!B147&CHAR(10)&TEXT('中信三级行业指数热度'!E147,"0.0")&"%" | G10: ='中信三级行业指数热度'!B145&CHAR(10)&TEXT('中信三级行业指数热度'!E145,"0.0")&"%" | H10: ='中信三级行业指数热度'!B81&CHAR(10)&TEXT('中信三级行业指数热度'!E81,"0.0")&"%" | I10: ='中信三级行业指数热度'!B63&CHAR(10)&TEXT('中信三级行业指数热度'!E63,"0.0")&"%" | J10: ='中信三级行业指数热度'!B116&CHAR(10)&TEXT('中信三级行业指数热度'!E116,"0.0")&"%" | K10: ='中信三级行业指数热度'!B45&CHAR(10)&TEXT('中信三级行业指数热度'!E45,"0.0")&"%" | L10: ='中信三级行业指数热度'!B237&CHAR(10)&TEXT('中信三级行业指数热度'!E237,"0.0")&"%" | M10: ='中信三级行业指数热度'!B104&CHAR(10)&TEXT('中信三级行业指数热度'!E104,"0.0")&"%" | N10: ='中信三级行业指数热度'!B185&CHAR(10)&TEXT('中信三级行业指数热度'!E185,"0.0")&"%" | O10: ='中信三级行业指数热度'!B7&CHAR(10)&TEXT('中信三级行业指数热度'!E7,"0.0")&"%" | R10: ='中信三级行业指数热度'!E172 | S10: ='中信三级行业指数热度'!E158 | T10: ='中信三级行业指数热度'!E87 | U10: ='中信三级行业指数热度'!E86 | V10: ='中信三级行业指数热度'!E147 | W10: ='中信三级行业指数热度'!E145 | X10: ='中信三级行业指数热度'!E81 | Y10: ='中信三级行业指数热度'!E63 | Z10: ='中信三级行业指数热度'!E116 | AA10: ='中信三级行业指数热度'!E45 | AB10: ='中信三级行业指数热度'!E237 | AC10: ='中信三级行业指数热度'!E104 | AD10: ='中信三级行业指数热度'!E185 | AE10: ='中信三级行业指数热度'!E7 | AG10: =IFERROR('中信三级行业指数热度'!G10+ROW()*0.0000000001,-9999)
B11: ='中信三级行业指数热度'!B84&CHAR(10)&TEXT('中信三级行业指数热度'!E84,"0.0")&"%" | C11: ='中信三级行业指数热度'!B225&CHAR(10)&TEXT('中信三级行业指数热度'!E225,"0.0")&"%" | D11: ='中信三级行业指数热度'!B15&CHAR(10)&TEXT('中信三级行业指数热度'!E15,"0.0")&"%" | E11: ='中信三级行业指数热度'!B128&CHAR(10)&TEXT('中信三级行业指数热度'!E128,"0.0")&"%" | F11: ='中信三级行业指数热度'!B200&CHAR(10)&TEXT('中信三级行业指数热度'!E200,"0.0")&"%" | G11: ='中信三级行业指数热度'!B141&CHAR(10)&TEXT('中信三级行业指数热度'!E141,"0.0")&"%" | H11: ='中信三级行业指数热度'!B251&CHAR(10)&TEXT('中信三级行业指数热度'!E251,"0.0")&"%" | I11: ='中信三级行业指数热度'!B206&CHAR(10)&TEXT('中信三级行业指数热度'!E206,"0.0")&"%" | J11: ='中信三级行业指数热度'!B215&CHAR(10)&TEXT('中信三级行业指数热度'!E215,"0.0")&"%" | K11: ='中信三级行业指数热度'!B129&CHAR(10)&TEXT('中信三级行业指数热度'!E129,"0.0")&"%" | L11: ='中信三级行业指数热度'!B252&CHAR(10)&TEXT('中信三级行业指数热度'!E252,"0.0")&"%" | M11: ='中信三级行业指数热度'!B202&CHAR(10)&TEXT('中信三级行业指数热度'!E202,"0.0")&"%" | N11: ='中信三级行业指数热度'!B118&CHAR(10)&TEXT('中信三级行业指数热度'!E118,"0.0")&"%" | O11: ='中信三级行业指数热度'!B207&CHAR(10)&TEXT('中信三级行业指数热度'!E207,"0.0")&"%" | R11: ='中信三级行业指数热度'!E84 | S11: ='中信三级行业指数热度'!E225 | T11: ='中信三级行业指数热度'!E15 | U11: ='中信三级行业指数热度'!E128 | V11: ='中信三级行业指数热度'!E200 | W11: ='中信三级行业指数热度'!E141 | X11: ='中信三级行业指数热度'!E251 | Y11: ='中信三级行业指数热度'!E206 | Z11: ='中信三级行业指数热度'!E215 | AA11: ='中信三级行业指数热度'!E129 | AB11: ='中信三级行业指数热度'!E252 | AC11: ='中信三级行业指数热度'!E202 | AD11: ='中信三级行业指数热度'!E118 | AE11: ='中信三级行业指数热度'!E207 | AG11: =IFERROR('中信三级行业指数热度'!G11+ROW()*0.0000000001,-9999)
B12: ='中信三级行业指数热度'!B218&CHAR(10)&TEXT('中信三级行业指数热度'!E218,"0.0")&"%" | C12: ='中信三级行业指数热度'!B198&CHAR(10)&TEXT('中信三级行业指数热度'!E198,"0.0")&"%" | D12: ='中信三级行业指数热度'!B203&CHAR(10)&TEXT('中信三级行业指数热度'!E203,"0.0")&"%" | E12: ='中信三级行业指数热度'!B155&CHAR(10)&TEXT('中信三级行业指数热度'!E155,"0.0")&"%" | F12: ='中信三级行业指数热度'!B125&CHAR(10)&TEXT('中信三级行业指数热度'!E125,"0.0")&"%" | G12: ='中信三级行业指数热度'!B178&CHAR(10)&TEXT('中信三级行业指数热度'!E178,"0.0")&"%" | H12: ='中信三级行业指数热度'!B156&CHAR(10)&TEXT('中信三级行业指数热度'!E156,"0.0")&"%" | I12: ='中信三级行业指数热度'!B96&CHAR(10)&TEXT('中信三级行业指数热度'!E96,"0.0")&"%" | J12: ='中信三级行业指数热度'!B186&CHAR(10)&TEXT('中信三级行业指数热度'!E186,"0.0")&"%" | K12: ='中信三级行业指数热度'!B54&CHAR(10)&TEXT('中信三级行业指数热度'!E54,"0.0")&"%" | L12: ='中信三级行业指数热度'!B190&CHAR(10)&TEXT('中信三级行业指数热度'!E190,"0.0")&"%" | M12: ='中信三级行业指数热度'!B68&CHAR(10)&TEXT('中信三级行业指数热度'!E68,"0.0")&"%" | N12: ='中信三级行业指数热度'!B126&CHAR(10)&TEXT('中信三级行业指数热度'!E126,"0.0")&"%" | O12: ='中信三级行业指数热度'!B233&CHAR(10)&TEXT('中信三级行业指数热度'!E233,"0.0")&"%" | R12: ='中信三级行业指数热度'!E218 | S12: ='中信三级行业指数热度'!E198 | T12: ='中信三级行业指数热度'!E203 | U12: ='中信三级行业指数热度'!E155 | V12: ='中信三级行业指数热度'!E125 | W12: ='中信三级行业指数热度'!E178 | X12: ='中信三级行业指数热度'!E156 | Y12: ='中信三级行业指数热度'!E96 | Z12: ='中信三级行业指数热度'!E186 | AA12: ='中信三级行业指数热度'!E54 | AB12: ='中信三级行业指数热度'!E190 | AC12: ='中信三级行业指数热度'!E68 | AD12: ='中信三级行业指数热度'!E126 | AE12: ='中信三级行业指数热度'!E233 | AG12: =IFERROR('中信三级行业指数热度'!G12+ROW()*0.0000000001,-9999)
B13: ='中信三级行业指数热度'!B38&CHAR(10)&TEXT('中信三级行业指数热度'!E38,"0.0")&"%" | C13: ='中信三级行业指数热度'!B106&CHAR(10)&TEXT('中信三级行业指数热度'!E106,"0.0")&"%" | D13: ='中信三级行业指数热度'!B29&CHAR(10)&TEXT('中信三级行业指数热度'!E29,"0.0")&"%" | E13: ='中信三级行业指数热度'!B192&CHAR(10)&TEXT('中信三级行业指数热度'!E192,"0.0")&"%" | F13: ='中信三级行业指数热度'!B113&CHAR(10)&TEXT('中信三级行业指数热度'!E113,"0.0")&"%" | G13: ='中信三级行业指数热度'!B223&CHAR(10)&TEXT('中信三级行业指数热度'!E223,"0.0")&"%" | H13: ='中信三级行业指数热度'!B256&CHAR(10)&TEXT('中信三级行业指数热度'!E256,"0.0")&"%" | I13: ='中信三级行业指数热度'!B14&CHAR(10)&TEXT('中信三级行业指数热度'!E14,"0.0")&"%" | J13: ='中信三级行业指数热度'!B110&CHAR(10)&TEXT('中信三级行业指数热度'!E110,"0.0")&"%" | K13: ='中信三级行业指数热度'!B64&CHAR(10)&TEXT('中信三级行业指数热度'!E64,"0.0")&"%" | L13: ='中信三级行业指数热度'!B238&CHAR(10)&TEXT('中信三级行业指数热度'!E238,"0.0")&"%" | M13: ='中信三级行业指数热度'!B194&CHAR(10)&TEXT('中信三级行业指数热度'!E194,"0.0")&"%" | N13: ='中信三级行业指数热度'!B97&CHAR(10)&TEXT('中信三级行业指数热度'!E97,"0.0")&"%" | O13: ='中信三级行业指数热度'!B85&CHAR(10)&TEXT('中信三级行业指数热度'!E85,"0.0")&"%" | R13: ='中信三级行业指数热度'!E38 | S13: ='中信三级行业指数热度'!E106 | T13: ='中信三级行业指数热度'!E29 | U13: ='中信三级行业指数热度'!E192 | V13: ='中信三级行业指数热度'!E113 | W13: ='中信三级行业指数热度'!E223 | X13: ='中信三级行业指数热度'!E256 | Y13: ='中信三级行业指数热度'!E14 | Z13: ='中信三级行业指数热度'!E110 | AA13: ='中信三级行业指数热度'!E64 | AB13: ='中信三级行业指数热度'!E238 | AC13: ='中信三级行业指数热度'!E194 | AD13: ='中信三级行业指数热度'!E97 | AE13: ='中信三级行业指数热度'!E85 | AG13: =IFERROR('中信三级行业指数热度'!G13+ROW()*0.0000000001,-9999)
B14: ='中信三级行业指数热度'!B72&CHAR(10)&TEXT('中信三级行业指数热度'!E72,"0.0")&"%" | C14: ='中信三级行业指数热度'!B257&CHAR(10)&TEXT('中信三级行业指数热度'!E257,"0.0")&"%" | D14: ='中信三级行业指数热度'!B213&CHAR(10)&TEXT('中信三级行业指数热度'!E213,"0.0")&"%" | E14: ='中信三级行业指数热度'!B78&CHAR(10)&TEXT('中信三级行业指数热度'!E78,"0.0")&"%" | F14: ='中信三级行业指数热度'!B89&CHAR(10)&TEXT('中信三级行业指数热度'!E89,"0.0")&"%" | G14: ='中信三级行业指数热度'!B167&CHAR(10)&TEXT('中信三级行业指数热度'!E167,"0.0")&"%" | H14: ='中信三级行业指数热度'!B93&CHAR(10)&TEXT('中信三级行业指数热度'!E93,"0.0")&"%" | I14: ='中信三级行业指数热度'!B133&CHAR(10)&TEXT('中信三级行业指数热度'!E133,"0.0")&"%" | J14: ='中信三级行业指数热度'!B50&CHAR(10)&TEXT('中信三级行业指数热度'!E50,"0.0")&"%" | K14: ='中信三级行业指数热度'!B209&CHAR(10)&TEXT('中信三级行业指数热度'!E209,"0.0")&"%" | L14: ='中信三级行业指数热度'!B65&CHAR(10)&TEXT('中信三级行业指数热度'!E65,"0.0")&"%" | M14: ='中信三级行业指数热度'!B195&CHAR(10)&TEXT('中信三级行业指数热度'!E195,"0.0")&"%" | N14: ='中信三级行业指数热度'!B222&CHAR(10)&TEXT('中信三级行业指数热度'!E222,"0.0")&"%" | O14: ='中信三级行业指数热度'!B33&CHAR(10)&TEXT('中信三级行业指数热度'!E33,"0.0")&"%" | R14: ='中信三级行业指数热度'!E72 | S14: ='中信三级行业指数热度'!E257 | T14: ='中信三级行业指数热度'!E213 | U14: ='中信三级行业指数热度'!E78 | V14: ='中信三级行业指数热度'!E89 | W14: ='中信三级行业指数热度'!E167 | X14: ='中信三级行业指数热度'!E93 | Y14: ='中信三级行业指数热度'!E133 | Z14: ='中信三级行业指数热度'!E50 | AA14: ='中信三级行业指数热度'!E209 | AB14: ='中信三级行业指数热度'!E65 | AC14: ='中信三级行业指数热度'!E195 | AD14: ='中信三级行业指数热度'!E222 | AE14: ='中信三级行业指数热度'!E33 | AG14: =IFERROR('中信三级行业指数热度'!G14+ROW()*0.0000000001,-9999)
B15: ='中信三级行业指数热度'!B120&CHAR(10)&TEXT('中信三级行业指数热度'!E120,"0.0")&"%" | C15: ='中信三级行业指数热度'!B39&CHAR(10)&TEXT('中信三级行业指数热度'!E39,"0.0")&"%" | D15: ='中信三级行业指数热度'!B241&CHAR(10)&TEXT('中信三级行业指数热度'!E241,"0.0")&"%" | E15: ='中信三级行业指数热度'!B169&CHAR(10)&TEXT('中信三级行业指数热度'!E169,"0.0")&"%" | F15: ='中信三级行业指数热度'!B115&CHAR(10)&TEXT('中信三级行业指数热度'!E115,"0.0")&"%" | G15: ='中信三级行业指数热度'!B180&CHAR(10)&TEXT('中信三级行业指数热度'!E180,"0.0")&"%" | H15: ='中信三级行业指数热度'!B208&CHAR(10)&TEXT('中信三级行业指数热度'!E208,"0.0")&"%" | I15: ='中信三级行业指数热度'!B211&CHAR(10)&TEXT('中信三级行业指数热度'!E211,"0.0")&"%" | J15: ='中信三级行业指数热度'!B255&CHAR(10)&TEXT('中信三级行业指数热度'!E255,"0.0")&"%" | K15: ='中信三级行业指数热度'!B148&CHAR(10)&TEXT('中信三级行业指数热度'!E148,"0.0")&"%" | L15: ='中信三级行业指数热度'!B164&CHAR(10)&TEXT('中信三级行业指数热度'!E164,"0.0")&"%" | M15: ='中信三级行业指数热度'!B55&CHAR(10)&TEXT('中信三级行业指数热度'!E55,"0.0")&"%" | N15: ='中信三级行业指数热度'!B111&CHAR(10)&TEXT('中信三级行业指数热度'!E111,"0.0")&"%" | O15: ='中信三级行业指数热度'!B44&CHAR(10)&TEXT('中信三级行业指数热度'!E44,"0.0")&"%" | R15: ='中信三级行业指数热度'!E120 | S15: ='中信三级行业指数热度'!E39 | T15: ='中信三级行业指数热度'!E241 | U15: ='中信三级行业指数热度'!E169 | V15: ='中信三级行业指数热度'!E115 | W15: ='中信三级行业指数热度'!E180 | X15: ='中信三级行业指数热度'!E208 | Y15: ='中信三级行业指数热度'!E211 | Z15: ='中信三级行业指数热度'!E255 | AA15: ='中信三级行业指数热度'!E148 | AB15: ='中信三级行业指数热度'!E164 | AC15: ='中信三级行业指数热度'!E55 | AD15: ='中信三级行业指数热度'!E111 | AE15: ='中信三级行业指数热度'!E44 | AG15: =IFERROR('中信三级行业指数热度'!G15+ROW()*0.0000000001,-9999)
B16: ='中信三级行业指数热度'!B130&CHAR(10)&TEXT('中信三级行业指数热度'!E130,"0.0")&"%" | C16: ='中信三级行业指数热度'!B95&CHAR(10)&TEXT('中信三级行业指数热度'!E95,"0.0")&"%" | D16: ='中信三级行业指数热度'!B174&CHAR(10)&TEXT('中信三级行业指数热度'!E174,"0.0")&"%" | E16: ='中信三级行业指数热度'!B105&CHAR(10)&TEXT('中信三级行业指数热度'!E105,"0.0")&"%" | F16: ='中信三级行业指数热度'!B132&CHAR(10)&TEXT('中信三级行业指数热度'!E132,"0.0")&"%" | G16: ='中信三级行业指数热度'!B100&CHAR(10)&TEXT('中信三级行业指数热度'!E100,"0.0")&"%" | H16: ='中信三级行业指数热度'!B249&CHAR(10)&TEXT('中信三级行业指数热度'!E249,"0.0")&"%" | I16: ='中信三级行业指数热度'!B153&CHAR(10)&TEXT('中信三级行业指数热度'!E153,"0.0")&"%" | J16: ='中信三级行业指数热度'!B193&CHAR(10)&TEXT('中信三级行业指数热度'!E193,"0.0")&"%" | K16: ='中信三级行业指数热度'!B175&CHAR(10)&TEXT('中信三级行业指数热度'!E175,"0.0")&"%" | L16: ='中信三级行业指数热度'!B187&CHAR(10)&TEXT('中信三级行业指数热度'!E187,"0.0")&"%" | M16: ='中信三级行业指数热度'!B30&CHAR(10)&TEXT('中信三级行业指数热度'!E30,"0.0")&"%" | N16: ='中信三级行业指数热度'!B70&CHAR(10)&TEXT('中信三级行业指数热度'!E70,"0.0")&"%" | O16: ='中信三级行业指数热度'!B161&CHAR(10)&TEXT('中信三级行业指数热度'!E161,"0.0")&"%" | R16: ='中信三级行业指数热度'!E130 | S16: ='中信三级行业指数热度'!E95 | T16: ='中信三级行业指数热度'!E174 | U16: ='中信三级行业指数热度'!E105 | V16: ='中信三级行业指数热度'!E132 | W16: ='中信三级行业指数热度'!E100 | X16: ='中信三级行业指数热度'!E249 | Y16: ='中信三级行业指数热度'!E153 | Z16: ='中信三级行业指数热度'!E193 | AA16: ='中信三级行业指数热度'!E175 | AB16: ='中信三级行业指数热度'!E187 | AC16: ='中信三级行业指数热度'!E30 | AD16: ='中信三级行业指数热度'!E70 | AE16: ='中信三级行业指数热度'!E161 | AG16: =IFERROR('中信三级行业指数热度'!G16+ROW()*0.0000000001,-9999)
B17: ='中信三级行业指数热度'!B143&CHAR(10)&TEXT('中信三级行业指数热度'!E143,"0.0")&"%" | C17: ='中信三级行业指数热度'!B258&CHAR(10)&TEXT('中信三级行业指数热度'!E258,"0.0")&"%" | D17: ='中信三级行业指数热度'!B197&CHAR(10)&TEXT('中信三级行业指数热度'!E197,"0.0")&"%" | E17: ='中信三级行业指数热度'!B135&CHAR(10)&TEXT('中信三级行业指数热度'!E135,"0.0")&"%" | F17: ='中信三级行业指数热度'!B36&CHAR(10)&TEXT('中信三级行业指数热度'!E36,"0.0")&"%" | G17: ='中信三级行业指数热度'!B112&CHAR(10)&TEXT('中信三级行业指数热度'!E112,"0.0")&"%" | H17: ='中信三级行业指数热度'!B232&CHAR(10)&TEXT('中信三级行业指数热度'!E232,"0.0")&"%" | I17: ='中信三级行业指数热度'!B219&CHAR(10)&TEXT('中信三级行业指数热度'!E219,"0.0")&"%" | J17: ='中信三级行业指数热度'!B159&CHAR(10)&TEXT('中信三级行业指数热度'!E159,"0.0")&"%" | K17: ='中信三级行业指数热度'!B134&CHAR(10)&TEXT('中信三级行业指数热度'!E134,"0.0")&"%" | L17: ='中信三级行业指数热度'!B199&CHAR(10)&TEXT('中信三级行业指数热度'!E199,"0.0")&"%" | M17: ='中信三级行业指数热度'!B188&CHAR(10)&TEXT('中信三级行业指数热度'!E188,"0.0")&"%" | N17: ='中信三级行业指数热度'!B217&CHAR(10)&TEXT('中信三级行业指数热度'!E217,"0.0")&"%" | O17: ='中信三级行业指数热度'!B83&CHAR(10)&TEXT('中信三级行业指数热度'!E83,"0.0")&"%" | R17: ='中信三级行业指数热度'!E143 | S17: ='中信三级行业指数热度'!E258 | T17: ='中信三级行业指数热度'!E197 | U17: ='中信三级行业指数热度'!E135 | V17: ='中信三级行业指数热度'!E36 | W17: ='中信三级行业指数热度'!E112 | X17: ='中信三级行业指数热度'!E232 | Y17: ='中信三级行业指数热度'!E219 | Z17: ='中信三级行业指数热度'!E159 | AA17: ='中信三级行业指数热度'!E134 | AB17: ='中信三级行业指数热度'!E199 | AC17: ='中信三级行业指数热度'!E188 | AD17: ='中信三级行业指数热度'!E217 | AE17: ='中信三级行业指数热度'!E83 | AG17: =IFERROR('中信三级行业指数热度'!G17+ROW()*0.0000000001,-9999)
B18: ='中信三级行业指数热度'!B160&CHAR(10)&TEXT('中信三级行业指数热度'!E160,"0.0")&"%" | C18: ='中信三级行业指数热度'!B163&CHAR(10)&TEXT('中信三级行业指数热度'!E163,"0.0")&"%" | D18: ='中信三级行业指数热度'!B239&CHAR(10)&TEXT('中信三级行业指数热度'!E239,"0.0")&"%" | E18: ='中信三级行业指数热度'!B73&CHAR(10)&TEXT('中信三级行业指数热度'!E73,"0.0")&"%" | F18: ='中信三级行业指数热度'!B41&CHAR(10)&TEXT('中信三级行业指数热度'!E41,"0.0")&"%" | G18: ='中信三级行业指数热度'!B171&CHAR(10)&TEXT('中信三级行业指数热度'!E171,"0.0")&"%" | H18: ='中信三级行业指数热度'!B177&CHAR(10)&TEXT('中信三级行业指数热度'!E177,"0.0")&"%" | I18: ='中信三级行业指数热度'!B26&CHAR(10)&TEXT('中信三级行业指数热度'!E26,"0.0")&"%" | J18: ='中信三级行业指数热度'!B224&CHAR(10)&TEXT('中信三级行业指数热度'!E224,"0.0")&"%" | K18: ='中信三级行业指数热度'!B220&CHAR(10)&TEXT('中信三级行业指数热度'!E220,"0.0")&"%" | L18: ='中信三级行业指数热度'!B154&CHAR(10)&TEXT('中信三级行业指数热度'!E154,"0.0")&"%" | M18: ='中信三级行业指数热度'!B228&CHAR(10)&TEXT('中信三级行业指数热度'!E228,"0.0")&"%" | N18: ='中信三级行业指数热度'!B227&CHAR(10)&TEXT('中信三级行业指数热度'!E227,"0.0")&"%" | O18: ='中信三级行业指数热度'!B109&CHAR(10)&TEXT('中信三级行业指数热度'!E109,"0.0")&"%" | R18: ='中信三级行业指数热度'!E160 | S18: ='中信三级行业指数热度'!E163 | T18: ='中信三级行业指数热度'!E239 | U18: ='中信三级行业指数热度'!E73 | V18: ='中信三级行业指数热度'!E41 | W18: ='中信三级行业指数热度'!E171 | X18: ='中信三级行业指数热度'!E177 | Y18: ='中信三级行业指数热度'!E26 | Z18: ='中信三级行业指数热度'!E224 | AA18: ='中信三级行业指数热度'!E220 | AB18: ='中信三级行业指数热度'!E154 | AC18: ='中信三级行业指数热度'!E228 | AD18: ='中信三级行业指数热度'!E227 | AE18: ='中信三级行业指数热度'!E109 | AG18: =IFERROR('中信三级行业指数热度'!G18+ROW()*0.0000000001,-9999)
B19: ='中信三级行业指数热度'!B13&CHAR(10)&TEXT('中信三级行业指数热度'!E13,"0.0")&"%" | C19: ='中信三级行业指数热度'!B191&CHAR(10)&TEXT('中信三级行业指数热度'!E191,"0.0")&"%" | D19: ='中信三级行业指数热度'!B92&CHAR(10)&TEXT('中信三级行业指数热度'!E92,"0.0")&"%" | E19: ='中信三级行业指数热度'!B242&CHAR(10)&TEXT('中信三级行业指数热度'!E242,"0.0")&"%" | F19: ='中信三级行业指数热度'!B168&CHAR(10)&TEXT('中信三级行业指数热度'!E168,"0.0")&"%" | G19: ='中信三级行业指数热度'!B234&CHAR(10)&TEXT('中信三级行业指数热度'!E234,"0.0")&"%" | H19: ='中信三级行业指数热度'!B254&CHAR(10)&TEXT('中信三级行业指数热度'!E254,"0.0")&"%" | I19: ='中信三级行业指数热度'!B229&CHAR(10)&TEXT('中信三级行业指数热度'!E229,"0.0")&"%" | J19: ='中信三级行业指数热度'!B76&CHAR(10)&TEXT('中信三级行业指数热度'!E76,"0.0")&"%" | K19: ='中信三级行业指数热度'!B262&CHAR(10)&TEXT('中信三级行业指数热度'!E262,"0.0")&"%" | L19: ='中信三级行业指数热度'!B102&CHAR(10)&TEXT('中信三级行业指数热度'!E102,"0.0")&"%" | M19: ='中信三级行业指数热度'!B149&CHAR(10)&TEXT('中信三级行业指数热度'!E149,"0.0")&"%" | N19: ='中信三级行业指数热度'!B236&CHAR(10)&TEXT('中信三级行业指数热度'!E236,"0.0")&"%" | O19: ='中信三级行业指数热度'!B204&CHAR(10)&TEXT('中信三级行业指数热度'!E204,"0.0")&"%" | R19: ='中信三级行业指数热度'!E13 | S19: ='中信三级行业指数热度'!E191 | T19: ='中信三级行业指数热度'!E92 | U19: ='中信三级行业指数热度'!E242 | V19: ='中信三级行业指数热度'!E168 | W19: ='中信三级行业指数热度'!E234 | X19: ='中信三级行业指数热度'!E254 | Y19: ='中信三级行业指数热度'!E229 | Z19: ='中信三级行业指数热度'!E76 | AA19: ='中信三级行业指数热度'!E262 | AB19: ='中信三级行业指数热度'!E102 | AC19: ='中信三级行业指数热度'!E149 | AD19: ='中信三级行业指数热度'!E236 | AE19: ='中信三级行业指数热度'!E204 | AG19: =IFERROR('中信三级行业指数热度'!G19+ROW()*0.0000000001,-9999)
B20: ='中信三级行业指数热度'!B117&CHAR(10)&TEXT('中信三级行业指数热度'!E117,"0.0")&"%" | C20: ='中信三级行业指数热度'!B261&CHAR(10)&TEXT('中信三级行业指数热度'!E261,"0.0")&"%" | D20: ='中信三级行业指数热度'!B170&CHAR(10)&TEXT('中信三级行业指数热度'!E170,"0.0")&"%" | E20: ='中信三级行业指数热度'!B114&CHAR(10)&TEXT('中信三级行业指数热度'!E114,"0.0")&"%" | F20: ='中信三级行业指数热度'!B201&CHAR(10)&TEXT('中信三级行业指数热度'!E201,"0.0")&"%" | G20: ='中信三级行业指数热度'!B235&CHAR(10)&TEXT('中信三级行业指数热度'!E235,"0.0")&"%" | H20: ='中信三级行业指数热度'!B221&CHAR(10)&TEXT('中信三级行业指数热度'!E221,"0.0")&"%" | I20: ='中信三级行业指数热度'!B260&CHAR(10)&TEXT('中信三级行业指数热度'!E260,"0.0")&"%" | J20: ='中信三级行业指数热度'!B243&CHAR(10)&TEXT('中信三级行业指数热度'!E243,"0.0")&"%" | K20: ='中信三级行业指数热度'!B214&CHAR(10)&TEXT('中信三级行业指数热度'!E214,"0.0")&"%" | L20: ='中信三级行业指数热度'!B127&CHAR(10)&TEXT('中信三级行业指数热度'!E127,"0.0")&"%" | M20: ='中信三级行业指数热度'!B230&CHAR(10)&TEXT('中信三级行业指数热度'!E230,"0.0")&"%" | N20: ='中信三级行业指数热度'!B138&CHAR(10)&TEXT('中信三级行业指数热度'!E138,"0.0")&"%" | O20: ='中信三级行业指数热度'!B216&CHAR(10)&TEXT('中信三级行业指数热度'!E216,"0.0")&"%" | R20: ='中信三级行业指数热度'!E117 | S20: ='中信三级行业指数热度'!E261 | T20: ='中信三级行业指数热度'!E170 | U20: ='中信三级行业指数热度'!E114 | V20: ='中信三级行业指数热度'!E201 | W20: ='中信三级行业指数热度'!E235 | X20: ='中信三级行业指数热度'!E221 | Y20: ='中信三级行业指数热度'!E260 | Z20: ='中信三级行业指数热度'!E243 | AA20: ='中信三级行业指数热度'!E214 | AB20: ='中信三级行业指数热度'!E127 | AC20: ='中信三级行业指数热度'!E230 | AD20: ='中信三级行业指数热度'!E138 | AE20: ='中信三级行业指数热度'!E216 | AG20: =IFERROR('中信三级行业指数热度'!G20+ROW()*0.0000000001,-9999)
B21: ='中信三级行业指数热度'!B98&CHAR(10)&TEXT('中信三级行业指数热度'!E98,"0.0")&"%" | C21: ='中信三级行业指数热度'!B183&CHAR(10)&TEXT('中信三级行业指数热度'!E183,"0.0")&"%" | D21: ='中信三级行业指数热度'!B250&CHAR(10)&TEXT('中信三级行业指数热度'!E250,"0.0")&"%" | E21: ='中信三级行业指数热度'!B24&CHAR(10)&TEXT('中信三级行业指数热度'!E24,"0.0")&"%" | F21: ='中信三级行业指数热度'!B259&CHAR(10)&TEXT('中信三级行业指数热度'!E259,"0.0")&"%" | G21: ='中信三级行业指数热度'!B58&CHAR(10)&TEXT('中信三级行业指数热度'!E58,"0.0")&"%" | H21: ='中信三级行业指数热度'!B247&CHAR(10)&TEXT('中信三级行业指数热度'!E247,"0.0")&"%" | I21: ='中信三级行业指数热度'!B226&CHAR(10)&TEXT('中信三级行业指数热度'!E226,"0.0")&"%" | J21: ='中信三级行业指数热度'!B248&CHAR(10)&TEXT('中信三级行业指数热度'!E248,"0.0")&"%" | R21: ='中信三级行业指数热度'!E98 | S21: ='中信三级行业指数热度'!E183 | T21: ='中信三级行业指数热度'!E250 | U21: ='中信三级行业指数热度'!E24 | V21: ='中信三级行业指数热度'!E259 | W21: ='中信三级行业指数热度'!E58 | X21: ='中信三级行业指数热度'!E247 | Y21: ='中信三级行业指数热度'!E226 | Z21: ='中信三级行业指数热度'!E248 | AG21: =IFERROR('中信三级行业指数热度'!G21+ROW()*0.0000000001,-9999)
AG22: =IFERROR('中信三级行业指数热度'!G22+ROW()*0.0000000001,-9999)
B23: 图例(近一周涨跌幅): | D23: ≤-7% | E23: -7~-3% | F23: -3~-1% | G23: -1~1% | H23: 1~3% | I23: 3~7% | J23: ≥7% | AG23: =IFERROR('中信三级行业指数热度'!G23+ROW()*0.0000000001,-9999)
AG24: =IFERROR('中信三级行业指数热度'!G24+ROW()*0.0000000001,-9999)
AG25: =IFERROR('中信三级行业指数热度'!G25+ROW()*0.0000000001,-9999)
B26: 短期热点 TOP20（按动量加速度自动排名，随刷新更新） | AG26: =IFERROR('中信三级行业指数热度'!G26+ROW()*0.0000000001,-9999)
B27: 排名 | C27: 指数名称 | D27: 近一周(%) | E27: 近一月(%) | F27: 动量加速度 | G27: YTD(%) | AG27: =IFERROR('中信三级行业指数热度'!G27+ROW()*0.0000000001,-9999)
B28: 1 | C28: =IFERROR(INDEX('中信三级行业指数热度'!$B$2:$B$262,MATCH(LARGE($AG$2:$AG$262,1),$AG$2:$AG$262,0)),"") | D28: =IFERROR(INDEX('中信三级行业指数热度'!$E$2:$E$262,MATCH(LARGE($AG$2:$AG$262,1),$AG$2:$AG$262,0)),"") | E28: =IFERROR(INDEX('中信三级行业指数热度'!$F$2:$F$262,MATCH(LARGE($AG$2:$AG$262,1),$AG$2:$AG$262,0)),"") | F28: =IFERROR(INDEX('中信三级行业指数热度'!$G$2:$G$262,MATCH(LARGE($AG$2:$AG$262,1),$AG$2:$AG$262,0)),"") | G28: =IFERROR(INDEX('中信三级行业指数热度'!$D$2:$D$262,MATCH(LARGE($AG$2:$AG$262,1),$AG$2:$AG$262,0)),"") | AG28: =IFERROR('中信三级行业指数热度'!G28+ROW()*0.0000000001,-9999)
B29: 2 | C29: =IFERROR(INDEX('中信三级行业指数热度'!$B$2:$B$262,MATCH(LARGE($AG$2:$AG$262,2),$AG$2:$AG$262,0)),"") | D29: =IFERROR(INDEX('中信三级行业指数热度'!$E$2:$E$262,MATCH(LARGE($AG$2:$AG$262,2),$AG$2:$AG$262,0)),"") | E29: =IFERROR(INDEX('中信三级行业指数热度'!$F$2:$F$262,MATCH(LARGE($AG$2:$AG$262,2),$AG$2:$AG$262,0)),"") | F29: =IFERROR(INDEX('中信三级行业指数热度'!$G$2:$G$262,MATCH(LARGE($AG$2:$AG$262,2),$AG$2:$AG$262,0)),"") | G29: =IFERROR(INDEX('中信三级行业指数热度'!$D$2:$D$262,MATCH(LARGE($AG$2:$AG$262,2),$AG$2:$AG$262,0)),"") | AG29: =IFERROR('中信三级行业指数热度'!G29+ROW()*0.0000000001,-9999)
B30: 3 | C30: =IFERROR(INDEX('中信三级行业指数热度'!$B$2:$B$262,MATCH(LARGE($AG$2:$AG$262,3),$AG$2:$AG$262,0)),"") | D30: =IFERROR(INDEX('中信三级行业指数热度'!$E$2:$E$262,MATCH(LARGE($AG$2:$AG$262,3),$AG$2:$AG$262,0)),"") | E30: =IFERROR(INDEX('中信三级行业指数热度'!$F$2:$F$262,MATCH(LARGE($AG$2:$AG$262,3),$AG$2:$AG$262,0)),"") | F30: =IFERROR(INDEX('中信三级行业指数热度'!$G$2:$G$262,MATCH(LARGE($AG$2:$AG$262,3),$AG$2:$AG$262,0)),"") | G30: =IFERROR(INDEX('中信三级行业指数热度'!$D$2:$D$262,MATCH(LARGE($AG$2:$AG$262,3),$AG$2:$AG$262,0)),"") | AG30: =IFERROR('中信三级行业指数热度'!G30+ROW()*0.0000000001,-9999)
B31: 4 | C31: =IFERROR(INDEX('中信三级行业指数热度'!$B$2:$B$262,MATCH(LARGE($AG$2:$AG$262,4),$AG$2:$AG$262,0)),"") | D31: =IFERROR(INDEX('中信三级行业指数热度'!$E$2:$E$262,MATCH(LARGE($AG$2:$AG$262,4),$AG$2:$AG$262,0)),"") | E31: =IFERROR(INDEX('中信三级行业指数热度'!$F$2:$F$262,MATCH(LARGE($AG$2:$AG$262,4),$AG$2:$AG$262,0)),"") | F31: =IFERROR(INDEX('中信三级行业指数热度'!$G$2:$G$262,MATCH(LARGE($AG$2:$AG$262,4),$AG$2:$AG$262,0)),"") | G31: =IFERROR(INDEX('中信三级行业指数热度'!$D$2:$D$262,MATCH(LARGE($AG$2:$AG$262,4),$AG$2:$AG$262,0)),"") | AG31: =IFERROR('中信三级行业指数热度'!G31+ROW()*0.0000000001,-9999)
B32: 5 | C32: =IFERROR(INDEX('中信三级行业指数热度'!$B$2:$B$262,MATCH(LARGE($AG$2:$AG$262,5),$AG$2:$AG$262,0)),"") | D32: =IFERROR(INDEX('中信三级行业指数热度'!$E$2:$E$262,MATCH(LARGE($AG$2:$AG$262,5),$AG$2:$AG$262,0)),"") | E32: =IFERROR(INDEX('中信三级行业指数热度'!$F$2:$F$262,MATCH(LARGE($AG$2:$AG$262,5),$AG$2:$AG$262,0)),"") | F32: =IFERROR(INDEX('中信三级行业指数热度'!$G$2:$G$262,MATCH(LARGE($AG$2:$AG$262,5),$AG$2:$AG$262,0)),"") | G32: =IFERROR(INDEX('中信三级行业指数热度'!$D$2:$D$262,MATCH(LARGE($AG$2:$AG$262,5),$AG$2:$AG$262,0)),"") | AG32: =IFERROR('中信三级行业指数热度'!G32+ROW()*0.0000000001,-9999)
B33: 6 | C33: =IFERROR(INDEX('中信三级行业指数热度'!$B$2:$B$262,MATCH(LARGE($AG$2:$AG$262,6),$AG$2:$AG$262,0)),"") | D33: =IFERROR(INDEX('中信三级行业指数热度'!$E$2:$E$262,MATCH(LARGE($AG$2:$AG$262,6),$AG$2:$AG$262,0)),"") | E33: =IFERROR(INDEX('中信三级行业指数热度'!$F$2:$F$262,MATCH(LARGE($AG$2:$AG$262,6),$AG$2:$AG$262,0)),"") | F33: =IFERROR(INDEX('中信三级行业指数热度'!$G$2:$G$262,MATCH(LARGE($AG$2:$AG$262,6),$AG$2:$AG$262,0)),"") | G33: =IFERROR(INDEX('中信三级行业指数热度'!$D$2:$D$262,MATCH(LARGE($AG$2:$AG$262,6),$AG$2:$AG$262,0)),"") | AG33: =IFERROR('中信三级行业指数热度'!G33+ROW()*0.0000000001,-9999)
B34: 7 | C34: =IFERROR(INDEX('中信三级行业指数热度'!$B$2:$B$262,MATCH(LARGE($AG$2:$AG$262,7),$AG$2:$AG$262,0)),"") | D34: =IFERROR(INDEX('中信三级行业指数热度'!$E$2:$E$262,MATCH(LARGE($AG$2:$AG$262,7),$AG$2:$AG$262,0)),"") | E34: =IFERROR(INDEX('中信三级行业指数热度'!$F$2:$F$262,MATCH(LARGE($AG$2:$AG$262,7),$AG$2:$AG$262,0)),"") | F34: =IFERROR(INDEX('中信三级行业指数热度'!$G$2:$G$262,MATCH(LARGE($AG$2:$AG$262,7),$AG$2:$AG$262,0)),"") | G34: =IFERROR(INDEX('中信三级行业指数热度'!$D$2:$D$262,MATCH(LARGE($AG$2:$AG$262,7),$AG$2:$AG$262,0)),"") | AG34: =IFERROR('中信三级行业指数热度'!G34+ROW()*0.0000000001,-9999)
