Workbook

Sheet 中信三级行业指数热度
A1: 指数代码 | B1: 指数名称 | C1: 指数成分股数 | D1: YTD涨幅(%) | E1: 近一周涨跌幅(%) | F1: 近一月涨跌幅(%) | G1: 动量加速度 | H1: CR5合计权重(%) | I1: CR1代码 | J1: CR1名称 | K1: CR1自由流通市值(亿) | L1: CR1权重(%) | M1: CR2代码 | N1: CR2名称 | O1: CR2自由流通市值(亿) | P1: CR2权重(%) | Q1: CR3代码 | R1: CR3名称 | S1: CR3自由流通市值(亿) | T1: CR3权重(%) | U1: CR4代码 | V1: CR4名称 | W1: CR4自由流通市值(亿) | X1: CR4权重(%) | Y1: CR5代码 | Z1: CR5名称 | AA1: CR5自由流通市值(亿) | AB1: CR5权重(%) | AD1: 基准日:今天 | AE1: =TODAY() -> 46199
A2: CI005541.CI | B2: 半导体设备指数 | C2: 29 | D2: =IFERROR(([1]!thsiFinD("ths_close_price_index",$A2,$AE$2,"","")/[1]!thsiFinD("ths_close_price_index",$A2,$AE$5,"","")-1)*100,"") -> 118.03563 | E2: =IFERROR(([1]!thsiFinD("ths_close_price_index",$A2,$AE$2,"","")/[1]!thsiFinD("ths_close_price_index",$A2,$AE$3,"","")-1)*100,"") -> 12.773946 | F2: =IFERROR(([1]!thsiFinD("ths_close_price_index",$A2,$AE$2,"","")/[1]!thsiFinD("ths_close_price_index",$A2,$AE$4,"","")-1)*100,"") -> 30.866909 | G2: =IFERROR(E2/5-F2/20,"") -> 1.0114438 | H2: 71.44 | I2: 002371.SZ | J2: 北方华创 | K2: 3209.173 | L2: 24.23 | M2: 688012.SH | N2: 中微公司 | O2: 2697.3147 | P2: 20.37 | Q2: 688072.SH | R2: 拓荆科技 | S2: 1518.2949 | T2: 11.47 | U2: 300604.SZ | V2: 长川科技 | W2: 1199.3993 | X2: 9.06 | Y2: 688120.SH | Z2: 华海清科 | AA2: 835.7473 | AB2: 6.31 | AD2: 前一交易日T0(工作日近似) | AE2: =TEXT(WORKDAY($AE$1,-1),"yyyy-mm-dd") -> 2026-06-25
A3: CI005539.CI | B3: 分立器件指数 | C3: 16 | D3: =IFERROR(([1]!thsiFinD("ths_close_price_index",$A3,$AE$2,"","")/[1]!thsiFinD("ths_close_price_index",$A3,$AE$5,"","")-1)*100,"") -> 63.771828 | E3: =IFERROR(([1]!thsiFinD("ths_close_price_index",$A3,$AE$2,"","")/[1]!thsiFinD("ths_close_price_index",$A3,$AE$3,"","")-1)*100,"") -> 10.727 | F3: =IFERROR(([1]!thsiFinD("ths_close_price_index",$A3,$AE$2,"","")/[1]!thsiFinD("ths_close_price_index",$A3,$AE$4,"","")-1)*100,"") -> 14.042782 | G3: =IFERROR(E3/5-F3/20,"") -> 1.4432608 | H3: 67.2 | I3: 600460.SH | J3: 士兰微 | K3: 493.4561 | L3: 20.19 | M3: 688172.SH | N3: 燕东微 | O3: 371.7856 | P3: 15.21 | Q3: 300373.SZ | R3: 扬杰科技 | S3: 356.7835 | T3: 14.6 | U3: 605111.SH | V3: 新洁能 | W3: 236.6472 | X3: 9.68 | Y3: 300623.SZ | Z3: 捷捷微电 | AA3: 183.7881 | AB3: 7.52 | AD3: 一周前(T0前5交易日) | AE3: =TEXT(WORKDAY($AE$1,-6),"yyyy-mm-dd") -> 2026-06-18
A4: CI005414.CI | B4: 碳纤维指数 | C4: 2 | D4: =IFERROR(([1]!thsiFinD("ths_close_price_index",$A4,$AE$2,"","")/[1]!thsiFinD("ths_close_price_index",$A4,$AE$5,"","")-1)*100,"") -> 76.22654 | E4: =IFERROR(([1]!thsiFinD("ths_close_price_index",$A4,$AE$2,"","")/[1]!thsiFinD("ths_close_price_index",$A4,$AE$3,"","")-1)*100,"") -> -0.93914612 | F4: =IFERROR(([1]!thsiFinD("ths_close_price_index",$A4,$AE$2,"","")/[1]!thsiFinD("ths_close_price_index",$A4,$AE$4,"","")-1)*100,"") -> 30.992531 | G4: =IFERROR(E4/5-F4/20,"") -> -1.7374558 | H4: 100 | I4: 688598.SH | J4: 金博股份 | K4: 111.1097 | L4: 56.73 | M4: 688295.SH | N4: 中复神鹰 | O4: 84.7332 | P4: 43.27 | AD4: 一月前(T0前20交易日) | AE4: =TEXT(WORKDAY($AE$1,-21),"yyyy-mm-dd") -> 2026-05-28
A5: CI005538.CI | B5: 集成电路指数 | C5: 110 | D5: =IFERROR(([1]!thsiFinD("ths_close_price_index",$A5,$AE$2,"","")/[1]!thsiFinD("ths_close_price_index",$A5,$AE$5,"","")-1)*100,"") -> 84.306331 | E5: =IFERROR(([1]!thsiFinD("ths_close_price_index",$A5,$AE$2,"","")/[1]!thsiFinD("ths_close_price_index",$A5,$AE$3,"","")-1)*100,"") -> 10.902559 | F5: =IFERROR(([1]!thsiFinD("ths_close_price_index",$A5,$AE$2,"","")/[1]!thsiFinD("ths_close_price_index",$A5,$AE$4,"","")-1)*100,"") -> 17.487046 | G5: =IFERROR(E5/5-F5/20,"") -> 1.3061596 | H5: 49.59 | I5: 688256.SH | J5: 寒武纪 | K5: 4468.3271 | L5: 12.66 | M5: 603986.SH | N5: 兆易创新 | O5: 4272.3406 | P5: 12.11 | Q5: 688008.SH | R5: 澜起科技 | S5: 3012.5987 | T5: 8.54 | U5: 688041.SH | V5: 海光信息 | W5: 2939.7339 | X5: 8.33 | Y5: 688981.SH | Z5: 中芯国际 | AA5: 2805.6528 | AB5: 7.95 | AD5: 年初基准(上年末交易日) | AE5: =TEXT(WORKDAY(DATE(YEAR($AE$1),1,1),-1),"yyyy-mm-dd") -> 2025-12-31
A6: CI005422.CI | B6: 橡胶助剂指数 | C6: 5 | D6: =IFERROR(([1]!thsiFinD("ths_close_price_index",$A6,$AE$2,"","")/[1]!thsiFinD("ths_close_price_index",$A6,$AE$5,"","")-1)*100,"") -> 47.346122 | E6: =IFERROR(([1]!thsiFinD("ths_close_price_index",$A6,$AE$2,"","")/[1]!thsiFinD("ths_close_price_index",$A6,$AE$3,"","")-1)*100,"") -> 16.97181 | F6: =IFERROR(([1]!thsiFinD("ths_close_price_index",$A6,$AE$2,"","")/[1]!thsiFinD("ths_close_price_index",$A6,$AE$4,"","")-1)*100,"") -> 27.839876 | G6: =IFERROR(E6/5-F6/20,"") -> 2.0023683 | H6: 100 | I6: 603650.SH | J6: 彤程新材 | K6: 165.2254 | L6: 57.1 | M6: 002068.SZ | N6: 黑猫股份 | O6: 53.5358 | P6: 18.5 | Q6: 300121.SZ | R6: 阳谷华泰 | S6: 37.2273 | T6: 12.87 | U6: 002442.SZ | V6: 龙星科技 | W6: 21.0056 | X6: 7.26 | Y6: 002753.SZ | Z6: 永东股份 | AA6: 12.3687 | AB6: 4.27
A7: CI005292.CI | B7: 卡车指数 | C7: 8 | D7: =IFERROR(([1]!thsiFinD("ths_close_price_index",$A7,$AE$2,"","")/[1]!thsiFinD("ths_close_price_index",$A7,$AE$5,"","")-1)*100,"") -> 39.333336 | E7: =IFERROR(([1]!thsiFinD("ths_close_price_index",$A7,$AE$2,"","")/[1]!thsiFinD("ths_close_price_index",$A7,$AE$3,"","")-1)*100,"") -> -4.0003812 | F7: =IFERROR(([1]!thsiFinD("ths_close_price_index",$A7,$AE$2,"","")/[1]!thsiFinD("ths_close_price_index",$A7,$AE$4,"","")-1)*100,"") -> -14.814469 | G7: =IFERROR(E7/5-F7/20,"") -> -0.059352782 | H7: 93.99 | I7: 000338.SZ | J7: 潍柴动力 | K7: 1525.8845 | L7: 75.12 | M7: 600166.SH | N7: 福田汽车 | O7: 140.3812 | P7: 6.91 | Q7: 000951.SZ | R7: 中国重汽 | S7: 124.8397 | T7: 6.15 | U7: 000800.SZ | V7: 一汽解放 | W7: 66.0473 | X7: 3.25 | Y7: 301039.SZ | Z7: 中集车辆 | AA7: 52.0545 | AB7: 2.56
A8: CI005323.CI | B8: 医疗服务指数 | C8: 47 | D8: =IFERROR(([1]!thsiFinD("ths_close_price_index",$A8,$AE$2,"","")/[1]!thsiFinD("ths_close_price_index",$A8,$AE$5,"","")-1)*100,"") -> 4.0206399 | E8: =IFERROR(([1]!thsiFinD("ths_close_price_index",$A8,$AE$2,"","")/[1]!thsiFinD("ths_close_price_index",$A8,$AE$3,"","")-1)*100,"") -> 8.0227067 | F8: =IFERROR(([1]!thsiFinD("ths_close_price_index",$A8,$AE$2,"","")/[1]!thsiFinD("ths_close_price_index",$A8,$AE$4,"","")-1)*100,"") -> 5.0132767 | G8: =IFERROR(E8/5-F8/20,"") -> 1.3538775 | H8: 67.5 | I8: 603259.SH | J8: 药明康德 | K8: 2293.7092 | L8: 45.98 | M8: 300015.SZ | N8: 爱尔眼科 | O8: 363.2255 | P8: 7.28 | Q8: 300759.SZ | R8: 康龙化成 | S8: 254.6971 | T8: 5.11 | U8: 002821.SZ | V8: 凯莱英 | W8: 245.5889 | X8: 4.92 | Y8: 300347.SZ | Z8: 泰格医药 | AA8: 209.9511 | AB8: 4.21
A9: CI005547.CI | B9: 显示零组指数 | C9: 28 | D9: =IFERROR(([1]!thsiFinD("ths_close_price_index",$A9,$AE$2,"","")/[1]!thsiFinD("ths_close_price_index",$A9,$AE$5,"","")-1)*100,"") -> 78.945039 | E9: =IFERROR(([1]!thsiFinD("ths_close_price_index",$A9,$AE$2,"","")/[1]!thsiFinD("ths_close_price_index",$A9,$AE$3,"","")-1)*100,"") -> 4.5272635 | F9: =IFERROR(([1]!thsiFinD("ths_close_price_index",$A9,$AE$2,"","")/[1]!thsiFinD("ths_close_price_index",$A9,$AE$4,"","")-1)*100,"") -> 8.1582128 | G9: =IFERROR(E9/5-F9/20,"") -> 0.49754206 | H9: 58.15 | I9: 603629.SH | J9: 利通电子 | K9: 274.0956 | L9: 15.21 | M9: 603773.SH | N9: 沃格光电 | O9: 259.3009 | P9: 14.39 | Q9: 300088.SZ | R9: 长信科技 | S9: 230.0351 | T9: 12.77 | U9: 688127.SH | V9: 蓝特光学 | W9: 175.6906 | X9: 9.75 | Y9: 688150.SH | Z9: 莱特光电 | AA9: 108.5704 | AB9: 6.03
A10: CI005480.CI | B10: 燃料电池指数 | C10: 9 | D10: =IFERROR(([1]!thsiFinD("ths_close_price_index",$A10,$AE$2,"","")/[1]!thsiFinD("ths_close_price_index",$A10,$AE$5,"","")-1)*100,"") -> 37.50765 | E10: =IFERROR(([1]!thsiFinD("ths_close_price_index",$A10,$AE$2,"","")/[1]!thsiFinD("ths_close_price_index",$A10,$AE$3,"","")-1)*100,"") -> 10.99687 | F10: =IFERROR(([1]!thsiFinD("ths_close_price_index",$A10,$AE$2,"","")/[1]!thsiFinD("ths_close_price_index",$A10,$AE$4,"","")-1)*100,"") -> 13.220679 | G10: =IFERROR(E10/5-F10/20,"") -> 1.53834 | H10: 100 | I10: 000811.SZ | J10: 冰轮环境 | K10: 273.7642 | L10: 43.69 | M10: 000969.SZ | N10: 安泰科技 | O10: 178.9266 | P10: 28.55 | Q10: 002639.SZ | R10: 雪人集团 | S10: 88.1494 | T10: 14.07 | U10: 600273.SH | V10: 嘉化能源 | W10: 53.3992 | X10: 8.52 | Y10: 688339.SH | Z10: 亿华通 | AA10: 32.4103 | AB10: 5.17
A11: CI005357.CI | B11: 航运指数 | C11: 17 | D11: =IFERROR(([1]!thsiFinD("ths_close_price_index",$A11,$AE$2,"","")/[1]!thsiFinD("ths_close_price_index",$A11,$AE$5,"","")-1)*100,"") -> 20.034214 | E11: =IFERROR(([1]!thsiFinD("ths_close_price_index",$A11,$AE$2,"","")/[1]!thsiFinD("ths_close_price_index",$A11,$AE$3,"","")-1)*100,"") -> 6.9384061 | F11: =IFERROR(([1]!thsiFinD("ths_close_price_index",$A11,$AE$2,"","")/[1]!thsiFinD("ths_close_price_index",$A11,$AE$4,"","")-1)*100,"") -> 5.376593 | G11: =IFERROR(E11/5-F11/20,"") -> 1.1188516 | H11: 82.06 | I11: 601919.SH | J11: 中远海控 | K11: 724.7891 | L11: 33.24 | M11: 601872.SH | N11: 招商轮船 | O11: 494.2193 | P11: 22.67 | Q11: 600026.SH | R11: 中远海能 | S11: 329.4191 | T11: 15.11 | U11: 601975.SH | V11: 招商南油 | W11: 147.7589 | X11: 6.78 | Y11: 600428.SH | Z11: 中远海特 | AA11: 92.8258 | AB11: 4.26
A12: CI005546.CI | B12: 面板指数 | C12: 12 | D12: =IFERROR(([1]!thsiFinD("ths_close_price_index",$A12,$AE$2,"","")/[1]!thsiFinD("ths_close_price_index",$A12,$AE$5,"","")-1)*100,"") -> 50.277387 | E12: =IFERROR(([1]!thsiFinD("ths_close_price_index",$A12,$AE$2,"","")/[1]!thsiFinD("ths_close_price_index",$A12,$AE$3,"","")-1)*100,"") -> 11.871478 | F12: =IFERROR(([1]!thsiFinD("ths_close_price_index",$A12,$AE$2,"","")/[1]!thsiFinD("ths_close_price_index",$A12,$AE$4,"","")-1)*100,"") -> 25.642215 | G12: =IFERROR(E12/5-F12/20,"") -> 1.0921849 | H12: 95.92 | I12: 000725.SZ | J12: 京东方A | K12: 2150.3835 | L12: 59.43 | M12: 000100.SZ | N12: TCL科技 | O12: 925.1556 | P12: 25.57 | Q12: 600707.SH | R12: 彩虹股份 | S12: 164.1556 | T12: 4.54 | U12: 000050.SZ | V12: 深天马A | W12: 126.8056 | X12: 3.5 | Y12: 688538.SH | Z12: 和辉光电 | AA12: 104.1695 | AB12: 2.88
A13: CI005255.CI | B13: 印染化学品指数 | C13: 14 | D13: =IFERROR(([1]!thsiFinD("ths_close_price_index",$A13,$AE$2,"","")/[1]!thsiFinD("ths_close_price_index",$A13,$AE$5,"","")-1)*100,"") -> 25.606664 | E13: =IFERROR(([1]!thsiFinD("ths_close_price_index",$A13,$AE$2,"","")/[1]!thsiFinD("ths_close_price_index",$A13,$AE$3,"","")-1)*100,"") -> 9.5575775 | F13: =IFERROR(([1]!thsiFinD("ths_close_price_index",$A13,$AE$2,"","")/[1]!thsiFinD("ths_close_price_index",$A13,$AE$4,"","")-1)*100,"") -> 9.3877472 | G13: =IFERROR(E13/5-F13/20,"") -> 1.4421281 | H13: 75.26 | I13: 600352.SH | J13: 浙江龙盛 | K13: 294.0162 | L13: 44.85 | M13: 002440.SZ | N13: 闰土股份 | O13: 69.4079 | P13: 10.59 | Q13: 300905.SZ | R13: 宝丽迪 | S13: 50.4684 | T13: 7.7 | U13: 300067.SZ | V13: 安诺其 | W13: 42.6645 | X13: 6.51 | Y13: 300522.SZ | Z13: 世名科技 | AA13: 36.7817 | AB13: 5.61
A14: CI005316.CI | B14: 化学原料药指数 | C14: 59 | D14: =IFERROR(([1]!thsiFinD("ths_close_price_index",$A14,$AE$2,"","")/[1]!thsiFinD("ths_close_price_index",$A14,$AE$5,"","")-1)*100,"") -> 2.0109929 | E14: =IFERROR(([1]!thsiFinD("ths_close_price_index",$A14,$AE$2,"","")/[1]!thsiFinD("ths_close_price_index",$A14,$AE$3,"","")-1)*100,"") -> 4.6023343 | F14: =IFERROR(([1]!thsiFinD("ths_close_price_index",$A14,$AE$2,"","")/[1]!thsiFinD("ths_close_price_index",$A14,$AE$4,"","")-1)*100,"") -> 0.34022749 | G14: =IFERROR(E14/5-F14/20,"") -> 0.90345549 | H14: 92.03 | I14: 688131.SH | J14: 皓元医药 | K14: 123.93 | L14: 32.89 | M14: 000739.SZ | N14: 普洛药业 | O14: 89.0288 | P14: 23.63 | Q14: 300436.SZ | R14: 广生堂 | S14: 82.627 | T14: 21.93 | U14: 301201.SZ | V14: 诚达药业 | W14: 31.1282 | X14: 8.26 | Y14: 300381.SZ | Z14: 溢多利 | AA14: 20.0589 | AB14: 5.32
A15: CI005230.CI | B15: 特钢指数 | C15: 14 | D15: =IFERROR(([1]!thsiFinD("ths_close_price_index",$A15,$AE$2,"","")/[1]!thsiFinD("ths_close_price_index",$A15,$AE$5,"","")-1)*100,"") -> -6.1889528 | E15: =IFERROR(([1]!thsiFinD("ths_close_price_index",$A15,$AE$2,"","")/[1]!thsiFinD("ths_close_price_index",$A15,$AE$3,"","")-1)*100,"") -> -1.8536246 | F15: =IFERROR(([1]!thsiFinD("ths_close_price_index",$A15,$AE$2,"","")/[1]!thsiFinD("ths_close_price_index",$A15,$AE$4,"","")-1)*100,"") -> -3.2375157 | G15: =IFERROR(E15/5-F15/20,"") -> -0.20884913 | H15: 71.76 | I15: 002318.SZ | J15: 久立特材 | K15: 146.483 | L15: 24.1 | M15: 000708.SZ | N15: 中信特钢 | O15: 111.3349 | P15: 18.32 | Q15: 600399.SH | R15: 抚顺特钢 | S15: 61.5034 | T15: 10.12 | U15: 002075.SZ | V15: 沙钢股份 | W15: 59.9019 | X15: 9.86 | Y15: 600507.SH | Z15: 方大特钢 | AA15: 56.8891 | AB15: 9.36
A16: CI005442.CI | B16: 其他专用材料指数 | C16: 13 | D16: =IFERROR(([1]!thsiFinD("ths_close_price_index",$A16,$AE$2,"","")/[1]!thsiFinD("ths_close_price_index",$A16,$AE$5,"","")-1)*100,"") -> 41.763779 | E16: =IFERROR(([1]!thsiFinD("ths_close_price_index",$A16,$AE$2,"","")/[1]!thsiFinD("ths_close_price_index",$A16,$AE$3,"","")-1)*100,"") -> 6.7269618 | F16: =IFERROR(([1]!thsiFinD("ths_close_price_index",$A16,$AE$2,"","")/[1]!thsiFinD("ths_close_price_index",$A16,$AE$4,"","")-1)*100,"") -> 10.41438 | G16: =IFERROR(E16/5-F16/20,"") -> 0.82467337 | H16: 69.09 | I16: 300179.SZ | J16: 四方达 | K16: 173.6464 | L16: 34.87 | M16: 002392.SZ | N16: 北京利尔 | O16: 72.5882 | P16: 14.58 | Q16: 002225.SZ | R16: 濮耐股份 | S16: 36.2324 | T16: 7.28 | U16: 300234.SZ | V16: 开尔新材 | W16: 31.796 | X16: 6.38 | Y16: 002066.SZ | Z16: 瑞泰科技 | AA16: 29.8042 | AB16: 5.98
A17: CI005386.CI | B17: 棉纺制品指数 | C17: 9 | D17: =IFERROR(([1]!thsiFinD("ths_close_price_index",$A17,$AE$2,"","")/[1]!thsiFinD("ths_close_price_index",$A17,$AE$5,"","")-1)*100,"") -> -13.107595 | E17: =IFERROR(([1]!thsiFinD("ths_close_price_index",$A17,$AE$2,"","")/[1]!thsiFinD("ths_close_price_index",$A17,$AE$3,"","")-1)*100,"") -> 2.2547549 | F17: =IFERROR(([1]!thsiFinD("ths_close_price_index",$A17,$AE$2,"","")/[1]!thsiFinD("ths_close_price_index",$A17,$AE$4,"","")-1)*100,"") -> -2.2380651 | G17: =IFERROR(E17/5-F17/20,"") -> 0.56285423 | H17: 78.13 | I17: 002083.SZ | J17: 孚日股份 | K17: 64.506 | L17: 24.46 | M17: 300888.SZ | N17: 稳健医疗 | O17: 47.6732 | P17: 18.08 | Q17: 002042.SZ | R17: 华孚时尚 | S17: 42.1185 | T17: 15.97 | U17: 601339.SH | V17: 百隆东方 | W17: 25.9815 | X17: 9.85 | Y17: 000726.SZ | Z17: 鲁泰A | AA17: 25.7716 | AB17: 9.77
... A23: CI005320.CI | B23: 生物医药Ⅲ指数 | C23: 84 | D23: =IFERROR(([1]!thsiFinD("ths_close_price_index",$A23,$AE$2,"","")/[1]!thsiFinD("ths_close_price_index",$A23,$AE$5,"","")-1)*100,"") -> -21.025632 | E23: =IFERROR(([1]!thsiFinD("ths_close_price_index",$A23,$AE$2,"","")/[1]!thsiFinD("ths_close_price_index",$A23,$AE$3,"","")-1)*100,"") -> 1.6050567 | F23: =IFERROR(([1]!thsiFinD("ths_close_price_index",$A23,$AE$2,"","")/[1]!thsiFinD("ths_close_price_index",$A23,$AE$4,"","")-1)*100,"") -> -7.124169 | G23: =IFERROR(E23/5-F23/20,"") -> 0.67721979 | H23: 25.36 | I23: 688235.SH | J23: 百济神州 | K23: 263.2349 | L23: 6.25 | M23: 002252.SZ | N23: 上海莱士 | O23: 210.8348 | P23: 5.01 | Q23: 688506.SH | R23: 百利天恒 | S23: 203.3973 | T23: 4.83 | U23: 603087.SH | V23: 甘李药业 | W23: 197.1162 | X23: 4.68 | Y23: 300142.SZ | Z23: 沃森生物 | AA23: 193.1902 | AB23: 4.59
A24: CI005533.CI | B24: 数字金融服务指数 | C24: 2 | D24: =IFERROR(([1]!thsiFinD("ths_close_price_index",$A24,$AE$2,"","")/[1]!thsiFinD("ths_close_price_index",$A24,$AE$5,"","")-1)*100,"") -> -25.834412 | E24: =IFERROR(([1]!thsiFinD("ths_close_price_index",$A24,$AE$2,"","")/[1]!thsiFinD("ths_close_price_index",$A24,$AE$3,"","")-1)*100,"") -> -3.4811007 | F24: =IFERROR(([1]!thsiFinD("ths_close_price_index",$A24,$AE$2,"","")/[1]!thsiFinD("ths_close_price_index",$A24,$AE$4,"","")-1)*100,"") -> -9.452406 | G24: =IFERROR(E24/5-F24/20,"") -> -0.22359984 | H24: 100 | I24: 300773.SZ | J24: 拉卡拉 | K24: 134.1753 | L24: 81.66 | M24: 603123.SH | N24: 翠微股份 | O24: 30.14 | P24: 18.34
A25: CI005452.CI | B25: 电梯指数 | C25: 12 | D25: =IFERROR(([1]!thsiFinD("ths_close_price_index",$A25,$AE$2,"","")/[1]!thsiFinD("ths_close_price_index",$A25,$AE$5,"","")-1)*100,"") -> -10.65691 | E25: =IFERROR(([1]!thsiFinD("ths_close_price_index",$A25,$AE$2,"","")/[1]!thsiFinD("ths_close_price_index",$A25,$AE$3,"","")-1)*100,"") -> -3.0996064 | F25: =IFERROR(([1]!thsiFinD("ths_close_price_index",$A25,$AE$2,"","")/[1]!thsiFinD("ths_close_price_index",$A25,$AE$4,"","")-1)*100,"") -> -6.1801029 | G25: =IFERROR(E25/5-F25/20,"") -> -0.31091614 | H25: 64.65 | I25: 600835.SH | J25: 上海机电 | K25: 70.8457 | L25: 25.14 | M25: 300669.SZ | N25: 沪宁股份 | O25: 33.263 | P25: 11.81 | Q25: 600894.SH | R25: 广日股份 | S25: 30.2195 | T25: 10.73 | U25: 002367.SZ | V25: 康力电梯 | W25: 25.0385 | X25: 8.89 | Y25: 300931.SZ | Z25: 通用电梯 | AA25: 22.7622 | AB25: 8.08
A26: CI005355.CI | B26: 公交指数 | C26: 6 | D26: =IFERROR(([1]!thsiFinD("ths_close_price_index",$A26,$AE$2,"","")/[1]!thsiFinD("ths_close_price_index",$A26,$AE$5,"","")-1)*100,"") -> -28.600451 | E26: =IFERROR(([1]!thsiFinD("ths_close_price_index",$A26,$AE$2,"","")/[1]!thsiFinD("ths_close_price_index",$A26,$AE$3,"","")-1)*100,"") -> -5.922553 | F26: =IFERROR(([1]!thsiFinD("ths_close_price_index",$A26,$AE$2,"","")/[1]!thsiFinD("ths_close_price_index",$A26,$AE$4,"","")-1)*100,"") -> -16.696199 | G26: =IFERROR(E26/5-F26/20,"") -> -0.34970065 | H26: 92.67 | I26: 600611.SH | J26: 大众交通 | K26: 46.5486 | L26: 36.71 | M26: 002357.SZ | N26: 富临运业 | O26: 21.6229 | P26: 17.05 | Q26: 603069.SH | R26: 海汽集团 | S26: 18.003 | T26: 14.2 | U26: 600650.SH | V26: 锦江在线 | W26: 17.5374 | X26: 13.83 | Y26: 600834.SH | Z26: 申通地铁 | AA26: 13.7914 | AB26: 10.88
A27: CI005565.CI | B27: 云基础设施服务指数 | C27: 13 | D27: =IFERROR(([1]!thsiFinD("ths_close_price_index",$A27,$AE$2,"","")/[1]!thsiFinD("ths_close_price_index",$A27,$AE$5,"","")-1)*100,"") -> 15.027812 | E27: =IFERROR(([1]!thsiFinD("ths_close_price_index",$A27,$AE$2,"","")/[1]!thsiFinD("ths_close_price_index",$A27,$AE$3,"","")-1)*100,"") -> -3.2396427 | F27: =IFERROR(([1]!thsiFinD("ths_close_price_index",$A27,$AE$2,"","")/[1]!thsiFinD("ths_close_price_index",$A27,$AE$4,"","")-1)*100,"") -> -9.2431938 | G27: =IFERROR(E27/5-F27/20,"") -> -0.18576884 | H27: 68.14 | I27: 300442.SZ | J27: 润泽科技 | K27: 577.3328 | L27: 26.4 | M27: 300017.SZ | N27: 网宿科技 | O27: 321.2089 | P27: 14.69 | Q27: 300454.SZ | R27: 深信服 | S27: 245.7691 | T27: 11.24 | U27: 300383.SZ | V27: 光环新网 | W27: 188.8693 | X27: 8.64 | Y27: 300738.SZ | Z27: 奥飞数据 | AA27: 156.8503 | AB27: 7.17
A28: CI005408.CI | B28: 贸易流通指数 | C28: 4 | D28: =IFERROR(([1]!thsiFinD("ths_close_price_index",$A28,$AE$2,"","")/[1]!thsiFinD("ths_close_price_index",$A28,$AE$5,"","")-1)*100,"") -> -15.250729 | E28: =IFERROR(([1]!thsiFinD("ths_close_price_index",$A28,$AE$2,"","")/[1]!thsiFinD("ths_close_price_index",$A28,$AE$3,"","")-1)*100,"") -> 5.7422695 | F28: =IFERROR(([1]!thsiFinD("ths_close_price_index",$A28,$AE$2,"","")/[1]!thsiFinD("ths_close_price_index",$A28,$AE$4,"","")-1)*100,"") -> -5.0957807 | G28: =IFERROR(E28/5-F28/20,"") -> 1.4032429 | H28: 100 | I28: 600058.SH | J28: 五矿发展 | K28: 45.3877 | L28: 54.09 | M28: 000906.SZ | N28: 浙商中拓 | O28: 20.4316 | P28: 24.35 | Q28: 605050.SH | R28: 福然德 | S28: 18.0928 | T28: 21.56
A29: CI005418.CI | B29: 其他化学原料指数 | C29: 23 | D29: =IFERROR(([1]!thsiFinD("ths_close_price_index",$A29,$AE$2,"","")/[1]!thsiFinD("ths_close_price_index",$A29,$AE$5,"","")-1)*100,"") -> 34.578953 | E29: =IFERROR(([1]!thsiFinD("ths_close_price_index",$A29,$AE$2,"","")/[1]!thsiFinD("ths_close_price_index",$A29,$AE$3,"","")-1)*100,"") -> 6.963528 | F29: =IFERROR(([1]!thsiFinD("ths_close_price_index",$A29,$AE$2,"","")/[1]!thsiFinD("ths_close_price_index",$A29,$AE$4,"","")-1)*100,"") -> 12.697609 | G29: =IFERROR(E29/5-F29/20,"") -> 0.75782513 | H29: 75.44 | I29: 002648.SZ | J29: 卫星化学 | K29: 382.0021 | L29: 31.54 | M29: 688300.SH | N29: 联瑞新材 | O29: 257.3746 | P29: 21.25 | Q29: 002430.SZ | R29: 杭氧股份 | S29: 108.9079 | T29: 8.99 | U29: 003022.SZ | V29: 联泓新科 | W29: 99.1859 | X29: 8.19 | Y29: 002549.SZ | Z29: 凯美特气 | AA29: 66.2993 | AB29: 5.47
A30: CI005558.CI | B30: 网络覆盖优化与运维指数 | C30: 6 | D30: =IFERROR(([1]!thsiFinD("ths_close_price_index",$A30,$AE$2,"","")/[1]!thsiFinD("ths_close_price_index",$A30,$AE$5,"","")-1)*100,"") -> -12.490011 | E30: =IFERROR(([1]!thsiFinD("ths_close_price_index",$A30,$AE$2,"","")/[1]!thsiFinD("ths_close_price_index",$A30,$AE$3,"","")-1)*100,"") -> -2.8461825 | F30: =IFERROR(([1]!thsiFinD("ths_close_price_index",$A30,$AE$2,"","")/[1]!thsiFinD("ths_close_price_index",$A30,$AE$4,"","")-1)*100,"") -> -11.056619 | G30: =IFERROR(E30/5-F30/20,"") -> -0.016405577 | H30: 97.39 | I30: 300560.SZ | J30: 中富通 | K30: 30.6516 | L30: 23.51 | M30: 300050.SZ | N30: 世纪鼎利 | O30: 29.5291 | P30: 22.65 | Q30: 300310.SZ | R30: 宜通世纪 | S30: 29.4694 | T30: 22.6 | U30: 300025.SZ | V30: 华星创业 | W30: 19.5607 | X30: 15 | Y30: 603206.SH | Z30: 嘉环科技 | AA30: 17.7729 | AB30: 13.63
A31: CI005490.CI | B31: 电商及服务Ⅲ指数 | C31: 17 | D31: =IFERROR(([1]!thsiFinD("ths_close_price_index",$A31,$AE$2,"","")/[1]!thsiFinD("ths_close_price_index",$A31,$AE$5,"","")-1)*100,"") -> 18.084723 | E31: =IFERROR(([1]!thsiFinD("ths_close_price_index",$A31,$AE$2,"","")/[1]!thsiFinD("ths_close_price_index",$A31,$AE$3,"","")-1)*100,"") -> 0.04780603 | F31: =IFERROR(([1]!thsiFinD("ths_close_price_index",$A31,$AE$2,"","")/[1]!thsiFinD("ths_close_price_index",$A31,$AE$4,"","")-1)*100,"") -> -4.3333033 | G31: =IFERROR(E31/5-F31/20,"") -> 0.22622637 | H31: 80.76 | I31: 300209.SZ | J31: 行云科技 | K31: 212.5412 | L31: 41.94 | M31: 002803.SZ | N31: 吉宏股份 | O31: 62.3061 | P31: 12.29 | Q31: 002640.SZ | R31: 跨境通 | S31: 47.57 | T31: 9.39 | U31: 002127.SZ | V31: 南极电商 | W31: 46.0242 | X31: 9.08 | Y31: 003010.SZ | Z31: 若羽臣 | AA31: 40.8279 | AB31: 8.06
A32: CI005563.CI | B32: 行业应用软件指数 | C32: 184 | D32: =IFERROR(([1]!thsiFinD("ths_close_price_index",$A32,$AE$2,"","")/[1]!thsiFinD("ths_close_price_index",$A32,$AE$5,"","")-1)*100,"") -> -13.927759 | E32: =IFERROR(([1]!thsiFinD("ths_close_price_index",$A32,$AE$2,"","")/[1]!thsiFinD("ths_close_price_index",$A32,$AE$3,"","")-1)*100,"") -> -1.6087978 | F32: =IFERROR(([1]!thsiFinD("ths_close_price_index",$A32,$AE$2,"","")/[1]!thsiFinD("ths_close_price_index",$A32,$AE$4,"","")-1)*100,"") -> -5.9870736 | G32: =IFERROR(E32/5-F32/20,"") -> -0.022405876 | H32: 46.01 | I32: 600570.SH | J32: 恒生电子 | K32: 333.7288 | L32: 12.71 | M32: 002261.SZ | N32: 拓维信息 | O32: 310.4848 | P32: 11.82 | Q32: 301269.SZ | R32: 华大九天 | S32: 239.3293 | T32: 9.11 | U32: 002065.SZ | V32: 东华软件 | W32: 162.9713 | X32: 6.21 | Y32: 600536.SH | Z32: 中国软件 | AA32: 161.8781 | AB32: 6.16
A33: CI005317.CI | B33: 化学制剂指数 | C33: 74 | D33: =IFERROR(([1]!thsiFinD("ths_close_price_index",$A33,$AE$2,"","")/[1]!thsiFinD("ths_close_price_index",$A33,$AE$5,"","")-1)*100,"") -> -11.420164 | E33: =IFERROR(([1]!thsiFinD("ths_close_price_index",$A33,$AE$2,"","")/[1]!thsiFinD("ths_close_price_index",$A33,$AE$3,"","")-1)*100,"") -> 3.2798066 | F33: =IFERROR(([1]!thsiFinD("ths_close_price_index",$A33,$AE$2,"","")/[1]!thsiFinD("ths_close_price_index",$A33,$AE$4,"","")-1)*100,"") -> 0.037137418 | G33: =IFERROR(E33/5-F33/20,"") -> 0.65410444 | H33: 73.51 | I33: 600276.SH | J33: 恒瑞医药 | K33: 1919.1493 | L33: 49.55 | M33: 002422.SZ | N33: 科伦药业 | O33: 406.8296 | P33: 10.5 | Q33: 688578.SH | R33: 艾力斯 | S33: 192.1826 | T33: 4.96 | U33: 600079.SH | V33: ST人福 | W33: 174.0025 | X33: 4.49 | Y33: 688266.SH | Z33: 泽璟制药 | AA33: 155.3624 | AB33: 4.01
A34: CI005293.CI | B34: 客车指数 | C34: 6 | D34: =IFERROR(([1]!thsiFinD("ths_close_price_index",$A34,$AE$2,"","")/[1]!thsiFinD("ths_close_price_index",$A34,$AE$5,"","")-1)*100,"") -> -18.11034 | E34: =IFERROR(([1]!thsiFinD("ths_close_price_index",$A34,$AE$2,"","")/[1]!thsiFinD("ths_close_price_index",$A34,$AE$3,"","")-1)*100,"") -> 0.34433546 | F34: =IFERROR(([1]!thsiFinD("ths_close_price_index",$A34,$AE$2,"","")/[1]!thsiFinD("ths_close_price_index",$A34,$AE$4,"","")-1)*100,"") -> -15.846114 | G34: =IFERROR(E34/5-F34/20,"") -> 0.86117278 | H34: 96.98 | I34: 600066.SH | J34: 宇通客车 | K34: 354.1994 | L34: 69.9 | M34: 600686.SH | N34: 金龙汽车 | O34: 49.5622 | P34: 9.78 | Q34: 000957.SZ | R34: 中通客车 | S34: 39.4996 | T34: 7.8 | U34: 600609.SH | V34: 金杯汽车 | W34: 30.6466 | X34: 6.05 | Y34: 000868.SZ | Z34: 安凯客车 | AA34: 17.4736 | AB34: 3.45
A35: CI005425.CI | B35: 电子化学品指数 | C35: 24 | D35: =IFERROR(([1]!thsiFinD("ths_close_price_index",$A35,$AE$2,"","")/[1]!thsiFinD("ths_close_price_index",$A35,$AE$5,"","")-1)*100,"") -> 99.00353 | E35: =IFERROR(([1]!thsiFinD("ths_close_price_index",$A35,$AE$2,"","")/[1]!thsiFinD("ths_close_price_index",$A35,$AE$3,"","")-1)*100,"") -> 6.1844263 | F35: =IFERROR(([1]!thsiFinD("ths_close_price_index",$A35,$AE$2,"","")/[1]!thsiFinD("ths_close_price_index",$A35,$AE$4,"","")-1)*100,"") -> 29.830647 | G35: =IFERROR(E35/5-F35/20,"") -> -0.2546471 | H35: 61.38 | I35: 300285.SZ | J35: 国瓷材料 | K35: 806.4518 | L35: 21.74 | M35: 300054.SZ | N35: 鼎龙股份 | O35: 615.6881 | P35: 16.6 | Q35: 688019.SH | R35: 安集科技 | S35: 412.0659 | T35: 11.11 | U35: 300236.SZ | V35: 上海新阳 | W35: 227.5715 | X35: 6.14 | Y35: 300398.SZ | Z35: 飞凯材料 | AA35: 214.6571 | AB35: 5.79
A36: CI005560.CI | B36: 通用计算机设备指数 | C36: 24 | D36: =IFERROR(([1]!thsiFinD("ths_close_price_index",$A36,$AE$2,"","")/[1]!thsiFinD("ths_close_price_index",$A36,$AE$5,"","")-1)*100,"") -> 27.965479 | E36: =IFERROR(([1]!thsiFinD("ths_close_price_index",$A36,$AE$2,"","")/[1]!thsiFinD("ths_close_price_index",$A36,$AE$3,"","")-1)*100,"") -> 5.0357421 | F36: =IFERROR(([1]!thsiFinD("ths_close_price_index",$A36,$AE$2,"","")/[1]!thsiFinD("ths_close_price_index",$A36,$AE$4,"","")-1)*100,"") -> 6.0053757 | G36: =IFERROR(E36/5-F36/20,"") -> 0.70687963 | H36: 78.8 | I36: 601138.SH | J36: 工业富联 | K36: 2537.4976 | L36: 31.99 | M36: 301308.SZ | N36: 江波龙 | O36: 1396.4275 | P36: 17.6 | Q36: 603019.SH | R36: 中科曙光 | S36: 1087.7655 | T36: 13.71 | U36: 000977.SZ | V36: 浪潮信息 | W36: 654.9753 | X36: 8.26 | Y36: 000938.SZ | Z36: 紫光股份 | AA36: 574.3114 | AB36: 7.24
A37: CI005564.CI | B37: 新兴计算机软件指数 | C37: 6 | D37: =IFERROR(([1]!thsiFinD("ths_close_price_index",$A37,$AE$2,"","")/[1]!thsiFinD("ths_close_price_index",$A37,$AE$5,"","")-1)*100,"") -> -14.685397 | E37: =IFERROR(([1]!thsiFinD("ths_close_price_index",$A37,$AE$2,"","")/[1]!thsiFinD("ths_close_price_index",$A37,$AE$3,"","")-1)*100,"") -> -4.3115381 | F37: =IFERROR(([1]!thsiFinD("ths_close_price_index",$A37,$AE$2,"","")/[1]!thsiFinD("ths_close_price_index",$A37,$AE$4,"","")-1)*100,"") -> -12.554904 | G37: =IFERROR(E37/5-F37/20,"") -> -0.23456244 | H37: 97.47 | I37: 002230.SZ | J37: 科大讯飞 | K37: 819.7338 | L37: 71.65 | M37: 688031.SH | N37: 星环科技 | O37: 100.2613 | P37: 8.76 | Q37: 688088.SH | R37: 虹软科技 | S37: 89.9376 | T37: 7.86 | U37: 688787.SH | V37: 海天瑞声 | W37: 64.1795 | X37: 5.61 | Y37: 688207.SH | Z37: 格灵深瞳 | AA37: 41.0937 | AB37: 3.59
A38: CI005557.CI | B38: 增值服务Ⅲ指数 | C38: 13 | D38: =IFERROR(([1]!thsiFinD("ths_close_price_index",$A38,$AE$2,"","")/[1]!thsiFinD("ths_close_price_index",$A38,$AE$5,"","")-1)*100,"") -> -2.6534483 | E38: =IFERROR(([1]!thsiFinD("ths_close_price_index",$A38,$AE$2,"","")/[1]!thsiFinD("ths_close_price_index",$A38,$AE$3,"","")-1)*100,"") -> -4.4966796 | F38: =IFERROR(([1]!thsiFinD("ths_close_price_index",$A38,$AE$2,"","")/[1]!thsiFinD("ths_close_price_index",$A38,$AE$4,"","")-1)*100,"") -> -10.765722 | G38: =IFERROR(E38/5-F38/20,"") -> -0.36104983 | H38: 58.43 | I38: 000839.SZ | J38: 国安股份 | K38: 73.2453 | L38: 13.5 | M38: 300292.SZ | N38: 吴通控股 | O38: 67.4036 | P38: 12.42 | Q38: 002467.SZ | R38: 二六三 | S38: 63.0134 | T38: 11.61 | U38: 300959.SZ | V38: 线上线下 | W38: 59.2937 | X38: 10.93 | Y38: 002123.SZ | Z38: 梦网科技 | AA38: 54.0636 | AB38: 9.97
A39: CI005554.CI | B39: 通信终端及配件指数 | C39: 30 | D39: =IFERROR(([1]!thsiFinD("ths_close_price_index",$A39,$AE$2,"","")/[1]!thsiFinD("ths_close_price_index",$A39,$AE$5,"","")-1)*100,"") -> 26.898451 | E39: =IFERROR(([1]!thsiFinD("ths_close_price_index",$A39,$AE$2,"","")/[1]!thsiFinD("ths_close_price_index",$A39,$AE$3,"","")-1)*100,"") -> 4.2681039 | F39: =IFERROR(([1]!thsiFinD("ths_close_price_index",$A39,$AE$2,"","")/[1]!thsiFinD("ths_close_price_index",$A39,$AE$4,"","")-1)*100,"") -> 1.4561327 | G39: =IFERROR(E39/5-F39/20,"") -> 0.78081414 | H39: 78.38 | I39: 603083.SH | J39: 剑桥科技 | K39: 564.3233 | L39: 34.78 | M39: 688027.SH | N39: 国盾量子 | O39: 317.3645 | P39: 19.56 | Q39: 300628.SZ | R39: 亿联网络 | S39: 154.1245 | T39: 9.5 | U39: 603236.SH | V39: 移远通信 | W39: 142.812 | X39: 8.8 | Y39: 300638.SZ | Z39: 广和通 | AA39: 93.1183 | AB39: 5.74
A40: CI005578.CI | B40: 其他文化娱乐指数 | C40: 7 | D40: =IFERROR(([1]!thsiFinD("ths_close_price_index",$A40,$AE$2,"","")/[1]!thsiFinD("ths_close_price_index",$A40,$AE$5,"","")-1)*100,"") -> -12.631676 | E40: =IFERROR(([1]!thsiFinD("ths_close_price_index",$A40,$AE$2,"","")/[1]!thsiFinD("ths_close_price_index",$A40,$AE$3,"","")-1)*100,"") -> -2.3298733 | F40: =IFERROR(([1]!thsiFinD("ths_close_price_index",$A40,$AE$2,"","")/[1]!thsiFinD("ths_close_price_index",$A40,$AE$4,"","")-1)*100,"") -> -20.14827 | G40: =IFERROR(E40/5-F40/20,"") -> 0.54143885 | H40: 86.6 | I40: 603533.SH | J40: 掌阅科技 | K40: 58.3757 | L40: 27.88 | M40: 600158.SH | N40: 中体产业 | O40: 52.0681 | P40: 24.87 | Q40: 603466.SH | R40: 风语筑 | S40: 35.7283 | T40: 17.06 | U40: 600136.SH | V40: ST明诚 | W40: 17.8507 | X40: 8.53 | Y40: 300860.SZ | Z40: 锋尚文化 | AA40: 17.2872 | AB40: 8.26
... A48: CI005545.CI | B48: LED指数 | C48: 26 | D48: =IFERROR(([1]!thsiFinD("ths_close_price_index",$A48,$AE$2,"","")/[1]!thsiFinD("ths_close_price_index",$A48,$AE$5,"","")-1)*100,"") -> 19.702331 | E48: =IFERROR(([1]!thsiFinD("ths_close_price_index",$A48,$AE$2,"","")/[1]!thsiFinD("ths_close_price_index",$A48,$AE$3,"","")-1)*100,"") -> 5.5178131 | F48: =IFERROR(([1]!thsiFinD("ths_close_price_index",$A48,$AE$2,"","")/[1]!thsiFinD("ths_close_price_index",$A48,$AE$4,"","")-1)*100,"") -> 5.6637977 | G48: =IFERROR(E48/5-F48/20,"") -> 0.82037274 | H48: 81.7 | I48: 600703.SH | J48: 三安光电 | K48: 654.6462 | L48: 56.05 | M48: 300303.SZ | N48: 聚飞光电 | O48: 111.7501 | P48: 9.57 | Q48: 002654.SZ | R48: 万润科技 | S48: 91.4079 | T48: 7.83 | U48: 300102.SZ | V48: 乾照光电 | W48: 54.2 | X48: 4.64 | Y48: 300219.SZ | Z48: 鸿利智汇 | AA48: 42.1244 | AB48: 3.61
A49: CI005294.CI | B49: 专用汽车指数 | C49: 3 | D49: =IFERROR(([1]!thsiFinD("ths_close_price_index",$A49,$AE$2,"","")/[1]!thsiFinD("ths_close_price_index",$A49,$AE$5,"","")-1)*100,"") -> 39.921973 | E49: =IFERROR(([1]!thsiFinD("ths_close_price_index",$A49,$AE$2,"","")/[1]!thsiFinD("ths_close_price_index",$A49,$AE$3,"","")-1)*100,"") -> -3.004264 | F49: =IFERROR(([1]!thsiFinD("ths_close_price_index",$A49,$AE$2,"","")/[1]!thsiFinD("ths_close_price_index",$A49,$AE$4,"","")-1)*100,"") -> -12.418249 | G49: =IFERROR(E49/5-F49/20,"") -> 0.020059677 | H49: 100 | I49: 601965.SH | J49: 中国汽研 | K49: 46.6219 | L49: 61.68 | M49: 603611.SH | N49: 诺力股份 | O49: 28.9697 | P49: 38.32
A50: CI005297.CI | B50: 摩托车及其他Ⅲ指数 | C50: 13 | D50: =IFERROR(([1]!thsiFinD("ths_close_price_index",$A50,$AE$2,"","")/[1]!thsiFinD("ths_close_price_index",$A50,$AE$5,"","")-1)*100,"") -> -15.701845 | E50: =IFERROR(([1]!thsiFinD("ths_close_price_index",$A50,$AE$2,"","")/[1]!thsiFinD("ths_close_price_index",$A50,$AE$3,"","")-1)*100,"") -> 1.4120549 | F50: =IFERROR(([1]!thsiFinD("ths_close_price_index",$A50,$AE$2,"","")/[1]!thsiFinD("ths_close_price_index",$A50,$AE$4,"","")-1)*100,"") -> -7.4219567 | G50: =IFERROR(E50/5-F50/20,"") -> 0.65350881 | H50: 79.22 | I50: 603129.SH | J50: 春风动力 | K50: 214.0442 | L50: 26.61 | M50: 601777.SH | N50: 千里科技 | O50: 171.181 | P50: 21.28 | Q50: 603766.SH | R50: 隆鑫通用 | S50: 139.926 | T50: 17.4 | U50: 301345.SZ | V50: 涛涛车业 | W50: 62.2649 | X50: 7.74 | Y50: 301322.SZ | Z50: 绿通科技 | AA50: 49.7629 | AB50: 6.19
A51: CI005436.CI | B51: 建筑装修Ⅲ指数 | C51: 27 | D51: =IFERROR(([1]!thsiFinD("ths_close_price_index",$A51,$AE$2,"","")/[1]!thsiFinD("ths_close_price_index",$A51,$AE$5,"","")-1)*100,"") -> 12.722416 | E51: =IFERROR(([1]!thsiFinD("ths_close_price_index",$A51,$AE$2,"","")/[1]!thsiFinD("ths_close_price_index",$A51,$AE$3,"","")-1)*100,"") -> 0.62448854 | F51: =IFERROR(([1]!thsiFinD("ths_close_price_index",$A51,$AE$2,"","")/[1]!thsiFinD("ths_close_price_index",$A51,$AE$4,"","")-1)*100,"") -> -5.2452475 | G51: =IFERROR(E51/5-F51/20,"") -> 0.38716008 | H51: 44.89 | I51: 002081.SZ | J51: 金螳螂 | K51: 63.1568 | L51: 12.47 | M51: 002047.SZ | N51: 宝鹰股份 | O51: 44.8026 | P51: 8.84 | Q51: 600234.SH | R51: 科新发展 | S51: 42.1723 | T51: 8.33 | U51: 300668.SZ | V51: 杰恩股份 | W51: 39.3722 | X51: 7.77 | Y51: 002989.SZ | Z51: 中天精装 | AA51: 37.908 | AB51: 7.48
A52: CI005387.CI | B52: 非棉纺织品指数 | C52: 13 | D52: =IFERROR(([1]!thsiFinD("ths_close_price_index",$A52,$AE$2,"","")/[1]!thsiFinD("ths_close_price_index",$A52,$AE$5,"","")-1)*100,"") -> -13.404022 | E52: =IFERROR(([1]!thsiFinD("ths_close_price_index",$A52,$AE$2,"","")/[1]!thsiFinD("ths_close_price_index",$A52,$AE$3,"","")-1)*100,"") -> -2.3782433 | F52: =IFERROR(([1]!thsiFinD("ths_close_price_index",$A52,$AE$2,"","")/[1]!thsiFinD("ths_close_price_index",$A52,$AE$4,"","")-1)*100,"") -> -10.676649 | G52: =IFERROR(E52/5-F52/20,"") -> 0.058183793 | H52: 51.24 | I52: 603889.SH | J52: 新澳股份 | K52: 29.4978 | L52: 11.82 | M52: 600527.SH | N52: 江南高纤 | O52: 28.2929 | P52: 11.33 | Q52: 601599.SH | R52: 浙文影业 | S52: 27.0496 | T52: 10.84 | U52: 600156.SH | V52: 华升股份 | W52: 21.6966 | X52: 8.69 | Y52: 603055.SH | Z52: 台华新材 | AA52: 21.3591 | AB52: 8.56
...

Sheet 热点热力图
B1: 中信三级行业指数 · 短期热点热力图
B2: 瓦片按【指数自由流通市值】从大到小、从左上到右下排列(市值大→越靠前越显眼)；颜色按【近一周涨跌幅】红涨绿跌、幅度越大越深。数据随上一页(中信三级行业指数热度)iFinD公式自动刷新。 | AG2: =IFERROR(中信三级行业指数热度!G2+ROW()*0.0000000001,-9999) -> 1.0114438
B3: =中信三级行业指数热度!B17&CHAR(10)&TEXT(中信三级行业指数热度!E17,"0.0")&"%" -> 棉纺制品指数 2.3% | C3: =中信三级行业指数热度!B8&CHAR(10)&TEXT(中信三级行业指数热度!E8,"0.0")&"%" -> 医疗服务指数 8.0% | D3: =中信三级行业指数热度!B176&CHAR(10)&TEXT(中信三级行业指数热度!E176,"0.0")&"%" -> 兵器兵装Ⅲ指数 -2.6% | E3: =中信三级行业指数热度!B22&CHAR(10)&TEXT(中信三级行业指数热度!E22,"0.0")&"%" -> 出版指数 1.1% | F3: =中信三级行业指数热度!B75&CHAR(10)&TEXT(中信三级行业指数热度!E75,"0.0")&"%" -> 游戏指数 5.4% | G3: =中信三级行业指数热度!B11&CHAR(10)&TEXT(中信三级行业指数热度!E11,"0.0")&"%" -> 航运指数 6.9% | H3: =中信三级行业指数热度!B10&CHAR(10)&TEXT(中信三级行业指数热度!E10,"0.0")&"%" -> 燃料电池指数 11.0% | I3: =中信三级行业指数热度!B162&CHAR(10)&TEXT(中信三级行业指数热度!E162,"0.0")&"%" -> 农药指数 -1.3% | J3: =中信三级行业指数热度!B212&CHAR(10)&TEXT(中信三级行业指数热度!E212,"0.0")&"%" -> 大众成人品牌服饰指数 -1.1% | K3: =中信三级行业指数热度!B42&CHAR(10)&TEXT(中信三级行业指数热度!E42,"0.0")&"%" -> 综合能源设备指数 -3.2% | L3: =中信三级行业指数热度!B136&CHAR(10)&TEXT(中信三级行业指数热度!E136,"0.0")&"%" -> 其他装饰材料指数 -1.8% | M3: =中信三级行业指数热度!B244&CHAR(10)&TEXT(中信三级行业指数热度!E244,"0.0")&"%" -> 锂指数 0.4% | N3: =中信三级行业指数热度!B122&CHAR(10)&TEXT(中信三级行业指数热度!E122,"0.0")&"%" -> 非乳饮料指数 -4.1% | O3: =中信三级行业指数热度!B18&CHAR(10)&TEXT(中信三级行业指数热度!E18,"0.0")&"%" -> 聚氨酯指数 6.3% | R3: =中信三级行业指数热度!E17 -> 2.2547549 | S3: =中信三级行业指数热度!E8 -> 8.0227067 | T3: =中信三级行业指数热度!E176 -> -2.6072184 | U3: =中信三级行业指数热度!E22 -> 1.1078919 | V3: =中信三级行业指数热度!E75 -> 5.4308486 | W3: =中信三级行业指数热度!E11 -> 6.9384061 | X3: =中信三级行业指数热度!E10 -> 10.99687 | Y3: =中信三级行业指数热度!E162 -> -1.2689345 | Z3: =中信三级行业指数热度!E212 -> -1.1407558 | AA3: =中信三级行业指数热度!E42 -> -3.2413678 | AB3: =中信三级行业指数热度!E136 -> -1.8132384 | AC3: =中信三级行业指数热度!E244 -> 0.41439451 | AD3: =中信三级行业指数热度!E122 -> -4.0586634 | AE3: =中信三级行业指数热度!E18 -> 6.3281788 | AG3: =IFERROR(中信三级行业指数热度!G3+ROW()*0.0000000001,-9999) -> 1.4432608
B4: =中信三级行业指数热度!B121&CHAR(10)&TEXT(中信三级行业指数热度!E121,"0.0")&"%" -> 专业工程及其他指数 -0.4% | C4: =中信三级行业指数热度!B2&CHAR(10)&TEXT(中信三级行业指数热度!E2,"0.0")&"%" -> 半导体设备指数 12.8% | D4: =中信三级行业指数热度!B119&CHAR(10)&TEXT(中信三级行业指数热度!E119,"0.0")&"%" -> 家纺指数 -2.7% | E4: =中信三级行业指数热度!B90&CHAR(10)&TEXT(中信三级行业指数热度!E90,"0.0")&"%" -> 电机指数 -4.8% | F4: =中信三级行业指数热度!B107&CHAR(10)&TEXT(中信三级行业指数热度!E107,"0.0")&"%" -> 民爆用品指数 -5.5% | G4: =中信三级行业指数热度!B157&CHAR(10)&TEXT(中信三级行业指数热度!E157,"0.0")&"%" -> 粘胶指数 3.3% | H4: =中信三级行业指数热度!B9&CHAR(10)&TEXT(中信三级行业指数热度!E9,"0.0")&"%" -> 显示零组指数 4.5% | I4: =中信三级行业指数热度!B139&CHAR(10)&TEXT(中信三级行业指数热度!E139,"0.0")&"%" -> 中成药指数 -1.6% | J4: =中信三级行业指数热度!B51&CHAR(10)&TEXT(中信三级行业指数热度!E51,"0.0")&"%" -> 建筑装修Ⅲ指数 0.6% | K4: =中信三级行业指数热度!B151&CHAR(10)&TEXT(中信三级行业指数热度!E151,"0.0")&"%" -> 贸易Ⅲ指数 -2.2% | L4: =中信三级行业指数热度!B3&CHAR(10)&TEXT(中信三级行业指数热度!E3,"0.0")&"%" -> 分立器件指数 10.7% | M4: =中信三级行业指数热度!B231&CHAR(10)&TEXT(中信三级行业指数热度!E231,"0.0")&"%" -> 其他发电指数 -4.6% | N4: =中信三级行业指数热度!B52&CHAR(10)&TEXT(中信三级行业指数热度!E52,"0.0")&"%" -> 非棉纺织品指数 -2.4% | O4: =中信三级行业指数热度!B179&CHAR(10)&TEXT(中信三级行业指数热度!E179,"0.0")&"%" -> 其他广告营销指数 -3.4% | R4: =中信三级行业指数热度!E121 -> -0.42343967 | S4: =中信三级行业指数热度!E2 -> 12.773946 | T4: =中信三级行业指数热度!E119 -> -2.7194189 | U4: =中信三级行业指数热度!E90 -> -4.8138015 | V4: =中信三级行业指数热度!E107 -> -5.4890528 | W4: =中信三级行业指数热度!E157 -> 3.3241071 | X4: =中信三级行业指数热度!E9 -> 4.5272635 | Y4: =中信三级行业指数热度!E139 -> -1.562442 | Z4: =中信三级行业指数热度!E51 -> 0.62448854 | AA4: =中信三级行业指数热度!E151 -> -2.2082612 | AB4: =中信三级行业指数热度!E3 -> 10.727 | AC4: =中信三级行业指数热度!E231 -> -4.5923337 | AD4: =中信三级行业指数热度!E52 -> -2.3782433 | AE4: =中信三级行业指数热度!E179 -> -3.3590513 | AG4: =IFERROR(中信三级行业指数热度!G4+ROW()*0.0000000001,-9999) -> -1.7374558
B5: =中信三级行业指数热度!B246&CHAR(10)&TEXT(中信三级行业指数热度!E246,"0.0")&"%" -> 日用化学品指数 -7.3% | C5: =中信三级行业指数热度!B146&CHAR(10)&TEXT(中信三级行业指数热度!E146,"0.0")&"%" -> 综合业态指数 -3.0% | D5: =中信三级行业指数热度!B94&CHAR(10)&TEXT(中信三级行业指数热度!E94,"0.0")&"%" -> 锂电化学品指数 1.8% | E5: =中信三级行业指数热度!B12&CHAR(10)&TEXT(中信三级行业指数热度!E12,"0.0")&"%" -> 面板指数 11.9% | F5: =中信三级行业指数热度!B32&CHAR(10)&TEXT(中信三级行业指数热度!E32,"0.0")&"%" -> 行业应用软件指数 -1.6% | G5: =中信三级行业指数热度!B31&CHAR(10)&TEXT(中信三级行业指数热度!E31,"0.0")&"%" -> 电商及服务Ⅲ指数 0.0% | H5: =中信三级行业指数热度!B49&CHAR(10)&TEXT(中信三级行业指数热度!E49,"0.0")&"%" -> 专用汽车指数 -3.0% | I5: =中信三级行业指数热度!B27&CHAR(10)&TEXT(中信三级行业指数热度!E27,"0.0")&"%" -> 云基础设施服务指数 -3.2% | J5: =中信三级行业指数热度!B103&CHAR(10)&TEXT(中信三级行业指数热度!E103,"0.0")&"%" -> 物业管理服务指数 -3.7% | K5: =中信三级行业指数热度!B79&CHAR(10)&TEXT(中信三级行业指数热度!E79,"0.0")&"%" -> 儿童品牌指数 -2.7% | L5: =中信三级行业指数热度!B196&CHAR(10)&TEXT(中信三级行业指数热度!E196,"0.0")&"%" -> 合成树脂指数 0.2% | M5: =中信三级行业指数热度!B144&CHAR(10)&TEXT(中信三级行业指数热度!E144,"0.0")&"%" -> 综合Ⅲ指数 -3.1% | N5: =中信三级行业指数热度!B59&CHAR(10)&TEXT(中信三级行业指数热度!E59,"0.0")&"%" -> 叉车指数 -4.9% | O5: =中信三级行业指数热度!B240&CHAR(10)&TEXT(中信三级行业指数热度!E240,"0.0")&"%" -> 电网指数 -6.4% | R5: =中信三级行业指数热度!E246 -> -7.3117274 | S5: =中信三级行业指数热度!E146 -> -3.0313633 | T5: =中信三级行业指数热度!E94 -> 1.7882459 | U5: =中信三级行业指数热度!E12 -> 11.871478 | V5: =中信三级行业指数热度!E32 -> -1.6087978 | W5: =中信三级行业指数热度!E31 -> 0.04780603 | X5: =中信三级行业指数热度!E49 -> -3.004264 | Y5: =中信三级行业指数热度!E27 -> -3.2396427 | Z5: =中信三级行业指数热度!E103 -> -3.6555789 | AA5: =中信三级行业指数热度!E79 -> -2.7135273 | AB5: =中信三级行业指数热度!E196 -> 0.20972669 | AC5: =中信三级行业指数热度!E144 -> -3.1086603 | AD5: =中信三级行业指数热度!E59 -> -4.9300912 | AE5: =中信三级行业指数热度!E240 -> -6.4487407 | AG5: =IFERROR(中信三级行业指数热度!G5+ROW()*0.0000000001,-9999) -> 1.3061596
B6: =中信三级行业指数热度!B40&CHAR(10)&TEXT(中信三级行业指数热度!E40,"0.0")&"%" -> 其他文化娱乐指数 -2.3% | C6: =中信三级行业指数热度!B173&CHAR(10)&TEXT(中信三级行业指数热度!E173,"0.0")&"%" -> K12培训指数 -3.3% | D6: =中信三级行业指数热度!B91&CHAR(10)&TEXT(中信三级行业指数热度!E91,"0.0")&"%" -> 储能指数 0.1% | E6: =中信三级行业指数热度!B210&CHAR(10)&TEXT(中信三级行业指数热度!E210,"0.0")&"%" -> 酒店指数 -3.9% | F6: =中信三级行业指数热度!B181&CHAR(10)&TEXT(中信三级行业指数热度!E181,"0.0")&"%" -> 造纸Ⅲ指数 -3.5% | G6: =中信三级行业指数热度!B152&CHAR(10)&TEXT(中信三级行业指数热度!E152,"0.0")&"%" -> 水产养殖指数 -3.9% | H6: =中信三级行业指数热度!B108&CHAR(10)&TEXT(中信三级行业指数热度!E108,"0.0")&"%" -> 住宅物业开发指数 -2.5% | I6: =中信三级行业指数热度!B21&CHAR(10)&TEXT(中信三级行业指数热度!E21,"0.0")&"%" -> 油品销售及仓储指数 -0.6% | J6: =中信三级行业指数热度!B189&CHAR(10)&TEXT(中信三级行业指数热度!E189,"0.0")&"%" -> 其他运输设备指数 0.1% | K6: =中信三级行业指数热度!B77&CHAR(10)&TEXT(中信三级行业指数热度!E77,"0.0")&"%" -> 产业互联网综合服务指数 -3.7% | L6: =中信三级行业指数热度!B53&CHAR(10)&TEXT(中信三级行业指数热度!E53,"0.0")&"%" -> 信托指数 1.0% | M6: =中信三级行业指数热度!B20&CHAR(10)&TEXT(中信三级行业指数热度!E20,"0.0")&"%" -> 供热或其他指数 4.8% | N6: =中信三级行业指数热度!B46&CHAR(10)&TEXT(中信三级行业指数热度!E46,"0.0")&"%" -> 消费电子设备指数 -1.9% | O6: =中信三级行业指数热度!B48&CHAR(10)&TEXT(中信三级行业指数热度!E48,"0.0")&"%" -> LED指数 5.5% | R6: =中信三级行业指数热度!E40 -> -2.3298733 | S6: =中信三级行业指数热度!E173 -> -3.2914106 | T6: =中信三级行业指数热度!E91 -> 0.10720697 | U6: =中信三级行业指数热度!E210 -> -3.9462635 | V6: =中信三级行业指数热度!E181 -> -3.5052281 | W6: =中信三级行业指数热度!E152 -> -3.922558 | X6: =中信三级行业指数热度!E108 -> -2.5388852 | Y6: =中信三级行业指数热度!E21 -> -0.58729821 | Z6: =中信三级行业指数热度!E189 -> 0.1142829 | AA6: =中信三级行业指数热度!E77 -> -3.6863552 | AB6: =中信三级行业指数热度!E53 -> 1.0053474 | AC6: =中信三级行业指数热度!E20 -> 4.7657774 | AD6: =中信三级行业指数热度!E46 -> -1.8528563 | AE6: =中信三级行业指数热度!E48 -> 5.5178131 | AG6: =IFERROR(中信三级行业指数热度!G6+ROW()*0.0000000001,-9999) -> 2.0023683
B7: =中信三级行业指数热度!B6&CHAR(10)&TEXT(中信三级行业指数热度!E6,"0.0")&"%" -> 橡胶助剂指数 17.0% | C7: =中信三级行业指数热度!B47&CHAR(10)&TEXT(中信三级行业指数热度!E47,"0.0")&"%" -> 证券Ⅲ指数 9.5% | D7: =中信三级行业指数热度!B62&CHAR(10)&TEXT(中信三级行业指数热度!E62,"0.0")&"%" -> 半导体材料指数 10.2% | E7: =中信三级行业指数热度!B80&CHAR(10)&TEXT(中信三级行业指数热度!E80,"0.0")&"%" -> 咨询实施及其他服务指数 -3.0% | F7: =中信三级行业指数热度!B5&CHAR(10)&TEXT(中信三级行业指数热度!E5,"0.0")&"%" -> 集成电路指数 10.9% | G7: =中信三级行业指数热度!B74&CHAR(10)&TEXT(中信三级行业指数热度!E74,"0.0")&"%" -> 工程服务指数 1.7% | H7: =中信三级行业指数热度!B23&CHAR(10)&TEXT(中信三级行业指数热度!E23,"0.0")&"%" -> 生物医药Ⅲ指数 1.6% | I7: =中信三级行业指数热度!B35&CHAR(10)&TEXT(中信三级行业指数热度!E35,"0.0")&"%" -> 电子化学品指数 6.2% | J7: =中信三级行业指数热度!B71&CHAR(10)&TEXT(中信三级行业指数热度!E71,"0.0")&"%" -> 公路指数 -1.0% | K7: =中信三级行业指数热度!B88&CHAR(10)&TEXT(中信三级行业指数热度!E88,"0.0")&"%" -> 调味品指数 2.6% | L7: =中信三级行业指数热度!B4&CHAR(10)&TEXT(中信三级行业指数热度!E4,"0.0")&"%" -> 碳纤维指数 -0.9% | M7: =中信三级行业指数热度!B245&CHAR(10)&TEXT(中信三级行业指数热度!E245,"0.0")&"%" -> PCB指数 0.9% | N7: =中信三级行业指数热度!B16&CHAR(10)&TEXT(中信三级行业指数热度!E16,"0.0")&"%" -> 其他专用材料指数 6.7% | O7: =中信三级行业指数热度!B66&CHAR(10)&TEXT(中信三级行业指数热度!E66,"0.0")&"%" -> 金属包装指数 -4.8% | R7: =中信三级行业指数热度!E6 -> 16.97181 | S7: =中信三级行业指数热度!E47 -> 9.4874126 | T7: =中信三级行业指数热度!E62 -> 10.235065 | U7: =中信三级行业指数热度!E80 -> -2.9533878 | V7: =中信三级行业指数热度!E5 -> 10.902559 | W7: =中信三级行业指数热度!E74 -> 1.7380063 | X7: =中信三级行业指数热度!E23 -> 1.6050567 | Y7: =中信三级行业指数热度!E35 -> 6.1844263 | Z7: =中信三级行业指数热度!E71 -> -1.0044199 | AA7: =中信三级行业指数热度!E88 -> 2.6233097 | AB7: =中信三级行业指数热度!E4 -> -0.93914612 | AC7: =中信三级行业指数热度!E245 -> 0.85090171 | AD7: =中信三级行业指数热度!E16 -> 6.7269618 | AE7: =中信三级行业指数热度!E66 -> -4.7827773 | AG7: =IFERROR(中信三级行业指数热度!G7+ROW()*0.0000000001,-9999) -> -0.059352781
B8: =中信三级行业指数热度!B184&CHAR(10)&TEXT(中信三级行业指数热度!E184,"0.0")&"%" -> 高等及职业教育指数 -5.4% | C8: =中信三级行业指数热度!B99&CHAR(10)&TEXT(中信三级行业指数热度!E99,"0.0")&"%" -> 其他通用机械指数 -2.3% | D8: =中信三级行业指数热度!B123&CHAR(10)&TEXT(中信三级行业指数热度!E123,"0.0")&"%" -> 照明电工指数 -2.4% | E8: =中信三级行业指数热度!B142&CHAR(10)&TEXT(中信三级行业指数热度!E142,"0.0")&"%" -> 工业机器人及工控系统指数 -4.2% | F8: =中信三级行业指数热度!B182&CHAR(10)&TEXT(中信三级行业指数热度!E182,"0.0")&"%" -> 动物疫苗及兽药指数 0.9% | G8: =中信三级行业指数热度!B43&CHAR(10)&TEXT(中信三级行业指数热度!E43,"0.0")&"%" -> 其他化学制品Ⅲ指数 4.7% | H8: =中信三级行业指数热度!B67&CHAR(10)&TEXT(中信三级行业指数热度!E67,"0.0")&"%" -> 网络规划设计和工程施工指数 -3.0% | I8: =中信三级行业指数热度!B124&CHAR(10)&TEXT(中信三级行业指数热度!E124,"0.0")&"%" -> 复合肥指数 2.5% | J8: =中信三级行业指数热度!B25&CHAR(10)&TEXT(中信三级行业指数热度!E25,"0.0")&"%" -> 电梯指数 -3.1% | K8: =中信三级行业指数热度!B56&CHAR(10)&TEXT(中信三级行业指数热度!E56,"0.0")&"%" -> 风电指数 -3.9% | L8: =中信三级行业指数热度!B60&CHAR(10)&TEXT(中信三级行业指数热度!E60,"0.0")&"%" -> 消费电子组件指数 2.2% | M8: =中信三级行业指数热度!B253&CHAR(10)&TEXT(中信三级行业指数热度!E253,"0.0")&"%" -> 钨指数 3.9% | N8: =中信三级行业指数热度!B140&CHAR(10)&TEXT(中信三级行业指数热度!E140,"0.0")&"%" -> 互联网广告营销指数 -6.0% | O8: =中信三级行业指数热度!B205&CHAR(10)&TEXT(中信三级行业指数热度!E205,"0.0")&"%" -> 锂电池指数 1.9% | R8: =中信三级行业指数热度!E184 -> -5.3761573 | S8: =中信三级行业指数热度!E99 -> -2.280407 | T8: =中信三级行业指数热度!E123 -> -2.4003137 | U8: =中信三级行业指数热度!E142 -> -4.2265309 | V8: =中信三级行业指数热度!E182 -> 0.89582655 | W8: =中信三级行业指数热度!E43 -> 4.6832542 | X8: =中信三级行业指数热度!E67 -> -2.9639123 | Y8: =中信三级行业指数热度!E124 -> 2.5221256 | Z8: =中信三级行业指数热度!E25 -> -3.0996064 | AA8: =中信三级行业指数热度!E56 -> -3.942318 | AB8: =中信三级行业指数热度!E60 -> 2.1752303 | AC8: =中信三级行业指数热度!E253 -> 3.9172175 | AD8: =中信三级行业指数热度!E140 -> -6.0497267 | AE8: =中信三级行业指数热度!E205 -> 1.8665407 | AG8: =IFERROR(中信三级行业指数热度!G8+ROW()*0.0000000001,-9999) -> 1.3538775
B9: =中信三级行业指数热度!B150&CHAR(10)&TEXT(中信三级行业指数热度!E150,"0.0")&"%" -> 其他通信设备指数 -1.9% | C9: =中信三级行业指数热度!B34&CHAR(10)&TEXT(中信三级行业指数热度!E34,"0.0")&"%" -> 客车指数 0.3% | D9: =中信三级行业指数热度!B137&CHAR(10)&TEXT(中信三级行业指数热度!E137,"0.0")&"%" -> 其他石化指数 7.7% | E9: =中信三级行业指数热度!B19&CHAR(10)&TEXT(中信三级行业指数热度!E19,"0.0")&"%" -> 钛白粉指数 9.5% | F9: =中信三级行业指数热度!B165&CHAR(10)&TEXT(中信三级行业指数热度!E165,"0.0")&"%" -> 无机盐指数 9.5% | G9: =中信三级行业指数热度!B82&CHAR(10)&TEXT(中信三级行业指数热度!E82,"0.0")&"%" -> 输变电设备指数 -1.0% | H9: =中信三级行业指数热度!B69&CHAR(10)&TEXT(中信三级行业指数热度!E69,"0.0")&"%" -> 起重运输设备指数 -6.8% | I9: =中信三级行业指数热度!B101&CHAR(10)&TEXT(中信三级行业指数热度!E101,"0.0")&"%" -> 食品及饲料添加剂指数 -4.6% | J9: =中信三级行业指数热度!B28&CHAR(10)&TEXT(中信三级行业指数热度!E28,"0.0")&"%" -> 贸易流通指数 5.7% | K9: =中信三级行业指数热度!B131&CHAR(10)&TEXT(中信三级行业指数热度!E131,"0.0")&"%" -> 基建建设指数 -3.2% | L9: =中信三级行业指数热度!B37&CHAR(10)&TEXT(中信三级行业指数热度!E37,"0.0")&"%" -> 新兴计算机软件指数 -4.3% | M9: =中信三级行业指数热度!B61&CHAR(10)&TEXT(中信三级行业指数热度!E61,"0.0")&"%" -> 印染指数 -2.3% | N9: =中信三级行业指数热度!B57&CHAR(10)&TEXT(中信三级行业指数热度!E57,"0.0")&"%" -> 陶瓷指数 -6.1% | O9: =中信三级行业指数热度!B166&CHAR(10)&TEXT(中信三级行业指数热度!E166,"0.0")&"%" -> 种业指数 -5.1% | R9: =中信三级行业指数热度!E150 -> -1.9073685 | S9: =中信三级行业指数热度!E34 -> 0.34433546 | T9: =中信三级行业指数热度!E137 -> 7.7417234 | U9: =中信三级行业指数热度!E19 -> 9.5045087 | V9: =中信三级行业指数热度!E165 -> 9.4669789 | W9: =中信三级行业指数热度!E82 -> -1.0471866 | X9: =中信三级行业指数热度!E69 -> -6.8028734 | Y9: =中信三级行业指数热度!E101 -> -4.5537994 | Z9: =中信三级行业指数热度!E28 -> 5.7422695 | AA9: =中信三级行业指数热度!E131 -> -3.205189 | AB9: =中信三级行业指数热度!E37 -> -4.3115381 | AC9: =中信三级行业指数热度!E61 -> -2.2880362 | AD9: =中信三级行业指数热度!E57 -> -6.070654 | AE9: =中信三级行业指数热度!E166 -> -5.1153833 | AG9: =IFERROR(中信三级行业指数热度!G9+ROW()*0.0000000001,-9999) -> 0.49754206
B10: =中信三级行业指数热度!B172&CHAR(10)&TEXT(中信三级行业指数热度!E172,"0.0")&"%" -> 氮肥指数 0.7% | C10: =中信三级行业指数热度!B158&CHAR(10)&TEXT(中信三级行业指数热度!E158,"0.0")&"%" -> 汽车零部件Ⅲ指数 -5.3% | D10: =中信三级行业指数热度!B87&CHAR(10)&TEXT(中信三级行业指数热度!E87,"0.0")&"%" -> 其他时尚品指数 -5.8% | E10: =中信三级行业指数热度!B86&CHAR(10)&TEXT(中信三级行业指数热度!E86,"0.0")&"%" -> 动漫指数 -1.5% | F10: =中信三级行业指数热度!B147&CHAR(10)&TEXT(中信三级行业指数热度!E147,"0.0")&"%" -> 涤纶指数 -2.0% | G10: =中信三级行业指数热度!B145&CHAR(10)&TEXT(中信三级行业指数热度!E145,"0.0")&"%" -> 家具指数 -2.6% | H10: =中信三级行业指数热度!B81&CHAR(10)&TEXT(中信三级行业指数热度!E81,"0.0")&"%" -> 其他家电指数 -3.9% | I10: =中信三级行业指数热度!B63&CHAR(10)&TEXT(中信三级行业指数热度!E63,"0.0")&"%" -> 激光加工设备指数 10.2% | J10: =中信三级行业指数热度!B116&CHAR(10)&TEXT(中信三级行业指数热度!E116,"0.0")&"%" -> 互联网影视音频指数 -3.9% | K10: =中信三级行业指数热度!B45&CHAR(10)&TEXT(中信三级行业指数热度!E45,"0.0")&"%" -> 专用计算机设备指数 -3.9% | L10: =中信三级行业指数热度!B237&CHAR(10)&TEXT(中信三级行业指数热度!E237,"0.0")&"%" -> 专业市场经营Ⅲ指数 -4.8% | M10: =中信三级行业指数热度!B104&CHAR(10)&TEXT(中信三级行业指数热度!E104,"0.0")&"%" -> 信息搜索与聚合指数 -3.9% | N10: =中信三级行业指数热度!B185&CHAR(10)&TEXT(中信三级行业指数热度!E185,"0.0")&"%" -> 黑色家电Ⅲ指数 -2.4% | O10: =中信三级行业指数热度!B7&CHAR(10)&TEXT(中信三级行业指数热度!E7,"0.0")&"%" -> 卡车指数 -4.0% | R10: =中信三级行业指数热度!E172 -> 0.72417155 | S10: =中信三级行业指数热度!E158 -> -5.309339 | T10: =中信三级行业指数热度!E87 -> -5.7997538 | U10: =中信三级行业指数热度!E86 -> -1.5361117 | V10: =中信三级行业指数热度!E147 -> -2.0492156 | W10: =中信三级行业指数热度!E145 -> -2.6004325 | X10: =中信三级行业指数热度!E81 -> -3.9366798 | Y10: =中信三级行业指数热度!E63 -> 10.215833 | Z10: =中信三级行业指数热度!E116 -> -3.9141197 | AA10: =中信三级行业指数热度!E45 -> -3.8965396 | AB10: =中信三级行业指数热度!E237 -> -4.810784 | AC10: =中信三级行业指数热度!E104 -> -3.8904647 | AD10: =中信三级行业指数热度!E185 -> -2.4318222 | AE10: =中信三级行业指数热度!E7 -> -4.0003812 | AG10: =IFERROR(中信三级行业指数热度!G10+ROW()*0.0000000001,-9999) -> 1.53834
B11: =中信三级行业指数热度!B84&CHAR(10)&TEXT(中信三级行业指数热度!E84,"0.0")&"%" -> 医疗器械指数 -1.6% | C11: =中信三级行业指数热度!B225&CHAR(10)&TEXT(中信三级行业指数热度!E225,"0.0")&"%" -> 航空指数 3.0% | D11: =中信三级行业指数热度!B15&CHAR(10)&TEXT(中信三级行业指数热度!E15,"0.0")&"%" -> 特钢指数 -1.9% | E11: =中信三级行业指数热度!B128&CHAR(10)&TEXT(中信三级行业指数热度!E128,"0.0")&"%" -> 教育信息化及在线教育指数 -6.6% | F11: =中信三级行业指数热度!B200&CHAR(10)&TEXT(中信三级行业指数热度!E200,"0.0")&"%" -> 水电指数 -2.3% | G11: =中信三级行业指数热度!B141&CHAR(10)&TEXT(中信三级行业指数热度!E141,"0.0")&"%" -> 厨房电器Ⅲ指数 -2.3% | H11: =中信三级行业指数热度!B251&CHAR(10)&TEXT(中信三级行业指数热度!E251,"0.0")&"%" -> 服务综合指数 -8.0% | I11: =中信三级行业指数热度!B206&CHAR(10)&TEXT(中信三级行业指数热度!E206,"0.0")&"%" -> 百货指数 -4.0% | J11: =中信三级行业指数热度!B215&CHAR(10)&TEXT(中信三级行业指数热度!E215,"0.0")&"%" -> 石油开采Ⅲ指数 -7.0% | K11: =中信三级行业指数热度!B129&CHAR(10)&TEXT(中信三级行业指数热度!E129,"0.0")&"%" -> 线缆指数 15.7% | L11: =中信三级行业指数热度!B252&CHAR(10)&TEXT(中信三级行业指数热度!E252,"0.0")&"%" -> 有机硅指数 -0.6% | M11: =中信三级行业指数热度!B202&CHAR(10)&TEXT(中信三级行业指数热度!E202,"0.0")&"%" -> 休闲食品指数 -1.5% | N11: =中信三级行业指数热度!B118&CHAR(10)&TEXT(中信三级行业指数热度!E118,"0.0")&"%" -> 其他纺织指数 0.0% | O11: =中信三级行业指数热度!B207&CHAR(10)&TEXT(中信三级行业指数热度!E207,"0.0")&"%" -> 其他电子零组件Ⅲ指数 1.1% | R11: =中信三级行业指数热度!E84 -> -1.5751358 | S11: =中信三级行业指数热度!E225 -> 3.0282445 | T11: =中信三级行业指数热度!E15 -> -1.8536246 | U11: =中信三级行业指数热度!E128 -> -6.6274644 | V11: =中信三级行业指数热度!E200 -> -2.3319551 | W11: =中信三级行业指数热度!E141 -> -2.3229648 | X11: =中信三级行业指数热度!E251 -> -7.9524702 | Y11: =中信三级行业指数热度!E206 -> -3.9966181 | Z11: =中信三级行业指数热度!E215 -> -6.9647159 | AA11: =中信三级行业指数热度!E129 -> 15.676661 | AB11: =中信三级行业指数热度!E252 -> -0.64215108 | AC11: =中信三级行业指数热度!E202 -> -1.524849 | AD11: =中信三级行业指数热度!E118 -> 0.047723483 | AE11: =中信三级行业指数热度!E207 -> 1.0998687 | AG11: =IFERROR(中信三级行业指数热度!G11+ROW()*0.0000000001,-9999) -> 1.1188516
B12: =中信三级行业指数热度!B218&CHAR(10)&TEXT(中信三级行业指数热度!E218,"0.0")&"%" -> 超市及便利店指数 -2.9% | C12: =中信三级行业指数热度!B198&CHAR(10)&TEXT(中信三级行业指数热度!E198,"0.0")&"%" -> 板材指数 -3.2% | D12: =中信三级行业指数热度!B203&CHAR(10)&TEXT(中信三级行业指数热度!E203,"0.0")&"%" -> 其他军工Ⅲ指数 -3.2% | E12: =中信三级行业指数热度!B155&CHAR(10)&TEXT(中信三级行业指数热度!E155,"0.0")&"%" -> 基础软件及管理办公软件指数 -7.2% | F12: =中信三级行业指数热度!B125&CHAR(10)&TEXT(中信三级行业指数热度!E125,"0.0")&"%" -> 电力电子及自动化指数 -3.2% | G12: =中信三级行业指数热度!B178&CHAR(10)&TEXT(中信三级行业指数热度!E178,"0.0")&"%" -> 印刷指数 -9.1% | H12: =中信三级行业指数热度!B156&CHAR(10)&TEXT(中信三级行业指数热度!E156,"0.0")&"%" -> 乳制品指数 0.4% | I12: =中信三级行业指数热度!B96&CHAR(10)&TEXT(中信三级行业指数热度!E96,"0.0")&"%" -> 其他结构材料指数 -3.3% | J12: =中信三级行业指数热度!B186&CHAR(10)&TEXT(中信三级行业指数热度!E186,"0.0")&"%" -> 园林工程指数 -5.3% | K12: =中信三级行业指数热度!B54&CHAR(10)&TEXT(中信三级行业指数热度!E54,"0.0")&"%" -> 中药饮片指数 -8.8% | L12: =中信三级行业指数热度!B190&CHAR(10)&TEXT(中信三级行业指数热度!E190,"0.0")&"%" -> 珠宝首饰及钟表指数 -3.6% | M12: =中信三级行业指数热度!B68&CHAR(10)&TEXT(中信三级行业指数热度!E68,"0.0")&"%" -> 油气装备指数 -1.9% | N12: =中信三级行业指数热度!B126&CHAR(10)&TEXT(中信三级行业指数热度!E126,"0.0")&"%" -> 铝指数 -2.4% | O12: =中信三级行业指数热度!B233&CHAR(10)&TEXT(中信三级行业指数热度!E233,"0.0")&"%" -> 全国性股份制银行Ⅲ指数 -2.2% | R12: =中信三级行业指数热度!E218 -> -2.9449684 | S12: =中信三级行业指数热度!E198 -> -3.1920895 | T12: =中信三级行业指数热度!E203 -> -3.1636281 | U12: =中信三级行业指数热度!E155 -> -7.2124035 | V12: =中信三级行业指数热度!E125 -> -3.2124474 | W12: =中信三级行业指数热度!E178 -> -9.0793174 | X12: =中信三级行业指数热度!E156 -> 0.37709553 | Y12: =中信三级行业指数热度!E96 -> -3.310468 | Z12: =中信三级行业指数热度!E186 -> -5.3413633 | AA12: =中信三级行业指数热度!E54 -> -8.8269993 | AB12: =中信三级行业指数热度!E190 -> -3.5500377 | AC12: =中信三级行业指数热度!E68 -> -1.8947478 | AD12: =中信三级行业指数热度!E126 -> -2.4044909 | AE12: =中信三级行业指数热度!E233 -> -2.2401415 | AG12: =IFERROR(中信三级行业指数热度!G12+ROW()*0.0000000001,-9999) -> 1.0921849
B13: =中信三级行业指数热度!B38&CHAR(10)&TEXT(中信三级行业指数热度!E38,"0.0")&"%" -> 增值服务Ⅲ指数 -4.5% | C13: =中信三级行业指数热度!B106&CHAR(10)&TEXT(中信三级行业指数热度!E106,"0.0")&"%" -> 影视指数 -1.9% | D13: =中信三级行业指数热度!B29&CHAR(10)&TEXT(中信三级行业指数热度!E29,"0.0")&"%" -> 其他化学原料指数 7.0% | E13: =中信三级行业指数热度!B192&CHAR(10)&TEXT(中信三级行业指数热度!E192,"0.0")&"%" -> 畜牧养殖指数 -3.9% | F13: =中信三级行业指数热度!B113&CHAR(10)&TEXT(中信三级行业指数热度!E113,"0.0")&"%" -> 港口指数 -2.1% | G13: =中信三级行业指数热度!B223&CHAR(10)&TEXT(中信三级行业指数热度!E223,"0.0")&"%" -> 乘用车Ⅲ指数 -6.1% | H13: =中信三级行业指数热度!B256&CHAR(10)&TEXT(中信三级行业指数热度!E256,"0.0")&"%" -> 火电指数 -4.6% | I13: =中信三级行业指数热度!B14&CHAR(10)&TEXT(中信三级行业指数热度!E14,"0.0")&"%" -> 化学原料药指数 4.6% | J13: =中信三级行业指数热度!B110&CHAR(10)&TEXT(中信三级行业指数热度!E110,"0.0")&"%" -> 其他专用机械指数 0.0% | K13: =中信三级行业指数热度!B64&CHAR(10)&TEXT(中信三级行业指数热度!E64,"0.0")&"%" -> 其他食品指数 1.1% | L13: =中信三级行业指数热度!B238&CHAR(10)&TEXT(中信三级行业指数热度!E238,"0.0")&"%" -> 玻璃指数 -0.7% | M13: =中信三级行业指数热度!B194&CHAR(10)&TEXT(中信三级行业指数热度!E194,"0.0")&"%" -> 氯碱指数 3.2% | N13: =中信三级行业指数热度!B97&CHAR(10)&TEXT(中信三级行业指数热度!E97,"0.0")&"%" -> 物业经纪服务指数 -4.1% | O13: =中信三级行业指数热度!B85&CHAR(10)&TEXT(中信三级行业指数热度!E85,"0.0")&"%" -> 磷肥及磷化工指数 13.0% | R13: =中信三级行业指数热度!E38 -> -4.4966796 | S13: =中信三级行业指数热度!E106 -> -1.8508264 | T13: =中信三级行业指数热度!E29 -> 6.963528 | U13: =中信三级行业指数热度!E192 -> -3.8910515 | V13: =中信三级行业指数热度!E113 -> -2.092177 | W13: =中信三级行业指数热度!E223 -> -6.0856247 | X13: =中信三级行业指数热度!E256 -> -4.5993776 | Y13: =中信三级行业指数热度!E14 -> 4.6023343 | Z13: =中信三级行业指数热度!E110 -> -0.03290472 | AA13: =中信三级行业指数热度!E64 -> 1.0843792 | AB13: =中信三级行业指数热度!E238 -> -0.74502543 | AC13: =中信三级行业指数热度!E194 -> 3.2324587 | AD13: =中信三级行业指数热度!E97 -> -4.1411661 | AE13: =中信三级行业指数热度!E85 -> 13.043545 | AG13: =IFERROR(中信三级行业指数热度!G13+ROW()*0.0000000001,-9999) -> 1.4421281
B14: =中信三级行业指数热度!B72&CHAR(10)&TEXT(中信三级行业指数热度!E72,"0.0")&"%" -> 其他家居指数 -2.5% | C14: =中信三级行业指数热度!B257&CHAR(10)&TEXT(中信三级行业指数热度!E257,"0.0")&"%" -> 其他酒指数 -6.5% | D14: =中信三级行业指数热度!B213&CHAR(10)&TEXT(中信三级行业指数热度!E213,"0.0")&"%" -> 金属制品Ⅲ指数 -7.0% | E14: =中信三级行业指数热度!B78&CHAR(10)&TEXT(中信三级行业指数热度!E78,"0.0")&"%" -> 其他塑料制品指数 -1.9% | F14: =中信三级行业指数热度!B89&CHAR(10)&TEXT(中信三级行业指数热度!E89,"0.0")&"%" -> 绵纶指数 1.8% | G14: =中信三级行业指数热度!B167&CHAR(10)&TEXT(中信三级行业指数热度!E167,"0.0")&"%" -> 非住宅物业开发和运营指数 -1.5% | H14: =中信三级行业指数热度!B93&CHAR(10)&TEXT(中信三级行业指数热度!E93,"0.0")&"%" -> 车用电机电控指数 -5.0% | I14: =中信三级行业指数热度!B133&CHAR(10)&TEXT(中信三级行业指数热度!E133,"0.0")&"%" -> 物流综合指数 -1.6% | J14: =中信三级行业指数热度!B50&CHAR(10)&TEXT(中信三级行业指数热度!E50,"0.0")&"%" -> 摩托车及其他Ⅲ指数 1.4% | K14: =中信三级行业指数热度!B209&CHAR(10)&TEXT(中信三级行业指数热度!E209,"0.0")&"%" -> 其他连锁指数 -6.7% | L14: =中信三级行业指数热度!B65&CHAR(10)&TEXT(中信三级行业指数热度!E65,"0.0")&"%" -> 纸包装指数 -0.1% | M14: =中信三级行业指数热度!B195&CHAR(10)&TEXT(中信三级行业指数热度!E195,"0.0")&"%" -> 小家电Ⅲ指数 -6.2% | N14: =中信三级行业指数热度!B222&CHAR(10)&TEXT(中信三级行业指数热度!E222,"0.0")&"%" -> 工程机械Ⅲ指数 -4.9% | O14: =中信三级行业指数热度!B33&CHAR(10)&TEXT(中信三级行业指数热度!E33,"0.0")&"%" -> 化学制剂指数 3.3% | R14: =中信三级行业指数热度!E72 -> -2.5007458 | S14: =中信三级行业指数热度!E257 -> -6.5213846 | T14: =中信三级行业指数热度!E213 -> -6.9945085 | U14: =中信三级行业指数热度!E78 -> -1.8715974 | V14: =中信三级行业指数热度!E89 -> 1.8055389 | W14: =中信三级行业指数热度!E167 -> -1.5240746 | X14: =中信三级行业指数热度!E93 -> -4.9640395 | Y14: =中信三级行业指数热度!E133 -> -1.605378 | Z14: =中信三级行业指数热度!E50 -> 1.4120549 | AA14: =中信三级行业指数热度!E209 -> -6.7355539 | AB14: =中信三级行业指数热度!E65 -> -0.085813083 | AC14: =中信三级行业指数热度!E195 -> -6.2436943 | AD14: =中信三级行业指数热度!E222 -> -4.8703734 | AE14: =中信三级行业指数热度!E33 -> 3.2798066 | AG14: =IFERROR(中信三级行业指数热度!G14+ROW()*0.0000000001,-9999) -> 0.90345549
B15: =中信三级行业指数热度!B120&CHAR(10)&TEXT(中信三级行业指数热度!E120,"0.0")&"%" -> 其他包装指数 0.5% | C15: =中信三级行业指数热度!B39&CHAR(10)&TEXT(中信三级行业指数热度!E39,"0.0")&"%" -> 通信终端及配件指数 4.3% | D15: =中信三级行业指数热度!B241&CHAR(10)&TEXT(中信三级行业指数热度!E241,"0.0")&"%" -> 保险Ⅲ指数 1.8% | E15: =中信三级行业指数热度!B169&CHAR(10)&TEXT(中信三级行业指数热度!E169,"0.0")&"%" -> 人力资源服务指数 -3.4% | F15: =中信三级行业指数热度!B115&CHAR(10)&TEXT(中信三级行业指数热度!E115,"0.0")&"%" -> 涂料油墨颜料指数 -0.8% | G15: =中信三级行业指数热度!B180&CHAR(10)&TEXT(中信三级行业指数热度!E180,"0.0")&"%" -> 纯碱指数 -0.4% | H15: =中信三级行业指数热度!B208&CHAR(10)&TEXT(中信三级行业指数热度!E208,"0.0")&"%" -> 宠物食品指数 -3.5% | I15: =中信三级行业指数热度!B211&CHAR(10)&TEXT(中信三级行业指数热度!E211,"0.0")&"%" -> 农产品加工Ⅲ指数 -6.0% | J15: =中信三级行业指数热度!B255&CHAR(10)&TEXT(中信三级行业指数热度!E255,"0.0")&"%" -> 黄金指数 -11.4% | K15: =中信三级行业指数热度!B148&CHAR(10)&TEXT(中信三级行业指数热度!E148,"0.0")&"%" -> 系统设备指数 1.9% | L15: =中信三级行业指数热度!B164&CHAR(10)&TEXT(中信三级行业指数热度!E164,"0.0")&"%" -> 改性塑料指数 -3.9% | M15: =中信三级行业指数热度!B55&CHAR(10)&TEXT(中信三级行业指数热度!E55,"0.0")&"%" -> 其他非银金融指数 2.4% | N15: =中信三级行业指数热度!B111&CHAR(10)&TEXT(中信三级行业指数热度!E111,"0.0")&"%" -> 基础件指数 -4.6% | O15: =中信三级行业指数热度!B44&CHAR(10)&TEXT(中信三级行业指数热度!E44,"0.0")&"%" -> 多领域控股Ⅲ指数 0.1% | R15: =中信三级行业指数热度!E120 -> 0.48185541 | S15: =中信三级行业指数热度!E39 -> 4.2681039 | T15: =中信三级行业指数热度!E241 -> 1.8232594 | U15: =中信三级行业指数热度!E169 -> -3.4183568 | V15: =中信三级行业指数热度!E115 -> -0.80681619 | W15: =中信三级行业指数热度!E180 -> -0.42091993 | X15: =中信三级行业指数热度!E208 -> -3.5365171 | Y15: =中信三级行业指数热度!E211 -> -6.0062537 | Z15: =中信三级行业指数热度!E255 -> -11.447703 | AA15: =中信三级行业指数热度!E148 -> 1.9445069 | AB15: =中信三级行业指数热度!E164 -> -3.9264122 | AC15: =中信三级行业指数热度!E55 -> 2.4142643 | AD15: =中信三级行业指数热度!E111 -> -4.5566997 | AE15: =中信三级行业指数热度!E44 -> 0.13312361 | AG15: =IFERROR(中信三级行业指数热度!G15+ROW()*0.0000000001,-9999) -> -0.20884913
B16: =中信三级行业指数热度!B130&CHAR(10)&TEXT(中信三级行业指数热度!E130,"0.0")&"%" -> 电池综合服务指数 -3.1% | C16: =中信三级行业指数热度!B95&CHAR(10)&TEXT(中信三级行业指数热度!E95,"0.0")&"%" -> 玻璃纤维指数 23.2% | D16: =中信三级行业指数热度!B174&CHAR(10)&TEXT(中信三级行业指数热度!E174,"0.0")&"%" -> 体育及户外品牌指数 19.2% | E16: =中信三级行业指数热度!B105&CHAR(10)&TEXT(中信三级行业指数热度!E105,"0.0")&"%" -> 服务机器人指数 -2.0% | F16: =中信三级行业指数热度!B132&CHAR(10)&TEXT(中信三级行业指数热度!E132,"0.0")&"%" -> 餐饮指数 -3.0% | G16: =中信三级行业指数热度!B100&CHAR(10)&TEXT(中信三级行业指数热度!E100,"0.0")&"%" -> 医药流通指数 -2.1% | H16: =中信三级行业指数热度!B249&CHAR(10)&TEXT(中信三级行业指数热度!E249,"0.0")&"%" -> 家电3C指数 -7.8% | I16: =中信三级行业指数热度!B153&CHAR(10)&TEXT(中信三级行业指数热度!E153,"0.0")&"%" -> 太阳能指数 -0.9% | J16: =中信三级行业指数热度!B193&CHAR(10)&TEXT(中信三级行业指数热度!E193,"0.0")&"%" -> 配电设备指数 -4.4% | K16: =中信三级行业指数热度!B175&CHAR(10)&TEXT(中信三级行业指数热度!E175,"0.0")&"%" -> 水泥指数 -1.3% | L16: =中信三级行业指数热度!B187&CHAR(10)&TEXT(中信三级行业指数热度!E187,"0.0")&"%" -> 景区指数 -3.3% | M16: =中信三级行业指数热度!B30&CHAR(10)&TEXT(中信三级行业指数热度!E30,"0.0")&"%" -> 网络覆盖优化与运维指数 -2.8% | N16: =中信三级行业指数热度!B70&CHAR(10)&TEXT(中信三级行业指数热度!E70,"0.0")&"%" -> 汽车销售及服务Ⅲ指数 -2.3% | O16: =中信三级行业指数热度!B161&CHAR(10)&TEXT(中信三级行业指数热度!E161,"0.0")&"%" -> 船舶制造指数 -2.6% | R16: =中信三级行业指数热度!E130 -> -3.0787083 | S16: =中信三级行业指数热度!E95 -> 23.198454 | T16: =中信三级行业指数热度!E174 -> 19.238437 | U16: =中信三级行业指数热度!E105 -> -2.0360908 | V16: =中信三级行业指数热度!E132 -> -2.9720068 | W16: =中信三级行业指数热度!E100 -> -2.1185569 | X16: =中信三级行业指数热度!E249 -> -7.7515031 | Y16: =中信三级行业指数热度!E153 -> -0.90229483 | Z16: =中信三级行业指数热度!E193 -> -4.3823399 | AA16: =中信三级行业指数热度!E175 -> -1.3169824 | AB16: =中信三级行业指数热度!E187 -> -3.2632248 | AC16: =中信三级行业指数热度!E30 -> -2.8461825 | AD16: =中信三级行业指数热度!E70 -> -2.3057969 | AE16: =中信三级行业指数热度!E161 -> -2.5982194 | AG16: =IFERROR(中信三级行业指数热度!G16+ROW()*0.0000000001,-9999) -> 0.82467338
B17: =中信三级行业指数热度!B143&CHAR(10)&TEXT(中信三级行业指数热度!E143,"0.0")&"%" -> 肉制品指数 3.9% | C17: =中信三级行业指数热度!B258&CHAR(10)&TEXT(中信三级行业指数热度!E258,"0.0")&"%" -> 锂电设备指数 -6.4% | D17: =中信三级行业指数热度!B197&CHAR(10)&TEXT(中信三级行业指数热度!E197,"0.0")&"%" -> 安防指数 1.5% | E17: =中信三级行业指数热度!B135&CHAR(10)&TEXT(中信三级行业指数热度!E135,"0.0")&"%" -> 铁路交通设备指数 -3.1% | F17: =中信三级行业指数热度!B36&CHAR(10)&TEXT(中信三级行业指数热度!E36,"0.0")&"%" -> 通用计算机设备指数 5.0% | G17: =中信三级行业指数热度!B112&CHAR(10)&TEXT(中信三级行业指数热度!E112,"0.0")&"%" -> 塑料加工机械指数 -4.1% | H17: =中信三级行业指数热度!B232&CHAR(10)&TEXT(中信三级行业指数热度!E232,"0.0")&"%" -> 油田服务指数 -3.8% | I17: =中信三级行业指数热度!B219&CHAR(10)&TEXT(中信三级行业指数热度!E219,"0.0")&"%" -> 城商行指数 -1.4% | J17: =中信三级行业指数热度!B159&CHAR(10)&TEXT(中信三级行业指数热度!E159,"0.0")&"%" -> 航天军工指数 -3.8% | K17: =中信三级行业指数热度!B134&CHAR(10)&TEXT(中信三级行业指数热度!E134,"0.0")&"%" -> 航空军工指数 -3.4% | L17: =中信三级行业指数热度!B199&CHAR(10)&TEXT(中信三级行业指数热度!E199,"0.0")&"%" -> 休闲综合指数 -4.2% | M17: =中信三级行业指数热度!B188&CHAR(10)&TEXT(中信三级行业指数热度!E188,"0.0")&"%" -> 农商行指数 -1.5% | N17: =中信三级行业指数热度!B217&CHAR(10)&TEXT(中信三级行业指数热度!E217,"0.0")&"%" -> 房建建设指数 -4.1% | O17: =中信三级行业指数热度!B83&CHAR(10)&TEXT(中信三级行业指数热度!E83,"0.0")&"%" -> 环保及水务指数 -1.0% | R17: =中信三级行业指数热度!E143 -> 3.9368365 | S17: =中信三级行业指数热度!E258 -> -6.4372903 | T17: =中信三级行业指数热度!E197 -> 1.4525424 | U17: =中信三级行业指数热度!E135 -> -3.1370846 | V17: =中信三级行业指数热度!E36 -> 5.0357421 | W17: =中信三级行业指数热度!E112 -> -4.0763878 | X17: =中信三级行业指数热度!E232 -> -3.7955606 | Y17: =中信三级行业指数热度!E219 -> -1.3944542 | Z17: =中信三级行业指数热度!E159 -> -3.773255 | AA17: =中信三级行业指数热度!E134 -> -3.4467939 | AB17: =中信三级行业指数热度!E199 -> -4.2416758 | AC17: =中信三级行业指数热度!E188 -> -1.4503282 | AD17: =中信三级行业指数热度!E217 -> -4.1394512 | AE17: =中信三级行业指数热度!E83 -> -0.97761711 | AG17: =IFERROR(中信三级行业指数热度!G17+ROW()*0.0000000001,-9999) -> 0.56285423
