Workbook

Sheet 概念指数热点监控
C1: 46023 | D1: =DATE(YEAR(D2),MONTH(D2),DAY(D2)-7) | E1: =DATE(YEAR(E2),MONTH(E2),DAY(E2)-30)
A2: =TODAY()-1 | C2: =A2 | D2: =C2 | E2: =D2 | K2: ↓前5大重仓=iFinD智能选股快照(按A股流通市值取前5,数据日2026-06-18),非单元格公式,需定期手动刷新
A3: 概念代码 | B3: 概念名称 | C3: YTD涨跌幅 | D3: 近一周 | E3: 近一月 | F3: 加速度 | G3: 概念类型 | H3: 一级 | I3: 二级 | J3: 产业链位置 | K3: 第1大重仓-名称 | L3: 第1大重仓-代码 | M3: 第1大重仓-流通市值(亿元) | N3: 第2大重仓-名称 | O3: 第2大重仓-代码 | P3: 第2大重仓-流通市值(亿元) | Q3: 第3大重仓-名称 | R3: 第3大重仓-代码 | S3: 第3大重仓-流通市值(亿元) | T3: 第4大重仓-名称 | U3: 第4大重仓-代码 | V3: 第4大重仓-流通市值(亿元) | W3: 第5大重仓-名称 | X3: 第5大重仓-代码 | Y3: 第5大重仓-流通市值(亿元)
A4: 886020.TI | B4: =[1]!thsiFinD("THS_GPJC_STOCK",$A4) | C4: =[1]!thsiFinD("ths_int_chg_ratio_index",$A4,C$1,C$2)/100 | D4: =[1]!thsiFinD("ths_int_chg_ratio_index",$A4,D$1,D$2)/100 | E4: =[1]!thsiFinD("ths_int_chg_ratio_index",$A4,E$1,E$2)/100 | F4: =D4-(E4-D4)/3 | G4: 产业链 | H4: =IFERROR(VLOOKUP($I4,'分类规则'!$A$30:$C$200,2,0),"") | I4: 电子材料 | J4: =IFERROR(VLOOKUP($I4,'分类规则'!$A$30:$C$200,3,0),"") | K4: 中天科技 | L4: 600522.SH | M4: 1929.7 | N4: 铜冠铜箔 | O4: 301217.SZ | P4: 1656.4 | Q4: 恒力石化 | R4: 600346.SH | S4: 1208.6 | T4: 东材科技 | U4: 601208.SH | V4: 755.9 | W4: 远东股份 | X4: 600869.SH | Y4: 729.3
A5: 886033.TI | B5: =[1]!thsiFinD("THS_GPJC_STOCK",$A5) | C5: =[1]!thsiFinD("ths_int_chg_ratio_index",$A5,C$1,C$2)/100 | D5: =[1]!thsiFinD("ths_int_chg_ratio_index",$A5,D$1,D$2)/100 | E5: =[1]!thsiFinD("ths_int_chg_ratio_index",$A5,E$1,E$2)/100 | F5: =D5-(E5-D5)/3 | G5: 产业链 | H5: =IFERROR(VLOOKUP($I5,'分类规则'!$A$30:$C$200,2,0),"") | I5: 光通信/算力硬件 | J5: =IFERROR(VLOOKUP($I5,'分类规则'!$A$30:$C$200,3,0),"") | K5: 工业富联 | L5: 601138.SH | M5: 15494.3 | N5: 中际旭创 | O5: 300308.SZ | P5: 15182.6 | Q5: 新易盛 | R5: 300502.SZ | S5: 7293.2 | T5: 立讯精密 | U5: 002475.SZ | V5: 5083.4 | W5: 生益科技 | X5: 600183.SH | Y5: 4402.8
A6: 886084.TI | B6: =[1]!thsiFinD("THS_GPJC_STOCK",$A6) | C6: =[1]!thsiFinD("ths_int_chg_ratio_index",$A6,C$1,C$2)/100 | D6: =[1]!thsiFinD("ths_int_chg_ratio_index",$A6,D$1,D$2)/100 | E6: =[1]!thsiFinD("ths_int_chg_ratio_index",$A6,E$1,E$2)/100 | F6: =D6-(E6-D6)/3 | G6: 产业链 | H6: =IFERROR(VLOOKUP($I6,'分类规则'!$A$30:$C$200,2,0),"") | I6: 光通信/算力硬件 | J6: =IFERROR(VLOOKUP($I6,'分类规则'!$A$30:$C$200,3,0),"") | K6: 东山精密 | L6: 002384.SZ | M6: 3784.7 | N6: 天孚通信 | O6: 300394.SZ | P6: 3663.5 | Q6: 三环集团 | R6: 300408.SZ | S6: 2952.2 | T6: 海康威视 | U6: 002415.SZ | V6: 2922 | W6: 蓝思科技 | X6: 300433.SZ | Y6: 2771.6
A7: 886009.TI | B7: =[1]!thsiFinD("THS_GPJC_STOCK",$A7) | C7: =[1]!thsiFinD("ths_int_chg_ratio_index",$A7,C$1,C$2)/100 | D7: =[1]!thsiFinD("ths_int_chg_ratio_index",$A7,D$1,D$2)/100 | E7: =[1]!thsiFinD("ths_int_chg_ratio_index",$A7,E$1,E$2)/100 | F7: =D7-(E7-D7)/3 | G7: 产业链 | H7: =IFERROR(VLOOKUP($I7,'分类规则'!$A$30:$C$200,2,0),"") | I7: 半导体 | J7: =IFERROR(VLOOKUP($I7,'分类规则'!$A$30:$C$200,3,0),"") | K7: 寒武纪 | L7: 688256.SH | M7: 9471.3 | N7: 生益科技 | O7: 600183.SH | P7: 4402.8 | Q7: 天孚通信 | R7: 300394.SZ | S7: 3663.5 | T7: 中微公司 | U7: 688012.SH | V7: 3373.1 | W7: 深南电路 | X7: 002916.SZ | Y7: 3016.9
A8: 885959.TI | B8: =[1]!thsiFinD("THS_GPJC_STOCK",$A8) | C8: =[1]!thsiFinD("ths_int_chg_ratio_index",$A8,C$1,C$2)/100 | D8: =[1]!thsiFinD("ths_int_chg_ratio_index",$A8,D$1,D$2)/100 | E8: =[1]!thsiFinD("ths_int_chg_ratio_index",$A8,E$1,E$2)/100 | F8: =D8-(E8-D8)/3 | G8: 产业链 | H8: =IFERROR(VLOOKUP($I8,'分类规则'!$A$30:$C$200,2,0),"") | I8: PCB/覆铜板 | J8: =IFERROR(VLOOKUP($I8,'分类规则'!$A$30:$C$200,3,0),"") | K8: 生益科技 | L8: 600183.SH | M8: 4402.8 | N8: 东山精密 | O8: 002384.SZ | P8: 3784.7 | Q8: 胜宏科技 | R8: 300476.SZ | S8: 3192.6 | T8: 深南电路 | U8: 002916.SZ | V8: 3016.9 | W8: 沪电股份 | X8: 002463.SZ | Y8: 2843.8
A9: 885893.TI | B9: =[1]!thsiFinD("THS_GPJC_STOCK",$A9) | C9: =[1]!thsiFinD("ths_int_chg_ratio_index",$A9,C$1,C$2)/100 | D9: =[1]!thsiFinD("ths_int_chg_ratio_index",$A9,D$1,D$2)/100 | E9: =[1]!thsiFinD("ths_int_chg_ratio_index",$A9,E$1,E$2)/100 | F9: =D9-(E9-D9)/3 | G9: 产业链 | H9: =IFERROR(VLOOKUP($I9,'分类规则'!$A$30:$C$200,2,0),"") | I9: 半导体 | J9: =IFERROR(VLOOKUP($I9,'分类规则'!$A$30:$C$200,3,0),"") | K9: 北方华创 | L9: 002371.SZ | M9: 5222.2 | N9: 中微公司 | O9: 688012.SH | P9: 3373.1 | Q9: 深南电路 | R9: 002916.SZ | S9: 3016.9 | T9: 中芯国际 | U9: 688981.SH | V9: 2813.4 | W9: 拓荆科技 | X9: 688072.SH | Y9: 2075
A10: 886042.TI | B10: =[1]!thsiFinD("THS_GPJC_STOCK",$A10) | C10: =[1]!thsiFinD("ths_int_chg_ratio_index",$A10,C$1,C$2)/100 | D10: =[1]!thsiFinD("ths_int_chg_ratio_index",$A10,D$1,D$2)/100 | E10: =[1]!thsiFinD("ths_int_chg_ratio_index",$A10,E$1,E$2)/100 | F10: =D10-(E10-D10)/3 | G10: 产业链 | H10: =IFERROR(VLOOKUP($I10,'分类规则'!$A$30:$C$200,2,0),"") | I10: 半导体 | J10: =IFERROR(VLOOKUP($I10,'分类规则'!$A$30:$C$200,3,0),"") | K10: 北方华创 | L10: 002371.SZ | M10: 5222.2 | N10: 生益科技 | O10: 600183.SH | P10: 4402.8 | Q10: 兆易创新 | R10: 603986.SH | S10: 4204.8 | T10: 中微公司 | U10: 688012.SH | V10: 3373.1 | W10: 澜起科技 | X10: 688008.SH | Y10: 3094.2
A11: 886054.TI | B11: =[1]!thsiFinD("THS_GPJC_STOCK",$A11) | C11: =[1]!thsiFinD("ths_int_chg_ratio_index",$A11,C$1,C$2)/100 | D11: =[1]!thsiFinD("ths_int_chg_ratio_index",$A11,D$1,D$2)/100 | E11: =[1]!thsiFinD("ths_int_chg_ratio_index",$A11,E$1,E$2)/100 | F11: =D11-(E11-D11)/3 | G11: 产业链 | H11: =IFERROR(VLOOKUP($I11,'分类规则'!$A$30:$C$200,2,0),"") | I11: 半导体 | J11: =IFERROR(VLOOKUP($I11,'分类规则'!$A$30:$C$200,3,0),"") | K11: 大族激光 | L11: 002008.SZ | M11: 1290.6 | N11: 江丰电子 | O11: 300666.SZ | P11: 688.1 | Q11: 芯碁微装 | R11: 688630.SH | S11: 661.3 | T11: 富创精密 | U11: 688409.SH | V11: 622.5 | W11: 中瓷电子 | X11: 003031.SZ | Y11: 599.7
A12: 885897.TI | B12: =[1]!thsiFinD("THS_GPJC_STOCK",$A12) | C12: =[1]!thsiFinD("ths_int_chg_ratio_index",$A12,C$1,C$2)/100 | D12: =[1]!thsiFinD("ths_int_chg_ratio_index",$A12,D$1,D$2)/100 | E12: =[1]!thsiFinD("ths_int_chg_ratio_index",$A12,E$1,E$2)/100 | F12: =D12-(E12-D12)/3 | G12: 公司链 | H12: =IFERROR(VLOOKUP($I12,'分类规则'!$A$30:$C$200,2,0),"") | I12: 半导体 | J12: =IFERROR(VLOOKUP($I12,'分类规则'!$A$30:$C$200,3,0),"") | K12: 北方华创 | L12: 002371.SZ | M12: 5222.2 | N12: 中微公司 | O12: 688012.SH | P12: 3373.1 | Q12: 澜起科技 | R12: 688008.SH | S12: 3094.2 | T12: 中芯国际 | U12: 688981.SH | V12: 2813.4 | W12: 盛美上海 | X12: 688082.SH | Y12: 1808.2
A13: 885875.TI | B13: =[1]!thsiFinD("THS_GPJC_STOCK",$A13) | C13: =[1]!thsiFinD("ths_int_chg_ratio_index",$A13,C$1,C$2)/100 | D13: =[1]!thsiFinD("ths_int_chg_ratio_index",$A13,D$1,D$2)/100 | E13: =[1]!thsiFinD("ths_int_chg_ratio_index",$A13,E$1,E$2)/100 | F13: =D13-(E13-D13)/3 | G13: 产业链 | H13: =IFERROR(VLOOKUP($I13,'分类规则'!$A$30:$C$200,2,0),"") | I13: 面板显示 | J13: =IFERROR(VLOOKUP($I13,'分类规则'!$A$30:$C$200,3,0),"") | K13: 生益科技 | L13: 600183.SH | M13: 4402.8 | N13: 东山精密 | O13: 002384.SZ | P13: 3784.7 | Q13: 中微公司 | R13: 688012.SH | S13: 3373.1 | T13: 鹏鼎控股 | U13: 002938.SZ | V13: 2769.2 | W13: 京东方A | X13: 000725.SZ | Y13: 2316.5
A14: 885908.TI | B14: =[1]!thsiFinD("THS_GPJC_STOCK",$A14) | C14: =[1]!thsiFinD("ths_int_chg_ratio_index",$A14,C$1,C$2)/100 | D14: =[1]!thsiFinD("ths_int_chg_ratio_index",$A14,D$1,D$2)/100 | E14: =[1]!thsiFinD("ths_int_chg_ratio_index",$A14,E$1,E$2)/100 | F14: =D14-(E14-D14)/3 | G14: 产业链 | H14: =IFERROR(VLOOKUP($I14,'分类规则'!$A$30:$C$200,2,0),"") | I14: 半导体 | J14: =IFERROR(VLOOKUP($I14,'分类规则'!$A$30:$C$200,3,0),"") | K14: 北方华创 | L14: 002371.SZ | M14: 5222.2 | N14: 格力电器 | O14: 000651.SZ | P14: 2027.7 | Q14: 长飞光纤 | R14: 601869.SH | S14: 1916.1 | T14: 盛美上海 | U14: 688082.SH | V14: 1808.2 | W14: 华工科技 | X14: 000988.SZ | Y14: 1784.4
A15: 885937.TI | B15: =[1]!thsiFinD("THS_GPJC_STOCK",$A15) | C15: =[1]!thsiFinD("ths_int_chg_ratio_index",$A15,C$1,C$2)/100 | D15: =[1]!thsiFinD("ths_int_chg_ratio_index",$A15,D$1,D$2)/100 | E15: =[1]!thsiFinD("ths_int_chg_ratio_index",$A15,E$1,E$2)/100 | F15: =D15-(E15-D15)/3 | G15: 产业链 | H15: =IFERROR(VLOOKUP($I15,'分类规则'!$A$30:$C$200,2,0),"") | I15: 超硬材料 | J15: =IFERROR(VLOOKUP($I15,'分类规则'!$A$30:$C$200,3,0),"") | K15: 晶盛机电 | L15: 300316.SZ | M15: 663.7 | N15: 国机精工 | O15: 002046.SZ | P15: 337.7 | Q15: 中兵红箭 | R15: 000519.SZ | S15: 283.2 | T15: 楚江新材 | U15: 002171.SZ | V15: 248.2 | W15: 英诺激光 | X15: 301021.SZ | Y15: 189.9
... A18: 885998.TI | B18: =[1]!thsiFinD("THS_GPJC_STOCK",$A18) | C18: =[1]!thsiFinD("ths_int_chg_ratio_index",$A18,C$1,C$2)/100 | D18: =[1]!thsiFinD("ths_int_chg_ratio_index",$A18,D$1,D$2)/100 | E18: =[1]!thsiFinD("ths_int_chg_ratio_index",$A18,E$1,E$2)/100 | F18: =D18-(E18-D18)/3 | G18: 产业链 | H18: =IFERROR(VLOOKUP($I18,'分类规则'!$A$30:$C$200,2,0),"") | I18: 光通信/算力硬件 | J18: =IFERROR(VLOOKUP($I18,'分类规则'!$A$30:$C$200,3,0),"") | K18: 中际旭创 | L18: 300308.SZ | M18: 15182.6 | N18: 亨通光电 | O18: 600487.SH | P18: 2714.4 | Q18: 光迅科技 | R18: 002281.SZ | S18: 2077.7 | T18: 华工科技 | U18: 000988.SZ | V18: 1784.4 | W18: 上港集团 | X18: 600018.SH | Y18: 1136.8
A19: 886073.TI | B19: =[1]!thsiFinD("THS_GPJC_STOCK",$A19) | C19: =[1]!thsiFinD("ths_int_chg_ratio_index",$A19,C$1,C$2)/100 | D19: =[1]!thsiFinD("ths_int_chg_ratio_index",$A19,D$1,D$2)/100 | E19: =[1]!thsiFinD("ths_int_chg_ratio_index",$A19,E$1,E$2)/100 | F19: =D19-(E19-D19)/3 | G19: 产业链 | H19: =IFERROR(VLOOKUP($I19,'分类规则'!$A$30:$C$200,2,0),"") | I19: 光通信/算力硬件 | J19: =IFERROR(VLOOKUP($I19,'分类规则'!$A$30:$C$200,3,0),"")
A20: 885987.TI | B20: =[1]!thsiFinD("THS_GPJC_STOCK",$A20) | C20: =[1]!thsiFinD("ths_int_chg_ratio_index",$A20,C$1,C$2)/100 | D20: =[1]!thsiFinD("ths_int_chg_ratio_index",$A20,D$1,D$2)/100 | E20: =[1]!thsiFinD("ths_int_chg_ratio_index",$A20,E$1,E$2)/100 | F20: =D20-(E20-D20)/3 | G20: 产业链 | H20: =IFERROR(VLOOKUP($I20,'分类规则'!$A$30:$C$200,2,0),"") | I20: 面板显示 | J20: =IFERROR(VLOOKUP($I20,'分类规则'!$A$30:$C$200,3,0),"") | K20: 京东方A | L20: 000725.SZ | M20: 2316.5 | N20: 华工科技 | O20: 000988.SZ | P20: 1784.4 | Q20: 大族激光 | R20: 002008.SZ | S20: 1290.6 | T20: 华海清科 | U20: 688120.SH | V20: 1122.3 | W20: 晶合集成 | X20: 688249.SH | Y20: 1003
A21: 885864.TI | B21: =[1]!thsiFinD("THS_GPJC_STOCK",$A21) | C21: =[1]!thsiFinD("ths_int_chg_ratio_index",$A21,C$1,C$2)/100 | D21: =[1]!thsiFinD("ths_int_chg_ratio_index",$A21,D$1,D$2)/100 | E21: =[1]!thsiFinD("ths_int_chg_ratio_index",$A21,E$1,E$2)/100 | F21: =D21-(E21-D21)/3 | G21: 产业链 | H21: =IFERROR(VLOOKUP($I21,'分类规则'!$A$30:$C$200,2,0),"") | I21: 半导体 | J21: =IFERROR(VLOOKUP($I21,'分类规则'!$A$30:$C$200,3,0),"") | K21: 东材科技 | L21: 601208.SH | M21: 755.9 | N21: 鼎龙股份 | O21: 300054.SZ | P21: 684.8 | Q21: 芯碁微装 | R21: 688630.SH | S21: 661.3 | T21: 芯源微 | U21: 688037.SH | V21: 590.9 | W21: 圣泉集团 | X21: 605589.SH | Y21: 590.6
A22: 885809.TI | B22: =[1]!thsiFinD("THS_GPJC_STOCK",$A22) | C22: =[1]!thsiFinD("ths_int_chg_ratio_index",$A22,C$1,C$2)/100 | D22: =[1]!thsiFinD("ths_int_chg_ratio_index",$A22,D$1,D$2)/100 | E22: =[1]!thsiFinD("ths_int_chg_ratio_index",$A22,E$1,E$2)/100 | F22: =D22-(E22-D22)/3 | G22: 产业链 | H22: =IFERROR(VLOOKUP($I22,'分类规则'!$A$30:$C$200,2,0),"") | I22: 面板显示 | J22: =IFERROR(VLOOKUP($I22,'分类规则'!$A$30:$C$200,3,0),"") | K22: 蓝思科技 | L22: 300433.SZ | M22: 2771.6 | N22: 京东方A | O22: 000725.SZ | P22: 2316.5 | Q22: 华工科技 | R22: 000988.SZ | S22: 1784.4 | T22: 领益智造 | U22: 002600.SZ | V22: 1211 | W22: TCL科技 | X22: 000100.SZ | Y22: 956.6
A23: 885376.TI | B23: =[1]!thsiFinD("THS_GPJC_STOCK",$A23) | C23: =[1]!thsiFinD("ths_int_chg_ratio_index",$A23,C$1,C$2)/100 | D23: =[1]!thsiFinD("ths_int_chg_ratio_index",$A23,D$1,D$2)/100 | E23: =[1]!thsiFinD("ths_int_chg_ratio_index",$A23,E$1,E$2)/100 | F23: =D23-(E23-D23)/3 | G23: 公司链 | H23: =IFERROR(VLOOKUP($I23,'分类规则'!$A$30:$C$200,2,0),"") | I23: 消费电子 | J23: =IFERROR(VLOOKUP($I23,'分类规则'!$A$30:$C$200,3,0),"") | K23: 工业富联 | L23: 601138.SH | M23: 15494.3 | N23: 立讯精密 | O23: 002475.SZ | P23: 5083.4 | Q23: 东山精密 | R23: 002384.SZ | S23: 3784.7 | T23: 深南电路 | U23: 002916.SZ | V23: 3016.9 | W23: 蓝思科技 | X23: 300433.SZ | Y23: 2771.6
A24: 885886.TI | B24: =[1]!thsiFinD("THS_GPJC_STOCK",$A24) | C24: =[1]!thsiFinD("ths_int_chg_ratio_index",$A24,C$1,C$2)/100 | D24: =[1]!thsiFinD("ths_int_chg_ratio_index",$A24,D$1,D$2)/100 | E24: =[1]!thsiFinD("ths_int_chg_ratio_index",$A24,E$1,E$2)/100 | F24: =D24-(E24-D24)/3 | G24: 产业链 | H24: =IFERROR(VLOOKUP($I24,'分类规则'!$A$30:$C$200,2,0),"") | I24: 储能/电池 | J24: =IFERROR(VLOOKUP($I24,'分类规则'!$A$30:$C$200,3,0),"") | K24: 中天科技 | L24: 600522.SH | M24: 1930 | N24: 思源电气 | O24: 002028.SZ | P24: 1161.5 | Q24: 东阳光 | R24: 600673.SH | S24: 1088.4 | T24: 江海股份 | U24: 002484.SZ | V24: 886.6 | W24: 风华高科 | X24: 000636.SZ | Y24: 863.1
A25: 885907.TI | B25: =[1]!thsiFinD("THS_GPJC_STOCK",$A25) | C25: =[1]!thsiFinD("ths_int_chg_ratio_index",$A25,C$1,C$2)/100 | D25: =[1]!thsiFinD("ths_int_chg_ratio_index",$A25,D$1,D$2)/100 | E25: =[1]!thsiFinD("ths_int_chg_ratio_index",$A25,E$1,E$2)/100 | F25: =D25-(E25-D25)/3 | G25: 宽基风格 | H25: =IFERROR(VLOOKUP($I25,'分类规则'!$A$30:$C$200,2,0),"") | I25: 次新股 | J25: =IFERROR(VLOOKUP($I25,'分类规则'!$A$30:$C$200,3,0),"") | K25: 联讯仪器 | L25: 688808.SH | M25: 457.9 | N25: 盛合晶微 | O25: 688820.SH | P25: 320.9 | Q25: 摩尔线程 | R25: 688795.SH | S25: 202.2 | T25: 强一股份 | U25: 688809.SH | V25: 152.4 | W25: 沐曦股份 | X25: 688802.SH | Y25: 142.6
A26: 886082.TI | B26: =[1]!thsiFinD("THS_GPJC_STOCK",$A26) | C26: =[1]!thsiFinD("ths_int_chg_ratio_index",$A26,C$1,C$2)/100 | D26: =[1]!thsiFinD("ths_int_chg_ratio_index",$A26,D$1,D$2)/100 | E26: =[1]!thsiFinD("ths_int_chg_ratio_index",$A26,E$1,E$2)/100 | F26: =D26-(E26-D26)/3 | G26: 宽基风格 | H26: =IFERROR(VLOOKUP($I26,'分类规则'!$A$30:$C$200,2,0),"") | I26: 主题指数 | J26: =IFERROR(VLOOKUP($I26,'分类规则'!$A$30:$C$200,3,0),"")
A27: 886071.TI | B27: =[1]!thsiFinD("THS_GPJC_STOCK",$A27) | C27: =[1]!thsiFinD("ths_int_chg_ratio_index",$A27,C$1,C$2)/100 | D27: =[1]!thsiFinD("ths_int_chg_ratio_index",$A27,D$1,D$2)/100 | E27: =[1]!thsiFinD("ths_int_chg_ratio_index",$A27,E$1,E$2)/100 | F27: =D27-(E27-D27)/3 | G27: 产业链 | H27: =IFERROR(VLOOKUP($I27,'分类规则'!$A$30:$C$200,2,0),"") | I27: 消费电子 | J27: =IFERROR(VLOOKUP($I27,'分类规则'!$A$30:$C$200,3,0),"") | K27: 胜宏科技 | L27: 300476.SZ | M27: 3192.6 | N27: 鹏鼎控股 | O27: 002938.SZ | P27: 2769.2 | Q27: 京东方A | R27: 000725.SZ | S27: 2316.5 | T27: 佰维存储 | U27: 688525.SH | V27: 1821.2 | W27: 江波龙 | X27: 301308.SZ | Y27: 1628.5
A28: 886053.TI | B28: =[1]!thsiFinD("THS_GPJC_STOCK",$A28) | C28: =[1]!thsiFinD("ths_int_chg_ratio_index",$A28,C$1,C$2)/100 | D28: =[1]!thsiFinD("ths_int_chg_ratio_index",$A28,D$1,D$2)/100 | E28: =[1]!thsiFinD("ths_int_chg_ratio_index",$A28,E$1,E$2)/100 | F28: =D28-(E28-D28)/3 | G28: 产业链 | H28: =IFERROR(VLOOKUP($I28,'分类规则'!$A$30:$C$200,2,0),"") | I28: 光伏 | J28: =IFERROR(VLOOKUP($I28,'分类规则'!$A$30:$C$200,3,0),"") | K28: 罗博特科 | L28: 300757.SZ | M28: 1082.7 | N28: 隆基绿能 | O28: 601012.SH | P28: 973 | Q28: 东材科技 | R28: 601208.SH | S28: 755.9 | T28: 先导智能 | U28: 300450.SZ | V28: 728.7 | W28: 晶盛机电 | X28: 300316.SZ | Y28: 663.7
A29: 885756.TI | B29: =[1]!thsiFinD("THS_GPJC_STOCK",$A29) | C29: =[1]!thsiFinD("ths_int_chg_ratio_index",$A29,C$1,C$2)/100 | D29: =[1]!thsiFinD("ths_int_chg_ratio_index",$A29,D$1,D$2)/100 | E29: =[1]!thsiFinD("ths_int_chg_ratio_index",$A29,E$1,E$2)/100 | F29: =D29-(E29-D29)/3 | G29: 产业链 | H29: =IFERROR(VLOOKUP($I29,'分类规则'!$A$30:$C$200,2,0),"") | I29: 半导体 | J29: =IFERROR(VLOOKUP($I29,'分类规则'!$A$30:$C$200,3,0),"") | K29: 工业富联 | L29: 601138.SH | M29: 15494.3 | N29: 中际旭创 | O29: 300308.SZ | P29: 15182.6 | Q29: 寒武纪 | R29: 688256.SH | S29: 9471.3 | T29: 海光信息 | U29: 688041.SH | V29: 7623.8 | W29: 新易盛 | X29: 300502.SZ | Y29: 7293.2
A30: 886037.TI | B30: =[1]!thsiFinD("THS_GPJC_STOCK",$A30) | C30: =[1]!thsiFinD("ths_int_chg_ratio_index",$A30,C$1,C$2)/100 | D30: =[1]!thsiFinD("ths_int_chg_ratio_index",$A30,D$1,D$2)/100 | E30: =[1]!thsiFinD("ths_int_chg_ratio_index",$A30,E$1,E$2)/100 | F30: =D30-(E30-D30)/3 | G30: 产业链 | H30: =IFERROR(VLOOKUP($I30,'分类规则'!$A$30:$C$200,2,0),"") | I30: 通信 | J30: =IFERROR(VLOOKUP($I30,'分类规则'!$A$30:$C$200,3,0),"") | K30: 中国电信 | L30: 601728.SH | M30: 4409.4 | N30: 亨通光电 | O30: 600487.SH | P30: 2714.4 | Q30: 光迅科技 | R30: 002281.SZ | S30: 2077.7 | T30: 中天科技 | U30: 600522.SH | V30: 1930 | W30: 华工科技 | X30: 000988.SZ | Y30: 1784.4
A31: 885945.TI | B31: =[1]!thsiFinD("THS_GPJC_STOCK",$A31) | C31: =[1]!thsiFinD("ths_int_chg_ratio_index",$A31,C$1,C$2)/100 | D31: =[1]!thsiFinD("ths_int_chg_ratio_index",$A31,D$1,D$2)/100 | E31: =[1]!thsiFinD("ths_int_chg_ratio_index",$A31,E$1,E$2)/100 | F31: =D31-(E31-D31)/3 | G31: 产业链 | H31: =IFERROR(VLOOKUP($I31,'分类规则'!$A$30:$C$200,2,0),"") | I31: 半导体 | J31: =IFERROR(VLOOKUP($I31,'分类规则'!$A$30:$C$200,3,0),"") | K31: 寒武纪 | L31: 688256.SH | M31: 9471.3 | N31: 兆易创新 | O31: 603986.SH | P31: 4204.8 | Q31: 源杰科技 | R31: 688498.SH | S31: 2056.4 | T31: 佰维存储 | U31: 688525.SH | V31: 1821.2 | W31: 中兴通讯 | X31: 000063.SZ | Y31: 1526.1
A32: 886091.TI | B32: =[1]!thsiFinD("THS_GPJC_STOCK",$A32) | C32: =[1]!thsiFinD("ths_int_chg_ratio_index",$A32,C$1,C$2)/100 | D32: =[1]!thsiFinD("ths_int_chg_ratio_index",$A32,D$1,D$2)/100 | E32: =[1]!thsiFinD("ths_int_chg_ratio_index",$A32,E$1,E$2)/100 | F32: =D32-(E32-D32)/3 | G32: 公司链 | H32: =IFERROR(VLOOKUP($I32,'分类规则'!$A$30:$C$200,2,0),"") | I32: 消费电子 | J32: =IFERROR(VLOOKUP($I32,'分类规则'!$A$30:$C$200,3,0),"") | K32: 立讯精密 | L32: 002475.SZ | M32: 5083.4 | N32: 宏和科技 | O32: 603256.SH | P32: 2267.9 | Q32: 豪威集团 | R32: 603501.SH | S32: 1089.2 | T32: 景旺电子 | U32: 603228.SH | V32: 791 | W32: 华勤技术 | X32: 603296.SH | Y32: 642.1
A33: 886044.TI | B33: =[1]!thsiFinD("THS_GPJC_STOCK",$A33) | C33: =[1]!thsiFinD("ths_int_chg_ratio_index",$A33,C$1,C$2)/100 | D33: =[1]!thsiFinD("ths_int_chg_ratio_index",$A33,D$1,D$2)/100 | E33: =[1]!thsiFinD("ths_int_chg_ratio_index",$A33,E$1,E$2)/100 | F33: =D33-(E33-D33)/3 | G33: 产业链 | H33: =IFERROR(VLOOKUP($I33,'分类规则'!$A$30:$C$200,2,0),"") | I33: 光通信/算力硬件 | J33: =IFERROR(VLOOKUP($I33,'分类规则'!$A$30:$C$200,3,0),"") | K33: 工业富联 | L33: 601138.SH | M33: 15494.3 | N33: 中际旭创 | O33: 300308.SZ | P33: 15182.6 | Q33: 美的集团 | R33: 000333.SZ | S33: 5352.5 | T33: 立讯精密 | U33: 002475.SZ | V33: 5083.4 | W33: 蓝思科技 | X33: 300433.SZ | Y33: 2771.6
A34: 885800.TI | B34: =[1]!thsiFinD("THS_GPJC_STOCK",$A34) | C34: =[1]!thsiFinD("ths_int_chg_ratio_index",$A34,C$1,C$2)/100 | D34: =[1]!thsiFinD("ths_int_chg_ratio_index",$A34,D$1,D$2)/100 | E34: =[1]!thsiFinD("ths_int_chg_ratio_index",$A34,E$1,E$2)/100 | F34: =D34-(E34-D34)/3 | G34: 产业链 | H34: =IFERROR(VLOOKUP($I34,'分类规则'!$A$30:$C$200,2,0),"") | I34: 消费电子 | J34: =IFERROR(VLOOKUP($I34,'分类规则'!$A$30:$C$200,3,0),"") | K34: 立讯精密 | L34: 002475.SZ | M34: 5083.4 | N34: 东山精密 | O34: 002384.SZ | P34: 3784.7 | Q34: 澜起科技 | R34: 688008.SH | S34: 3094.2 | T34: 三环集团 | U34: 300408.SZ | V34: 2952.2 | W34: 中芯国际 | X34: 688981.SH | Y34: 2813.4
A35: 886006.TI | B35: =[1]!thsiFinD("THS_GPJC_STOCK",$A35) | C35: =[1]!thsiFinD("ths_int_chg_ratio_index",$A35,C$1,C$2)/100 | D35: =[1]!thsiFinD("ths_int_chg_ratio_index",$A35,D$1,D$2)/100 | E35: =[1]!thsiFinD("ths_int_chg_ratio_index",$A35,E$1,E$2)/100 | F35: =D35-(E35-D35)/3 | G35: 产业链 | H35: =IFERROR(VLOOKUP($I35,'分类规则'!$A$30:$C$200,2,0),"") | I35: 光伏 | J35: =IFERROR(VLOOKUP($I35,'分类规则'!$A$30:$C$200,3,0),"") | K35: 京东方A | L35: 000725.SZ | M35: 2316.5 | N35: 中天科技 | O35: 600522.SH | P35: 1930 | Q35: 华工科技 | R35: 000988.SZ | S35: 1784.4 | T35: 中国核电 | U35: 601985.SH | V35: 1722.2 | W35: 大族激光 | X35: 002008.SZ | Y35: 1290.6
A36: 885843.TI | B36: =[1]!thsiFinD("THS_GPJC_STOCK",$A36) | C36: =[1]!thsiFinD("ths_int_chg_ratio_index",$A36,C$1,C$2)/100 | D36: =[1]!thsiFinD("ths_int_chg_ratio_index",$A36,D$1,D$2)/100 | E36: =[1]!thsiFinD("ths_int_chg_ratio_index",$A36,E$1,E$2)/100 | F36: =D36-(E36-D36)/3 | G36: 公司链 | H36: =IFERROR(VLOOKUP($I36,'分类规则'!$A$30:$C$200,2,0),"") | I36: 半导体 | J36: =IFERROR(VLOOKUP($I36,'分类规则'!$A$30:$C$200,3,0),"") | K36: 北方华创 | L36: 002371.SZ | M36: 5222.2 | N36: 罗博特科 | O36: 300757.SZ | P36: 1082.7 | Q36: 通富微电 | R36: 002156.SZ | S36: 1036 | T36: 华天科技 | U36: 002185.SZ | V36: 651.6 | W36: 中瓷电子 | X36: 003031.SZ | Y36: 599.7
A37: 886109.TI | B37: =[1]!thsiFinD("THS_GPJC_STOCK",$A37) | C37: =[1]!thsiFinD("ths_int_chg_ratio_index",$A37,C$1,C$2)/100 | D37: =[1]!thsiFinD("ths_int_chg_ratio_index",$A37,D$1,D$2)/100 | E37: =[1]!thsiFinD("ths_int_chg_ratio_index",$A37,E$1,E$2)/100 | F37: =D37-(E37-D37)/3 | G37: 主题事件 | H37: =IFERROR(VLOOKUP($I37,'分类规则'!$A$30:$C$200,2,0),"") | I37: 预增 | J37: =IFERROR(VLOOKUP($I37,'分类规则'!$A$30:$C$200,3,0),"")
A38: 886085.TI | B38: =[1]!thsiFinD("THS_GPJC_STOCK",$A38) | C38: =[1]!thsiFinD("ths_int_chg_ratio_index",$A38,C$1,C$2)/100 | D38: =[1]!thsiFinD("ths_int_chg_ratio_index",$A38,D$1,D$2)/100 | E38: =[1]!thsiFinD("ths_int_chg_ratio_index",$A38,E$1,E$2)/100 | F38: =D38-(E38-D38)/3 | G38: 产业链 | H38: =IFERROR(VLOOKUP($I38,'分类规则'!$A$30:$C$200,2,0),"") | I38: 消费电子 | J38: =IFERROR(VLOOKUP($I38,'分类规则'!$A$30:$C$200,3,0),"") | K38: 立讯精密 | L38: 002475.SZ | M38: 5083.4 | N38: 蓝思科技 | O38: 300433.SZ | P38: 2771.6 | Q38: 鹏鼎控股 | R38: 002938.SZ | S38: 2769.2 | T38: 京东方A | U38: 000725.SZ | V38: 2316.5 | W38: 佰维存储 | X38: 688525.SH | Y38: 1821.2
A39: 885556.TI | B39: =[1]!thsiFinD("THS_GPJC_STOCK",$A39) | C39: =[1]!thsiFinD("ths_int_chg_ratio_index",$A39,C$1,C$2)/100 | D39: =[1]!thsiFinD("ths_int_chg_ratio_index",$A39,D$1,D$2)/100 | E39: =[1]!thsiFinD("ths_int_chg_ratio_index",$A39,E$1,E$2)/100 | F39: =D39-(E39-D39)/3 | G39: 产业链 | H39: =IFERROR(VLOOKUP($I39,'分类规则'!$A$30:$C$200,2,0),"") | I39: 通信 | J39: =IFERROR(VLOOKUP($I39,'分类规则'!$A$30:$C$200,3,0),"") | K39: 工业富联 | L39: 601138.SH | M39: 15494.3 | N39: 中际旭创 | O39: 300308.SZ | P39: 15182.6 | Q39: 新易盛 | R39: 300502.SZ | S39: 7293.2 | T39: 立讯精密 | U39: 002475.SZ | V39: 5083.4 | W39: 中国电信 | X39: 601728.SH | Y39: 4409.4
A40: 885425.TI | B40: =[1]!thsiFinD("THS_GPJC_STOCK",$A40) | C40: =[1]!thsiFinD("ths_int_chg_ratio_index",$A40,C$1,C$2)/100 | D40: =[1]!thsiFinD("ths_int_chg_ratio_index",$A40,D$1,D$2)/100 | E40: =[1]!thsiFinD("ths_int_chg_ratio_index",$A40,E$1,E$2)/100 | F40: =D40-(E40-D40)/3 | G40: 产业链 | H40: =IFERROR(VLOOKUP($I40,'分类规则'!$A$30:$C$200,2,0),"") | I40: 电力设备 | J40: =IFERROR(VLOOKUP($I40,'分类规则'!$A$30:$C$200,3,0),"") | K40: 亨通光电 | L40: 600487.SH | M40: 2714.4 | N40: 中天科技 | O40: 600522.SH | P40: 1930 | Q40: 长飞光纤 | R40: 601869.SH | S40: 1916.1 | T40: 国电南瑞 | U40: 600406.SH | V40: 1846.7 | W40: 中国中车 | X40: 601766.SH | Y40: 1362.4
A41: 886007.TI | B41: =[1]!thsiFinD("THS_GPJC_STOCK",$A41) | C41: =[1]!thsiFinD("ths_int_chg_ratio_index",$A41,C$1,C$2)/100 | D41: =[1]!thsiFinD("ths_int_chg_ratio_index",$A41,D$1,D$2)/100 | E41: =[1]!thsiFinD("ths_int_chg_ratio_index",$A41,E$1,E$2)/100 | F41: =D41-(E41-D41)/3 | G41: 产业链 | H41: =IFERROR(VLOOKUP($I41,'分类规则'!$A$30:$C$200,2,0),"") | I41: 光伏 | J41: =IFERROR(VLOOKUP($I41,'分类规则'!$A$30:$C$200,3,0),"") | K41: 蓝思科技 | L41: 300433.SZ | M41: 2771.6 | N41: 大族激光 | O41: 002008.SZ | P41: 1290.6 | Q41: 罗博特科 | R41: 300757.SZ | S41: 1082.7 | T41: 隆基绿能 | U41: 601012.SH | V41: 973 | W41: 先导智能 | X41: 300450.SZ | Y41: 728.7
A42: 885948.TI | B42: =[1]!thsiFinD("THS_GPJC_STOCK",$A42) | C42: =[1]!thsiFinD("ths_int_chg_ratio_index",$A42,C$1,C$2)/100 | D42: =[1]!thsiFinD("ths_int_chg_ratio_index",$A42,D$1,D$2)/100 | E42: =[1]!thsiFinD("ths_int_chg_ratio_index",$A42,E$1,E$2)/100 | F42: =D42-(E42-D42)/3 | G42: 产业链 | H42: =IFERROR(VLOOKUP($I42,'分类规则'!$A$30:$C$200,2,0),"") | I42: 电力设备 | J42: =IFERROR(VLOOKUP($I42,'分类规则'!$A$30:$C$200,3,0),"") | K42: 亨通光电 | L42: 600487.SH | M42: 2714.4 | N42: 中天科技 | O42: 600522.SH | P42: 1930 | Q42: 国电南瑞 | R42: 600406.SH | S42: 1846.7 | T42: 特变电工 | U42: 600089.SH | V42: 1178.3 | W42: 中国能建 | X42: 601868.SH | Y42: 895
...

Sheet 分类规则
A1: 概念指数热点监控 — 分类与计算规则
A3: 一、口径目标：跟踪市场资金短期追捧的热点，识别哪个细分方向(二级赛道)最热。
A5: 二、加速度 = 近一周 − (近一月 − 近一周) ÷ 3 【F列】
A6: 含义：本周涨幅 减去 前三周的平均周涨幅。>0=本周比过去三周更猛(在加速/发动)，<0=在退潮。
A7: 目的：YTD是"今年赢家"，本指标抓"现在刚发动"的方向，更贴近短期资金。
A9: 三、概念类型【G列，决定是否计入产业热度】
A10: 产业链 = 真实产业细分方向(计入热度)；公司链 = 单龙头供应链篮子(计入)；
A11: 主题事件 = 区域/政策/事件/业绩(不计)；宽基风格 = 指数/风格/资金面(不计)。
A12: 统计"哪个方向最热"时只用 产业链+公司链，剔除 主题事件/宽基风格(否则污染排序)。
A14: 四、一级 / 二级【H/I列】：二级为细分赛道(硬编码)，一级由二级自动带出(VLOOKUP本表)。
A15: 二级由概念名称语义判定(复用已确认分类+名称规则)，是排序"最热方向"的主键。
A17: 五、产业链位置【J列，由二级VLOOKUP本表自动带出】
... A26: 下表为 二级→一级→产业链位置 主表，H/J列VLOOKUP引用此处(第30行起，请勿插改行)：
A29: 二级 | B29: 一级 | C29: 产业链位置
A30: AIoT/物联网 | B30: 科技·TMT | C30: 中游
A31: AI应用 | B31: 科技·TMT | C31: 下游
A32: PCB/覆铜板 | B32: 科技·TMT | C32: 中游
A33: 传媒/游戏 | B33: 科技·TMT | C33: 下游
A34: 传媒互联网 | B34: 科技·TMT | C34: 下游
A35: 信创/国产化 | B35: 科技·TMT | C35: 下游
A36: 光通信/算力硬件 | B36: 科技·TMT | C36: 中游
A37: 区块链/Web3 | B37: 科技·TMT | C37: 下游
A38: 半导体 | B38: 科技·TMT | C38: 中游
A39: 消费电子 | B39: 科技·TMT | C39: 中游
A40: 综合 | B40: 科技·TMT | C40: 中游
... A115: 风格/事件 | B115: 市场风格 | C115: —

Sheet 二级赛道热度
A1: 二级赛道 | B1: 一级 | C1: 概念数 | D1: 周涨幅均值 | E1: 月涨幅均值 | F1: 加速度均值 | G1: 周内最强
A2: AIoT/物联网 | B2: 科技·TMT | C2: =COUNTIF('概念指数热点监控'!$I$4:$I$396,$A2) | D2: =IFERROR(AVERAGEIF('概念指数热点监控'!$I$4:$I$396,$A2,'概念指数热点监控'!$D$4:$D$396),"") | E2: =IFERROR(AVERAGEIF('概念指数热点监控'!$I$4:$I$396,$A2,'概念指数热点监控'!$E$4:$E$396),"") | F2: =IFERROR(AVERAGEIF('概念指数热点监控'!$I$4:$I$396,$A2,'概念指数热点监控'!$F$4:$F$396),"") | G2: =IFERROR(MAXIFS('概念指数热点监控'!$D$4:$D$396,'概念指数热点监控'!$I$4:$I$396,$A2),"")
A3: AI应用 | B3: 科技·TMT | C3: =COUNTIF('概念指数热点监控'!$I$4:$I$396,$A3) | D3: =IFERROR(AVERAGEIF('概念指数热点监控'!$I$4:$I$396,$A3,'概念指数热点监控'!$D$4:$D$396),"") | E3: =IFERROR(AVERAGEIF('概念指数热点监控'!$I$4:$I$396,$A3,'概念指数热点监控'!$E$4:$E$396),"") | F3: =IFERROR(AVERAGEIF('概念指数热点监控'!$I$4:$I$396,$A3,'概念指数热点监控'!$F$4:$F$396),"") | G3: =IFERROR(MAXIFS('概念指数热点监控'!$D$4:$D$396,'概念指数热点监控'!$I$4:$I$396,$A3),"")
A4: PCB/覆铜板 | B4: 科技·TMT | C4: =COUNTIF('概念指数热点监控'!$I$4:$I$396,$A4) | D4: =IFERROR(AVERAGEIF('概念指数热点监控'!$I$4:$I$396,$A4,'概念指数热点监控'!$D$4:$D$396),"") | E4: =IFERROR(AVERAGEIF('概念指数热点监控'!$I$4:$I$396,$A4,'概念指数热点监控'!$E$4:$E$396),"") | F4: =IFERROR(AVERAGEIF('概念指数热点监控'!$I$4:$I$396,$A4,'概念指数热点监控'!$F$4:$F$396),"") | G4: =IFERROR(MAXIFS('概念指数热点监控'!$D$4:$D$396,'概念指数热点监控'!$I$4:$I$396,$A4),"")
A5: 传媒/游戏 | B5: 科技·TMT | C5: =COUNTIF('概念指数热点监控'!$I$4:$I$396,$A5) | D5: =IFERROR(AVERAGEIF('概念指数热点监控'!$I$4:$I$396,$A5,'概念指数热点监控'!$D$4:$D$396),"") | E5: =IFERROR(AVERAGEIF('概念指数热点监控'!$I$4:$I$396,$A5,'概念指数热点监控'!$E$4:$E$396),"") | F5: =IFERROR(AVERAGEIF('概念指数热点监控'!$I$4:$I$396,$A5,'概念指数热点监控'!$F$4:$F$396),"") | G5: =IFERROR(MAXIFS('概念指数热点监控'!$D$4:$D$396,'概念指数热点监控'!$I$4:$I$396,$A5),"")
A6: 传媒互联网 | B6: 科技·TMT | C6: =COUNTIF('概念指数热点监控'!$I$4:$I$396,$A6) | D6: =IFERROR(AVERAGEIF('概念指数热点监控'!$I$4:$I$396,$A6,'概念指数热点监控'!$D$4:$D$396),"") | E6: =IFERROR(AVERAGEIF('概念指数热点监控'!$I$4:$I$396,$A6,'概念指数热点监控'!$E$4:$E$396),"") | F6: =IFERROR(AVERAGEIF('概念指数热点监控'!$I$4:$I$396,$A6,'概念指数热点监控'!$F$4:$F$396),"") | G6: =IFERROR(MAXIFS('概念指数热点监控'!$D$4:$D$396,'概念指数热点监控'!$I$4:$I$396,$A6),"")
A7: 信创/国产化 | B7: 科技·TMT | C7: =COUNTIF('概念指数热点监控'!$I$4:$I$396,$A7) | D7: =IFERROR(AVERAGEIF('概念指数热点监控'!$I$4:$I$396,$A7,'概念指数热点监控'!$D$4:$D$396),"") | E7: =IFERROR(AVERAGEIF('概念指数热点监控'!$I$4:$I$396,$A7,'概念指数热点监控'!$E$4:$E$396),"") | F7: =IFERROR(AVERAGEIF('概念指数热点监控'!$I$4:$I$396,$A7,'概念指数热点监控'!$F$4:$F$396),"") | G7: =IFERROR(MAXIFS('概念指数热点监控'!$D$4:$D$396,'概念指数热点监控'!$I$4:$I$396,$A7),"")
A8: 光通信/算力硬件 | B8: 科技·TMT | C8: =COUNTIF('概念指数热点监控'!$I$4:$I$396,$A8) | D8: =IFERROR(AVERAGEIF('概念指数热点监控'!$I$4:$I$396,$A8,'概念指数热点监控'!$D$4:$D$396),"") | E8: =IFERROR(AVERAGEIF('概念指数热点监控'!$I$4:$I$396,$A8,'概念指数热点监控'!$E$4:$E$396),"") | F8: =IFERROR(AVERAGEIF('概念指数热点监控'!$I$4:$I$396,$A8,'概念指数热点监控'!$F$4:$F$396),"") | G8: =IFERROR(MAXIFS('概念指数热点监控'!$D$4:$D$396,'概念指数热点监控'!$I$4:$I$396,$A8),"")
A9: 区块链/Web3 | B9: 科技·TMT | C9: =COUNTIF('概念指数热点监控'!$I$4:$I$396,$A9) | D9: =IFERROR(AVERAGEIF('概念指数热点监控'!$I$4:$I$396,$A9,'概念指数热点监控'!$D$4:$D$396),"") | E9: =IFERROR(AVERAGEIF('概念指数热点监控'!$I$4:$I$396,$A9,'概念指数热点监控'!$E$4:$E$396),"") | F9: =IFERROR(AVERAGEIF('概念指数热点监控'!$I$4:$I$396,$A9,'概念指数热点监控'!$F$4:$F$396),"") | G9: =IFERROR(MAXIFS('概念指数热点监控'!$D$4:$D$396,'概念指数热点监控'!$I$4:$I$396,$A9),"")
A10: 半导体 | B10: 科技·TMT | C10: =COUNTIF('概念指数热点监控'!$I$4:$I$396,$A10) | D10: =IFERROR(AVERAGEIF('概念指数热点监控'!$I$4:$I$396,$A10,'概念指数热点监控'!$D$4:$D$396),"") | E10: =IFERROR(AVERAGEIF('概念指数热点监控'!$I$4:$I$396,$A10,'概念指数热点监控'!$E$4:$E$396),"") | F10: =IFERROR(AVERAGEIF('概念指数热点监控'!$I$4:$I$396,$A10,'概念指数热点监控'!$F$4:$F$396),"") | G10: =IFERROR(MAXIFS('概念指数热点监控'!$D$4:$D$396,'概念指数热点监控'!$I$4:$I$396,$A10),"")
A11: 消费电子 | B11: 科技·TMT | C11: =COUNTIF('概念指数热点监控'!$I$4:$I$396,$A11) | D11: =IFERROR(AVERAGEIF('概念指数热点监控'!$I$4:$I$396,$A11,'概念指数热点监控'!$D$4:$D$396),"") | E11: =IFERROR(AVERAGEIF('概念指数热点监控'!$I$4:$I$396,$A11,'概念指数热点监控'!$E$4:$E$396),"") | F11: =IFERROR(AVERAGEIF('概念指数热点监控'!$I$4:$I$396,$A11,'概念指数热点监控'!$F$4:$F$396),"") | G11: =IFERROR(MAXIFS('概念指数热点监控'!$D$4:$D$396,'概念指数热点监控'!$I$4:$I$396,$A11),"")
A12: 综合 | B12: 科技·TMT | C12: =COUNTIF('概念指数热点监控'!$I$4:$I$396,$A12) | D12: =IFERROR(AVERAGEIF('概念指数热点监控'!$I$4:$I$396,$A12,'概念指数热点监控'!$D$4:$D$396),"") | E12: =IFERROR(AVERAGEIF('概念指数热点监控'!$I$4:$I$396,$A12,'概念指数热点监控'!$E$4:$E$396),"") | F12: =IFERROR(AVERAGEIF('概念指数热点监控'!$I$4:$I$396,$A12,'概念指数热点监控'!$F$4:$F$396),"") | G12: =IFERROR(MAXIFS('概念指数热点监控'!$D$4:$D$396,'概念指数热点监控'!$I$4:$I$396,$A12),"")
A13: 通信 | B13: 科技·TMT | C13: =COUNTIF('概念指数热点监控'!$I$4:$I$396,$A13) | D13: =IFERROR(AVERAGEIF('概念指数热点监控'!$I$4:$I$396,$A13,'概念指数热点监控'!$D$4:$D$396),"") | E13: =IFERROR(AVERAGEIF('概念指数热点监控'!$I$4:$I$396,$A13,'概念指数热点监控'!$E$4:$E$396),"") | F13: =IFERROR(AVERAGEIF('概念指数热点监控'!$I$4:$I$396,$A13,'概念指数热点监控'!$F$4:$F$396),"") | G13: =IFERROR(MAXIFS('概念指数热点监控'!$D$4:$D$396,'概念指数热点监控'!$I$4:$I$396,$A13),"")
... A55: 航运 | B55: 交通运输 | C55: =COUNTIF('概念指数热点监控'!$I$4:$I$396,$A55) | D55: =IFERROR(AVERAGEIF('概念指数热点监控'!$I$4:$I$396,$A55,'概念指数热点监控'!$D$4:$D$396),"") | E55: =IFERROR(AVERAGEIF('概念指数热点监控'!$I$4:$I$396,$A55,'概念指数热点监控'!$E$4:$E$396),"") | F55: =IFERROR(AVERAGEIF('概念指数热点监控'!$I$4:$I$396,$A55,'概念指数热点监控'!$F$4:$F$396),"") | G55: =IFERROR(MAXIFS('概念指数热点监控'!$D$4:$D$396,'概念指数热点监控'!$I$4:$I$396,$A55),"")
A57: 提示：刷新iFinD后，选中表格按"周涨幅均值"降序排序，即得本周最热细分方向。
