Workbook

Sheet 绩效总览
A1: 玄驹组合·卫星轮动引擎V1 历史回测绩效报告
A2: 区间: 2019-07-15 ~ 2026-07-07(建仓完成日起) | 参数: K=3/持续期12日/3窗口风险调整动量/无即时止损/T+3/最短持有7天/只动进出腿
A3: ⚠️ 指数池确定于2026年(含后见之明),收益水平系统性偏乐观;本报告用于理解策略机制、换手结构与仓位行为,不构成收益预期。
A5: 无风险利率(夏普) | B5: 0.015 | C5: 区间自然日数 | D5: 2549
A7: 指标 | B7: 策略 | C7: 科技100 | D7: 创业板指 | E7: 万得全A
A8: 累计收益 | B8: ='净值曲线'!B1693/'净值曲线'!B2-1 | C8: ='净值曲线'!C1693/'净值曲线'!C2-1 | D8: ='净值曲线'!D1693/'净值曲线'!D2-1 | E8: ='净值曲线'!E1693/'净值曲线'!E2-1
A9: 年化收益 | B9: =(1+B8)^(365/$D$5)-1 | C9: =(1+C8)^(365/$D$5)-1 | D9: =(1+D8)^(365/$D$5)-1 | E9: =(1+E8)^(365/$D$5)-1
A10: 年化波动 | B10: =STDEV.S('净值曲线'!F3:F1693)*SQRT(250) | C10: =STDEV.S('净值曲线'!H3:H1693)*SQRT(250) | D10: =STDEV.S('净值曲线'!J3:J1693)*SQRT(250) | E10: =STDEV.S('净值曲线'!L3:L1693)*SQRT(250)
A11: 夏普比率 | B11: =(B9-$B$5)/B10 | C11: =(C9-$B$5)/C10 | D11: =(D9-$B$5)/D10 | E11: =(E9-$B$5)/E10
A12: 最大回撤 | B12: =MIN('净值曲线'!G3:G1693) | C12: =MIN('净值曲线'!I3:I1693) | D12: =MIN('净值曲线'!K3:K1693) | E12: =MIN('净值曲线'!M3:M1693)
A13: 卡玛比率 | B13: =B9/ABS(B12) | C13: =C9/ABS(C12) | D13: =D9/ABS(D12) | E13: =E9/ABS(E12)
A14: 年均监管换手率 | B14: 0.93165744 | C14: - | D14: - | E14: -
A15: 最差年监管换手 | B15: 1.0579989 | F15: 口径:(申购+赎回)/(2×年均资产),不含建仓;上限200% | Source:调仓记录汇总

Sheet 分年度
A1: 年份 | B1: 策略收益 | C1: 科技100收益 | D1: 创业板指收益 | E1: 万得全A收益 | F1: 超额(vs科技100) | G1: 监管换手率 | H1: 备注
A2: 2019 | B2: ='净值曲线'!B117/'净值曲线'!B2-1 | C2: ='净值曲线'!C117/'净值曲线'!C2-1 | D2: ='净值曲线'!D117/'净值曲线'!D2-1 | E2: ='净值曲线'!E117/'净值曲线'!E2-1 | F2: =B2-C2 | G2: 0.31367112 | H2: 建仓年(不满整年)
A3: 2020 | B3: ='净值曲线'!B360/'净值曲线'!B117-1 | C3: ='净值曲线'!C360/'净值曲线'!C117-1 | D3: ='净值曲线'!D360/'净值曲线'!D117-1 | E3: ='净值曲线'!E360/'净值曲线'!E117-1 | F3: =B3-C3 | G3: 0.80886117
A4: 2021 | B4: ='净值曲线'!B603/'净值曲线'!B360-1 | C4: ='净值曲线'!C603/'净值曲线'!C360-1 | D4: ='净值曲线'!D603/'净值曲线'!D360-1 | E4: ='净值曲线'!E603/'净值曲线'!E360-1 | F4: =B4-C4 | G4: 0.88253719
A5: 2022 | B5: ='净值曲线'!B845/'净值曲线'!B603-1 | C5: ='净值曲线'!C845/'净值曲线'!C603-1 | D5: ='净值曲线'!D845/'净值曲线'!D603-1 | E5: ='净值曲线'!E845/'净值曲线'!E603-1 | F5: =B5-C5 | G5: 1.0579989
A6: 2023 | B6: ='净值曲线'!B1087/'净值曲线'!B845-1 | C6: ='净值曲线'!C1087/'净值曲线'!C845-1 | D6: ='净值曲线'!D1087/'净值曲线'!D845-1 | E6: ='净值曲线'!E1087/'净值曲线'!E845-1 | F6: =B6-C6 | G6: 0.90737986
A7: 2024 | B7: ='净值曲线'!B1329/'净值曲线'!B1087-1 | C7: ='净值曲线'!C1329/'净值曲线'!C1087-1 | D7: ='净值曲线'!D1329/'净值曲线'!D1087-1 | E7: ='净值曲线'!E1329/'净值曲线'!E1087-1 | F7: =B7-C7 | G7: 1.0197631
A8: 2025 | B8: ='净值曲线'!B1572/'净值曲线'!B1329-1 | C8: ='净值曲线'!C1572/'净值曲线'!C1329-1 | D8: ='净值曲线'!D1572/'净值曲线'!D1329-1 | E8: ='净值曲线'!E1572/'净值曲线'!E1329-1 | F8: =B8-C8 | G8: 0.9134044
A9: 2026 | B9: ='净值曲线'!B1693/'净值曲线'!B1572-1 | C9: ='净值曲线'!C1693/'净值曲线'!C1572-1 | D9: ='净值曲线'!D1693/'净值曲线'!D1572-1 | E9: ='净值曲线'!E1693/'净值曲线'!E1572-1 | F9: =B9-C9 | G9: 0.29149633 | H9: 半年

Sheet 调仓记录
A1: 序号 | B1: 信号日 | C1: 执行日 | D1: 类型 | E1: 卖出(占组合) | F1: 买入(占组合) | G1: 金额(元) | H1: 占组合 | I1: 执行后持仓 | J1: 卫星现金占比 | K1: 当年累计换手
A2: 1 | B2: 43656 | C2: 43661 | D2: 建仓 | F2: 半导体材料设备(14.4%), 港股通创新药(14.4%) | G2: 3300 | H2: 0.28774415 | I2: 半导体材料设备/港股通创新药 | J2: 0.14387208 | K2: 0
A3: 2 | B3: 43661 | C3: 43664 | D3: 核心再平衡 | G3: 1372.3368 | H3: 0.12001814 | I3: 半导体材料设备/港股通创新药 | J3: 0.16373611 | K3: 0.060786495
A4: 3 | B4: 43719 | C4: 43725 | D4: 卫星调仓 | F4: 计算机(15.0%) | G4: 1872.2261 | H4: 0.14987736 | I4: 半导体材料设备/港股通创新药/计算机 | J4: 0 | K4: 0.14194528
A5: 4 | B5: 43749 | C5: 43754 | D5: 复核撤销 | G5: 0 | H5: 0 | I5: 半导体材料设备/港股通创新药/计算机 | J5: 0 | K5: 0.14090776
A6: 5 | B6: 43815 | C6: 43818 | D6: 卫星调仓 | E6: 港股通创新药(15.4%) | F6: 新能源电池(15.4%) | G6: 4155.4588 | H6: 0.30718048 | I6: 半导体材料设备/计算机/新能源电池 | J6: 0 | K6: 0.31497836
A7: 6 | B7: 43844 | C7: 43847 | D7: 卫星调仓 | E7: 计算机(14.0%) | F7: 工业有色(14.0%) | G7: 4187.9319 | H7: 0.28063445 | I7: 半导体材料设备/新能源电池/工业有色 | J7: 0 | K7: 0.14501716
A8: 7 | B8: 43874 | C8: 43879 | D8: 卫星调仓 | E8: 工业有色(13.0%) | G8: 2159.87 | H8: 0.12951827 | I8: 半导体材料设备/新能源电池 | J8: 0.12951827 | K8: 0.2128177
A9: 8 | B9: 43907 | C9: 43910 | D9: 核心再平衡 | G9: 1591.6269 | H9: 0.10605543 | I9: 半导体材料设备/新能源电池 | J9: 0.12999358 | K9: 0.25624011
A10: 9 | B10: 43921 | C10: 43924 | D10: 卫星调仓 | E10: 新能源电池(13.4%) | G10: 1943.9277 | H10: 0.13379916 | I10: 半导体材料设备 | J10: 0.26807675 | K10: 0.32269952
A11: 10 | B11: 43943 | C11: 43948 | D11: 卫星调仓 | E11: 半导体材料设备(20.6%) | G11: 3018.0113 | H11: 0.20553837 | J11: 0.47078993 | K11: 0.4240819
A12: 11 | B12: 43969 | C12: 43972 | D12: 卫星调仓 | F12: 港股通互联网(15.4%) | G12: 2304.2726 | H12: 0.15425822 | I12: 港股通互联网 | J12: 0.30851645 | K12: 0.50073308
A13: 12 | B13: 43990 | C13: 43993 | D13: 卫星调仓 | F13: 半导体材料设备(15.2%) | G13: 2352.482 | H13: 0.15198589 | I13: 港股通互联网/半导体材料设备 | J13: 0.14575659 | K13: 0.57898893
A14: 13 | B14: 44013 | C14: 44018 | D14: 卫星调仓 | F14: 新能源电池(12.8%) | G14: 2256.0632 | H14: 0.12761813 | I14: 港股通互联网/半导体材料设备/新能源电池 | J14: 0 | K14: 0.64733072
A15: 14 | B15: 44028 | C15: 44033 | D15: 核心再平衡 | G15: 1888.4102 | H15: 0.10165153 | I15: 港股通互联网/半导体材料设备/新能源电池 | J15: 0 | K15: 0.69638382
A16: 15 | B16: 44050 | C16: 44055 | D16: 卫星调仓 | E16: 半导体材料设备(16.9%) | G16: 3102.672 | H16: 0.16897704 | I16: 港股通互联网/新能源电池 | J16: 0.16897704 | K16: 0.77929023
A17: 16 | B17: 44071 | C17: 44076 | D17: 卫星调仓 | F17: 机器人(15.9%) | G17: 3102.672 | H17: 0.15853412 | I17: 港股通互联网/新能源电池/机器人 | J17: 0 | K17: 0.86206433
A18: 17 | B18: 44228 | C18: 44231 | D18: 核心再平衡 | G18: 2565.8982 | H18: 0.11141032 | I18: 港股通互联网/新能源电池/机器人 | J18: 0 | K18: 0.055925288
A19: 18 | B19: 44237 | C19: 44249 | D19: 卫星调仓 | E19: 机器人(13.6%) | G19: 3160.8526 | H19: 0.1357863 | I19: 港股通互联网/新能源电池 | J19: 0.1357863 | K19: 0.12396636
A20: 19 | B20: 44274 | C20: 44279 | D20: 卫星调仓 | E20: 新能源电池(16.0%) | G20: 3273.4295 | H20: 0.16021313 | I20: 港股通互联网 | J20: 0.31491634 | K20: 0.20058198
A21: 20 | B21: 44298 | C21: 44301 | D21: 卫星调仓 | E21: 港股通互联网(17.8%) | G21: 3706.8293 | H21: 0.17826256 | J21: 0.48768916 | K21: 0.28761533
A22: 21 | B22: 44322 | C22: 44327 | D22: 卫星调仓 | F22: 港股通创新药(16.1%) | G22: 3380.3705 | H22: 0.16063431 | I22: 港股通创新药 | J22: 0.32126862 | K22: 0.36680781
A23: 22 | B23: 44347 | C23: 44350 | D23: 卫星调仓 | F23: 新能源电池(16.3%) | G23: 3596.0504 | H23: 0.16292641 | I23: 港股通创新药/新能源电池 | J23: 0.14338277 | K23: 0.4490514
A24: 23 | B24: 44369 | C24: 44372 | D24: 卫星调仓 | F24: 半导体材料设备(13.6%) | G24: 3164.6905 | H24: 0.13648598 | I24: 港股通创新药/新能源电池/半导体材料设备 | J24: 0 | K24: 0.51971019
A25: 24 | B25: 44413 | C25: 44418 | D25: 卫星调仓 | E25: 港股通创新药(14.8%) | F25: 工业有色(14.8%) | G25: 7400.0397 | H25: 0.29611472 | I25: 新能源电池/半导体材料设备/工业有色 | J25: 0 | K25: 0.67381317
A26: 25 | B26: 44469 | C26: 44481 | D26: 卫星调仓 | E26: 半导体材料设备(14.2%) | G26: 3246.3938 | H26: 0.14244529 | I26: 新能源电池/工业有色 | J26: 0.14244529 | K26: 0.73270854
A27: 26 | B27: 44497 | C27: 44502 | D27: 卫星调仓 | E27: 工业有色(14.3%) | G27: 3429.1618 | H27: 0.14276785 | I27: 新能源电池 | J27: 0.27792643 | K27: 0.80499305
A28: 27 | B28: 44531 | C28: 44536 | D28: 卫星调仓 | F28: 通信设备(16.7%) | G28: 4143.2028 | H28: 0.16660962 | I28: 新能源电池/通信设备 | J28: 0.1018329 | K28: 0.88764139
A29: 28 | B29: 44572 | C29: 44575 | D29: 卫星调仓 | E29: 新能源电池(20.8%) | G29: 4918.8256 | H29: 0.20759476 | I29: 通信设备 | J29: 0.31447051 | K29: 0.10295384
A30: 29 | B30: 44603 | C30: 44608 | D30: 卫星调仓 | E30: 通信设备(17.1%) | G30: 3876.492 | H30: 0.17134005 | J30: 0.50068041 | K30: 0.18860901
A31: 30 | B31: 44672 | C31: 44677 | D31: 核心再平衡 | G31: 2977.2205 | H31: 0.14931384 | J31: 0.495 | K31: 0.26338575
A32: 31 | B32: 44727 | C32: 44732 | D32: 卫星调仓 | F32: 港股通互联网(15.0%) | G32: 3289.9924 | H32: 0.15027105 | I32: 港股通互联网 | J32: 0.30054211 | K32: 0.34322576
A33: 32 | B33: 44742 | C33: 44747 | D33: 核心再平衡 | G33: 2467.5865 | H33: 0.10905819 | I33: 港股通互联网 | J33: 0.32593382 | K33: 0.39888862
A34: 33 | B34: 44748 | C34: 44753 | D34: 卫星调仓 | F34: 新能源电池(16.6%), 工业有色(16.6%) | G34: 7324.989 | H34: 0.33262682 | I34: 港股通互联网/新能源电池/工业有色 | J34: 0.0022567456 | K34: 0.56527778
A35: 34 | B35: 44769 | C35: 44774 | D35: 卫星调仓 | E35: 港股通互联网(15.4%) | G35: 3336.7986 | H35: 0.15373626 | I35: 新能源电池/工业有色 | J35: 0.15602596 | K35: 0.64176047
A36: 35 | B36: 44790 | C36: 44795 | D36: 卫星调仓 | E36: 工业有色(16.1%) | G36: 3590.5261 | H36: 0.16098275 | I36: 新能源电池 | J36: 0.31281772 | K36: 0.7240944
A37: 36 | B37: 44832 | C37: 44844 | D37: 卫星调仓 | E37: 新能源电池(17.0%) | G37: 3311.7913 | H37: 0.1701456 | J37: 0.52859498 | K37: 0.8066889
A38: 37 | B38: 44866 | C38: 44869 | D38: 卫星调仓 | F38: 计算机(16.7%) | G38: 3429.6044 | H38: 0.16733025 | I38: 计算机 | J38: 0.3346605 | K38: 0.89182288
A39: 38 | B39: 44887 | C39: 44890 | D39: 卫星调仓 | F39: 卫星产业(16.9%) | G39: 3394.6554 | H39: 0.1688633 | I39: 计算机/卫星产业 | J39: 0.1723403 | K39: 0.97406957
A40: 39 | B40: 44915 | C40: 44918 | D40: 卫星调仓 | F40: 港股通互联网(16.9%) | G40: 3281.2131 | H40: 0.16945951 | I40: 计算机/卫星产业/港股通互联网 | J40: 0.0094686772 | K40: 1.0562767
...

Sheet 调仓因子打分
A1: 信号日 | B1: 标的 | C1: 综合分 | D1: z(r20/σ) | E1: z(r60/σ) | F1: z(r120/σ) | G1: 合格排名 | H1: 过资格线 | I1: 当时持有 | J1: 计划动作
A2: 43656 | B2: 港股通创新药 | C2: 1.3797614 | D2: 2.2757951 | E2: 0.10121088 | F2: 1.7622783 | G2: 1 | H2: 是 | I2: 否 | J2: 买入
A3: 43656 | B3: 半导体材料设备 | C3: 1.2182264 | D3: -0.29376208 | E3: 2.3907641 | F3: 1.5576771 | G3: 2 | H3: 是 | I3: 否 | J3: 买入
A4: 43656 | B4: 计算机 | C4: -0.029250757 | D4: 0.087289208 | E4: -0.37477386 | F4: 0.19973238 | H4: 否 | I4: 否
A5: 43656 | B5: 机器人 | C5: -0.14264037 | D5: 0.46655613 | E5: -0.29815037 | F5: -0.59632688 | H5: 否 | I5: 否
A6: 43656 | B6: 卫星产业 | C6: -0.2074232 | D6: -0.37492959 | E6: 0.064978429 | F6: -0.31231844 | H6: 否 | I6: 否
A7: 43656 | B7: 通信设备 | C7: -0.32692689 | D7: -0.66867181 | E7: 0.20648188 | F7: -0.51859075 | H7: 否 | I7: 否
A8: 43656 | B8: 新能源电池 | C8: -0.35535666 | D8: 0.11187826 | E8: -0.78469885 | F8: -0.39324938 | H8: 否 | I8: 否
A9: 43656 | B9: 工业有色 | C9: -0.70525256 | D9: -1.3598851 | E9: -0.1383811 | F9: -0.61749147 | H9: 否 | I9: 否
A10: 43656 | B10: 港股通互联网 | C10: -0.83113739 | D10: -0.24427014 | E10: -1.1674312 | F10: -1.0817109 | H10: 否 | I10: 否
A11: 43656 | B11: 科创芯片设计 | H11: 否 | I11: 否
A13: 43719 | B13: 半导体材料设备 | C13: 1.5668613 | D13: 1.1795472 | E13: 1.6053515 | F13: 1.915685 | G13: 1 | H13: 是 | I13: 是 | J13: 保留
A14: 43719 | B14: 计算机 | C14: 0.5325351 | D14: 0.97027093 | E14: 0.44254895 | F14: 0.18478543 | G14: 2 | H14: 是 | I14: 否 | J14: 买入
A15: 43719 | B15: 新能源电池 | C15: 0.31806813 | D15: 0.67270611 | E15: 0.46571937 | F15: -0.18422108 | G15: 3 | H15: 是 | I15: 否
A16: 43719 | B16: 卫星产业 | C16: 0.24983839 | D16: 0.67105719 | E16: -0.0051290384 | F16: 0.083587027 | G16: 4 | H16: 是 | I16: 否
A17: 43719 | B17: 通信设备 | C17: 0.21504538 | D17: -0.0083200628 | E17: 0.3403013 | F17: 0.3131549 | G17: 5 | H17: 是 | I17: 否
A18: 43719 | B18: 机器人 | C18: -0.2429842 | D18: -0.2836718 | E18: 0.090824756 | F18: -0.53610554 | G18: 6 | H18: 是 | I18: 否
A19: 43719 | B19: 港股通创新药 | C19: -0.3592244 | D19: -1.3954649 | E19: -0.13257423 | F19: 0.45036597 | G19: 7 | H19: 是 | I19: 是 | J19: 保留
A20: 43719 | B20: 工业有色 | C20: -0.90401073 | D20: -1.6465295 | E20: -0.72208821 | F20: -0.34341444 | G20: 8 | H20: 是 | I20: 否
A21: 43719 | B21: 港股通互联网 | C21: -1.3761289 | D21: -0.15959514 | E21: -2.0849544 | F21: -1.8838373 | H21: 否 | I21: 否
A22: 43719 | B22: 科创芯片设计 | H22: 否 | I22: 否
A24: 43815 | B24: 半导体材料设备 | C24: 1.4387262 | D24: 0.35415332 | E24: 1.8246384 | F24: 2.1373868 | G24: 1 | H24: 是 | I24: 是 | J24: 保留
A25: 43815 | B25: 新能源电池 | C25: 0.61227345 | D25: 1.2043478 | E25: 0.34737952 | F25: 0.28509299 | G25: 2 | H25: 是 | I25: 否 | J25: 买入
A26: 43815 | B26: 通信设备 | C26: 0.07401778 | D26: 0.29912787 | E26: -0.26548304 | F26: 0.1884085 | G26: 3 | H26: 是 | I26: 否
A27: 43815 | B27: 港股通互联网 | C27: -0.14938402 | D27: -0.12954467 | E27: 0.77921832 | F27: -1.0978257 | G27: 4 | H27: 是 | I27: 否
A28: 43815 | B28: 计算机 | C28: -0.149561 | D28: -0.15404914 | E28: -0.3262647 | F28: 0.031630855 | G28: 5 | H28: 是 | I28: 是 | J28: 保留
A29: 43815 | B29: 机器人 | C29: -0.262453 | D29: -0.1180783 | E29: -0.44315381 | F29: -0.22612689 | G29: 6 | H29: 是 | I29: 否
A30: 43815 | B30: 港股通创新药 | C30: -0.42966102 | D30: -2.3926493 | E30: 0.60648473 | F30: 0.4971815 | H30: 否 | I30: 是 | J30: 卖出
A31: 43815 | B31: 工业有色 | C31: -0.54843478 | D31: 0.70992626 | E31: -1.1629387 | F31: -1.1922919 | G31: 7 | H31: 是 | I31: 否
A32: 43815 | B32: 卫星产业 | C32: -0.58552357 | D32: 0.22676612 | E32: -1.3598807 | F32: -0.62345612 | G32: 8 | H32: 是 | I32: 否
A33: 43815 | B33: 科创芯片设计 | H33: 否 | I33: 否
A35: 43844 | B35: 工业有色 | C35: 0.88646284 | D35: 1.8413267 | E35: 1.0963316 | F35: -0.27826973 | G35: 1 | H35: 是 | I35: 否 | J35: 买入
A36: 43844 | B36: 半导体材料设备 | C36: 0.85502613 | D36: -0.70997066 | E36: 1.143564 | F36: 2.131485 | G36: 2 | H36: 是 | I36: 是 | J36: 保留
A37: 43844 | B37: 新能源电池 | C37: 0.7723904 | D37: 0.55083811 | E37: 1.137782 | F37: 0.62855107 | G37: 3 | H37: 是 | I37: 是 | J37: 保留
A38: 43844 | B38: 机器人 | C38: 0.37183577 | D38: 0.73640971 | E38: 0.25243663 | F38: 0.12666099 | G38: 4 | H38: 是 | I38: 否
A39: 43844 | B39: 港股通互联网 | C39: -0.20627728 | D39: 0.68063942 | E39: -0.15745148 | F39: -1.1420198 | G39: 5 | H39: 是 | I39: 否
A40: 43844 | B40: 计算机 | C40: -0.33479437 | D40: -0.56634078 | E40: -0.60377923 | F40: 0.16573691 | G40: 6 | H40: 是 | I40: 是 | J40: 卖出
A41: 43844 | B41: 通信设备 | C41: -0.45234501 | D41: -1.0064361 | E41: -0.51017069 | F41: 0.15957171 | G41: 7 | H41: 是 | I41: 否
A42: 43844 | B42: 卫星产业 | C42: -0.60204911 | D42: -0.37738307 | E42: -0.58746601 | F42: -0.84129825 | G42: 8 | H42: 是 | I42: 否
A43: 43844 | B43: 港股通创新药 | C43: -1.2902494 | D43: -1.1490833 | E43: -1.7712469 | F43: -0.95041794 | G43: 9 | H43: 是 | I43: 否
...

Sheet 月度持仓
A1: 月末 | B1: 现金(顶层) | C1: 核心:科技100 | D1: 半导体材料设备 | E1: 科创芯片设计 | F1: 卫星产业 | G1: 港股通互联网 | H1: 通信设备 | I1: 计算机 | J1: 机器人 | K1: 新能源电池 | L1: 港股通创新药 | M1: 工业有色 | N1: 卫星内现金 | O1: 合计
A2: 43677 | B2: 0.0097371889 | C2: 0.49981232 | D2: 0.16755131 | E2: 0 | F2: 0 | G2: 0 | H2: 0 | I2: 0 | J2: 0 | K2: 0 | L2: 0.16346624 | M2: 0 | N2: 0.15943294 | O2: =SUM(B2:N2)
A3: 43708 | B3: 0.0094705527 | C3: 0.49245136 | D3: 0.17579703 | E3: 0 | F3: 0 | G3: 0 | H3: 0 | I3: 0 | J3: 0 | K3: 0 | L3: 0.16721391 | M3: 0 | N3: 0.15506715 | O3: =SUM(B3:N3)
A4: 43738 | B4: 0.0094499368 | C4: 0.5011075 | D4: 0.18691704 | E4: 0 | F4: 0 | G4: 0 | H4: 0 | I4: 0.14501417 | J4: 0 | K4: 0 | L4: 0.15751134 | M4: 0 | N4: 0 | O4: =SUM(B4:N4)
A5: 43769 | B5: 0.0091603249 | C5: 0.49059892 | D5: 0.18515974 | E5: 0 | F5: 0 | G5: 0 | H5: 0 | I5: 0.14101001 | J5: 0 | K5: 0 | L5: 0.174071 | M5: 0 | N5: 0 | O5: =SUM(B5:N5)
A6: 43799 | B6: 0.0092096074 | C6: 0.497471 | D6: 0.19101381 | E6: 0 | F6: 0 | G6: 0 | H6: 0 | I6: 0.13935097 | J6: 0 | K6: 0 | L6: 0.16295461 | M6: 0 | N6: 0 | O6: =SUM(B6:N6)
A7: 43830 | B7: 0.0084133816 | C7: 0.4911849 | D7: 0.20808838 | E7: 0 | F7: 0 | G7: 0 | H7: 0 | I7: 0.13832269 | J7: 0 | K7: 0.15399065 | L7: 0 | M7: 0 | N7: 0 | O7: =SUM(B7:N7)
A8: 43861 | B8: 0.0075855848 | C8: 0.46977622 | D8: 0.23497835 | E8: 0 | F8: 0 | G8: 0 | H8: 0 | I8: 0 | J8: 0 | K8: 0.15460909 | L8: 0 | M8: 0.13305076 | N8: 0 | O8: =SUM(B8:N8)
A9: 43890 | B9: 0.0070967894 | C9: 0.46030172 | D9: 0.24771669 | E9: 0 | F9: 0 | G9: 0 | H9: 0 | I9: 0 | J9: 0 | K9: 0.15083206 | L9: 0 | M9: 0 | N9: 0.13405275 | O9: =SUM(B9:N9)
A10: 43921 | B10: 0.010599831 | C10: 0.5142151 | D10: 0.20242993 | E10: 0 | F10: 0 | G10: 0 | H10: 0 | I10: 0 | J10: 0 | K10: 0.13496414 | L10: 0 | M10: 0 | N10: 0.137791 | O10: =SUM(B10:N10)
A11: 43951 | B11: 0.010065249 | C11: 0.52630504 | D11: 0 | E11: 0 | F11: 0 | G11: 0 | H11: 0 | I11: 0 | J11: 0 | K11: 0 | L11: 0 | M11: 0 | N11: 0.46362971 | O11: =SUM(B11:N11)
A12: 43982 | B12: 0.01021718 | C12: 0.52225283 | D12: 0 | E12: 0 | F12: 0 | G12: 0.15377797 | H12: 0 | I12: 0 | J12: 0 | K12: 0 | L12: 0 | M12: 0 | N12: 0.31375201 | O12: =SUM(B12:N12)
A13: 44012 | B13: 0.0089796183 | C13: 0.54460869 | D13: 0.15180792 | E13: 0 | F13: 0 | G13: 0.15961404 | H13: 0 | I13: 0 | J13: 0 | K13: 0 | L13: 0 | M13: 0 | N13: 0.13498974 | O13: =SUM(B13:N13)
... A86: 46234 | B86: 0.0060833108 | C86: 0.4864897 | D86: 0.13261638 | E86: 0.10799554 | F86: 0 | G86: 0 | H86: 0.26681507 | I86: 0 | J86: 0 | K86: 0 | L86: 0 | M86: 0 | N86: 0 | O86: =SUM(B86:N86)

Sheet 参数快照
A1: 参数 | B1: 取值
A2: K(目标持有数) | B2: 3
A3: 持续期persist(交易日) | B3: 12
A4: 打分 | B4: 3窗口风险调整动量 z(r20/σ20)+z(r60/σ60)+z(r120/σ120) 等权; 量能项未启用
A5: 资格线 | B5: 收盘价>MA60 且 历史≥120交易日
A6: 即时止损 | B6: 无(退出仅靠轮换持续期; 排名跌出前K+1持续12日)
A7: 权重 | B7: 入场=min(现金等分,卫星桶/K); 此后只动进出腿,不修剪不重等权
A8: 执行延迟 | B8: T+3交易日,执行日复核,信号消失撤单
A9: 最短持有 | B9: 7自然日(C份额惩罚性赎回费)
A10: 核心仓 | B10: 科技100,占可投50%,band 45%-55%
A11: 顶层现金 | B11: 1%(货基)
A12: 换手约束 | B12: 监管口径(申购+赎回)/(2×年均资产)≤200%; 本回测自然换手未触顶,throttle未启用
... A15: 引擎版本 | B15: V1平台档(参数经5×4×2×2敏感性网格验证为平台而非尖峰)

Sheet 净值曲线
A1: 日期 | B1: 策略 | C1: 科技100 | D1: 创业板指 | E1: 万得全A | F1: 策略日收益 | G1: 策略回撤 | H1: 科技100日收益 | I1: 科技100回撤 | J1: 创业板指日收益 | K1: 创业板指回撤 | L1: 万得全A日收益 | M1: 万得全A回撤
A2: 43661 | B2: 1 | C2: 1 | D2: 1 | E2: 1
A3: 43662 | B3: 1.0022917 | C3: 0.999657 | D3: 0.99858168 | E3: 0.99870182 | F3: =B3/B2-1 | G3: =B3/MAX(B$2:B3)-1 | H3: =C3/C2-1 | I3: =C3/MAX(C$2:C3)-1 | J3: =D3/D2-1 | K3: =D3/MAX(D$2:D3)-1 | L3: =E3/E2-1 | M3: =E3/MAX(E$2:E3)-1
A4: 43663 | B4: 1.009317 | C4: 1.0052656 | D4: 1.0017768 | E4: 0.99860138 | F4: =B4/B3-1 | G4: =B4/MAX(B$2:B4)-1 | H4: =C4/C3-1 | I4: =C4/MAX(C$2:C4)-1 | J4: =D4/D3-1 | K4: =D4/MAX(D$2:D4)-1 | L4: =E4/E3-1 | M4: =E4/MAX(E$2:E4)-1
A5: 43664 | B5: 0.99702577 | C5: 0.98873271 | D5: 0.98514444 | E5: 0.9858204 | F5: =B5/B4-1 | G5: =B5/MAX(B$2:B5)-1 | H5: =C5/C4-1 | I5: =C5/MAX(C$2:C5)-1 | J5: =D5/D4-1 | K5: =D5/MAX(D$2:D5)-1 | L5: =E5/E4-1 | M5: =E5/MAX(E$2:E5)-1
A6: 43665 | B6: 1.0017814 | C6: 0.99355875 | D6: 0.99645466 | E6: 0.99429766 | F6: =B6/B5-1 | G6: =B6/MAX(B$2:B6)-1 | H6: =C6/C5-1 | I6: =C6/MAX(C$2:C6)-1 | J6: =D6/D5-1 | K6: =D6/MAX(D$2:D6)-1 | L6: =E6/E5-1 | M6: =E6/MAX(E$2:E6)-1
A7: 43668 | B7: 0.98997488 | C7: 0.98662924 | D7: 0.97964268 | E7: 0.97888683 | F7: =B7/B6-1 | G7: =B7/MAX(B$2:B7)-1 | H7: =C7/C6-1 | I7: =C7/MAX(C$2:C7)-1 | J7: =D7/D6-1 | K7: =D7/MAX(D$2:D7)-1 | L7: =E7/E6-1 | M7: =E7/MAX(E$2:E7)-1
A8: 43669 | B8: 1.0009662 | C8: 0.99836854 | D8: 0.9918954 | E8: 0.98544471 | F8: =B8/B7-1 | G8: =B8/MAX(B$2:B8)-1 | H8: =C8/C7-1 | I8: =C8/MAX(C$2:C8)-1 | J8: =D8/D7-1 | K8: =D8/MAX(D$2:D8)-1 | L8: =E8/E7-1 | M8: =E8/MAX(E$2:E8)-1
A9: 43670 | B9: 1.0114744 | C9: 1.012292 | D9: 1.0040389 | E9: 0.99480726 | F9: =B9/B8-1 | G9: =B9/MAX(B$2:B9)-1 | H9: =C9/C8-1 | I9: =C9/MAX(C$2:C9)-1 | J9: =D9/D8-1 | K9: =D9/MAX(D$2:D9)-1 | L9: =E9/E8-1 | M9: =E9/MAX(E$2:E9)-1
A10: 43671 | B10: 1.022517 | C10: 1.0232708 | D10: 1.0120257 | E10: 1.0009746 | F10: =B10/B9-1 | G10: =B10/MAX(B$2:B10)-1 | H10: =C10/C9-1 | I10: =C10/MAX(C$2:C10)-1 | J10: =D10/D9-1 | K10: =D10/MAX(D$2:D10)-1 | L10: =E10/E9-1 | M10: =E10/MAX(E$2:E10)-1
A11: 43672 | B11: 1.0222457 | C11: 1.0296964 | D11: 1.0092974 | E11: 1.0027749 | F11: =B11/B10-1 | G11: =B11/MAX(B$2:B11)-1 | H11: =C11/C10-1 | I11: =C11/MAX(C$2:C11)-1 | J11: =D11/D10-1 | K11: =D11/MAX(D$2:D11)-1 | L11: =E11/E10-1 | M11: =E11/MAX(E$2:E11)-1
A12: 43675 | B12: 1.0263767 | C12: 1.0293299 | D12: 1.0123148 | E12: 1.0019715 | F12: =B12/B11-1 | G12: =B12/MAX(B$2:B12)-1 | H12: =C12/C11-1 | I12: =C12/MAX(C$2:C12)-1 | J12: =D12/D11-1 | K12: =D12/MAX(D$2:D12)-1 | L12: =E12/E11-1 | M12: =E12/MAX(E$2:E12)-1
A13: 43676 | B13: 1.0256772 | C13: 1.0293305 | D13: 1.021106 | E13: 1.0061785 | F13: =B13/B12-1 | G13: =B13/MAX(B$2:B13)-1 | H13: =C13/C12-1 | I13: =C13/MAX(C$2:C13)-1 | J13: =D13/D12-1 | K13: =D13/MAX(D$2:D13)-1 | L13: =E13/E12-1 | M13: =E13/MAX(E$2:E13)-1
A14: 43677 | B14: 1.023936 | C14: 1.0252908 | D14: 1.014815 | E14: 0.99863114 | F14: =B14/B13-1 | G14: =B14/MAX(B$2:B14)-1 | H14: =C14/C13-1 | I14: =C14/MAX(C$2:C14)-1 | J14: =D14/D13-1 | K14: =D14/MAX(D$2:D14)-1 | L14: =E14/E13-1 | M14: =E14/MAX(E$2:E14)-1
... A1693: 46210 | B1693: 3.2431474 | C1693: 2.6291917 | D1693: 2.5279413 | E1693: 1.683833 | F1693: =B1693/B1692-1 | G1693: =B1693/MAX(B$2:B1693)-1 | H1693: =C1693/C1692-1 | I1693: =C1693/MAX(C$2:C1693)-1 | J1693: =D1693/D1692-1 | K1693: =D1693/MAX(D$2:D1693)-1 | L1693: =E1693/E1692-1 | M1693: =E1693/MAX(E$2:E1693)-1
