Workbook

Sheet 贴图

Sheet 股指
C1: 2020-4-6 | D1: 日度 | E1: =F1-7 -> 46195 | F1: 2026-6-29 | G1: 2026-1-1 | H1: 2026-4-1 | I1: 45200 | J1: 2024-7-1 | K1: 2025-4-1 | L1: 44927 | M1: 44927 | N1: 44562 | O1: 44197 | P1: 43831 | Q1: 43466 | R1: 43101
D2: =TODAY()-1 -> 46209 | E2: =F2-7 -> 46196 | F2: 2026-6-30 | G2: =F2 -> 2026-6-30 | H2: =F2 -> 2026-6-30 | I2: 45291 | J2: 2024-9-30 | K2: 2025-6-30 | L2: 2023-3-31 | M2: 45289 | N2: 44926 | O2: 44561 | P2: 44196 | Q2: 43830 | R2: 43465
B3: 代码 | C3: 申万一级行业 | D3: 昨日 | E3: 前周 | F3: 近一周 | G3: 2026YTD | H3: 2026Q2 | I3: Q4 | J3: Q3 | K3: Q2 | L3: Q1 | M3: 2023年 | N3: 2022年 | O3: 2021年 | P3: 2020年 | Q3: 2019年 | R3: 2018年
B4: 801150.SL | C4: =[1]!thsiFinD("ths_stock_short_name_stock",B4) -> 医药生物 | D4: =[1]!thsiFinD("ths_chg_ratio_index",B4,D$2)/100 -> 0.0069522709 | E4: =[1]!thsiFinD("ths_int_chg_ratio_index",$B4,E$1,E$2) -> 1.749365 | F4: =[1]!thsiFinD("ths_int_chg_ratio_index",$B4,F$1,F$2) -> 4.4848513 | G4: =[1]!thsiFinD("ths_int_chg_ratio_index",$B4,G$1,G$2) -> -10.258627 | H4: =[1]!thsiFinD("ths_int_chg_ratio_index",$B4,H$1,H$2) -> -9.445219 | I4: =[1]!thsiFinD("ths_int_chg_ratio_index",$B4,I$1,I$2) -> -0.0035701658 | J4: =[1]!thsiFinD("ths_int_chg_ratio_index",$B4,J$1,J$2) -> 17.623742 | K4: =[1]!thsiFinD("ths_int_chg_ratio_index",$B4,K$1,K$2) -> 4.9532624 | L4: =[1]!thsiFinD("ths_int_chg_ratio_index",$B4,L$1,L$2) -> 1.8629671 | ... R4: =[1]!thsiFinD("ths_int_chg_ratio_index",$B4,R$1,R$2) -> -27.672089 | Y4: =8.48/5 -> 1.696
B5: 801980.SL | C5: =[1]!thsiFinD("ths_stock_short_name_stock",B5) -> 美容护理 | D5: =[1]!thsiFinD("ths_chg_ratio_index",B5,D$2)/100 -> -0.0072070552 | E5: =[1]!thsiFinD("ths_int_chg_ratio_index",$B5,E$1,E$2) -> -1.0893417 | F5: =[1]!thsiFinD("ths_int_chg_ratio_index",$B5,F$1,F$2) -> 2.9713359 | G5: =[1]!thsiFinD("ths_int_chg_ratio_index",$B5,G$1,G$2) -> -24.862304 | H5: =[1]!thsiFinD("ths_int_chg_ratio_index",$B5,H$1,H$2) -> -17.493519 | I5: =[1]!thsiFinD("ths_int_chg_ratio_index",$B5,I$1,I$2) -> -14.545458 | J5: =[1]!thsiFinD("ths_int_chg_ratio_index",$B5,J$1,J$2) -> 18.207146 | K5: =[1]!thsiFinD("ths_int_chg_ratio_index",$B5,K$1,K$2) -> 4.9227838 | L5: =[1]!thsiFinD("ths_int_chg_ratio_index",$B5,L$1,L$2) -> -1.6341889 | ... R5: =[1]!thsiFinD("ths_int_chg_ratio_index",$B5,R$1,R$2) -> -22.793649
B6: 801880.SL | C6: =[1]!thsiFinD("ths_stock_short_name_stock",B6) -> 汽车 | D6: =[1]!thsiFinD("ths_chg_ratio_index",B6,D$2)/100 -> -0.0044424476 | E6: =[1]!thsiFinD("ths_int_chg_ratio_index",$B6,E$1,E$2) -> -2.3903776 | F6: =[1]!thsiFinD("ths_int_chg_ratio_index",$B6,F$1,F$2) -> 1.0644235 | G6: =[1]!thsiFinD("ths_int_chg_ratio_index",$B6,G$1,G$2) -> -17.822964 | H6: =[1]!thsiFinD("ths_int_chg_ratio_index",$B6,H$1,H$2) -> -12.237187 | I6: =[1]!thsiFinD("ths_int_chg_ratio_index",$B6,I$1,I$2) -> -1.0188913 | J6: =[1]!thsiFinD("ths_int_chg_ratio_index",$B6,J$1,J$2) -> 15.78049 | K6: =[1]!thsiFinD("ths_int_chg_ratio_index",$B6,K$1,K$2) -> -2.2424578 | L6: =[1]!thsiFinD("ths_int_chg_ratio_index",$B6,L$1,L$2) -> 3.9315654 | ... R6: =[1]!thsiFinD("ths_int_chg_ratio_index",$B6,R$1,R$2) -> -34.343632 | AP6: 列2 | AQ6: 列3 | AT6: 列2 | AU6: 列3
B7: 801010.SL | C7: =[1]!thsiFinD("ths_stock_short_name_stock",B7) -> 农林牧渔 | D7: =[1]!thsiFinD("ths_chg_ratio_index",B7,D$2)/100 -> 0.025717167 | E7: =[1]!thsiFinD("ths_int_chg_ratio_index",$B7,E$1,E$2) -> -0.30378191 | F7: =[1]!thsiFinD("ths_int_chg_ratio_index",$B7,F$1,F$2) -> 1.6006056 | G7: =[1]!thsiFinD("ths_int_chg_ratio_index",$B7,G$1,G$2) -> -25.264323 | H7: =[1]!thsiFinD("ths_int_chg_ratio_index",$B7,H$1,H$2) -> -20.190424 | I7: =[1]!thsiFinD("ths_int_chg_ratio_index",$B7,I$1,I$2) -> 1.7252814 | J7: =[1]!thsiFinD("ths_int_chg_ratio_index",$B7,J$1,J$2) -> 9.1985402 | K7: =[1]!thsiFinD("ths_int_chg_ratio_index",$B7,K$1,K$2) -> 6.4915497 | L7: =[1]!thsiFinD("ths_int_chg_ratio_index",$B7,L$1,L$2) -> 1.8562752 | ... R7: =[1]!thsiFinD("ths_int_chg_ratio_index",$B7,R$1,R$2) -> -22.444282 | AP7: 主要指数2025涨幅（截止8.22） | AT7: 2025涨幅前15行业（截止8.22）
B8: 801130.SL | C8: =[1]!thsiFinD("ths_stock_short_name_stock",B8) -> 纺织服饰 | D8: =[1]!thsiFinD("ths_chg_ratio_index",B8,D$2)/100 -> -0.0089787465 | E8: 0 | F8: =[1]!thsiFinD("ths_int_chg_ratio_index",$B8,F$1,F$2) -> -0.42708521 | G8: =[1]!thsiFinD("ths_int_chg_ratio_index",$B8,G$1,G$2) -> -11.819423 | H8: =[1]!thsiFinD("ths_int_chg_ratio_index",$B8,H$1,H$2) -> -10.22838 | I8: =[1]!thsiFinD("ths_int_chg_ratio_index",$B8,I$1,I$2) -> -2.2874632 | J8: =[1]!thsiFinD("ths_int_chg_ratio_index",$B8,J$1,J$2) -> 9.698646 | K8: =[1]!thsiFinD("ths_int_chg_ratio_index",$B8,K$1,K$2) -> 6.4704254 | L8: =[1]!thsiFinD("ths_int_chg_ratio_index",$B8,L$1,L$2) -> 3.7267673 | M8: =[1]!thsiFinD("ths_int_chg_ratio_index",$B8,M$1,M$2) -> 0.33741064 | ... R8: =[1]!thsiFinD("ths_int_chg_ratio_index",$B8,R$1,R$2) -> -34.326417 | S8: =13.22/5 -> 2.644 | AP8: 指数名称 | AQ8: 2025YTD | AT8: 申万一级行业 | AU8: 2025YTD
B9: 801740.SL | C9: =[1]!thsiFinD("ths_stock_short_name_stock",B9) -> 国防军工 | D9: =[1]!thsiFinD("ths_chg_ratio_index",B9,D$2)/100 -> -0.016629459 | E9: =[1]!thsiFinD("ths_int_chg_ratio_index",$B9,E$1,E$2) -> -3.1279845 | F9: =[1]!thsiFinD("ths_int_chg_ratio_index",$B9,F$1,F$2) -> 3.2507576 | G9: =[1]!thsiFinD("ths_int_chg_ratio_index",$B9,G$1,G$2) -> -6.5906658 | H9: =[1]!thsiFinD("ths_int_chg_ratio_index",$B9,H$1,H$2) -> -0.47820638 | I9: =[1]!thsiFinD("ths_int_chg_ratio_index",$B9,I$1,I$2) -> -3.6291008 | J9: =[1]!thsiFinD("ths_int_chg_ratio_index",$B9,J$1,J$2) -> 13.856409 | K9: =[1]!thsiFinD("ths_int_chg_ratio_index",$B9,K$1,K$2) -> 15.013011 | L9: =[1]!thsiFinD("ths_int_chg_ratio_index",$B9,L$1,L$2) -> 3.8622921 | ... R9: =[1]!thsiFinD("ths_int_chg_ratio_index",$B9,R$1,R$2) -> -31.038296 | AP9: wind微盘股指数 | AQ9: 70.116042 | AT9: 通信(申万) | AU9: 44.907835
B10: 801790.SL | C10: =[1]!thsiFinD("ths_stock_short_name_stock",B10) -> 非银金融 | D10: =[1]!thsiFinD("ths_chg_ratio_index",B10,D$2)/100 -> 0.0084438276 | E10: =[1]!thsiFinD("ths_int_chg_ratio_index",$B10,E$1,E$2) -> 6.2304166 | F10: =[1]!thsiFinD("ths_int_chg_ratio_index",$B10,F$1,F$2) -> 1.2105496 | G10: =[1]!thsiFinD("ths_int_chg_ratio_index",$B10,G$1,G$2) -> -15.25894 | H10: =[1]!thsiFinD("ths_int_chg_ratio_index",$B10,H$1,H$2) -> -0.33209276 | I10: =[1]!thsiFinD("ths_int_chg_ratio_index",$B10,I$1,I$2) -> -8.3118835 | J10: =[1]!thsiFinD("ths_int_chg_ratio_index",$B10,J$1,J$2) -> 41.671816 | K10: =[1]!thsiFinD("ths_int_chg_ratio_index",$B10,K$1,K$2) -> 6.2320758 | L10: =[1]!thsiFinD("ths_int_chg_ratio_index",$B10,L$1,L$2) -> 2.3677637 | ... R10: =[1]!thsiFinD("ths_int_chg_ratio_index",$B10,R$1,R$2) -> -25.371968 | AP10: 北证50 | AQ10: 54.197435 | AT10: 有色金属(申万) | AU10: 38.596662
B11: 801110.SL | C11: =[1]!thsiFinD("ths_stock_short_name_stock",B11) -> 家用电器 | D11: =[1]!thsiFinD("ths_chg_ratio_index",B11,D$2)/100 -> 0.0027650325 | E11: =[1]!thsiFinD("ths_int_chg_ratio_index",$B11,E$1,E$2) -> -0.60641538 | F11: =[1]!thsiFinD("ths_int_chg_ratio_index",$B11,F$1,F$2) -> 0.69340495 | G11: =[1]!thsiFinD("ths_int_chg_ratio_index",$B11,G$1,G$2) -> -9.2511114 | H11: =[1]!thsiFinD("ths_int_chg_ratio_index",$B11,H$1,H$2) -> -2.3193736 | I11: =[1]!thsiFinD("ths_int_chg_ratio_index",$B11,I$1,I$2) -> -4.3134523 | J11: =[1]!thsiFinD("ths_int_chg_ratio_index",$B11,J$1,J$2) -> 16.847318 | K11: =[1]!thsiFinD("ths_int_chg_ratio_index",$B11,K$1,K$2) -> -5.3182954 | L11: =[1]!thsiFinD("ths_int_chg_ratio_index",$B11,L$1,L$2) -> 7.7384678 | ... R11: =[1]!thsiFinD("ths_int_chg_ratio_index",$B11,R$1,R$2) -> -31.402943 | AP11: 神鹿1号 | AQ11: 36.2 | AT11: 神鹿1号 | AU11: 36.2
B12: 801200.SL | C12: =[1]!thsiFinD("ths_stock_short_name_stock",B12) -> 商贸零售 | D12: =[1]!thsiFinD("ths_chg_ratio_index",B12,D$2)/100 -> -0.005398364 | E12: =[1]!thsiFinD("ths_int_chg_ratio_index",$B12,E$1,E$2) -> 0.067495579 | F12: =[1]!thsiFinD("ths_int_chg_ratio_index",$B12,F$1,F$2) -> 0.81666107 | G12: =[1]!thsiFinD("ths_int_chg_ratio_index",$B12,G$1,G$2) -> -29.423468 | H12: =[1]!thsiFinD("ths_int_chg_ratio_index",$B12,H$1,H$2) -> -17.519477 | I12: =[1]!thsiFinD("ths_int_chg_ratio_index",$B12,I$1,I$2) -> -9.3173382 | J12: =[1]!thsiFinD("ths_int_chg_ratio_index",$B12,J$1,J$2) -> 27.497206 | K12: =[1]!thsiFinD("ths_int_chg_ratio_index",$B12,K$1,K$2) -> 6.2245107 | L12: =[1]!thsiFinD("ths_int_chg_ratio_index",$B12,L$1,L$2) -> -5.1061484 | ... R12: =[1]!thsiFinD("ths_int_chg_ratio_index",$B12,R$1,R$2) -> -32.695271 | AP12: 中证2000 | AQ12: 33.129667 | AT12: 综合(申万) | AU12: 30.486613
B13: 801950.SL | C13: =[1]!thsiFinD("ths_stock_short_name_stock",B13) -> 煤炭 | D13: =[1]!thsiFinD("ths_chg_ratio_index",B13,D$2)/100 -> 0.041135372 | E13: =[1]!thsiFinD("ths_int_chg_ratio_index",$B13,E$1,E$2) -> 0.73770437 | F13: =[1]!thsiFinD("ths_int_chg_ratio_index",$B13,F$1,F$2) -> -1.2241431 | G13: =[1]!thsiFinD("ths_int_chg_ratio_index",$B13,G$1,G$2) -> 1.4263339 | H13: =[1]!thsiFinD("ths_int_chg_ratio_index",$B13,H$1,H$2) -> -13.184424 | I13: =[1]!thsiFinD("ths_int_chg_ratio_index",$B13,I$1,I$2) -> 4.1832208 | J13: =[1]!thsiFinD("ths_int_chg_ratio_index",$B13,J$1,J$2) -> 1.2420506 | K13: =[1]!thsiFinD("ths_int_chg_ratio_index",$B13,K$1,K$2) -> -1.9007542 | L13: =[1]!thsiFinD("ths_int_chg_ratio_index",$B13,L$1,L$2) -> 3.4241577 | ... R13: =[1]!thsiFinD("ths_int_chg_ratio_index",$B13,R$1,R$2) -> -32.726667 | AP13: 恒生科技 | AQ13: 26.399753 | AT13: 电子(申万) | AU13: 30.165717
B14: 801230.SL | C14: =[1]!thsiFinD("ths_stock_short_name_stock",B14) -> 综合 | D14: =[1]!thsiFinD("ths_chg_ratio_index",B14,D$2)/100 -> -4.8690017e-05 | E14: =[1]!thsiFinD("ths_int_chg_ratio_index",$B14,E$1,E$2) -> -1.9178379 | F14: =[1]!thsiFinD("ths_int_chg_ratio_index",$B14,F$1,F$2) -> -1.642541 | G14: =[1]!thsiFinD("ths_int_chg_ratio_index",$B14,G$1,G$2) -> 9.6679225 | H14: =[1]!thsiFinD("ths_int_chg_ratio_index",$B14,H$1,H$2) -> -3.5205977 | I14: =[1]!thsiFinD("ths_int_chg_ratio_index",$B14,I$1,I$2) -> 0.79791497 | J14: =[1]!thsiFinD("ths_int_chg_ratio_index",$B14,J$1,J$2) -> 31.203327 | K14: =[1]!thsiFinD("ths_int_chg_ratio_index",$B14,K$1,K$2) -> 8.1950096 | L14: =[1]!thsiFinD("ths_int_chg_ratio_index",$B14,L$1,L$2) -> -1.1104702 | ... R14: =[1]!thsiFinD("ths_int_chg_ratio_index",$B14,R$1,R$2) -> -39.303493 | AP14: 恒生指数 | AQ14: 26.317065 | AT14: 机械设备(申万) | AU14: 29.10817
B15: 801140.SL | C15: =[1]!thsiFinD("ths_stock_short_name_stock",B15) -> 轻工制造 | D15: =[1]!thsiFinD("ths_chg_ratio_index",B15,D$2)/100 -> -0.0090435595 | E15: =[1]!thsiFinD("ths_int_chg_ratio_index",$B15,E$1,E$2) -> 0.14805619 | F15: =[1]!thsiFinD("ths_int_chg_ratio_index",$B15,F$1,F$2) -> 0.60983216 | G15: =[1]!thsiFinD("ths_int_chg_ratio_index",$B15,G$1,G$2) -> -13.880116 | H15: =[1]!thsiFinD("ths_int_chg_ratio_index",$B15,H$1,H$2) -> -12.608099 | I15: =[1]!thsiFinD("ths_int_chg_ratio_index",$B15,I$1,I$2) -> -4.7879631 | J15: =[1]!thsiFinD("ths_int_chg_ratio_index",$B15,J$1,J$2) -> 14.062617 | K15: =[1]!thsiFinD("ths_int_chg_ratio_index",$B15,K$1,K$2) -> 6.3516191 | L15: =[1]!thsiFinD("ths_int_chg_ratio_index",$B15,L$1,L$2) -> 3.7813229 | ... R15: =[1]!thsiFinD("ths_int_chg_ratio_index",$B15,R$1,R$2) -> -36.619742 | AP15: 科创50 | AQ15: 26.182469 | AT15: 计算机(申万) | AU15: 28.863996
B16: 801970.SL | C16: =[1]!thsiFinD("ths_stock_short_name_stock",B16) -> 环保 | D16: =[1]!thsiFinD("ths_chg_ratio_index",B16,D$2)/100 -> -0.015075081 | E16: =[1]!thsiFinD("ths_int_chg_ratio_index",$B16,E$1,E$2) -> 0.96328157 | F16: =[1]!thsiFinD("ths_int_chg_ratio_index",$B16,F$1,F$2) -> -0.055943351 | G16: =[1]!thsiFinD("ths_int_chg_ratio_index",$B16,G$1,G$2) -> 1.2529997 | H16: =[1]!thsiFinD("ths_int_chg_ratio_index",$B16,H$1,H$2) -> -3.4514321 | I16: =[1]!thsiFinD("ths_int_chg_ratio_index",$B16,I$1,I$2) -> -4.9931845 | J16: =[1]!thsiFinD("ths_int_chg_ratio_index",$B16,J$1,J$2) -> 15.507818 | K16: =[1]!thsiFinD("ths_int_chg_ratio_index",$B16,K$1,K$2) -> 4.6483234 | L16: =[1]!thsiFinD("ths_int_chg_ratio_index",$B16,L$1,L$2) -> 3.8091147 | ... R16: =[1]!thsiFinD("ths_int_chg_ratio_index",$B16,R$1,R$2) -> -45.62455 | AP16: 宁组合 | AQ16: 25.273204 | AT16: 传媒(申万) | AU16: 27.464822
B17: 801210.SL | C17: =[1]!thsiFinD("ths_stock_short_name_stock",B17) -> 社会服务 | D17: =[1]!thsiFinD("ths_chg_ratio_index",B17,D$2)/100 -> -0.0011519166 | E17: =[1]!thsiFinD("ths_int_chg_ratio_index",$B17,E$1,E$2) -> -0.1131452 | F17: =[1]!thsiFinD("ths_int_chg_ratio_index",$B17,F$1,F$2) -> -0.16430291 | G17: =[1]!thsiFinD("ths_int_chg_ratio_index",$B17,G$1,G$2) -> -17.49802 | H17: =[1]!thsiFinD("ths_int_chg_ratio_index",$B17,H$1,H$2) -> -13.736012 | I17: =[1]!thsiFinD("ths_int_chg_ratio_index",$B17,I$1,I$2) -> -7.9632939 | J17: =[1]!thsiFinD("ths_int_chg_ratio_index",$B17,J$1,J$2) -> 25.430223 | K17: =[1]!thsiFinD("ths_int_chg_ratio_index",$B17,K$1,K$2) -> -0.92744142 | L17: =[1]!thsiFinD("ths_int_chg_ratio_index",$B17,L$1,L$2) -> 2.0467433 | ... R17: =[1]!thsiFinD("ths_int_chg_ratio_index",$B17,R$1,R$2) -> -10.607492 | AP17: 创业板指 | AQ17: 25.259533 | AT17: 医药生物(申万) | AU17: 26.327172
B18: 801050.SL | C18: =[1]!thsiFinD("ths_stock_short_name_stock",B18) -> 有色金属 | D18: =[1]!thsiFinD("ths_chg_ratio_index",B18,D$2)/100 -> -0.016983724 | E18: =[1]!thsiFinD("ths_int_chg_ratio_index",$B18,E$1,E$2) -> -2.9005769 | F18: =[1]!thsiFinD("ths_int_chg_ratio_index",$B18,F$1,F$2) -> 0.72520225 | G18: =[1]!thsiFinD("ths_int_chg_ratio_index",$B18,G$1,G$2) -> -0.21513714 | H18: =[1]!thsiFinD("ths_int_chg_ratio_index",$B18,H$1,H$2) -> -3.737935 | I18: =[1]!thsiFinD("ths_int_chg_ratio_index",$B18,I$1,I$2) -> -2.0263618 | J18: =[1]!thsiFinD("ths_int_chg_ratio_index",$B18,J$1,J$2) -> 10.751915 | K18: =[1]!thsiFinD("ths_int_chg_ratio_index",$B18,K$1,K$2) -> 5.5003858 | L18: =[1]!thsiFinD("ths_int_chg_ratio_index",$B18,L$1,L$2) -> 6.156357 | ... R18: =[1]!thsiFinD("ths_int_chg_ratio_index",$B18,R$1,R$2) -> -41.036192 | AP18: 中证1000 | AQ18: 23.586591 | AT18: 国防军工(申万) | AU18: 25.485157
B19: 801040.SL | C19: =[1]!thsiFinD("ths_stock_short_name_stock",B19) -> 钢铁 | D19: =[1]!thsiFinD("ths_chg_ratio_index",B19,D$2)/100 -> -0.005250753 | E19: =[1]!thsiFinD("ths_int_chg_ratio_index",$B19,E$1,E$2) -> -1.0133752 | F19: =[1]!thsiFinD("ths_int_chg_ratio_index",$B19,F$1,F$2) -> 0.12593112 | G19: =[1]!thsiFinD("ths_int_chg_ratio_index",$B19,G$1,G$2) -> -19.008867 | H19: =[1]!thsiFinD("ths_int_chg_ratio_index",$B19,H$1,H$2) -> -18.589942 | I19: =[1]!thsiFinD("ths_int_chg_ratio_index",$B19,I$1,I$2) -> -6.0813553 | J19: =[1]!thsiFinD("ths_int_chg_ratio_index",$B19,J$1,J$2) -> 14.316308 | K19: =[1]!thsiFinD("ths_int_chg_ratio_index",$B19,K$1,K$2) -> -4.4006268 | L19: =[1]!thsiFinD("ths_int_chg_ratio_index",$B19,L$1,L$2) -> 3.8101821 | ... R19: =[1]!thsiFinD("ths_int_chg_ratio_index",$B19,R$1,R$2) -> -29.61898 | AP19: 万得全A | AQ19: 20.688866 | AT19: 基础化工(申万) | AU19: 22.531764
B20: 801120.SL | C20: =[1]!thsiFinD("ths_stock_short_name_stock",B20) -> 食品饮料 | D20: =[1]!thsiFinD("ths_chg_ratio_index",B20,D$2)/100 -> 0.010678635 | E20: =[1]!thsiFinD("ths_int_chg_ratio_index",$B20,E$1,E$2) -> 0.23777527 | F20: =[1]!thsiFinD("ths_int_chg_ratio_index",$B20,F$1,F$2) -> 0.85483624 | G20: =[1]!thsiFinD("ths_int_chg_ratio_index",$B20,G$1,G$2) -> -19.518788 | H20: =[1]!thsiFinD("ths_int_chg_ratio_index",$B20,H$1,H$2) -> -17.316102 | I20: =[1]!thsiFinD("ths_int_chg_ratio_index",$B20,I$1,I$2) -> -6.9590471 | J20: =[1]!thsiFinD("ths_int_chg_ratio_index",$B20,J$1,J$2) -> 18.261276 | K20: =[1]!thsiFinD("ths_int_chg_ratio_index",$B20,K$1,K$2) -> -6.2247641 | L20: =[1]!thsiFinD("ths_int_chg_ratio_index",$B20,L$1,L$2) -> 4.40916 | ... R20: =[1]!thsiFinD("ths_int_chg_ratio_index",$B20,R$1,R$2) -> -21.953798 | AP20: 中证500 | AQ20: 19.161121 | AT20: 汽车(申万) | AU20: 21.681344
... B24: 801720.SL | C24: =[1]!thsiFinD("ths_stock_short_name_stock",B24) -> 建筑装饰 | D24: =[1]!thsiFinD("ths_chg_ratio_index",B24,D$2)/100 -> -0.01144832 | E24: =[1]!thsiFinD("ths_int_chg_ratio_index",$B24,E$1,E$2) -> -0.55720208 | F24: =[1]!thsiFinD("ths_int_chg_ratio_index",$B24,F$1,F$2) -> 0.18851165 | G24: =[1]!thsiFinD("ths_int_chg_ratio_index",$B24,G$1,G$2) -> -4.4593361 | H24: =[1]!thsiFinD("ths_int_chg_ratio_index",$B24,H$1,H$2) -> -8.8905144 | I24: =[1]!thsiFinD("ths_int_chg_ratio_index",$B24,I$1,I$2) -> -8.5524345 | J24: =[1]!thsiFinD("ths_int_chg_ratio_index",$B24,J$1,J$2) -> 9.6399938 | K24: =[1]!thsiFinD("ths_int_chg_ratio_index",$B24,K$1,K$2) -> 2.9939768 | L24: =[1]!thsiFinD("ths_int_chg_ratio_index",$B24,L$1,L$2) -> 11.191705 | ... R24: =[1]!thsiFinD("ths_int_chg_ratio_index",$B24,R$1,R$2) -> -29.27467 | AP24: 上证50 | AQ24: 9.0824482 | AT24: 美容护理(申万) | AU24: 16.62315
B25: 801170.SL | C25: =[1]!thsiFinD("ths_stock_short_name_stock",B25) -> 交通运输 | D25: =[1]!thsiFinD("ths_chg_ratio_index",B25,D$2)/100 -> 0.014491744 | E25: =[1]!thsiFinD("ths_int_chg_ratio_index",$B25,E$1,E$2) -> 1.2664172 | F25: =[1]!thsiFinD("ths_int_chg_ratio_index",$B25,F$1,F$2) -> -2.1650438 | G25: =[1]!thsiFinD("ths_int_chg_ratio_index",$B25,G$1,G$2) -> -14.609792 | H25: =[1]!thsiFinD("ths_int_chg_ratio_index",$B25,H$1,H$2) -> -12.841643 | I25: =[1]!thsiFinD("ths_int_chg_ratio_index",$B25,I$1,I$2) -> -4.9807349 | J25: =[1]!thsiFinD("ths_int_chg_ratio_index",$B25,J$1,J$2) -> 11.290229 | K25: =[1]!thsiFinD("ths_int_chg_ratio_index",$B25,K$1,K$2) -> 3.084402 | L25: =[1]!thsiFinD("ths_int_chg_ratio_index",$B25,L$1,L$2) -> 0.66934744 | ... R25: =[1]!thsiFinD("ths_int_chg_ratio_index",$B25,R$1,R$2) -> -30.170881 | AP25: 中证红利 | AQ25: 0.32080114
B26: 801960.SL | C26: =[1]!thsiFinD("ths_stock_short_name_stock",B26) -> 石油石化 | D26: =[1]!thsiFinD("ths_chg_ratio_index",B26,D$2)/100 -> 0.024327758 | E26: =[1]!thsiFinD("ths_int_chg_ratio_index",$B26,E$1,E$2) -> 1.2634729 | F26: =[1]!thsiFinD("ths_int_chg_ratio_index",$B26,F$1,F$2) -> -3.0877958 | G26: =[1]!thsiFinD("ths_int_chg_ratio_index",$B26,G$1,G$2) -> -10.250354 | H26: =[1]!thsiFinD("ths_int_chg_ratio_index",$B26,H$1,H$2) -> -22.203159 | I26: =[1]!thsiFinD("ths_int_chg_ratio_index",$B26,I$1,I$2) -> -6.8186605 | J26: =[1]!thsiFinD("ths_int_chg_ratio_index",$B26,J$1,J$2) -> 2.0023797 | K26: =[1]!thsiFinD("ths_int_chg_ratio_index",$B26,K$1,K$2) -> 1.1730044 | L26: =[1]!thsiFinD("ths_int_chg_ratio_index",$B26,L$1,L$2) -> 10.627643 | ... R26: =[1]!thsiFinD("ths_int_chg_ratio_index",$B26,R$1,R$2) -> -25.255757
B27: 801180.SL | C27: =[1]!thsiFinD("ths_stock_short_name_stock",B27) -> 房地产 | D27: =[1]!thsiFinD("ths_chg_ratio_index",B27,D$2)/100 -> 0.008908614 | E27: =[1]!thsiFinD("ths_int_chg_ratio_index",$B27,E$1,E$2) -> -0.32133542 | F27: =[1]!thsiFinD("ths_int_chg_ratio_index",$B27,F$1,F$2) -> -0.42414249 | G27: =[1]!thsiFinD("ths_int_chg_ratio_index",$B27,G$1,G$2) -> -16.439472 | H27: =[1]!thsiFinD("ths_int_chg_ratio_index",$B27,H$1,H$2) -> -9.6563704 | I27: =[1]!thsiFinD("ths_int_chg_ratio_index",$B27,I$1,I$2) -> -14.470267 | J27: =[1]!thsiFinD("ths_int_chg_ratio_index",$B27,J$1,J$2) -> 33.049784 | K27: =[1]!thsiFinD("ths_int_chg_ratio_index",$B27,K$1,K$2) -> -1.1410119 | L27: =[1]!thsiFinD("ths_int_chg_ratio_index",$B27,L$1,L$2) -> -6.1129437 | ... R27: =[1]!thsiFinD("ths_int_chg_ratio_index",$B27,R$1,R$2) -> -28.789159
B28: 801160.SL | C28: =[1]!thsiFinD("ths_stock_short_name_stock",B28) -> 公用事业 | D28: =[1]!thsiFinD("ths_chg_ratio_index",B28,D$2)/100 -> -0.003758399 | E28: =[1]!thsiFinD("ths_int_chg_ratio_index",$B28,E$1,E$2) -> -0.10166466 | F28: =[1]!thsiFinD("ths_int_chg_ratio_index",$B28,F$1,F$2) -> -0.36439312 | G28: =[1]!thsiFinD("ths_int_chg_ratio_index",$B28,G$1,G$2) -> 1.6875894 | H28: =[1]!thsiFinD("ths_int_chg_ratio_index",$B28,H$1,H$2) -> -6.8921158 | I28: =[1]!thsiFinD("ths_int_chg_ratio_index",$B28,I$1,I$2) -> -0.13920427 | J28: =[1]!thsiFinD("ths_int_chg_ratio_index",$B28,J$1,J$2) -> 2.9515919 | K28: =[1]!thsiFinD("ths_int_chg_ratio_index",$B28,K$1,K$2) -> 3.2419486 | L28: =[1]!thsiFinD("ths_int_chg_ratio_index",$B28,L$1,L$2) -> 1.5396791 | ... R28: =[1]!thsiFinD("ths_int_chg_ratio_index",$B28,R$1,R$2) -> -29.71819
B29: 801780.SL | C29: =[1]!thsiFinD("ths_stock_short_name_stock",B29) -> 银行 | D29: =[1]!thsiFinD("ths_chg_ratio_index",B29,D$2)/100 -> 0.019009908 | E29: =[1]!thsiFinD("ths_int_chg_ratio_index",$B29,E$1,E$2) -> 1.9695069 | F29: =[1]!thsiFinD("ths_int_chg_ratio_index",$B29,F$1,F$2) -> -1.9500073 | G29: =[1]!thsiFinD("ths_int_chg_ratio_index",$B29,G$1,G$2) -> -12.274205 | H29: =[1]!thsiFinD("ths_int_chg_ratio_index",$B29,H$1,H$2) -> -9.0810661 | I29: =[1]!thsiFinD("ths_int_chg_ratio_index",$B29,I$1,I$2) -> -6.6100764 | J29: =[1]!thsiFinD("ths_int_chg_ratio_index",$B29,J$1,J$2) -> 9.3060284 | K29: =[1]!thsiFinD("ths_int_chg_ratio_index",$B29,K$1,K$2) -> 10.846098 | L29: =[1]!thsiFinD("ths_int_chg_ratio_index",$B29,L$1,L$2) -> -2.7043714 | ... R29: =[1]!thsiFinD("ths_int_chg_ratio_index",$B29,R$1,R$2) -> -14.665096
B30: 801730.SL | C30: =[1]!thsiFinD("ths_stock_short_name_stock",B30) -> 电力设备 | D30: =[1]!thsiFinD("ths_chg_ratio_index",B30,D$2)/100 -> -0.01815827 | E30: =[1]!thsiFinD("ths_int_chg_ratio_index",$B30,E$1,E$2) -> -0.78167456 | F30: =[1]!thsiFinD("ths_int_chg_ratio_index",$B30,F$1,F$2) -> 3.1019007 | G30: =[1]!thsiFinD("ths_int_chg_ratio_index",$B30,G$1,G$2) -> 7.2773916 | H30: =[1]!thsiFinD("ths_int_chg_ratio_index",$B30,H$1,H$2) -> 0.46489564 | I30: =[1]!thsiFinD("ths_int_chg_ratio_index",$B30,I$1,I$2) -> -9.292038 | J30: =[1]!thsiFinD("ths_int_chg_ratio_index",$B30,J$1,J$2) -> 22.960788 | K30: =[1]!thsiFinD("ths_int_chg_ratio_index",$B30,K$1,K$2) -> 0.029165127 | L30: =[1]!thsiFinD("ths_int_chg_ratio_index",$B30,L$1,L$2) -> -0.35996042 | ... R30: =[1]!thsiFinD("ths_int_chg_ratio_index",$B30,R$1,R$2) -> -34.945743
B31: 801030.SL | C31: =[1]!thsiFinD("ths_stock_short_name_stock",B31) -> 基础化工 | D31: =[1]!thsiFinD("ths_chg_ratio_index",B31,D$2)/100 -> -0.010557857 | E31: =[1]!thsiFinD("ths_int_chg_ratio_index",$B31,E$1,E$2) -> 2.212225 | F31: =[1]!thsiFinD("ths_int_chg_ratio_index",$B31,F$1,F$2) -> -0.37230129 | G31: =[1]!thsiFinD("ths_int_chg_ratio_index",$B31,G$1,G$2) -> 9.0010269 | H31: =[1]!thsiFinD("ths_int_chg_ratio_index",$B31,H$1,H$2) -> 1.9589764 | I31: =[1]!thsiFinD("ths_int_chg_ratio_index",$B31,I$1,I$2) -> -3.9693459 | J31: =[1]!thsiFinD("ths_int_chg_ratio_index",$B31,J$1,J$2) -> 11.921204 | K31: =[1]!thsiFinD("ths_int_chg_ratio_index",$B31,K$1,K$2) -> 3.3150419 | L31: =[1]!thsiFinD("ths_int_chg_ratio_index",$B31,L$1,L$2) -> 2.8743434 | ... R31: =[1]!thsiFinD("ths_int_chg_ratio_index",$B31,R$1,R$2) -> -31.723867 | V31: =8.56/4 -> 2.14
B32: 801080.SL | C32: =[1]!thsiFinD("ths_stock_short_name_stock",B32) -> 电子 | D32: =[1]!thsiFinD("ths_chg_ratio_index",B32,D$2)/100 -> -0.014462885 | E32: =[1]!thsiFinD("ths_int_chg_ratio_index",$B32,E$1,E$2) -> -0.78019077 | F32: =[1]!thsiFinD("ths_int_chg_ratio_index",$B32,F$1,F$2) -> 5.9901489 | G32: =[1]!thsiFinD("ths_int_chg_ratio_index",$B32,G$1,G$2) -> 86.287245 | H32: =[1]!thsiFinD("ths_int_chg_ratio_index",$B32,H$1,H$2) -> 90.917904 | I32: =[1]!thsiFinD("ths_int_chg_ratio_index",$B32,I$1,I$2) -> 3.9176024 | J32: =[1]!thsiFinD("ths_int_chg_ratio_index",$B32,J$1,J$2) -> 14.100777 | K32: =[1]!thsiFinD("ths_int_chg_ratio_index",$B32,K$1,K$2) -> 0.68955274 | L32: =[1]!thsiFinD("ths_int_chg_ratio_index",$B32,L$1,L$2) -> 15.502051 | ... R32: =[1]!thsiFinD("ths_int_chg_ratio_index",$B32,R$1,R$2) -> -42.367716
B33: 801710.SL | C33: =[1]!thsiFinD("ths_stock_short_name_stock",B33) -> 建筑材料 | D33: =[1]!thsiFinD("ths_chg_ratio_index",B33,D$2)/100 -> -0.057469694 | E33: =[1]!thsiFinD("ths_int_chg_ratio_index",$B33,E$1,E$2) -> 0.51447794 | F33: =[1]!thsiFinD("ths_int_chg_ratio_index",$B33,F$1,F$2) -> -2.7776297 | G33: =[1]!thsiFinD("ths_int_chg_ratio_index",$B33,G$1,G$2) -> 46.264207 | H33: =[1]!thsiFinD("ths_int_chg_ratio_index",$B33,H$1,H$2) -> 35.199846 | I33: =[1]!thsiFinD("ths_int_chg_ratio_index",$B33,I$1,I$2) -> -14.468494 | J33: =[1]!thsiFinD("ths_int_chg_ratio_index",$B33,J$1,J$2) -> 12.164652 | K33: =[1]!thsiFinD("ths_int_chg_ratio_index",$B33,K$1,K$2) -> -3.0632362 | L33: =[1]!thsiFinD("ths_int_chg_ratio_index",$B33,L$1,L$2) -> 1.918885 | ... R33: =[1]!thsiFinD("ths_int_chg_ratio_index",$B33,R$1,R$2) -> -30.299249
B34: 801770.SL | C34: =[1]!thsiFinD("ths_stock_short_name_stock",B34) -> 通信 | D34: =[1]!thsiFinD("ths_chg_ratio_index",B34,D$2)/100 -> -0.030501922 | E34: =[1]!thsiFinD("ths_int_chg_ratio_index",$B34,E$1,E$2) -> -1.5477581 | F34: =[1]!thsiFinD("ths_int_chg_ratio_index",$B34,F$1,F$2) -> 2.0480452 | G34: =[1]!thsiFinD("ths_int_chg_ratio_index",$B34,G$1,G$2) -> 73.594752 | H34: =[1]!thsiFinD("ths_int_chg_ratio_index",$B34,H$1,H$2) -> 63.838343 | I34: =[1]!thsiFinD("ths_int_chg_ratio_index",$B34,I$1,I$2) -> -6.5813986 | J34: =[1]!thsiFinD("ths_int_chg_ratio_index",$B34,J$1,J$2) -> 14.219699 | K34: =[1]!thsiFinD("ths_int_chg_ratio_index",$B34,K$1,K$2) -> 10.688232 | L34: =[1]!thsiFinD("ths_int_chg_ratio_index",$B34,L$1,L$2) -> 29.510194 | ... R34: =[1]!thsiFinD("ths_int_chg_ratio_index",$B34,R$1,R$2) -> -31.316647
B37: 399371.SZ | C37: 399370.SZ
B38: 932000.csi | C38: 中证2000 | D38: =[1]!thsiFinD("ths_chg_ratio_index",B38,D$2)/100 -> -0.021262574 | E38: =[1]!thsiFinD("ths_int_chg_ratio_index",$B38,E$1,E$2) -> 0.27057505 | F38: =[1]!thsiFinD("ths_int_chg_ratio_index",$B38,F$1,F$2) -> 1.3809605 | G38: =[1]!thsiFinD("ths_int_chg_ratio_index",$B38,G$1,G$2) -> 9.0956418 | H38: =[1]!thsiFinD("ths_int_chg_ratio_index",$B38,H$1,H$2) -> 7.7838129 | I38: =[1]!thsiFinD("ths_int_chg_ratio_index",$B38,I$1,I$2) -> 1.9242224 | J38: =[1]!thsiFinD("ths_int_chg_ratio_index",$B38,J$1,J$2) -> 17.672598 | K38: =[1]!thsiFinD("ths_int_chg_ratio_index",$B38,K$1,K$2) -> 7.6219668 | L38: =[1]!thsiFinD("ths_int_chg_ratio_index",$B38,L$1,L$2) -> 9.4060079 | ... R38: =[1]!thsiFinD("ths_int_chg_ratio_index",$B38,R$1,R$2) -> -33.342492
B39: 000903.sh | C39: 中证100 | D39: =[1]!thsiFinD("ths_chg_ratio_index",B39,D$2)/100 -> -0.00088843766 | E39: =[1]!thsiFinD("ths_int_chg_ratio_index",$B39,E$1,E$2) -> -1.0073418 | F39: =[1]!thsiFinD("ths_int_chg_ratio_index",$B39,F$1,F$2) -> 3.2421856 | G39: =[1]!thsiFinD("ths_int_chg_ratio_index",$B39,G$1,G$2) -> 8.4670562 | H39: =[1]!thsiFinD("ths_int_chg_ratio_index",$B39,H$1,H$2) -> 12.383787 | I39: =[1]!thsiFinD("ths_int_chg_ratio_index",$B39,I$1,I$2) -> -7.5072482 | J39: =[1]!thsiFinD("ths_int_chg_ratio_index",$B39,J$1,J$2) -> 16.661624 | K39: =[1]!thsiFinD("ths_int_chg_ratio_index",$B39,K$1,K$2) -> 0.025245887 | L39: =[1]!thsiFinD("ths_int_chg_ratio_index",$B39,L$1,L$2) -> 4.8756729 | ... R39: =[1]!thsiFinD("ths_int_chg_ratio_index",$B39,R$1,R$2) -> -21.939855
B40: 700050.TI | C40: wind微盘 | D40: =[1]!thsiFinD("ths_chg_ratio_index",B40,D$2)/100 -> -0.015326415 | E40: =[1]!thsiFinD("ths_int_chg_ratio_index",$B40,E$1,E$2) -> 3.7809473 | F40: =[1]!thsiFinD("ths_int_chg_ratio_index",$B40,F$1,F$2) -> -1.1671943 | G40: =[1]!thsiFinD("ths_int_chg_ratio_index",$B40,G$1,G$2) -> -15.949822 | H40: =[1]!thsiFinD("ths_int_chg_ratio_index",$B40,H$1,H$2) -> -16.16222 | I40: =[1]!thsiFinD("ths_int_chg_ratio_index",$B40,I$1,I$2) -> 39.608564 | J40: =[1]!thsiFinD("ths_int_chg_ratio_index",$B40,J$1,J$2) -> 35.14515 | K40: =[1]!thsiFinD("ths_int_chg_ratio_index",$B40,K$1,K$2) -> 30.982631 | L40: =[1]!thsiFinD("ths_int_chg_ratio_index",$B40,L$1,L$2) -> 5.1493007 | ... R40: =[1]!thsiFinD("ths_int_chg_ratio_index",$B40,R$1,R$2) -> -48.227765
C41: 主要指数 | D41: 昨日 | E41: =E3 -> 前周 | F41: 近一周 | G41: =G3 -> 2026YTD | H41: =H3 -> 2026Q2 | I41: =I3 -> Q4 | J41: =J3 -> Q3 | K41: =K3 -> Q2 | L41: =L3 -> Q1 | M41: =M3 -> 2023年 | N41: =N3 -> 2022年 | O41: 2021年 | P41: 2020年 | Q41: 2019年 | R41: 2018年
B42: 899050.BJ | C42: 北证50 | D42: =[1]!thsiFinD("ths_chg_ratio_index",B42,D$2)/100 -> -0.032499205 | E42: =[1]!thsiFinD("ths_int_chg_ratio_index",$B42,E$1,E$2) -> 1.2692039 | F42: =[1]!thsiFinD("ths_int_chg_ratio_index",$B42,F$1,F$2) -> -1.2394244 | G42: =[1]!thsiFinD("ths_int_chg_ratio_index",$B42,G$1,G$2) -> -13.137083 | H42: =[1]!thsiFinD("ths_int_chg_ratio_index",$B42,H$1,H$2) -> 0.23318309 | I42: =[1]!thsiFinD("ths_int_chg_ratio_index",$B42,I$1,I$2) -> 33.463574 | J42: =[1]!thsiFinD("ths_int_chg_ratio_index",$B42,J$1,J$2) -> 24.238243 | K42: =[1]!thsiFinD("ths_int_chg_ratio_index",$B42,K$1,K$2) -> 13.849234 | L42: =[1]!thsiFinD("ths_int_chg_ratio_index",$B42,L$1,L$2) -> 1.7626088 | ... R42: =[1]!thsiFinD("ths_int_chg_ratio_index",$B42,R$1,R$2) -> 0
A43: 1 | B43: 000016.SH | C43: =[1]!thsiFinD("ths_stock_short_name_stock",B43) -> 上证50 | D43: =[1]!thsiFinD("ths_chg_ratio_index",B43,D$2)/100 -> 0.0091035548 | E43: =[1]!thsiFinD("ths_int_chg_ratio_index",$B43,E$1,E$2) -> -0.065533129 | F43: =[1]!thsiFinD("ths_int_chg_ratio_index",$B43,F$1,F$2) -> 2.8365942 | G43: =[1]!thsiFinD("ths_int_chg_ratio_index",$B43,G$1,G$2) -> -1.3765117 | H43: =[1]!thsiFinD("ths_int_chg_ratio_index",$B43,H$1,H$2) -> 5.7774198 | I43: =[1]!thsiFinD("ths_int_chg_ratio_index",$B43,I$1,I$2) -> -7.2160477 | J43: =[1]!thsiFinD("ths_int_chg_ratio_index",$B43,J$1,J$2) -> 15.054225 | K43: =[1]!thsiFinD("ths_int_chg_ratio_index",$B43,K$1,K$2) -> 1.7388509 | L43: =[1]!thsiFinD("ths_int_chg_ratio_index",$B43,L$1,L$2) -> 1.0120981 | ... R43: =[1]!thsiFinD("ths_int_chg_ratio_index",$B43,R$1,R$2) -> -19.833952
A44: 2 | B44: 000905.SH | C44: =[1]!thsiFinD("ths_stock_short_name_stock",B44) -> 中证500 | D44: =[1]!thsiFinD("ths_chg_ratio_index",B44,D$2)/100 -> -0.010763178 | E44: =[1]!thsiFinD("ths_int_chg_ratio_index",$B44,E$1,E$2) -> 0.17874137 | F44: =[1]!thsiFinD("ths_int_chg_ratio_index",$B44,F$1,F$2) -> 3.766429 | G44: =[1]!thsiFinD("ths_int_chg_ratio_index",$B44,G$1,G$2) -> 20.973666 | H44: =[1]!thsiFinD("ths_int_chg_ratio_index",$B44,H$1,H$2) -> 18.563635 | I44: =[1]!thsiFinD("ths_int_chg_ratio_index",$B44,I$1,I$2) -> -4.5958792 | J44: =[1]!thsiFinD("ths_int_chg_ratio_index",$B44,J$1,J$2) -> 16.194025 | K44: =[1]!thsiFinD("ths_int_chg_ratio_index",$B44,K$1,K$2) -> 0.9835736 | L44: =[1]!thsiFinD("ths_int_chg_ratio_index",$B44,L$1,L$2) -> 8.10562 | ... R44: =[1]!thsiFinD("ths_int_chg_ratio_index",$B44,R$1,R$2) -> -33.320178
A45: 3 | B45: 000300.SH | C45: =[1]!thsiFinD("ths_stock_short_name_stock",B45) -> 沪深300 | D45: =[1]!thsiFinD("ths_chg_ratio_index",B45,D$2)/100 -> -3.6285357e-05 | E45: =[1]!thsiFinD("ths_int_chg_ratio_index",$B45,E$1,E$2) -> -0.44950231 | F45: =[1]!thsiFinD("ths_int_chg_ratio_index",$B45,F$1,F$2) -> 2.2844549 | G45: =[1]!thsiFinD("ths_int_chg_ratio_index",$B45,G$1,G$2) -> 7.54855 | H45: =[1]!thsiFinD("ths_int_chg_ratio_index",$B45,H$1,H$2) -> 11.896127 | I45: =[1]!thsiFinD("ths_int_chg_ratio_index",$B45,I$1,I$2) -> -7.0038242 | J45: =[1]!thsiFinD("ths_int_chg_ratio_index",$B45,J$1,J$2) -> 16.067378 | K45: =[1]!thsiFinD("ths_int_chg_ratio_index",$B45,K$1,K$2) -> 1.2546865 | L45: =[1]!thsiFinD("ths_int_chg_ratio_index",$B45,L$1,L$2) -> 4.6309106 | ... R45: =[1]!thsiFinD("ths_int_chg_ratio_index",$B45,R$1,R$2) -> -25.3098
...

Sheet 估值
A1: =TODAY()-3 -> 46207 | B1: =DATE(YEAR(A1)-10,MONTH(A1),DAY(A1)) -> 42555 | C1: =A1-7 -> 46200
C2: 主要指数 | D2: PE(TTM) | E2: PE历史分位 | F2: PB（LF） | G2: PB历史分位 | H2: PE本周变化 | I2: PB本周变化
B3: 899050.BJ | C3: =[1]!thsiFinD("ths_stock_short_name_stock",B3) -> 北证50 | D3: =[1]!thsiFinD("ths_pe_ttm_sr_index",$B3,$A$1,100,100) -> 51.3101 | E3: =[1]!thsiFinD("ths_pettm_quantile_index",$B3,$A$1,$B$1,$A$1,100,100)/100 -> 0.55782313 | F3: =[1]!thsiFinD("ths_pb_latest_index",$B3,$A$1,100) -> 4.4872759 | G3: =[1]!thsiFinD("ths_pb_quantile_sr_index",$B3,$A$1,$B$1,$A$1,108,100)/100 -> 0.65544332 | H3: =D3/J3-1 -> 0.017787335 | I3: =F3/K3-1 -> 0.018274041 | J3: =[1]!thsiFinD("ths_pe_ttm_sr_index",$B3,$C$1,100,100) -> 50.41338 | K3: =[1]!thsiFinD("ths_pb_latest_index",$B3,$C$1,100) -> 4.4067468
B4: 000016.SH | C4: =[1]!thsiFinD("ths_stock_short_name_stock",B4) -> 上证50 | D4: =[1]!thsiFinD("ths_pe_ttm_sr_index",$B4,$A$1,100,100) -> 11.115231 | E4: =[1]!thsiFinD("ths_pettm_quantile_index",$B4,$A$1,$B$1,$A$1,100,100)/100 -> 0.70717366 | F4: =[1]!thsiFinD("ths_pb_latest_index",$B4,$A$1,100) -> 1.1930756 | G4: =[1]!thsiFinD("ths_pb_quantile_sr_index",$B4,$A$1,$B$1,$A$1,108,100)/100 -> 0.32020892 | H4: =D4/J4-1 -> 0.0027257843 | I4: =F4/K4-1 -> 0.0030536108 | J4: =[1]!thsiFinD("ths_pe_ttm_sr_index",$B4,$C$1,100,100) -> 11.085015 | K4: =[1]!thsiFinD("ths_pb_latest_index",$B4,$C$1,100) -> 1.1894435
B5: 000905.SH | C5: =[1]!thsiFinD("ths_stock_short_name_stock",B5) -> 中证500 | D5: =[1]!thsiFinD("ths_pe_ttm_sr_index",$B5,$A$1,100,100) -> 40.915062 | E5: =[1]!thsiFinD("ths_pettm_quantile_index",$B5,$A$1,$B$1,$A$1,100,100)/100 -> 0.93489393 | F5: =[1]!thsiFinD("ths_pb_latest_index",$B5,$A$1,100) -> 2.7331615 | G5: =[1]!thsiFinD("ths_pb_quantile_sr_index",$B5,$A$1,$B$1,$A$1,108,100)/100 -> 0.89678179 | H5: =D5/J5-1 -> 0.0037534166 | I5: =F5/K5-1 -> 0.0047478795 | J5: =[1]!thsiFinD("ths_pe_ttm_sr_index",$B5,$C$1,100,100) -> 40.762065 | K5: =[1]!thsiFinD("ths_pb_latest_index",$B5,$C$1,100) -> 2.7202461
B6: 000300.SH | C6: =[1]!thsiFinD("ths_stock_short_name_stock",B6) -> 沪深300 | D6: =[1]!thsiFinD("ths_pe_ttm_sr_index",$B6,$A$1,100,100) -> 14.326763 | E6: =[1]!thsiFinD("ths_pettm_quantile_index",$B6,$A$1,$B$1,$A$1,100,100)/100 -> 0.85446527 | F6: =[1]!thsiFinD("ths_pb_latest_index",$B6,$A$1,100) -> 1.4455942 | G6: =[1]!thsiFinD("ths_pb_quantile_sr_index",$B6,$A$1,$B$1,$A$1,108,100)/100 -> 0.48684727 | H6: =D6/J6-1 -> -0.001294568 | I6: =F6/K6-1 -> -0.00017713933 | J6: =[1]!thsiFinD("ths_pe_ttm_sr_index",$B6,$C$1,100,100) -> 14.345334 | K6: =[1]!thsiFinD("ths_pb_latest_index",$B6,$C$1,100) -> 1.4458503
B7: 000852.SH | C7: =[1]!thsiFinD("ths_stock_short_name_stock",B7) -> 中证1000 | D7: =[1]!thsiFinD("ths_pe_ttm_sr_index",$B7,$A$1,100,100) -> 51.789884 | E7: =[1]!thsiFinD("ths_pettm_quantile_index",$B7,$A$1,$B$1,$A$1,100,100)/100 -> 0.79611307 | F7: =[1]!thsiFinD("ths_pb_latest_index",$B7,$A$1,100) -> 2.7435348 | G7: =[1]!thsiFinD("ths_pb_quantile_sr_index",$B7,$A$1,$B$1,$A$1,108,100)/100 -> 0.71618452 | H7: =D7/J7-1 -> 0.004817567 | I7: =F7/K7-1 -> 0.0052505948 | J7: =[1]!thsiFinD("ths_pe_ttm_sr_index",$B7,$C$1,100,100) -> 51.541579 | K7: =[1]!thsiFinD("ths_pb_latest_index",$B7,$C$1,100) -> 2.7292049
B8: 000688.sh | C8: =[1]!thsiFinD("ths_stock_short_name_stock",B8) -> 科创50 | D8: =[1]!thsiFinD("ths_pe_ttm_sr_index",$B8,$A$1,100,100) -> 231.65265 | E8: =[1]!thsiFinD("ths_pettm_quantile_index",$B8,$A$1,$B$1,$A$1,100,100)/100 -> 0.99479844 | F8: =[1]!thsiFinD("ths_pb_latest_index",$B8,$A$1,100) -> 9.1121593 | G8: =[1]!thsiFinD("ths_pb_quantile_sr_index",$B8,$A$1,$B$1,$A$1,108,100)/100 -> 0.99533022 | H8: =D8/J8-1 -> -0.031666621 | I8: =F8/K8-1 -> -0.034969689 | J8: =[1]!thsiFinD("ths_pe_ttm_sr_index",$B8,$C$1,100,100) -> 239.22819 | K8: =[1]!thsiFinD("ths_pb_latest_index",$B8,$C$1,100) -> 9.4423556
B9: 000001.SH | C9: =[1]!thsiFinD("ths_stock_short_name_stock",B9) -> 上证指数 | D9: =[1]!thsiFinD("ths_pe_ttm_sr_index",$B9,$A$1,100,100) -> 16.949311 | E9: =[1]!thsiFinD("ths_pettm_quantile_index",$B9,$A$1,$B$1,$A$1,100,100)/100 -> 0.95533241 | F9: =[1]!thsiFinD("ths_pb_latest_index",$B9,$A$1,100) -> 1.4845601 | G9: =[1]!thsiFinD("ths_pb_quantile_sr_index",$B9,$A$1,$B$1,$A$1,108,100)/100 -> 0.60944206 | H9: =D9/J9-1 -> 0.0033212908 | I9: =F9/K9-1 -> 0.0039388244 | J9: =[1]!thsiFinD("ths_pe_ttm_sr_index",$B9,$C$1,100,100) -> 16.893203 | K9: =[1]!thsiFinD("ths_pb_latest_index",$B9,$C$1,100) -> 1.4787356
B10: 700082.TI | C10: =[1]!thsiFinD("ths_stock_short_name_stock",B10) -> 同花顺全A(沪深京等权) | D10: =[1]!thsiFinD("ths_pe_ttm_sr_index",$B10,$A$1,100,100) -> 23.744745 | E10: =[1]!thsiFinD("ths_pettm_quantile_index",$B10,$A$1,$B$1,$A$1,100,100)/100 -> 0.95691995 | F10: =[1]!thsiFinD("ths_pb_latest_index",$B10,$A$1,100) -> 1.8998265 | G10: =[1]!thsiFinD("ths_pb_quantile_sr_index",$B10,$A$1,$B$1,$A$1,108,100)/100 -> 0.64655508 | H10: =D10/J10-1 -> 0.0030319428 | I10: =F10/K10-1 -> 0.0041934612 | J10: =[1]!thsiFinD("ths_pe_ttm_sr_index",$B10,$C$1,100,100) -> 23.67297 | K10: =[1]!thsiFinD("ths_pb_latest_index",$B10,$C$1,100) -> 1.8918929
B11: 399006.SZ | C11: =[1]!thsiFinD("ths_stock_short_name_stock",B11) -> 创业板指 | D11: =[1]!thsiFinD("ths_pe_ttm_sr_index",$B11,$A$1,100,100) -> 51.202095 | E11: =[1]!thsiFinD("ths_pettm_quantile_index",$B11,$A$1,$B$1,$A$1,100,100)/100 -> 0.70174051 | F11: =[1]!thsiFinD("ths_pb_latest_index",$B11,$A$1,100) -> 7.008661 | G11: =[1]!thsiFinD("ths_pb_quantile_sr_index",$B11,$A$1,$B$1,$A$1,108,100)/100 -> 0.83760347 | H11: =D11/J11-1 -> -0.034542223 | I11: =F11/K11-1 -> -0.034810584 | J11: =[1]!thsiFinD("ths_pe_ttm_sr_index",$B11,$C$1,100,100) -> 53.034008 | K11: =[1]!thsiFinD("ths_pb_latest_index",$B11,$C$1,100) -> 7.2614358

Sheet 成交额
A1: =TODAY()-3 -> 46207
A2: =DATE(YEAR(A1),MONTH(A1),DAY(A1)-7) -> 46200 | B2: 两市成交额
A3: =[1]!HX_AutoDate(1,A2,A1,-1,-1,0,0,1,0,0,"SSE",5,0) -> 日期 | B3: 700001.TI
A4: 46206 | B4: =IF(A4="","",[1]!thsiFinD("ths_trans_amt_index",B$3,A4)/100000000) -> 31877.371
A5: 46205 | B5: =IF(A5="","",[1]!thsiFinD("ths_trans_amt_index",B$3,A5)/100000000) -> 34380.131
A6: 46204 | B6: =IF(A6="","",[1]!thsiFinD("ths_trans_amt_index",B$3,A6)/100000000) -> 36647.171
A7: 46203 | B7: =IF(A7="","",[1]!thsiFinD("ths_trans_amt_index",B$3,A7)/100000000) -> 32793.969
A8: 46202 | B8: =IF(A8="","",[1]!thsiFinD("ths_trans_amt_index",B$3,A8)/100000000) -> 35258.602
B9: =SUM(B4:B8)/COUNT(A4:A8) -> 34191.449

Sheet 融资融券
A1: 单位 | B1: 亿元 | C1: 亿元
A2: 指标名称 | B2: 深交所:融资融券余额 | C2: 上交所:融资融券余额
A3: 频率 | B3: 日 | C3: 日
A4: 指标ID | B4: S004273908 | C4: S004273899 | D4: 两市两融余额
A5: 46129 | B5: =[1]!thsMEDB(B4:C4,"2010/03/31","2026/04/17","Format(isAsc=N,Display=R,FillBlank=B,DecimalPoint=2,LineBlank=N)") -> 13083.069 | C5: 13543.627 | D5: =SUM(B5:C5) -> 26626.696
A6: 46128 | B6: 13066.744 | C6: 13538.188 | D6: =SUM(B6:C6) -> 26604.932
A7: 46127 | B7: 13006.837 | C7: 13488.531 | D7: =SUM(B7:C7) -> 26495.368
A8: 46126 | B8: 12952.996 | C8: 13441.997 | D8: =SUM(B8:C8) -> 26394.992
A9: 46125 | B9: 12864.371 | C9: 13361.108 | D9: =SUM(B9:C9) -> 26225.478
A10: 46122 | B10: 12782.232 | C10: 13280.753 | D10: =SUM(B10:C10) -> 26062.985
A11: 46121 | B11: 12754.011 | C11: 13251.761 | D11: =SUM(B11:C11) -> 26005.771
A12: 46120 | B12: 12709.265 | C12: 13224.065 | D12: =SUM(B12:C12) -> 25933.33
A13: 46119 | B13: 12611.587 | C13: 13157.378 | D13: =SUM(B13:C13) -> 25768.965
A14: 46115 | B14: 12578.565 | C14: 13149.437 | D14: =SUM(B14:C14) -> 25728.001
A15: 46114 | B15: 12670.343 | C15: 13234.849 | D15: =SUM(B15:C15) -> 25905.193
A16: 46113 | B16: 12728.015 | C16: 13288.151 | D16: =SUM(B16:C16) -> 26016.167
A17: 46112 | B17: 12717.999 | C17: 13287.182 | D17: =SUM(B17:C17) -> 26005.181
... A3897: 40275 | B3897: 0.11525003 | C3897: 0.25125244 | D3897: =SUM(B3897:C3897) -> 0.36650247
A3898: 40274 | B3898: 0.04436147 | C3898: 0.1010151
A3899: 40270 | B3899: 0.0643823 | C3899: 0.0677471
A3900: 40269 | B3900: 0.06886631 | C3900: 0.06859439
A3901: 40268 | B3901: 0.00741691 | C3901: 0.05848955

Sheet 金牛组合持仓
H1: 46202 | J1: =J2+1 -> 46176 | K1: =K2+1 -> 46115 | L1: =L2+1 -> 46021 | M1: =M2+1 -> 45841 | N1: 46027 | O1: 45659 | P1: =P2+1 -> #NAME? | Q1: =Q2+1 -> 45778 | R1: =R2+1 -> 45808 | S1: 45293 | AA1: 金牛千里马 | AB1: 930950.CSI
D2: =D3 -> 46206 | H2: =H3-7 -> 46199 | J2: =EDATE(J3,-1)-1 -> 46175 | K2: =EDATE(K3,-3)-1 -> 46114 | L2: =EDATE(L3,-6)-5 -> 46020 | M2: =EDATE(M3,-12)-1 -> 45840 | N2: 46022 | O2: 45657 | P2: =[2]!TDays("2025-03-31","2025-05-31","Period=M","Direction=H","cols=3;rows=1") -> #NAME? | Q2: 45777 | R2: 45807 | S2: 45289 | T2: 44927 | U2: 44562 | V2: 44197 | W2: 43831 | X2: =DATE(YEAR(D3)-3,MONTH(H3),DAY(H3)) -> 45110
D3: 46206 | H3: =D3 -> 46206 | I3: =D3 -> 46206 | J3: =D3 -> 46206 | K3: =H3 -> 46206 | L3: =I3 -> 46206 | M3: =J3 -> 46206 | N3: =D3 -> 46206 | O3: 46022 | P3: =[2]!TDays("2025-04-30","2025-06-30","Period=M","Direction=H","cols=3;rows=1") -> #NAME? | Q3: 45807 | R3: 45838 | S3: 45657 | T3: 45289 | U3: 44926 | V3: 44561 | W3: 44196 | X3: =D3 -> 46206
A4: 代码 | B4: 基金简称 | C4: 标签1 | D4: 基金经理 | E4: 成立日期 | F4: 任职日期 | G4: 基金经理规模（亿） | H4: 近一周 | I4: 调仓以来表现 | J4: 近一月 | K4: 近三月 | L4: 近六月 | M4: 近一年 | N4: 2026YTD | O4: 2025 | S4: 2024 | T4: 2023年 | U4: 2022年 | V4: 2021年 | W4: 2020年 | X4: 近三年最大回撤 | Y4: 成立以来 | Z4: 持仓权重
A5: 016276.OF | B5: =[1]!thsiFinD("ths_fund_official_short_name_fund",A5) -> 招商中证800指数增强A | C5: 800增强 | D5: =[1]!thsiFinD("ths_fund_manager_current_fund",A5) -> 王平 | E5: =[1]!thsiFinD("ths_fund_establishment_date_fund",A5) -> 2022-08-23 | F5: =[1]!thsiFinD("ths_service_sd_fund",A5,"100",1,"101") -> 2022-08-23 | G5: =[1]!thsiFinD("ths_fund_scale_fund",A5,1)/100000000 -> 2.1947306 | H5: =IF($F5-H$1>0,"",[1]!thsiFinD("ths_adjustment_nvg_ratio_fund",$A5,H$1,H$3,"")/100) -> -0.0014817808 | I5: =IF($F5-#REF!>0,"",[1]!thsiFinD("ths_adjustment_nvg_ratio_fund",$A5,#REF!,I$3,"")/100) -> #REF! | J5: =IF($F5-J$2>0,"",[1]!thsiFinD("ths_adjustment_nvg_ratio_fund",$A5,J$2,J$3,"")/100) -> 0.030587417 | K5: =IF($F5-K$2>0,"",[1]!thsiFinD("ths_adjustment_nvg_ratio_fund",$A5,K$2,K$3,"")/100) -> 0.11524863 | N5: =IF($F5-N$1>0,"",[1]!thsiFinD("ths_adjustment_nvg_ratio_fund",$A5,N$1,N$3,"")/100) -> 0.11853026 | O5: =IF($F5-O$2>0,"",[1]!thsiFinD("ths_adjustment_nvg_ratio_fund",$A5,O$2,O$3,"")/100) -> 0.30106999 | S5: =IF($F5-S$1>0,"",[1]!thsiFinD("ths_adjustment_nvg_ratio_fund",$A5,S$1,S$3,"")/100) -> 0.13093493 | T5: =IF($F5-T$2>0,"",[1]!thsiFinD("ths_adjustment_nvg_ratio_fund",$A5,T$2,T$3,"")/100) -> -0.060699153 | U5: =IF($F5-U$2>0,"",[1]!thsiFinD("ths_adjustment_nvg_ratio_fund",$A5,U$2,U$3,"")/100) | V5: =IF($F5-V$2>0,"",[1]!thsiFinD("ths_adjustment_nvg_ratio_fund",$A5,V$2,V$3,"")/100) | W5: =IF($F5-W$2>0,"",[1]!thsiFinD("ths_adjustment_nvg_ratio_fund",$A5,W$2,W$3,"")/100) | X5: =IF(X$2-F5>0,[1]!thsiFinD("ths_max_retrace_rate_fund",A5,$X$2,$X$3)/100,[1]!thsiFinD("ths_max_retrace_rate_fund",A5,$F5,$X$3)/100) -> 0.21445545 | Z5: 0.06
A6: 007126.OF | B6: =[1]!thsiFinD("ths_fund_official_short_name_fund",A6) -> 博道远航混合A | C6: 偏股增强 | D6: =[1]!thsiFinD("ths_fund_manager_current_fund",A6) -> 杨梦 | E6: =[1]!thsiFinD("ths_fund_establishment_date_fund",A6) -> 2019-04-30 | F6: =[1]!thsiFinD("ths_service_sd_fund",A6,"100",1,"101") -> 2019-04-30 | G6: =[1]!thsiFinD("ths_fund_scale_fund",A6,1)/100000000 -> 25.009107 | H6: =IF($F6-H$1>0,"",[1]!thsiFinD("ths_adjustment_nvg_ratio_fund",$A6,H$1,H$3,"")/100) -> -0.0090293454 | I6: =IF($F6-#REF!>0,"",[1]!thsiFinD("ths_adjustment_nvg_ratio_fund",$A6,#REF!,I$3,"")/100) -> #REF! | J6: =IF($F6-J$2>0,"",[1]!thsiFinD("ths_adjustment_nvg_ratio_fund",$A6,J$2,J$3,"")/100) -> 0.060877166 | K6: =IF($F6-K$2>0,"",[1]!thsiFinD("ths_adjustment_nvg_ratio_fund",$A6,K$2,K$3,"")/100) -> 0.18132371 | N6: =IF($F6-N$1>0,"",[1]!thsiFinD("ths_adjustment_nvg_ratio_fund",$A6,N$1,N$3,"")/100) -> 0.17446494 | O6: =IF($F6-O$2>0,"",[1]!thsiFinD("ths_adjustment_nvg_ratio_fund",$A6,O$2,O$3,"")/100) -> 0.30529757 | S6: =IF($F6-S$1>0,"",[1]!thsiFinD("ths_adjustment_nvg_ratio_fund",$A6,S$1,S$3,"")/100) -> 0.12229181 | T6: =IF($F6-T$2>0,"",[1]!thsiFinD("ths_adjustment_nvg_ratio_fund",$A6,T$2,T$3,"")/100) -> -0.038721223 | U6: =IF($F6-U$2>0,"",[1]!thsiFinD("ths_adjustment_nvg_ratio_fund",$A6,U$2,U$3,"")/100) -> -0.21914502 | X6: =IF(X$2-F6>0,[1]!thsiFinD("ths_max_retrace_rate_fund",A6,$X$2,$X$3)/100,[1]!thsiFinD("ths_max_retrace_rate_fund",A6,$F6,$X$3)/100) -> 0.23711659 | Z6: 0.06
A7: 015718.OF | B7: =[1]!thsiFinD("ths_fund_official_short_name_fund",A7) -> 财通资管均衡臻选混合A | C7: 均衡-偏价值 | D7: =[1]!thsiFinD("ths_fund_manager_current_fund",A7) -> 王浩冰 | E7: =[1]!thsiFinD("ths_fund_establishment_date_fund",A7) -> 2022-11-15 | F7: =[1]!thsiFinD("ths_service_sd_fund",A7,"100",1,"101") -> 2024-03-19 | G7: =[1]!thsiFinD("ths_fund_scale_fund",A7,1)/100000000 -> 8.5081517 | H7: =IF($F7-H$1>0,"",[1]!thsiFinD("ths_adjustment_nvg_ratio_fund",$A7,H$1,H$3,"")/100) -> 0.031253288 | I7: =IF($F7-#REF!>0,"",[1]!thsiFinD("ths_adjustment_nvg_ratio_fund",$A7,#REF!,I$3,"")/100) -> #REF! | J7: =IF($F7-J$2>0,"",[1]!thsiFinD("ths_adjustment_nvg_ratio_fund",$A7,J$2,J$3,"")/100) -> -0.040814329 | K7: =IF($F7-K$2>0,"",[1]!thsiFinD("ths_adjustment_nvg_ratio_fund",$A7,K$2,K$3,"")/100) -> -0.079293499 | N7: =IF($F7-N$1>0,"",[1]!thsiFinD("ths_adjustment_nvg_ratio_fund",$A7,N$1,N$3,"")/100) -> -0.082826392 | O7: =IF($F7-O$2>0,"",[1]!thsiFinD("ths_adjustment_nvg_ratio_fund",$A7,O$2,O$3,"")/100) -> 0.32027678 | S7: =IF($F7-S$1>0,"",[1]!thsiFinD("ths_adjustment_nvg_ratio_fund",$A7,S$1,S$3,"")/100) | T7: =IF($F7-T$2>0,"",[1]!thsiFinD("ths_adjustment_nvg_ratio_fund",$A7,T$2,T$3,"")/100) | U7: =IF($F7-U$2>0,"",[1]!thsiFinD("ths_adjustment_nvg_ratio_fund",$A7,U$2,U$3,"")/100) | V7: =IF($F7-V$2>0,"",[1]!thsiFinD("ths_adjustment_nvg_ratio_fund",$A7,V$2,V$3,"")/100) | X7: =IF(X$2-F7>0,[1]!thsiFinD("ths_max_retrace_rate_fund",A7,$X$2,$X$3)/100,[1]!thsiFinD("ths_max_retrace_rate_fund",A7,$F7,$X$3)/100) -> 0.18826974 | Z7: 0.08
A8: 000480.OF | B8: =[1]!thsiFinD("ths_fund_official_short_name_fund",A8) -> 东方红新动力混合A | C8: 均衡-偏价值 | D8: =[1]!thsiFinD("ths_fund_manager_current_fund",A8) -> 周云 | E8: =[1]!thsiFinD("ths_fund_establishment_date_fund",A8) -> 2014-01-28 | F8: =[1]!thsiFinD("ths_service_sd_fund",A8,"100",1,"101") -> 2015-09-14 | G8: =[1]!thsiFinD("ths_fund_scale_fund",A8,1)/100000000 -> 48.090501 | H8: =IF($F8-H$1>0,"",[1]!thsiFinD("ths_adjustment_nvg_ratio_fund",$A8,H$1,H$3,"")/100) -> 0.028869679 | I8: =IF($F8-#REF!>0,"",[1]!thsiFinD("ths_adjustment_nvg_ratio_fund",$A8,#REF!,I$3,"")/100) -> #REF! | J8: =IF($F8-J$2>0,"",[1]!thsiFinD("ths_adjustment_nvg_ratio_fund",$A8,J$2,J$3,"")/100) -> -0.0039475762 | K8: =IF($F8-K$2>0,"",[1]!thsiFinD("ths_adjustment_nvg_ratio_fund",$A8,K$2,K$3,"")/100) -> 0.056970509 | N8: =IF($F8-N$1>0,"",[1]!thsiFinD("ths_adjustment_nvg_ratio_fund",$A8,N$1,N$3,"")/100) -> 0.086836664 | O8: =IF($F8-O$2>0,"",[1]!thsiFinD("ths_adjustment_nvg_ratio_fund",$A8,O$2,O$3,"")/100) -> 0.25546182 | S8: =IF($F8-S$1>0,"",[1]!thsiFinD("ths_adjustment_nvg_ratio_fund",$A8,S$1,S$3,"")/100) -> 0.15137731 | T8: =IF($F8-T$2>0,"",[1]!thsiFinD("ths_adjustment_nvg_ratio_fund",$A8,T$2,T$3,"")/100) -> 0.067152104 | U8: =IF($F8-U$2>0,"",[1]!thsiFinD("ths_adjustment_nvg_ratio_fund",$A8,U$2,U$3,"")/100) -> -0.11036468 | V8: =IF($F8-V$2>0,"",[1]!thsiFinD("ths_adjustment_nvg_ratio_fund",$A8,V$2,V$3,"")/100) -> 0.25579994 | W8: =IF($F8-W$2>0,"",[1]!thsiFinD("ths_adjustment_nvg_ratio_fund",$A8,W$2,W$3,"")/100) -> 0.3249501 | X8: =IF(X$2-F8>0,[1]!thsiFinD("ths_max_retrace_rate_fund",A8,$X$2,$X$3)/100,[1]!thsiFinD("ths_max_retrace_rate_fund",A8,$F8,$X$3)/100) -> 0.20137408 | Z8: 0.08
A9: 000965.OF | B9: =[1]!thsiFinD("ths_fund_official_short_name_fund",A9) -> 汇丰晋信新动力混合A | C9: 均衡-偏价值 | D9: =[1]!thsiFinD("ths_fund_manager_current_fund",A9) -> 闵良超 | E9: =[1]!thsiFinD("ths_fund_establishment_date_fund",A9) -> 2015-02-11 | F9: =[1]!thsiFinD("ths_service_sd_fund",A9,"100",1,"101") -> 2021-09-30 | G9: =[1]!thsiFinD("ths_fund_scale_fund",A9,1)/100000000 -> 25.856235 | H9: =IF($F9-H$1>0,"",[1]!thsiFinD("ths_adjustment_nvg_ratio_fund",$A9,H$1,H$3,"")/100) -> 0.040587824 | I9: =IF($F9-#REF!>0,"",[1]!thsiFinD("ths_adjustment_nvg_ratio_fund",$A9,#REF!,I$3,"")/100) -> #REF! | J9: =IF($F9-J$2>0,"",[1]!thsiFinD("ths_adjustment_nvg_ratio_fund",$A9,J$2,J$3,"")/100) -> -0.054629672 | K9: =IF($F9-K$2>0,"",[1]!thsiFinD("ths_adjustment_nvg_ratio_fund",$A9,K$2,K$3,"")/100) -> -0.092146003 | N9: =IF($F9-N$1>0,"",[1]!thsiFinD("ths_adjustment_nvg_ratio_fund",$A9,N$1,N$3,"")/100) -> -0.046445584 | O9: =IF($F9-O$2>0,"",[1]!thsiFinD("ths_adjustment_nvg_ratio_fund",$A9,O$2,O$3,"")/100) -> 0.34169125 | S9: =IF($F9-S$1>0,"",[1]!thsiFinD("ths_adjustment_nvg_ratio_fund",$A9,S$1,S$3,"")/100) -> 0.10597169 | T9: =IF($F9-T$2>0,"",[1]!thsiFinD("ths_adjustment_nvg_ratio_fund",$A9,T$2,T$3,"")/100) -> 0.075660826 | U9: =IF($F9-U$2>0,"",[1]!thsiFinD("ths_adjustment_nvg_ratio_fund",$A9,U$2,U$3,"")/100) -> -0.16415317 | V9: =IF($F9-V$2>0,"",[1]!thsiFinD("ths_adjustment_nvg_ratio_fund",$A9,V$2,V$3,"")/100) | W9: =IF($F9-W$2>0,"",[1]!thsiFinD("ths_adjustment_nvg_ratio_fund",$A9,W$2,W$3,"")/100) | X9: =IF(X$2-F9>0,[1]!thsiFinD("ths_max_retrace_rate_fund",A9,$X$2,$X$3)/100,[1]!thsiFinD("ths_max_retrace_rate_fund",A9,$F9,$X$3)/100) -> 0.24066287 | Z9: 0.08
A10: 016840.OF | B10: =[1]!thsiFinD("ths_fund_official_short_name_fund",A10) -> 博道惠泰优选混合A | C10: 均衡成长 | D10: =[1]!thsiFinD("ths_fund_manager_current_fund",A10) -> 孙文龙 | E10: =[1]!thsiFinD("ths_fund_establishment_date_fund",A10) -> 2023-01-18 | F10: =[1]!thsiFinD("ths_service_sd_fund",A10,"100",1,"101") -> 2023-01-18 | G10: =[1]!thsiFinD("ths_fund_scale_fund",A10,1)/100000000 -> 5.0687625 | H10: =IF($F10-H$1>0,"",[1]!thsiFinD("ths_adjustment_nvg_ratio_fund",$A10,H$1,H$3,"")/100) -> 0.022093935 | I10: =IF($F10-#REF!>0,"",[1]!thsiFinD("ths_adjustment_nvg_ratio_fund",$A10,#REF!,I$3,"")/100) -> #REF! | J10: =IF($F10-J$2>0,"",[1]!thsiFinD("ths_adjustment_nvg_ratio_fund",$A10,J$2,J$3,"")/100) -> -0.015919852 | K10: =IF($F10-K$2>0,"",[1]!thsiFinD("ths_adjustment_nvg_ratio_fund",$A10,K$2,K$3,"")/100) -> 0.047246969 | N10: =IF($F10-N$1>0,"",[1]!thsiFinD("ths_adjustment_nvg_ratio_fund",$A10,N$1,N$3,"")/100) -> 0.077541513 | O10: =IF($F10-O$2>0,"",[1]!thsiFinD("ths_adjustment_nvg_ratio_fund",$A10,O$2,O$3,"")/100) -> 0.25143394 | S10: =IF($F10-S$1>0,"",[1]!thsiFinD("ths_adjustment_nvg_ratio_fund",$A10,S$1,S$3,"")/100) -> 0.19452922 | T10: =IF($F10-T$2>0,"",[1]!thsiFinD("ths_adjustment_nvg_ratio_fund",$A10,T$2,T$3,"")/100) | U10: =IF($F10-U$2>0,"",[1]!thsiFinD("ths_adjustment_nvg_ratio_fund",$A10,U$2,U$3,"")/100) | V10: =IF($F10-V$2>0,"",[1]!thsiFinD("ths_adjustment_nvg_ratio_fund",$A10,V$2,V$3,"")/100) | X10: =IF(X$2-F10>0,[1]!thsiFinD("ths_max_retrace_rate_fund",A10,$X$2,$X$3)/100,[1]!thsiFinD("ths_max_retrace_rate_fund",A10,$F10,$X$3)/100) -> 0.22501775 | Z10: 0.06
A11: 010826.OF | B11: =[1]!thsiFinD("ths_fund_official_short_name_fund",A11) -> 大成产业趋势混合A | C11: 周期成长 | D11: =[1]!thsiFinD("ths_fund_manager_current_fund",A11) -> 韩创 | E11: =[1]!thsiFinD("ths_fund_establishment_date_fund",A11) -> 2021-02-09 | F11: =[1]!thsiFinD("ths_service_sd_fund",A11,"100",1,"101") -> 2021-02-09 | G11: =[1]!thsiFinD("ths_fund_scale_fund",A11,1)/100000000 -> 36.014824 | H11: =IF($F11-H$1>0,"",[1]!thsiFinD("ths_adjustment_nvg_ratio_fund",$A11,H$1,H$3,"")/100) -> 0.055249745 | I11: =IF($F11-#REF!>0,"",[1]!thsiFinD("ths_adjustment_nvg_ratio_fund",$A11,#REF!,I$3,"")/100) -> #REF! | J11: =IF($F11-J$2>0,"",[1]!thsiFinD("ths_adjustment_nvg_ratio_fund",$A11,J$2,J$3,"")/100) -> -0.113395 | K11: =IF($F11-K$2>0,"",[1]!thsiFinD("ths_adjustment_nvg_ratio_fund",$A11,K$2,K$3,"")/100) -> -0.23264519 | N11: =IF($F11-N$1>0,"",[1]!thsiFinD("ths_adjustment_nvg_ratio_fund",$A11,N$1,N$3,"")/100) -> -0.091332017 | O11: =IF($F11-O$2>0,"",[1]!thsiFinD("ths_adjustment_nvg_ratio_fund",$A11,O$2,O$3,"")/100) -> 0.67894776 | S11: =IF($F11-S$1>0,"",[1]!thsiFinD("ths_adjustment_nvg_ratio_fund",$A11,S$1,S$3,"")/100) -> 0.066111111 | T11: =IF($F11-T$2>0,"",[1]!thsiFinD("ths_adjustment_nvg_ratio_fund",$A11,T$2,T$3,"")/100) -> -0.052698842 | U11: =IF($F11-U$2>0,"",[1]!thsiFinD("ths_adjustment_nvg_ratio_fund",$A11,U$2,U$3,"")/100) -> -0.11005553 | V11: =IF($F11-V$2>0,"",[1]!thsiFinD("ths_adjustment_nvg_ratio_fund",$A11,V$2,V$3,"")/100) | X11: =IF(X$2-F11>0,[1]!thsiFinD("ths_max_retrace_rate_fund",A11,$X$2,$X$3)/100,[1]!thsiFinD("ths_max_retrace_rate_fund",A11,$F11,$X$3)/100) -> 0.37605343 | Z11: 0.1
A12: 519183.OF | B12: =[1]!thsiFinD("ths_fund_official_short_name_fund",A12) -> 万家双引擎灵活配置混合A | C12: 周期成长 | D12: =[1]!thsiFinD("ths_fund_manager_current_fund",A12) -> 李杨 | E12: =[1]!thsiFinD("ths_fund_establishment_date_fund",A12) -> 2008-06-27 | F12: =[1]!thsiFinD("ths_service_sd_fund",A12,"100",1,"101") -> 2026-06-19 | G12: =[1]!thsiFinD("ths_fund_scale_fund",A12,1)/100000000 -> 17.666927 | H12: =IF($F12-H$1>0,"",[1]!thsiFinD("ths_adjustment_nvg_ratio_fund",$A12,H$1,H$3,"")/100) -> 0.010940235 | I12: =IF($F12-#REF!>0,"",[1]!thsiFinD("ths_adjustment_nvg_ratio_fund",$A12,#REF!,I$3,"")/100) -> #REF! | J12: =IF($F12-J$2>0,"",[1]!thsiFinD("ths_adjustment_nvg_ratio_fund",$A12,J$2,J$3,"")/100) | K12: =IF($F12-K$2>0,"",[1]!thsiFinD("ths_adjustment_nvg_ratio_fund",$A12,K$2,K$3,"")/100) | N12: =IF($F12-N$1>0,"",[1]!thsiFinD("ths_adjustment_nvg_ratio_fund",$A12,N$1,N$3,"")/100) | O12: =IF($F12-O$2>0,"",[1]!thsiFinD("ths_adjustment_nvg_ratio_fund",$A12,O$2,O$3,"")/100) | S12: =IF($F12-S$1>0,"",[1]!thsiFinD("ths_adjustment_nvg_ratio_fund",$A12,S$1,S$3,"")/100) | T12: =IF($F12-T$2>0,"",[1]!thsiFinD("ths_adjustment_nvg_ratio_fund",$A12,T$2,T$3,"")/100) | U12: =IF($F12-U$2>0,"",[1]!thsiFinD("ths_adjustment_nvg_ratio_fund",$A12,U$2,U$3,"")/100) | V12: =IF($F12-V$2>0,"",[1]!thsiFinD("ths_adjustment_nvg_ratio_fund",$A12,V$2,V$3,"")/100) | W12: =IF($F12-W$2>0,"",[1]!thsiFinD("ths_adjustment_nvg_ratio_fund",$A12,W$2,W$3,"")/100) | X12: =IF(X$2-F12>0,[1]!thsiFinD("ths_max_retrace_rate_fund",A12,$X$2,$X$3)/100,[1]!thsiFinD("ths_max_retrace_rate_fund",A12,$F12,$X$3)/100) -> 0.083618539 | Z12: 0.05
A13: 013955.OF | B13: =[1]!thsiFinD("ths_fund_official_short_name_fund",A13) -> 广发中小盘精选混合C | C13: 均衡成长 | D13: =[1]!thsiFinD("ths_fund_manager_current_fund",A13) -> 陈韫中 | E13: =[1]!thsiFinD("ths_fund_establishment_date_fund",A13) -> 2021-10-27 | F13: =[1]!thsiFinD("ths_service_sd_fund",A13,"100",1,"101") -> 2021-10-27 | G13: =[1]!thsiFinD("ths_fund_scale_fund",A13,1)/100000000 -> 20.9725 | H13: =IF($F13-H$1>0,"",[1]!thsiFinD("ths_adjustment_nvg_ratio_fund",$A13,H$1,H$3,"")/100) -> -0.03031071 | I13: =IF($F13-#REF!>0,"",[1]!thsiFinD("ths_adjustment_nvg_ratio_fund",$A13,#REF!,I$3,"")/100) -> #REF! | J13: =IF($F13-J$2>0,"",[1]!thsiFinD("ths_adjustment_nvg_ratio_fund",$A13,J$2,J$3,"")/100) -> 0.26040123 | K13: =IF($F13-K$2>0,"",[1]!thsiFinD("ths_adjustment_nvg_ratio_fund",$A13,K$2,K$3,"")/100) -> 0.44237946 | N13: =IF($F13-N$1>0,"",[1]!thsiFinD("ths_adjustment_nvg_ratio_fund",$A13,N$1,N$3,"")/100) -> 0.43869148 | O13: =IF($F13-O$2>0,"",[1]!thsiFinD("ths_adjustment_nvg_ratio_fund",$A13,O$2,O$3,"")/100) -> 0.53746098 | S13: =IF($F13-S$1>0,"",[1]!thsiFinD("ths_adjustment_nvg_ratio_fund",$A13,S$1,S$3,"")/100) -> 0.086398467 | T13: =IF($F13-T$2>0,"",[1]!thsiFinD("ths_adjustment_nvg_ratio_fund",$A13,T$2,T$3,"")/100) -> 0.0073974013 | U13: =IF($F13-U$2>0,"",[1]!thsiFinD("ths_adjustment_nvg_ratio_fund",$A13,U$2,U$3,"")/100) -> -0.25158868 | V13: =IF($F13-V$2>0,"",[1]!thsiFinD("ths_adjustment_nvg_ratio_fund",$A13,V$2,V$3,"")/100) | W13: =IF($F13-W$2>0,"",[1]!thsiFinD("ths_adjustment_nvg_ratio_fund",$A13,W$2,W$3,"")/100) | X13: =IF(X$2-F13>0,[1]!thsiFinD("ths_max_retrace_rate_fund",A13,$X$2,$X$3)/100,[1]!thsiFinD("ths_max_retrace_rate_fund",A13,$F13,$X$3)/100) -> 0.36591754 | Z13: 0.11
A14: 001975.OF | B14: =[1]!thsiFinD("ths_fund_official_short_name_fund",A14) -> 景顺长城环保优势股票 | C14: 均衡成长 | D14: =[1]!thsiFinD("ths_fund_manager_current_fund",A14) -> 杨锐文 | E14: =[1]!thsiFinD("ths_fund_establishment_date_fund",A14) -> 2016-03-15 | F14: =[1]!thsiFinD("ths_service_sd_fund",A14,"100",1,"101") -> 2016-03-15 | G14: =[1]!thsiFinD("ths_fund_scale_fund",A14,1)/100000000 -> 26.966624 | H14: =IF($F14-H$1>0,"",[1]!thsiFinD("ths_adjustment_nvg_ratio_fund",$A14,H$1,H$3,"")/100) -> 0.029205841 | I14: =IF($F14-#REF!>0,"",[1]!thsiFinD("ths_adjustment_nvg_ratio_fund",$A14,#REF!,I$3,"")/100) -> #REF! | J14: =IF($F14-J$2>0,"",[1]!thsiFinD("ths_adjustment_nvg_ratio_fund",$A14,J$2,J$3,"")/100) -> 0.085901224 | K14: =IF($F14-K$2>0,"",[1]!thsiFinD("ths_adjustment_nvg_ratio_fund",$A14,K$2,K$3,"")/100) -> 0.25426621 | N14: =IF($F14-N$1>0,"",[1]!thsiFinD("ths_adjustment_nvg_ratio_fund",$A14,N$1,N$3,"")/100) -> 0.29727685 | O14: =IF($F14-O$2>0,"",[1]!thsiFinD("ths_adjustment_nvg_ratio_fund",$A14,O$2,O$3,"")/100) -> 0.31150794 | S14: =IF($F14-S$1>0,"",[1]!thsiFinD("ths_adjustment_nvg_ratio_fund",$A14,S$1,S$3,"")/100) -> 0.019723183 | T14: =IF($F14-T$2>0,"",[1]!thsiFinD("ths_adjustment_nvg_ratio_fund",$A14,T$2,T$3,"")/100) -> 0.036944046 | U14: =IF($F14-U$2>0,"",[1]!thsiFinD("ths_adjustment_nvg_ratio_fund",$A14,U$2,U$3,"")/100) -> -0.34167651 | X14: =IF(X$2-F14>0,[1]!thsiFinD("ths_max_retrace_rate_fund",A14,$X$2,$X$3)/100,[1]!thsiFinD("ths_max_retrace_rate_fund",A14,$F14,$X$3)/100) -> 0.32383666 | Z14: 0.07
A15: 003956.OF | B15: =[1]!thsiFinD("ths_fund_official_short_name_fund",A15) -> 南方产业智选股票A | C15: 价值 | D15: =[1]!thsiFinD("ths_fund_manager_current_fund",A15) -> 恽雷 | E15: =[1]!thsiFinD("ths_fund_establishment_date_fund",A15) -> 2017-01-25 | F15: =[1]!thsiFinD("ths_service_sd_fund",A15,"100",1,"101") -> 2023-04-14 | G15: =[1]!thsiFinD("ths_fund_scale_fund",A15,1)/100000000 -> 11.446085 | H15: =IF($F15-H$1>0,"",[1]!thsiFinD("ths_adjustment_nvg_ratio_fund",$A15,H$1,H$3,"")/100) -> 0.023092585 | I15: =IF($F15-#REF!>0,"",[1]!thsiFinD("ths_adjustment_nvg_ratio_fund",$A15,#REF!,I$3,"")/100) -> #REF! | J15: =IF($F15-J$2>0,"",[1]!thsiFinD("ths_adjustment_nvg_ratio_fund",$A15,J$2,J$3,"")/100) -> -0.083909039 | K15: =IF($F15-K$2>0,"",[1]!thsiFinD("ths_adjustment_nvg_ratio_fund",$A15,K$2,K$3,"")/100) -> -0.11028795 | N15: =IF($F15-N$1>0,"",[1]!thsiFinD("ths_adjustment_nvg_ratio_fund",$A15,N$1,N$3,"")/100) -> -0.085357092 | O15: =IF($F15-O$2>0,"",[1]!thsiFinD("ths_adjustment_nvg_ratio_fund",$A15,O$2,O$3,"")/100) -> 0.13105429 | S15: =IF($F15-S$1>0,"",[1]!thsiFinD("ths_adjustment_nvg_ratio_fund",$A15,S$1,S$3,"")/100) -> 0.20990489 | T15: =IF($F15-T$2>0,"",[1]!thsiFinD("ths_adjustment_nvg_ratio_fund",$A15,T$2,T$3,"")/100) | U15: =IF($F15-U$2>0,"",[1]!thsiFinD("ths_adjustment_nvg_ratio_fund",$A15,U$2,U$3,"")/100) | X15: =IF(X$2-F15>0,[1]!thsiFinD("ths_max_retrace_rate_fund",A15,$X$2,$X$3)/100,[1]!thsiFinD("ths_max_retrace_rate_fund",A15,$F15,$X$3)/100) -> 0.17638233 | Z15: 0.08
A16: 013776.OF | B16: =[1]!thsiFinD("ths_fund_official_short_name_fund",A16) -> 中泰兴为价值精选混合A | C16: 价值 | D16: =[1]!thsiFinD("ths_fund_manager_current_fund",A16) -> 姜诚 | E16: =[1]!thsiFinD("ths_fund_establishment_date_fund",A16) -> 2022-01-18 | F16: =[1]!thsiFinD("ths_service_sd_fund",A16,"100",1,"101") -> 2022-01-18 | G16: =[1]!thsiFinD("ths_fund_scale_fund",A16,1)/100000000 -> 16.084866 | H16: =IF($F16-H$1>0,"",[1]!thsiFinD("ths_adjustment_nvg_ratio_fund",$A16,H$1,H$3,"")/100) -> 0.01699946 | I16: =IF($F16-#REF!>0,"",[1]!thsiFinD("ths_adjustment_nvg_ratio_fund",$A16,#REF!,I$3,"")/100) -> #REF! | J16: =IF($F16-J$2>0,"",[1]!thsiFinD("ths_adjustment_nvg_ratio_fund",$A16,J$2,J$3,"")/100) -> -0.08777733 | K16: =IF($F16-K$2>0,"",[1]!thsiFinD("ths_adjustment_nvg_ratio_fund",$A16,K$2,K$3,"")/100) -> -0.067002228 | N16: =IF($F16-N$1>0,"",[1]!thsiFinD("ths_adjustment_nvg_ratio_fund",$A16,N$1,N$3,"")/100) -> -0.044774858 | O16: =IF($F16-O$2>0,"",[1]!thsiFinD("ths_adjustment_nvg_ratio_fund",$A16,O$2,O$3,"")/100) -> 0.11291839 | S16: =IF($F16-S$1>0,"",[1]!thsiFinD("ths_adjustment_nvg_ratio_fund",$A16,S$1,S$3,"")/100) -> 0.1422117 | T16: =IF($F16-T$2>0,"",[1]!thsiFinD("ths_adjustment_nvg_ratio_fund",$A16,T$2,T$3,"")/100) -> -0.073819486 | U16: =IF($F16-U$2>0,"",[1]!thsiFinD("ths_adjustment_nvg_ratio_fund",$A16,U$2,U$3,"")/100) | X16: =IF(X$2-F16>0,[1]!thsiFinD("ths_max_retrace_rate_fund",A16,$X$2,$X$3)/100,[1]!thsiFinD("ths_max_retrace_rate_fund",A16,$F16,$X$3)/100) -> 0.21036121 | Z16: 0.08
